5:return {{["x"] = 0, ["y"] = 0, ["z"] = 1, ["name"] = "wool:grey"}, {["x"] = 0, ["y"] = 0, ["z"] = 2, ["name"] = "wool:grey"}, {["x"] = 0, ["y"] = 1, ["z"] = 1, ["name"] = "wool:grey"}, {["x"] = 0, ["y"] = 1, ["z"] = 2, ["name"] = "wool:grey"}, {["x"] = 0, ["y"] = 2, ["z"] = 1, ["name"] = "wool:grey"}, {["x"] = 0, ["y"] = 2, ["z"] = 2, ["name"] = "wool:grey"}, {["x"] = 0, ["y"] = 3, ["z"] = 1, ["name"] = "wool:grey"}, {["x"] = 0, ["y"] = 3, ["z"] = 2, ["name"] = "wool:grey"}, {["x"] = 0, ["y"] = 4, ["z"] = 1, ["name"] = "wool:grey"}, {["x"] = 0, ["y"] = 4, ["z"] = 2, ["name"] = "wool:grey"}, {["x"] = 0, ["y"] = 5, ["z"] = 1, ["name"] = "wool:grey"}, {["x"] = 0, ["y"] = 5, ["z"] = 2, ["name"] = "wool:grey"}, {["x"] = 0, ["y"] = 6, ["z"] = 1, ["name"] = "wool:grey"}, {["x"] = 0, ["y"] = 6, ["z"] = 2, ["name"] = "wool:grey"}, {["x"] = 0, ["y"] = 7, ["z"] = 1, ["name"] = "wool:grey"}, {["x"] = 0, ["y"] = 7, ["z"] = 2, ["name"] = "wool:grey"}, {["x"] = 0, ["y"] = 8, ["z"] = 1, ["name"] = "wool:grey"}, {["x"] = 0, ["y"] = 8, ["z"] = 2, ["name"] = "wool:grey"}, {["x"] = 0, ["y"] = 9, ["z"] = 1, ["name"] = "wool:grey"}, {["x"] = 0, ["y"] = 9, ["z"] = 2, ["name"] = "wool:grey"}, {["x"] = 1, ["y"] = 0, ["z"] = 1, ["name"] = "wool:grey"}, {["x"] = 1, ["y"] = 0, ["z"] = 2, ["name"] = "wool:grey"}, {["x"] = 1, ["y"] = 0, ["z"] = 12, ["name"] = "wool:grey"}, {["x"] = 1, ["y"] = 0, ["z"] = 13, ["name"] = "wool:grey"}, {["x"] = 1, ["y"] = 1, ["z"] = 1, ["name"] = "wool:grey"}, {["x"] = 1, ["y"] = 1, ["z"] = 2, ["name"] = "wool:grey"}, {["x"] = 1, ["y"] = 1, ["z"] = 12, ["name"] = "wool:grey"}, {["x"] = 1, ["y"] = 1, ["z"] = 13, ["name"] = "wool:grey"}, {["x"] = 1, ["y"] = 2, ["z"] = 1, ["name"] = "wool:grey"}, {["x"] = 1, ["y"] = 2, ["z"] = 2, ["name"] = "wool:grey"}, {["x"] = 1, ["y"] = 2, ["z"] = 12, ["name"] = "wool:grey"}, {["x"] = 1, ["y"] = 2, ["z"] = 13, ["name"] = "wool:grey"}, {["x"] = 1, ["y"] = 3, ["z"] = 1, ["name"] = "wool:grey"}, {["x"] = 1, ["y"] = 3, ["z"] = 2, ["name"] = "wool:grey"}, {["x"] = 1, ["y"] = 3, ["z"] = 12, ["name"] = "wool:grey"}, {["x"] = 1, ["y"] = 3, ["z"] = 13, ["name"] = "wool:grey"}, {["x"] = 1, ["y"] = 4, ["z"] = 1, ["name"] = "wool:grey"}, {["x"] = 1, ["y"] = 4, ["z"] = 2, ["name"] = "wool:grey"}, {["x"] = 1, ["y"] = 4, ["z"] = 12, ["name"] = "wool:grey"}, {["x"] = 1, ["y"] = 4, ["z"] = 13, ["name"] = "wool:grey"}, {["x"] = 1, ["y"] = 5, ["z"] = 1, ["name"] = "wool:grey"}, {["x"] = 1, ["y"] = 5, ["z"] = 2, ["name"] = "wool:grey"}, {["x"] = 1, ["y"] = 5, ["z"] = 3, ["name"] = "wool:grey"}, {["x"] = 1, ["y"] = 5, ["z"] = 4, ["name"] = "wool:grey"}, {["x"] = 1, ["y"] = 5, ["z"] = 5, ["name"] = "wool:grey"}, {["x"] = 1, ["y"] = 5, ["z"] = 6, ["name"] = "wool:grey"}, {["x"] = 1, ["y"] = 5, ["z"] = 7, ["name"] = "wool:grey"}, {["x"] = 1, ["y"] = 5, ["z"] = 8, ["name"] = "wool:grey"}, {["x"] = 1, ["y"] = 5, ["z"] = 9, ["name"] = "wool:grey"}, {["x"] = 1, ["y"] = 5, ["z"] = 10, ["name"] = "wool:grey"}, {["x"] = 1, ["y"] = 5, ["z"] = 11, ["name"] = "wool:grey"}, {["x"] = 1, ["y"] = 5, ["z"] = 12, ["name"] = "wool:grey"}, {["x"] = 1, ["y"] = 5, ["z"] = 13, ["name"] = "wool:grey"}, {["x"] = 1, ["y"] = 6, ["z"] = 1, ["name"] = "wool:grey"}, {["x"] = 1, ["y"] = 6, ["z"] = 2, ["name"] = "wool:grey"}, {["x"] = 1, ["y"] = 6, ["z"] = 3, ["name"] = "wool:grey"}, {["x"] = 1, ["y"] = 6, ["z"] = 4, ["name"] = "wool:grey"}, {["x"] = 1, ["y"] = 6, ["z"] = 5, ["name"] = "wool:grey"}, {["x"] = 1, ["y"] = 6, ["z"] = 6, ["name"] = "wool:grey"}, {["x"] = 1, ["y"] = 6, ["z"] = 7, ["name"] = "wool:grey"}, {["x"] = 1, ["y"] = 6, ["z"] = 8, ["name"] = "wool:grey"}, {["x"] = 1, ["y"] = 6, ["z"] = 9, ["name"] = "wool:grey"}, {["x"] = 1, ["y"] = 6, ["z"] = 10, ["name"] = "wool:grey"}, {["x"] = 1, ["y"] = 6, ["z"] = 11, ["name"] = "wool:grey"}, {["x"] = 1, ["y"] = 6, ["z"] = 12, ["name"] = "wool:grey"}, {["x"] = 1, ["y"] = 6, ["z"] = 13, ["name"] = "wool:grey"}, {["x"] = 1, ["y"] = 7, ["z"] = 1, ["name"] = "wool:grey"}, {["x"] = 1, ["y"] = 7, ["z"] = 2, ["name"] = "wool:grey"}, {["x"] = 1, ["y"] = 7, ["z"] = 12, ["name"] = "wool:grey"}, {["x"] = 1, ["y"] = 7, ["z"] = 13, ["name"] = "wool:grey"}, {["x"] = 1, ["y"] = 7, ["z"] = 14, ["name"] = "wool:grey"}, {["x"] = 1, ["y"] = 8, ["z"] = 1, ["name"] = "wool:grey"}, {["x"] = 1, ["y"] = 8, ["z"] = 2, ["name"] = "wool:grey"}, {["x"] = 1, ["y"] = 8, ["z"] = 12, ["name"] = "wool:grey"}, {["x"] = 1, ["y"] = 8, ["z"] = 13, ["name"] = "wool:grey"}, {["x"] = 1, ["y"] = 8, ["z"] = 14, ["name"] = "wool:grey"}, {["x"] = 1, ["y"] = 9, ["z"] = 1, ["name"] = "wool:grey"}, {["x"] = 1, ["y"] = 9, ["z"] = 2, ["name"] = "wool:grey"}, {["x"] = 1, ["y"] = 9, ["z"] = 12, ["name"] = "wool:grey"}, {["x"] = 1, ["y"] = 9, ["z"] = 13, ["name"] = "wool:grey"}, {["x"] = 1, ["y"] = 10, ["z"] = 1, ["name"] = "wool:grey"}, {["x"] = 1, ["y"] = 10, ["z"] = 2, ["name"] = "wool:grey"}, {["x"] = 1, ["y"] = 10, ["z"] = 12, ["name"] = "wool:grey"}, {["x"] = 1, ["y"] = 10, ["z"] = 13, ["name"] = "wool:grey"}, {["x"] = 1, ["y"] = 11, ["z"] = 12, ["name"] = "wool:grey"}, {["x"] = 1, ["y"] = 11, ["z"] = 13, ["name"] = "wool:grey"}, {["x"] = 1, ["y"] = 12, ["z"] = 12, ["name"] = "wool:grey"}, {["x"] = 1, ["y"] = 12, ["z"] = 13, ["name"] = "wool:grey"}, {["x"] = 1, ["y"] = 13, ["z"] = 12, ["name"] = "wool:grey"}, {["x"] = 1, ["y"] = 13, ["z"] = 13, ["name"] = "wool:grey"}, {["x"] = 1, ["y"] = 14, ["z"] = 12, ["name"] = "wool:grey"}, {["x"] = 1, ["y"] = 14, ["z"] = 13, ["name"] = "wool:grey"}, {["x"] = 1, ["y"] = 15, ["z"] = 12, ["name"] = "wool:grey"}, {["x"] = 1, ["y"] = 15, ["z"] = 13, ["name"] = "wool:grey"}, {["x"] = 2, ["y"] = 0, ["z"] = 12, ["name"] = "wool:grey"}, {["x"] = 2, ["y"] = 0, ["z"] = 13, ["name"] = "wool:grey"}, {["x"] = 2, ["y"] = 1, ["z"] = 12, ["name"] = "wool:grey"}, {["x"] = 2, ["y"] = 1, ["z"] = 13, ["name"] = "wool:grey"}, {["x"] = 2, ["y"] = 2, ["z"] = 1, ["name"] = "wool:grey"}, {["x"] = 2, ["y"] = 2, ["z"] = 12, ["name"] = "wool:grey"}, {["x"] = 2, ["y"] = 2, ["z"] = 13, ["name"] = "wool:grey"}, {["x"] = 2, ["y"] = 3, ["z"] = 1, ["name"] = "wool:grey"}, {["x"] = 2, ["y"] = 3, ["z"] = 12, ["name"] = "wool:grey"}, {["x"] = 2, ["y"] = 3, ["z"] = 13, ["name"] = "wool:grey"}, {["x"] = 2, ["y"] = 4, ["z"] = 12, ["name"] = "wool:grey"}, {["x"] = 2, ["y"] = 4, ["z"] = 13, ["name"] = "wool:grey"}, {["x"] = 2, ["y"] = 5, ["z"] = 2, ["name"] = "default:steelblock"}, {["x"] = 2, ["y"] = 5, ["z"] = 3, ["name"] = "default:steelblock"}, {["x"] = 2, ["y"] = 5, ["z"] = 4, ["name"] = "default:steelblock"}, {["x"] = 2, ["y"] = 5, ["z"] = 5, ["name"] = "default:steelblock"}, {["x"] = 2, ["y"] = 5, ["z"] = 6, ["name"] = "default:steelblock"}, {["x"] = 2, ["y"] = 5, ["z"] = 7, ["name"] = "default:steelblock"}, {["x"] = 2, ["y"] = 5, ["z"] = 8, ["name"] = "default:steelblock"}, {["x"] = 2, ["y"] = 5, ["z"] = 9, ["name"] = "default:steelblock"}, {["x"] = 2, ["y"] = 5, ["z"] = 12, ["name"] = "wool:grey"}, {["x"] = 2, ["y"] = 5, ["z"] = 13, ["name"] = "wool:grey"}, {["x"] = 2, ["y"] = 6, ["z"] = 2, ["name"] = "default:steelblock"}, {["x"] = 2, ["y"] = 6, ["z"] = 3, ["name"] = "default:steelblock"}, {["x"] = 2, ["y"] = 6, ["z"] = 4, ["name"] = "default:steelblock"}, {["x"] = 2, ["y"] = 6, ["z"] = 5, ["name"] = "default:steelblock"}, {["x"] = 2, ["y"] = 6, ["z"] = 6, ["name"] = "default:steelblock"}, {["x"] = 2, ["y"] = 6, ["z"] = 7, ["name"] = "default:steelblock"}, {["x"] = 2, ["y"] = 6, ["z"] = 8, ["name"] = "default:steelblock"}, {["x"] = 2, ["y"] = 6, ["z"] = 9, ["name"] = "default:steelblock"}, {["x"] = 2, ["y"] = 6, ["z"] = 12, ["name"] = "wool:grey"}, {["x"] = 2, ["y"] = 6, ["z"] = 13, ["name"] = "wool:grey"}, {["x"] = 2, ["y"] = 7, ["z"] = 2, ["name"] = "default:steelblock"}, {["x"] = 2, ["y"] = 7, ["z"] = 3, ["name"] = "default:steelblock"}, {["x"] = 2, ["y"] = 7, ["z"] = 4, ["name"] = "default:steelblock"}, {["x"] = 2, ["y"] = 7, ["z"] = 5, ["name"] = "default:steelblock"}, {["x"] = 2, ["y"] = 7, ["z"] = 6, ["name"] = "default:steelblock"}, {["x"] = 2, ["y"] = 7, ["z"] = 7, ["name"] = "default:steelblock"}, {["x"] = 2, ["y"] = 7, ["z"] = 8, ["name"] = "default:steelblock"}, {["x"] = 2, ["y"] = 7, ["z"] = 9, ["name"] = "default:steelblock"}, {["x"] = 2, ["y"] = 7, ["z"] = 12, ["name"] = "wool:grey"}, {["x"] = 2, ["y"] = 7, ["z"] = 13, ["name"] = "wool:grey"}, {["x"] = 2, ["y"] = 7, ["z"] = 14, ["name"] = "wool:grey"}, {["x"] = 2, ["y"] = 8, ["z"] = 2, ["name"] = "default:steelblock"}, {["x"] = 2, ["y"] = 8, ["z"] = 3, ["name"] = "default:steelblock"}, {["x"] = 2, ["y"] = 8, ["z"] = 4, ["name"] = "default:steelblock"}, {["x"] = 2, ["y"] = 8, ["z"] = 5, ["name"] = "default:steelblock"}, {["x"] = 2, ["y"] = 8, ["z"] = 6, ["name"] = "default:steelblock"}, {["x"] = 2, ["y"] = 8, ["z"] = 7, ["name"] = "default:steelblock"}, {["x"] = 2, ["y"] = 8, ["z"] = 8, ["name"] = "default:steelblock"}, {["x"] = 2, ["y"] = 8, ["z"] = 9, ["name"] = "default:steelblock"}, {["x"] = 2, ["y"] = 8, ["z"] = 12, ["name"] = "wool:grey"}, {["x"] = 2, ["y"] = 8, ["z"] = 13, ["name"] = "wool:grey"}, {["x"] = 2, ["y"] = 8, ["z"] = 14, ["name"] = "wool:grey"}, {["x"] = 2, ["y"] = 9, ["z"] = 1, ["name"] = "wool:grey"}, {["x"] = 2, ["y"] = 9, ["z"] = 2, ["name"] = "default:steelblock"}, {["x"] = 2, ["y"] = 9, ["z"] = 3, ["name"] = "default:steelblock"}, {["x"] = 2, ["y"] = 9, ["z"] = 4, ["name"] = "default:steelblock"}, {["x"] = 2, ["y"] = 9, ["z"] = 5, ["name"] = "default:steelblock"}, {["x"] = 2, ["y"] = 9, ["z"] = 6, ["name"] = "default:steelblock"}, {["x"] = 2, ["y"] = 9, ["z"] = 7, ["name"] = "default:steelblock"}, {["x"] = 2, ["y"] = 9, ["z"] = 8, ["name"] = "default:steelblock"}, {["x"] = 2, ["y"] = 9, ["z"] = 9, ["name"] = "default:steelblock"}, {["x"] = 2, ["y"] = 9, ["z"] = 12, ["name"] = "wool:grey"}, {["x"] = 2, ["y"] = 9, ["z"] = 13, ["name"] = "wool:grey"}, {["x"] = 2, ["y"] = 10, ["z"] = 1, ["name"] = "wool:grey"}, {["x"] = 2, ["y"] = 10, ["z"] = 2, ["name"] = "default:steelblock"}, {["x"] = 2, ["y"] = 10, ["z"] = 3, ["name"] = "default:steelblock"}, {["x"] = 2, ["y"] = 10, ["z"] = 4, ["name"] = "default:steelblock"}, {["x"] = 2, ["y"] = 10, ["z"] = 5, ["name"] = "default:steelblock"}, {["x"] = 2, ["y"] = 10, ["z"] = 6, ["name"] = "default:steelblock"}, {["x"] = 2, ["y"] = 10, ["z"] = 7, ["name"] = "default:steelblock"}, {["x"] = 2, ["y"] = 10, ["z"] = 8, ["name"] = "default:steelblock"}, {["x"] = 2, ["y"] = 10, ["z"] = 9, ["name"] = "default:steelblock"}, {["x"] = 2, ["y"] = 10, ["z"] = 12, ["name"] = "wool:grey"}, {["x"] = 2, ["y"] = 10, ["z"] = 13, ["name"] = "wool:grey"}, {["x"] = 2, ["y"] = 11, ["z"] = 12, ["name"] = "wool:grey"}, {["x"] = 2, ["y"] = 11, ["z"] = 13, ["name"] = "wool:grey"}, {["x"] = 2, ["y"] = 12, ["z"] = 12, ["name"] = "wool:grey"}, {["x"] = 2, ["y"] = 12, ["z"] = 13, ["name"] = "wool:grey"}, {["x"] = 2, ["y"] = 13, ["z"] = 12, ["name"] = "wool:grey"}, {["x"] = 2, ["y"] = 13, ["z"] = 13, ["name"] = "wool:grey"}, {["x"] = 2, ["y"] = 14, ["z"] = 12, ["name"] = "wool:grey"}, {["x"] = 2, ["y"] = 14, ["z"] = 13, ["name"] = "wool:grey"}, {["x"] = 2, ["y"] = 15, ["z"] = 12, ["name"] = "wool:grey"}, {["x"] = 2, ["y"] = 15, ["z"] = 13, ["name"] = "wool:grey"}, {["x"] = 3, ["y"] = 2, ["z"] = 1, ["name"] = "wool:grey"}, {["x"] = 3, ["y"] = 2, ["z"] = 2, ["name"] = "default:steelblock"}, {["x"] = 3, ["y"] = 2, ["z"] = 3, ["name"] = "default:steelblock"}, {["x"] = 3, ["y"] = 2, ["z"] = 4, ["name"] = "default:steelblock"}, {["x"] = 3, ["y"] = 2, ["z"] = 5, ["name"] = "default:steelblock"}, {["x"] = 3, ["y"] = 2, ["z"] = 6, ["name"] = "default:steelblock"}, {["x"] = 3, ["y"] = 2, ["z"] = 7, ["name"] = "default:steelblock"}, {["x"] = 3, ["y"] = 2, ["z"] = 8, ["name"] = "default:steelblock"}, {["x"] = 3, ["y"] = 2, ["z"] = 9, ["name"] = "default:steelblock"}, {["x"] = 3, ["y"] = 2, ["z"] = 10, ["name"] = "default:steelblock"}, {["x"] = 3, ["y"] = 2, ["z"] = 11, ["name"] = "default:steelblock"}, {["x"] = 3, ["y"] = 2, ["z"] = 12, ["name"] = "default:steelblock"}, {["x"] = 3, ["y"] = 2, ["z"] = 13, ["name"] = "default:steelblock"}, {["x"] = 3, ["y"] = 3, ["z"] = 1, ["name"] = "wool:grey"}, {["x"] = 3, ["y"] = 3, ["z"] = 2, ["name"] = "default:steelblock"}, {["x"] = 3, ["y"] = 3, ["z"] = 3, ["name"] = "default:steelblock"}, {["x"] = 3, ["y"] = 3, ["z"] = 4, ["name"] = "default:steelblock"}, {["x"] = 3, ["y"] = 3, ["z"] = 5, ["name"] = "default:steelblock"}, {["x"] = 3, ["y"] = 3, ["z"] = 6, ["name"] = "default:steelblock"}, {["x"] = 3, ["y"] = 3, ["z"] = 7, ["name"] = "default:steelblock"}, {["x"] = 3, ["y"] = 3, ["z"] = 8, ["name"] = "default:steelblock"}, {["x"] = 3, ["y"] = 3, ["z"] = 9, ["name"] = "default:steelblock"}, {["x"] = 3, ["y"] = 3, ["z"] = 10, ["name"] = "default:steelblock"}, {["x"] = 3, ["y"] = 3, ["z"] = 11, ["name"] = "default:steelblock"}, {["x"] = 3, ["y"] = 3, ["z"] = 12, ["name"] = "default:steelblock"}, {["x"] = 3, ["y"] = 3, ["z"] = 13, ["name"] = "default:steelblock"}, {["x"] = 3, ["y"] = 4, ["z"] = 2, ["name"] = "default:steelblock"}, {["x"] = 3, ["y"] = 4, ["z"] = 3, ["name"] = "default:steelblock"}, {["x"] = 3, ["y"] = 4, ["z"] = 4, ["name"] = "default:steelblock"}, {["x"] = 3, ["y"] = 4, ["z"] = 5, ["name"] = "default:steelblock"}, {["x"] = 3, ["y"] = 4, ["z"] = 6, ["name"] = "default:steelblock"}, {["x"] = 3, ["y"] = 4, ["z"] = 7, ["name"] = "default:steelblock"}, {["x"] = 3, ["y"] = 4, ["z"] = 8, ["name"] = "default:steelblock"}, {["x"] = 3, ["y"] = 4, ["z"] = 9, ["name"] = "default:steelblock"}, {["x"] = 3, ["y"] = 4, ["z"] = 10, ["name"] = "default:steelblock"}, {["x"] = 3, ["y"] = 4, ["z"] = 11, ["name"] = "default:steelblock"}, {["x"] = 3, ["y"] = 4, ["z"] = 12, ["name"] = "default:steelblock"}, {["x"] = 3, ["y"] = 4, ["z"] = 13, ["name"] = "default:steelblock"}, {["x"] = 3, ["y"] = 5, ["z"] = 2, ["name"] = "default:steelblock"}, {["x"] = 3, ["y"] = 5, ["z"] = 3, ["name"] = "default:steelblock"}, {["x"] = 3, ["y"] = 5, ["z"] = 4, ["name"] = "default:steelblock"}, {["x"] = 3, ["y"] = 5, ["z"] = 5, ["name"] = "default:steelblock"}, {["x"] = 3, ["y"] = 5, ["z"] = 6, ["name"] = "default:steelblock"}, {["x"] = 3, ["y"] = 5, ["z"] = 7, ["name"] = "default:steelblock"}, {["x"] = 3, ["y"] = 5, ["z"] = 8, ["name"] = "default:steelblock"}, {["x"] = 3, ["y"] = 5, ["z"] = 9, ["name"] = "default:steelblock"}, {["x"] = 3, ["y"] = 5, ["z"] = 10, ["name"] = "default:steelblock"}, {["x"] = 3, ["y"] = 5, ["z"] = 11, ["name"] = "default:steelblock"}, {["x"] = 3, ["y"] = 5, ["z"] = 12, ["name"] = "default:steelblock"}, {["x"] = 3, ["y"] = 5, ["z"] = 13, ["name"] = "default:steelblock"}, {["x"] = 3, ["y"] = 6, ["z"] = 2, ["name"] = "default:steelblock"}, {["x"] = 3, ["y"] = 6, ["z"] = 3, ["name"] = "default:steelblock"}, {["x"] = 3, ["y"] = 6, ["z"] = 4, ["name"] = "default:steelblock"}, {["x"] = 3, ["y"] = 6, ["z"] = 5, ["name"] = "default:steelblock"}, {["x"] = 3, ["y"] = 6, ["z"] = 6, ["name"] = "default:steelblock"}, {["x"] = 3, ["y"] = 6, ["z"] = 7, ["name"] = "default:steelblock"}, {["x"] = 3, ["y"] = 6, ["z"] = 8, ["name"] = "default:steelblock"}, {["x"] = 3, ["y"] = 6, ["z"] = 9, ["name"] = "default:steelblock"}, {["x"] = 3, ["y"] = 6, ["z"] = 10, ["name"] = "default:steelblock"}, {["x"] = 3, ["y"] = 6, ["z"] = 11, ["name"] = "default:steelblock"}, {["x"] = 3, ["y"] = 6, ["z"] = 12, ["name"] = "default:steelblock"}, {["x"] = 3, ["y"] = 6, ["z"] = 13, ["name"] = "default:steelblock"}, {["x"] = 3, ["y"] = 7, ["z"] = 2, ["name"] = "default:steelblock"}, {["x"] = 3, ["y"] = 7, ["z"] = 3, ["name"] = "default:steelblock"}, {["x"] = 3, ["y"] = 7, ["z"] = 4, ["name"] = "default:steelblock"}, {["x"] = 3, ["y"] = 7, ["z"] = 5, ["name"] = "default:steelblock"}, {["x"] = 3, ["y"] = 7, ["z"] = 6, ["name"] = "default:steelblock"}, {["x"] = 3, ["y"] = 7, ["z"] = 7, ["name"] = "default:steelblock"}, {["x"] = 3, ["y"] = 7, ["z"] = 8, ["name"] = "default:steelblock"}, {["x"] = 3, ["y"] = 7, ["z"] = 9, ["name"] = "default:steelblock"}, {["x"] = 3, ["y"] = 7, ["z"] = 10, ["name"] = "default:steelblock"}, {["x"] = 3, ["y"] = 7, ["z"] = 11, ["name"] = "default:steelblock"}, {["x"] = 3, ["y"] = 7, ["z"] = 12, ["name"] = "default:steelblock"}, {["x"] = 3, ["y"] = 7, ["z"] = 13, ["name"] = "default:steelblock"}, {["x"] = 3, ["y"] = 7, ["z"] = 14, ["name"] = "wool:grey"}, {["x"] = 3, ["y"] = 8, ["z"] = 2, ["name"] = "default:steelblock"}, {["x"] = 3, ["y"] = 8, ["z"] = 3, ["name"] = "default:steelblock"}, {["x"] = 3, ["y"] = 8, ["z"] = 4, ["name"] = "default:steelblock"}, {["x"] = 3, ["y"] = 8, ["z"] = 5, ["name"] = "default:steelblock"}, {["x"] = 3, ["y"] = 8, ["z"] = 6, ["name"] = "default:steelblock"}, {["x"] = 3, ["y"] = 8, ["z"] = 7, ["name"] = "default:steelblock"}, {["x"] = 3, ["y"] = 8, ["z"] = 8, ["name"] = "default:steelblock"}, {["x"] = 3, ["y"] = 8, ["z"] = 9, ["name"] = "default:steelblock"}, {["x"] = 3, ["y"] = 8, ["z"] = 14, ["name"] = "wool:grey"}, {["x"] = 3, ["y"] = 9, ["z"] = 1, ["name"] = "wool:grey"}, {["x"] = 3, ["y"] = 9, ["z"] = 2, ["name"] = "default:steelblock"}, {["x"] = 3, ["y"] = 9, ["z"] = 3, ["name"] = "default:steelblock"}, {["x"] = 3, ["y"] = 9, ["z"] = 4, ["name"] = "default:steelblock"}, {["x"] = 3, ["y"] = 9, ["z"] = 5, ["name"] = "default:steelblock"}, {["x"] = 3, ["y"] = 9, ["z"] = 6, ["name"] = "default:steelblock"}, {["x"] = 3, ["y"] = 9, ["z"] = 7, ["name"] = "default:steelblock"}, {["x"] = 3, ["y"] = 9, ["z"] = 8, ["name"] = "default:steelblock"}, {["x"] = 3, ["y"] = 9, ["z"] = 9, ["name"] = "default:steelblock"}, {["x"] = 3, ["y"] = 10, ["z"] = 1, ["name"] = "wool:grey"}, {["x"] = 3, ["y"] = 10, ["z"] = 2, ["name"] = "default:steelblock"}, {["x"] = 3, ["y"] = 10, ["z"] = 3, ["name"] = "default:steelblock"}, {["x"] = 3, ["y"] = 10, ["z"] = 4, ["name"] = "default:steelblock"}, {["x"] = 3, ["y"] = 10, ["z"] = 5, ["name"] = "default:steelblock"}, {["x"] = 3, ["y"] = 10, ["z"] = 6, ["name"] = "default:steelblock"}, {["x"] = 3, ["y"] = 10, ["z"] = 7, ["name"] = "default:steelblock"}, {["x"] = 3, ["y"] = 10, ["z"] = 8, ["name"] = "default:steelblock"}, {["x"] = 3, ["y"] = 10, ["z"] = 9, ["name"] = "default:steelblock"}, {["x"] = 3, ["y"] = 11, ["z"] = 2, ["name"] = "default:steelblock"}, {["x"] = 3, ["y"] = 11, ["z"] = 3, ["name"] = "default:steelblock"}, {["x"] = 3, ["y"] = 11, ["z"] = 4, ["name"] = "default:steelblock"}, {["x"] = 3, ["y"] = 11, ["z"] = 5, ["name"] = "default:steelblock"}, {["x"] = 3, ["y"] = 11, ["z"] = 6, ["name"] = "default:steelblock"}, {["x"] = 3, ["y"] = 11, ["z"] = 7, ["name"] = "default:steelblock"}, {["x"] = 3, ["y"] = 11, ["z"] = 8, ["name"] = "default:steelblock"}, {["x"] = 3, ["y"] = 11, ["z"] = 9, ["name"] = "default:steelblock"}, {["x"] = 4, ["y"] = 1, ["z"] = 2, ["name"] = "default:steelblock"}, {["x"] = 4, ["y"] = 1, ["z"] = 3, ["name"] = "default:steelblock"}, {["x"] = 4, ["y"] = 1, ["z"] = 4, ["name"] = "default:steelblock"}, {["x"] = 4, ["y"] = 1, ["z"] = 5, ["name"] = "default:steelblock"}, {["x"] = 4, ["y"] = 1, ["z"] = 6, ["name"] = "default:steelblock"}, {["x"] = 4, ["y"] = 1, ["z"] = 7, ["name"] = "default:steelblock"}, {["x"] = 4, ["y"] = 1, ["z"] = 8, ["name"] = "default:steelblock"}, {["x"] = 4, ["y"] = 1, ["z"] = 9, ["name"] = "default:steelblock"}, {["x"] = 4, ["y"] = 1, ["z"] = 10, ["name"] = "default:steelblock"}, {["x"] = 4, ["y"] = 1, ["z"] = 11, ["name"] = "default:steelblock"}, {["x"] = 4, ["y"] = 1, ["z"] = 12, ["name"] = "default:steelblock"}, {["x"] = 4, ["y"] = 1, ["z"] = 13, ["name"] = "default:steelblock"}, {["x"] = 4, ["y"] = 2, ["z"] = 1, ["name"] = "wool:grey"}, {["x"] = 4, ["y"] = 2, ["z"] = 2, ["name"] = "default:steelblock"}, {["x"] = 4, ["y"] = 2, ["z"] = 3, ["name"] = "default:steelblock"}, {["x"] = 4, ["y"] = 2, ["z"] = 4, ["name"] = "default:steelblock"}, {["x"] = 4, ["y"] = 2, ["z"] = 5, ["name"] = "default:steelblock"}, {["x"] = 4, ["y"] = 2, ["z"] = 6, ["name"] = "default:steelblock"}, {["x"] = 4, ["y"] = 2, ["z"] = 7, ["name"] = "default:steelblock"}, {["x"] = 4, ["y"] = 2, ["z"] = 8, ["name"] = "default:steelblock"}, {["x"] = 4, ["y"] = 2, ["z"] = 9, ["name"] = "default:steelblock"}, {["x"] = 4, ["y"] = 2, ["z"] = 10, ["name"] = "default:steelblock"}, {["x"] = 4, ["y"] = 2, ["z"] = 11, ["name"] = "default:steelblock"}, {["x"] = 4, ["y"] = 2, ["z"] = 12, ["name"] = "default:steelblock"}, {["x"] = 4, ["y"] = 2, ["z"] = 13, ["name"] = "default:steelblock"}, {["x"] = 4, ["y"] = 3, ["z"] = 1, ["name"] = "wool:grey"}, {["x"] = 4, ["y"] = 3, ["z"] = 2, ["name"] = "default:steelblock"}, {["x"] = 4, ["y"] = 3, ["z"] = 3, ["name"] = "default:steelblock"}, {["x"] = 4, ["y"] = 3, ["z"] = 4, ["name"] = "default:steelblock"}, {["x"] = 4, ["y"] = 3, ["z"] = 5, ["name"] = "default:steelblock"}, {["x"] = 4, ["y"] = 3, ["z"] = 6, ["name"] = "default:steelblock"}, {["x"] = 4, ["y"] = 3, ["z"] = 7, ["name"] = "default:steelblock"}, {["x"] = 4, ["y"] = 3, ["z"] = 8, ["name"] = "default:steelblock"}, {["x"] = 4, ["y"] = 3, ["z"] = 9, ["name"] = "default:steelblock"}, {["x"] = 4, ["y"] = 3, ["z"] = 10, ["name"] = "default:steelblock"}, {["x"] = 4, ["y"] = 3, ["z"] = 11, ["name"] = "default:steelblock"}, {["x"] = 4, ["y"] = 3, ["z"] = 12, ["name"] = "default:steelblock"}, {["x"] = 4, ["y"] = 3, ["z"] = 13, ["name"] = "default:steelblock"}, {["x"] = 4, ["y"] = 4, ["z"] = 2, ["name"] = "default:steelblock"}, {["x"] = 4, ["y"] = 4, ["z"] = 3, ["name"] = "default:steelblock"}, {["x"] = 4, ["y"] = 4, ["z"] = 4, ["name"] = "default:steelblock"}, {["x"] = 4, ["y"] = 4, ["z"] = 5, ["name"] = "default:steelblock"}, {["x"] = 4, ["y"] = 4, ["z"] = 6, ["name"] = "default:steelblock"}, {["x"] = 4, ["y"] = 4, ["z"] = 7, ["name"] = "default:steelblock"}, {["x"] = 4, ["y"] = 4, ["z"] = 8, ["name"] = "default:steelblock"}, {["x"] = 4, ["y"] = 4, ["z"] = 9, ["name"] = "default:steelblock"}, {["x"] = 4, ["y"] = 4, ["z"] = 10, ["name"] = "default:steelblock"}, {["x"] = 4, ["y"] = 4, ["z"] = 11, ["name"] = "default:steelblock"}, {["x"] = 4, ["y"] = 4, ["z"] = 12, ["name"] = "default:steelblock"}, {["x"] = 4, ["y"] = 4, ["z"] = 13, ["name"] = "default:steelblock"}, {["x"] = 4, ["y"] = 5, ["z"] = 2, ["name"] = "default:steelblock"}, {["x"] = 4, ["y"] = 5, ["z"] = 3, ["name"] = "default:steelblock"}, {["x"] = 4, ["y"] = 5, ["z"] = 4, ["name"] = "default:steelblock"}, {["x"] = 4, ["y"] = 5, ["z"] = 5, ["name"] = "default:steelblock"}, {["x"] = 4, ["y"] = 5, ["z"] = 6, ["name"] = "default:steelblock"}, {["x"] = 4, ["y"] = 5, ["z"] = 7, ["name"] = "default:steelblock"}, {["x"] = 4, ["y"] = 5, ["z"] = 8, ["name"] = "default:steelblock"}, {["x"] = 4, ["y"] = 5, ["z"] = 9, ["name"] = "default:steelblock"}, {["x"] = 4, ["y"] = 5, ["z"] = 10, ["name"] = "default:steelblock"}, {["x"] = 4, ["y"] = 5, ["z"] = 11, ["name"] = "default:steelblock"}, {["x"] = 4, ["y"] = 5, ["z"] = 12, ["name"] = "default:steelblock"}, {["x"] = 4, ["y"] = 5, ["z"] = 13, ["name"] = "default:steelblock"}, {["x"] = 4, ["y"] = 6, ["z"] = 2, ["name"] = "default:steelblock"}, {["x"] = 4, ["y"] = 6, ["z"] = 3, ["name"] = "default:steelblock"}, {["x"] = 4, ["y"] = 6, ["z"] = 4, ["name"] = "default:steelblock"}, {["x"] = 4, ["y"] = 6, ["z"] = 5, ["name"] = "default:steelblock"}, {["x"] = 4, ["y"] = 6, ["z"] = 6, ["name"] = "default:steelblock"}, {["x"] = 4, ["y"] = 6, ["z"] = 7, ["name"] = "default:steelblock"}, {["x"] = 4, ["y"] = 6, ["z"] = 8, ["name"] = "default:steelblock"}, {["x"] = 4, ["y"] = 6, ["z"] = 9, ["name"] = "default:steelblock"}, {["x"] = 4, ["y"] = 6, ["z"] = 10, ["name"] = "default:steelblock"}, {["x"] = 4, ["y"] = 6, ["z"] = 11, ["name"] = "default:steelblock"}, {["x"] = 4, ["y"] = 6, ["z"] = 12, ["name"] = "default:steelblock"}, {["x"] = 4, ["y"] = 6, ["z"] = 13, ["name"] = "default:steelblock"}, {["x"] = 4, ["y"] = 7, ["z"] = 2, ["name"] = "default:steelblock"}, {["x"] = 4, ["y"] = 7, ["z"] = 3, ["name"] = "default:steelblock"}, {["x"] = 4, ["y"] = 7, ["z"] = 4, ["name"] = "default:steelblock"}, {["x"] = 4, ["y"] = 7, ["z"] = 5, ["name"] = "default:steelblock"}, {["x"] = 4, ["y"] = 7, ["z"] = 6, ["name"] = "default:steelblock"}, {["x"] = 4, ["y"] = 7, ["z"] = 7, ["name"] = "default:steelblock"}, {["x"] = 4, ["y"] = 7, ["z"] = 8, ["name"] = "default:steelblock"}, {["x"] = 4, ["y"] = 7, ["z"] = 9, ["name"] = "default:steelblock"}, {["x"] = 4, ["y"] = 7, ["z"] = 10, ["name"] = "default:steelblock"}, {["x"] = 4, ["y"] = 7, ["z"] = 11, ["name"] = "default:steelblock"}, {["x"] = 4, ["y"] = 7, ["z"] = 12, ["name"] = "default:steelblock"}, {["x"] = 4, ["y"] = 7, ["z"] = 13, ["name"] = "default:steelblock"}, {["x"] = 4, ["y"] = 7, ["z"] = 14, ["name"] = "wool:grey"}, {["x"] = 4, ["y"] = 8, ["z"] = 2, ["name"] = "default:steelblock"}, {["x"] = 4, ["y"] = 8, ["z"] = 3, ["name"] = "default:steelblock"}, {["x"] = 4, ["y"] = 8, ["z"] = 4, ["name"] = "default:steelblock"}, {["x"] = 4, ["y"] = 8, ["z"] = 5, ["name"] = "default:steelblock"}, {["x"] = 4, ["y"] = 8, ["z"] = 6, ["name"] = "default:steelblock"}, {["x"] = 4, ["y"] = 8, ["z"] = 7, ["name"] = "default:steelblock"}, {["x"] = 4, ["y"] = 8, ["z"] = 8, ["name"] = "default:steelblock"}, {["x"] = 4, ["y"] = 8, ["z"] = 9, ["name"] = "default:steelblock"}, {["x"] = 4, ["y"] = 8, ["z"] = 10, ["name"] = "default:steelblock"}, {["x"] = 4, ["y"] = 8, ["z"] = 11, ["name"] = "default:steelblock"}, {["x"] = 4, ["y"] = 8, ["z"] = 12, ["name"] = "default:steelblock"}, {["x"] = 4, ["y"] = 8, ["z"] = 13, ["name"] = "default:steelblock"}, {["x"] = 4, ["y"] = 8, ["z"] = 14, ["name"] = "wool:grey"}, {["x"] = 4, ["y"] = 9, ["z"] = 1, ["name"] = "wool:grey"}, {["x"] = 4, ["y"] = 9, ["z"] = 2, ["name"] = "default:steelblock"}, {["x"] = 4, ["y"] = 9, ["z"] = 3, ["name"] = "default:steelblock"}, {["x"] = 4, ["y"] = 9, ["z"] = 4, ["name"] = "default:steelblock"}, {["x"] = 4, ["y"] = 9, ["z"] = 5, ["name"] = "default:steelblock"}, {["x"] = 4, ["y"] = 9, ["z"] = 6, ["name"] = "default:steelblock"}, {["x"] = 4, ["y"] = 9, ["z"] = 7, ["name"] = "default:steelblock"}, {["x"] = 4, ["y"] = 9, ["z"] = 8, ["name"] = "default:steelblock"}, {["x"] = 4, ["y"] = 9, ["z"] = 9, ["name"] = "default:steelblock"}, {["x"] = 4, ["y"] = 10, ["z"] = 1, ["name"] = "wool:grey"}, {["x"] = 4, ["y"] = 10, ["z"] = 2, ["name"] = "default:steelblock"}, {["x"] = 4, ["y"] = 10, ["z"] = 3, ["name"] = "default:steelblock"}, {["x"] = 4, ["y"] = 10, ["z"] = 4, ["name"] = "default:steelblock"}, {["x"] = 4, ["y"] = 10, ["z"] = 5, ["name"] = "default:steelblock"}, {["x"] = 4, ["y"] = 10, ["z"] = 6, ["name"] = "default:steelblock"}, {["x"] = 4, ["y"] = 10, ["z"] = 7, ["name"] = "default:steelblock"}, {["x"] = 4, ["y"] = 10, ["z"] = 8, ["name"] = "default:steelblock"}, {["x"] = 4, ["y"] = 10, ["z"] = 9, ["name"] = "default:steelblock"}, {["x"] = 4, ["y"] = 11, ["z"] = 2, ["name"] = "default:steelblock"}, {["x"] = 4, ["y"] = 11, ["z"] = 3, ["name"] = "default:steelblock"}, {["x"] = 4, ["y"] = 11, ["z"] = 4, ["name"] = "default:steelblock"}, {["x"] = 4, ["y"] = 11, ["z"] = 5, ["name"] = "default:steelblock"}, {["x"] = 4, ["y"] = 11, ["z"] = 6, ["name"] = "default:steelblock"}, {["x"] = 4, ["y"] = 11, ["z"] = 7, ["name"] = "default:steelblock"}, {["x"] = 4, ["y"] = 11, ["z"] = 8, ["name"] = "default:steelblock"}, {["x"] = 4, ["y"] = 11, ["z"] = 9, ["name"] = "default:steelblock"}, {["x"] = 4, ["y"] = 12, ["z"] = 2, ["name"] = "default:steelblock"}, {["x"] = 4, ["y"] = 12, ["z"] = 3, ["name"] = "default:steelblock"}, {["x"] = 4, ["y"] = 12, ["z"] = 4, ["name"] = "default:steelblock"}, {["x"] = 4, ["y"] = 12, ["z"] = 5, ["name"] = "default:steelblock"}, {["x"] = 4, ["y"] = 12, ["z"] = 6, ["name"] = "default:steelblock"}, {["x"] = 4, ["y"] = 12, ["z"] = 7, ["name"] = "default:steelblock"}, {["x"] = 4, ["y"] = 12, ["z"] = 8, ["name"] = "default:steelblock"}, {["x"] = 4, ["y"] = 12, ["z"] = 9, ["name"] = "default:steelblock"}, {["x"] = 5, ["y"] = 0, ["z"] = 2, ["name"] = "default:steelblock"}, {["x"] = 5, ["y"] = 0, ["z"] = 3, ["name"] = "default:steelblock"}, {["x"] = 5, ["y"] = 0, ["z"] = 4, ["name"] = "default:steelblock"}, {["x"] = 5, ["y"] = 0, ["z"] = 5, ["name"] = "default:steelblock"}, {["x"] = 5, ["y"] = 0, ["z"] = 6, ["name"] = "default:steelblock"}, {["x"] = 5, ["y"] = 0, ["z"] = 7, ["name"] = "default:steelblock"}, {["x"] = 5, ["y"] = 0, ["z"] = 8, ["name"] = "default:steelblock"}, {["x"] = 5, ["y"] = 0, ["z"] = 9, ["name"] = "default:steelblock"}, {["x"] = 5, ["y"] = 0, ["z"] = 10, ["name"] = "default:steelblock"}, {["x"] = 5, ["y"] = 0, ["z"] = 11, ["name"] = "default:steelblock"}, {["x"] = 5, ["y"] = 0, ["z"] = 12, ["name"] = "default:steelblock"}, {["x"] = 5, ["y"] = 0, ["z"] = 13, ["name"] = "default:steelblock"}, {["x"] = 5, ["y"] = 1, ["z"] = 2, ["name"] = "default:steelblock"}, {["x"] = 5, ["y"] = 1, ["z"] = 3, ["name"] = "default:steelblock"}, {["x"] = 5, ["y"] = 1, ["z"] = 4, ["name"] = "default:steelblock"}, {["x"] = 5, ["y"] = 1, ["z"] = 5, ["name"] = "default:steelblock"}, {["x"] = 5, ["y"] = 1, ["z"] = 6, ["name"] = "default:steelblock"}, {["x"] = 5, ["y"] = 1, ["z"] = 7, ["name"] = "default:steelblock"}, {["x"] = 5, ["y"] = 1, ["z"] = 8, ["name"] = "default:steelblock"}, {["x"] = 5, ["y"] = 1, ["z"] = 9, ["name"] = "default:steelblock"}, {["x"] = 5, ["y"] = 1, ["z"] = 10, ["name"] = "default:steelblock"}, {["x"] = 5, ["y"] = 1, ["z"] = 11, ["name"] = "default:steelblock"}, {["x"] = 5, ["y"] = 1, ["z"] = 12, ["name"] = "default:steelblock"}, {["x"] = 5, ["y"] = 1, ["z"] = 13, ["name"] = "default:steelblock"}, {["x"] = 5, ["y"] = 2, ["z"] = 1, ["name"] = "wool:grey"}, {["x"] = 5, ["y"] = 2, ["z"] = 2, ["name"] = "default:steelblock"}, {["x"] = 5, ["y"] = 2, ["z"] = 3, ["name"] = "default:steelblock"}, {["x"] = 5, ["y"] = 2, ["z"] = 4, ["name"] = "default:steelblock"}, {["x"] = 5, ["y"] = 2, ["z"] = 5, ["name"] = "default:steelblock"}, {["x"] = 5, ["y"] = 2, ["z"] = 6, ["name"] = "default:steelblock"}, {["x"] = 5, ["y"] = 2, ["z"] = 7, ["name"] = "default:steelblock"}, {["x"] = 5, ["y"] = 2, ["z"] = 8, ["name"] = "default:steelblock"}, {["x"] = 5, ["y"] = 2, ["z"] = 9, ["name"] = "default:steelblock"}, {["x"] = 5, ["y"] = 2, ["z"] = 10, ["name"] = "default:steelblock"}, {["x"] = 5, ["y"] = 2, ["z"] = 11, ["name"] = "default:steelblock"}, {["x"] = 5, ["y"] = 2, ["z"] = 12, ["name"] = "default:steelblock"}, {["x"] = 5, ["y"] = 2, ["z"] = 13, ["name"] = "default:steelblock"}, {["x"] = 5, ["y"] = 3, ["z"] = 1, ["name"] = "wool:grey"}, {["x"] = 5, ["y"] = 3, ["z"] = 2, ["name"] = "default:steelblock"}, {["x"] = 5, ["y"] = 3, ["z"] = 3, ["name"] = "default:steelblock"}, {["x"] = 5, ["y"] = 3, ["z"] = 4, ["name"] = "default:steelblock"}, {["x"] = 5, ["y"] = 3, ["z"] = 5, ["name"] = "default:steelblock"}, {["x"] = 5, ["y"] = 3, ["z"] = 6, ["name"] = "default:steelblock"}, {["x"] = 5, ["y"] = 3, ["z"] = 7, ["name"] = "default:steelblock"}, {["x"] = 5, ["y"] = 3, ["z"] = 8, ["name"] = "default:steelblock"}, {["x"] = 5, ["y"] = 3, ["z"] = 9, ["name"] = "default:steelblock"}, {["x"] = 5, ["y"] = 3, ["z"] = 10, ["name"] = "default:steelblock"}, {["x"] = 5, ["y"] = 3, ["z"] = 11, ["name"] = "default:steelblock"}, {["x"] = 5, ["y"] = 3, ["z"] = 12, ["name"] = "default:steelblock"}, {["x"] = 5, ["y"] = 3, ["z"] = 13, ["name"] = "default:steelblock"}, {["x"] = 5, ["y"] = 4, ["z"] = 2, ["name"] = "default:steelblock"}, {["x"] = 5, ["y"] = 4, ["z"] = 3, ["name"] = "default:steelblock"}, {["x"] = 5, ["y"] = 4, ["z"] = 4, ["name"] = "default:steelblock"}, {["x"] = 5, ["y"] = 4, ["z"] = 5, ["name"] = "default:steelblock"}, {["x"] = 5, ["y"] = 4, ["z"] = 6, ["name"] = "default:steelblock"}, {["x"] = 5, ["y"] = 4, ["z"] = 7, ["name"] = "default:steelblock"}, {["x"] = 5, ["y"] = 4, ["z"] = 8, ["name"] = "default:steelblock"}, {["x"] = 5, ["y"] = 4, ["z"] = 9, ["name"] = "default:steelblock"}, {["x"] = 5, ["y"] = 4, ["z"] = 10, ["name"] = "default:steelblock"}, {["x"] = 5, ["y"] = 4, ["z"] = 11, ["name"] = "default:steelblock"}, {["x"] = 5, ["y"] = 4, ["z"] = 12, ["name"] = "default:steelblock"}, {["x"] = 5, ["y"] = 4, ["z"] = 13, ["name"] = "default:steelblock"}, {["x"] = 5, ["y"] = 5, ["z"] = 2, ["name"] = "default:steelblock"}, {["x"] = 5, ["y"] = 5, ["z"] = 3, ["name"] = "default:steelblock"}, {["x"] = 5, ["y"] = 5, ["z"] = 4, ["name"] = "default:steelblock"}, {["x"] = 5, ["y"] = 5, ["z"] = 5, ["name"] = "default:steelblock"}, {["x"] = 5, ["y"] = 5, ["z"] = 6, ["name"] = "default:steelblock"}, {["x"] = 5, ["y"] = 5, ["z"] = 7, ["name"] = "default:steelblock"}, {["x"] = 5, ["y"] = 5, ["z"] = 8, ["name"] = "default:steelblock"}, {["x"] = 5, ["y"] = 5, ["z"] = 9, ["name"] = "default:steelblock"}, {["x"] = 5, ["y"] = 5, ["z"] = 10, ["name"] = "default:steelblock"}, {["x"] = 5, ["y"] = 5, ["z"] = 11, ["name"] = "default:steelblock"}, {["x"] = 5, ["y"] = 5, ["z"] = 12, ["name"] = "default:steelblock"}, {["x"] = 5, ["y"] = 5, ["z"] = 13, ["name"] = "default:steelblock"}, {["x"] = 5, ["y"] = 6, ["z"] = 2, ["name"] = "default:steelblock"}, {["x"] = 5, ["y"] = 6, ["z"] = 3, ["name"] = "default:steelblock"}, {["x"] = 5, ["y"] = 6, ["z"] = 4, ["name"] = "default:steelblock"}, {["x"] = 5, ["y"] = 6, ["z"] = 5, ["name"] = "default:steelblock"}, {["x"] = 5, ["y"] = 6, ["z"] = 6, ["name"] = "default:steelblock"}, {["x"] = 5, ["y"] = 6, ["z"] = 7, ["name"] = "default:steelblock"}, {["x"] = 5, ["y"] = 6, ["z"] = 8, ["name"] = "default:steelblock"}, {["x"] = 5, ["y"] = 6, ["z"] = 9, ["name"] = "default:steelblock"}, {["x"] = 5, ["y"] = 6, ["z"] = 10, ["name"] = "default:steelblock"}, {["x"] = 5, ["y"] = 6, ["z"] = 11, ["name"] = "default:steelblock"}, {["x"] = 5, ["y"] = 6, ["z"] = 12, ["name"] = "default:steelblock"}, {["x"] = 5, ["y"] = 6, ["z"] = 13, ["name"] = "default:steelblock"}, {["x"] = 5, ["y"] = 7, ["z"] = 2, ["name"] = "default:steelblock"}, {["x"] = 5, ["y"] = 7, ["z"] = 3, ["name"] = "default:steelblock"}, {["x"] = 5, ["y"] = 7, ["z"] = 4, ["name"] = "default:steelblock"}, {["x"] = 5, ["y"] = 7, ["z"] = 5, ["name"] = "default:steelblock"}, {["x"] = 5, ["y"] = 7, ["z"] = 6, ["name"] = "default:steelblock"}, {["x"] = 5, ["y"] = 7, ["z"] = 7, ["name"] = "default:steelblock"}, {["x"] = 5, ["y"] = 7, ["z"] = 8, ["name"] = "default:steelblock"}, {["x"] = 5, ["y"] = 7, ["z"] = 9, ["name"] = "default:steelblock"}, {["x"] = 5, ["y"] = 7, ["z"] = 10, ["name"] = "default:steelblock"}, {["x"] = 5, ["y"] = 7, ["z"] = 11, ["name"] = "default:steelblock"}, {["x"] = 5, ["y"] = 7, ["z"] = 12, ["name"] = "default:steelblock"}, {["x"] = 5, ["y"] = 7, ["z"] = 13, ["name"] = "default:steelblock"}, {["x"] = 5, ["y"] = 7, ["z"] = 14, ["name"] = "wool:grey"}, {["x"] = 5, ["y"] = 8, ["z"] = 2, ["name"] = "default:steelblock"}, {["x"] = 5, ["y"] = 8, ["z"] = 3, ["name"] = "default:steelblock"}, {["x"] = 5, ["y"] = 8, ["z"] = 4, ["name"] = "default:steelblock"}, {["x"] = 5, ["y"] = 8, ["z"] = 5, ["name"] = "default:steelblock"}, {["x"] = 5, ["y"] = 8, ["z"] = 6, ["name"] = "default:steelblock"}, {["x"] = 5, ["y"] = 8, ["z"] = 7, ["name"] = "default:steelblock"}, {["x"] = 5, ["y"] = 8, ["z"] = 8, ["name"] = "default:steelblock"}, {["x"] = 5, ["y"] = 8, ["z"] = 9, ["name"] = "default:steelblock"}, {["x"] = 5, ["y"] = 8, ["z"] = 10, ["name"] = "default:steelblock"}, {["x"] = 5, ["y"] = 8, ["z"] = 11, ["name"] = "default:steelblock"}, {["x"] = 5, ["y"] = 8, ["z"] = 12, ["name"] = "default:steelblock"}, {["x"] = 5, ["y"] = 8, ["z"] = 13, ["name"] = "default:steelblock"}, {["x"] = 5, ["y"] = 8, ["z"] = 14, ["name"] = "wool:grey"}, {["x"] = 5, ["y"] = 9, ["z"] = 1, ["name"] = "wool:grey"}, {["x"] = 5, ["y"] = 9, ["z"] = 2, ["name"] = "default:steelblock"}, {["x"] = 5, ["y"] = 9, ["z"] = 3, ["name"] = "default:steelblock"}, {["x"] = 5, ["y"] = 9, ["z"] = 4, ["name"] = "default:steelblock"}, {["x"] = 5, ["y"] = 9, ["z"] = 5, ["name"] = "default:steelblock"}, {["x"] = 5, ["y"] = 9, ["z"] = 6, ["name"] = "default:steelblock"}, {["x"] = 5, ["y"] = 9, ["z"] = 7, ["name"] = "default:steelblock"}, {["x"] = 5, ["y"] = 9, ["z"] = 8, ["name"] = "default:steelblock"}, {["x"] = 5, ["y"] = 9, ["z"] = 9, ["name"] = "default:steelblock"}, {["x"] = 5, ["y"] = 9, ["z"] = 10, ["name"] = "default:steelblock"}, {["x"] = 5, ["y"] = 9, ["z"] = 11, ["name"] = "default:steelblock"}, {["x"] = 5, ["y"] = 9, ["z"] = 12, ["name"] = "default:steelblock"}, {["x"] = 5, ["y"] = 9, ["z"] = 13, ["name"] = "default:steelblock"}, {["x"] = 5, ["y"] = 10, ["z"] = 1, ["name"] = "wool:grey"}, {["x"] = 5, ["y"] = 10, ["z"] = 2, ["name"] = "default:steelblock"}, {["x"] = 5, ["y"] = 10, ["z"] = 3, ["name"] = "default:steelblock"}, {["x"] = 5, ["y"] = 10, ["z"] = 4, ["name"] = "default:steelblock"}, {["x"] = 5, ["y"] = 10, ["z"] = 5, ["name"] = "default:steelblock"}, {["x"] = 5, ["y"] = 10, ["z"] = 6, ["name"] = "default:steelblock"}, {["x"] = 5, ["y"] = 10, ["z"] = 7, ["name"] = "default:steelblock"}, {["x"] = 5, ["y"] = 10, ["z"] = 8, ["name"] = "default:steelblock"}, {["x"] = 5, ["y"] = 10, ["z"] = 9, ["name"] = "default:steelblock"}, {["x"] = 5, ["y"] = 10, ["z"] = 10, ["name"] = "default:stone"}, {["x"] = 5, ["y"] = 10, ["z"] = 11, ["name"] = "default:stone"}, {["x"] = 5, ["y"] = 10, ["z"] = 12, ["name"] = "default:stone"}, {["x"] = 5, ["y"] = 10, ["z"] = 13, ["name"] = "default:stone"}, {["x"] = 5, ["y"] = 11, ["z"] = 2, ["name"] = "default:steelblock"}, {["x"] = 5, ["y"] = 11, ["z"] = 3, ["name"] = "default:steelblock"}, {["x"] = 5, ["y"] = 11, ["z"] = 4, ["name"] = "default:steelblock"}, {["x"] = 5, ["y"] = 11, ["z"] = 5, ["name"] = "default:steelblock"}, {["x"] = 5, ["y"] = 11, ["z"] = 6, ["name"] = "default:steelblock"}, {["x"] = 5, ["y"] = 11, ["z"] = 7, ["name"] = "default:steelblock"}, {["x"] = 5, ["y"] = 11, ["z"] = 8, ["name"] = "default:steelblock"}, {["x"] = 5, ["y"] = 11, ["z"] = 9, ["name"] = "default:steelblock"}, {["x"] = 5, ["y"] = 11, ["z"] = 10, ["name"] = "default:stone"}, {["x"] = 5, ["y"] = 11, ["z"] = 11, ["name"] = "default:stone"}, {["x"] = 5, ["y"] = 11, ["z"] = 12, ["name"] = "default:stone"}, {["x"] = 5, ["y"] = 11, ["z"] = 13, ["name"] = "default:stone"}, {["x"] = 5, ["y"] = 12, ["z"] = 2, ["name"] = "default:steelblock"}, {["x"] = 5, ["y"] = 12, ["z"] = 3, ["name"] = "default:steelblock"}, {["x"] = 5, ["y"] = 12, ["z"] = 4, ["name"] = "default:steelblock"}, {["x"] = 5, ["y"] = 12, ["z"] = 5, ["name"] = "default:steelblock"}, {["x"] = 5, ["y"] = 12, ["z"] = 6, ["name"] = "default:steelblock"}, {["x"] = 5, ["y"] = 12, ["z"] = 7, ["name"] = "default:steelblock"}, {["x"] = 5, ["y"] = 12, ["z"] = 8, ["name"] = "default:steelblock"}, {["x"] = 5, ["y"] = 12, ["z"] = 9, ["name"] = "default:steelblock"}, {["x"] = 5, ["y"] = 12, ["z"] = 10, ["name"] = "default:stone"}, {["x"] = 5, ["y"] = 12, ["z"] = 11, ["name"] = "default:stone"}, {["x"] = 5, ["y"] = 12, ["z"] = 12, ["name"] = "default:stone"}, {["x"] = 5, ["y"] = 12, ["z"] = 13, ["name"] = "default:stone"}, {["x"] = 5, ["y"] = 13, ["z"] = 2, ["name"] = "default:steelblock"}, {["x"] = 5, ["y"] = 13, ["z"] = 3, ["name"] = "default:steelblock"}, {["x"] = 5, ["y"] = 13, ["z"] = 4, ["name"] = "default:steelblock"}, {["x"] = 5, ["y"] = 13, ["z"] = 5, ["name"] = "default:steelblock"}, {["x"] = 5, ["y"] = 13, ["z"] = 6, ["name"] = "default:steelblock"}, {["x"] = 5, ["y"] = 13, ["z"] = 7, ["name"] = "default:steelblock"}, {["x"] = 5, ["y"] = 13, ["z"] = 8, ["name"] = "default:steelblock"}, {["x"] = 5, ["y"] = 13, ["z"] = 9, ["name"] = "default:steelblock"}, {["x"] = 5, ["y"] = 13, ["z"] = 10, ["name"] = "default:stone"}, {["x"] = 5, ["y"] = 13, ["z"] = 11, ["name"] = "default:stone"}, {["x"] = 5, ["y"] = 13, ["z"] = 12, ["name"] = "default:stone"}, {["x"] = 5, ["y"] = 13, ["z"] = 13, ["name"] = "default:stone"}, {["x"] = 5, ["y"] = 14, ["z"] = 10, ["name"] = "default:stone"}, {["x"] = 5, ["y"] = 14, ["z"] = 11, ["name"] = "default:stone"}, {["x"] = 5, ["y"] = 14, ["z"] = 12, ["name"] = "default:stone"}, {["x"] = 5, ["y"] = 14, ["z"] = 13, ["name"] = "default:stone"}, {["x"] = 5, ["y"] = 15, ["z"] = 10, ["name"] = "default:stone"}, {["x"] = 5, ["y"] = 15, ["z"] = 11, ["name"] = "default:stone"}, {["x"] = 5, ["y"] = 15, ["z"] = 12, ["name"] = "default:stone"}, {["x"] = 5, ["y"] = 15, ["z"] = 13, ["name"] = "default:stone"}, {["x"] = 6, ["y"] = 0, ["z"] = 2, ["name"] = "default:steelblock"}, {["x"] = 6, ["y"] = 0, ["z"] = 3, ["name"] = "default:steelblock"}, {["x"] = 6, ["y"] = 0, ["z"] = 4, ["name"] = "default:steelblock"}, {["x"] = 6, ["y"] = 0, ["z"] = 5, ["name"] = "default:steelblock"}, {["x"] = 6, ["y"] = 0, ["z"] = 6, ["name"] = "default:steelblock"}, {["x"] = 6, ["y"] = 0, ["z"] = 7, ["name"] = "default:steelblock"}, {["x"] = 6, ["y"] = 0, ["z"] = 8, ["name"] = "default:steelblock"}, {["x"] = 6, ["y"] = 0, ["z"] = 9, ["name"] = "default:steelblock"}, {["x"] = 6, ["y"] = 0, ["z"] = 10, ["name"] = "default:steelblock"}, {["x"] = 6, ["y"] = 0, ["z"] = 11, ["name"] = "default:steelblock"}, {["x"] = 6, ["y"] = 0, ["z"] = 12, ["name"] = "default:steelblock"}, {["x"] = 6, ["y"] = 0, ["z"] = 13, ["name"] = "default:steelblock"}, {["x"] = 6, ["y"] = 1, ["z"] = 2, ["name"] = "default:steelblock"}, {["x"] = 6, ["y"] = 1, ["z"] = 3, ["name"] = "default:steelblock"}, {["x"] = 6, ["y"] = 1, ["z"] = 4, ["name"] = "default:steelblock"}, {["x"] = 6, ["y"] = 1, ["z"] = 5, ["name"] = "default:steelblock"}, {["x"] = 6, ["y"] = 1, ["z"] = 6, ["name"] = "default:steelblock"}, {["x"] = 6, ["y"] = 1, ["z"] = 7, ["name"] = "default:steelblock"}, {["x"] = 6, ["y"] = 1, ["z"] = 8, ["name"] = "default:steelblock"}, {["x"] = 6, ["y"] = 1, ["z"] = 9, ["name"] = "default:steelblock"}, {["x"] = 6, ["y"] = 1, ["z"] = 10, ["name"] = "default:steelblock"}, {["x"] = 6, ["y"] = 1, ["z"] = 11, ["name"] = "default:steelblock"}, {["x"] = 6, ["y"] = 1, ["z"] = 12, ["name"] = "default:steelblock"}, {["x"] = 6, ["y"] = 1, ["z"] = 13, ["name"] = "default:steelblock"}, {["x"] = 6, ["y"] = 2, ["z"] = 1, ["name"] = "wool:grey"}, {["x"] = 6, ["y"] = 2, ["z"] = 2, ["name"] = "default:steelblock"}, {["x"] = 6, ["y"] = 2, ["z"] = 3, ["name"] = "default:steelblock"}, {["x"] = 6, ["y"] = 2, ["z"] = 4, ["name"] = "default:steelblock"}, {["x"] = 6, ["y"] = 2, ["z"] = 5, ["name"] = "default:steelblock"}, {["x"] = 6, ["y"] = 2, ["z"] = 6, ["name"] = "default:steelblock"}, {["x"] = 6, ["y"] = 2, ["z"] = 7, ["name"] = "default:steelblock"}, {["x"] = 6, ["y"] = 2, ["z"] = 8, ["name"] = "default:steelblock"}, {["x"] = 6, ["y"] = 2, ["z"] = 9, ["name"] = "default:steelblock"}, {["x"] = 6, ["y"] = 2, ["z"] = 10, ["name"] = "default:steelblock"}, {["x"] = 6, ["y"] = 2, ["z"] = 11, ["name"] = "default:steelblock"}, {["x"] = 6, ["y"] = 2, ["z"] = 12, ["name"] = "default:steelblock"}, {["x"] = 6, ["y"] = 2, ["z"] = 13, ["name"] = "default:steelblock"}, {["x"] = 6, ["y"] = 3, ["z"] = 1, ["name"] = "wool:grey"}, {["x"] = 6, ["y"] = 3, ["z"] = 2, ["name"] = "default:steelblock"}, {["x"] = 6, ["y"] = 3, ["z"] = 3, ["name"] = "default:steelblock"}, {["x"] = 6, ["y"] = 3, ["z"] = 4, ["name"] = "default:steelblock"}, {["x"] = 6, ["y"] = 3, ["z"] = 5, ["name"] = "default:steelblock"}, {["x"] = 6, ["y"] = 3, ["z"] = 6, ["name"] = "default:steelblock"}, {["x"] = 6, ["y"] = 3, ["z"] = 7, ["name"] = "default:steelblock"}, {["x"] = 6, ["y"] = 3, ["z"] = 8, ["name"] = "default:steelblock"}, {["x"] = 6, ["y"] = 3, ["z"] = 9, ["name"] = "default:steelblock"}, {["x"] = 6, ["y"] = 3, ["z"] = 10, ["name"] = "default:steelblock"}, {["x"] = 6, ["y"] = 3, ["z"] = 11, ["name"] = "default:steelblock"}, {["x"] = 6, ["y"] = 3, ["z"] = 12, ["name"] = "default:steelblock"}, {["x"] = 6, ["y"] = 3, ["z"] = 13, ["name"] = "default:steelblock"}, {["x"] = 6, ["y"] = 4, ["z"] = 2, ["name"] = "default:steelblock"}, {["x"] = 6, ["y"] = 4, ["z"] = 3, ["name"] = "default:steelblock"}, {["x"] = 6, ["y"] = 4, ["z"] = 4, ["name"] = "default:steelblock"}, {["x"] = 6, ["y"] = 4, ["z"] = 5, ["name"] = "default:steelblock"}, {["x"] = 6, ["y"] = 4, ["z"] = 6, ["name"] = "default:steelblock"}, {["x"] = 6, ["y"] = 4, ["z"] = 7, ["name"] = "default:steelblock"}, {["x"] = 6, ["y"] = 4, ["z"] = 8, ["name"] = "wool:yellow"}, {["x"] = 6, ["y"] = 4, ["z"] = 9, ["name"] = "wool:yellow"}, {["x"] = 6, ["y"] = 4, ["z"] = 10, ["name"] = "wool:yellow"}, {["x"] = 6, ["y"] = 4, ["z"] = 11, ["name"] = "wool:yellow"}, {["x"] = 6, ["y"] = 4, ["z"] = 12, ["name"] = "wool:yellow"}, {["x"] = 6, ["y"] = 4, ["z"] = 13, ["name"] = "wool:yellow"}, {["x"] = 6, ["y"] = 4, ["z"] = 14, ["name"] = "wool:red"}, {["x"] = 6, ["y"] = 4, ["z"] = 15, ["name"] = "wool:red"}, {["x"] = 6, ["y"] = 5, ["z"] = 2, ["name"] = "default:steelblock"}, {["x"] = 6, ["y"] = 5, ["z"] = 3, ["name"] = "default:steelblock"}, {["x"] = 6, ["y"] = 5, ["z"] = 4, ["name"] = "default:steelblock"}, {["x"] = 6, ["y"] = 5, ["z"] = 5, ["name"] = "default:steelblock"}, {["x"] = 6, ["y"] = 5, ["z"] = 6, ["name"] = "default:steelblock"}, {["x"] = 6, ["y"] = 5, ["z"] = 7, ["name"] = "default:steelblock"}, {["x"] = 6, ["y"] = 5, ["z"] = 8, ["name"] = "wool:yellow"}, {["x"] = 6, ["y"] = 5, ["z"] = 9, ["name"] = "wool:yellow"}, {["x"] = 6, ["y"] = 5, ["z"] = 10, ["name"] = "wool:yellow"}, {["x"] = 6, ["y"] = 5, ["z"] = 11, ["name"] = "wool:yellow"}, {["x"] = 6, ["y"] = 5, ["z"] = 12, ["name"] = "wool:yellow"}, {["x"] = 6, ["y"] = 5, ["z"] = 13, ["name"] = "wool:yellow"}, {["x"] = 6, ["y"] = 5, ["z"] = 14, ["name"] = "wool:red"}, {["x"] = 6, ["y"] = 5, ["z"] = 15, ["name"] = "wool:red"}, {["x"] = 6, ["y"] = 6, ["z"] = 2, ["name"] = "default:steelblock"}, {["x"] = 6, ["y"] = 6, ["z"] = 3, ["name"] = "default:steelblock"}, {["x"] = 6, ["y"] = 6, ["z"] = 4, ["name"] = "default:steelblock"}, {["x"] = 6, ["y"] = 6, ["z"] = 5, ["name"] = "default:steelblock"}, {["x"] = 6, ["y"] = 6, ["z"] = 6, ["name"] = "default:steelblock"}, {["x"] = 6, ["y"] = 6, ["z"] = 7, ["name"] = "default:steelblock"}, {["x"] = 6, ["y"] = 6, ["z"] = 8, ["name"] = "default:steelblock"}, {["x"] = 6, ["y"] = 6, ["z"] = 9, ["name"] = "default:steelblock"}, {["x"] = 6, ["y"] = 6, ["z"] = 10, ["name"] = "default:steelblock"}, {["x"] = 6, ["y"] = 6, ["z"] = 11, ["name"] = "default:steelblock"}, {["x"] = 6, ["y"] = 6, ["z"] = 12, ["name"] = "default:steelblock"}, {["x"] = 6, ["y"] = 6, ["z"] = 13, ["name"] = "default:steelblock"}, {["x"] = 6, ["y"] = 7, ["z"] = 2, ["name"] = "default:steelblock"}, {["x"] = 6, ["y"] = 7, ["z"] = 3, ["name"] = "default:steelblock"}, {["x"] = 6, ["y"] = 7, ["z"] = 4, ["name"] = "default:steelblock"}, {["x"] = 6, ["y"] = 7, ["z"] = 5, ["name"] = "default:steelblock"}, {["x"] = 6, ["y"] = 7, ["z"] = 6, ["name"] = "default:steelblock"}, {["x"] = 6, ["y"] = 7, ["z"] = 7, ["name"] = "default:steelblock"}, {["x"] = 6, ["y"] = 7, ["z"] = 8, ["name"] = "default:steelblock"}, {["x"] = 6, ["y"] = 7, ["z"] = 9, ["name"] = "default:steelblock"}, {["x"] = 6, ["y"] = 7, ["z"] = 10, ["name"] = "default:steelblock"}, {["x"] = 6, ["y"] = 7, ["z"] = 11, ["name"] = "default:steelblock"}, {["x"] = 6, ["y"] = 7, ["z"] = 12, ["name"] = "default:steelblock"}, {["x"] = 6, ["y"] = 7, ["z"] = 13, ["name"] = "default:steelblock"}, {["x"] = 6, ["y"] = 7, ["z"] = 14, ["name"] = "wool:grey"}, {["x"] = 6, ["y"] = 8, ["z"] = 2, ["name"] = "default:steelblock"}, {["x"] = 6, ["y"] = 8, ["z"] = 3, ["name"] = "default:steelblock"}, {["x"] = 6, ["y"] = 8, ["z"] = 4, ["name"] = "default:steelblock"}, {["x"] = 6, ["y"] = 8, ["z"] = 5, ["name"] = "default:steelblock"}, {["x"] = 6, ["y"] = 8, ["z"] = 6, ["name"] = "default:steelblock"}, {["x"] = 6, ["y"] = 8, ["z"] = 7, ["name"] = "default:steelblock"}, {["x"] = 6, ["y"] = 8, ["z"] = 8, ["name"] = "default:steelblock"}, {["x"] = 6, ["y"] = 8, ["z"] = 9, ["name"] = "default:steelblock"}, {["x"] = 6, ["y"] = 8, ["z"] = 10, ["name"] = "default:steelblock"}, {["x"] = 6, ["y"] = 8, ["z"] = 11, ["name"] = "default:steelblock"}, {["x"] = 6, ["y"] = 8, ["z"] = 12, ["name"] = "default:steelblock"}, {["x"] = 6, ["y"] = 8, ["z"] = 13, ["name"] = "default:steelblock"}, {["x"] = 6, ["y"] = 8, ["z"] = 14, ["name"] = "wool:grey"}, {["x"] = 6, ["y"] = 9, ["z"] = 1, ["name"] = "wool:grey"}, {["x"] = 6, ["y"] = 9, ["z"] = 2, ["name"] = "default:steelblock"}, {["x"] = 6, ["y"] = 9, ["z"] = 3, ["name"] = "default:steelblock"}, {["x"] = 6, ["y"] = 9, ["z"] = 4, ["name"] = "default:steelblock"}, {["x"] = 6, ["y"] = 9, ["z"] = 5, ["name"] = "default:steelblock"}, {["x"] = 6, ["y"] = 9, ["z"] = 6, ["name"] = "default:steelblock"}, {["x"] = 6, ["y"] = 9, ["z"] = 7, ["name"] = "default:steelblock"}, {["x"] = 6, ["y"] = 9, ["z"] = 8, ["name"] = "default:steelblock"}, {["x"] = 6, ["y"] = 9, ["z"] = 9, ["name"] = "default:steelblock"}, {["x"] = 6, ["y"] = 9, ["z"] = 10, ["name"] = "default:steelblock"}, {["x"] = 6, ["y"] = 9, ["z"] = 11, ["name"] = "default:steelblock"}, {["x"] = 6, ["y"] = 9, ["z"] = 12, ["name"] = "default:steelblock"}, {["x"] = 6, ["y"] = 9, ["z"] = 13, ["name"] = "default:steelblock"}, {["x"] = 6, ["y"] = 10, ["z"] = 1, ["name"] = "wool:grey"}, {["x"] = 6, ["y"] = 10, ["z"] = 2, ["name"] = "default:steelblock"}, {["x"] = 6, ["y"] = 10, ["z"] = 3, ["name"] = "default:steelblock"}, {["x"] = 6, ["y"] = 10, ["z"] = 4, ["name"] = "default:steelblock"}, {["x"] = 6, ["y"] = 10, ["z"] = 5, ["name"] = "default:steelblock"}, {["x"] = 6, ["y"] = 10, ["z"] = 6, ["name"] = "default:steelblock"}, {["x"] = 6, ["y"] = 10, ["z"] = 7, ["name"] = "default:steelblock"}, {["x"] = 6, ["y"] = 10, ["z"] = 8, ["name"] = "default:steelblock"}, {["x"] = 6, ["y"] = 10, ["z"] = 9, ["name"] = "default:steelblock"}, {["x"] = 6, ["y"] = 10, ["z"] = 10, ["name"] = "default:steelblock"}, {["x"] = 6, ["y"] = 10, ["z"] = 11, ["name"] = "default:steelblock"}, {["x"] = 6, ["y"] = 10, ["z"] = 12, ["name"] = "default:steelblock"}, {["x"] = 6, ["y"] = 10, ["z"] = 13, ["name"] = "default:steelblock"}, {["x"] = 6, ["y"] = 11, ["z"] = 2, ["name"] = "default:steelblock"}, {["x"] = 6, ["y"] = 11, ["z"] = 3, ["name"] = "default:steelblock"}, {["x"] = 6, ["y"] = 11, ["z"] = 4, ["name"] = "default:steelblock"}, {["x"] = 6, ["y"] = 11, ["z"] = 5, ["name"] = "default:steelblock"}, {["x"] = 6, ["y"] = 11, ["z"] = 6, ["name"] = "default:steelblock"}, {["x"] = 6, ["y"] = 11, ["z"] = 7, ["name"] = "default:steelblock"}, {["x"] = 6, ["y"] = 11, ["z"] = 8, ["name"] = "default:steelblock"}, {["x"] = 6, ["y"] = 11, ["z"] = 9, ["name"] = "default:steelblock"}, {["x"] = 6, ["y"] = 11, ["z"] = 10, ["name"] = "default:stone"}, {["x"] = 6, ["y"] = 11, ["z"] = 11, ["name"] = "default:stone"}, {["x"] = 6, ["y"] = 11, ["z"] = 12, ["name"] = "default:stone"}, {["x"] = 6, ["y"] = 11, ["z"] = 13, ["name"] = "default:stone"}, {["x"] = 6, ["y"] = 12, ["z"] = 2, ["name"] = "default:steelblock"}, {["x"] = 6, ["y"] = 12, ["z"] = 3, ["name"] = "default:steelblock"}, {["x"] = 6, ["y"] = 12, ["z"] = 4, ["name"] = "default:steelblock"}, {["x"] = 6, ["y"] = 12, ["z"] = 5, ["name"] = "default:steelblock"}, {["x"] = 6, ["y"] = 12, ["z"] = 6, ["name"] = "default:steelblock"}, {["x"] = 6, ["y"] = 12, ["z"] = 7, ["name"] = "default:steelblock"}, {["x"] = 6, ["y"] = 12, ["z"] = 8, ["name"] = "default:steelblock"}, {["x"] = 6, ["y"] = 12, ["z"] = 9, ["name"] = "default:steelblock"}, {["x"] = 6, ["y"] = 12, ["z"] = 10, ["name"] = "default:stone"}, {["x"] = 6, ["y"] = 12, ["z"] = 11, ["name"] = "default:stone"}, {["x"] = 6, ["y"] = 12, ["z"] = 12, ["name"] = "default:stone"}, {["x"] = 6, ["y"] = 12, ["z"] = 13, ["name"] = "default:stone"}, {["x"] = 6, ["y"] = 13, ["z"] = 2, ["name"] = "default:steelblock"}, {["x"] = 6, ["y"] = 13, ["z"] = 3, ["name"] = "default:steelblock"}, {["x"] = 6, ["y"] = 13, ["z"] = 4, ["name"] = "default:steelblock"}, {["x"] = 6, ["y"] = 13, ["z"] = 5, ["name"] = "default:steelblock"}, {["x"] = 6, ["y"] = 13, ["z"] = 6, ["name"] = "default:steelblock"}, {["x"] = 6, ["y"] = 13, ["z"] = 7, ["name"] = "default:steelblock"}, {["x"] = 6, ["y"] = 13, ["z"] = 8, ["name"] = "default:steelblock"}, {["x"] = 6, ["y"] = 13, ["z"] = 9, ["name"] = "default:steelblock"}, {["x"] = 6, ["y"] = 13, ["z"] = 10, ["name"] = "default:stone"}, {["x"] = 6, ["y"] = 13, ["z"] = 11, ["name"] = "default:stone"}, {["x"] = 6, ["y"] = 13, ["z"] = 12, ["name"] = "default:stone"}, {["x"] = 6, ["y"] = 13, ["z"] = 13, ["name"] = "default:stone"}, {["x"] = 6, ["y"] = 14, ["z"] = 10, ["name"] = "default:stone"}, {["x"] = 6, ["y"] = 14, ["z"] = 11, ["name"] = "default:stone"}, {["x"] = 6, ["y"] = 14, ["z"] = 12, ["name"] = "default:stone"}, {["x"] = 6, ["y"] = 14, ["z"] = 13, ["name"] = "default:stone"}, {["x"] = 6, ["y"] = 15, ["z"] = 10, ["name"] = "default:stone"}, {["x"] = 6, ["y"] = 15, ["z"] = 11, ["name"] = "default:stone"}, {["x"] = 6, ["y"] = 15, ["z"] = 12, ["name"] = "default:stone"}, {["x"] = 6, ["y"] = 15, ["z"] = 13, ["name"] = "default:stone"}, {["x"] = 7, ["y"] = 0, ["z"] = 2, ["name"] = "default:steelblock"}, {["x"] = 7, ["y"] = 0, ["z"] = 3, ["name"] = "default:steelblock"}, {["x"] = 7, ["y"] = 0, ["z"] = 4, ["name"] = "default:steelblock"}, {["x"] = 7, ["y"] = 0, ["z"] = 5, ["name"] = "default:steelblock"}, {["x"] = 7, ["y"] = 0, ["z"] = 6, ["name"] = "default:steelblock"}, {["x"] = 7, ["y"] = 0, ["z"] = 7, ["name"] = "default:steelblock"}, {["x"] = 7, ["y"] = 0, ["z"] = 8, ["name"] = "default:steelblock"}, {["x"] = 7, ["y"] = 0, ["z"] = 9, ["name"] = "default:steelblock"}, {["x"] = 7, ["y"] = 0, ["z"] = 10, ["name"] = "default:steelblock"}, {["x"] = 7, ["y"] = 0, ["z"] = 11, ["name"] = "default:steelblock"}, {["x"] = 7, ["y"] = 0, ["z"] = 12, ["name"] = "default:steelblock"}, {["x"] = 7, ["y"] = 0, ["z"] = 13, ["name"] = "default:steelblock"}, {["x"] = 7, ["y"] = 1, ["z"] = 2, ["name"] = "default:steelblock"}, {["x"] = 7, ["y"] = 1, ["z"] = 3, ["name"] = "default:steelblock"}, {["x"] = 7, ["y"] = 1, ["z"] = 4, ["name"] = "default:steelblock"}, {["x"] = 7, ["y"] = 1, ["z"] = 5, ["name"] = "default:steelblock"}, {["x"] = 7, ["y"] = 1, ["z"] = 6, ["name"] = "default:steelblock"}, {["x"] = 7, ["y"] = 1, ["z"] = 7, ["name"] = "default:steelblock"}, {["x"] = 7, ["y"] = 1, ["z"] = 8, ["name"] = "default:steelblock"}, {["x"] = 7, ["y"] = 1, ["z"] = 9, ["name"] = "default:steelblock"}, {["x"] = 7, ["y"] = 1, ["z"] = 10, ["name"] = "default:steelblock"}, {["x"] = 7, ["y"] = 1, ["z"] = 11, ["name"] = "default:steelblock"}, {["x"] = 7, ["y"] = 1, ["z"] = 12, ["name"] = "default:steelblock"}, {["x"] = 7, ["y"] = 1, ["z"] = 13, ["name"] = "default:steelblock"}, {["x"] = 7, ["y"] = 2, ["z"] = 1, ["name"] = "wool:grey"}, {["x"] = 7, ["y"] = 2, ["z"] = 2, ["name"] = "default:steelblock"}, {["x"] = 7, ["y"] = 2, ["z"] = 3, ["name"] = "default:steelblock"}, {["x"] = 7, ["y"] = 2, ["z"] = 4, ["name"] = "default:steelblock"}, {["x"] = 7, ["y"] = 2, ["z"] = 5, ["name"] = "default:steelblock"}, {["x"] = 7, ["y"] = 2, ["z"] = 6, ["name"] = "default:steelblock"}, {["x"] = 7, ["y"] = 2, ["z"] = 7, ["name"] = "default:steelblock"}, {["x"] = 7, ["y"] = 2, ["z"] = 8, ["name"] = "default:steelblock"}, {["x"] = 7, ["y"] = 2, ["z"] = 9, ["name"] = "default:steelblock"}, {["x"] = 7, ["y"] = 2, ["z"] = 10, ["name"] = "default:steelblock"}, {["x"] = 7, ["y"] = 2, ["z"] = 11, ["name"] = "default:steelblock"}, {["x"] = 7, ["y"] = 2, ["z"] = 12, ["name"] = "default:steelblock"}, {["x"] = 7, ["y"] = 2, ["z"] = 13, ["name"] = "default:steelblock"}, {["x"] = 7, ["y"] = 3, ["z"] = 1, ["name"] = "wool:grey"}, {["x"] = 7, ["y"] = 3, ["z"] = 2, ["name"] = "default:steelblock"}, {["x"] = 7, ["y"] = 3, ["z"] = 3, ["name"] = "default:steelblock"}, {["x"] = 7, ["y"] = 3, ["z"] = 4, ["name"] = "default:steelblock"}, {["x"] = 7, ["y"] = 3, ["z"] = 5, ["name"] = "default:steelblock"}, {["x"] = 7, ["y"] = 3, ["z"] = 6, ["name"] = "default:steelblock"}, {["x"] = 7, ["y"] = 3, ["z"] = 7, ["name"] = "default:steelblock"}, {["x"] = 7, ["y"] = 3, ["z"] = 8, ["name"] = "wool:yellow"}, {["x"] = 7, ["y"] = 3, ["z"] = 9, ["name"] = "wool:yellow"}, {["x"] = 7, ["y"] = 3, ["z"] = 10, ["name"] = "wool:yellow"}, {["x"] = 7, ["y"] = 3, ["z"] = 11, ["name"] = "wool:yellow"}, {["x"] = 7, ["y"] = 3, ["z"] = 12, ["name"] = "wool:yellow"}, {["x"] = 7, ["y"] = 3, ["z"] = 13, ["name"] = "wool:yellow"}, {["x"] = 7, ["y"] = 3, ["z"] = 14, ["name"] = "wool:red"}, {["x"] = 7, ["y"] = 3, ["z"] = 15, ["name"] = "wool:red"}, {["x"] = 7, ["y"] = 4, ["z"] = 2, ["name"] = "default:steelblock"}, {["x"] = 7, ["y"] = 4, ["z"] = 3, ["name"] = "default:steelblock"}, {["x"] = 7, ["y"] = 4, ["z"] = 4, ["name"] = "default:steelblock"}, {["x"] = 7, ["y"] = 4, ["z"] = 5, ["name"] = "default:steelblock"}, {["x"] = 7, ["y"] = 4, ["z"] = 6, ["name"] = "default:steelblock"}, {["x"] = 7, ["y"] = 4, ["z"] = 7, ["name"] = "default:steelblock"}, {["x"] = 7, ["y"] = 4, ["z"] = 8, ["name"] = "wool:yellow"}, {["x"] = 7, ["y"] = 4, ["z"] = 9, ["name"] = "wool:yellow"}, {["x"] = 7, ["y"] = 4, ["z"] = 10, ["name"] = "wool:yellow"}, {["x"] = 7, ["y"] = 4, ["z"] = 11, ["name"] = "wool:yellow"}, {["x"] = 7, ["y"] = 4, ["z"] = 12, ["name"] = "wool:yellow"}, {["x"] = 7, ["y"] = 4, ["z"] = 13, ["name"] = "wool:yellow"}, {["x"] = 7, ["y"] = 4, ["z"] = 14, ["name"] = "wool:red"}, {["x"] = 7, ["y"] = 4, ["z"] = 15, ["name"] = "wool:red"}, {["x"] = 7, ["y"] = 5, ["z"] = 2, ["name"] = "default:steelblock"}, {["x"] = 7, ["y"] = 5, ["z"] = 3, ["name"] = "default:steelblock"}, {["x"] = 7, ["y"] = 5, ["z"] = 4, ["name"] = "default:steelblock"}, {["x"] = 7, ["y"] = 5, ["z"] = 5, ["name"] = "default:steelblock"}, {["x"] = 7, ["y"] = 5, ["z"] = 6, ["name"] = "default:steelblock"}, {["x"] = 7, ["y"] = 5, ["z"] = 7, ["name"] = "default:steelblock"}, {["x"] = 7, ["y"] = 5, ["z"] = 8, ["name"] = "wool:yellow"}, {["x"] = 7, ["y"] = 5, ["z"] = 9, ["name"] = "wool:yellow"}, {["x"] = 7, ["y"] = 5, ["z"] = 10, ["name"] = "wool:yellow"}, {["x"] = 7, ["y"] = 5, ["z"] = 11, ["name"] = "wool:yellow"}, {["x"] = 7, ["y"] = 5, ["z"] = 12, ["name"] = "wool:yellow"}, {["x"] = 7, ["y"] = 5, ["z"] = 13, ["name"] = "wool:yellow"}, {["x"] = 7, ["y"] = 5, ["z"] = 14, ["name"] = "wool:red"}, {["x"] = 7, ["y"] = 5, ["z"] = 15, ["name"] = "wool:red"}, {["x"] = 7, ["y"] = 6, ["z"] = 2, ["name"] = "default:steelblock"}, {["x"] = 7, ["y"] = 6, ["z"] = 3, ["name"] = "default:steelblock"}, {["x"] = 7, ["y"] = 6, ["z"] = 4, ["name"] = "default:steelblock"}, {["x"] = 7, ["y"] = 6, ["z"] = 5, ["name"] = "default:steelblock"}, {["x"] = 7, ["y"] = 6, ["z"] = 6, ["name"] = "default:steelblock"}, {["x"] = 7, ["y"] = 6, ["z"] = 7, ["name"] = "default:steelblock"}, {["x"] = 7, ["y"] = 6, ["z"] = 8, ["name"] = "wool:yellow"}, {["x"] = 7, ["y"] = 6, ["z"] = 9, ["name"] = "wool:yellow"}, {["x"] = 7, ["y"] = 6, ["z"] = 10, ["name"] = "wool:yellow"}, {["x"] = 7, ["y"] = 6, ["z"] = 11, ["name"] = "wool:yellow"}, {["x"] = 7, ["y"] = 6, ["z"] = 12, ["name"] = "wool:yellow"}, {["x"] = 7, ["y"] = 6, ["z"] = 13, ["name"] = "wool:yellow"}, {["x"] = 7, ["y"] = 6, ["z"] = 14, ["name"] = "wool:red"}, {["x"] = 7, ["y"] = 6, ["z"] = 15, ["name"] = "wool:red"}, {["x"] = 7, ["y"] = 7, ["z"] = 0, ["name"] = "wool:red"}, {["x"] = 7, ["y"] = 7, ["z"] = 1, ["name"] = "wool:red"}, {["x"] = 7, ["y"] = 7, ["z"] = 2, ["name"] = "default:steelblock"}, {["x"] = 7, ["y"] = 7, ["z"] = 3, ["name"] = "default:steelblock"}, {["x"] = 7, ["y"] = 7, ["z"] = 4, ["name"] = "default:steelblock"}, {["x"] = 7, ["y"] = 7, ["z"] = 5, ["name"] = "default:steelblock"}, {["x"] = 7, ["y"] = 7, ["z"] = 6, ["name"] = "default:steelblock"}, {["x"] = 7, ["y"] = 7, ["z"] = 7, ["name"] = "default:steelblock"}, {["x"] = 7, ["y"] = 7, ["z"] = 8, ["name"] = "default:steelblock"}, {["x"] = 7, ["y"] = 7, ["z"] = 9, ["name"] = "default:steelblock"}, {["x"] = 7, ["y"] = 7, ["z"] = 10, ["name"] = "default:steelblock"}, {["x"] = 7, ["y"] = 7, ["z"] = 11, ["name"] = "default:steelblock"}, {["x"] = 7, ["y"] = 7, ["z"] = 12, ["name"] = "default:steelblock"}, {["x"] = 7, ["y"] = 7, ["z"] = 13, ["name"] = "default:steelblock"}, {["x"] = 7, ["y"] = 7, ["z"] = 14, ["name"] = "wool:grey"}, {["x"] = 7, ["y"] = 8, ["z"] = 0, ["name"] = "wool:red"}, {["x"] = 7, ["y"] = 8, ["z"] = 1, ["name"] = "wool:red"}, {["x"] = 7, ["y"] = 8, ["z"] = 2, ["name"] = "default:steelblock"}, {["x"] = 7, ["y"] = 8, ["z"] = 3, ["name"] = "default:steelblock"}, {["x"] = 7, ["y"] = 8, ["z"] = 4, ["name"] = "default:steelblock"}, {["x"] = 7, ["y"] = 8, ["z"] = 5, ["name"] = "default:steelblock"}, {["x"] = 7, ["y"] = 8, ["z"] = 6, ["name"] = "default:steelblock"}, {["x"] = 7, ["y"] = 8, ["z"] = 7, ["name"] = "default:steelblock"}, {["x"] = 7, ["y"] = 8, ["z"] = 8, ["name"] = "default:steelblock"}, {["x"] = 7, ["y"] = 8, ["z"] = 9, ["name"] = "default:steelblock"}, {["x"] = 7, ["y"] = 8, ["z"] = 10, ["name"] = "default:steelblock"}, {["x"] = 7, ["y"] = 8, ["z"] = 11, ["name"] = "default:steelblock"}, {["x"] = 7, ["y"] = 8, ["z"] = 12, ["name"] = "default:steelblock"}, {["x"] = 7, ["y"] = 8, ["z"] = 13, ["name"] = "default:steelblock"}, {["x"] = 7, ["y"] = 8, ["z"] = 14, ["name"] = "wool:grey"}, {["x"] = 7, ["y"] = 9, ["z"] = 1, ["name"] = "wool:grey"}, {["x"] = 7, ["y"] = 9, ["z"] = 2, ["name"] = "default:steelblock"}, {["x"] = 7, ["y"] = 9, ["z"] = 3, ["name"] = "default:steelblock"}, {["x"] = 7, ["y"] = 9, ["z"] = 4, ["name"] = "default:steelblock"}, {["x"] = 7, ["y"] = 9, ["z"] = 5, ["name"] = "default:steelblock"}, {["x"] = 7, ["y"] = 9, ["z"] = 6, ["name"] = "default:steelblock"}, {["x"] = 7, ["y"] = 9, ["z"] = 7, ["name"] = "default:steelblock"}, {["x"] = 7, ["y"] = 9, ["z"] = 8, ["name"] = "default:steelblock"}, {["x"] = 7, ["y"] = 9, ["z"] = 9, ["name"] = "default:steelblock"}, {["x"] = 7, ["y"] = 9, ["z"] = 10, ["name"] = "default:steelblock"}, {["x"] = 7, ["y"] = 9, ["z"] = 11, ["name"] = "default:steelblock"}, {["x"] = 7, ["y"] = 9, ["z"] = 12, ["name"] = "default:steelblock"}, {["x"] = 7, ["y"] = 9, ["z"] = 13, ["name"] = "default:steelblock"}, {["x"] = 7, ["y"] = 10, ["z"] = 1, ["name"] = "wool:grey"}, {["x"] = 7, ["y"] = 10, ["z"] = 2, ["name"] = "default:steelblock"}, {["x"] = 7, ["y"] = 10, ["z"] = 3, ["name"] = "default:steelblock"}, {["x"] = 7, ["y"] = 10, ["z"] = 4, ["name"] = "default:steelblock"}, {["x"] = 7, ["y"] = 10, ["z"] = 5, ["name"] = "default:steelblock"}, {["x"] = 7, ["y"] = 10, ["z"] = 6, ["name"] = "default:steelblock"}, {["x"] = 7, ["y"] = 10, ["z"] = 7, ["name"] = "default:steelblock"}, {["x"] = 7, ["y"] = 10, ["z"] = 8, ["name"] = "default:steelblock"}, {["x"] = 7, ["y"] = 10, ["z"] = 9, ["name"] = "default:steelblock"}, {["x"] = 7, ["y"] = 10, ["z"] = 10, ["name"] = "default:steelblock"}, {["x"] = 7, ["y"] = 10, ["z"] = 11, ["name"] = "default:steelblock"}, {["x"] = 7, ["y"] = 10, ["z"] = 12, ["name"] = "default:steelblock"}, {["x"] = 7, ["y"] = 10, ["z"] = 13, ["name"] = "default:steelblock"}, {["x"] = 7, ["y"] = 11, ["z"] = 2, ["name"] = "default:steelblock"}, {["x"] = 7, ["y"] = 11, ["z"] = 3, ["name"] = "default:steelblock"}, {["x"] = 7, ["y"] = 11, ["z"] = 4, ["name"] = "default:steelblock"}, {["x"] = 7, ["y"] = 11, ["z"] = 5, ["name"] = "default:steelblock"}, {["x"] = 7, ["y"] = 11, ["z"] = 6, ["name"] = "default:steelblock"}, {["x"] = 7, ["y"] = 11, ["z"] = 7, ["name"] = "default:steelblock"}, {["x"] = 7, ["y"] = 11, ["z"] = 8, ["name"] = "default:steelblock"}, {["x"] = 7, ["y"] = 11, ["z"] = 9, ["name"] = "default:steelblock"}, {["x"] = 7, ["y"] = 11, ["z"] = 10, ["name"] = "default:stone"}, {["x"] = 7, ["y"] = 11, ["z"] = 11, ["name"] = "default:stone"}, {["x"] = 7, ["y"] = 11, ["z"] = 12, ["name"] = "default:stone"}, {["x"] = 7, ["y"] = 11, ["z"] = 13, ["name"] = "default:stone"}, {["x"] = 7, ["y"] = 12, ["z"] = 2, ["name"] = "default:steelblock"}, {["x"] = 7, ["y"] = 12, ["z"] = 3, ["name"] = "default:steelblock"}, {["x"] = 7, ["y"] = 12, ["z"] = 4, ["name"] = "default:steelblock"}, {["x"] = 7, ["y"] = 12, ["z"] = 5, ["name"] = "default:steelblock"}, {["x"] = 7, ["y"] = 12, ["z"] = 6, ["name"] = "default:steelblock"}, {["x"] = 7, ["y"] = 12, ["z"] = 7, ["name"] = "default:steelblock"}, {["x"] = 7, ["y"] = 12, ["z"] = 8, ["name"] = "default:steelblock"}, {["x"] = 7, ["y"] = 12, ["z"] = 9, ["name"] = "default:steelblock"}, {["x"] = 7, ["y"] = 12, ["z"] = 10, ["name"] = "default:stone"}, {["x"] = 7, ["y"] = 12, ["z"] = 11, ["name"] = "default:stone"}, {["x"] = 7, ["y"] = 12, ["z"] = 12, ["name"] = "default:stone"}, {["x"] = 7, ["y"] = 12, ["z"] = 13, ["name"] = "default:stone"}, {["x"] = 7, ["y"] = 13, ["z"] = 2, ["name"] = "default:steelblock"}, {["x"] = 7, ["y"] = 13, ["z"] = 3, ["name"] = "default:steelblock"}, {["x"] = 7, ["y"] = 13, ["z"] = 4, ["name"] = "default:steelblock"}, {["x"] = 7, ["y"] = 13, ["z"] = 5, ["name"] = "default:steelblock"}, {["x"] = 7, ["y"] = 13, ["z"] = 6, ["name"] = "default:steelblock"}, {["x"] = 7, ["y"] = 13, ["z"] = 7, ["name"] = "default:steelblock"}, {["x"] = 7, ["y"] = 13, ["z"] = 8, ["name"] = "default:steelblock"}, {["x"] = 7, ["y"] = 13, ["z"] = 9, ["name"] = "default:steelblock"}, {["x"] = 7, ["y"] = 13, ["z"] = 10, ["name"] = "default:stone"}, {["x"] = 7, ["y"] = 13, ["z"] = 11, ["name"] = "default:stone"}, {["x"] = 7, ["y"] = 13, ["z"] = 12, ["name"] = "default:stone"}, {["x"] = 7, ["y"] = 13, ["z"] = 13, ["name"] = "default:stone"}, {["x"] = 7, ["y"] = 14, ["z"] = 10, ["name"] = "default:stone"}, {["x"] = 7, ["y"] = 14, ["z"] = 11, ["name"] = "default:stone"}, {["x"] = 7, ["y"] = 14, ["z"] = 12, ["name"] = "default:stone"}, {["x"] = 7, ["y"] = 14, ["z"] = 13, ["name"] = "default:stone"}, {["x"] = 7, ["y"] = 15, ["z"] = 10, ["name"] = "default:stone"}, {["x"] = 7, ["y"] = 15, ["z"] = 11, ["name"] = "default:stone"}, {["x"] = 7, ["y"] = 15, ["z"] = 12, ["name"] = "default:stone"}, {["x"] = 7, ["y"] = 15, ["z"] = 13, ["name"] = "default:stone"}, {["x"] = 8, ["y"] = 0, ["z"] = 2, ["name"] = "default:steelblock"}, {["x"] = 8, ["y"] = 0, ["z"] = 3, ["name"] = "default:steelblock"}, {["x"] = 8, ["y"] = 0, ["z"] = 4, ["name"] = "default:steelblock"}, {["x"] = 8, ["y"] = 0, ["z"] = 5, ["name"] = "default:steelblock"}, {["x"] = 8, ["y"] = 0, ["z"] = 6, ["name"] = "default:steelblock"}, {["x"] = 8, ["y"] = 0, ["z"] = 7, ["name"] = "default:steelblock"}, {["x"] = 8, ["y"] = 0, ["z"] = 8, ["name"] = "default:steelblock"}, {["x"] = 8, ["y"] = 0, ["z"] = 9, ["name"] = "default:steelblock"}, {["x"] = 8, ["y"] = 0, ["z"] = 10, ["name"] = "default:steelblock"}, {["x"] = 8, ["y"] = 0, ["z"] = 11, ["name"] = "default:steelblock"}, {["x"] = 8, ["y"] = 0, ["z"] = 12, ["name"] = "default:steelblock"}, {["x"] = 8, ["y"] = 0, ["z"] = 13, ["name"] = "default:steelblock"}, {["x"] = 8, ["y"] = 1, ["z"] = 2, ["name"] = "default:steelblock"}, {["x"] = 8, ["y"] = 1, ["z"] = 3, ["name"] = "default:steelblock"}, {["x"] = 8, ["y"] = 1, ["z"] = 4, ["name"] = "default:steelblock"}, {["x"] = 8, ["y"] = 1, ["z"] = 5, ["name"] = "default:steelblock"}, {["x"] = 8, ["y"] = 1, ["z"] = 6, ["name"] = "default:steelblock"}, {["x"] = 8, ["y"] = 1, ["z"] = 7, ["name"] = "default:steelblock"}, {["x"] = 8, ["y"] = 1, ["z"] = 8, ["name"] = "default:steelblock"}, {["x"] = 8, ["y"] = 1, ["z"] = 9, ["name"] = "default:steelblock"}, {["x"] = 8, ["y"] = 1, ["z"] = 10, ["name"] = "default:steelblock"}, {["x"] = 8, ["y"] = 1, ["z"] = 11, ["name"] = "default:steelblock"}, {["x"] = 8, ["y"] = 1, ["z"] = 12, ["name"] = "default:steelblock"}, {["x"] = 8, ["y"] = 1, ["z"] = 13, ["name"] = "default:steelblock"}, {["x"] = 8, ["y"] = 2, ["z"] = 1, ["name"] = "wool:grey"}, {["x"] = 8, ["y"] = 2, ["z"] = 2, ["name"] = "default:steelblock"}, {["x"] = 8, ["y"] = 2, ["z"] = 3, ["name"] = "default:steelblock"}, {["x"] = 8, ["y"] = 2, ["z"] = 4, ["name"] = "default:steelblock"}, {["x"] = 8, ["y"] = 2, ["z"] = 5, ["name"] = "default:steelblock"}, {["x"] = 8, ["y"] = 2, ["z"] = 6, ["name"] = "default:steelblock"}, {["x"] = 8, ["y"] = 2, ["z"] = 7, ["name"] = "default:steelblock"}, {["x"] = 8, ["y"] = 2, ["z"] = 8, ["name"] = "default:steelblock"}, {["x"] = 8, ["y"] = 2, ["z"] = 9, ["name"] = "default:steelblock"}, {["x"] = 8, ["y"] = 2, ["z"] = 10, ["name"] = "default:steelblock"}, {["x"] = 8, ["y"] = 2, ["z"] = 11, ["name"] = "default:steelblock"}, {["x"] = 8, ["y"] = 2, ["z"] = 12, ["name"] = "default:steelblock"}, {["x"] = 8, ["y"] = 2, ["z"] = 13, ["name"] = "default:steelblock"}, {["x"] = 8, ["y"] = 3, ["z"] = 1, ["name"] = "wool:grey"}, {["x"] = 8, ["y"] = 3, ["z"] = 2, ["name"] = "default:steelblock"}, {["x"] = 8, ["y"] = 3, ["z"] = 3, ["name"] = "default:steelblock"}, {["x"] = 8, ["y"] = 3, ["z"] = 4, ["name"] = "default:steelblock"}, {["x"] = 8, ["y"] = 3, ["z"] = 5, ["name"] = "default:steelblock"}, {["x"] = 8, ["y"] = 3, ["z"] = 6, ["name"] = "default:steelblock"}, {["x"] = 8, ["y"] = 3, ["z"] = 7, ["name"] = "default:steelblock"}, {["x"] = 8, ["y"] = 3, ["z"] = 8, ["name"] = "wool:yellow"}, {["x"] = 8, ["y"] = 3, ["z"] = 9, ["name"] = "wool:yellow"}, {["x"] = 8, ["y"] = 3, ["z"] = 10, ["name"] = "wool:yellow"}, {["x"] = 8, ["y"] = 3, ["z"] = 11, ["name"] = "wool:yellow"}, {["x"] = 8, ["y"] = 3, ["z"] = 12, ["name"] = "wool:yellow"}, {["x"] = 8, ["y"] = 3, ["z"] = 13, ["name"] = "wool:yellow"}, {["x"] = 8, ["y"] = 3, ["z"] = 14, ["name"] = "wool:red"}, {["x"] = 8, ["y"] = 3, ["z"] = 15, ["name"] = "wool:red"}, {["x"] = 8, ["y"] = 4, ["z"] = 2, ["name"] = "default:steelblock"}, {["x"] = 8, ["y"] = 4, ["z"] = 3, ["name"] = "default:steelblock"}, {["x"] = 8, ["y"] = 4, ["z"] = 4, ["name"] = "default:steelblock"}, {["x"] = 8, ["y"] = 4, ["z"] = 5, ["name"] = "default:steelblock"}, {["x"] = 8, ["y"] = 4, ["z"] = 6, ["name"] = "default:steelblock"}, {["x"] = 8, ["y"] = 4, ["z"] = 7, ["name"] = "default:steelblock"}, {["x"] = 8, ["y"] = 4, ["z"] = 8, ["name"] = "wool:yellow"}, {["x"] = 8, ["y"] = 4, ["z"] = 9, ["name"] = "wool:yellow"}, {["x"] = 8, ["y"] = 4, ["z"] = 10, ["name"] = "wool:yellow"}, {["x"] = 8, ["y"] = 4, ["z"] = 11, ["name"] = "wool:yellow"}, {["x"] = 8, ["y"] = 4, ["z"] = 12, ["name"] = "wool:yellow"}, {["x"] = 8, ["y"] = 4, ["z"] = 13, ["name"] = "wool:yellow"}, {["x"] = 8, ["y"] = 4, ["z"] = 14, ["name"] = "wool:red"}, {["x"] = 8, ["y"] = 4, ["z"] = 15, ["name"] = "wool:red"}, {["x"] = 8, ["y"] = 5, ["z"] = 2, ["name"] = "default:steelblock"}, {["x"] = 8, ["y"] = 5, ["z"] = 3, ["name"] = "default:steelblock"}, {["x"] = 8, ["y"] = 5, ["z"] = 4, ["name"] = "default:steelblock"}, {["x"] = 8, ["y"] = 5, ["z"] = 5, ["name"] = "default:steelblock"}, {["x"] = 8, ["y"] = 5, ["z"] = 6, ["name"] = "default:steelblock"}, {["x"] = 8, ["y"] = 5, ["z"] = 7, ["name"] = "default:steelblock"}, {["x"] = 8, ["y"] = 5, ["z"] = 8, ["name"] = "wool:yellow"}, {["x"] = 8, ["y"] = 5, ["z"] = 9, ["name"] = "wool:yellow"}, {["x"] = 8, ["y"] = 5, ["z"] = 10, ["name"] = "wool:yellow"}, {["x"] = 8, ["y"] = 5, ["z"] = 11, ["name"] = "wool:yellow"}, {["x"] = 8, ["y"] = 5, ["z"] = 12, ["name"] = "wool:yellow"}, {["x"] = 8, ["y"] = 5, ["z"] = 13, ["name"] = "wool:yellow"}, {["x"] = 8, ["y"] = 5, ["z"] = 14, ["name"] = "wool:red"}, {["x"] = 8, ["y"] = 5, ["z"] = 15, ["name"] = "wool:red"}, {["x"] = 8, ["y"] = 6, ["z"] = 2, ["name"] = "default:steelblock"}, {["x"] = 8, ["y"] = 6, ["z"] = 3, ["name"] = "default:steelblock"}, {["x"] = 8, ["y"] = 6, ["z"] = 4, ["name"] = "default:steelblock"}, {["x"] = 8, ["y"] = 6, ["z"] = 5, ["name"] = "default:steelblock"}, {["x"] = 8, ["y"] = 6, ["z"] = 6, ["name"] = "default:steelblock"}, {["x"] = 8, ["y"] = 6, ["z"] = 7, ["name"] = "default:steelblock"}, {["x"] = 8, ["y"] = 6, ["z"] = 8, ["name"] = "wool:yellow"}, {["x"] = 8, ["y"] = 6, ["z"] = 9, ["name"] = "wool:yellow"}, {["x"] = 8, ["y"] = 6, ["z"] = 10, ["name"] = "wool:yellow"}, {["x"] = 8, ["y"] = 6, ["z"] = 11, ["name"] = "wool:yellow"}, {["x"] = 8, ["y"] = 6, ["z"] = 12, ["name"] = "wool:yellow"}, {["x"] = 8, ["y"] = 6, ["z"] = 13, ["name"] = "wool:yellow"}, {["x"] = 8, ["y"] = 6, ["z"] = 14, ["name"] = "wool:red"}, {["x"] = 8, ["y"] = 6, ["z"] = 15, ["name"] = "wool:red"}, {["x"] = 8, ["y"] = 7, ["z"] = 0, ["name"] = "wool:red"}, {["x"] = 8, ["y"] = 7, ["z"] = 1, ["name"] = "wool:red"}, {["x"] = 8, ["y"] = 7, ["z"] = 2, ["name"] = "default:steelblock"}, {["x"] = 8, ["y"] = 7, ["z"] = 3, ["name"] = "default:steelblock"}, {["x"] = 8, ["y"] = 7, ["z"] = 4, ["name"] = "default:steelblock"}, {["x"] = 8, ["y"] = 7, ["z"] = 5, ["name"] = "default:steelblock"}, {["x"] = 8, ["y"] = 7, ["z"] = 6, ["name"] = "default:steelblock"}, {["x"] = 8, ["y"] = 7, ["z"] = 7, ["name"] = "default:steelblock"}, {["x"] = 8, ["y"] = 7, ["z"] = 8, ["name"] = "default:steelblock"}, {["x"] = 8, ["y"] = 7, ["z"] = 9, ["name"] = "default:steelblock"}, {["x"] = 8, ["y"] = 7, ["z"] = 10, ["name"] = "default:steelblock"}, {["x"] = 8, ["y"] = 7, ["z"] = 11, ["name"] = "default:steelblock"}, {["x"] = 8, ["y"] = 7, ["z"] = 12, ["name"] = "default:steelblock"}, {["x"] = 8, ["y"] = 7, ["z"] = 13, ["name"] = "default:steelblock"}, {["x"] = 8, ["y"] = 7, ["z"] = 14, ["name"] = "wool:grey"}, {["x"] = 8, ["y"] = 8, ["z"] = 0, ["name"] = "wool:red"}, {["x"] = 8, ["y"] = 8, ["z"] = 1, ["name"] = "wool:red"}, {["x"] = 8, ["y"] = 8, ["z"] = 2, ["name"] = "default:steelblock"}, {["x"] = 8, ["y"] = 8, ["z"] = 3, ["name"] = "default:steelblock"}, {["x"] = 8, ["y"] = 8, ["z"] = 4, ["name"] = "default:steelblock"}, {["x"] = 8, ["y"] = 8, ["z"] = 5, ["name"] = "default:steelblock"}, {["x"] = 8, ["y"] = 8, ["z"] = 6, ["name"] = "default:steelblock"}, {["x"] = 8, ["y"] = 8, ["z"] = 7, ["name"] = "default:steelblock"}, {["x"] = 8, ["y"] = 8, ["z"] = 8, ["name"] = "default:steelblock"}, {["x"] = 8, ["y"] = 8, ["z"] = 9, ["name"] = "default:steelblock"}, {["x"] = 8, ["y"] = 8, ["z"] = 10, ["name"] = "default:steelblock"}, {["x"] = 8, ["y"] = 8, ["z"] = 11, ["name"] = "default:steelblock"}, {["x"] = 8, ["y"] = 8, ["z"] = 12, ["name"] = "default:steelblock"}, {["x"] = 8, ["y"] = 8, ["z"] = 13, ["name"] = "default:steelblock"}, {["x"] = 8, ["y"] = 8, ["z"] = 14, ["name"] = "wool:grey"}, {["x"] = 8, ["y"] = 9, ["z"] = 1, ["name"] = "wool:grey"}, {["x"] = 8, ["y"] = 9, ["z"] = 2, ["name"] = "default:steelblock"}, {["x"] = 8, ["y"] = 9, ["z"] = 3, ["name"] = "default:steelblock"}, {["x"] = 8, ["y"] = 9, ["z"] = 4, ["name"] = "default:steelblock"}, {["x"] = 8, ["y"] = 9, ["z"] = 5, ["name"] = "default:steelblock"}, {["x"] = 8, ["y"] = 9, ["z"] = 6, ["name"] = "default:steelblock"}, {["x"] = 8, ["y"] = 9, ["z"] = 7, ["name"] = "default:steelblock"}, {["x"] = 8, ["y"] = 9, ["z"] = 8, ["name"] = "default:steelblock"}, {["x"] = 8, ["y"] = 9, ["z"] = 9, ["name"] = "default:steelblock"}, {["x"] = 8, ["y"] = 9, ["z"] = 10, ["name"] = "default:steelblock"}, {["x"] = 8, ["y"] = 9, ["z"] = 11, ["name"] = "default:steelblock"}, {["x"] = 8, ["y"] = 9, ["z"] = 12, ["name"] = "default:steelblock"}, {["x"] = 8, ["y"] = 9, ["z"] = 13, ["name"] = "default:steelblock"}, {["x"] = 8, ["y"] = 10, ["z"] = 1, ["name"] = "wool:grey"}, {["x"] = 8, ["y"] = 10, ["z"] = 2, ["name"] = "default:steelblock"}, {["x"] = 8, ["y"] = 10, ["z"] = 3, ["name"] = "default:steelblock"}, {["x"] = 8, ["y"] = 10, ["z"] = 4, ["name"] = "default:steelblock"}, {["x"] = 8, ["y"] = 10, ["z"] = 5, ["name"] = "default:steelblock"}, {["x"] = 8, ["y"] = 10, ["z"] = 6, ["name"] = "default:steelblock"}, {["x"] = 8, ["y"] = 10, ["z"] = 7, ["name"] = "default:steelblock"}, {["x"] = 8, ["y"] = 10, ["z"] = 8, ["name"] = "default:steelblock"}, {["x"] = 8, ["y"] = 10, ["z"] = 9, ["name"] = "default:steelblock"}, {["x"] = 8, ["y"] = 10, ["z"] = 10, ["name"] = "default:steelblock"}, {["x"] = 8, ["y"] = 10, ["z"] = 11, ["name"] = "default:steelblock"}, {["x"] = 8, ["y"] = 10, ["z"] = 12, ["name"] = "default:steelblock"}, {["x"] = 8, ["y"] = 10, ["z"] = 13, ["name"] = "default:steelblock"}, {["x"] = 8, ["y"] = 11, ["z"] = 2, ["name"] = "default:steelblock"}, {["x"] = 8, ["y"] = 11, ["z"] = 3, ["name"] = "default:steelblock"}, {["x"] = 8, ["y"] = 11, ["z"] = 4, ["name"] = "default:steelblock"}, {["x"] = 8, ["y"] = 11, ["z"] = 5, ["name"] = "default:steelblock"}, {["x"] = 8, ["y"] = 11, ["z"] = 6, ["name"] = "default:steelblock"}, {["x"] = 8, ["y"] = 11, ["z"] = 7, ["name"] = "default:steelblock"}, {["x"] = 8, ["y"] = 11, ["z"] = 8, ["name"] = "default:steelblock"}, {["x"] = 8, ["y"] = 11, ["z"] = 9, ["name"] = "default:steelblock"}, {["x"] = 8, ["y"] = 11, ["z"] = 10, ["name"] = "default:stone"}, {["x"] = 8, ["y"] = 11, ["z"] = 11, ["name"] = "default:stone"}, {["x"] = 8, ["y"] = 11, ["z"] = 12, ["name"] = "default:stone"}, {["x"] = 8, ["y"] = 11, ["z"] = 13, ["name"] = "default:stone"}, {["x"] = 8, ["y"] = 12, ["z"] = 2, ["name"] = "default:steelblock"}, {["x"] = 8, ["y"] = 12, ["z"] = 3, ["name"] = "default:steelblock"}, {["x"] = 8, ["y"] = 12, ["z"] = 4, ["name"] = "default:steelblock"}, {["x"] = 8, ["y"] = 12, ["z"] = 5, ["name"] = "default:steelblock"}, {["x"] = 8, ["y"] = 12, ["z"] = 6, ["name"] = "default:steelblock"}, {["x"] = 8, ["y"] = 12, ["z"] = 7, ["name"] = "default:steelblock"}, {["x"] = 8, ["y"] = 12, ["z"] = 8, ["name"] = "default:steelblock"}, {["x"] = 8, ["y"] = 12, ["z"] = 9, ["name"] = "default:steelblock"}, {["x"] = 8, ["y"] = 12, ["z"] = 10, ["name"] = "default:stone"}, {["x"] = 8, ["y"] = 12, ["z"] = 11, ["name"] = "default:stone"}, {["x"] = 8, ["y"] = 12, ["z"] = 12, ["name"] = "default:stone"}, {["x"] = 8, ["y"] = 12, ["z"] = 13, ["name"] = "default:stone"}, {["x"] = 8, ["y"] = 13, ["z"] = 2, ["name"] = "default:steelblock"}, {["x"] = 8, ["y"] = 13, ["z"] = 3, ["name"] = "default:steelblock"}, {["x"] = 8, ["y"] = 13, ["z"] = 4, ["name"] = "default:steelblock"}, {["x"] = 8, ["y"] = 13, ["z"] = 5, ["name"] = "default:steelblock"}, {["x"] = 8, ["y"] = 13, ["z"] = 6, ["name"] = "default:steelblock"}, {["x"] = 8, ["y"] = 13, ["z"] = 7, ["name"] = "default:steelblock"}, {["x"] = 8, ["y"] = 13, ["z"] = 8, ["name"] = "default:steelblock"}, {["x"] = 8, ["y"] = 13, ["z"] = 9, ["name"] = "default:steelblock"}, {["x"] = 8, ["y"] = 13, ["z"] = 10, ["name"] = "default:stone"}, {["x"] = 8, ["y"] = 13, ["z"] = 11, ["name"] = "default:stone"}, {["x"] = 8, ["y"] = 13, ["z"] = 12, ["name"] = "default:stone"}, {["x"] = 8, ["y"] = 13, ["z"] = 13, ["name"] = "default:stone"}, {["x"] = 8, ["y"] = 14, ["z"] = 10, ["name"] = "default:stone"}, {["x"] = 8, ["y"] = 14, ["z"] = 11, ["name"] = "default:stone"}, {["x"] = 8, ["y"] = 14, ["z"] = 12, ["name"] = "default:stone"}, {["x"] = 8, ["y"] = 14, ["z"] = 13, ["name"] = "default:stone"}, {["x"] = 8, ["y"] = 15, ["z"] = 10, ["name"] = "default:stone"}, {["x"] = 8, ["y"] = 15, ["z"] = 11, ["name"] = "default:stone"}, {["x"] = 8, ["y"] = 15, ["z"] = 12, ["name"] = "default:stone"}, {["x"] = 8, ["y"] = 15, ["z"] = 13, ["name"] = "default:stone"}, {["x"] = 9, ["y"] = 0, ["z"] = 2, ["name"] = "default:steelblock"}, {["x"] = 9, ["y"] = 0, ["z"] = 3, ["name"] = "default:steelblock"}, {["x"] = 9, ["y"] = 0, ["z"] = 4, ["name"] = "default:steelblock"}, {["x"] = 9, ["y"] = 0, ["z"] = 5, ["name"] = "default:steelblock"}, {["x"] = 9, ["y"] = 0, ["z"] = 6, ["name"] = "default:steelblock"}, {["x"] = 9, ["y"] = 0, ["z"] = 7, ["name"] = "default:steelblock"}, {["x"] = 9, ["y"] = 0, ["z"] = 8, ["name"] = "default:steelblock"}, {["x"] = 9, ["y"] = 0, ["z"] = 9, ["name"] = "default:steelblock"}, {["x"] = 9, ["y"] = 0, ["z"] = 10, ["name"] = "default:steelblock"}, {["x"] = 9, ["y"] = 0, ["z"] = 11, ["name"] = "default:steelblock"}, {["x"] = 9, ["y"] = 0, ["z"] = 12, ["name"] = "default:steelblock"}, {["x"] = 9, ["y"] = 0, ["z"] = 13, ["name"] = "default:steelblock"}, {["x"] = 9, ["y"] = 1, ["z"] = 2, ["name"] = "default:steelblock"}, {["x"] = 9, ["y"] = 1, ["z"] = 3, ["name"] = "default:steelblock"}, {["x"] = 9, ["y"] = 1, ["z"] = 4, ["name"] = "default:steelblock"}, {["x"] = 9, ["y"] = 1, ["z"] = 5, ["name"] = "default:steelblock"}, {["x"] = 9, ["y"] = 1, ["z"] = 6, ["name"] = "default:steelblock"}, {["x"] = 9, ["y"] = 1, ["z"] = 7, ["name"] = "default:steelblock"}, {["x"] = 9, ["y"] = 1, ["z"] = 8, ["name"] = "default:steelblock"}, {["x"] = 9, ["y"] = 1, ["z"] = 9, ["name"] = "default:steelblock"}, {["x"] = 9, ["y"] = 1, ["z"] = 10, ["name"] = "default:steelblock"}, {["x"] = 9, ["y"] = 1, ["z"] = 11, ["name"] = "default:steelblock"}, {["x"] = 9, ["y"] = 1, ["z"] = 12, ["name"] = "default:steelblock"}, {["x"] = 9, ["y"] = 1, ["z"] = 13, ["name"] = "default:steelblock"}, {["x"] = 9, ["y"] = 2, ["z"] = 1, ["name"] = "wool:grey"}, {["x"] = 9, ["y"] = 2, ["z"] = 2, ["name"] = "default:steelblock"}, {["x"] = 9, ["y"] = 2, ["z"] = 3, ["name"] = "default:steelblock"}, {["x"] = 9, ["y"] = 2, ["z"] = 4, ["name"] = "default:steelblock"}, {["x"] = 9, ["y"] = 2, ["z"] = 5, ["name"] = "default:steelblock"}, {["x"] = 9, ["y"] = 2, ["z"] = 6, ["name"] = "default:steelblock"}, {["x"] = 9, ["y"] = 2, ["z"] = 7, ["name"] = "default:steelblock"}, {["x"] = 9, ["y"] = 2, ["z"] = 8, ["name"] = "default:steelblock"}, {["x"] = 9, ["y"] = 2, ["z"] = 9, ["name"] = "default:steelblock"}, {["x"] = 9, ["y"] = 2, ["z"] = 10, ["name"] = "default:steelblock"}, {["x"] = 9, ["y"] = 2, ["z"] = 11, ["name"] = "default:steelblock"}, {["x"] = 9, ["y"] = 2, ["z"] = 12, ["name"] = "default:steelblock"}, {["x"] = 9, ["y"] = 2, ["z"] = 13, ["name"] = "default:steelblock"}, {["x"] = 9, ["y"] = 3, ["z"] = 1, ["name"] = "wool:grey"}, {["x"] = 9, ["y"] = 3, ["z"] = 2, ["name"] = "default:steelblock"}, {["x"] = 9, ["y"] = 3, ["z"] = 3, ["name"] = "default:steelblock"}, {["x"] = 9, ["y"] = 3, ["z"] = 4, ["name"] = "default:steelblock"}, {["x"] = 9, ["y"] = 3, ["z"] = 5, ["name"] = "default:steelblock"}, {["x"] = 9, ["y"] = 3, ["z"] = 6, ["name"] = "default:steelblock"}, {["x"] = 9, ["y"] = 3, ["z"] = 7, ["name"] = "default:steelblock"}, {["x"] = 9, ["y"] = 3, ["z"] = 8, ["name"] = "default:steelblock"}, {["x"] = 9, ["y"] = 3, ["z"] = 9, ["name"] = "default:steelblock"}, {["x"] = 9, ["y"] = 3, ["z"] = 10, ["name"] = "default:steelblock"}, {["x"] = 9, ["y"] = 3, ["z"] = 11, ["name"] = "default:steelblock"}, {["x"] = 9, ["y"] = 3, ["z"] = 12, ["name"] = "default:steelblock"}, {["x"] = 9, ["y"] = 3, ["z"] = 13, ["name"] = "default:steelblock"}, {["x"] = 9, ["y"] = 4, ["z"] = 2, ["name"] = "default:steelblock"}, {["x"] = 9, ["y"] = 4, ["z"] = 3, ["name"] = "default:steelblock"}, {["x"] = 9, ["y"] = 4, ["z"] = 4, ["name"] = "default:steelblock"}, {["x"] = 9, ["y"] = 4, ["z"] = 5, ["name"] = "default:steelblock"}, {["x"] = 9, ["y"] = 4, ["z"] = 6, ["name"] = "default:steelblock"}, {["x"] = 9, ["y"] = 4, ["z"] = 7, ["name"] = "default:steelblock"}, {["x"] = 9, ["y"] = 4, ["z"] = 8, ["name"] = "wool:yellow"}, {["x"] = 9, ["y"] = 4, ["z"] = 9, ["name"] = "wool:yellow"}, {["x"] = 9, ["y"] = 4, ["z"] = 10, ["name"] = "wool:yellow"}, {["x"] = 9, ["y"] = 4, ["z"] = 11, ["name"] = "wool:yellow"}, {["x"] = 9, ["y"] = 4, ["z"] = 12, ["name"] = "wool:yellow"}, {["x"] = 9, ["y"] = 4, ["z"] = 13, ["name"] = "wool:yellow"}, {["x"] = 9, ["y"] = 4, ["z"] = 14, ["name"] = "wool:red"}, {["x"] = 9, ["y"] = 4, ["z"] = 15, ["name"] = "wool:red"}, {["x"] = 9, ["y"] = 5, ["z"] = 2, ["name"] = "default:steelblock"}, {["x"] = 9, ["y"] = 5, ["z"] = 3, ["name"] = "default:steelblock"}, {["x"] = 9, ["y"] = 5, ["z"] = 4, ["name"] = "default:steelblock"}, {["x"] = 9, ["y"] = 5, ["z"] = 5, ["name"] = "default:steelblock"}, {["x"] = 9, ["y"] = 5, ["z"] = 6, ["name"] = "default:steelblock"}, {["x"] = 9, ["y"] = 5, ["z"] = 7, ["name"] = "default:steelblock"}, {["x"] = 9, ["y"] = 5, ["z"] = 8, ["name"] = "wool:yellow"}, {["x"] = 9, ["y"] = 5, ["z"] = 9, ["name"] = "wool:yellow"}, {["x"] = 9, ["y"] = 5, ["z"] = 10, ["name"] = "wool:yellow"}, {["x"] = 9, ["y"] = 5, ["z"] = 11, ["name"] = "wool:yellow"}, {["x"] = 9, ["y"] = 5, ["z"] = 12, ["name"] = "wool:yellow"}, {["x"] = 9, ["y"] = 5, ["z"] = 13, ["name"] = "wool:yellow"}, {["x"] = 9, ["y"] = 5, ["z"] = 14, ["name"] = "wool:red"}, {["x"] = 9, ["y"] = 5, ["z"] = 15, ["name"] = "wool:red"}, {["x"] = 9, ["y"] = 6, ["z"] = 2, ["name"] = "default:steelblock"}, {["x"] = 9, ["y"] = 6, ["z"] = 3, ["name"] = "default:steelblock"}, {["x"] = 9, ["y"] = 6, ["z"] = 4, ["name"] = "default:steelblock"}, {["x"] = 9, ["y"] = 6, ["z"] = 5, ["name"] = "default:steelblock"}, {["x"] = 9, ["y"] = 6, ["z"] = 6, ["name"] = "default:steelblock"}, {["x"] = 9, ["y"] = 6, ["z"] = 7, ["name"] = "default:steelblock"}, {["x"] = 9, ["y"] = 6, ["z"] = 8, ["name"] = "default:steelblock"}, {["x"] = 9, ["y"] = 6, ["z"] = 9, ["name"] = "default:steelblock"}, {["x"] = 9, ["y"] = 6, ["z"] = 10, ["name"] = "default:steelblock"}, {["x"] = 9, ["y"] = 6, ["z"] = 11, ["name"] = "default:steelblock"}, {["x"] = 9, ["y"] = 6, ["z"] = 12, ["name"] = "default:steelblock"}, {["x"] = 9, ["y"] = 6, ["z"] = 13, ["name"] = "default:steelblock"}, {["x"] = 9, ["y"] = 7, ["z"] = 2, ["name"] = "default:steelblock"}, {["x"] = 9, ["y"] = 7, ["z"] = 3, ["name"] = "default:steelblock"}, {["x"] = 9, ["y"] = 7, ["z"] = 4, ["name"] = "default:steelblock"}, {["x"] = 9, ["y"] = 7, ["z"] = 5, ["name"] = "default:steelblock"}, {["x"] = 9, ["y"] = 7, ["z"] = 6, ["name"] = "default:steelblock"}, {["x"] = 9, ["y"] = 7, ["z"] = 7, ["name"] = "default:steelblock"}, {["x"] = 9, ["y"] = 7, ["z"] = 8, ["name"] = "default:steelblock"}, {["x"] = 9, ["y"] = 7, ["z"] = 9, ["name"] = "default:steelblock"}, {["x"] = 9, ["y"] = 7, ["z"] = 10, ["name"] = "default:steelblock"}, {["x"] = 9, ["y"] = 7, ["z"] = 11, ["name"] = "default:steelblock"}, {["x"] = 9, ["y"] = 7, ["z"] = 12, ["name"] = "default:steelblock"}, {["x"] = 9, ["y"] = 7, ["z"] = 13, ["name"] = "default:steelblock"}, {["x"] = 9, ["y"] = 7, ["z"] = 14, ["name"] = "wool:grey"}, {["x"] = 9, ["y"] = 8, ["z"] = 2, ["name"] = "default:steelblock"}, {["x"] = 9, ["y"] = 8, ["z"] = 3, ["name"] = "default:steelblock"}, {["x"] = 9, ["y"] = 8, ["z"] = 4, ["name"] = "default:steelblock"}, {["x"] = 9, ["y"] = 8, ["z"] = 5, ["name"] = "default:steelblock"}, {["x"] = 9, ["y"] = 8, ["z"] = 6, ["name"] = "default:steelblock"}, {["x"] = 9, ["y"] = 8, ["z"] = 7, ["name"] = "default:steelblock"}, {["x"] = 9, ["y"] = 8, ["z"] = 8, ["name"] = "default:steelblock"}, {["x"] = 9, ["y"] = 8, ["z"] = 9, ["name"] = "default:steelblock"}, {["x"] = 9, ["y"] = 8, ["z"] = 10, ["name"] = "default:steelblock"}, {["x"] = 9, ["y"] = 8, ["z"] = 11, ["name"] = "default:steelblock"}, {["x"] = 9, ["y"] = 8, ["z"] = 12, ["name"] = "default:steelblock"}, {["x"] = 9, ["y"] = 8, ["z"] = 13, ["name"] = "default:steelblock"}, {["x"] = 9, ["y"] = 8, ["z"] = 14, ["name"] = "wool:grey"}, {["x"] = 9, ["y"] = 9, ["z"] = 1, ["name"] = "wool:grey"}, {["x"] = 9, ["y"] = 9, ["z"] = 2, ["name"] = "default:steelblock"}, {["x"] = 9, ["y"] = 9, ["z"] = 3, ["name"] = "default:steelblock"}, {["x"] = 9, ["y"] = 9, ["z"] = 4, ["name"] = "default:steelblock"}, {["x"] = 9, ["y"] = 9, ["z"] = 5, ["name"] = "default:steelblock"}, {["x"] = 9, ["y"] = 9, ["z"] = 6, ["name"] = "default:steelblock"}, {["x"] = 9, ["y"] = 9, ["z"] = 7, ["name"] = "default:steelblock"}, {["x"] = 9, ["y"] = 9, ["z"] = 8, ["name"] = "default:steelblock"}, {["x"] = 9, ["y"] = 9, ["z"] = 9, ["name"] = "default:steelblock"}, {["x"] = 9, ["y"] = 9, ["z"] = 10, ["name"] = "default:steelblock"}, {["x"] = 9, ["y"] = 9, ["z"] = 11, ["name"] = "default:steelblock"}, {["x"] = 9, ["y"] = 9, ["z"] = 12, ["name"] = "default:steelblock"}, {["x"] = 9, ["y"] = 9, ["z"] = 13, ["name"] = "default:steelblock"}, {["x"] = 9, ["y"] = 10, ["z"] = 1, ["name"] = "wool:grey"}, {["x"] = 9, ["y"] = 10, ["z"] = 2, ["name"] = "default:steelblock"}, {["x"] = 9, ["y"] = 10, ["z"] = 3, ["name"] = "default:steelblock"}, {["x"] = 9, ["y"] = 10, ["z"] = 4, ["name"] = "default:steelblock"}, {["x"] = 9, ["y"] = 10, ["z"] = 5, ["name"] = "default:steelblock"}, {["x"] = 9, ["y"] = 10, ["z"] = 6, ["name"] = "default:steelblock"}, {["x"] = 9, ["y"] = 10, ["z"] = 7, ["name"] = "default:steelblock"}, {["x"] = 9, ["y"] = 10, ["z"] = 8, ["name"] = "default:steelblock"}, {["x"] = 9, ["y"] = 10, ["z"] = 9, ["name"] = "default:steelblock"}, {["x"] = 9, ["y"] = 10, ["z"] = 10, ["name"] = "default:steelblock"}, {["x"] = 9, ["y"] = 10, ["z"] = 11, ["name"] = "default:steelblock"}, {["x"] = 9, ["y"] = 10, ["z"] = 12, ["name"] = "default:steelblock"}, {["x"] = 9, ["y"] = 10, ["z"] = 13, ["name"] = "default:steelblock"}, {["x"] = 9, ["y"] = 11, ["z"] = 2, ["name"] = "default:steelblock"}, {["x"] = 9, ["y"] = 11, ["z"] = 3, ["name"] = "default:steelblock"}, {["x"] = 9, ["y"] = 11, ["z"] = 4, ["name"] = "default:steelblock"}, {["x"] = 9, ["y"] = 11, ["z"] = 5, ["name"] = "default:steelblock"}, {["x"] = 9, ["y"] = 11, ["z"] = 6, ["name"] = "default:steelblock"}, {["x"] = 9, ["y"] = 11, ["z"] = 7, ["name"] = "default:steelblock"}, {["x"] = 9, ["y"] = 11, ["z"] = 8, ["name"] = "default:steelblock"}, {["x"] = 9, ["y"] = 11, ["z"] = 9, ["name"] = "default:steelblock"}, {["x"] = 9, ["y"] = 11, ["z"] = 10, ["name"] = "default:stone"}, {["x"] = 9, ["y"] = 11, ["z"] = 11, ["name"] = "default:stone"}, {["x"] = 9, ["y"] = 11, ["z"] = 12, ["name"] = "default:stone"}, {["x"] = 9, ["y"] = 11, ["z"] = 13, ["name"] = "default:stone"}, {["x"] = 9, ["y"] = 12, ["z"] = 2, ["name"] = "default:steelblock"}, {["x"] = 9, ["y"] = 12, ["z"] = 3, ["name"] = "default:steelblock"}, {["x"] = 9, ["y"] = 12, ["z"] = 4, ["name"] = "default:steelblock"}, {["x"] = 9, ["y"] = 12, ["z"] = 5, ["name"] = "default:steelblock"}, {["x"] = 9, ["y"] = 12, ["z"] = 6, ["name"] = "default:steelblock"}, {["x"] = 9, ["y"] = 12, ["z"] = 7, ["name"] = "default:steelblock"}, {["x"] = 9, ["y"] = 12, ["z"] = 8, ["name"] = "default:steelblock"}, {["x"] = 9, ["y"] = 12, ["z"] = 9, ["name"] = "default:steelblock"}, {["x"] = 9, ["y"] = 12, ["z"] = 10, ["name"] = "default:stone"}, {["x"] = 9, ["y"] = 12, ["z"] = 11, ["name"] = "default:stone"}, {["x"] = 9, ["y"] = 12, ["z"] = 12, ["name"] = "default:stone"}, {["x"] = 9, ["y"] = 12, ["z"] = 13, ["name"] = "default:stone"}, {["x"] = 9, ["y"] = 13, ["z"] = 2, ["name"] = "default:steelblock"}, {["x"] = 9, ["y"] = 13, ["z"] = 3, ["name"] = "default:steelblock"}, {["x"] = 9, ["y"] = 13, ["z"] = 4, ["name"] = "default:steelblock"}, {["x"] = 9, ["y"] = 13, ["z"] = 5, ["name"] = "default:steelblock"}, {["x"] = 9, ["y"] = 13, ["z"] = 6, ["name"] = "default:steelblock"}, {["x"] = 9, ["y"] = 13, ["z"] = 7, ["name"] = "default:steelblock"}, {["x"] = 9, ["y"] = 13, ["z"] = 8, ["name"] = "default:steelblock"}, {["x"] = 9, ["y"] = 13, ["z"] = 9, ["name"] = "default:steelblock"}, {["x"] = 9, ["y"] = 13, ["z"] = 10, ["name"] = "default:stone"}, {["x"] = 9, ["y"] = 13, ["z"] = 11, ["name"] = "default:stone"}, {["x"] = 9, ["y"] = 13, ["z"] = 12, ["name"] = "default:stone"}, {["x"] = 9, ["y"] = 13, ["z"] = 13, ["name"] = "default:stone"}, {["x"] = 9, ["y"] = 14, ["z"] = 10, ["name"] = "default:stone"}, {["x"] = 9, ["y"] = 14, ["z"] = 11, ["name"] = "default:stone"}, {["x"] = 9, ["y"] = 14, ["z"] = 12, ["name"] = "default:stone"}, {["x"] = 9, ["y"] = 14, ["z"] = 13, ["name"] = "default:stone"}, {["x"] = 9, ["y"] = 15, ["z"] = 10, ["name"] = "default:stone"}, {["x"] = 9, ["y"] = 15, ["z"] = 11, ["name"] = "default:stone"}, {["x"] = 9, ["y"] = 15, ["z"] = 12, ["name"] = "wool:red"}, {["x"] = 9, ["y"] = 15, ["z"] = 13, ["name"] = "default:stone"}, {["x"] = 10, ["y"] = 0, ["z"] = 2, ["name"] = "default:steelblock"}, {["x"] = 10, ["y"] = 0, ["z"] = 3, ["name"] = "default:steelblock"}, {["x"] = 10, ["y"] = 0, ["z"] = 4, ["name"] = "default:steelblock"}, {["x"] = 10, ["y"] = 0, ["z"] = 5, ["name"] = "default:steelblock"}, {["x"] = 10, ["y"] = 0, ["z"] = 6, ["name"] = "default:steelblock"}, {["x"] = 10, ["y"] = 0, ["z"] = 7, ["name"] = "default:steelblock"}, {["x"] = 10, ["y"] = 0, ["z"] = 8, ["name"] = "default:steelblock"}, {["x"] = 10, ["y"] = 0, ["z"] = 9, ["name"] = "default:steelblock"}, {["x"] = 10, ["y"] = 0, ["z"] = 10, ["name"] = "default:steelblock"}, {["x"] = 10, ["y"] = 0, ["z"] = 11, ["name"] = "default:steelblock"}, {["x"] = 10, ["y"] = 0, ["z"] = 12, ["name"] = "default:steelblock"}, {["x"] = 10, ["y"] = 0, ["z"] = 13, ["name"] = "default:steelblock"}, {["x"] = 10, ["y"] = 1, ["z"] = 2, ["name"] = "default:steelblock"}, {["x"] = 10, ["y"] = 1, ["z"] = 3, ["name"] = "default:steelblock"}, {["x"] = 10, ["y"] = 1, ["z"] = 4, ["name"] = "default:steelblock"}, {["x"] = 10, ["y"] = 1, ["z"] = 5, ["name"] = "default:steelblock"}, {["x"] = 10, ["y"] = 1, ["z"] = 6, ["name"] = "default:steelblock"}, {["x"] = 10, ["y"] = 1, ["z"] = 7, ["name"] = "default:steelblock"}, {["x"] = 10, ["y"] = 1, ["z"] = 8, ["name"] = "default:steelblock"}, {["x"] = 10, ["y"] = 1, ["z"] = 9, ["name"] = "default:steelblock"}, {["x"] = 10, ["y"] = 1, ["z"] = 10, ["name"] = "default:steelblock"}, {["x"] = 10, ["y"] = 1, ["z"] = 11, ["name"] = "default:steelblock"}, {["x"] = 10, ["y"] = 1, ["z"] = 12, ["name"] = "default:steelblock"}, {["x"] = 10, ["y"] = 1, ["z"] = 13, ["name"] = "default:steelblock"}, {["x"] = 10, ["y"] = 2, ["z"] = 1, ["name"] = "wool:grey"}, {["x"] = 10, ["y"] = 2, ["z"] = 2, ["name"] = "default:steelblock"}, {["x"] = 10, ["y"] = 2, ["z"] = 3, ["name"] = "default:steelblock"}, {["x"] = 10, ["y"] = 2, ["z"] = 4, ["name"] = "default:steelblock"}, {["x"] = 10, ["y"] = 2, ["z"] = 5, ["name"] = "default:steelblock"}, {["x"] = 10, ["y"] = 2, ["z"] = 6, ["name"] = "default:steelblock"}, {["x"] = 10, ["y"] = 2, ["z"] = 7, ["name"] = "default:steelblock"}, {["x"] = 10, ["y"] = 2, ["z"] = 8, ["name"] = "default:steelblock"}, {["x"] = 10, ["y"] = 2, ["z"] = 9, ["name"] = "default:steelblock"}, {["x"] = 10, ["y"] = 2, ["z"] = 10, ["name"] = "default:steelblock"}, {["x"] = 10, ["y"] = 2, ["z"] = 11, ["name"] = "default:steelblock"}, {["x"] = 10, ["y"] = 2, ["z"] = 12, ["name"] = "default:steelblock"}, {["x"] = 10, ["y"] = 2, ["z"] = 13, ["name"] = "default:steelblock"}, {["x"] = 10, ["y"] = 3, ["z"] = 1, ["name"] = "wool:grey"}, {["x"] = 10, ["y"] = 3, ["z"] = 2, ["name"] = "default:steelblock"}, {["x"] = 10, ["y"] = 3, ["z"] = 3, ["name"] = "default:steelblock"}, {["x"] = 10, ["y"] = 3, ["z"] = 4, ["name"] = "default:steelblock"}, {["x"] = 10, ["y"] = 3, ["z"] = 5, ["name"] = "default:steelblock"}, {["x"] = 10, ["y"] = 3, ["z"] = 6, ["name"] = "default:steelblock"}, {["x"] = 10, ["y"] = 3, ["z"] = 7, ["name"] = "default:steelblock"}, {["x"] = 10, ["y"] = 3, ["z"] = 8, ["name"] = "default:steelblock"}, {["x"] = 10, ["y"] = 3, ["z"] = 9, ["name"] = "default:steelblock"}, {["x"] = 10, ["y"] = 3, ["z"] = 10, ["name"] = "default:steelblock"}, {["x"] = 10, ["y"] = 3, ["z"] = 11, ["name"] = "default:steelblock"}, {["x"] = 10, ["y"] = 3, ["z"] = 12, ["name"] = "default:steelblock"}, {["x"] = 10, ["y"] = 3, ["z"] = 13, ["name"] = "default:steelblock"}, {["x"] = 10, ["y"] = 4, ["z"] = 2, ["name"] = "default:steelblock"}, {["x"] = 10, ["y"] = 4, ["z"] = 3, ["name"] = "default:steelblock"}, {["x"] = 10, ["y"] = 4, ["z"] = 4, ["name"] = "default:steelblock"}, {["x"] = 10, ["y"] = 4, ["z"] = 5, ["name"] = "default:steelblock"}, {["x"] = 10, ["y"] = 4, ["z"] = 6, ["name"] = "default:steelblock"}, {["x"] = 10, ["y"] = 4, ["z"] = 7, ["name"] = "default:steelblock"}, {["x"] = 10, ["y"] = 4, ["z"] = 8, ["name"] = "default:steelblock"}, {["x"] = 10, ["y"] = 4, ["z"] = 9, ["name"] = "default:steelblock"}, {["x"] = 10, ["y"] = 4, ["z"] = 10, ["name"] = "default:steelblock"}, {["x"] = 10, ["y"] = 4, ["z"] = 11, ["name"] = "default:steelblock"}, {["x"] = 10, ["y"] = 4, ["z"] = 12, ["name"] = "default:steelblock"}, {["x"] = 10, ["y"] = 4, ["z"] = 13, ["name"] = "default:steelblock"}, {["x"] = 10, ["y"] = 5, ["z"] = 2, ["name"] = "default:steelblock"}, {["x"] = 10, ["y"] = 5, ["z"] = 3, ["name"] = "default:steelblock"}, {["x"] = 10, ["y"] = 5, ["z"] = 4, ["name"] = "default:steelblock"}, {["x"] = 10, ["y"] = 5, ["z"] = 5, ["name"] = "default:steelblock"}, {["x"] = 10, ["y"] = 5, ["z"] = 6, ["name"] = "default:steelblock"}, {["x"] = 10, ["y"] = 5, ["z"] = 7, ["name"] = "default:steelblock"}, {["x"] = 10, ["y"] = 5, ["z"] = 8, ["name"] = "default:steelblock"}, {["x"] = 10, ["y"] = 5, ["z"] = 9, ["name"] = "default:steelblock"}, {["x"] = 10, ["y"] = 5, ["z"] = 10, ["name"] = "default:steelblock"}, {["x"] = 10, ["y"] = 5, ["z"] = 11, ["name"] = "default:steelblock"}, {["x"] = 10, ["y"] = 5, ["z"] = 12, ["name"] = "default:steelblock"}, {["x"] = 10, ["y"] = 5, ["z"] = 13, ["name"] = "default:steelblock"}, {["x"] = 10, ["y"] = 6, ["z"] = 2, ["name"] = "default:steelblock"}, {["x"] = 10, ["y"] = 6, ["z"] = 3, ["name"] = "default:steelblock"}, {["x"] = 10, ["y"] = 6, ["z"] = 4, ["name"] = "default:steelblock"}, {["x"] = 10, ["y"] = 6, ["z"] = 5, ["name"] = "default:steelblock"}, {["x"] = 10, ["y"] = 6, ["z"] = 6, ["name"] = "default:steelblock"}, {["x"] = 10, ["y"] = 6, ["z"] = 7, ["name"] = "default:steelblock"}, {["x"] = 10, ["y"] = 6, ["z"] = 8, ["name"] = "default:steelblock"}, {["x"] = 10, ["y"] = 6, ["z"] = 9, ["name"] = "default:steelblock"}, {["x"] = 10, ["y"] = 6, ["z"] = 10, ["name"] = "default:steelblock"}, {["x"] = 10, ["y"] = 6, ["z"] = 11, ["name"] = "default:steelblock"}, {["x"] = 10, ["y"] = 6, ["z"] = 12, ["name"] = "default:steelblock"}, {["x"] = 10, ["y"] = 6, ["z"] = 13, ["name"] = "default:steelblock"}, {["x"] = 10, ["y"] = 7, ["z"] = 2, ["name"] = "default:steelblock"}, {["x"] = 10, ["y"] = 7, ["z"] = 3, ["name"] = "default:steelblock"}, {["x"] = 10, ["y"] = 7, ["z"] = 4, ["name"] = "default:steelblock"}, {["x"] = 10, ["y"] = 7, ["z"] = 5, ["name"] = "default:steelblock"}, {["x"] = 10, ["y"] = 7, ["z"] = 6, ["name"] = "default:steelblock"}, {["x"] = 10, ["y"] = 7, ["z"] = 7, ["name"] = "default:steelblock"}, {["x"] = 10, ["y"] = 7, ["z"] = 8, ["name"] = "default:steelblock"}, {["x"] = 10, ["y"] = 7, ["z"] = 9, ["name"] = "default:steelblock"}, {["x"] = 10, ["y"] = 7, ["z"] = 10, ["name"] = "default:steelblock"}, {["x"] = 10, ["y"] = 7, ["z"] = 11, ["name"] = "default:steelblock"}, {["x"] = 10, ["y"] = 7, ["z"] = 12, ["name"] = "default:steelblock"}, {["x"] = 10, ["y"] = 7, ["z"] = 13, ["name"] = "default:steelblock"}, {["x"] = 10, ["y"] = 7, ["z"] = 14, ["name"] = "wool:grey"}, {["x"] = 10, ["y"] = 8, ["z"] = 2, ["name"] = "default:steelblock"}, {["x"] = 10, ["y"] = 8, ["z"] = 3, ["name"] = "default:steelblock"}, {["x"] = 10, ["y"] = 8, ["z"] = 4, ["name"] = "default:steelblock"}, {["x"] = 10, ["y"] = 8, ["z"] = 5, ["name"] = "default:steelblock"}, {["x"] = 10, ["y"] = 8, ["z"] = 6, ["name"] = "default:steelblock"}, {["x"] = 10, ["y"] = 8, ["z"] = 7, ["name"] = "default:steelblock"}, {["x"] = 10, ["y"] = 8, ["z"] = 8, ["name"] = "default:steelblock"}, {["x"] = 10, ["y"] = 8, ["z"] = 9, ["name"] = "default:steelblock"}, {["x"] = 10, ["y"] = 8, ["z"] = 10, ["name"] = "default:steelblock"}, {["x"] = 10, ["y"] = 8, ["z"] = 11, ["name"] = "default:steelblock"}, {["x"] = 10, ["y"] = 8, ["z"] = 12, ["name"] = "default:steelblock"}, {["x"] = 10, ["y"] = 8, ["z"] = 13, ["name"] = "default:steelblock"}, {["x"] = 10, ["y"] = 8, ["z"] = 14, ["name"] = "wool:grey"}, {["x"] = 10, ["y"] = 9, ["z"] = 1, ["name"] = "wool:grey"}, {["x"] = 10, ["y"] = 9, ["z"] = 2, ["name"] = "default:steelblock"}, {["x"] = 10, ["y"] = 9, ["z"] = 3, ["name"] = "default:steelblock"}, {["x"] = 10, ["y"] = 9, ["z"] = 4, ["name"] = "default:steelblock"}, {["x"] = 10, ["y"] = 9, ["z"] = 5, ["name"] = "default:steelblock"}, {["x"] = 10, ["y"] = 9, ["z"] = 6, ["name"] = "default:steelblock"}, {["x"] = 10, ["y"] = 9, ["z"] = 7, ["name"] = "default:steelblock"}, {["x"] = 10, ["y"] = 9, ["z"] = 8, ["name"] = "default:steelblock"}, {["x"] = 10, ["y"] = 9, ["z"] = 9, ["name"] = "default:steelblock"}, {["x"] = 10, ["y"] = 9, ["z"] = 10, ["name"] = "default:steelblock"}, {["x"] = 10, ["y"] = 9, ["z"] = 11, ["name"] = "default:steelblock"}, {["x"] = 10, ["y"] = 9, ["z"] = 12, ["name"] = "default:steelblock"}, {["x"] = 10, ["y"] = 9, ["z"] = 13, ["name"] = "default:steelblock"}, {["x"] = 10, ["y"] = 10, ["z"] = 1, ["name"] = "wool:grey"}, {["x"] = 10, ["y"] = 10, ["z"] = 2, ["name"] = "default:steelblock"}, {["x"] = 10, ["y"] = 10, ["z"] = 3, ["name"] = "default:steelblock"}, {["x"] = 10, ["y"] = 10, ["z"] = 4, ["name"] = "default:steelblock"}, {["x"] = 10, ["y"] = 10, ["z"] = 5, ["name"] = "default:steelblock"}, {["x"] = 10, ["y"] = 10, ["z"] = 6, ["name"] = "default:steelblock"}, {["x"] = 10, ["y"] = 10, ["z"] = 7, ["name"] = "default:steelblock"},