5:return {{["param1"] = 87, ["x"] = 0, ["y"] = 0, ["z"] = 0, ["meta"] = {["inventory"] = {}, ["fields"] = {}}, ["name"] = "wool:grey"}, {["param1"] = 87, ["x"] = 0, ["y"] = 0, ["z"] = 1, ["meta"] = {["inventory"] = {}, ["fields"] = {}}, ["name"] = "wool:grey"}, {["param1"] = 87, ["x"] = 0, ["y"] = 0, ["z"] = 14, ["meta"] = {["inventory"] = {}, ["fields"] = {}}, ["name"] = "wool:grey"}, {["param1"] = 87, ["x"] = 0, ["y"] = 0, ["z"] = 15, ["meta"] = {["inventory"] = {}, ["fields"] = {}}, ["name"] = "wool:grey"}, {["param1"] = 87, ["x"] = 0, ["y"] = 1, ["z"] = 0, ["meta"] = {["inventory"] = {}, ["fields"] = {}}, ["name"] = "wool:grey"}, {["param1"] = 87, ["x"] = 0, ["y"] = 1, ["z"] = 1, ["meta"] = {["inventory"] = {}, ["fields"] = {}}, ["name"] = "wool:grey"}, {["param1"] = 87, ["x"] = 0, ["y"] = 1, ["z"] = 14, ["meta"] = {["inventory"] = {}, ["fields"] = {}}, ["name"] = "wool:grey"}, {["param1"] = 87, ["x"] = 0, ["y"] = 1, ["z"] = 15, ["meta"] = {["inventory"] = {}, ["fields"] = {}}, ["name"] = "wool:grey"}, {["param1"] = 87, ["x"] = 0, ["y"] = 2, ["z"] = 0, ["meta"] = {["inventory"] = {}, ["fields"] = {}}, ["name"] = "wool:grey"}, {["param1"] = 87, ["x"] = 0, ["y"] = 2, ["z"] = 1, ["meta"] = {["inventory"] = {}, ["fields"] = {}}, ["name"] = "wool:grey"}, {["param1"] = 87, ["x"] = 0, ["y"] = 2, ["z"] = 14, ["meta"] = {["inventory"] = {}, ["fields"] = {}}, ["name"] = "wool:grey"}, {["param1"] = 87, ["x"] = 0, ["y"] = 2, ["z"] = 15, ["meta"] = {["inventory"] = {}, ["fields"] = {}}, ["name"] = "wool:grey"}, {["param1"] = 87, ["x"] = 0, ["y"] = 3, ["z"] = 0, ["meta"] = {["inventory"] = {}, ["fields"] = {}}, ["name"] = "wool:grey"}, {["param1"] = 87, ["x"] = 0, ["y"] = 3, ["z"] = 1, ["meta"] = {["inventory"] = {}, ["fields"] = {}}, ["name"] = "wool:grey"}, {["param1"] = 87, ["x"] = 0, ["y"] = 3, ["z"] = 14, ["meta"] = {["inventory"] = {}, ["fields"] = {}}, ["name"] = "wool:grey"}, {["param1"] = 87, ["x"] = 0, ["y"] = 3, ["z"] = 15, ["meta"] = {["inventory"] = {}, ["fields"] = {}}, ["name"] = "wool:grey"}, {["param1"] = 87, ["x"] = 0, ["y"] = 4, ["z"] = 0, ["meta"] = {["inventory"] = {}, ["fields"] = {}}, ["name"] = "wool:grey"}, {["param1"] = 87, ["x"] = 0, ["y"] = 4, ["z"] = 1, ["meta"] = {["inventory"] = {}, ["fields"] = {}}, ["name"] = "wool:grey"}, {["param1"] = 87, ["x"] = 0, ["y"] = 4, ["z"] = 14, ["meta"] = {["inventory"] = {}, ["fields"] = {}}, ["name"] = "wool:grey"}, {["param1"] = 87, ["x"] = 0, ["y"] = 4, ["z"] = 15, ["meta"] = {["inventory"] = {}, ["fields"] = {}}, ["name"] = "wool:grey"}, {["param1"] = 87, ["x"] = 0, ["y"] = 5, ["z"] = 0, ["meta"] = {["inventory"] = {}, ["fields"] = {}}, ["name"] = "wool:grey"}, {["param1"] = 87, ["x"] = 0, ["y"] = 5, ["z"] = 1, ["meta"] = {["inventory"] = {}, ["fields"] = {}}, ["name"] = "wool:grey"}, {["param1"] = 87, ["x"] = 0, ["y"] = 5, ["z"] = 14, ["meta"] = {["inventory"] = {}, ["fields"] = {}}, ["name"] = "wool:grey"}, {["param1"] = 87, ["x"] = 0, ["y"] = 5, ["z"] = 15, ["meta"] = {["inventory"] = {}, ["fields"] = {}}, ["name"] = "wool:grey"}, {["param1"] = 87, ["x"] = 0, ["y"] = 6, ["z"] = 0, ["meta"] = {["inventory"] = {}, ["fields"] = {}}, ["name"] = "wool:grey"}, {["param1"] = 87, ["x"] = 0, ["y"] = 6, ["z"] = 1, ["meta"] = {["inventory"] = {}, ["fields"] = {}}, ["name"] = "wool:grey"}, {["param1"] = 87, ["x"] = 0, ["y"] = 6, ["z"] = 14, ["meta"] = {["inventory"] = {}, ["fields"] = {}}, ["name"] = "wool:grey"}, {["param1"] = 87, ["x"] = 0, ["y"] = 6, ["z"] = 15, ["meta"] = {["inventory"] = {}, ["fields"] = {}}, ["name"] = "wool:grey"}, {["param1"] = 87, ["x"] = 0, ["y"] = 7, ["z"] = 0, ["meta"] = {["inventory"] = {}, ["fields"] = {}}, ["name"] = "wool:grey"}, {["param1"] = 87, ["x"] = 0, ["y"] = 7, ["z"] = 1, ["meta"] = {["inventory"] = {}, ["fields"] = {}}, ["name"] = "wool:grey"}, {["param1"] = 95, ["x"] = 0, ["y"] = 7, ["z"] = 7, ["meta"] = {["inventory"] = {}, ["fields"] = {}}, ["name"] = "wool:yellow"}, {["param1"] = 95, ["x"] = 0, ["y"] = 7, ["z"] = 8, ["meta"] = {["inventory"] = {}, ["fields"] = {}}, ["name"] = "wool:yellow"}, {["param1"] = 87, ["x"] = 0, ["y"] = 7, ["z"] = 14, ["meta"] = {["inventory"] = {}, ["fields"] = {}}, ["name"] = "wool:grey"}, {["param1"] = 87, ["x"] = 0, ["y"] = 7, ["z"] = 15, ["meta"] = {["inventory"] = {}, ["fields"] = {}}, ["name"] = "wool:grey"}, {["param1"] = 87, ["x"] = 0, ["y"] = 8, ["z"] = 0, ["meta"] = {["inventory"] = {}, ["fields"] = {}}, ["name"] = "wool:grey"}, {["param1"] = 87, ["x"] = 0, ["y"] = 8, ["z"] = 1, ["meta"] = {["inventory"] = {}, ["fields"] = {}}, ["name"] = "wool:grey"}, {["param1"] = 95, ["x"] = 0, ["y"] = 8, ["z"] = 7, ["meta"] = {["inventory"] = {}, ["fields"] = {}}, ["name"] = "wool:yellow"}, {["param1"] = 95, ["x"] = 0, ["y"] = 8, ["z"] = 8, ["meta"] = {["inventory"] = {}, ["fields"] = {}}, ["name"] = "wool:yellow"}, {["param1"] = 87, ["x"] = 0, ["y"] = 8, ["z"] = 14, ["meta"] = {["inventory"] = {}, ["fields"] = {}}, ["name"] = "wool:grey"}, {["param1"] = 87, ["x"] = 0, ["y"] = 8, ["z"] = 15, ["meta"] = {["inventory"] = {}, ["fields"] = {}}, ["name"] = "wool:grey"}, {["param1"] = 87, ["x"] = 0, ["y"] = 9, ["z"] = 0, ["meta"] = {["inventory"] = {}, ["fields"] = {}}, ["name"] = "wool:grey"}, {["param1"] = 87, ["x"] = 0, ["y"] = 9, ["z"] = 1, ["meta"] = {["inventory"] = {}, ["fields"] = {}}, ["name"] = "wool:grey"}, {["param1"] = 87, ["x"] = 0, ["y"] = 9, ["z"] = 14, ["meta"] = {["inventory"] = {}, ["fields"] = {}}, ["name"] = "wool:grey"}, {["param1"] = 87, ["x"] = 0, ["y"] = 9, ["z"] = 15, ["meta"] = {["inventory"] = {}, ["fields"] = {}}, ["name"] = "wool:grey"}, {["param1"] = 87, ["x"] = 0, ["y"] = 10, ["z"] = 0, ["meta"] = {["inventory"] = {}, ["fields"] = {}}, ["name"] = "wool:grey"}, {["param1"] = 87, ["x"] = 0, ["y"] = 10, ["z"] = 1, ["meta"] = {["inventory"] = {}, ["fields"] = {}}, ["name"] = "wool:grey"}, {["param1"] = 87, ["x"] = 0, ["y"] = 10, ["z"] = 14, ["meta"] = {["inventory"] = {}, ["fields"] = {}}, ["name"] = "wool:grey"}, {["param1"] = 87, ["x"] = 0, ["y"] = 10, ["z"] = 15, ["meta"] = {["inventory"] = {}, ["fields"] = {}}, ["name"] = "wool:grey"}, {["param1"] = 87, ["x"] = 0, ["y"] = 11, ["z"] = 0, ["meta"] = {["inventory"] = {}, ["fields"] = {}}, ["name"] = "wool:grey"}, {["param1"] = 87, ["x"] = 0, ["y"] = 11, ["z"] = 1, ["meta"] = {["inventory"] = {}, ["fields"] = {}}, ["name"] = "wool:grey"}, {["param1"] = 87, ["x"] = 0, ["y"] = 11, ["z"] = 14, ["meta"] = {["inventory"] = {}, ["fields"] = {}}, ["name"] = "wool:grey"}, {["param1"] = 87, ["x"] = 0, ["y"] = 11, ["z"] = 15, ["meta"] = {["inventory"] = {}, ["fields"] = {}}, ["name"] = "wool:grey"}, {["param1"] = 87, ["x"] = 0, ["y"] = 12, ["z"] = 0, ["meta"] = {["inventory"] = {}, ["fields"] = {}}, ["name"] = "wool:grey"}, {["param1"] = 87, ["x"] = 0, ["y"] = 12, ["z"] = 1, ["meta"] = {["inventory"] = {}, ["fields"] = {}}, ["name"] = "wool:grey"}, {["param1"] = 87, ["x"] = 0, ["y"] = 12, ["z"] = 14, ["meta"] = {["inventory"] = {}, ["fields"] = {}}, ["name"] = "wool:grey"}, {["param1"] = 87, ["x"] = 0, ["y"] = 12, ["z"] = 15, ["meta"] = {["inventory"] = {}, ["fields"] = {}}, ["name"] = "wool:grey"}, {["param1"] = 87, ["x"] = 0, ["y"] = 13, ["z"] = 0, ["meta"] = {["inventory"] = {}, ["fields"] = {}}, ["name"] = "wool:grey"}, {["param1"] = 87, ["x"] = 0, ["y"] = 13, ["z"] = 1, ["meta"] = {["inventory"] = {}, ["fields"] = {}}, ["name"] = "wool:grey"}, {["param1"] = 87, ["x"] = 0, ["y"] = 13, ["z"] = 14, ["meta"] = {["inventory"] = {}, ["fields"] = {}}, ["name"] = "wool:grey"}, {["param1"] = 87, ["x"] = 0, ["y"] = 13, ["z"] = 15, ["meta"] = {["inventory"] = {}, ["fields"] = {}}, ["name"] = "wool:grey"}, {["param1"] = 87, ["x"] = 0, ["y"] = 14, ["z"] = 0, ["meta"] = {["inventory"] = {}, ["fields"] = {}}, ["name"] = "wool:grey"}, {["param1"] = 87, ["x"] = 0, ["y"] = 14, ["z"] = 1, ["meta"] = {["inventory"] = {}, ["fields"] = {}}, ["name"] = "wool:grey"}, {["param1"] = 87, ["x"] = 0, ["y"] = 14, ["z"] = 14, ["meta"] = {["inventory"] = {}, ["fields"] = {}}, ["name"] = "wool:grey"}, {["param1"] = 87, ["x"] = 0, ["y"] = 14, ["z"] = 15, ["meta"] = {["inventory"] = {}, ["fields"] = {}}, ["name"] = "wool:grey"}, {["param1"] = 87, ["x"] = 0, ["y"] = 15, ["z"] = 0, ["meta"] = {["inventory"] = {}, ["fields"] = {}}, ["name"] = "wool:grey"}, {["param1"] = 87, ["x"] = 0, ["y"] = 15, ["z"] = 1, ["meta"] = {["inventory"] = {}, ["fields"] = {}}, ["name"] = "wool:grey"}, {["param1"] = 87, ["x"] = 0, ["y"] = 15, ["z"] = 14, ["meta"] = {["inventory"] = {}, ["fields"] = {}}, ["name"] = "wool:grey"}, {["param1"] = 87, ["x"] = 0, ["y"] = 15, ["z"] = 15, ["meta"] = {["inventory"] = {}, ["fields"] = {}}, ["name"] = "wool:grey"}, {["param1"] = 87, ["x"] = 1, ["y"] = 0, ["z"] = 0, ["meta"] = {["inventory"] = {}, ["fields"] = {}}, ["name"] = "wool:grey"}, {["param1"] = 87, ["x"] = 1, ["y"] = 0, ["z"] = 1, ["meta"] = {["inventory"] = {}, ["fields"] = {}}, ["name"] = "wool:grey"}, {["param1"] = 87, ["x"] = 1, ["y"] = 0, ["z"] = 14, ["meta"] = {["inventory"] = {}, ["fields"] = {}}, ["name"] = "wool:grey"}, {["param1"] = 87, ["x"] = 1, ["y"] = 0, ["z"] = 15, ["meta"] = {["inventory"] = {}, ["fields"] = {}}, ["name"] = "wool:grey"}, {["param1"] = 87, ["x"] = 1, ["y"] = 1, ["z"] = 0, ["meta"] = {["inventory"] = {}, ["fields"] = {}}, ["name"] = "wool:grey"}, {["param1"] = 87, ["x"] = 1, ["y"] = 1, ["z"] = 1, ["meta"] = {["inventory"] = {}, ["fields"] = {}}, ["name"] = "wool:grey"}, {["param1"] = 87, ["x"] = 1, ["y"] = 1, ["z"] = 14, ["meta"] = {["inventory"] = {}, ["fields"] = {}}, ["name"] = "wool:grey"}, {["param1"] = 87, ["x"] = 1, ["y"] = 1, ["z"] = 15, ["meta"] = {["inventory"] = {}, ["fields"] = {}}, ["name"] = "wool:grey"}, {["param1"] = 87, ["x"] = 1, ["y"] = 2, ["z"] = 0, ["meta"] = {["inventory"] = {}, ["fields"] = {}}, ["name"] = "wool:grey"}, {["param1"] = 87, ["x"] = 1, ["y"] = 2, ["z"] = 1, ["meta"] = {["inventory"] = {}, ["fields"] = {}}, ["name"] = "wool:grey"}, {["param1"] = 87, ["x"] = 1, ["y"] = 2, ["z"] = 14, ["meta"] = {["inventory"] = {}, ["fields"] = {}}, ["name"] = "wool:grey"}, {["param1"] = 87, ["x"] = 1, ["y"] = 2, ["z"] = 15, ["meta"] = {["inventory"] = {}, ["fields"] = {}}, ["name"] = "wool:grey"}, {["param1"] = 87, ["x"] = 1, ["y"] = 3, ["z"] = 0, ["meta"] = {["inventory"] = {}, ["fields"] = {}}, ["name"] = "wool:grey"}, {["param1"] = 87, ["x"] = 1, ["y"] = 3, ["z"] = 1, ["meta"] = {["inventory"] = {}, ["fields"] = {}}, ["name"] = "wool:grey"}, {["param1"] = 87, ["x"] = 1, ["y"] = 3, ["z"] = 14, ["meta"] = {["inventory"] = {}, ["fields"] = {}}, ["name"] = "wool:grey"}, {["param1"] = 87, ["x"] = 1, ["y"] = 3, ["z"] = 15, ["meta"] = {["inventory"] = {}, ["fields"] = {}}, ["name"] = "wool:grey"}, {["param1"] = 87, ["x"] = 1, ["y"] = 4, ["z"] = 0, ["meta"] = {["inventory"] = {}, ["fields"] = {}}, ["name"] = "wool:grey"}, {["param1"] = 87, ["x"] = 1, ["y"] = 4, ["z"] = 1, ["meta"] = {["inventory"] = {}, ["fields"] = {}}, ["name"] = "wool:grey"}, {["param1"] = 87, ["x"] = 1, ["y"] = 4, ["z"] = 14, ["meta"] = {["inventory"] = {}, ["fields"] = {}}, ["name"] = "wool:grey"}, {["param1"] = 87, ["x"] = 1, ["y"] = 4, ["z"] = 15, ["meta"] = {["inventory"] = {}, ["fields"] = {}}, ["name"] = "wool:grey"}, {["param1"] = 87, ["x"] = 1, ["y"] = 5, ["z"] = 0, ["meta"] = {["inventory"] = {}, ["fields"] = {}}, ["name"] = "wool:grey"}, {["param1"] = 87, ["x"] = 1, ["y"] = 5, ["z"] = 1, ["meta"] = {["inventory"] = {}, ["fields"] = {}}, ["name"] = "wool:grey"}, {["param1"] = 87, ["x"] = 1, ["y"] = 5, ["z"] = 14, ["meta"] = {["inventory"] = {}, ["fields"] = {}}, ["name"] = "wool:grey"}, {["param1"] = 87, ["x"] = 1, ["y"] = 5, ["z"] = 15, ["meta"] = {["inventory"] = {}, ["fields"] = {}}, ["name"] = "wool:grey"}, {["param1"] = 87, ["x"] = 1, ["y"] = 6, ["z"] = 0, ["meta"] = {["inventory"] = {}, ["fields"] = {}}, ["name"] = "wool:grey"}, {["param1"] = 87, ["x"] = 1, ["y"] = 6, ["z"] = 1, ["meta"] = {["inventory"] = {}, ["fields"] = {}}, ["name"] = "wool:grey"}, {["param1"] = 87, ["x"] = 1, ["y"] = 6, ["z"] = 2, ["meta"] = {["inventory"] = {}, ["fields"] = {}}, ["name"] = "wool:grey"}, {["param1"] = 87, ["x"] = 1, ["y"] = 6, ["z"] = 3, ["meta"] = {["inventory"] = {}, ["fields"] = {}}, ["name"] = "wool:grey"}, {["param1"] = 87, ["x"] = 1, ["y"] = 6, ["z"] = 4, ["meta"] = {["inventory"] = {}, ["fields"] = {}}, ["name"] = "wool:grey"}, {["param1"] = 87, ["x"] = 1, ["y"] = 6, ["z"] = 5, ["meta"] = {["inventory"] = {}, ["fields"] = {}}, ["name"] = "wool:grey"}, {["param1"] = 87, ["x"] = 1, ["y"] = 6, ["z"] = 6, ["meta"] = {["inventory"] = {}, ["fields"] = {}}, ["name"] = "wool:grey"}, {["param1"] = 87, ["x"] = 1, ["y"] = 6, ["z"] = 7, ["meta"] = {["inventory"] = {}, ["fields"] = {}}, ["name"] = "wool:grey"}, {["param1"] = 87, ["x"] = 1, ["y"] = 6, ["z"] = 8, ["meta"] = {["inventory"] = {}, ["fields"] = {}}, ["name"] = "wool:grey"}, {["param1"] = 87, ["x"] = 1, ["y"] = 6, ["z"] = 9, ["meta"] = {["inventory"] = {}, ["fields"] = {}}, ["name"] = "wool:grey"}, {["param1"] = 87, ["x"] = 1, ["y"] = 6, ["z"] = 10, ["meta"] = {["inventory"] = {}, ["fields"] = {}}, ["name"] = "wool:grey"}, {["param1"] = 87, ["x"] = 1, ["y"] = 6, ["z"] = 11, ["meta"] = {["inventory"] = {}, ["fields"] = {}}, ["name"] = "wool:grey"}, {["param1"] = 87, ["x"] = 1, ["y"] = 6, ["z"] = 12, ["meta"] = {["inventory"] = {}, ["fields"] = {}}, ["name"] = "wool:grey"}, {["param1"] = 87, ["x"] = 1, ["y"] = 6, ["z"] = 13, ["meta"] = {["inventory"] = {}, ["fields"] = {}}, ["name"] = "wool:grey"}, {["param1"] = 87, ["x"] = 1, ["y"] = 6, ["z"] = 14, ["meta"] = {["inventory"] = {}, ["fields"] = {}}, ["name"] = "wool:grey"}, {["param1"] = 87, ["x"] = 1, ["y"] = 6, ["z"] = 15, ["meta"] = {["inventory"] = {}, ["fields"] = {}}, ["name"] = "wool:grey"}, {["param1"] = 87, ["x"] = 1, ["y"] = 7, ["z"] = 0, ["meta"] = {["inventory"] = {}, ["fields"] = {}}, ["name"] = "wool:grey"}, {["param1"] = 87, ["x"] = 1, ["y"] = 7, ["z"] = 1, ["meta"] = {["inventory"] = {}, ["fields"] = {}}, ["name"] = "wool:grey"}, {["param1"] = 87, ["x"] = 1, ["y"] = 7, ["z"] = 6, ["meta"] = {["inventory"] = {}, ["fields"] = {}}, ["name"] = "wool:grey"}, {["param1"] = 95, ["x"] = 1, ["y"] = 7, ["z"] = 7, ["meta"] = {["inventory"] = {}, ["fields"] = {}}, ["name"] = "wool:yellow"}, {["param1"] = 95, ["x"] = 1, ["y"] = 7, ["z"] = 8, ["meta"] = {["inventory"] = {}, ["fields"] = {}}, ["name"] = "wool:yellow"}, {["param1"] = 87, ["x"] = 1, ["y"] = 7, ["z"] = 9, ["meta"] = {["inventory"] = {}, ["fields"] = {}}, ["name"] = "wool:grey"}, {["param1"] = 87, ["x"] = 1, ["y"] = 7, ["z"] = 14, ["meta"] = {["inventory"] = {}, ["fields"] = {}}, ["name"] = "wool:grey"}, {["param1"] = 87, ["x"] = 1, ["y"] = 7, ["z"] = 15, ["meta"] = {["inventory"] = {}, ["fields"] = {}}, ["name"] = "wool:grey"}, {["param1"] = 87, ["x"] = 1, ["y"] = 8, ["z"] = 0, ["meta"] = {["inventory"] = {}, ["fields"] = {}}, ["name"] = "wool:grey"}, {["param1"] = 87, ["x"] = 1, ["y"] = 8, ["z"] = 1, ["meta"] = {["inventory"] = {}, ["fields"] = {}}, ["name"] = "wool:grey"}, {["param1"] = 87, ["x"] = 1, ["y"] = 8, ["z"] = 6, ["meta"] = {["inventory"] = {}, ["fields"] = {}}, ["name"] = "wool:grey"}, {["param1"] = 95, ["x"] = 1, ["y"] = 8, ["z"] = 7, ["meta"] = {["inventory"] = {}, ["fields"] = {}}, ["name"] = "wool:yellow"}, {["param1"] = 95, ["x"] = 1, ["y"] = 8, ["z"] = 8, ["meta"] = {["inventory"] = {}, ["fields"] = {}}, ["name"] = "wool:yellow"}, {["param1"] = 87, ["x"] = 1, ["y"] = 8, ["z"] = 9, ["meta"] = {["inventory"] = {}, ["fields"] = {}}, ["name"] = "wool:grey"}, {["param1"] = 87, ["x"] = 1, ["y"] = 8, ["z"] = 14, ["meta"] = {["inventory"] = {}, ["fields"] = {}}, ["name"] = "wool:grey"}, {["param1"] = 87, ["x"] = 1, ["y"] = 8, ["z"] = 15, ["meta"] = {["inventory"] = {}, ["fields"] = {}}, ["name"] = "wool:grey"}, {["param1"] = 87, ["x"] = 1, ["y"] = 9, ["z"] = 0, ["meta"] = {["inventory"] = {}, ["fields"] = {}}, ["name"] = "wool:grey"}, {["param1"] = 87, ["x"] = 1, ["y"] = 9, ["z"] = 1, ["meta"] = {["inventory"] = {}, ["fields"] = {}}, ["name"] = "wool:grey"}, {["param1"] = 87, ["x"] = 1, ["y"] = 9, ["z"] = 2, ["meta"] = {["inventory"] = {}, ["fields"] = {}}, ["name"] = "wool:grey"}, {["param1"] = 87, ["x"] = 1, ["y"] = 9, ["z"] = 3, ["meta"] = {["inventory"] = {}, ["fields"] = {}}, ["name"] = "wool:grey"}, {["param1"] = 87, ["x"] = 1, ["y"] = 9, ["z"] = 4, ["meta"] = {["inventory"] = {}, ["fields"] = {}}, ["name"] = "wool:grey"}, {["param1"] = 87, ["x"] = 1, ["y"] = 9, ["z"] = 5, ["meta"] = {["inventory"] = {}, ["fields"] = {}}, ["name"] = "wool:grey"}, {["param1"] = 87, ["x"] = 1, ["y"] = 9, ["z"] = 6, ["meta"] = {["inventory"] = {}, ["fields"] = {}}, ["name"] = "wool:grey"}, {["param1"] = 87, ["x"] = 1, ["y"] = 9, ["z"] = 7, ["meta"] = {["inventory"] = {}, ["fields"] = {}}, ["name"] = "wool:grey"}, {["param1"] = 87, ["x"] = 1, ["y"] = 9, ["z"] = 8, ["meta"] = {["inventory"] = {}, ["fields"] = {}}, ["name"] = "wool:grey"}, {["param1"] = 87, ["x"] = 1, ["y"] = 9, ["z"] = 9, ["meta"] = {["inventory"] = {}, ["fields"] = {}}, ["name"] = "wool:grey"}, {["param1"] = 87, ["x"] = 1, ["y"] = 9, ["z"] = 10, ["meta"] = {["inventory"] = {}, ["fields"] = {}}, ["name"] = "wool:grey"}, {["param1"] = 87, ["x"] = 1, ["y"] = 9, ["z"] = 11, ["meta"] = {["inventory"] = {}, ["fields"] = {}}, ["name"] = "wool:grey"}, {["param1"] = 87, ["x"] = 1, ["y"] = 9, ["z"] = 12, ["meta"] = {["inventory"] = {}, ["fields"] = {}}, ["name"] = "wool:grey"}, {["param1"] = 87, ["x"] = 1, ["y"] = 9, ["z"] = 13, ["meta"] = {["inventory"] = {}, ["fields"] = {}}, ["name"] = "wool:grey"}, {["param1"] = 87, ["x"] = 1, ["y"] = 9, ["z"] = 14, ["meta"] = {["inventory"] = {}, ["fields"] = {}}, ["name"] = "wool:grey"}, {["param1"] = 87, ["x"] = 1, ["y"] = 9, ["z"] = 15, ["meta"] = {["inventory"] = {}, ["fields"] = {}}, ["name"] = "wool:grey"}, {["param1"] = 87, ["x"] = 1, ["y"] = 10, ["z"] = 0, ["meta"] = {["inventory"] = {}, ["fields"] = {}}, ["name"] = "wool:grey"}, {["param1"] = 87, ["x"] = 1, ["y"] = 10, ["z"] = 1, ["meta"] = {["inventory"] = {}, ["fields"] = {}}, ["name"] = "wool:grey"}, {["param1"] = 87, ["x"] = 1, ["y"] = 10, ["z"] = 14, ["meta"] = {["inventory"] = {}, ["fields"] = {}}, ["name"] = "wool:grey"}, {["param1"] = 87, ["x"] = 1, ["y"] = 10, ["z"] = 15, ["meta"] = {["inventory"] = {}, ["fields"] = {}}, ["name"] = "wool:grey"}, {["param1"] = 87, ["x"] = 1, ["y"] = 11, ["z"] = 0, ["meta"] = {["inventory"] = {}, ["fields"] = {}}, ["name"] = "wool:grey"}, {["param1"] = 87, ["x"] = 1, ["y"] = 11, ["z"] = 1, ["meta"] = {["inventory"] = {}, ["fields"] = {}}, ["name"] = "wool:grey"}, {["param1"] = 87, ["x"] = 1, ["y"] = 11, ["z"] = 14, ["meta"] = {["inventory"] = {}, ["fields"] = {}}, ["name"] = "wool:grey"}, {["param1"] = 87, ["x"] = 1, ["y"] = 11, ["z"] = 15, ["meta"] = {["inventory"] = {}, ["fields"] = {}}, ["name"] = "wool:grey"}, {["param1"] = 87, ["x"] = 1, ["y"] = 12, ["z"] = 0, ["meta"] = {["inventory"] = {}, ["fields"] = {}}, ["name"] = "wool:grey"}, {["param1"] = 87, ["x"] = 1, ["y"] = 12, ["z"] = 1, ["meta"] = {["inventory"] = {}, ["fields"] = {}}, ["name"] = "wool:grey"}, {["param1"] = 87, ["x"] = 1, ["y"] = 12, ["z"] = 14, ["meta"] = {["inventory"] = {}, ["fields"] = {}}, ["name"] = "wool:grey"}, {["param1"] = 87, ["x"] = 1, ["y"] = 12, ["z"] = 15, ["meta"] = {["inventory"] = {}, ["fields"] = {}}, ["name"] = "wool:grey"}, {["param1"] = 87, ["x"] = 1, ["y"] = 13, ["z"] = 0, ["meta"] = {["inventory"] = {}, ["fields"] = {}}, ["name"] = "wool:grey"}, {["param1"] = 87, ["x"] = 1, ["y"] = 13, ["z"] = 1, ["meta"] = {["inventory"] = {}, ["fields"] = {}}, ["name"] = "wool:grey"}, {["param1"] = 87, ["x"] = 1, ["y"] = 13, ["z"] = 14, ["meta"] = {["inventory"] = {}, ["fields"] = {}}, ["name"] = "wool:grey"}, {["param1"] = 87, ["x"] = 1, ["y"] = 13, ["z"] = 15, ["meta"] = {["inventory"] = {}, ["fields"] = {}}, ["name"] = "wool:grey"}, {["param1"] = 87, ["x"] = 1, ["y"] = 14, ["z"] = 0, ["meta"] = {["inventory"] = {}, ["fields"] = {}}, ["name"] = "wool:grey"}, {["param1"] = 87, ["x"] = 1, ["y"] = 14, ["z"] = 1, ["meta"] = {["inventory"] = {}, ["fields"] = {}}, ["name"] = "wool:grey"}, {["param1"] = 87, ["x"] = 1, ["y"] = 14, ["z"] = 14, ["meta"] = {["inventory"] = {}, ["fields"] = {}}, ["name"] = "wool:grey"}, {["param1"] = 87, ["x"] = 1, ["y"] = 14, ["z"] = 15, ["meta"] = {["inventory"] = {}, ["fields"] = {}}, ["name"] = "wool:grey"}, {["param1"] = 87, ["x"] = 1, ["y"] = 15, ["z"] = 0, ["meta"] = {["inventory"] = {}, ["fields"] = {}}, ["name"] = "wool:grey"}, {["param1"] = 87, ["x"] = 1, ["y"] = 15, ["z"] = 1, ["meta"] = {["inventory"] = {}, ["fields"] = {}}, ["name"] = "wool:grey"}, {["param1"] = 87, ["x"] = 1, ["y"] = 15, ["z"] = 14, ["meta"] = {["inventory"] = {}, ["fields"] = {}}, ["name"] = "wool:grey"}, {["param1"] = 87, ["x"] = 1, ["y"] = 15, ["z"] = 15, ["meta"] = {["inventory"] = {}, ["fields"] = {}}, ["name"] = "wool:grey"}, {["param1"] = 87, ["x"] = 2, ["y"] = 6, ["z"] = 1, ["meta"] = {["inventory"] = {}, ["fields"] = {}}, ["name"] = "wool:grey"}, {["param1"] = 87, ["x"] = 2, ["y"] = 6, ["z"] = 14, ["meta"] = {["inventory"] = {}, ["fields"] = {}}, ["name"] = "wool:grey"}, {["param1"] = 95, ["x"] = 2, ["y"] = 8, ["z"] = 8, ["meta"] = {["inventory"] = {}, ["fields"] = {}}, ["name"] = "wool:yellow"}, {["param1"] = 87, ["x"] = 2, ["y"] = 9, ["z"] = 1, ["meta"] = {["inventory"] = {}, ["fields"] = {}}, ["name"] = "wool:grey"}, {["param1"] = 87, ["x"] = 2, ["y"] = 9, ["z"] = 14, ["meta"] = {["inventory"] = {}, ["fields"] = {}}, ["name"] = "wool:grey"}, {["param1"] = 87, ["x"] = 3, ["y"] = 6, ["z"] = 1, ["meta"] = {["inventory"] = {}, ["fields"] = {}}, ["name"] = "wool:grey"}, {["x"] = 3, ["y"] = 6, ["z"] = 2, ["meta"] = {["inventory"] = {}, ["fields"] = {}}, ["name"] = "default:steelblock"}, {["x"] = 3, ["y"] = 6, ["z"] = 3, ["meta"] = {["inventory"] = {}, ["fields"] = {}}, ["name"] = "default:steelblock"}, {["x"] = 3, ["y"] = 6, ["z"] = 4, ["meta"] = {["inventory"] = {}, ["fields"] = {}}, ["name"] = "default:steelblock"}, {["x"] = 3, ["y"] = 6, ["z"] = 5, ["meta"] = {["inventory"] = {}, ["fields"] = {}}, ["name"] = "default:steelblock"}, {["x"] = 3, ["y"] = 6, ["z"] = 6, ["meta"] = {["inventory"] = {}, ["fields"] = {}}, ["name"] = "default:steelblock"}, {["x"] = 3, ["y"] = 6, ["z"] = 7, ["meta"] = {["inventory"] = {}, ["fields"] = {}}, ["name"] = "default:steelblock"}, {["x"] = 3, ["y"] = 6, ["z"] = 8, ["meta"] = {["inventory"] = {}, ["fields"] = {}}, ["name"] = "default:steelblock"}, {["x"] = 3, ["y"] = 6, ["z"] = 9, ["meta"] = {["inventory"] = {}, ["fields"] = {}}, ["name"] = "default:steelblock"}, {["x"] = 3, ["y"] = 6, ["z"] = 10, ["meta"] = {["inventory"] = {}, ["fields"] = {}}, ["name"] = "default:steelblock"}, {["x"] = 3, ["y"] = 6, ["z"] = 11, ["meta"] = {["inventory"] = {}, ["fields"] = {}}, ["name"] = "default:steelblock"}, {["x"] = 3, ["y"] = 6, ["z"] = 12, ["meta"] = {["inventory"] = {}, ["fields"] = {}}, ["name"] = "default:steelblock"}, {["x"] = 3, ["y"] = 6, ["z"] = 13, ["meta"] = {["inventory"] = {}, ["fields"] = {}}, ["name"] = "default:steelblock"}, {["param1"] = 87, ["x"] = 3, ["y"] = 6, ["z"] = 14, ["meta"] = {["inventory"] = {}, ["fields"] = {}}, ["name"] = "wool:grey"}, {["x"] = 3, ["y"] = 7, ["z"] = 2, ["meta"] = {["inventory"] = {}, ["fields"] = {}}, ["name"] = "default:steelblock"}, {["x"] = 3, ["y"] = 7, ["z"] = 3, ["meta"] = {["inventory"] = {}, ["fields"] = {}}, ["name"] = "default:steelblock"}, {["x"] = 3, ["y"] = 7, ["z"] = 4, ["meta"] = {["inventory"] = {}, ["fields"] = {}}, ["name"] = "default:steelblock"}, {["x"] = 3, ["y"] = 7, ["z"] = 5, ["meta"] = {["inventory"] = {}, ["fields"] = {}}, ["name"] = "default:steelblock"}, {["x"] = 3, ["y"] = 7, ["z"] = 6, ["meta"] = {["inventory"] = {}, ["fields"] = {}}, ["name"] = "default:steelblock"}, {["x"] = 3, ["y"] = 7, ["z"] = 7, ["meta"] = {["inventory"] = {}, ["fields"] = {}}, ["name"] = "default:steelblock"}, {["x"] = 3, ["y"] = 7, ["z"] = 8, ["meta"] = {["inventory"] = {}, ["fields"] = {}}, ["name"] = "default:steelblock"}, {["x"] = 3, ["y"] = 7, ["z"] = 9, ["meta"] = {["inventory"] = {}, ["fields"] = {}}, ["name"] = "default:steelblock"}, {["x"] = 3, ["y"] = 7, ["z"] = 10, ["meta"] = {["inventory"] = {}, ["fields"] = {}}, ["name"] = "default:steelblock"}, {["x"] = 3, ["y"] = 7, ["z"] = 11, ["meta"] = {["inventory"] = {}, ["fields"] = {}}, ["name"] = "default:steelblock"}, {["x"] = 3, ["y"] = 7, ["z"] = 12, ["meta"] = {["inventory"] = {}, ["fields"] = {}}, ["name"] = "default:steelblock"}, {["x"] = 3, ["y"] = 7, ["z"] = 13, ["meta"] = {["inventory"] = {}, ["fields"] = {}}, ["name"] = "default:steelblock"}, {["x"] = 3, ["y"] = 8, ["z"] = 2, ["meta"] = {["inventory"] = {}, ["fields"] = {}}, ["name"] = "default:steelblock"}, {["x"] = 3, ["y"] = 8, ["z"] = 3, ["meta"] = {["inventory"] = {}, ["fields"] = {}}, ["name"] = "default:steelblock"}, {["x"] = 3, ["y"] = 8, ["z"] = 4, ["meta"] = {["inventory"] = {}, ["fields"] = {}}, ["name"] = "default:steelblock"}, {["x"] = 3, ["y"] = 8, ["z"] = 5, ["meta"] = {["inventory"] = {}, ["fields"] = {}}, ["name"] = "default:steelblock"}, {["x"] = 3, ["y"] = 8, ["z"] = 6, ["meta"] = {["inventory"] = {}, ["fields"] = {}}, ["name"] = "default:steelblock"}, {["x"] = 3, ["y"] = 8, ["z"] = 7, ["meta"] = {["inventory"] = {}, ["fields"] = {}}, ["name"] = "default:steelblock"}, {["x"] = 3, ["y"] = 8, ["z"] = 8, ["meta"] = {["inventory"] = {}, ["fields"] = {}}, ["name"] = "default:steelblock"}, {["x"] = 3, ["y"] = 8, ["z"] = 9, ["meta"] = {["inventory"] = {}, ["fields"] = {}}, ["name"] = "default:steelblock"}, {["x"] = 3, ["y"] = 8, ["z"] = 10, ["meta"] = {["inventory"] = {}, ["fields"] = {}}, ["name"] = "default:steelblock"}, {["x"] = 3, ["y"] = 8, ["z"] = 11, ["meta"] = {["inventory"] = {}, ["fields"] = {}}, ["name"] = "default:steelblock"}, {["x"] = 3, ["y"] = 8, ["z"] = 12, ["meta"] = {["inventory"] = {}, ["fields"] = {}}, ["name"] = "default:steelblock"}, {["x"] = 3, ["y"] = 8, ["z"] = 13, ["meta"] = {["inventory"] = {}, ["fields"] = {}}, ["name"] = "default:steelblock"}, {["param1"] = 87, ["x"] = 3, ["y"] = 9, ["z"] = 1, ["meta"] = {["inventory"] = {}, ["fields"] = {}}, ["name"] = "wool:grey"}, {["x"] = 3, ["y"] = 9, ["z"] = 2, ["meta"] = {["inventory"] = {}, ["fields"] = {}}, ["name"] = "default:steelblock"}, {["x"] = 3, ["y"] = 9, ["z"] = 3, ["meta"] = {["inventory"] = {}, ["fields"] = {}}, ["name"] = "default:steelblock"}, {["x"] = 3, ["y"] = 9, ["z"] = 4, ["meta"] = {["inventory"] = {}, ["fields"] = {}}, ["name"] = "default:steelblock"}, {["x"] = 3, ["y"] = 9, ["z"] = 5, ["meta"] = {["inventory"] = {}, ["fields"] = {}}, ["name"] = "default:steelblock"}, {["x"] = 3, ["y"] = 9, ["z"] = 6, ["meta"] = {["inventory"] = {}, ["fields"] = {}}, ["name"] = "default:steelblock"}, {["x"] = 3, ["y"] = 9, ["z"] = 7, ["meta"] = {["inventory"] = {}, ["fields"] = {}}, ["name"] = "default:steelblock"}, {["x"] = 3, ["y"] = 9, ["z"] = 8, ["meta"] = {["inventory"] = {}, ["fields"] = {}}, ["name"] = "default:steelblock"}, {["x"] = 3, ["y"] = 9, ["z"] = 9, ["meta"] = {["inventory"] = {}, ["fields"] = {}}, ["name"] = "default:steelblock"}, {["x"] = 3, ["y"] = 9, ["z"] = 10, ["meta"] = {["inventory"] = {}, ["fields"] = {}}, ["name"] = "default:steelblock"}, {["x"] = 3, ["y"] = 9, ["z"] = 11, ["meta"] = {["inventory"] = {}, ["fields"] = {}}, ["name"] = "default:steelblock"}, {["x"] = 3, ["y"] = 9, ["z"] = 12, ["meta"] = {["inventory"] = {}, ["fields"] = {}}, ["name"] = "default:steelblock"}, {["x"] = 3, ["y"] = 9, ["z"] = 13, ["meta"] = {["inventory"] = {}, ["fields"] = {}}, ["name"] = "default:steelblock"}, {["param1"] = 87, ["x"] = 3, ["y"] = 9, ["z"] = 14, ["meta"] = {["inventory"] = {}, ["fields"] = {}}, ["name"] = "wool:grey"}, {["x"] = 4, ["y"] = 5, ["z"] = 2, ["meta"] = {["inventory"] = {}, ["fields"] = {}}, ["name"] = "default:steelblock"}, {["x"] = 4, ["y"] = 5, ["z"] = 3, ["meta"] = {["inventory"] = {}, ["fields"] = {}}, ["name"] = "default:steelblock"}, {["x"] = 4, ["y"] = 5, ["z"] = 4, ["meta"] = {["inventory"] = {}, ["fields"] = {}}, ["name"] = "default:steelblock"}, {["x"] = 4, ["y"] = 5, ["z"] = 5, ["meta"] = {["inventory"] = {}, ["fields"] = {}}, ["name"] = "default:steelblock"}, {["x"] = 4, ["y"] = 5, ["z"] = 6, ["meta"] = {["inventory"] = {}, ["fields"] = {}}, ["name"] = "default:steelblock"}, {["x"] = 4, ["y"] = 5, ["z"] = 7, ["meta"] = {["inventory"] = {}, ["fields"] = {}}, ["name"] = "default:steelblock"}, {["x"] = 4, ["y"] = 5, ["z"] = 8, ["meta"] = {["inventory"] = {}, ["fields"] = {}}, ["name"] = "default:steelblock"}, {["x"] = 4, ["y"] = 5, ["z"] = 9, ["meta"] = {["inventory"] = {}, ["fields"] = {}}, ["name"] = "default:steelblock"}, {["x"] = 4, ["y"] = 5, ["z"] = 10, ["meta"] = {["inventory"] = {}, ["fields"] = {}}, ["name"] = "default:steelblock"}, {["x"] = 4, ["y"] = 5, ["z"] = 11, ["meta"] = {["inventory"] = {}, ["fields"] = {}}, ["name"] = "default:steelblock"}, {["x"] = 4, ["y"] = 5, ["z"] = 12, ["meta"] = {["inventory"] = {}, ["fields"] = {}}, ["name"] = "default:steelblock"}, {["x"] = 4, ["y"] = 5, ["z"] = 13, ["meta"] = {["inventory"] = {}, ["fields"] = {}}, ["name"] = "default:steelblock"}, {["param1"] = 87, ["x"] = 4, ["y"] = 6, ["z"] = 1, ["meta"] = {["inventory"] = {}, ["fields"] = {}}, ["name"] = "wool:grey"}, {["param1"] = 82, ["x"] = 4, ["y"] = 6, ["z"] = 2, ["meta"] = {["inventory"] = {}, ["fields"] = {}}, ["name"] = "default:steelblock"}, {["param1"] = 82, ["x"] = 4, ["y"] = 6, ["z"] = 3, ["meta"] = {["inventory"] = {}, ["fields"] = {}}, ["name"] = "default:steelblock"}, {["param1"] = 82, ["x"] = 4, ["y"] = 6, ["z"] = 4, ["meta"] = {["inventory"] = {}, ["fields"] = {}}, ["name"] = "default:steelblock"}, {["param1"] = 82, ["x"] = 4, ["y"] = 6, ["z"] = 5, ["meta"] = {["inventory"] = {}, ["fields"] = {}}, ["name"] = "default:steelblock"}, {["param1"] = 82, ["x"] = 4, ["y"] = 6, ["z"] = 6, ["meta"] = {["inventory"] = {}, ["fields"] = {}}, ["name"] = "default:steelblock"}, {["param1"] = 82, ["x"] = 4, ["y"] = 6, ["z"] = 7, ["meta"] = {["inventory"] = {}, ["fields"] = {}}, ["name"] = "default:steelblock"}, {["param1"] = 82, ["x"] = 4, ["y"] = 6, ["z"] = 8, ["meta"] = {["inventory"] = {}, ["fields"] = {}}, ["name"] = "default:steelblock"}, {["param1"] = 82, ["x"] = 4, ["y"] = 6, ["z"] = 9, ["meta"] = {["inventory"] = {}, ["fields"] = {}}, ["name"] = "default:steelblock"}, {["param1"] = 82, ["x"] = 4, ["y"] = 6, ["z"] = 10, ["meta"] = {["inventory"] = {}, ["fields"] = {}}, ["name"] = "default:steelblock"}, {["param1"] = 82, ["x"] = 4, ["y"] = 6, ["z"] = 11, ["meta"] = {["inventory"] = {}, ["fields"] = {}}, ["name"] = "default:steelblock"}, {["param1"] = 82, ["x"] = 4, ["y"] = 6, ["z"] = 12, ["meta"] = {["inventory"] = {}, ["fields"] = {}}, ["name"] = "default:steelblock"}, {["param1"] = 82, ["x"] = 4, ["y"] = 6, ["z"] = 13, ["meta"] = {["inventory"] = {}, ["fields"] = {}}, ["name"] = "default:steelblock"}, {["param1"] = 87, ["x"] = 4, ["y"] = 6, ["z"] = 14, ["meta"] = {["inventory"] = {}, ["fields"] = {}}, ["name"] = "wool:grey"}, {["param1"] = 82, ["x"] = 4, ["y"] = 7, ["z"] = 2, ["meta"] = {["inventory"] = {}, ["fields"] = {}}, ["name"] = "default:steelblock"}, {["param1"] = 82, ["x"] = 4, ["y"] = 7, ["z"] = 3, ["meta"] = {["inventory"] = {}, ["fields"] = {}}, ["name"] = "default:steelblock"}, {["param1"] = 82, ["x"] = 4, ["y"] = 7, ["z"] = 4, ["meta"] = {["inventory"] = {}, ["fields"] = {}}, ["name"] = "default:steelblock"}, {["param1"] = 82, ["x"] = 4, ["y"] = 7, ["z"] = 5, ["meta"] = {["inventory"] = {}, ["fields"] = {}}, ["name"] = "default:steelblock"}, {["param1"] = 82, ["x"] = 4, ["y"] = 7, ["z"] = 6, ["meta"] = {["inventory"] = {}, ["fields"] = {}}, ["name"] = "default:steelblock"}, {["param1"] = 82, ["x"] = 4, ["y"] = 7, ["z"] = 7, ["meta"] = {["inventory"] = {}, ["fields"] = {}}, ["name"] = "default:steelblock"}, {["param1"] = 82, ["x"] = 4, ["y"] = 7, ["z"] = 8, ["meta"] = {["inventory"] = {}, ["fields"] = {}}, ["name"] = "default:steelblock"}, {["param1"] = 82, ["x"] = 4, ["y"] = 7, ["z"] = 9, ["meta"] = {["inventory"] = {}, ["fields"] = {}}, ["name"] = "default:steelblock"}, {["param1"] = 82, ["x"] = 4, ["y"] = 7, ["z"] = 10, ["meta"] = {["inventory"] = {}, ["fields"] = {}}, ["name"] = "default:steelblock"}, {["param1"] = 82, ["x"] = 4, ["y"] = 7, ["z"] = 11, ["meta"] = {["inventory"] = {}, ["fields"] = {}}, ["name"] = "default:steelblock"}, {["param1"] = 82, ["x"] = 4, ["y"] = 7, ["z"] = 12, ["meta"] = {["inventory"] = {}, ["fields"] = {}}, ["name"] = "default:steelblock"}, {["param1"] = 82, ["x"] = 4, ["y"] = 7, ["z"] = 13, ["meta"] = {["inventory"] = {}, ["fields"] = {}}, ["name"] = "default:steelblock"}, {["param1"] = 82, ["x"] = 4, ["y"] = 8, ["z"] = 2, ["meta"] = {["inventory"] = {}, ["fields"] = {}}, ["name"] = "default:steelblock"}, {["param1"] = 82, ["x"] = 4, ["y"] = 8, ["z"] = 3, ["meta"] = {["inventory"] = {}, ["fields"] = {}}, ["name"] = "default:steelblock"}, {["param1"] = 82, ["x"] = 4, ["y"] = 8, ["z"] = 4, ["meta"] = {["inventory"] = {}, ["fields"] = {}}, ["name"] = "default:steelblock"}, {["param1"] = 82, ["x"] = 4, ["y"] = 8, ["z"] = 5, ["meta"] = {["inventory"] = {}, ["fields"] = {}}, ["name"] = "default:steelblock"}, {["param1"] = 82, ["x"] = 4, ["y"] = 8, ["z"] = 6, ["meta"] = {["inventory"] = {}, ["fields"] = {}}, ["name"] = "default:steelblock"}, {["param1"] = 82, ["x"] = 4, ["y"] = 8, ["z"] = 7, ["meta"] = {["inventory"] = {}, ["fields"] = {}}, ["name"] = "default:steelblock"}, {["param1"] = 82, ["x"] = 4, ["y"] = 8, ["z"] = 8, ["meta"] = {["inventory"] = {}, ["fields"] = {}}, ["name"] = "default:steelblock"}, {["param1"] = 82, ["x"] = 4, ["y"] = 8, ["z"] = 9, ["meta"] = {["inventory"] = {}, ["fields"] = {}}, ["name"] = "default:steelblock"}, {["param1"] = 82, ["x"] = 4, ["y"] = 8, ["z"] = 10, ["meta"] = {["inventory"] = {}, ["fields"] = {}}, ["name"] = "default:steelblock"}, {["param1"] = 82, ["x"] = 4, ["y"] = 8, ["z"] = 11, ["meta"] = {["inventory"] = {}, ["fields"] = {}}, ["name"] = "default:steelblock"}, {["param1"] = 82, ["x"] = 4, ["y"] = 8, ["z"] = 12, ["meta"] = {["inventory"] = {}, ["fields"] = {}}, ["name"] = "default:steelblock"}, {["param1"] = 82, ["x"] = 4, ["y"] = 8, ["z"] = 13, ["meta"] = {["inventory"] = {}, ["fields"] = {}}, ["name"] = "default:steelblock"}, {["param1"] = 87, ["x"] = 4, ["y"] = 9, ["z"] = 1, ["meta"] = {["inventory"] = {}, ["fields"] = {}}, ["name"] = "wool:grey"}, {["param1"] = 82, ["x"] = 4, ["y"] = 9, ["z"] = 2, ["meta"] = {["inventory"] = {}, ["fields"] = {}}, ["name"] = "default:steelblock"}, {["param1"] = 82, ["x"] = 4, ["y"] = 9, ["z"] = 3, ["meta"] = {["inventory"] = {}, ["fields"] = {}}, ["name"] = "default:steelblock"}, {["param1"] = 82, ["x"] = 4, ["y"] = 9, ["z"] = 4, ["meta"] = {["inventory"] = {}, ["fields"] = {}}, ["name"] = "default:steelblock"}, {["param1"] = 82, ["x"] = 4, ["y"] = 9, ["z"] = 5, ["meta"] = {["inventory"] = {}, ["fields"] = {}}, ["name"] = "default:steelblock"}, {["param1"] = 82, ["x"] = 4, ["y"] = 9, ["z"] = 6, ["meta"] = {["inventory"] = {}, ["fields"] = {}}, ["name"] = "default:steelblock"}, {["param1"] = 82, ["x"] = 4, ["y"] = 9, ["z"] = 7, ["meta"] = {["inventory"] = {}, ["fields"] = {}}, ["name"] = "default:steelblock"}, {["param1"] = 82, ["x"] = 4, ["y"] = 9, ["z"] = 8, ["meta"] = {["inventory"] = {}, ["fields"] = {}}, ["name"] = "default:steelblock"}, {["param1"] = 82, ["x"] = 4, ["y"] = 9, ["z"] = 9, ["meta"] = {["inventory"] = {}, ["fields"] = {}}, ["name"] = "default:steelblock"}, {["param1"] = 82, ["x"] = 4, ["y"] = 9, ["z"] = 10, ["meta"] = {["inventory"] = {}, ["fields"] = {}}, ["name"] = "default:steelblock"}, {["param1"] = 82, ["x"] = 4, ["y"] = 9, ["z"] = 11, ["meta"] = {["inventory"] = {}, ["fields"] = {}}, ["name"] = "default:steelblock"}, {["param1"] = 82, ["x"] = 4, ["y"] = 9, ["z"] = 12, ["meta"] = {["inventory"] = {}, ["fields"] = {}}, ["name"] = "default:steelblock"}, {["param1"] = 82, ["x"] = 4, ["y"] = 9, ["z"] = 13, ["meta"] = {["inventory"] = {}, ["fields"] = {}}, ["name"] = "default:steelblock"}, {["param1"] = 87, ["x"] = 4, ["y"] = 9, ["z"] = 14, ["meta"] = {["inventory"] = {}, ["fields"] = {}}, ["name"] = "wool:grey"}, {["x"] = 4, ["y"] = 10, ["z"] = 2, ["meta"] = {["inventory"] = {}, ["fields"] = {}}, ["name"] = "default:steelblock"}, {["x"] = 4, ["y"] = 10, ["z"] = 3, ["meta"] = {["inventory"] = {}, ["fields"] = {}}, ["name"] = "default:steelblock"}, {["x"] = 4, ["y"] = 10, ["z"] = 4, ["meta"] = {["inventory"] = {}, ["fields"] = {}}, ["name"] = "default:steelblock"}, {["x"] = 4, ["y"] = 10, ["z"] = 5, ["meta"] = {["inventory"] = {}, ["fields"] = {}}, ["name"] = "default:steelblock"}, {["x"] = 4, ["y"] = 10, ["z"] = 6, ["meta"] = {["inventory"] = {}, ["fields"] = {}}, ["name"] = "default:steelblock"}, {["x"] = 4, ["y"] = 10, ["z"] = 7, ["meta"] = {["inventory"] = {}, ["fields"] = {}}, ["name"] = "default:steelblock"}, {["x"] = 4, ["y"] = 10, ["z"] = 8, ["meta"] = {["inventory"] = {}, ["fields"] = {}}, ["name"] = "default:steelblock"}, {["x"] = 4, ["y"] = 10, ["z"] = 9, ["meta"] = {["inventory"] = {}, ["fields"] = {}}, ["name"] = "default:steelblock"}, {["x"] = 4, ["y"] = 10, ["z"] = 10, ["meta"] = {["inventory"] = {}, ["fields"] = {}}, ["name"] = "default:steelblock"}, {["x"] = 4, ["y"] = 10, ["z"] = 11, ["meta"] = {["inventory"] = {}, ["fields"] = {}}, ["name"] = "default:steelblock"}, {["x"] = 4, ["y"] = 10, ["z"] = 12, ["meta"] = {["inventory"] = {}, ["fields"] = {}}, ["name"] = "default:steelblock"}, {["x"] = 4, ["y"] = 10, ["z"] = 13, ["meta"] = {["inventory"] = {}, ["fields"] = {}}, ["name"] = "default:steelblock"}, {["x"] = 5, ["y"] = 4, ["z"] = 2, ["meta"] = {["inventory"] = {}, ["fields"] = {}}, ["name"] = "default:steelblock"}, {["x"] = 5, ["y"] = 4, ["z"] = 3, ["meta"] = {["inventory"] = {}, ["fields"] = {}}, ["name"] = "default:steelblock"}, {["x"] = 5, ["y"] = 4, ["z"] = 4, ["meta"] = {["inventory"] = {}, ["fields"] = {}}, ["name"] = "default:steelblock"}, {["x"] = 5, ["y"] = 4, ["z"] = 5, ["meta"] = {["inventory"] = {}, ["fields"] = {}}, ["name"] = "default:steelblock"}, {["x"] = 5, ["y"] = 4, ["z"] = 6, ["meta"] = {["inventory"] = {}, ["fields"] = {}}, ["name"] = "default:steelblock"}, {["x"] = 5, ["y"] = 4, ["z"] = 7, ["meta"] = {["inventory"] = {}, ["fields"] = {}}, ["name"] = "default:steelblock"}, {["x"] = 5, ["y"] = 4, ["z"] = 8, ["meta"] = {["inventory"] = {}, ["fields"] = {}}, ["name"] = "default:steelblock"}, {["x"] = 5, ["y"] = 4, ["z"] = 9, ["meta"] = {["inventory"] = {}, ["fields"] = {}}, ["name"] = "default:steelblock"}, {["x"] = 5, ["y"] = 4, ["z"] = 10, ["meta"] = {["inventory"] = {}, ["fields"] = {}}, ["name"] = "default:steelblock"}, {["x"] = 5, ["y"] = 4, ["z"] = 11, ["meta"] = {["inventory"] = {}, ["fields"] = {}}, ["name"] = "default:steelblock"}, {["x"] = 5, ["y"] = 4, ["z"] = 12, ["meta"] = {["inventory"] = {}, ["fields"] = {}}, ["name"] = "default:steelblock"}, {["x"] = 5, ["y"] = 4, ["z"] = 13, ["meta"] = {["inventory"] = {}, ["fields"] = {}}, ["name"] = "default:steelblock"}, {["param1"] = 82, ["x"] = 5, ["y"] = 5, ["z"] = 2, ["meta"] = {["inventory"] = {}, ["fields"] = {}}, ["name"] = "default:steelblock"}, {["param1"] = 82, ["x"] = 5, ["y"] = 5, ["z"] = 3, ["meta"] = {["inventory"] = {}, ["fields"] = {}}, ["name"] = "default:steelblock"}, {["param1"] = 82, ["x"] = 5, ["y"] = 5, ["z"] = 4, ["meta"] = {["inventory"] = {}, ["fields"] = {}}, ["name"] = "default:steelblock"}, {["param1"] = 82, ["x"] = 5, ["y"] = 5, ["z"] = 5, ["meta"] = {["inventory"] = {}, ["fields"] = {}}, ["name"] = "default:steelblock"}, {["param1"] = 82, ["x"] = 5, ["y"] = 5, ["z"] = 6, ["meta"] = {["inventory"] = {}, ["fields"] = {}}, ["name"] = "default:steelblock"}, {["param1"] = 82, ["x"] = 5, ["y"] = 5, ["z"] = 7, ["meta"] = {["inventory"] = {}, ["fields"] = {}}, ["name"] = "default:steelblock"}, {["param1"] = 82, ["x"] = 5, ["y"] = 5, ["z"] = 8, ["meta"] = {["inventory"] = {}, ["fields"] = {}}, ["name"] = "default:steelblock"}, {["param1"] = 82, ["x"] = 5, ["y"] = 5, ["z"] = 9, ["meta"] = {["inventory"] = {}, ["fields"] = {}}, ["name"] = "default:steelblock"}, {["param1"] = 82, ["x"] = 5, ["y"] = 5, ["z"] = 10, ["meta"] = {["inventory"] = {}, ["fields"] = {}}, ["name"] = "default:steelblock"}, {["param1"] = 82, ["x"] = 5, ["y"] = 5, ["z"] = 11, ["meta"] = {["inventory"] = {}, ["fields"] = {}}, ["name"] = "default:steelblock"}, {["param1"] = 82, ["x"] = 5, ["y"] = 5, ["z"] = 12, ["meta"] = {["inventory"] = {}, ["fields"] = {}}, ["name"] = "default:steelblock"}, {["param1"] = 82, ["x"] = 5, ["y"] = 5, ["z"] = 13, ["meta"] = {["inventory"] = {}, ["fields"] = {}}, ["name"] = "default:steelblock"}, {["param1"] = 87, ["x"] = 5, ["y"] = 6, ["z"] = 1, ["meta"] = {["inventory"] = {}, ["fields"] = {}}, ["name"] = "wool:grey"}, {["param1"] = 82, ["x"] = 5, ["y"] = 6, ["z"] = 2, ["meta"] = {["inventory"] = {}, ["fields"] = {}}, ["name"] = "default:steelblock"}, {["param1"] = 82, ["x"] = 5, ["y"] = 6, ["z"] = 3, ["meta"] = {["inventory"] = {}, ["fields"] = {}}, ["name"] = "default:steelblock"}, {["param1"] = 82, ["x"] = 5, ["y"] = 6, ["z"] = 4, ["meta"] = {["inventory"] = {}, ["fields"] = {}}, ["name"] = "default:steelblock"}, {["param1"] = 82, ["x"] = 5, ["y"] = 6, ["z"] = 5, ["meta"] = {["inventory"] = {}, ["fields"] = {}}, ["name"] = "default:steelblock"}, {["param1"] = 82, ["x"] = 5, ["y"] = 6, ["z"] = 6, ["meta"] = {["inventory"] = {}, ["fields"] = {}}, ["name"] = "default:steelblock"}, {["param1"] = 82, ["x"] = 5, ["y"] = 6, ["z"] = 7, ["meta"] = {["inventory"] = {}, ["fields"] = {}}, ["name"] = "default:steelblock"}, {["param1"] = 82, ["x"] = 5, ["y"] = 6, ["z"] = 8, ["meta"] = {["inventory"] = {}, ["fields"] = {}}, ["name"] = "default:steelblock"}, {["param1"] = 82, ["x"] = 5, ["y"] = 6, ["z"] = 9, ["meta"] = {["inventory"] = {}, ["fields"] = {}}, ["name"] = "default:steelblock"}, {["param1"] = 82, ["x"] = 5, ["y"] = 6, ["z"] = 10, ["meta"] = {["inventory"] = {}, ["fields"] = {}}, ["name"] = "default:steelblock"}, {["param1"] = 82, ["x"] = 5, ["y"] = 6, ["z"] = 11, ["meta"] = {["inventory"] = {}, ["fields"] = {}}, ["name"] = "default:steelblock"}, {["param1"] = 82, ["x"] = 5, ["y"] = 6, ["z"] = 12, ["meta"] = {["inventory"] = {}, ["fields"] = {}}, ["name"] = "default:steelblock"}, {["param1"] = 82, ["x"] = 5, ["y"] = 6, ["z"] = 13, ["meta"] = {["inventory"] = {}, ["fields"] = {}}, ["name"] = "default:steelblock"}, {["param1"] = 87, ["x"] = 5, ["y"] = 6, ["z"] = 14, ["meta"] = {["inventory"] = {}, ["fields"] = {}}, ["name"] = "wool:grey"}, {["param1"] = 82, ["x"] = 5, ["y"] = 7, ["z"] = 2, ["meta"] = {["inventory"] = {}, ["fields"] = {}}, ["name"] = "default:steelblock"}, {["param1"] = 82, ["x"] = 5, ["y"] = 7, ["z"] = 3, ["meta"] = {["inventory"] = {}, ["fields"] = {}}, ["name"] = "default:steelblock"}, {["param1"] = 82, ["x"] = 5, ["y"] = 7, ["z"] = 4, ["meta"] = {["inventory"] = {}, ["fields"] = {}}, ["name"] = "default:steelblock"}, {["param1"] = 82, ["x"] = 5, ["y"] = 7, ["z"] = 5, ["meta"] = {["inventory"] = {}, ["fields"] = {}}, ["name"] = "default:steelblock"}, {["param1"] = 82, ["x"] = 5, ["y"] = 7, ["z"] = 6, ["meta"] = {["inventory"] = {}, ["fields"] = {}}, ["name"] = "default:steelblock"}, {["param1"] = 82, ["x"] = 5, ["y"] = 7, ["z"] = 7, ["meta"] = {["inventory"] = {}, ["fields"] = {}}, ["name"] = "default:steelblock"}, {["param1"] = 82, ["x"] = 5, ["y"] = 7, ["z"] = 8, ["meta"] = {["inventory"] = {}, ["fields"] = {}}, ["name"] = "default:steelblock"}, {["param1"] = 82, ["x"] = 5, ["y"] = 7, ["z"] = 9, ["meta"] = {["inventory"] = {}, ["fields"] = {}}, ["name"] = "default:steelblock"}, {["param1"] = 82, ["x"] = 5, ["y"] = 7, ["z"] = 10, ["meta"] = {["inventory"] = {}, ["fields"] = {}}, ["name"] = "default:steelblock"}, {["param1"] = 82, ["x"] = 5, ["y"] = 7, ["z"] = 11, ["meta"] = {["inventory"] = {}, ["fields"] = {}}, ["name"] = "default:steelblock"}, {["param1"] = 82, ["x"] = 5, ["y"] = 7, ["z"] = 12, ["meta"] = {["inventory"] = {}, ["fields"] = {}}, ["name"] = "default:steelblock"}, {["param1"] = 82, ["x"] = 5, ["y"] = 7, ["z"] = 13, ["meta"] = {["inventory"] = {}, ["fields"] = {}}, ["name"] = "default:steelblock"}, {["param1"] = 82, ["x"] = 5, ["y"] = 8, ["z"] = 2, ["meta"] = {["inventory"] = {}, ["fields"] = {}}, ["name"] = "default:steelblock"}, {["param1"] = 82, ["x"] = 5, ["y"] = 8, ["z"] = 3, ["meta"] = {["inventory"] = {}, ["fields"] = {}}, ["name"] = "default:steelblock"}, {["param1"] = 82, ["x"] = 5, ["y"] = 8, ["z"] = 4, ["meta"] = {["inventory"] = {}, ["fields"] = {}}, ["name"] = "default:steelblock"}, {["param1"] = 82, ["x"] = 5, ["y"] = 8, ["z"] = 5, ["meta"] = {["inventory"] = {}, ["fields"] = {}}, ["name"] = "default:steelblock"}, {["param1"] = 82, ["x"] = 5, ["y"] = 8, ["z"] = 6, ["meta"] = {["inventory"] = {}, ["fields"] = {}}, ["name"] = "default:steelblock"}, {["param1"] = 82, ["x"] = 5, ["y"] = 8, ["z"] = 7, ["meta"] = {["inventory"] = {}, ["fields"] = {}}, ["name"] = "default:steelblock"}, {["param1"] = 82, ["x"] = 5, ["y"] = 8, ["z"] = 8, ["meta"] = {["inventory"] = {}, ["fields"] = {}}, ["name"] = "default:steelblock"}, {["param1"] = 82, ["x"] = 5, ["y"] = 8, ["z"] = 9, ["meta"] = {["inventory"] = {}, ["fields"] = {}}, ["name"] = "default:steelblock"}, {["param1"] = 82, ["x"] = 5, ["y"] = 8, ["z"] = 10, ["meta"] = {["inventory"] = {}, ["fields"] = {}}, ["name"] = "default:steelblock"}, {["param1"] = 82, ["x"] = 5, ["y"] = 8, ["z"] = 11, ["meta"] = {["inventory"] = {}, ["fields"] = {}}, ["name"] = "default:steelblock"}, {["param1"] = 82, ["x"] = 5, ["y"] = 8, ["z"] = 12, ["meta"] = {["inventory"] = {}, ["fields"] = {}}, ["name"] = "default:steelblock"}, {["param1"] = 82, ["x"] = 5, ["y"] = 8, ["z"] = 13, ["meta"] = {["inventory"] = {}, ["fields"] = {}}, ["name"] = "default:steelblock"}, {["param1"] = 87, ["x"] = 5, ["y"] = 9, ["z"] = 1, ["meta"] = {["inventory"] = {}, ["fields"] = {}}, ["name"] = "wool:grey"}, {["param1"] = 82, ["x"] = 5, ["y"] = 9, ["z"] = 2, ["meta"] = {["inventory"] = {}, ["fields"] = {}}, ["name"] = "default:steelblock"}, {["param1"] = 82, ["x"] = 5, ["y"] = 9, ["z"] = 3, ["meta"] = {["inventory"] = {}, ["fields"] = {}}, ["name"] = "default:steelblock"}, {["param1"] = 82, ["x"] = 5, ["y"] = 9, ["z"] = 4, ["meta"] = {["inventory"] = {}, ["fields"] = {}}, ["name"] = "default:steelblock"}, {["param1"] = 82, ["x"] = 5, ["y"] = 9, ["z"] = 5, ["meta"] = {["inventory"] = {}, ["fields"] = {}}, ["name"] = "default:steelblock"}, {["param1"] = 82, ["x"] = 5, ["y"] = 9, ["z"] = 6, ["meta"] = {["inventory"] = {}, ["fields"] = {}}, ["name"] = "default:steelblock"}, {["param1"] = 82, ["x"] = 5, ["y"] = 9, ["z"] = 7, ["meta"] = {["inventory"] = {}, ["fields"] = {}}, ["name"] = "default:steelblock"}, {["param1"] = 82, ["x"] = 5, ["y"] = 9, ["z"] = 8, ["meta"] = {["inventory"] = {}, ["fields"] = {}}, ["name"] = "default:steelblock"}, {["param1"] = 82, ["x"] = 5, ["y"] = 9, ["z"] = 9, ["meta"] = {["inventory"] = {}, ["fields"] = {}}, ["name"] = "default:steelblock"}, {["param1"] = 82, ["x"] = 5, ["y"] = 9, ["z"] = 10, ["meta"] = {["inventory"] = {}, ["fields"] = {}}, ["name"] = "default:steelblock"}, {["param1"] = 82, ["x"] = 5, ["y"] = 9, ["z"] = 11, ["meta"] = {["inventory"] = {}, ["fields"] = {}}, ["name"] = "default:steelblock"}, {["param1"] = 82, ["x"] = 5, ["y"] = 9, ["z"] = 12, ["meta"] = {["inventory"] = {}, ["fields"] = {}}, ["name"] = "default:steelblock"}, {["param1"] = 82, ["x"] = 5, ["y"] = 9, ["z"] = 13, ["meta"] = {["inventory"] = {}, ["fields"] = {}}, ["name"] = "default:steelblock"}, {["param1"] = 87, ["x"] = 5, ["y"] = 9, ["z"] = 14, ["meta"] = {["inventory"] = {}, ["fields"] = {}}, ["name"] = "wool:grey"}, {["param1"] = 82, ["x"] = 5, ["y"] = 10, ["z"] = 2, ["meta"] = {["inventory"] = {}, ["fields"] = {}}, ["name"] = "default:steelblock"}, {["param1"] = 82, ["x"] = 5, ["y"] = 10, ["z"] = 3, ["meta"] = {["inventory"] = {}, ["fields"] = {}}, ["name"] = "default:steelblock"}, {["param1"] = 82, ["x"] = 5, ["y"] = 10, ["z"] = 4, ["meta"] = {["inventory"] = {}, ["fields"] = {}}, ["name"] = "default:steelblock"}, {["param1"] = 82, ["x"] = 5, ["y"] = 10, ["z"] = 5, ["meta"] = {["inventory"] = {}, ["fields"] = {}}, ["name"] = "default:steelblock"}, {["param1"] = 82, ["x"] = 5, ["y"] = 10, ["z"] = 6, ["meta"] = {["inventory"] = {}, ["fields"] = {}}, ["name"] = "default:steelblock"}, {["param1"] = 82, ["x"] = 5, ["y"] = 10, ["z"] = 7, ["meta"] = {["inventory"] = {}, ["fields"] = {}}, ["name"] = "default:steelblock"}, {["param1"] = 82, ["x"] = 5, ["y"] = 10, ["z"] = 8, ["meta"] = {["inventory"] = {}, ["fields"] = {}}, ["name"] = "default:steelblock"}, {["param1"] = 82, ["x"] = 5, ["y"] = 10, ["z"] = 9, ["meta"] = {["inventory"] = {}, ["fields"] = {}}, ["name"] = "default:steelblock"}, {["param1"] = 82, ["x"] = 5, ["y"] = 10, ["z"] = 10, ["meta"] = {["inventory"] = {}, ["fields"] = {}}, ["name"] = "default:steelblock"}, {["param1"] = 82, ["x"] = 5, ["y"] = 10, ["z"] = 11, ["meta"] = {["inventory"] = {}, ["fields"] = {}}, ["name"] = "default:steelblock"}, {["param1"] = 82, ["x"] = 5, ["y"] = 10, ["z"] = 12, ["meta"] = {["inventory"] = {}, ["fields"] = {}}, ["name"] = "default:steelblock"}, {["param1"] = 82, ["x"] = 5, ["y"] = 10, ["z"] = 13, ["meta"] = {["inventory"] = {}, ["fields"] = {}}, ["name"] = "default:steelblock"}, {["x"] = 5, ["y"] = 11, ["z"] = 2, ["meta"] = {["inventory"] = {}, ["fields"] = {}}, ["name"] = "default:steelblock"}, {["x"] = 5, ["y"] = 11, ["z"] = 3, ["meta"] = {["inventory"] = {}, ["fields"] = {}}, ["name"] = "default:steelblock"}, {["x"] = 5, ["y"] = 11, ["z"] = 4, ["meta"] = {["inventory"] = {}, ["fields"] = {}}, ["name"] = "default:steelblock"}, {["x"] = 5, ["y"] = 11, ["z"] = 5, ["meta"] = {["inventory"] = {}, ["fields"] = {}}, ["name"] = "default:steelblock"}, {["x"] = 5, ["y"] = 11, ["z"] = 6, ["meta"] = {["inventory"] = {}, ["fields"] = {}}, ["name"] = "default:steelblock"}, {["x"] = 5, ["y"] = 11, ["z"] = 7, ["meta"] = {["inventory"] = {}, ["fields"] = {}}, ["name"] = "default:steelblock"}, {["x"] = 5, ["y"] = 11, ["z"] = 8, ["meta"] = {["inventory"] = {}, ["fields"] = {}}, ["name"] = "default:steelblock"}, {["x"] = 5, ["y"] = 11, ["z"] = 9, ["meta"] = {["inventory"] = {}, ["fields"] = {}}, ["name"] = "default:steelblock"}, {["x"] = 5, ["y"] = 11, ["z"] = 10, ["meta"] = {["inventory"] = {}, ["fields"] = {}}, ["name"] = "default:steelblock"}, {["x"] = 5, ["y"] = 11, ["z"] = 11, ["meta"] = {["inventory"] = {}, ["fields"] = {}}, ["name"] = "default:steelblock"}, {["x"] = 5, ["y"] = 11, ["z"] = 12, ["meta"] = {["inventory"] = {}, ["fields"] = {}}, ["name"] = "default:steelblock"}, {["x"] = 5, ["y"] = 11, ["z"] = 13, ["meta"] = {["inventory"] = {}, ["fields"] = {}}, ["name"] = "default:steelblock"}, {["x"] = 6, ["y"] = 3, ["z"] = 2, ["meta"] = {["inventory"] = {}, ["fields"] = {}}, ["name"] = "default:steelblock"}, {["x"] = 6, ["y"] = 3, ["z"] = 3, ["meta"] = {["inventory"] = {}, ["fields"] = {}}, ["name"] = "default:steelblock"}, {["x"] = 6, ["y"] = 3, ["z"] = 4, ["meta"] = {["inventory"] = {}, ["fields"] = {}}, ["name"] = "default:steelblock"}, {["x"] = 6, ["y"] = 3, ["z"] = 5, ["meta"] = {["inventory"] = {}, ["fields"] = {}}, ["name"] = "default:steelblock"}, {["x"] = 6, ["y"] = 3, ["z"] = 6, ["meta"] = {["inventory"] = {}, ["fields"] = {}}, ["name"] = "default:steelblock"}, {["x"] = 6, ["y"] = 3, ["z"] = 7, ["meta"] = {["inventory"] = {}, ["fields"] = {}}, ["name"] = "default:steelblock"}, {["x"] = 6, ["y"] = 3, ["z"] = 8, ["meta"] = {["inventory"] = {}, ["fields"] = {}}, ["name"] = "default:steelblock"}, {["x"] = 6, ["y"] = 3, ["z"] = 9, ["meta"] = {["inventory"] = {}, ["fields"] = {}}, ["name"] = "default:steelblock"}, {["x"] = 6, ["y"] = 3, ["z"] = 10, ["meta"] = {["inventory"] = {}, ["fields"] = {}}, ["name"] = "default:steelblock"}, {["x"] = 6, ["y"] = 3, ["z"] = 11, ["meta"] = {["inventory"] = {}, ["fields"] = {}}, ["name"] = "default:steelblock"}, {["x"] = 6, ["y"] = 3, ["z"] = 12, ["meta"] = {["inventory"] = {}, ["fields"] = {}}, ["name"] = "default:steelblock"}, {["x"] = 6, ["y"] = 3, ["z"] = 13, ["meta"] = {["inventory"] = {}, ["fields"] = {}}, ["name"] = "default:steelblock"}, {["param1"] = 82, ["x"] = 6, ["y"] = 4, ["z"] = 2, ["meta"] = {["inventory"] = {}, ["fields"] = {}}, ["name"] = "default:steelblock"}, {["param1"] = 82, ["x"] = 6, ["y"] = 4, ["z"] = 3, ["meta"] = {["inventory"] = {}, ["fields"] = {}}, ["name"] = "default:steelblock"}, {["param1"] = 82, ["x"] = 6, ["y"] = 4, ["z"] = 4, ["meta"] = {["inventory"] = {}, ["fields"] = {}}, ["name"] = "default:steelblock"}, {["param1"] = 82, ["x"] = 6, ["y"] = 4, ["z"] = 5, ["meta"] = {["inventory"] = {}, ["fields"] = {}}, ["name"] = "default:steelblock"}, {["param1"] = 82, ["x"] = 6, ["y"] = 4, ["z"] = 6, ["meta"] = {["inventory"] = {}, ["fields"] = {}}, ["name"] = "default:steelblock"}, {["param1"] = 82, ["x"] = 6, ["y"] = 4, ["z"] = 7, ["meta"] = {["inventory"] = {}, ["fields"] = {}}, ["name"] = "default:steelblock"}, {["param1"] = 82, ["x"] = 6, ["y"] = 4, ["z"] = 8, ["meta"] = {["inventory"] = {}, ["fields"] = {}}, ["name"] = "default:steelblock"}, {["param1"] = 82, ["x"] = 6, ["y"] = 4, ["z"] = 9, ["meta"] = {["inventory"] = {}, ["fields"] = {}}, ["name"] = "default:steelblock"}, {["param1"] = 82, ["x"] = 6, ["y"] = 4, ["z"] = 10, ["meta"] = {["inventory"] = {}, ["fields"] = {}}, ["name"] = "default:steelblock"}, {["param1"] = 82, ["x"] = 6, ["y"] = 4, ["z"] = 11, ["meta"] = {["inventory"] = {}, ["fields"] = {}}, ["name"] = "default:steelblock"}, {["param1"] = 82, ["x"] = 6, ["y"] = 4, ["z"] = 12, ["meta"] = {["inventory"] = {}, ["fields"] = {}}, ["name"] = "default:steelblock"}, {["param1"] = 82, ["x"] = 6, ["y"] = 4, ["z"] = 13, ["meta"] = {["inventory"] = {}, ["fields"] = {}}, ["name"] = "default:steelblock"}, {["param1"] = 82, ["x"] = 6, ["y"] = 5, ["z"] = 2, ["meta"] = {["inventory"] = {}, ["fields"] = {}}, ["name"] = "default:steelblock"}, {["param1"] = 82, ["x"] = 6, ["y"] = 5, ["z"] = 3, ["meta"] = {["inventory"] = {}, ["fields"] = {}}, ["name"] = "default:steelblock"}, {["param1"] = 82, ["x"] = 6, ["y"] = 5, ["z"] = 4, ["meta"] = {["inventory"] = {}, ["fields"] = {}}, ["name"] = "default:steelblock"}, {["param1"] = 82, ["x"] = 6, ["y"] = 5, ["z"] = 5, ["meta"] = {["inventory"] = {}, ["fields"] = {}}, ["name"] = "default:steelblock"}, {["param1"] = 82, ["x"] = 6, ["y"] = 5, ["z"] = 6, ["meta"] = {["inventory"] = {}, ["fields"] = {}}, ["name"] = "default:steelblock"}, {["param1"] = 82, ["x"] = 6, ["y"] = 5, ["z"] = 7, ["meta"] = {["inventory"] = {}, ["fields"] = {}}, ["name"] = "default:steelblock"}, {["param1"] = 82, ["x"] = 6, ["y"] = 5, ["z"] = 8, ["meta"] = {["inventory"] = {}, ["fields"] = {}}, ["name"] = "default:steelblock"}, {["param1"] = 82, ["x"] = 6, ["y"] = 5, ["z"] = 9, ["meta"] = {["inventory"] = {}, ["fields"] = {}}, ["name"] = "default:steelblock"}, {["param1"] = 82, ["x"] = 6, ["y"] = 5, ["z"] = 10, ["meta"] = {["inventory"] = {}, ["fields"] = {}}, ["name"] = "default:steelblock"}, {["param1"] = 82, ["x"] = 6, ["y"] = 5, ["z"] = 11, ["meta"] = {["inventory"] = {}, ["fields"] = {}}, ["name"] = "default:steelblock"}, {["param1"] = 82, ["x"] = 6, ["y"] = 5, ["z"] = 12, ["meta"] = {["inventory"] = {}, ["fields"] = {}}, ["name"] = "default:steelblock"}, {["param1"] = 82, ["x"] = 6, ["y"] = 5, ["z"] = 13, ["meta"] = {["inventory"] = {}, ["fields"] = {}}, ["name"] = "default:steelblock"}, {["param1"] = 87, ["x"] = 6, ["y"] = 6, ["z"] = 1, ["meta"] = {["inventory"] = {}, ["fields"] = {}}, ["name"] = "wool:grey"}, {["param1"] = 82, ["x"] = 6, ["y"] = 6, ["z"] = 2, ["meta"] = {["inventory"] = {}, ["fields"] = {}}, ["name"] = "default:steelblock"}, {["param1"] = 82, ["x"] = 6, ["y"] = 6, ["z"] = 3, ["meta"] = {["inventory"] = {}, ["fields"] = {}}, ["name"] = "default:steelblock"}, {["param1"] = 82, ["x"] = 6, ["y"] = 6, ["z"] = 4, ["meta"] = {["inventory"] = {}, ["fields"] = {}}, ["name"] = "default:steelblock"}, {["param1"] = 82, ["x"] = 6, ["y"] = 6, ["z"] = 5, ["meta"] = {["inventory"] = {}, ["fields"] = {}}, ["name"] = "default:steelblock"}, {["param1"] = 82, ["x"] = 6, ["y"] = 6, ["z"] = 6, ["meta"] = {["inventory"] = {}, ["fields"] = {}}, ["name"] = "default:steelblock"}, {["param1"] = 82, ["x"] = 6, ["y"] = 6, ["z"] = 7, ["meta"] = {["inventory"] = {}, ["fields"] = {}}, ["name"] = "default:steelblock"}, {["param1"] = 82, ["x"] = 6, ["y"] = 6, ["z"] = 8, ["meta"] = {["inventory"] = {}, ["fields"] = {}}, ["name"] = "default:steelblock"}, {["param1"] = 82, ["x"] = 6, ["y"] = 6, ["z"] = 9, ["meta"] = {["inventory"] = {}, ["fields"] = {}}, ["name"] = "default:steelblock"}, {["param1"] = 82, ["x"] = 6, ["y"] = 6, ["z"] = 10, ["meta"] = {["inventory"] = {}, ["fields"] = {}}, ["name"] = "default:steelblock"}, {["param1"] = 82, ["x"] = 6, ["y"] = 6, ["z"] = 11, ["meta"] = {["inventory"] = {}, ["fields"] = {}}, ["name"] = "default:steelblock"}, {["param1"] = 82, ["x"] = 6, ["y"] = 6, ["z"] = 12, ["meta"] = {["inventory"] = {}, ["fields"] = {}}, ["name"] = "default:steelblock"}, {["param1"] = 82, ["x"] = 6, ["y"] = 6, ["z"] = 13, ["meta"] = {["inventory"] = {}, ["fields"] = {}}, ["name"] = "default:steelblock"}, {["param1"] = 87, ["x"] = 6, ["y"] = 6, ["z"] = 14, ["meta"] = {["inventory"] = {}, ["fields"] = {}}, ["name"] = "wool:grey"}, {["param1"] = 87, ["x"] = 6, ["y"] = 7, ["z"] = 1, ["meta"] = {["inventory"] = {}, ["fields"] = {}}, ["name"] = "wool:grey"}, {["param1"] = 82, ["x"] = 6, ["y"] = 7, ["z"] = 2, ["meta"] = {["inventory"] = {}, ["fields"] = {}}, ["name"] = "default:steelblock"}, {["param1"] = 82, ["x"] = 6, ["y"] = 7, ["z"] = 3, ["meta"] = {["inventory"] = {}, ["fields"] = {}}, ["name"] = "default:steelblock"}, {["param1"] = 82, ["x"] = 6, ["y"] = 7, ["z"] = 4, ["meta"] = {["inventory"] = {}, ["fields"] = {}}, ["name"] = "default:steelblock"}, {["param1"] = 82, ["x"] = 6, ["y"] = 7, ["z"] = 5, ["meta"] = {["inventory"] = {}, ["fields"] = {}}, ["name"] = "default:steelblock"}, {["param1"] = 82, ["x"] = 6, ["y"] = 7, ["z"] = 6, ["meta"] = {["inventory"] = {}, ["fields"] = {}}, ["name"] = "default:steelblock"}, {["param1"] = 82, ["x"] = 6, ["y"] = 7, ["z"] = 7, ["meta"] = {["inventory"] = {}, ["fields"] = {}}, ["name"] = "default:steelblock"}, {["param1"] = 82, ["x"] = 6, ["y"] = 7, ["z"] = 8, ["meta"] = {["inventory"] = {}, ["fields"] = {}}, ["name"] = "default:steelblock"}, {["param1"] = 82, ["x"] = 6, ["y"] = 7, ["z"] = 9, ["meta"] = {["inventory"] = {}, ["fields"] = {}}, ["name"] = "default:steelblock"}, {["param1"] = 82, ["x"] = 6, ["y"] = 7, ["z"] = 10, ["meta"] = {["inventory"] = {}, ["fields"] = {}}, ["name"] = "default:steelblock"}, {["param1"] = 82, ["x"] = 6, ["y"] = 7, ["z"] = 11, ["meta"] = {["inventory"] = {}, ["fields"] = {}}, ["name"] = "default:steelblock"}, {["param1"] = 82, ["x"] = 6, ["y"] = 7, ["z"] = 12, ["meta"] = {["inventory"] = {}, ["fields"] = {}}, ["name"] = "default:steelblock"}, {["param1"] = 82, ["x"] = 6, ["y"] = 7, ["z"] = 13, ["meta"] = {["inventory"] = {}, ["fields"] = {}}, ["name"] = "default:steelblock"}, {["param1"] = 87, ["x"] = 6, ["y"] = 7, ["z"] = 14, ["meta"] = {["inventory"] = {}, ["fields"] = {}}, ["name"] = "wool:grey"}, {["param1"] = 87, ["x"] = 6, ["y"] = 8, ["z"] = 1, ["meta"] = {["inventory"] = {}, ["fields"] = {}}, ["name"] = "wool:grey"}, {["param1"] = 82, ["x"] = 6, ["y"] = 8, ["z"] = 2, ["meta"] = {["inventory"] = {}, ["fields"] = {}}, ["name"] = "default:steelblock"}, {["param1"] = 82, ["x"] = 6, ["y"] = 8, ["z"] = 3, ["meta"] = {["inventory"] = {}, ["fields"] = {}}, ["name"] = "default:steelblock"}, {["param1"] = 82, ["x"] = 6, ["y"] = 8, ["z"] = 4, ["meta"] = {["inventory"] = {}, ["fields"] = {}}, ["name"] = "default:steelblock"}, {["param1"] = 82, ["x"] = 6, ["y"] = 8, ["z"] = 5, ["meta"] = {["inventory"] = {}, ["fields"] = {}}, ["name"] = "default:steelblock"}, {["param1"] = 82, ["x"] = 6, ["y"] = 8, ["z"] = 6, ["meta"] = {["inventory"] = {}, ["fields"] = {}}, ["name"] = "default:steelblock"}, {["param1"] = 82, ["x"] = 6, ["y"] = 8, ["z"] = 7, ["meta"] = {["inventory"] = {}, ["fields"] = {}}, ["name"] = "default:steelblock"}, {["param1"] = 82, ["x"] = 6, ["y"] = 8, ["z"] = 8, ["meta"] = {["inventory"] = {}, ["fields"] = {}}, ["name"] = "default:steelblock"}, {["param1"] = 82, ["x"] = 6, ["y"] = 8, ["z"] = 9, ["meta"] = {["inventory"] = {}, ["fields"] = {}}, ["name"] = "default:steelblock"}, {["param1"] = 82, ["x"] = 6, ["y"] = 8, ["z"] = 10, ["meta"] = {["inventory"] = {}, ["fields"] = {}}, ["name"] = "default:steelblock"}, {["param1"] = 82, ["x"] = 6, ["y"] = 8, ["z"] = 11, ["meta"] = {["inventory"] = {}, ["fields"] = {}}, ["name"] = "default:steelblock"}, {["param1"] = 82, ["x"] = 6, ["y"] = 8, ["z"] = 12, ["meta"] = {["inventory"] = {}, ["fields"] = {}}, ["name"] = "default:steelblock"}, {["param1"] = 82, ["x"] = 6, ["y"] = 8, ["z"] = 13, ["meta"] = {["inventory"] = {}, ["fields"] = {}}, ["name"] = "default:steelblock"}, {["param1"] = 87, ["x"] = 6, ["y"] = 8, ["z"] = 14, ["meta"] = {["inventory"] = {}, ["fields"] = {}}, ["name"] = "wool:grey"}, {["param1"] = 87, ["x"] = 6, ["y"] = 9, ["z"] = 1, ["meta"] = {["inventory"] = {}, ["fields"] = {}}, ["name"] = "wool:grey"}, {["param1"] = 82, ["x"] = 6, ["y"] = 9, ["z"] = 2, ["meta"] = {["inventory"] = {}, ["fields"] = {}}, ["name"] = "default:steelblock"}, {["param1"] = 82, ["x"] = 6, ["y"] = 9, ["z"] = 3, ["meta"] = {["inventory"] = {}, ["fields"] = {}}, ["name"] = "default:steelblock"}, {["param1"] = 82, ["x"] = 6, ["y"] = 9, ["z"] = 4, ["meta"] = {["inventory"] = {}, ["fields"] = {}}, ["name"] = "default:steelblock"}, {["param1"] = 82, ["x"] = 6, ["y"] = 9, ["z"] = 5, ["meta"] = {["inventory"] = {}, ["fields"] = {}}, ["name"] = "default:steelblock"}, {["param1"] = 82, ["x"] = 6, ["y"] = 9, ["z"] = 6, ["meta"] = {["inventory"] = {}, ["fields"] = {}}, ["name"] = "default:steelblock"}, {["param1"] = 82, ["x"] = 6, ["y"] = 9, ["z"] = 7, ["meta"] = {["inventory"] = {}, ["fields"] = {}}, ["name"] = "default:steelblock"}, {["param1"] = 82, ["x"] = 6, ["y"] = 9, ["z"] = 8, ["meta"] = {["inventory"] = {}, ["fields"] = {}}, ["name"] = "default:steelblock"}, {["param1"] = 82, ["x"] = 6, ["y"] = 9, ["z"] = 9, ["meta"] = {["inventory"] = {}, ["fields"] = {}}, ["name"] = "default:steelblock"}, {["param1"] = 82, ["x"] = 6, ["y"] = 9, ["z"] = 10, ["meta"] = {["inventory"] = {}, ["fields"] = {}}, ["name"] = "default:steelblock"}, {["param1"] = 82, ["x"] = 6, ["y"] = 9, ["z"] = 11, ["meta"] = {["inventory"] = {}, ["fields"] = {}}, ["name"] = "default:steelblock"}, {["param1"] = 82, ["x"] = 6, ["y"] = 9, ["z"] = 12, ["meta"] = {["inventory"] = {}, ["fields"] = {}}, ["name"] = "default:steelblock"}, {["param1"] = 82, ["x"] = 6, ["y"] = 9, ["z"] = 13, ["meta"] = {["inventory"] = {}, ["fields"] = {}}, ["name"] = "default:steelblock"}, {["param1"] = 87, ["x"] = 6, ["y"] = 9, ["z"] = 14, ["meta"] = {["inventory"] = {}, ["fields"] = {}}, ["name"] = "wool:grey"}, {["param1"] = 82, ["x"] = 6, ["y"] = 10, ["z"] = 2, ["meta"] = {["inventory"] = {}, ["fields"] = {}}, ["name"] = "default:steelblock"}, {["param1"] = 82, ["x"] = 6, ["y"] = 10, ["z"] = 3, ["meta"] = {["inventory"] = {}, ["fields"] = {}}, ["name"] = "default:steelblock"}, {["param1"] = 82, ["x"] = 6, ["y"] = 10, ["z"] = 4, ["meta"] = {["inventory"] = {}, ["fields"] = {}}, ["name"] = "default:steelblock"}, {["param1"] = 82, ["x"] = 6, ["y"] = 10, ["z"] = 5, ["meta"] = {["inventory"] = {}, ["fields"] = {}}, ["name"] = "default:steelblock"}, {["param1"] = 82, ["x"] = 6, ["y"] = 10, ["z"] = 6, ["meta"] = {["inventory"] = {}, ["fields"] = {}}, ["name"] = "default:steelblock"}, {["param1"] = 82, ["x"] = 6, ["y"] = 10, ["z"] = 7, ["meta"] = {["inventory"] = {}, ["fields"] = {}}, ["name"] = "default:steelblock"}, {["param1"] = 82, ["x"] = 6, ["y"] = 10, ["z"] = 8, ["meta"] = {["inventory"] = {}, ["fields"] = {}}, ["name"] = "default:steelblock"}, {["param1"] = 82, ["x"] = 6, ["y"] = 10, ["z"] = 9, ["meta"] = {["inventory"] = {}, ["fields"] = {}}, ["name"] = "default:steelblock"}, {["param1"] = 82, ["x"] = 6, ["y"] = 10, ["z"] = 10, ["meta"] = {["inventory"] = {}, ["fields"] = {}}, ["name"] = "default:steelblock"}, {["param1"] = 82, ["x"] = 6, ["y"] = 10, ["z"] = 11, ["meta"] = {["inventory"] = {}, ["fields"] = {}}, ["name"] = "default:steelblock"}, {["param1"] = 82, ["x"] = 6, ["y"] = 10, ["z"] = 12, ["meta"] = {["inventory"] = {}, ["fields"] = {}}, ["name"] = "default:steelblock"}, {["param1"] = 82, ["x"] = 6, ["y"] = 10, ["z"] = 13, ["meta"] = {["inventory"] = {}, ["fields"] = {}}, ["name"] = "default:steelblock"}, {["param1"] = 82, ["x"] = 6, ["y"] = 11, ["z"] = 2, ["meta"] = {["inventory"] = {}, ["fields"] = {}}, ["name"] = "default:steelblock"}, {["param1"] = 82, ["x"] = 6, ["y"] = 11, ["z"] = 3, ["meta"] = {["inventory"] = {}, ["fields"] = {}}, ["name"] = "default:steelblock"}, {["param1"] = 82, ["x"] = 6, ["y"] = 11, ["z"] = 4, ["meta"] = {["inventory"] = {}, ["fields"] = {}}, ["name"] = "default:steelblock"}, {["param1"] = 82, ["x"] = 6, ["y"] = 11, ["z"] = 5, ["meta"] = {["inventory"] = {}, ["fields"] = {}}, ["name"] = "default:steelblock"}, {["param1"] = 82, ["x"] = 6, ["y"] = 11, ["z"] = 6, ["meta"] = {["inventory"] = {}, ["fields"] = {}}, ["name"] = "default:steelblock"}, {["param1"] = 82, ["x"] = 6, ["y"] = 11, ["z"] = 7, ["meta"] = {["inventory"] = {}, ["fields"] = {}}, ["name"] = "default:steelblock"}, {["param1"] = 82, ["x"] = 6, ["y"] = 11, ["z"] = 8, ["meta"] = {["inventory"] = {}, ["fields"] = {}}, ["name"] = "default:steelblock"}, {["param1"] = 82, ["x"] = 6, ["y"] = 11, ["z"] = 9, ["meta"] = {["inventory"] = {}, ["fields"] = {}}, ["name"] = "default:steelblock"}, {["param1"] = 82, ["x"] = 6, ["y"] = 11, ["z"] = 10, ["meta"] = {["inventory"] = {}, ["fields"] = {}}, ["name"] = "default:steelblock"}, {["param1"] = 82, ["x"] = 6, ["y"] = 11, ["z"] = 11, ["meta"] = {["inventory"] = {}, ["fields"] = {}}, ["name"] = "default:steelblock"}, {["param1"] = 82, ["x"] = 6, ["y"] = 11, ["z"] = 12, ["meta"] = {["inventory"] = {}, ["fields"] = {}}, ["name"] = "default:steelblock"}, {["param1"] = 82, ["x"] = 6, ["y"] = 11, ["z"] = 13, ["meta"] = {["inventory"] = {}, ["fields"] = {}}, ["name"] = "default:steelblock"}, {["x"] = 6, ["y"] = 12, ["z"] = 2, ["meta"] = {["inventory"] = {}, ["fields"] = {}}, ["name"] = "default:steelblock"}, {["x"] = 6, ["y"] = 12, ["z"] = 3, ["meta"] = {["inventory"] = {}, ["fields"] = {}}, ["name"] = "default:steelblock"}, {["x"] = 6, ["y"] = 12, ["z"] = 4, ["meta"] = {["inventory"] = {}, ["fields"] = {}}, ["name"] = "default:steelblock"}, {["x"] = 6, ["y"] = 12, ["z"] = 5, ["meta"] = {["inventory"] = {}, ["fields"] = {}}, ["name"] = "default:steelblock"}, {["x"] = 6, ["y"] = 12, ["z"] = 6, ["meta"] = {["inventory"] = {}, ["fields"] = {}}, ["name"] = "default:steelblock"}, {["x"] = 6, ["y"] = 12, ["z"] = 7, ["meta"] = {["inventory"] = {}, ["fields"] = {}}, ["name"] = "default:steelblock"}, {["x"] = 6, ["y"] = 12, ["z"] = 8, ["meta"] = {["inventory"] = {}, ["fields"] = {}}, ["name"] = "default:steelblock"}, {["x"] = 6, ["y"] = 12, ["z"] = 9, ["meta"] = {["inventory"] = {}, ["fields"] = {}}, ["name"] = "default:steelblock"}, {["x"] = 6, ["y"] = 12, ["z"] = 10, ["meta"] = {["inventory"] = {}, ["fields"] = {}}, ["name"] = "default:steelblock"}, {["x"] = 6, ["y"] = 12, ["z"] = 11, ["meta"] = {["inventory"] = {}, ["fields"] = {}}, ["name"] = "default:steelblock"}, {["x"] = 6, ["y"] = 12, ["z"] = 12, ["meta"] = {["inventory"] = {}, ["fields"] = {}}, ["name"] = "default:steelblock"}, {["x"] = 6, ["y"] = 12, ["z"] = 13, ["meta"] = {["inventory"] = {}, ["fields"] = {}}, ["name"] = "default:steelblock"}, {["x"] = 7, ["y"] = 3, ["z"] = 2, ["meta"] = {["inventory"] = {}, ["fields"] = {}}, ["name"] = "default:steelblock"}, {["x"] = 7, ["y"] = 3, ["z"] = 3, ["meta"] = {["inventory"] = {}, ["fields"] = {}}, ["name"] = "default:steelblock"}, {["x"] = 7, ["y"] = 3, ["z"] = 4, ["meta"] = {["inventory"] = {}, ["fields"] = {}}, ["name"] = "default:steelblock"}, {["x"] = 7, ["y"] = 3, ["z"] = 5, ["meta"] = {["inventory"] = {}, ["fields"] = {}}, ["name"] = "default:steelblock"}, {["x"] = 7, ["y"] = 3, ["z"] = 6, ["meta"] = {["inventory"] = {}, ["fields"] = {}}, ["name"] = "default:steelblock"}, {["x"] = 7, ["y"] = 3, ["z"] = 7, ["meta"] = {["inventory"] = {}, ["fields"] = {}}, ["name"] = "default:steelblock"}, {["x"] = 7, ["y"] = 3, ["z"] = 8, ["meta"] = {["inventory"] = {}, ["fields"] = {}}, ["name"] = "default:steelblock"}, {["x"] = 7, ["y"] = 3, ["z"] = 9, ["meta"] = {["inventory"] = {}, ["fields"] = {}}, ["name"] = "default:steelblock"}, {["x"] = 7, ["y"] = 3, ["z"] = 10, ["meta"] = {["inventory"] = {}, ["fields"] = {}}, ["name"] = "default:steelblock"}, {["x"] = 7, ["y"] = 3, ["z"] = 11, ["meta"] = {["inventory"] = {}, ["fields"] = {}}, ["name"] = "default:steelblock"}, {["x"] = 7, ["y"] = 3, ["z"] = 12, ["meta"] = {["inventory"] = {}, ["fields"] = {}}, ["name"] = "default:steelblock"}, {["x"] = 7, ["y"] = 3, ["z"] = 13, ["meta"] = {["inventory"] = {}, ["fields"] = {}}, ["name"] = "default:steelblock"}, {["param1"] = 82, ["x"] = 7, ["y"] = 4, ["z"] = 2, ["meta"] = {["inventory"] = {}, ["fields"] = {}}, ["name"] = "default:steelblock"}, {["param1"] = 82, ["x"] = 7, ["y"] = 4, ["z"] = 3, ["meta"] = {["inventory"] = {}, ["fields"] = {}}, ["name"] = "default:steelblock"}, {["param1"] = 82, ["x"] = 7, ["y"] = 4, ["z"] = 4, ["meta"] = {["inventory"] = {}, ["fields"] = {}}, ["name"] = "default:steelblock"}, {["param1"] = 82, ["x"] = 7, ["y"] = 4, ["z"] = 5, ["meta"] = {["inventory"] = {}, ["fields"] = {}}, ["name"] = "default:steelblock"}, {["param1"] = 82, ["x"] = 7, ["y"] = 4, ["z"] = 6, ["meta"] = {["inventory"] = {}, ["fields"] = {}}, ["name"] = "default:steelblock"}, {["param1"] = 82, ["x"] = 7, ["y"] = 4, ["z"] = 7, ["meta"] = {["inventory"] = {}, ["fields"] = {}}, ["name"] = "default:steelblock"}, {["param1"] = 82, ["x"] = 7, ["y"] = 4, ["z"] = 8, ["meta"] = {["inventory"] = {}, ["fields"] = {}}, ["name"] = "default:steelblock"}, {["param1"] = 82, ["x"] = 7, ["y"] = 4, ["z"] = 9, ["meta"] = {["inventory"] = {}, ["fields"] = {}}, ["name"] = "default:steelblock"}, {["param1"] = 82, ["x"] = 7, ["y"] = 4, ["z"] = 10, ["meta"] = {["inventory"] = {}, ["fields"] = {}}, ["name"] = "default:steelblock"}, {["param1"] = 82, ["x"] = 7, ["y"] = 4, ["z"] = 11, ["meta"] = {["inventory"] = {}, ["fields"] = {}}, ["name"] = "default:steelblock"}, {["param1"] = 82, ["x"] = 7, ["y"] = 4, ["z"] = 12, ["meta"] = {["inventory"] = {}, ["fields"] = {}}, ["name"] = "default:steelblock"}, {["param1"] = 82, ["x"] = 7, ["y"] = 4, ["z"] = 13, ["meta"] = {["inventory"] = {}, ["fields"] = {}}, ["name"] = "default:steelblock"}, {["param1"] = 82, ["x"] = 7, ["y"] = 5, ["z"] = 2, ["meta"] = {["inventory"] = {}, ["fields"] = {}}, ["name"] = "default:steelblock"}, {["param1"] = 82, ["x"] = 7, ["y"] = 5, ["z"] = 3, ["meta"] = {["inventory"] = {}, ["fields"] = {}}, ["name"] = "default:steelblock"}, {["param1"] = 82, ["x"] = 7, ["y"] = 5, ["z"] = 4, ["meta"] = {["inventory"] = {}, ["fields"] = {}}, ["name"] = "default:steelblock"}, {["param1"] = 82, ["x"] = 7, ["y"] = 5, ["z"] = 5, ["meta"] = {["inventory"] = {}, ["fields"] = {}}, ["name"] = "default:steelblock"}, {["param1"] = 82, ["x"] = 7, ["y"] = 5, ["z"] = 6, ["meta"] = {["inventory"] = {}, ["fields"] = {}}, ["name"] = "default:steelblock"}, {["param1"] = 82, ["x"] = 7, ["y"] = 5, ["z"] = 7, ["meta"] = {["inventory"] = {}, ["fields"] = {}}, ["name"] = "default:steelblock"}, {["param1"] = 82, ["x"] = 7, ["y"] = 5, ["z"] = 8, ["meta"] = {["inventory"] = {}, ["fields"] = {}}, ["name"] = "default:steelblock"}, {["param1"] = 82, ["x"] = 7, ["y"] = 5, ["z"] = 9, ["meta"] = {["inventory"] = {}, ["fields"] = {}}, ["name"] = "default:steelblock"}, {["param1"] = 82, ["x"] = 7, ["y"] = 5, ["z"] = 10, ["meta"] = {["inventory"] = {}, ["fields"] = {}}, ["name"] = "default:steelblock"}, {["param1"] = 82, ["x"] = 7, ["y"] = 5, ["z"] = 11, ["meta"] = {["inventory"] = {}, ["fields"] = {}}, ["name"] = "default:steelblock"}, {["param1"] = 82, ["x"] = 7, ["y"] = 5, ["z"] = 12, ["meta"] = {["inventory"] = {}, ["fields"] = {}}, ["name"] = "default:steelblock"}, {["param1"] = 82, ["x"] = 7, ["y"] = 5, ["z"] = 13, ["meta"] = {["inventory"] = {}, ["fields"] = {}}, ["name"] = "default:steelblock"}, {["param1"] = 87, ["x"] = 7, ["y"] = 6, ["z"] = 1, ["meta"] = {["inventory"] = {}, ["fields"] = {}}, ["name"] = "wool:grey"}, {["param1"] = 82, ["x"] = 7, ["y"] = 6, ["z"] = 2, ["meta"] = {["inventory"] = {}, ["fields"] = {}}, ["name"] = "default:steelblock"}, {["param1"] = 82, ["x"] = 7, ["y"] = 6, ["z"] = 3, ["meta"] = {["inventory"] = {}, ["fields"] = {}}, ["name"] = "default:steelblock"}, {["param1"] = 82, ["x"] = 7, ["y"] = 6, ["z"] = 4, ["meta"] = {["inventory"] = {}, ["fields"] = {}}, ["name"] = "default:steelblock"}, {["param1"] = 82, ["x"] = 7, ["y"] = 6, ["z"] = 5, ["meta"] = {["inventory"] = {}, ["fields"] = {}}, ["name"] = "default:steelblock"}, {["param1"] = 82, ["x"] = 7, ["y"] = 6, ["z"] = 6, ["meta"] = {["inventory"] = {}, ["fields"] = {}}, ["name"] = "default:steelblock"}, {["param1"] = 82, ["x"] = 7, ["y"] = 6, ["z"] = 7, ["meta"] = {["inventory"] = {}, ["fields"] = {}}, ["name"] = "default:steelblock"}, {["param1"] = 82, ["x"] = 7, ["y"] = 6, ["z"] = 8, ["meta"] = {["inventory"] = {}, ["fields"] = {}}, ["name"] = "default:steelblock"}, {["param1"] = 82, ["x"] = 7, ["y"] = 6, ["z"] = 9, ["meta"] = {["inventory"] = {}, ["fields"] = {}}, ["name"] = "default:steelblock"}, {["param1"] = 82, ["x"] = 7, ["y"] = 6, ["z"] = 10, ["meta"] = {["inventory"] = {}, ["fields"] = {}}, ["name"] = "default:steelblock"}, {["param1"] = 82, ["x"] = 7, ["y"] = 6, ["z"] = 11, ["meta"] = {["inventory"] = {}, ["fields"] = {}}, ["name"] = "default:steelblock"}, {["param1"] = 82, ["x"] = 7, ["y"] = 6, ["z"] = 12, ["meta"] = {["inventory"] = {}, ["fields"] = {}}, ["name"] = "default:steelblock"}, {["param1"] = 82, ["x"] = 7, ["y"] = 6, ["z"] = 13, ["meta"] = {["inventory"] = {}, ["fields"] = {}}, ["name"] = "default:steelblock"}, {["param1"] = 87, ["x"] = 7, ["y"] = 6, ["z"] = 14, ["meta"] = {["inventory"] = {}, ["fields"] = {}}, ["name"] = "wool:grey"}, {["param1"] = 98, ["x"] = 7, ["y"] = 7, ["z"] = 0, ["meta"] = {["inventory"] = {}, ["fields"] = {}}, ["name"] = "wool:red"}, {["param1"] = 98, ["x"] = 7, ["y"] = 7, ["z"] = 1, ["meta"] = {["inventory"] = {}, ["fields"] = {}}, ["name"] = "wool:red"}, {["param1"] = 82, ["x"] = 7, ["y"] = 7, ["z"] = 2, ["meta"] = {["inventory"] = {}, ["fields"] = {}}, ["name"] = "default:steelblock"}, {["param1"] = 82, ["x"] = 7, ["y"] = 7, ["z"] = 3, ["meta"] = {["inventory"] = {}, ["fields"] = {}}, ["name"] = "default:steelblock"}, {["param1"] = 82, ["x"] = 7, ["y"] = 7, ["z"] = 4, ["meta"] = {["inventory"] = {}, ["fields"] = {}}, ["name"] = "default:steelblock"}, {["param1"] = 82, ["x"] = 7, ["y"] = 7, ["z"] = 5, ["meta"] = {["inventory"] = {}, ["fields"] = {}}, ["name"] = "default:steelblock"}, {["param1"] = 82, ["x"] = 7, ["y"] = 7, ["z"] = 6, ["meta"] = {["inventory"] = {}, ["fields"] = {}}, ["name"] = "default:steelblock"}, {["param1"] = 82, ["x"] = 7, ["y"] = 7, ["z"] = 7, ["meta"] = {["inventory"] = {}, ["fields"] = {}}, ["name"] = "default:steelblock"}, {["param1"] = 82, ["x"] = 7, ["y"] = 7, ["z"] = 8, ["meta"] = {["inventory"] = {}, ["fields"] = {}}, ["name"] = "default:steelblock"}, {["param1"] = 82, ["x"] = 7, ["y"] = 7, ["z"] = 9, ["meta"] = {["inventory"] = {}, ["fields"] = {}}, ["name"] = "default:steelblock"}, {["param1"] = 82, ["x"] = 7, ["y"] = 7, ["z"] = 10, ["meta"] = {["inventory"] = {}, ["fields"] = {}}, ["name"] = "default:steelblock"}, {["param1"] = 82, ["x"] = 7, ["y"] = 7, ["z"] = 11, ["meta"] = {["inventory"] = {}, ["fields"] = {}}, ["name"] = "default:steelblock"}, {["param1"] = 82, ["x"] = 7, ["y"] = 7, ["z"] = 12, ["meta"] = {["inventory"] = {}, ["fields"] = {}}, ["name"] = "default:steelblock"}, {["param1"] = 82, ["x"] = 7, ["y"] = 7, ["z"] = 13, ["meta"] = {["inventory"] = {}, ["fields"] = {}}, ["name"] = "default:steelblock"}, {["param1"] = 95, ["x"] = 7, ["y"] = 7, ["z"] = 14, ["meta"] = {["inventory"] = {}, ["fields"] = {}}, ["name"] = "wool:yellow"}, {["param1"] = 95, ["x"] = 7, ["y"] = 7, ["z"] = 15, ["meta"] = {["inventory"] = {}, ["fields"] = {}}, ["name"] = "wool:yellow"}, {["param1"] = 98, ["x"] = 7, ["y"] = 8, ["z"] = 0, ["meta"] = {["inventory"] = {}, ["fields"] = {}}, ["name"] = "wool:red"}, {["param1"] = 98, ["x"] = 7, ["y"] = 8, ["z"] = 1, ["meta"] = {["inventory"] = {}, ["fields"] = {}}, ["name"] = "wool:red"}, {["param1"] = 82, ["x"] = 7, ["y"] = 8, ["z"] = 2, ["meta"] = {["inventory"] = {}, ["fields"] = {}}, ["name"] = "default:steelblock"}, {["param1"] = 82, ["x"] = 7, ["y"] = 8, ["z"] = 3, ["meta"] = {["inventory"] = {}, ["fields"] = {}}, ["name"] = "default:steelblock"}, {["param1"] = 82, ["x"] = 7, ["y"] = 8, ["z"] = 4, ["meta"] = {["inventory"] = {}, ["fields"] = {}}, ["name"] = "default:steelblock"}, {["param1"] = 82, ["x"] = 7, ["y"] = 8, ["z"] = 5, ["meta"] = {["inventory"] = {}, ["fields"] = {}}, ["name"] = "default:steelblock"}, {["param1"] = 82, ["x"] = 7, ["y"] = 8, ["z"] = 6, ["meta"] = {["inventory"] = {}, ["fields"] = {}}, ["name"] = "default:steelblock"}, {["param1"] = 82, ["x"] = 7, ["y"] = 8, ["z"] = 7, ["meta"] = {["inventory"] = {}, ["fields"] = {}}, ["name"] = "default:steelblock"}, {["param1"] = 82, ["x"] = 7, ["y"] = 8, ["z"] = 8, ["meta"] = {["inventory"] = {}, ["fields"] = {}}, ["name"] = "default:steelblock"}, {["param1"] = 82, ["x"] = 7, ["y"] = 8, ["z"] = 9, ["meta"] = {["inventory"] = {}, ["fields"] = {}}, ["name"] = "default:steelblock"}, {["param1"] = 82, ["x"] = 7, ["y"] = 8, ["z"] = 10, ["meta"] = {["inventory"] = {}, ["fields"] = {}}, ["name"] = "default:steelblock"}, {["param1"] = 82, ["x"] = 7, ["y"] = 8, ["z"] = 11, ["meta"] = {["inventory"] = {}, ["fields"] = {}}, ["name"] = "default:steelblock"}, {["param1"] = 82, ["x"] = 7, ["y"] = 8, ["z"] = 12, ["meta"] = {["inventory"] = {}, ["fields"] = {}}, ["name"] = "default:steelblock"}, {["param1"] = 82, ["x"] = 7, ["y"] = 8, ["z"] = 13, ["meta"] = {["inventory"] = {}, ["fields"] = {}}, ["name"] = "default:steelblock"}, {["param1"] = 95, ["x"] = 7, ["y"] = 8, ["z"] = 14, ["meta"] = {["inventory"] = {}, ["fields"] = {}}, ["name"] = "wool:yellow"}, {["param1"] = 95, ["x"] = 7, ["y"] = 8, ["z"] = 15, ["meta"] = {["inventory"] = {}, ["fields"] = {}}, ["name"] = "wool:yellow"}, {["param1"] = 87, ["x"] = 7, ["y"] = 9, ["z"] = 1, ["meta"] = {["inventory"] = {}, ["fields"] = {}}, ["name"] = "wool:grey"}, {["param1"] = 82, ["x"] = 7, ["y"] = 9, ["z"] = 2, ["meta"] = {["inventory"] = {}, ["fields"] = {}}, ["name"] = "default:steelblock"}, {["param1"] = 82, ["x"] = 7, ["y"] = 9, ["z"] = 3, ["meta"] = {["inventory"] = {}, ["fields"] = {}}, ["name"] = "default:steelblock"}, {["param1"] = 82, ["x"] = 7, ["y"] = 9, ["z"] = 4, ["meta"] = {["inventory"] = {}, ["fields"] = {}}, ["name"] = "default:steelblock"}, {["param1"] = 82, ["x"] = 7, ["y"] = 9, ["z"] = 5, ["meta"] = {["inventory"] = {}, ["fields"] = {}}, ["name"] = "default:steelblock"}, {["param1"] = 82, ["x"] = 7, ["y"] = 9, ["z"] = 6, ["meta"] = {["inventory"] = {}, ["fields"] = {}}, ["name"] = "default:steelblock"}, {["param1"] = 82, ["x"] = 7, ["y"] = 9, ["z"] = 7, ["meta"] = {["inventory"] = {}, ["fields"] = {}}, ["name"] = "default:steelblock"}, {["param1"] = 82, ["x"] = 7, ["y"] = 9, ["z"] = 8, ["meta"] = {["inventory"] = {}, ["fields"] = {}}, ["name"] = "default:steelblock"}, {["param1"] = 82, ["x"] = 7, ["y"] = 9, ["z"] = 9, ["meta"] = {["inventory"] = {}, ["fields"] = {}}, ["name"] = "default:steelblock"}, {["param1"] = 82, ["x"] = 7, ["y"] = 9, ["z"] = 10, ["meta"] = {["inventory"] = {}, ["fields"] = {}}, ["name"] = "default:steelblock"}, {["param1"] = 82, ["x"] = 7, ["y"] = 9, ["z"] = 11, ["meta"] = {["inventory"] = {}, ["fields"] = {}}, ["name"] = "default:steelblock"}, {["param1"] = 82, ["x"] = 7, ["y"] = 9, ["z"] = 12, ["meta"] = {["inventory"] = {}, ["fields"] = {}}, ["name"] = "default:steelblock"}, {["param1"] = 82, ["x"] = 7, ["y"] = 9, ["z"] = 13, ["meta"] = {["inventory"] = {}, ["fields"] = {}}, ["name"] = "default:steelblock"}, {["param1"] = 87, ["x"] = 7, ["y"] = 9, ["z"] = 14, ["meta"] = {["inventory"] = {}, ["fields"] = {}}, ["name"] = "wool:grey"}, {["param1"] = 82, ["x"] = 7, ["y"] = 10, ["z"] = 2, ["meta"] = {["inventory"] = {}, ["fields"] = {}}, ["name"] = "default:steelblock"}, {["param1"] = 82, ["x"] = 7, ["y"] = 10, ["z"] = 3, ["meta"] = {["inventory"] = {}, ["fields"] = {}}, ["name"] = "default:steelblock"}, {["param1"] = 82, ["x"] = 7, ["y"] = 10, ["z"] = 4, ["meta"] = {["inventory"] = {}, ["fields"] = {}}, ["name"] = "default:steelblock"}, {["param1"] = 82, ["x"] = 7, ["y"] = 10, ["z"] = 5, ["meta"] = {["inventory"] = {}, ["fields"] = {}}, ["name"] = "default:steelblock"}, {["param1"] = 82, ["x"] = 7, ["y"] = 10, ["z"] = 6, ["meta"] = {["inventory"] = {}, ["fields"] = {}}, ["name"] = "default:steelblock"}, {["param1"] = 82, ["x"] = 7, ["y"] = 10, ["z"] = 7, ["meta"] = {["inventory"] = {}, ["fields"] = {}}, ["name"] = "default:steelblock"}, {["param1"] = 82, ["x"] = 7, ["y"] = 10, ["z"] = 8, ["meta"] = {["inventory"] = {}, ["fields"] = {}}, ["name"] = "default:steelblock"}, {["param1"] = 82, ["x"] = 7, ["y"] = 10, ["z"] = 9, ["meta"] = {["inventory"] = {}, ["fields"] = {}}, ["name"] = "default:steelblock"}, {["param1"] = 82, ["x"] = 7, ["y"] = 10, ["z"] = 10, ["meta"] = {["inventory"] = {}, ["fields"] = {}}, ["name"] = "default:steelblock"}, {["param1"] = 82, ["x"] = 7, ["y"] = 10, ["z"] = 11, ["meta"] = {["inventory"] = {}, ["fields"] = {}}, ["name"] = "default:steelblock"}, {["param1"] = 82, ["x"] = 7, ["y"] = 10, ["z"] = 12, ["meta"] = {["inventory"] = {}, ["fields"] = {}}, ["name"] = "default:steelblock"}, {["param1"] = 82, ["x"] = 7, ["y"] = 10, ["z"] = 13, ["meta"] = {["inventory"] = {}, ["fields"] = {}}, ["name"] = "default:steelblock"}, {["param1"] = 82, ["x"] = 7, ["y"] = 11, ["z"] = 2, ["meta"] = {["inventory"] = {}, ["fields"] = {}}, ["name"] = "default:steelblock"}, {["param1"] = 82, ["x"] = 7, ["y"] = 11, ["z"] = 3, ["meta"] = {["inventory"] = {}, ["fields"] = {}}, ["name"] = "default:steelblock"}, {["param1"] = 82, ["x"] = 7, ["y"] = 11, ["z"] = 4, ["meta"] = {["inventory"] = {}, ["fields"] = {}}, ["name"] = "default:steelblock"}, {["param1"] = 82, ["x"] = 7, ["y"] = 11, ["z"] = 5, ["meta"] = {["inventory"] = {}, ["fields"] = {}}, ["name"] = "default:steelblock"}, {["param1"] = 82, ["x"] = 7, ["y"] = 11, ["z"] = 6, ["meta"] = {["inventory"] = {}, ["fields"] = {}}, ["name"] = "default:steelblock"}, {["param1"] = 82, ["x"] = 7, ["y"] = 11, ["z"] = 7, ["meta"] = {["inventory"] = {}, ["fields"] = {}}, ["name"] = "default:steelblock"}, {["param1"] = 82, ["x"] = 7, ["y"] = 11, ["z"] = 8, ["meta"] = {["inventory"] = {}, ["fields"] = {}}, ["name"] = "default:steelblock"}, {["param1"] = 82, ["x"] = 7, ["y"] = 11, ["z"] = 9, ["meta"] = {["inventory"] = {}, ["fields"] = {}}, ["name"] = "default:steelblock"}, {["param1"] = 82, ["x"] = 7, ["y"] = 11, ["z"] = 10, ["meta"] = {["inventory"] = {}, ["fields"] = {}}, ["name"] = "default:steelblock"}, {["param1"] = 82, ["x"] = 7, ["y"] = 11, ["z"] = 11, ["meta"] = {["inventory"] = {}, ["fields"] = {}}, ["name"] = "default:steelblock"}, {["param1"] = 82, ["x"] = 7, ["y"] = 11, ["z"] = 12, ["meta"] = {["inventory"] = {}, ["fields"] = {}}, ["name"] = "default:steelblock"}, {["param1"] = 82, ["x"] = 7, ["y"] = 11, ["z"] = 13, ["meta"] = {["inventory"] = {}, ["fields"] = {}}, ["name"] = "default:steelblock"}, {["x"] = 7, ["y"] = 12, ["z"] = 2, ["meta"] = {["inventory"] = {}, ["fields"] = {}}, ["name"] = "default:steelblock"}, {["x"] = 7, ["y"] = 12, ["z"] = 3, ["meta"] = {["inventory"] = {}, ["fields"] = {}}, ["name"] = "default:steelblock"}, {["x"] = 7, ["y"] = 12, ["z"] = 4, ["meta"] = {["inventory"] = {}, ["fields"] = {}}, ["name"] = "default:steelblock"}, {["x"] = 7, ["y"] = 12, ["z"] = 5, ["meta"] = {["inventory"] = {}, ["fields"] = {}}, ["name"] = "default:steelblock"}, {["x"] = 7, ["y"] = 12, ["z"] = 6, ["meta"] = {["inventory"] = {}, ["fields"] = {}}, ["name"] = "default:steelblock"}, {["x"] = 7, ["y"] = 12, ["z"] = 7, ["meta"] = {["inventory"] = {}, ["fields"] = {}}, ["name"] = "default:steelblock"}, {["x"] = 7, ["y"] = 12, ["z"] = 8, ["meta"] = {["inventory"] = {}, ["fields"] = {}}, ["name"] = "default:steelblock"}, {["x"] = 7, ["y"] = 12, ["z"] = 9, ["meta"] = {["inventory"] = {}, ["fields"] = {}}, ["name"] = "default:steelblock"}, {["x"] = 7, ["y"] = 12, ["z"] = 10, ["meta"] = {["inventory"] = {}, ["fields"] = {}}, ["name"] = "default:steelblock"}, {["x"] = 7, ["y"] = 12, ["z"] = 11, ["meta"] = {["inventory"] = {}, ["fields"] = {}}, ["name"] = "default:steelblock"}, {["x"] = 7, ["y"] = 12, ["z"] = 12, ["meta"] = {["inventory"] = {}, ["fields"] = {}}, ["name"] = "default:steelblock"}, {["x"] = 7, ["y"] = 12, ["z"] = 13, ["meta"] = {["inventory"] = {}, ["fields"] = {}}, ["name"] = "default:steelblock"}, {["x"] = 8, ["y"] = 3, ["z"] = 2, ["meta"] = {["inventory"] = {}, ["fields"] = {}}, ["name"] = "default:steelblock"}, {["x"] = 8, ["y"] = 3, ["z"] = 3, ["meta"] = {["inventory"] = {}, ["fields"] = {}}, ["name"] = "default:steelblock"}, {["x"] = 8, ["y"] = 3, ["z"] = 4, ["meta"] = {["inventory"] = {}, ["fields"] = {}}, ["name"] = "default:steelblock"}, {["x"] = 8, ["y"] = 3, ["z"] = 5, ["meta"] = {["inventory"] = {}, ["fields"] = {}}, ["name"] = "default:steelblock"}, {["x"] = 8, ["y"] = 3, ["z"] = 6, ["meta"] = {["inventory"] = {}, ["fields"] = {}}, ["name"] = "default:steelblock"}, {["x"] = 8, ["y"] = 3, ["z"] = 7, ["meta"] = {["inventory"] = {}, ["fields"] = {}}, ["name"] = "default:steelblock"}, {["x"] = 8, ["y"] = 3, ["z"] = 8, ["meta"] = {["inventory"] = {}, ["fields"] = {}}, ["name"] = "default:steelblock"}, {["x"] = 8, ["y"] = 3, ["z"] = 9, ["meta"] = {["inventory"] = {}, ["fields"] = {}}, ["name"] = "default:steelblock"}, {["x"] = 8, ["y"] = 3, ["z"] = 10, ["meta"] = {["inventory"] = {}, ["fields"] = {}}, ["name"] = "default:steelblock"}, {["x"] = 8, ["y"] = 3, ["z"] = 11, ["meta"] = {["inventory"] = {}, ["fields"] = {}}, ["name"] = "default:steelblock"}, {["x"] = 8, ["y"] = 3, ["z"] = 12, ["meta"] = {["inventory"] = {}, ["fields"] = {}}, ["name"] = "default:steelblock"}, {["x"] = 8, ["y"] = 3, ["z"] = 13, ["meta"] = {["inventory"] = {}, ["fields"] = {}}, ["name"] = "default:steelblock"}, {["param1"] = 82, ["x"] = 8, ["y"] = 4, ["z"] = 2, ["meta"] = {["inventory"] = {}, ["fields"] = {}}, ["name"] = "default:steelblock"}, {["param1"] = 82, ["x"] = 8, ["y"] = 4, ["z"] = 3, ["meta"] = {["inventory"] = {}, ["fields"] = {}}, ["name"] = "default:steelblock"}, {["param1"] = 82, ["x"] = 8, ["y"] = 4, ["z"] = 4, ["meta"] = {["inventory"] = {}, ["fields"] = {}}, ["name"] = "default:steelblock"}, {["param1"] = 82, ["x"] = 8, ["y"] = 4, ["z"] = 5, ["meta"] = {["inventory"] = {}, ["fields"] = {}}, ["name"] = "default:steelblock"}, {["param1"] = 82, ["x"] = 8, ["y"] = 4, ["z"] = 6, ["meta"] = {["inventory"] = {}, ["fields"] = {}}, ["name"] = "default:steelblock"}, {["param1"] = 82, ["x"] = 8, ["y"] = 4, ["z"] = 7, ["meta"] = {["inventory"] = {}, ["fields"] = {}}, ["name"] = "default:steelblock"}, {["param1"] = 82, ["x"] = 8, ["y"] = 4, ["z"] = 8, ["meta"] = {["inventory"] = {}, ["fields"] = {}}, ["name"] = "default:steelblock"}, {["param1"] = 82, ["x"] = 8, ["y"] = 4, ["z"] = 9, ["meta"] = {["inventory"] = {}, ["fields"] = {}}, ["name"] = "default:steelblock"}, {["param1"] = 82, ["x"] = 8, ["y"] = 4, ["z"] = 10, ["meta"] = {["inventory"] = {}, ["fields"] = {}}, ["name"] = "default:steelblock"}, {["param1"] = 82, ["x"] = 8, ["y"] = 4, ["z"] = 11, ["meta"] = {["inventory"] = {}, ["fields"] = {}}, ["name"] = "default:steelblock"}, {["param1"] = 82, ["x"] = 8, ["y"] = 4, ["z"] = 12, ["meta"] = {["inventory"] = {}, ["fields"] = {}}, ["name"] = "default:steelblock"}, {["param1"] = 82, ["x"] = 8, ["y"] = 4, ["z"] = 13, ["meta"] = {["inventory"] = {}, ["fields"] = {}}, ["name"] = "default:steelblock"}, {["param1"] = 82, ["x"] = 8, ["y"] = 5, ["z"] = 2, ["meta"] = {["inventory"] = {}, ["fields"] = {}}, ["name"] = "default:steelblock"}, {["param1"] = 82, ["x"] = 8, ["y"] = 5, ["z"] = 3, ["meta"] = {["inventory"] = {}, ["fields"] = {}}, ["name"] = "default:steelblock"}, {["param1"] = 82, ["x"] = 8, ["y"] = 5, ["z"] = 4, ["meta"] = {["inventory"] = {}, ["fields"] = {}}, ["name"] = "default:steelblock"}, {["param1"] = 82, ["x"] = 8, ["y"] = 5, ["z"] = 5, ["meta"] = {["inventory"] = {}, ["fields"] = {}}, ["name"] = "default:steelblock"}, {["param1"] = 82, ["x"] = 8, ["y"] = 5, ["z"] = 6, ["meta"] = {["inventory"] = {}, ["fields"] = {}}, ["name"] = "default:steelblock"}, {["param1"] = 82, ["x"] = 8, ["y"] = 5, ["z"] = 7, ["meta"] = {["inventory"] = {}, ["fields"] = {}}, ["name"] = "default:steelblock"}, {["param1"] = 82, ["x"] = 8, ["y"] = 5, ["z"] = 8, ["meta"] = {["inventory"] = {}, ["fields"] = {}}, ["name"] = "default:steelblock"}, {["param1"] = 82, ["x"] = 8, ["y"] = 5, ["z"] = 9, ["meta"] = {["inventory"] = {}, ["fields"] = {}}, ["name"] = "default:steelblock"}, {["param1"] = 82, ["x"] = 8, ["y"] = 5, ["z"] = 10, ["meta"] = {["inventory"] = {}, ["fields"] = {}}, ["name"] = "default:steelblock"}, {["param1"] = 82, ["x"] = 8, ["y"] = 5, ["z"] = 11, ["meta"] = {["inventory"] = {}, ["fields"] = {}}, ["name"] = "default:steelblock"}, {["param1"] = 82, ["x"] = 8, ["y"] = 5, ["z"] = 12, ["meta"] = {["inventory"] = {}, ["fields"] = {}}, ["name"] = "default:steelblock"}, {["param1"] = 82, ["x"] = 8, ["y"] = 5, ["z"] = 13, ["meta"] = {["inventory"] = {}, ["fields"] = {}}, ["name"] = "default:steelblock"}, {["param1"] = 87, ["x"] = 8, ["y"] = 6, ["z"] = 1, ["meta"] = {["inventory"] = {}, ["fields"] = {}}, ["name"] = "wool:grey"}, {["param1"] = 82, ["x"] = 8, ["y"] = 6, ["z"] = 2, ["meta"] = {["inventory"] = {}, ["fields"] = {}}, ["name"] = "default:steelblock"}, {["param1"] = 82, ["x"] = 8, ["y"] = 6, ["z"] = 3, ["meta"] = {["inventory"] = {}, ["fields"] = {}}, ["name"] = "default:steelblock"}, {["param1"] = 82, ["x"] = 8, ["y"] = 6, ["z"] = 4, ["meta"] = {["inventory"] = {}, ["fields"] = {}}, ["name"] = "default:steelblock"}, {["param1"] = 82, ["x"] = 8, ["y"] = 6, ["z"] = 5, ["meta"] = {["inventory"] = {}, ["fields"] = {}}, ["name"] = "default:steelblock"}, {["param1"] = 82, ["x"] = 8, ["y"] = 6, ["z"] = 6, ["meta"] = {["inventory"] = {}, ["fields"] = {}}, ["name"] = "default:steelblock"}, {["param1"] = 82, ["x"] = 8, ["y"] = 6, ["z"] = 7, ["meta"] = {["inventory"] = {}, ["fields"] = {}}, ["name"] = "default:steelblock"}, {["param1"] = 82, ["x"] = 8, ["y"] = 6, ["z"] = 8, ["meta"] = {["inventory"] = {}, ["fields"] = {}}, ["name"] = "default:steelblock"}, {["param1"] = 82, ["x"] = 8, ["y"] = 6, ["z"] = 9, ["meta"] = {["inventory"] = {}, ["fields"] = {}}, ["name"] = "default:steelblock"}, {["param1"] = 82, ["x"] = 8, ["y"] = 6, ["z"] = 10, ["meta"] = {["inventory"] = {}, ["fields"] = {}}, ["name"] = "default:steelblock"}, {["param1"] = 82, ["x"] = 8, ["y"] = 6, ["z"] = 11, ["meta"] = {["inventory"] = {}, ["fields"] = {}}, ["name"] = "default:steelblock"}, {["param1"] = 82, ["x"] = 8, ["y"] = 6, ["z"] = 12, ["meta"] = {["inventory"] = {}, ["fields"] = {}}, ["name"] = "default:steelblock"}, {["param1"] = 82, ["x"] = 8, ["y"] = 6, ["z"] = 13, ["meta"] = {["inventory"] = {}, ["fields"] = {}}, ["name"] = "default:steelblock"}, {["param1"] = 87, ["x"] = 8, ["y"] = 6, ["z"] = 14, ["meta"] = {["inventory"] = {}, ["fields"] = {}}, ["name"] = "wool:grey"}, {["param1"] = 98, ["x"] = 8, ["y"] = 7, ["z"] = 0, ["meta"] = {["inventory"] = {}, ["fields"] = {}}, ["name"] = "wool:red"}, {["param1"] = 98, ["x"] = 8, ["y"] = 7, ["z"] = 1, ["meta"] = {["inventory"] = {}, ["fields"] = {}}, ["name"] = "wool:red"}, {["param1"] = 82, ["x"] = 8, ["y"] = 7, ["z"] = 2, ["meta"] = {["inventory"] = {}, ["fields"] = {}}, ["name"] = "default:steelblock"}, {["param1"] = 82, ["x"] = 8, ["y"] = 7, ["z"] = 3, ["meta"] = {["inventory"] = {}, ["fields"] = {}}, ["name"] = "default:steelblock"}, {["param1"] = 82, ["x"] = 8, ["y"] = 7, ["z"] = 4, ["meta"] = {["inventory"] = {}, ["fields"] = {}}, ["name"] = "default:steelblock"}, {["param1"] = 82, ["x"] = 8, ["y"] = 7, ["z"] = 5, ["meta"] = {["inventory"] = {}, ["fields"] = {}}, ["name"] = "default:steelblock"}, {["param1"] = 82, ["x"] = 8, ["y"] = 7, ["z"] = 6, ["meta"] = {["inventory"] = {}, ["fields"] = {}}, ["name"] = "default:steelblock"}, {["param1"] = 82, ["x"] = 8, ["y"] = 7, ["z"] = 7, ["meta"] = {["inventory"] = {}, ["fields"] = {}}, ["name"] = "default:steelblock"}, {["param1"] = 82, ["x"] = 8, ["y"] = 7, ["z"] = 8, ["meta"] = {["inventory"] = {}, ["fields"] = {}}, ["name"] = "default:steelblock"}, {["param1"] = 82, ["x"] = 8, ["y"] = 7, ["z"] = 9, ["meta"] = {["inventory"] = {}, ["fields"] = {}}, ["name"] = "default:steelblock"}, {["param1"] = 82, ["x"] = 8, ["y"] = 7, ["z"] = 10, ["meta"] = {["inventory"] = {}, ["fields"] = {}}, ["name"] = "default:steelblock"}, {["param1"] = 82, ["x"] = 8, ["y"] = 7, ["z"] = 11, ["meta"] = {["inventory"] = {}, ["fields"] = {}}, ["name"] = "default:steelblock"}, {["param1"] = 82, ["x"] = 8, ["y"] = 7, ["z"] = 12, ["meta"] = {["inventory"] = {}, ["fields"] = {}}, ["name"] = "default:steelblock"}, {["param1"] = 82, ["x"] = 8, ["y"] = 7, ["z"] = 13, ["meta"] = {["inventory"] = {}, ["fields"] = {}}, ["name"] = "default:steelblock"}, {["param1"] = 95, ["x"] = 8, ["y"] = 7, ["z"] = 14, ["meta"] = {["inventory"] = {}, ["fields"] = {}}, ["name"] = "wool:yellow"}, {["param1"] = 95, ["x"] = 8, ["y"] = 7, ["z"] = 15, ["meta"] = {["inventory"] = {}, ["fields"] = {}}, ["name"] = "wool:yellow"}, {["param1"] = 98, ["x"] = 8, ["y"] = 8, ["z"] = 0, ["meta"] = {["inventory"] = {}, ["fields"] = {}}, ["name"] = "wool:red"}, {["param1"] = 98, ["x"] = 8, ["y"] = 8, ["z"] = 1, ["meta"] = {["inventory"] = {}, ["fields"] = {}}, ["name"] = "wool:red"}, {["param1"] = 82, ["x"] = 8, ["y"] = 8, ["z"] = 2, ["meta"] = {["inventory"] = {}, ["fields"] = {}}, ["name"] = "default:steelblock"}, {["param1"] = 82, ["x"] = 8, ["y"] = 8, ["z"] = 3, ["meta"] = {["inventory"] = {}, ["fields"] = {}}, ["name"] = "default:steelblock"}, {["param1"] = 82, ["x"] = 8, ["y"] = 8, ["z"] = 4, ["meta"] = {["inventory"] = {}, ["fields"] = {}}, ["name"] = "default:steelblock"}, {["param1"] = 82, ["x"] = 8, ["y"] = 8, ["z"] = 5, ["meta"] = {["inventory"] = {}, ["fields"] = {}}, ["name"] = "default:steelblock"}, {["param1"] = 82, ["x"] = 8, ["y"] = 8, ["z"] = 6, ["meta"] = {["inventory"] = {}, ["fields"] = {}}, ["name"] = "default:steelblock"}, {["param1"] = 82, ["x"] = 8, ["y"] = 8, ["z"] = 7, ["meta"] = {["inventory"] = {}, ["fields"] = {}}, ["name"] = "default:steelblock"}, {["param1"] = 82, ["x"] = 8, ["y"] = 8, ["z"] = 8, ["meta"] = {["inventory"] = {}, ["fields"] = {}}, ["name"] = "default:steelblock"}, {["param1"] = 82, ["x"] = 8, ["y"] = 8, ["z"] = 9, ["meta"] = {["inventory"] = {}, ["fields"] = {}}, ["name"] = "default:steelblock"}, {["param1"] = 82, ["x"] = 8, ["y"] = 8, ["z"] = 10, ["meta"] = {["inventory"] = {}, ["fields"] = {}}, ["name"] = "default:steelblock"}, {["param1"] = 82, ["x"] = 8, ["y"] = 8, ["z"] = 11, ["meta"] = {["inventory"] = {}, ["fields"] = {}}, ["name"] = "default:steelblock"}, {["param1"] = 82, ["x"] = 8, ["y"] = 8, ["z"] = 12, ["meta"] = {["inventory"] = {}, ["fields"] = {}}, ["name"] = "default:steelblock"}, {["param1"] = 82, ["x"] = 8, ["y"] = 8, ["z"] = 13, ["meta"] = {["inventory"] = {}, ["fields"] = {}}, ["name"] = "default:steelblock"}, {["param1"] = 95, ["x"] = 8, ["y"] = 8, ["z"] = 14, ["meta"] = {["inventory"] = {}, ["fields"] = {}}, ["name"] = "wool:yellow"}, {["param1"] = 95, ["x"] = 8, ["y"] = 8, ["z"] = 15, ["meta"] = {["inventory"] = {}, ["fields"] = {}}, ["name"] = "wool:yellow"}, {["param1"] = 87, ["x"] = 8, ["y"] = 9, ["z"] = 1, ["meta"] = {["inventory"] = {}, ["fields"] = {}}, ["name"] = "wool:grey"}, {["param1"] = 82, ["x"] = 8, ["y"] = 9, ["z"] = 2, ["meta"] = {["inventory"] = {}, ["fields"] = {}}, ["name"] = "default:steelblock"}, {["param1"] = 82, ["x"] = 8, ["y"] = 9, ["z"] = 3, ["meta"] = {["inventory"] = {}, ["fields"] = {}}, ["name"] = "default:steelblock"}, {["param1"] = 82, ["x"] = 8, ["y"] = 9, ["z"] = 4, ["meta"] = {["inventory"] = {}, ["fields"] = {}}, ["name"] = "default:steelblock"}, {["param1"] = 82, ["x"] = 8, ["y"] = 9, ["z"] = 5, ["meta"] = {["inventory"] = {}, ["fields"] = {}}, ["name"] = "default:steelblock"}, {["param1"] = 82, ["x"] = 8, ["y"] = 9, ["z"] = 6, ["meta"] = {["inventory"] = {}, ["fields"] = {}}, ["name"] = "default:steelblock"}, {["param1"] = 82, ["x"] = 8, ["y"] = 9, ["z"] = 7, ["meta"] = {["inventory"] = {}, ["fields"] = {}}, ["name"] = "default:steelblock"}, {["param1"] = 82, ["x"] = 8, ["y"] = 9, ["z"] = 8, ["meta"] = {["inventory"] = {}, ["fields"] = {}}, ["name"] = "default:steelblock"}, {["param1"] = 82, ["x"] = 8, ["y"] = 9, ["z"] = 9, ["meta"] = {["inventory"] = {}, ["fields"] = {}}, ["name"] = "default:steelblock"}, {["param1"] = 82, ["x"] = 8, ["y"] = 9, ["z"] = 10, ["meta"] = {["inventory"] = {}, ["fields"] = {}}, ["name"] = "default:steelblock"}, {["param1"] = 82, ["x"] = 8, ["y"] = 9, ["z"] = 11, ["meta"] = {["inventory"] = {}, ["fields"] = {}}, ["name"] = "default:steelblock"}, {["param1"] = 82, ["x"] = 8, ["y"] = 9, ["z"] = 12, ["meta"] = {["inventory"] = {}, ["fields"] = {}}, ["name"] = "default:steelblock"}, {["param1"] = 82, ["x"] = 8, ["y"] = 9, ["z"] = 13, ["meta"] = {["inventory"] = {}, ["fields"] = {}}, ["name"] = "default:steelblock"}, {["param1"] = 87, ["x"] = 8, ["y"] = 9, ["z"] = 14, ["meta"] = {["inventory"] = {}, ["fields"] = {}}, ["name"] = "wool:grey"}, {["param1"] = 82, ["x"] = 8, ["y"] = 10, ["z"] = 2, ["meta"] = {["inventory"] = {}, ["fields"] = {}}, ["name"] = "default:steelblock"}, {["param1"] = 82, ["x"] = 8, ["y"] = 10, ["z"] = 3, ["meta"] = {["inventory"] = {}, ["fields"] = {}}, ["name"] = "default:steelblock"}, {["param1"] = 82, ["x"] = 8, ["y"] = 10, ["z"] = 4, ["meta"] = {["inventory"] = {}, ["fields"] = {}}, ["name"] = "default:steelblock"}, {["param1"] = 82, ["x"] = 8, ["y"] = 10, ["z"] = 5, ["meta"] = {["inventory"] = {}, ["fields"] = {}}, ["name"] = "default:steelblock"}, {["param1"] = 82, ["x"] = 8, ["y"] = 10, ["z"] = 6, ["meta"] = {["inventory"] = {}, ["fields"] = {}}, ["name"] = "default:steelblock"}, {["param1"] = 82, ["x"] = 8, ["y"] = 10, ["z"] = 7, ["meta"] = {["inventory"] = {}, ["fields"] = {}}, ["name"] = "default:steelblock"}, {["param1"] = 82, ["x"] = 8, ["y"] = 10, ["z"] = 8, ["meta"] = {["inventory"] = {}, ["fields"] = {}}, ["name"] = "default:steelblock"}, {["param1"] = 82, ["x"] = 8, ["y"] = 10, ["z"] = 9, ["meta"] = {["inventory"] = {}, ["fields"] = {}}, ["name"] = "default:steelblock"}, {["param1"] = 82, ["x"] = 8, ["y"] = 10, ["z"] = 10, ["meta"] = {["inventory"] = {}, ["fields"] = {}}, ["name"] = "default:steelblock"}, {["param1"] = 82, ["x"] = 8, ["y"] = 10, ["z"] = 11, ["meta"] = {["inventory"] = {}, ["fields"] = {}}, ["name"] = "default:steelblock"}, {["param1"] = 82, ["x"] = 8, ["y"] = 10, ["z"] = 12, ["meta"] = {["inventory"] = {}, ["fields"] = {}}, ["name"] = "default:steelblock"}, {["param1"] = 82, ["x"] = 8, ["y"] = 10, ["z"] = 13, ["meta"] = {["inventory"] = {}, ["fields"] = {}}, ["name"] = "default:steelblock"}, {["param1"] = 82, ["x"] = 8, ["y"] = 11, ["z"] = 2, ["meta"] = {["inventory"] = {}, ["fields"] = {}}, ["name"] = "default:steelblock"}, {["param1"] = 82, ["x"] = 8, ["y"] = 11, ["z"] = 3, ["meta"] = {["inventory"] = {}, ["fields"] = {}}, ["name"] = "default:steelblock"}, {["param1"] = 82, ["x"] = 8, ["y"] = 11, ["z"] = 4, ["meta"] = {["inventory"] = {}, ["fields"] = {}}, ["name"] = "default:steelblock"}, {["param1"] = 82, ["x"] = 8, ["y"] = 11, ["z"] = 5, ["meta"] = {["inventory"] = {}, ["fields"] = {}}, ["name"] = "default:steelblock"}, {["param1"] = 82, ["x"] = 8, ["y"] = 11, ["z"] = 6, ["meta"] = {["inventory"] = {}, ["fields"] = {}}, ["name"] = "default:steelblock"}, {["param1"] = 82, ["x"] = 8, ["y"] = 11, ["z"] = 7, ["meta"] = {["inventory"] = {}, ["fields"] = {}},