5:return {{["x"] = 0, ["meta"] = {["fields"] = {}, ["inventory"] = {}}, ["y"] = 0, ["z"] = 0, ["name"] = "wool:grey"}, {["x"] = 0, ["meta"] = {["fields"] = {}, ["inventory"] = {}}, ["y"] = 0, ["z"] = 1, ["name"] = "wool:grey"}, {["x"] = 0, ["meta"] = {["fields"] = {}, ["inventory"] = {}}, ["y"] = 0, ["z"] = 14, ["name"] = "wool:grey"}, {["x"] = 0, ["meta"] = {["fields"] = {}, ["inventory"] = {}}, ["y"] = 0, ["z"] = 15, ["name"] = "wool:grey"}, {["x"] = 0, ["meta"] = {["fields"] = {}, ["inventory"] = {}}, ["y"] = 1, ["z"] = 0, ["name"] = "wool:grey"}, {["x"] = 0, ["meta"] = {["fields"] = {}, ["inventory"] = {}}, ["y"] = 1, ["z"] = 1, ["name"] = "wool:grey"}, {["x"] = 0, ["meta"] = {["fields"] = {}, ["inventory"] = {}}, ["y"] = 1, ["z"] = 14, ["name"] = "wool:grey"}, {["x"] = 0, ["meta"] = {["fields"] = {}, ["inventory"] = {}}, ["y"] = 1, ["z"] = 15, ["name"] = "wool:grey"}, {["x"] = 0, ["meta"] = {["fields"] = {}, ["inventory"] = {}}, ["y"] = 2, ["z"] = 0, ["name"] = "wool:grey"}, {["x"] = 0, ["meta"] = {["fields"] = {}, ["inventory"] = {}}, ["y"] = 2, ["z"] = 1, ["name"] = "wool:grey"}, {["x"] = 0, ["meta"] = {["fields"] = {}, ["inventory"] = {}}, ["y"] = 2, ["z"] = 14, ["name"] = "wool:grey"}, {["x"] = 0, ["meta"] = {["fields"] = {}, ["inventory"] = {}}, ["y"] = 2, ["z"] = 15, ["name"] = "wool:grey"}, {["x"] = 0, ["meta"] = {["fields"] = {}, ["inventory"] = {}}, ["y"] = 3, ["z"] = 0, ["name"] = "wool:grey"}, {["x"] = 0, ["meta"] = {["fields"] = {}, ["inventory"] = {}}, ["y"] = 3, ["z"] = 1, ["name"] = "wool:grey"}, {["x"] = 0, ["meta"] = {["fields"] = {}, ["inventory"] = {}}, ["y"] = 3, ["z"] = 14, ["name"] = "wool:grey"}, {["x"] = 0, ["meta"] = {["fields"] = {}, ["inventory"] = {}}, ["y"] = 3, ["z"] = 15, ["name"] = "wool:grey"}, {["x"] = 0, ["meta"] = {["fields"] = {}, ["inventory"] = {}}, ["y"] = 4, ["z"] = 0, ["name"] = "wool:grey"}, {["x"] = 0, ["meta"] = {["fields"] = {}, ["inventory"] = {}}, ["y"] = 4, ["z"] = 1, ["name"] = "wool:grey"}, {["x"] = 0, ["meta"] = {["fields"] = {}, ["inventory"] = {}}, ["y"] = 4, ["z"] = 14, ["name"] = "wool:grey"}, {["x"] = 0, ["meta"] = {["fields"] = {}, ["inventory"] = {}}, ["y"] = 4, ["z"] = 15, ["name"] = "wool:grey"}, {["x"] = 0, ["meta"] = {["fields"] = {}, ["inventory"] = {}}, ["y"] = 5, ["z"] = 0, ["name"] = "wool:grey"}, {["x"] = 0, ["meta"] = {["fields"] = {}, ["inventory"] = {}}, ["y"] = 5, ["z"] = 1, ["name"] = "wool:grey"}, {["x"] = 0, ["meta"] = {["fields"] = {}, ["inventory"] = {}}, ["y"] = 5, ["z"] = 14, ["name"] = "wool:grey"}, {["x"] = 0, ["meta"] = {["fields"] = {}, ["inventory"] = {}}, ["y"] = 5, ["z"] = 15, ["name"] = "wool:grey"}, {["x"] = 0, ["meta"] = {["fields"] = {}, ["inventory"] = {}}, ["y"] = 6, ["z"] = 0, ["name"] = "wool:grey"}, {["x"] = 0, ["meta"] = {["fields"] = {}, ["inventory"] = {}}, ["y"] = 6, ["z"] = 1, ["name"] = "wool:grey"}, {["x"] = 0, ["meta"] = {["fields"] = {}, ["inventory"] = {}}, ["y"] = 6, ["z"] = 14, ["name"] = "wool:grey"}, {["x"] = 0, ["meta"] = {["fields"] = {}, ["inventory"] = {}}, ["y"] = 6, ["z"] = 15, ["name"] = "wool:grey"}, {["x"] = 0, ["meta"] = {["fields"] = {}, ["inventory"] = {}}, ["y"] = 7, ["z"] = 0, ["name"] = "wool:grey"}, {["x"] = 0, ["meta"] = {["fields"] = {}, ["inventory"] = {}}, ["y"] = 7, ["z"] = 1, ["name"] = "wool:grey"}, {["x"] = 0, ["meta"] = {["fields"] = {}, ["inventory"] = {}}, ["y"] = 7, ["z"] = 14, ["name"] = "wool:grey"}, {["x"] = 0, ["meta"] = {["fields"] = {}, ["inventory"] = {}}, ["y"] = 7, ["z"] = 15, ["name"] = "wool:grey"}, {["x"] = 0, ["meta"] = {["fields"] = {}, ["inventory"] = {}}, ["y"] = 8, ["z"] = 0, ["name"] = "wool:grey"}, {["x"] = 0, ["meta"] = {["fields"] = {}, ["inventory"] = {}}, ["y"] = 8, ["z"] = 1, ["name"] = "wool:grey"}, {["x"] = 0, ["meta"] = {["fields"] = {}, ["inventory"] = {}}, ["y"] = 8, ["z"] = 14, ["name"] = "wool:grey"}, {["x"] = 0, ["meta"] = {["fields"] = {}, ["inventory"] = {}}, ["y"] = 8, ["z"] = 15, ["name"] = "wool:grey"}, {["x"] = 0, ["meta"] = {["fields"] = {}, ["inventory"] = {}}, ["y"] = 9, ["z"] = 0, ["name"] = "wool:grey"}, {["x"] = 0, ["meta"] = {["fields"] = {}, ["inventory"] = {}}, ["y"] = 9, ["z"] = 1, ["name"] = "wool:grey"}, {["x"] = 0, ["meta"] = {["fields"] = {}, ["inventory"] = {}}, ["y"] = 9, ["z"] = 14, ["name"] = "wool:grey"}, {["x"] = 0, ["meta"] = {["fields"] = {}, ["inventory"] = {}}, ["y"] = 9, ["z"] = 15, ["name"] = "wool:grey"}, {["x"] = 0, ["meta"] = {["fields"] = {}, ["inventory"] = {}}, ["y"] = 10, ["z"] = 0, ["name"] = "wool:grey"}, {["x"] = 0, ["meta"] = {["fields"] = {}, ["inventory"] = {}}, ["y"] = 10, ["z"] = 1, ["name"] = "wool:grey"}, {["x"] = 0, ["meta"] = {["fields"] = {}, ["inventory"] = {}}, ["y"] = 10, ["z"] = 14, ["name"] = "wool:grey"}, {["x"] = 0, ["meta"] = {["fields"] = {}, ["inventory"] = {}}, ["y"] = 10, ["z"] = 15, ["name"] = "wool:grey"}, {["x"] = 0, ["meta"] = {["fields"] = {}, ["inventory"] = {}}, ["y"] = 11, ["z"] = 0, ["name"] = "wool:grey"}, {["x"] = 0, ["meta"] = {["fields"] = {}, ["inventory"] = {}}, ["y"] = 11, ["z"] = 1, ["name"] = "wool:grey"}, {["x"] = 0, ["meta"] = {["fields"] = {}, ["inventory"] = {}}, ["y"] = 11, ["z"] = 14, ["name"] = "wool:grey"}, {["x"] = 0, ["meta"] = {["fields"] = {}, ["inventory"] = {}}, ["y"] = 11, ["z"] = 15, ["name"] = "wool:grey"}, {["x"] = 0, ["meta"] = {["fields"] = {}, ["inventory"] = {}}, ["y"] = 12, ["z"] = 0, ["name"] = "wool:grey"}, {["x"] = 0, ["meta"] = {["fields"] = {}, ["inventory"] = {}}, ["y"] = 12, ["z"] = 1, ["name"] = "wool:grey"}, {["x"] = 0, ["meta"] = {["fields"] = {}, ["inventory"] = {}}, ["y"] = 12, ["z"] = 14, ["name"] = "wool:grey"}, {["x"] = 0, ["meta"] = {["fields"] = {}, ["inventory"] = {}}, ["y"] = 12, ["z"] = 15, ["name"] = "wool:grey"}, {["x"] = 0, ["meta"] = {["fields"] = {}, ["inventory"] = {}}, ["y"] = 13, ["z"] = 0, ["name"] = "wool:grey"}, {["x"] = 0, ["meta"] = {["fields"] = {}, ["inventory"] = {}}, ["y"] = 13, ["z"] = 1, ["name"] = "wool:grey"}, {["x"] = 0, ["meta"] = {["fields"] = {}, ["inventory"] = {}}, ["y"] = 13, ["z"] = 14, ["name"] = "wool:grey"}, {["x"] = 0, ["meta"] = {["fields"] = {}, ["inventory"] = {}}, ["y"] = 13, ["z"] = 15, ["name"] = "wool:grey"}, {["x"] = 0, ["meta"] = {["fields"] = {}, ["inventory"] = {}}, ["y"] = 14, ["z"] = 0, ["name"] = "wool:grey"}, {["x"] = 0, ["meta"] = {["fields"] = {}, ["inventory"] = {}}, ["y"] = 14, ["z"] = 1, ["name"] = "wool:grey"}, {["x"] = 0, ["meta"] = {["fields"] = {}, ["inventory"] = {}}, ["y"] = 14, ["z"] = 14, ["name"] = "wool:grey"}, {["x"] = 0, ["meta"] = {["fields"] = {}, ["inventory"] = {}}, ["y"] = 14, ["z"] = 15, ["name"] = "wool:grey"}, {["x"] = 0, ["meta"] = {["fields"] = {}, ["inventory"] = {}}, ["y"] = 15, ["z"] = 0, ["name"] = "wool:grey"}, {["x"] = 0, ["meta"] = {["fields"] = {}, ["inventory"] = {}}, ["y"] = 15, ["z"] = 1, ["name"] = "wool:grey"}, {["x"] = 0, ["meta"] = {["fields"] = {}, ["inventory"] = {}}, ["y"] = 15, ["z"] = 14, ["name"] = "wool:grey"}, {["x"] = 0, ["meta"] = {["fields"] = {}, ["inventory"] = {}}, ["y"] = 15, ["z"] = 15, ["name"] = "wool:grey"}, {["x"] = 1, ["meta"] = {["fields"] = {}, ["inventory"] = {}}, ["y"] = 0, ["z"] = 0, ["name"] = "wool:grey"}, {["x"] = 1, ["meta"] = {["fields"] = {}, ["inventory"] = {}}, ["y"] = 0, ["z"] = 1, ["name"] = "wool:grey"}, {["x"] = 1, ["meta"] = {["fields"] = {}, ["inventory"] = {}}, ["y"] = 0, ["z"] = 14, ["name"] = "wool:grey"}, {["x"] = 1, ["meta"] = {["fields"] = {}, ["inventory"] = {}}, ["y"] = 0, ["z"] = 15, ["name"] = "wool:grey"}, {["x"] = 1, ["meta"] = {["fields"] = {}, ["inventory"] = {}}, ["y"] = 1, ["z"] = 0, ["name"] = "wool:grey"}, {["x"] = 1, ["meta"] = {["fields"] = {}, ["inventory"] = {}}, ["y"] = 1, ["z"] = 1, ["name"] = "wool:grey"}, {["x"] = 1, ["meta"] = {["fields"] = {}, ["inventory"] = {}}, ["y"] = 1, ["z"] = 14, ["name"] = "wool:grey"}, {["x"] = 1, ["meta"] = {["fields"] = {}, ["inventory"] = {}}, ["y"] = 1, ["z"] = 15, ["name"] = "wool:grey"}, {["x"] = 1, ["meta"] = {["fields"] = {}, ["inventory"] = {}}, ["y"] = 2, ["z"] = 0, ["name"] = "wool:grey"}, {["x"] = 1, ["meta"] = {["fields"] = {}, ["inventory"] = {}}, ["y"] = 2, ["z"] = 1, ["name"] = "wool:grey"}, {["x"] = 1, ["meta"] = {["fields"] = {}, ["inventory"] = {}}, ["y"] = 2, ["z"] = 14, ["name"] = "wool:grey"}, {["x"] = 1, ["meta"] = {["fields"] = {}, ["inventory"] = {}}, ["y"] = 2, ["z"] = 15, ["name"] = "wool:grey"}, {["x"] = 1, ["meta"] = {["fields"] = {}, ["inventory"] = {}}, ["y"] = 3, ["z"] = 0, ["name"] = "wool:grey"}, {["x"] = 1, ["meta"] = {["fields"] = {}, ["inventory"] = {}}, ["y"] = 3, ["z"] = 1, ["name"] = "wool:grey"}, {["x"] = 1, ["meta"] = {["fields"] = {}, ["inventory"] = {}}, ["y"] = 3, ["z"] = 14, ["name"] = "wool:grey"}, {["x"] = 1, ["meta"] = {["fields"] = {}, ["inventory"] = {}}, ["y"] = 3, ["z"] = 15, ["name"] = "wool:grey"}, {["x"] = 1, ["meta"] = {["fields"] = {}, ["inventory"] = {}}, ["y"] = 4, ["z"] = 0, ["name"] = "wool:grey"}, {["x"] = 1, ["meta"] = {["fields"] = {}, ["inventory"] = {}}, ["y"] = 4, ["z"] = 1, ["name"] = "wool:grey"}, {["x"] = 1, ["meta"] = {["fields"] = {}, ["inventory"] = {}}, ["y"] = 4, ["z"] = 14, ["name"] = "wool:grey"}, {["x"] = 1, ["meta"] = {["fields"] = {}, ["inventory"] = {}}, ["y"] = 4, ["z"] = 15, ["name"] = "wool:grey"}, {["x"] = 1, ["meta"] = {["fields"] = {}, ["inventory"] = {}}, ["y"] = 5, ["z"] = 0, ["name"] = "wool:grey"}, {["x"] = 1, ["meta"] = {["fields"] = {}, ["inventory"] = {}}, ["y"] = 5, ["z"] = 1, ["name"] = "wool:grey"}, {["x"] = 1, ["meta"] = {["fields"] = {}, ["inventory"] = {}}, ["y"] = 5, ["z"] = 14, ["name"] = "wool:grey"}, {["x"] = 1, ["meta"] = {["fields"] = {}, ["inventory"] = {}}, ["y"] = 5, ["z"] = 15, ["name"] = "wool:grey"}, {["x"] = 1, ["meta"] = {["fields"] = {}, ["inventory"] = {}}, ["y"] = 6, ["z"] = 0, ["name"] = "wool:grey"}, {["x"] = 1, ["meta"] = {["fields"] = {}, ["inventory"] = {}}, ["y"] = 6, ["z"] = 1, ["name"] = "wool:grey"}, {["x"] = 1, ["meta"] = {["fields"] = {}, ["inventory"] = {}}, ["y"] = 6, ["z"] = 2, ["name"] = "wool:grey"}, {["x"] = 1, ["meta"] = {["fields"] = {}, ["inventory"] = {}}, ["y"] = 6, ["z"] = 3, ["name"] = "wool:grey"}, {["x"] = 1, ["meta"] = {["fields"] = {}, ["inventory"] = {}}, ["y"] = 6, ["z"] = 4, ["name"] = "wool:grey"}, {["x"] = 1, ["meta"] = {["fields"] = {}, ["inventory"] = {}}, ["y"] = 6, ["z"] = 5, ["name"] = "wool:grey"}, {["x"] = 1, ["meta"] = {["fields"] = {}, ["inventory"] = {}}, ["y"] = 6, ["z"] = 6, ["name"] = "wool:grey"}, {["x"] = 1, ["meta"] = {["fields"] = {}, ["inventory"] = {}}, ["y"] = 6, ["z"] = 7, ["name"] = "wool:grey"}, {["x"] = 1, ["meta"] = {["fields"] = {}, ["inventory"] = {}}, ["y"] = 6, ["z"] = 8, ["name"] = "wool:grey"}, {["x"] = 1, ["meta"] = {["fields"] = {}, ["inventory"] = {}}, ["y"] = 6, ["z"] = 9, ["name"] = "wool:grey"}, {["x"] = 1, ["meta"] = {["fields"] = {}, ["inventory"] = {}}, ["y"] = 6, ["z"] = 10, ["name"] = "wool:grey"}, {["x"] = 1, ["meta"] = {["fields"] = {}, ["inventory"] = {}}, ["y"] = 6, ["z"] = 11, ["name"] = "wool:grey"}, {["x"] = 1, ["meta"] = {["fields"] = {}, ["inventory"] = {}}, ["y"] = 6, ["z"] = 12, ["name"] = "wool:grey"}, {["x"] = 1, ["meta"] = {["fields"] = {}, ["inventory"] = {}}, ["y"] = 6, ["z"] = 13, ["name"] = "wool:grey"}, {["x"] = 1, ["meta"] = {["fields"] = {}, ["inventory"] = {}}, ["y"] = 6, ["z"] = 14, ["name"] = "wool:grey"}, {["x"] = 1, ["meta"] = {["fields"] = {}, ["inventory"] = {}}, ["y"] = 6, ["z"] = 15, ["name"] = "wool:grey"}, {["x"] = 1, ["meta"] = {["fields"] = {}, ["inventory"] = {}}, ["y"] = 7, ["z"] = 0, ["name"] = "wool:grey"}, {["x"] = 1, ["meta"] = {["fields"] = {}, ["inventory"] = {}}, ["y"] = 7, ["z"] = 1, ["name"] = "wool:grey"}, {["x"] = 1, ["meta"] = {["fields"] = {}, ["inventory"] = {}}, ["y"] = 7, ["z"] = 2, ["name"] = "wool:grey"}, {["x"] = 1, ["meta"] = {["fields"] = {}, ["inventory"] = {}}, ["y"] = 7, ["z"] = 6, ["name"] = "wool:grey"}, {["x"] = 1, ["meta"] = {["fields"] = {}, ["inventory"] = {}}, ["y"] = 7, ["z"] = 9, ["name"] = "wool:grey"}, {["x"] = 1, ["meta"] = {["fields"] = {}, ["inventory"] = {}}, ["y"] = 7, ["z"] = 13, ["name"] = "wool:grey"}, {["x"] = 1, ["meta"] = {["fields"] = {}, ["inventory"] = {}}, ["y"] = 7, ["z"] = 14, ["name"] = "wool:grey"}, {["x"] = 1, ["meta"] = {["fields"] = {}, ["inventory"] = {}}, ["y"] = 7, ["z"] = 15, ["name"] = "wool:grey"}, {["x"] = 1, ["meta"] = {["fields"] = {}, ["inventory"] = {}}, ["y"] = 8, ["z"] = 0, ["name"] = "wool:grey"}, {["x"] = 1, ["meta"] = {["fields"] = {}, ["inventory"] = {}}, ["y"] = 8, ["z"] = 1, ["name"] = "wool:grey"}, {["x"] = 1, ["meta"] = {["fields"] = {}, ["inventory"] = {}}, ["y"] = 8, ["z"] = 2, ["name"] = "wool:grey"}, {["x"] = 1, ["meta"] = {["fields"] = {}, ["inventory"] = {}}, ["y"] = 8, ["z"] = 6, ["name"] = "wool:grey"}, {["x"] = 1, ["meta"] = {["fields"] = {}, ["inventory"] = {}}, ["y"] = 8, ["z"] = 9, ["name"] = "wool:grey"}, {["x"] = 1, ["meta"] = {["fields"] = {}, ["inventory"] = {}}, ["y"] = 8, ["z"] = 13, ["name"] = "wool:grey"}, {["x"] = 1, ["meta"] = {["fields"] = {}, ["inventory"] = {}}, ["y"] = 8, ["z"] = 14, ["name"] = "wool:grey"}, {["x"] = 1, ["meta"] = {["fields"] = {}, ["inventory"] = {}}, ["y"] = 8, ["z"] = 15, ["name"] = "wool:grey"}, {["x"] = 1, ["meta"] = {["fields"] = {}, ["inventory"] = {}}, ["y"] = 9, ["z"] = 0, ["name"] = "wool:grey"}, {["x"] = 1, ["meta"] = {["fields"] = {}, ["inventory"] = {}}, ["y"] = 9, ["z"] = 1, ["name"] = "wool:grey"}, {["x"] = 1, ["meta"] = {["fields"] = {}, ["inventory"] = {}}, ["y"] = 9, ["z"] = 2, ["name"] = "wool:grey"}, {["x"] = 1, ["meta"] = {["fields"] = {}, ["inventory"] = {}}, ["y"] = 9, ["z"] = 3, ["name"] = "wool:grey"}, {["x"] = 1, ["meta"] = {["fields"] = {}, ["inventory"] = {}}, ["y"] = 9, ["z"] = 4, ["name"] = "wool:grey"}, {["x"] = 1, ["meta"] = {["fields"] = {}, ["inventory"] = {}}, ["y"] = 9, ["z"] = 5, ["name"] = "wool:grey"}, {["x"] = 1, ["meta"] = {["fields"] = {}, ["inventory"] = {}}, ["y"] = 9, ["z"] = 6, ["name"] = "wool:grey"}, {["x"] = 1, ["meta"] = {["fields"] = {}, ["inventory"] = {}}, ["y"] = 9, ["z"] = 7, ["name"] = "wool:grey"}, {["x"] = 1, ["meta"] = {["fields"] = {}, ["inventory"] = {}}, ["y"] = 9, ["z"] = 8, ["name"] = "wool:grey"}, {["x"] = 1, ["meta"] = {["fields"] = {}, ["inventory"] = {}}, ["y"] = 9, ["z"] = 9, ["name"] = "wool:grey"}, {["x"] = 1, ["meta"] = {["fields"] = {}, ["inventory"] = {}}, ["y"] = 9, ["z"] = 10, ["name"] = "wool:grey"}, {["x"] = 1, ["meta"] = {["fields"] = {}, ["inventory"] = {}}, ["y"] = 9, ["z"] = 11, ["name"] = "wool:grey"}, {["x"] = 1, ["meta"] = {["fields"] = {}, ["inventory"] = {}}, ["y"] = 9, ["z"] = 12, ["name"] = "wool:grey"}, {["x"] = 1, ["meta"] = {["fields"] = {}, ["inventory"] = {}}, ["y"] = 9, ["z"] = 13, ["name"] = "wool:grey"}, {["x"] = 1, ["meta"] = {["fields"] = {}, ["inventory"] = {}}, ["y"] = 9, ["z"] = 14, ["name"] = "wool:grey"}, {["x"] = 1, ["meta"] = {["fields"] = {}, ["inventory"] = {}}, ["y"] = 9, ["z"] = 15, ["name"] = "wool:grey"}, {["x"] = 1, ["meta"] = {["fields"] = {}, ["inventory"] = {}}, ["y"] = 10, ["z"] = 0, ["name"] = "wool:grey"}, {["x"] = 1, ["meta"] = {["fields"] = {}, ["inventory"] = {}}, ["y"] = 10, ["z"] = 1, ["name"] = "wool:grey"}, {["x"] = 1, ["meta"] = {["fields"] = {}, ["inventory"] = {}}, ["y"] = 10, ["z"] = 14, ["name"] = "wool:grey"}, {["x"] = 1, ["meta"] = {["fields"] = {}, ["inventory"] = {}}, ["y"] = 10, ["z"] = 15, ["name"] = "wool:grey"}, {["x"] = 1, ["meta"] = {["fields"] = {}, ["inventory"] = {}}, ["y"] = 11, ["z"] = 0, ["name"] = "wool:grey"}, {["x"] = 1, ["meta"] = {["fields"] = {}, ["inventory"] = {}}, ["y"] = 11, ["z"] = 1, ["name"] = "wool:grey"}, {["x"] = 1, ["meta"] = {["fields"] = {}, ["inventory"] = {}}, ["y"] = 11, ["z"] = 14, ["name"] = "wool:grey"}, {["x"] = 1, ["meta"] = {["fields"] = {}, ["inventory"] = {}}, ["y"] = 11, ["z"] = 15, ["name"] = "wool:grey"}, {["x"] = 1, ["meta"] = {["fields"] = {}, ["inventory"] = {}}, ["y"] = 12, ["z"] = 0, ["name"] = "wool:grey"}, {["x"] = 1, ["meta"] = {["fields"] = {}, ["inventory"] = {}}, ["y"] = 12, ["z"] = 1, ["name"] = "wool:grey"}, {["x"] = 1, ["meta"] = {["fields"] = {}, ["inventory"] = {}}, ["y"] = 12, ["z"] = 14, ["name"] = "wool:grey"}, {["x"] = 1, ["meta"] = {["fields"] = {}, ["inventory"] = {}}, ["y"] = 12, ["z"] = 15, ["name"] = "wool:grey"}, {["x"] = 1, ["meta"] = {["fields"] = {}, ["inventory"] = {}}, ["y"] = 13, ["z"] = 0, ["name"] = "wool:grey"}, {["x"] = 1, ["meta"] = {["fields"] = {}, ["inventory"] = {}}, ["y"] = 13, ["z"] = 1, ["name"] = "wool:grey"}, {["x"] = 1, ["meta"] = {["fields"] = {}, ["inventory"] = {}}, ["y"] = 13, ["z"] = 14, ["name"] = "wool:grey"}, {["x"] = 1, ["meta"] = {["fields"] = {}, ["inventory"] = {}}, ["y"] = 13, ["z"] = 15, ["name"] = "wool:grey"}, {["x"] = 1, ["meta"] = {["fields"] = {}, ["inventory"] = {}}, ["y"] = 14, ["z"] = 0, ["name"] = "wool:grey"}, {["x"] = 1, ["meta"] = {["fields"] = {}, ["inventory"] = {}}, ["y"] = 14, ["z"] = 1, ["name"] = "wool:grey"}, {["x"] = 1, ["meta"] = {["fields"] = {}, ["inventory"] = {}}, ["y"] = 14, ["z"] = 14, ["name"] = "wool:grey"}, {["x"] = 1, ["meta"] = {["fields"] = {}, ["inventory"] = {}}, ["y"] = 14, ["z"] = 15, ["name"] = "wool:grey"}, {["x"] = 1, ["meta"] = {["fields"] = {}, ["inventory"] = {}}, ["y"] = 15, ["z"] = 0, ["name"] = "wool:grey"}, {["x"] = 1, ["meta"] = {["fields"] = {}, ["inventory"] = {}}, ["y"] = 15, ["z"] = 1, ["name"] = "wool:grey"}, {["x"] = 1, ["meta"] = {["fields"] = {}, ["inventory"] = {}}, ["y"] = 15, ["z"] = 14, ["name"] = "wool:grey"}, {["x"] = 1, ["meta"] = {["fields"] = {}, ["inventory"] = {}}, ["y"] = 15, ["z"] = 15, ["name"] = "wool:grey"}, {["x"] = 2, ["meta"] = {["fields"] = {}, ["inventory"] = {}}, ["y"] = 6, ["z"] = 1, ["name"] = "wool:grey"}, {["x"] = 2, ["meta"] = {["fields"] = {}, ["inventory"] = {}}, ["y"] = 6, ["z"] = 14, ["name"] = "wool:grey"}, {["x"] = 2, ["meta"] = {["fields"] = {}, ["inventory"] = {}}, ["y"] = 7, ["z"] = 14, ["name"] = "wool:grey"}, {["x"] = 2, ["meta"] = {["fields"] = {}, ["inventory"] = {}}, ["y"] = 8, ["z"] = 14, ["name"] = "wool:grey"}, {["x"] = 2, ["meta"] = {["fields"] = {}, ["inventory"] = {}}, ["y"] = 9, ["z"] = 1, ["name"] = "wool:grey"}, {["x"] = 2, ["meta"] = {["fields"] = {}, ["inventory"] = {}}, ["y"] = 9, ["z"] = 14, ["name"] = "wool:grey"}, {["x"] = 3, ["meta"] = {["fields"] = {}, ["inventory"] = {}}, ["y"] = 6, ["z"] = 1, ["name"] = "wool:grey"}, {["x"] = 3, ["meta"] = {["fields"] = {}, ["inventory"] = {}}, ["y"] = 6, ["z"] = 14, ["name"] = "wool:grey"}, {["x"] = 3, ["meta"] = {["fields"] = {}, ["inventory"] = {}}, ["y"] = 9, ["z"] = 1, ["name"] = "wool:grey"}, {["x"] = 3, ["meta"] = {["fields"] = {}, ["inventory"] = {}}, ["y"] = 9, ["z"] = 14, ["name"] = "wool:grey"}, {["x"] = 4, ["meta"] = {["fields"] = {}, ["inventory"] = {}}, ["y"] = 6, ["z"] = 1, ["name"] = "wool:grey"}, {["x"] = 4, ["meta"] = {["fields"] = {}, ["inventory"] = {}}, ["y"] = 6, ["z"] = 14, ["name"] = "wool:grey"}, {["x"] = 4, ["meta"] = {["fields"] = {}, ["inventory"] = {}}, ["y"] = 9, ["z"] = 1, ["name"] = "wool:grey"}, {["x"] = 4, ["meta"] = {["fields"] = {}, ["inventory"] = {}}, ["y"] = 9, ["z"] = 14, ["name"] = "wool:grey"}, {["x"] = 5, ["meta"] = {["fields"] = {}, ["inventory"] = {}}, ["y"] = 6, ["z"] = 1, ["name"] = "wool:grey"}, {["x"] = 5, ["meta"] = {["fields"] = {}, ["inventory"] = {}}, ["y"] = 6, ["z"] = 14, ["name"] = "wool:grey"}, {["x"] = 5, ["meta"] = {["fields"] = {}, ["inventory"] = {}}, ["y"] = 9, ["z"] = 1, ["name"] = "wool:grey"}, {["x"] = 5, ["meta"] = {["fields"] = {}, ["inventory"] = {}}, ["y"] = 9, ["z"] = 14, ["name"] = "wool:grey"}, {["x"] = 6, ["meta"] = {["fields"] = {}, ["inventory"] = {}}, ["y"] = 6, ["z"] = 1, ["name"] = "wool:grey"}, {["x"] = 6, ["meta"] = {["fields"] = {}, ["inventory"] = {}}, ["y"] = 6, ["z"] = 14, ["name"] = "wool:grey"}, {["x"] = 6, ["meta"] = {["fields"] = {}, ["inventory"] = {}}, ["y"] = 7, ["z"] = 1, ["name"] = "wool:grey"}, {["x"] = 6, ["meta"] = {["fields"] = {}, ["inventory"] = {}}, ["y"] = 7, ["z"] = 14, ["name"] = "wool:grey"}, {["x"] = 6, ["meta"] = {["fields"] = {}, ["inventory"] = {}}, ["y"] = 8, ["z"] = 1, ["name"] = "wool:grey"}, {["x"] = 6, ["meta"] = {["fields"] = {}, ["inventory"] = {}}, ["y"] = 8, ["z"] = 14, ["name"] = "wool:grey"}, {["x"] = 6, ["meta"] = {["fields"] = {}, ["inventory"] = {}}, ["y"] = 9, ["z"] = 1, ["name"] = "wool:grey"}, {["x"] = 6, ["meta"] = {["fields"] = {}, ["inventory"] = {}}, ["y"] = 9, ["z"] = 14, ["name"] = "wool:grey"}, {["x"] = 7, ["meta"] = {["fields"] = {}, ["inventory"] = {}}, ["y"] = 6, ["z"] = 1, ["name"] = "wool:grey"}, {["x"] = 7, ["meta"] = {["fields"] = {}, ["inventory"] = {}}, ["y"] = 6, ["z"] = 14, ["name"] = "wool:grey"}, {["x"] = 7, ["meta"] = {["fields"] = {}, ["inventory"] = {}}, ["y"] = 7, ["z"] = 0, ["name"] = "wool:red"}, {["x"] = 7, ["meta"] = {["fields"] = {}, ["inventory"] = {}}, ["y"] = 7, ["z"] = 1, ["name"] = "wool:red"}, {["x"] = 7, ["meta"] = {["fields"] = {}, ["inventory"] = {}}, ["y"] = 7, ["z"] = 2, ["name"] = "wool:red"}, {["x"] = 7, ["meta"] = {["fields"] = {}, ["inventory"] = {}}, ["y"] = 7, ["z"] = 3, ["name"] = "wool:red"}, {["x"] = 7, ["meta"] = {["fields"] = {}, ["inventory"] = {}}, ["y"] = 7, ["z"] = 4, ["name"] = "wool:red"}, {["x"] = 7, ["meta"] = {["fields"] = {}, ["inventory"] = {}}, ["y"] = 7, ["z"] = 5, ["name"] = "wool:red"}, {["x"] = 7, ["meta"] = {["fields"] = {}, ["inventory"] = {}}, ["y"] = 7, ["z"] = 6, ["name"] = "wool:red"}, {["x"] = 7, ["meta"] = {["fields"] = {}, ["inventory"] = {}}, ["y"] = 7, ["z"] = 7, ["name"] = "wool:red"}, {["x"] = 7, ["meta"] = {["fields"] = {}, ["inventory"] = {}}, ["y"] = 7, ["z"] = 8, ["name"] = "wool:red"}, {["x"] = 7, ["meta"] = {["fields"] = {}, ["inventory"] = {}}, ["y"] = 7, ["z"] = 9, ["name"] = "wool:red"}, {["x"] = 7, ["meta"] = {["fields"] = {}, ["inventory"] = {}}, ["y"] = 7, ["z"] = 10, ["name"] = "wool:red"}, {["x"] = 7, ["meta"] = {["fields"] = {}, ["inventory"] = {}}, ["y"] = 7, ["z"] = 11, ["name"] = "wool:red"}, {["x"] = 7, ["meta"] = {["fields"] = {}, ["inventory"] = {}}, ["y"] = 7, ["z"] = 12, ["name"] = "wool:red"}, {["x"] = 7, ["meta"] = {["fields"] = {}, ["inventory"] = {}}, ["y"] = 7, ["z"] = 13, ["name"] = "wool:red"}, {["x"] = 7, ["meta"] = {["fields"] = {}, ["inventory"] = {}}, ["y"] = 7, ["z"] = 14, ["name"] = "wool:red"}, {["x"] = 7, ["meta"] = {["fields"] = {}, ["inventory"] = {}}, ["y"] = 7, ["z"] = 15, ["name"] = "wool:red"}, {["x"] = 7, ["meta"] = {["fields"] = {}, ["inventory"] = {}}, ["y"] = 8, ["z"] = 0, ["name"] = "wool:red"}, {["x"] = 7, ["meta"] = {["fields"] = {}, ["inventory"] = {}}, ["y"] = 8, ["z"] = 1, ["name"] = "wool:red"}, {["x"] = 7, ["meta"] = {["fields"] = {}, ["inventory"] = {}}, ["y"] = 8, ["z"] = 2, ["name"] = "wool:red"}, {["x"] = 7, ["meta"] = {["fields"] = {}, ["inventory"] = {}}, ["y"] = 8, ["z"] = 3, ["name"] = "wool:red"}, {["x"] = 7, ["meta"] = {["fields"] = {}, ["inventory"] = {}}, ["y"] = 8, ["z"] = 4, ["name"] = "wool:red"}, {["x"] = 7, ["meta"] = {["fields"] = {}, ["inventory"] = {}}, ["y"] = 8, ["z"] = 5, ["name"] = "wool:red"}, {["x"] = 7, ["meta"] = {["fields"] = {}, ["inventory"] = {}}, ["y"] = 8, ["z"] = 6, ["name"] = "wool:red"}, {["x"] = 7, ["meta"] = {["fields"] = {}, ["inventory"] = {}}, ["y"] = 8, ["z"] = 7, ["name"] = "wool:red"}, {["x"] = 7, ["meta"] = {["fields"] = {}, ["inventory"] = {}}, ["y"] = 8, ["z"] = 8, ["name"] = "wool:red"}, {["x"] = 7, ["meta"] = {["fields"] = {}, ["inventory"] = {}}, ["y"] = 8, ["z"] = 9, ["name"] = "wool:red"}, {["x"] = 7, ["meta"] = {["fields"] = {}, ["inventory"] = {}}, ["y"] = 8, ["z"] = 10, ["name"] = "wool:red"}, {["x"] = 7, ["meta"] = {["fields"] = {}, ["inventory"] = {}}, ["y"] = 8, ["z"] = 11, ["name"] = "wool:red"}, {["x"] = 7, ["meta"] = {["fields"] = {}, ["inventory"] = {}}, ["y"] = 8, ["z"] = 12, ["name"] = "wool:red"}, {["x"] = 7, ["meta"] = {["fields"] = {}, ["inventory"] = {}}, ["y"] = 8, ["z"] = 13, ["name"] = "wool:red"}, {["x"] = 7, ["meta"] = {["fields"] = {}, ["inventory"] = {}}, ["y"] = 8, ["z"] = 14, ["name"] = "wool:red"}, {["x"] = 7, ["meta"] = {["fields"] = {}, ["inventory"] = {}}, ["y"] = 8, ["z"] = 15, ["name"] = "wool:red"}, {["x"] = 7, ["meta"] = {["fields"] = {}, ["inventory"] = {}}, ["y"] = 9, ["z"] = 1, ["name"] = "wool:grey"}, {["x"] = 7, ["meta"] = {["fields"] = {}, ["inventory"] = {}}, ["y"] = 9, ["z"] = 14, ["name"] = "wool:grey"}, {["x"] = 8, ["meta"] = {["fields"] = {}, ["inventory"] = {}}, ["y"] = 6, ["z"] = 1, ["name"] = "wool:grey"}, {["x"] = 8, ["meta"] = {["fields"] = {}, ["inventory"] = {}}, ["y"] = 6, ["z"] = 14, ["name"] = "wool:grey"}, {["x"] = 8, ["meta"] = {["fields"] = {}, ["inventory"] = {}}, ["y"] = 7, ["z"] = 0, ["name"] = "wool:red"}, {["x"] = 8, ["meta"] = {["fields"] = {}, ["inventory"] = {}}, ["y"] = 7, ["z"] = 1, ["name"] = "wool:red"}, {["x"] = 8, ["meta"] = {["fields"] = {}, ["inventory"] = {}}, ["y"] = 7, ["z"] = 2, ["name"] = "wool:red"}, {["x"] = 8, ["meta"] = {["fields"] = {}, ["inventory"] = {}}, ["y"] = 7, ["z"] = 3, ["name"] = "wool:red"}, {["x"] = 8, ["meta"] = {["fields"] = {}, ["inventory"] = {}}, ["y"] = 7, ["z"] = 4, ["name"] = "wool:red"}, {["x"] = 8, ["meta"] = {["fields"] = {}, ["inventory"] = {}}, ["y"] = 7, ["z"] = 5, ["name"] = "wool:red"}, {["x"] = 8, ["meta"] = {["fields"] = {}, ["inventory"] = {}}, ["y"] = 7, ["z"] = 6, ["name"] = "wool:red"}, {["x"] = 8, ["meta"] = {["fields"] = {}, ["inventory"] = {}}, ["y"] = 7, ["z"] = 7, ["name"] = "wool:red"}, {["x"] = 8, ["meta"] = {["fields"] = {}, ["inventory"] = {}}, ["y"] = 7, ["z"] = 8, ["name"] = "wool:red"}, {["x"] = 8, ["meta"] = {["fields"] = {}, ["inventory"] = {}}, ["y"] = 7, ["z"] = 9, ["name"] = "wool:red"}, {["x"] = 8, ["meta"] = {["fields"] = {}, ["inventory"] = {}}, ["y"] = 7, ["z"] = 10, ["name"] = "wool:red"}, {["x"] = 8, ["meta"] = {["fields"] = {}, ["inventory"] = {}}, ["y"] = 7, ["z"] = 11, ["name"] = "wool:red"}, {["x"] = 8, ["meta"] = {["fields"] = {}, ["inventory"] = {}}, ["y"] = 7, ["z"] = 12, ["name"] = "wool:red"}, {["x"] = 8, ["meta"] = {["fields"] = {}, ["inventory"] = {}}, ["y"] = 7, ["z"] = 13, ["name"] = "wool:red"}, {["x"] = 8, ["meta"] = {["fields"] = {}, ["inventory"] = {}}, ["y"] = 7, ["z"] = 14, ["name"] = "wool:red"}, {["x"] = 8, ["meta"] = {["fields"] = {}, ["inventory"] = {}}, ["y"] = 7, ["z"] = 15, ["name"] = "wool:red"}, {["x"] = 8, ["meta"] = {["fields"] = {}, ["inventory"] = {}}, ["y"] = 8, ["z"] = 0, ["name"] = "wool:red"}, {["x"] = 8, ["meta"] = {["fields"] = {}, ["inventory"] = {}}, ["y"] = 8, ["z"] = 1, ["name"] = "wool:red"}, {["x"] = 8, ["meta"] = {["fields"] = {}, ["inventory"] = {}}, ["y"] = 8, ["z"] = 2, ["name"] = "wool:red"}, {["x"] = 8, ["meta"] = {["fields"] = {}, ["inventory"] = {}}, ["y"] = 8, ["z"] = 3, ["name"] = "wool:red"}, {["x"] = 8, ["meta"] = {["fields"] = {}, ["inventory"] = {}}, ["y"] = 8, ["z"] = 4, ["name"] = "wool:red"}, {["x"] = 8, ["meta"] = {["fields"] = {}, ["inventory"] = {}}, ["y"] = 8, ["z"] = 5, ["name"] = "wool:red"}, {["x"] = 8, ["meta"] = {["fields"] = {}, ["inventory"] = {}}, ["y"] = 8, ["z"] = 6, ["name"] = "wool:red"}, {["x"] = 8, ["meta"] = {["fields"] = {}, ["inventory"] = {}}, ["y"] = 8, ["z"] = 7, ["name"] = "wool:red"}, {["x"] = 8, ["meta"] = {["fields"] = {}, ["inventory"] = {}}, ["y"] = 8, ["z"] = 8, ["name"] = "wool:red"}, {["x"] = 8, ["meta"] = {["fields"] = {}, ["inventory"] = {}}, ["y"] = 8, ["z"] = 9, ["name"] = "wool:red"}, {["x"] = 8, ["meta"] = {["fields"] = {}, ["inventory"] = {}}, ["y"] = 8, ["z"] = 10, ["name"] = "wool:red"}, {["x"] = 8, ["meta"] = {["fields"] = {}, ["inventory"] = {}}, ["y"] = 8, ["z"] = 11, ["name"] = "wool:red"}, {["x"] = 8, ["meta"] = {["fields"] = {}, ["inventory"] = {}}, ["y"] = 8, ["z"] = 12, ["name"] = "wool:red"}, {["x"] = 8, ["meta"] = {["fields"] = {}, ["inventory"] = {}}, ["y"] = 8, ["z"] = 13, ["name"] = "wool:red"}, {["x"] = 8, ["meta"] = {["fields"] = {}, ["inventory"] = {}}, ["y"] = 8, ["z"] = 14, ["name"] = "wool:red"}, {["x"] = 8, ["meta"] = {["fields"] = {}, ["inventory"] = {}}, ["y"] = 8, ["z"] = 15, ["name"] = "wool:red"}, {["x"] = 8, ["meta"] = {["fields"] = {}, ["inventory"] = {}}, ["y"] = 9, ["z"] = 1, ["name"] = "wool:grey"}, {["x"] = 8, ["meta"] = {["fields"] = {}, ["inventory"] = {}}, ["y"] = 9, ["z"] = 14, ["name"] = "wool:grey"}, {["x"] = 9, ["meta"] = {["fields"] = {}, ["inventory"] = {}}, ["y"] = 6, ["z"] = 1, ["name"] = "wool:grey"}, {["x"] = 9, ["meta"] = {["fields"] = {}, ["inventory"] = {}}, ["y"] = 6, ["z"] = 14, ["name"] = "wool:grey"}, {["x"] = 9, ["meta"] = {["fields"] = {}, ["inventory"] = {}}, ["y"] = 7, ["z"] = 1, ["name"] = "wool:grey"}, {["x"] = 9, ["meta"] = {["fields"] = {}, ["inventory"] = {}}, ["y"] = 7, ["z"] = 14, ["name"] = "wool:grey"}, {["x"] = 9, ["meta"] = {["fields"] = {}, ["inventory"] = {}}, ["y"] = 8, ["z"] = 1, ["name"] = "wool:grey"}, {["x"] = 9, ["meta"] = {["fields"] = {}, ["inventory"] = {}}, ["y"] = 8, ["z"] = 14, ["name"] = "wool:grey"}, {["x"] = 9, ["meta"] = {["fields"] = {}, ["inventory"] = {}}, ["y"] = 9, ["z"] = 1, ["name"] = "wool:grey"}, {["x"] = 9, ["meta"] = {["fields"] = {}, ["inventory"] = {}}, ["y"] = 9, ["z"] = 14, ["name"] = "wool:grey"}, {["x"] = 10, ["meta"] = {["fields"] = {}, ["inventory"] = {}}, ["y"] = 6, ["z"] = 1, ["name"] = "wool:grey"}, {["x"] = 10, ["meta"] = {["fields"] = {}, ["inventory"] = {}}, ["y"] = 6, ["z"] = 14, ["name"] = "wool:grey"}, {["x"] = 10, ["meta"] = {["fields"] = {}, ["inventory"] = {}}, ["y"] = 9, ["z"] = 1, ["name"] = "wool:grey"}, {["x"] = 10, ["meta"] = {["fields"] = {}, ["inventory"] = {}}, ["y"] = 9, ["z"] = 14, ["name"] = "wool:grey"}, {["x"] = 11, ["meta"] = {["fields"] = {}, ["inventory"] = {}}, ["y"] = 6, ["z"] = 1, ["name"] = "wool:grey"}, {["x"] = 11, ["meta"] = {["fields"] = {}, ["inventory"] = {}}, ["y"] = 6, ["z"] = 14, ["name"] = "wool:grey"}, {["x"] = 11, ["meta"] = {["fields"] = {}, ["inventory"] = {}}, ["y"] = 9, ["z"] = 1, ["name"] = "wool:grey"}, {["x"] = 11, ["meta"] = {["fields"] = {}, ["inventory"] = {}}, ["y"] = 9, ["z"] = 14, ["name"] = "wool:grey"}, {["x"] = 12, ["meta"] = {["fields"] = {}, ["inventory"] = {}}, ["y"] = 6, ["z"] = 1, ["name"] = "wool:grey"}, {["x"] = 12, ["meta"] = {["fields"] = {}, ["inventory"] = {}}, ["y"] = 6, ["z"] = 14, ["name"] = "wool:grey"}, {["x"] = 12, ["meta"] = {["fields"] = {}, ["inventory"] = {}}, ["y"] = 9, ["z"] = 1, ["name"] = "wool:grey"}, {["x"] = 12, ["meta"] = {["fields"] = {}, ["inventory"] = {}}, ["y"] = 9, ["z"] = 14, ["name"] = "wool:grey"}, {["x"] = 13, ["meta"] = {["fields"] = {}, ["inventory"] = {}}, ["y"] = 6, ["z"] = 1, ["name"] = "wool:grey"}, {["x"] = 13, ["meta"] = {["fields"] = {}, ["inventory"] = {}}, ["y"] = 6, ["z"] = 14, ["name"] = "wool:grey"}, {["x"] = 13, ["meta"] = {["fields"] = {}, ["inventory"] = {}}, ["y"] = 7, ["z"] = 14, ["name"] = "wool:grey"}, {["x"] = 13, ["meta"] = {["fields"] = {}, ["inventory"] = {}}, ["y"] = 8, ["z"] = 14, ["name"] = "wool:grey"}, {["x"] = 13, ["meta"] = {["fields"] = {}, ["inventory"] = {}}, ["y"] = 9, ["z"] = 1, ["name"] = "wool:grey"}, {["x"] = 13, ["meta"] = {["fields"] = {}, ["inventory"] = {}}, ["y"] = 9, ["z"] = 14, ["name"] = "wool:grey"}, {["x"] = 14, ["meta"] = {["fields"] = {}, ["inventory"] = {}}, ["y"] = 0, ["z"] = 0, ["name"] = "wool:grey"}, {["x"] = 14, ["meta"] = {["fields"] = {}, ["inventory"] = {}}, ["y"] = 0, ["z"] = 1, ["name"] = "wool:grey"}, {["x"] = 14, ["meta"] = {["fields"] = {}, ["inventory"] = {}}, ["y"] = 0, ["z"] = 14, ["name"] = "wool:grey"}, {["x"] = 14, ["meta"] = {["fields"] = {}, ["inventory"] = {}}, ["y"] = 0, ["z"] = 15, ["name"] = "wool:grey"}, {["x"] = 14, ["meta"] = {["fields"] = {}, ["inventory"] = {}}, ["y"] = 1, ["z"] = 0, ["name"] = "wool:grey"}, {["x"] = 14, ["meta"] = {["fields"] = {}, ["inventory"] = {}}, ["y"] = 1, ["z"] = 1, ["name"] = "wool:grey"}, {["x"] = 14, ["meta"] = {["fields"] = {}, ["inventory"] = {}}, ["y"] = 1, ["z"] = 14, ["name"] = "wool:grey"}, {["x"] = 14, ["meta"] = {["fields"] = {}, ["inventory"] = {}}, ["y"] = 1, ["z"] = 15, ["name"] = "wool:grey"}, {["x"] = 14, ["meta"] = {["fields"] = {}, ["inventory"] = {}}, ["y"] = 2, ["z"] = 0, ["name"] = "wool:grey"}, {["x"] = 14, ["meta"] = {["fields"] = {}, ["inventory"] = {}}, ["y"] = 2, ["z"] = 1, ["name"] = "wool:grey"}, {["x"] = 14, ["meta"] = {["fields"] = {}, ["inventory"] = {}}, ["y"] = 2, ["z"] = 14, ["name"] = "wool:grey"}, {["x"] = 14, ["meta"] = {["fields"] = {}, ["inventory"] = {}}, ["y"] = 2, ["z"] = 15, ["name"] = "wool:grey"}, {["x"] = 14, ["meta"] = {["fields"] = {}, ["inventory"] = {}}, ["y"] = 3, ["z"] = 0, ["name"] = "wool:grey"}, {["x"] = 14, ["meta"] = {["fields"] = {}, ["inventory"] = {}}, ["y"] = 3, ["z"] = 1, ["name"] = "wool:grey"}, {["x"] = 14, ["meta"] = {["fields"] = {}, ["inventory"] = {}}, ["y"] = 3, ["z"] = 14, ["name"] = "wool:grey"}, {["x"] = 14, ["meta"] = {["fields"] = {}, ["inventory"] = {}}, ["y"] = 3, ["z"] = 15, ["name"] = "wool:grey"}, {["x"] = 14, ["meta"] = {["fields"] = {}, ["inventory"] = {}}, ["y"] = 4, ["z"] = 0, ["name"] = "wool:grey"}, {["x"] = 14, ["meta"] = {["fields"] = {}, ["inventory"] = {}}, ["y"] = 4, ["z"] = 1, ["name"] = "wool:grey"}, {["x"] = 14, ["meta"] = {["fields"] = {}, ["inventory"] = {}}, ["y"] = 4, ["z"] = 14, ["name"] = "wool:grey"}, {["x"] = 14, ["meta"] = {["fields"] = {}, ["inventory"] = {}}, ["y"] = 4, ["z"] = 15, ["name"] = "wool:grey"}, {["x"] = 14, ["meta"] = {["fields"] = {}, ["inventory"] = {}}, ["y"] = 5, ["z"] = 0, ["name"] = "wool:grey"}, {["x"] = 14, ["meta"] = {["fields"] = {}, ["inventory"] = {}}, ["y"] = 5, ["z"] = 1, ["name"] = "wool:grey"}, {["x"] = 14, ["meta"] = {["fields"] = {}, ["inventory"] = {}}, ["y"] = 5, ["z"] = 14, ["name"] = "wool:grey"}, {["x"] = 14, ["meta"] = {["fields"] = {}, ["inventory"] = {}}, ["y"] = 5, ["z"] = 15, ["name"] = "wool:grey"}, {["x"] = 14, ["meta"] = {["fields"] = {}, ["inventory"] = {}}, ["y"] = 6, ["z"] = 0, ["name"] = "wool:grey"}, {["x"] = 14, ["meta"] = {["fields"] = {}, ["inventory"] = {}}, ["y"] = 6, ["z"] = 1, ["name"] = "wool:grey"}, {["x"] = 14, ["meta"] = {["fields"] = {}, ["inventory"] = {}}, ["y"] = 6, ["z"] = 2, ["name"] = "wool:grey"}, {["x"] = 14, ["meta"] = {["fields"] = {}, ["inventory"] = {}}, ["y"] = 6, ["z"] = 3, ["name"] = "wool:grey"}, {["x"] = 14, ["meta"] = {["fields"] = {}, ["inventory"] = {}}, ["y"] = 6, ["z"] = 4, ["name"] = "wool:grey"}, {["x"] = 14, ["meta"] = {["fields"] = {}, ["inventory"] = {}}, ["y"] = 6, ["z"] = 5, ["name"] = "wool:grey"}, {["x"] = 14, ["meta"] = {["fields"] = {}, ["inventory"] = {}}, ["y"] = 6, ["z"] = 6, ["name"] = "wool:grey"}, {["x"] = 14, ["meta"] = {["fields"] = {}, ["inventory"] = {}}, ["y"] = 6, ["z"] = 7, ["name"] = "wool:grey"}, {["x"] = 14, ["meta"] = {["fields"] = {}, ["inventory"] = {}}, ["y"] = 6, ["z"] = 8, ["name"] = "wool:grey"}, {["x"] = 14, ["meta"] = {["fields"] = {}, ["inventory"] = {}}, ["y"] = 6, ["z"] = 9, ["name"] = "wool:grey"}, {["x"] = 14, ["meta"] = {["fields"] = {}, ["inventory"] = {}}, ["y"] = 6, ["z"] = 10, ["name"] = "wool:grey"}, {["x"] = 14, ["meta"] = {["fields"] = {}, ["inventory"] = {}}, ["y"] = 6, ["z"] = 11, ["name"] = "wool:grey"}, {["x"] = 14, ["meta"] = {["fields"] = {}, ["inventory"] = {}}, ["y"] = 6, ["z"] = 12, ["name"] = "wool:grey"}, {["x"] = 14, ["meta"] = {["fields"] = {}, ["inventory"] = {}}, ["y"] = 6, ["z"] = 13, ["name"] = "wool:grey"}, {["x"] = 14, ["meta"] = {["fields"] = {}, ["inventory"] = {}}, ["y"] = 6, ["z"] = 14, ["name"] = "wool:grey"}, {["x"] = 14, ["meta"] = {["fields"] = {}, ["inventory"] = {}}, ["y"] = 6, ["z"] = 15, ["name"] = "wool:grey"}, {["x"] = 14, ["meta"] = {["fields"] = {}, ["inventory"] = {}}, ["y"] = 7, ["z"] = 0, ["name"] = "wool:grey"}, {["x"] = 14, ["meta"] = {["fields"] = {}, ["inventory"] = {}}, ["y"] = 7, ["z"] = 1, ["name"] = "wool:grey"}, {["x"] = 14, ["meta"] = {["fields"] = {}, ["inventory"] = {}}, ["y"] = 7, ["z"] = 2, ["name"] = "wool:grey"}, {["x"] = 14, ["meta"] = {["fields"] = {}, ["inventory"] = {}}, ["y"] = 7, ["z"] = 6, ["name"] = "wool:grey"}, {["x"] = 14, ["meta"] = {["fields"] = {}, ["inventory"] = {}}, ["y"] = 7, ["z"] = 9, ["name"] = "wool:grey"}, {["x"] = 14, ["meta"] = {["fields"] = {}, ["inventory"] = {}}, ["y"] = 7, ["z"] = 13, ["name"] = "wool:grey"}, {["x"] = 14, ["meta"] = {["fields"] = {}, ["inventory"] = {}}, ["y"] = 7, ["z"] = 14, ["name"] = "wool:grey"}, {["x"] = 14, ["meta"] = {["fields"] = {}, ["inventory"] = {}}, ["y"] = 7, ["z"] = 15, ["name"] = "wool:grey"}, {["x"] = 14, ["meta"] = {["fields"] = {}, ["inventory"] = {}}, ["y"] = 8, ["z"] = 0, ["name"] = "wool:grey"}, {["x"] = 14, ["meta"] = {["fields"] = {}, ["inventory"] = {}}, ["y"] = 8, ["z"] = 1, ["name"] = "wool:grey"}, {["x"] = 14, ["meta"] = {["fields"] = {}, ["inventory"] = {}}, ["y"] = 8, ["z"] = 2, ["name"] = "wool:grey"}, {["x"] = 14, ["meta"] = {["fields"] = {}, ["inventory"] = {}}, ["y"] = 8, ["z"] = 6, ["name"] = "wool:grey"}, {["x"] = 14, ["meta"] = {["fields"] = {}, ["inventory"] = {}}, ["y"] = 8, ["z"] = 9, ["name"] = "wool:grey"}, {["x"] = 14, ["meta"] = {["fields"] = {}, ["inventory"] = {}}, ["y"] = 8, ["z"] = 13, ["name"] = "wool:grey"}, {["x"] = 14, ["meta"] = {["fields"] = {}, ["inventory"] = {}}, ["y"] = 8, ["z"] = 14, ["name"] = "wool:grey"}, {["x"] = 14, ["meta"] = {["fields"] = {}, ["inventory"] = {}}, ["y"] = 8, ["z"] = 15, ["name"] = "wool:grey"}, {["x"] = 14, ["meta"] = {["fields"] = {}, ["inventory"] = {}}, ["y"] = 9, ["z"] = 0, ["name"] = "wool:grey"}, {["x"] = 14, ["meta"] = {["fields"] = {}, ["inventory"] = {}}, ["y"] = 9, ["z"] = 1, ["name"] = "wool:grey"}, {["x"] = 14, ["meta"] = {["fields"] = {}, ["inventory"] = {}}, ["y"] = 9, ["z"] = 2, ["name"] = "wool:grey"}, {["x"] = 14, ["meta"] = {["fields"] = {}, ["inventory"] = {}}, ["y"] = 9, ["z"] = 3, ["name"] = "wool:grey"}, {["x"] = 14, ["meta"] = {["fields"] = {}, ["inventory"] = {}}, ["y"] = 9, ["z"] = 4, ["name"] = "wool:grey"}, {["x"] = 14, ["meta"] = {["fields"] = {}, ["inventory"] = {}}, ["y"] = 9, ["z"] = 5, ["name"] = "wool:grey"}, {["x"] = 14, ["meta"] = {["fields"] = {}, ["inventory"] = {}}, ["y"] = 9, ["z"] = 6, ["name"] = "wool:grey"}, {["x"] = 14, ["meta"] = {["fields"] = {}, ["inventory"] = {}}, ["y"] = 9, ["z"] = 7, ["name"] = "wool:grey"}, {["x"] = 14, ["meta"] = {["fields"] = {}, ["inventory"] = {}}, ["y"] = 9, ["z"] = 8, ["name"] = "wool:grey"}, {["x"] = 14, ["meta"] = {["fields"] = {}, ["inventory"] = {}}, ["y"] = 9, ["z"] = 9, ["name"] = "wool:grey"}, {["x"] = 14, ["meta"] = {["fields"] = {}, ["inventory"] = {}}, ["y"] = 9, ["z"] = 10, ["name"] = "wool:grey"}, {["x"] = 14, ["meta"] = {["fields"] = {}, ["inventory"] = {}}, ["y"] = 9, ["z"] = 11, ["name"] = "wool:grey"}, {["x"] = 14, ["meta"] = {["fields"] = {}, ["inventory"] = {}}, ["y"] = 9, ["z"] = 12, ["name"] = "wool:grey"}, {["x"] = 14, ["meta"] = {["fields"] = {}, ["inventory"] = {}}, ["y"] = 9, ["z"] = 13, ["name"] = "wool:grey"}, {["x"] = 14, ["meta"] = {["fields"] = {}, ["inventory"] = {}}, ["y"] = 9, ["z"] = 14, ["name"] = "wool:grey"}, {["x"] = 14, ["meta"] = {["fields"] = {}, ["inventory"] = {}}, ["y"] = 9, ["z"] = 15, ["name"] = "wool:grey"}, {["x"] = 14, ["meta"] = {["fields"] = {}, ["inventory"] = {}}, ["y"] = 10, ["z"] = 0, ["name"] = "wool:grey"}, {["x"] = 14, ["meta"] = {["fields"] = {}, ["inventory"] = {}}, ["y"] = 10, ["z"] = 1, ["name"] = "wool:grey"}, {["x"] = 14, ["meta"] = {["fields"] = {}, ["inventory"] = {}}, ["y"] = 10, ["z"] = 14, ["name"] = "wool:grey"}, {["x"] = 14, ["meta"] = {["fields"] = {}, ["inventory"] = {}}, ["y"] = 10, ["z"] = 15, ["name"] = "wool:grey"}, {["x"] = 14, ["meta"] = {["fields"] = {}, ["inventory"] = {}}, ["y"] = 11, ["z"] = 0, ["name"] = "wool:grey"}, {["x"] = 14, ["meta"] = {["fields"] = {}, ["inventory"] = {}}, ["y"] = 11, ["z"] = 1, ["name"] = "wool:grey"}, {["x"] = 14, ["meta"] = {["fields"] = {}, ["inventory"] = {}}, ["y"] = 11, ["z"] = 14, ["name"] = "wool:grey"}, {["x"] = 14, ["meta"] = {["fields"] = {}, ["inventory"] = {}}, ["y"] = 11, ["z"] = 15, ["name"] = "wool:grey"}, {["x"] = 14, ["meta"] = {["fields"] = {}, ["inventory"] = {}}, ["y"] = 12, ["z"] = 0, ["name"] = "wool:grey"}, {["x"] = 14, ["meta"] = {["fields"] = {}, ["inventory"] = {}}, ["y"] = 12, ["z"] = 1, ["name"] = "wool:grey"}, {["x"] = 14, ["meta"] = {["fields"] = {}, ["inventory"] = {}}, ["y"] = 12, ["z"] = 14, ["name"] = "wool:grey"}, {["x"] = 14, ["meta"] = {["fields"] = {}, ["inventory"] = {}}, ["y"] = 12, ["z"] = 15, ["name"] = "wool:grey"}, {["x"] = 14, ["meta"] = {["fields"] = {}, ["inventory"] = {}}, ["y"] = 13, ["z"] = 0, ["name"] = "wool:grey"}, {["x"] = 14, ["meta"] = {["fields"] = {}, ["inventory"] = {}}, ["y"] = 13, ["z"] = 1, ["name"] = "wool:grey"}, {["x"] = 14, ["meta"] = {["fields"] = {}, ["inventory"] = {}}, ["y"] = 13, ["z"] = 14, ["name"] = "wool:grey"}, {["x"] = 14, ["meta"] = {["fields"] = {}, ["inventory"] = {}}, ["y"] = 13, ["z"] = 15, ["name"] = "wool:grey"}, {["x"] = 14, ["meta"] = {["fields"] = {}, ["inventory"] = {}}, ["y"] = 14, ["z"] = 0, ["name"] = "wool:grey"}, {["x"] = 14, ["meta"] = {["fields"] = {}, ["inventory"] = {}}, ["y"] = 14, ["z"] = 1, ["name"] = "wool:grey"}, {["x"] = 14, ["meta"] = {["fields"] = {}, ["inventory"] = {}}, ["y"] = 14, ["z"] = 14, ["name"] = "wool:grey"}, {["x"] = 14, ["meta"] = {["fields"] = {}, ["inventory"] = {}}, ["y"] = 14, ["z"] = 15, ["name"] = "wool:grey"}, {["x"] = 14, ["meta"] = {["fields"] = {}, ["inventory"] = {}}, ["y"] = 15, ["z"] = 0, ["name"] = "wool:grey"}, {["x"] = 14, ["meta"] = {["fields"] = {}, ["inventory"] = {}}, ["y"] = 15, ["z"] = 1, ["name"] = "wool:grey"}, {["x"] = 14, ["meta"] = {["fields"] = {}, ["inventory"] = {}}, ["y"] = 15, ["z"] = 14, ["name"] = "wool:grey"}, {["x"] = 14, ["meta"] = {["fields"] = {}, ["inventory"] = {}}, ["y"] = 15, ["z"] = 15, ["name"] = "wool:grey"}, {["x"] = 15, ["meta"] = {["fields"] = {}, ["inventory"] = {}}, ["y"] = 0, ["z"] = 0, ["name"] = "wool:grey"}, {["x"] = 15, ["meta"] = {["fields"] = {}, ["inventory"] = {}}, ["y"] = 0, ["z"] = 1, ["name"] = "wool:grey"}, {["x"] = 15, ["meta"] = {["fields"] = {}, ["inventory"] = {}}, ["y"] = 0, ["z"] = 14, ["name"] = "wool:grey"}, {["x"] = 15, ["meta"] = {["fields"] = {}, ["inventory"] = {}}, ["y"] = 0, ["z"] = 15, ["name"] = "wool:grey"}, {["x"] = 15, ["meta"] = {["fields"] = {}, ["inventory"] = {}}, ["y"] = 1, ["z"] = 0, ["name"] = "wool:grey"}, {["x"] = 15, ["meta"] = {["fields"] = {}, ["inventory"] = {}}, ["y"] = 1, ["z"] = 1, ["name"] = "wool:grey"}, {["x"] = 15, ["meta"] = {["fields"] = {}, ["inventory"] = {}}, ["y"] = 1, ["z"] = 14, ["name"] = "wool:grey"}, {["x"] = 15, ["meta"] = {["fields"] = {}, ["inventory"] = {}}, ["y"] = 1, ["z"] = 15, ["name"] = "wool:grey"}, {["x"] = 15, ["meta"] = {["fields"] = {}, ["inventory"] = {}}, ["y"] = 2, ["z"] = 0, ["name"] = "wool:grey"}, {["x"] = 15, ["meta"] = {["fields"] = {}, ["inventory"] = {}}, ["y"] = 2, ["z"] = 1, ["name"] = "wool:grey"}, {["x"] = 15, ["meta"] = {["fields"] = {}, ["inventory"] = {}}, ["y"] = 2, ["z"] = 14, ["name"] = "wool:grey"}, {["x"] = 15, ["meta"] = {["fields"] = {}, ["inventory"] = {}}, ["y"] = 2, ["z"] = 15, ["name"] = "wool:grey"}, {["x"] = 15, ["meta"] = {["fields"] = {}, ["inventory"] = {}}, ["y"] = 3, ["z"] = 0, ["name"] = "wool:grey"}, {["x"] = 15, ["meta"] = {["fields"] = {}, ["inventory"] = {}}, ["y"] = 3, ["z"] = 1, ["name"] = "wool:grey"}, {["x"] = 15, ["meta"] = {["fields"] = {}, ["inventory"] = {}}, ["y"] = 3, ["z"] = 14, ["name"] = "wool:grey"}, {["x"] = 15, ["meta"] = {["fields"] = {}, ["inventory"] = {}}, ["y"] = 3, ["z"] = 15, ["name"] = "wool:grey"}, {["x"] = 15, ["meta"] = {["fields"] = {}, ["inventory"] = {}}, ["y"] = 4, ["z"] = 0, ["name"] = "wool:grey"}, {["x"] = 15, ["meta"] = {["fields"] = {}, ["inventory"] = {}}, ["y"] = 4, ["z"] = 1, ["name"] = "wool:grey"}, {["x"] = 15, ["meta"] = {["fields"] = {}, ["inventory"] = {}}, ["y"] = 4, ["z"] = 14, ["name"] = "wool:grey"}, {["x"] = 15, ["meta"] = {["fields"] = {}, ["inventory"] = {}}, ["y"] = 4, ["z"] = 15, ["name"] = "wool:grey"}, {["x"] = 15, ["meta"] = {["fields"] = {}, ["inventory"] = {}}, ["y"] = 5, ["z"] = 0, ["name"] = "wool:grey"}, {["x"] = 15, ["meta"] = {["fields"] = {}, ["inventory"] = {}}, ["y"] = 5, ["z"] = 1, ["name"] = "wool:grey"}, {["x"] = 15, ["meta"] = {["fields"] = {}, ["inventory"] = {}}, ["y"] = 5, ["z"] = 14, ["name"] = "wool:grey"}, {["x"] = 15, ["meta"] = {["fields"] = {}, ["inventory"] = {}}, ["y"] = 5, ["z"] = 15, ["name"] = "wool:grey"}, {["x"] = 15, ["meta"] = {["fields"] = {}, ["inventory"] = {}}, ["y"] = 6, ["z"] = 0, ["name"] = "wool:grey"}, {["x"] = 15, ["meta"] = {["fields"] = {}, ["inventory"] = {}}, ["y"] = 6, ["z"] = 1, ["name"] = "wool:grey"}, {["x"] = 15, ["meta"] = {["fields"] = {}, ["inventory"] = {}}, ["y"] = 6, ["z"] = 14, ["name"] = "wool:grey"}, {["x"] = 15, ["meta"] = {["fields"] = {}, ["inventory"] = {}}, ["y"] = 6, ["z"] = 15, ["name"] = "wool:grey"}, {["x"] = 15, ["meta"] = {["fields"] = {}, ["inventory"] = {}}, ["y"] = 7, ["z"] = 0, ["name"] = "wool:grey"}, {["x"] = 15, ["meta"] = {["fields"] = {}, ["inventory"] = {}}, ["y"] = 7, ["z"] = 1, ["name"] = "wool:grey"}, {["x"] = 15, ["meta"] = {["fields"] = {}, ["inventory"] = {}}, ["y"] = 7, ["z"] = 14, ["name"] = "wool:grey"}, {["x"] = 15, ["meta"] = {["fields"] = {}, ["inventory"] = {}}, ["y"] = 7, ["z"] = 15, ["name"] = "wool:grey"}, {["x"] = 15, ["meta"] = {["fields"] = {}, ["inventory"] = {}}, ["y"] = 8, ["z"] = 0, ["name"] = "wool:grey"}, {["x"] = 15, ["meta"] = {["fields"] = {}, ["inventory"] = {}}, ["y"] = 8, ["z"] = 1, ["name"] = "wool:grey"}, {["x"] = 15, ["meta"] = {["fields"] = {}, ["inventory"] = {}}, ["y"] = 8, ["z"] = 14, ["name"] = "wool:grey"}, {["x"] = 15, ["meta"] = {["fields"] = {}, ["inventory"] = {}}, ["y"] = 8, ["z"] = 15, ["name"] = "wool:grey"}, {["x"] = 15, ["meta"] = {["fields"] = {}, ["inventory"] = {}}, ["y"] = 9, ["z"] = 0, ["name"] = "wool:grey"}, {["x"] = 15, ["meta"] = {["fields"] = {}, ["inventory"] = {}}, ["y"] = 9, ["z"] = 1, ["name"] = "wool:grey"}, {["x"] = 15, ["meta"] = {["fields"] = {}, ["inventory"] = {}}, ["y"] = 9, ["z"] = 14, ["name"] = "wool:grey"}, {["x"] = 15, ["meta"] = {["fields"] = {}, ["inventory"] = {}}, ["y"] = 9, ["z"] = 15, ["name"] = "wool:grey"}, {["x"] = 15, ["meta"] = {["fields"] = {}, ["inventory"] = {}}, ["y"] = 10, ["z"] = 0, ["name"] = "wool:grey"}, {["x"] = 15, ["meta"] = {["fields"] = {}, ["inventory"] = {}}, ["y"] = 10, ["z"] = 1, ["name"] = "wool:grey"}, {["x"] = 15, ["meta"] = {["fields"] = {}, ["inventory"] = {}}, ["y"] = 10, ["z"] = 14, ["name"] = "wool:grey"}, {["x"] = 15, ["meta"] = {["fields"] = {}, ["inventory"] = {}}, ["y"] = 10, ["z"] = 15, ["name"] = "wool:grey"}, {["x"] = 15, ["meta"] = {["fields"] = {}, ["inventory"] = {}}, ["y"] = 11, ["z"] = 0, ["name"] = "wool:grey"}, {["x"] = 15, ["meta"] = {["fields"] = {}, ["inventory"] = {}}, ["y"] = 11, ["z"] = 1, ["name"] = "wool:grey"}, {["x"] = 15, ["meta"] = {["fields"] = {}, ["inventory"] = {}}, ["y"] = 11, ["z"] = 14, ["name"] = "wool:grey"}, {["x"] = 15, ["meta"] = {["fields"] = {}, ["inventory"] = {}}, ["y"] = 11, ["z"] = 15, ["name"] = "wool:grey"}, {["x"] = 15, ["meta"] = {["fields"] = {}, ["inventory"] = {}}, ["y"] = 12, ["z"] = 0, ["name"] = "wool:grey"}, {["x"] = 15, ["meta"] = {["fields"] = {}, ["inventory"] = {}}, ["y"] = 12, ["z"] = 1, ["name"] = "wool:grey"}, {["x"] = 15, ["meta"] = {["fields"] = {}, ["inventory"] = {}}, ["y"] = 12, ["z"] = 14, ["name"] = "wool:grey"}, {["x"] = 15, ["meta"] = {["fields"] = {}, ["inventory"] = {}}, ["y"] = 12, ["z"] = 15, ["name"] = "wool:grey"}, {["x"] = 15, ["meta"] = {["fields"] = {}, ["inventory"] = {}}, ["y"] = 13, ["z"] = 0, ["name"] = "wool:grey"}, {["x"] = 15, ["meta"] = {["fields"] = {}, ["inventory"] = {}}, ["y"] = 13, ["z"] = 1, ["name"] = "wool:grey"}, {["x"] = 15, ["meta"] = {["fields"] = {}, ["inventory"] = {}}, ["y"] = 13, ["z"] = 14, ["name"] = "wool:grey"}, {["x"] = 15, ["meta"] = {["fields"] = {}, ["inventory"] = {}}, ["y"] = 13, ["z"] = 15, ["name"] = "wool:grey"}, {["x"] = 15, ["meta"] = {["fields"] = {}, ["inventory"] = {}}, ["y"] = 14, ["z"] = 0, ["name"] = "wool:grey"}, {["x"] = 15, ["meta"] = {["fields"] = {}, ["inventory"] = {}}, ["y"] = 14, ["z"] = 1, ["name"] = "wool:grey"}, {["x"] = 15, ["meta"] = {["fields"] = {}, ["inventory"] = {}}, ["y"] = 14, ["z"] = 14, ["name"] = "wool:grey"}, {["x"] = 15, ["meta"] = {["fields"] = {}, ["inventory"] = {}}, ["y"] = 14, ["z"] = 15, ["name"] = "wool:grey"}, {["x"] = 15, ["meta"] = {["fields"] = {}, ["inventory"] = {}}, ["y"] = 15, ["z"] = 0, ["name"] = "wool:grey"}, {["x"] = 15, ["meta"] = {["fields"] = {}, ["inventory"] = {}}, ["y"] = 15, ["z"] = 1, ["name"] = "wool:grey"}, {["x"] = 15, ["meta"] = {["fields"] = {}, ["inventory"] = {}}, ["y"] = 15, ["z"] = 14, ["name"] = "wool:grey"}, {["x"] = 15, ["meta"] = {["fields"] = {}, ["inventory"] = {}}, ["y"] = 15, ["z"] = 15, ["name"] = "wool:grey"}}