5:return {{["x"] = 0, ["y"] = 0, ["param1"] = 86, ["z"] = 0, ["name"] = "wool:grey"}, {["x"] = 0, ["y"] = 0, ["param1"] = 86, ["z"] = 1, ["name"] = "wool:grey"}, {["x"] = 0, ["y"] = 0, ["param1"] = 86, ["z"] = 14, ["name"] = "wool:grey"}, {["x"] = 0, ["y"] = 0, ["param1"] = 86, ["z"] = 15, ["name"] = "wool:grey"}, {["x"] = 0, ["y"] = 1, ["param1"] = 86, ["z"] = 0, ["name"] = "wool:grey"}, {["x"] = 0, ["y"] = 1, ["param1"] = 86, ["z"] = 1, ["name"] = "wool:grey"}, {["x"] = 0, ["y"] = 1, ["param1"] = 86, ["z"] = 14, ["name"] = "wool:grey"}, {["x"] = 0, ["y"] = 1, ["param1"] = 86, ["z"] = 15, ["name"] = "wool:grey"}, {["x"] = 0, ["y"] = 2, ["param1"] = 86, ["z"] = 0, ["name"] = "wool:grey"}, {["x"] = 0, ["y"] = 2, ["param1"] = 86, ["z"] = 1, ["name"] = "wool:grey"}, {["x"] = 0, ["y"] = 2, ["param1"] = 86, ["z"] = 14, ["name"] = "wool:grey"}, {["x"] = 0, ["y"] = 2, ["param1"] = 86, ["z"] = 15, ["name"] = "wool:grey"}, {["x"] = 0, ["y"] = 3, ["param1"] = 86, ["z"] = 0, ["name"] = "wool:grey"}, {["x"] = 0, ["y"] = 3, ["param1"] = 86, ["z"] = 1, ["name"] = "wool:grey"}, {["x"] = 0, ["y"] = 3, ["param1"] = 86, ["z"] = 14, ["name"] = "wool:grey"}, {["x"] = 0, ["y"] = 3, ["param1"] = 86, ["z"] = 15, ["name"] = "wool:grey"}, {["x"] = 0, ["y"] = 4, ["param1"] = 86, ["z"] = 0, ["name"] = "wool:grey"}, {["x"] = 0, ["y"] = 4, ["param1"] = 86, ["z"] = 1, ["name"] = "wool:grey"}, {["x"] = 0, ["y"] = 4, ["param1"] = 86, ["z"] = 14, ["name"] = "wool:grey"}, {["x"] = 0, ["y"] = 4, ["param1"] = 86, ["z"] = 15, ["name"] = "wool:grey"}, {["x"] = 0, ["y"] = 5, ["param1"] = 86, ["z"] = 0, ["name"] = "wool:grey"}, {["x"] = 0, ["y"] = 5, ["param1"] = 86, ["z"] = 1, ["name"] = "wool:grey"}, {["x"] = 0, ["y"] = 5, ["param1"] = 86, ["z"] = 14, ["name"] = "wool:grey"}, {["x"] = 0, ["y"] = 5, ["param1"] = 86, ["z"] = 15, ["name"] = "wool:grey"}, {["x"] = 0, ["y"] = 6, ["z"] = 0, ["name"] = "wool:grey"}, {["x"] = 0, ["y"] = 6, ["z"] = 1, ["name"] = "wool:grey"}, {["x"] = 0, ["y"] = 6, ["param1"] = 86, ["z"] = 14, ["name"] = "wool:grey"}, {["x"] = 0, ["y"] = 6, ["param1"] = 86, ["z"] = 15, ["name"] = "wool:grey"}, {["x"] = 0, ["y"] = 7, ["z"] = 0, ["name"] = "wool:grey"}, {["x"] = 0, ["y"] = 7, ["z"] = 1, ["name"] = "wool:grey"}, {["x"] = 0, ["y"] = 7, ["param1"] = 94, ["z"] = 7, ["name"] = "wool:yellow"}, {["x"] = 0, ["y"] = 7, ["param1"] = 94, ["z"] = 8, ["name"] = "wool:yellow"}, {["x"] = 0, ["y"] = 7, ["z"] = 14, ["name"] = "wool:grey"}, {["x"] = 0, ["y"] = 7, ["z"] = 15, ["name"] = "wool:grey"}, {["x"] = 0, ["y"] = 8, ["z"] = 0, ["name"] = "wool:grey"}, {["x"] = 0, ["y"] = 8, ["z"] = 1, ["name"] = "wool:grey"}, {["x"] = 0, ["y"] = 8, ["param1"] = 94, ["z"] = 7, ["name"] = "wool:yellow"}, {["x"] = 0, ["y"] = 8, ["param1"] = 94, ["z"] = 8, ["name"] = "wool:yellow"}, {["x"] = 0, ["y"] = 8, ["z"] = 14, ["name"] = "wool:grey"}, {["x"] = 0, ["y"] = 8, ["z"] = 15, ["name"] = "wool:grey"}, {["x"] = 0, ["y"] = 9, ["z"] = 0, ["name"] = "wool:grey"}, {["x"] = 0, ["y"] = 9, ["z"] = 1, ["name"] = "wool:grey"}, {["x"] = 0, ["y"] = 9, ["z"] = 14, ["name"] = "wool:grey"}, {["x"] = 0, ["y"] = 9, ["z"] = 15, ["name"] = "wool:grey"}, {["x"] = 0, ["y"] = 10, ["z"] = 0, ["name"] = "wool:grey"}, {["x"] = 0, ["y"] = 10, ["z"] = 1, ["name"] = "wool:grey"}, {["x"] = 0, ["y"] = 10, ["z"] = 14, ["name"] = "wool:grey"}, {["x"] = 0, ["y"] = 10, ["z"] = 15, ["name"] = "wool:grey"}, {["x"] = 0, ["y"] = 11, ["z"] = 0, ["name"] = "wool:grey"}, {["x"] = 0, ["y"] = 11, ["z"] = 1, ["name"] = "wool:grey"}, {["x"] = 0, ["y"] = 11, ["z"] = 14, ["name"] = "wool:grey"}, {["x"] = 0, ["y"] = 11, ["z"] = 15, ["name"] = "wool:grey"}, {["x"] = 0, ["y"] = 12, ["z"] = 0, ["name"] = "wool:grey"}, {["x"] = 0, ["y"] = 12, ["z"] = 1, ["name"] = "wool:grey"}, {["x"] = 0, ["y"] = 12, ["z"] = 14, ["name"] = "wool:grey"}, {["x"] = 0, ["y"] = 12, ["z"] = 15, ["name"] = "wool:grey"}, {["x"] = 0, ["y"] = 13, ["z"] = 0, ["name"] = "wool:grey"}, {["x"] = 0, ["y"] = 13, ["z"] = 1, ["name"] = "wool:grey"}, {["x"] = 0, ["y"] = 13, ["z"] = 14, ["name"] = "wool:grey"}, {["x"] = 0, ["y"] = 13, ["z"] = 15, ["name"] = "wool:grey"}, {["x"] = 0, ["y"] = 14, ["z"] = 0, ["name"] = "wool:grey"}, {["x"] = 0, ["y"] = 14, ["z"] = 1, ["name"] = "wool:grey"}, {["x"] = 0, ["y"] = 14, ["z"] = 14, ["name"] = "wool:grey"}, {["x"] = 0, ["y"] = 14, ["z"] = 15, ["name"] = "wool:grey"}, {["x"] = 0, ["y"] = 15, ["z"] = 0, ["name"] = "wool:grey"}, {["x"] = 0, ["y"] = 15, ["z"] = 1, ["name"] = "wool:grey"}, {["x"] = 0, ["y"] = 15, ["z"] = 14, ["name"] = "wool:grey"}, {["x"] = 0, ["y"] = 15, ["z"] = 15, ["name"] = "wool:grey"}, {["x"] = 1, ["y"] = 0, ["param1"] = 86, ["z"] = 0, ["name"] = "wool:grey"}, {["x"] = 1, ["y"] = 0, ["param1"] = 86, ["z"] = 1, ["name"] = "wool:grey"}, {["x"] = 1, ["y"] = 0, ["param1"] = 86, ["z"] = 14, ["name"] = "wool:grey"}, {["x"] = 1, ["y"] = 0, ["param1"] = 86, ["z"] = 15, ["name"] = "wool:grey"}, {["x"] = 1, ["y"] = 1, ["param1"] = 86, ["z"] = 0, ["name"] = "wool:grey"}, {["x"] = 1, ["y"] = 1, ["param1"] = 86, ["z"] = 1, ["name"] = "wool:grey"}, {["x"] = 1, ["y"] = 1, ["param1"] = 86, ["z"] = 14, ["name"] = "wool:grey"}, {["x"] = 1, ["y"] = 1, ["param1"] = 86, ["z"] = 15, ["name"] = "wool:grey"}, {["x"] = 1, ["y"] = 2, ["param1"] = 86, ["z"] = 0, ["name"] = "wool:grey"}, {["x"] = 1, ["y"] = 2, ["param1"] = 86, ["z"] = 1, ["name"] = "wool:grey"}, {["x"] = 1, ["y"] = 2, ["param1"] = 86, ["z"] = 14, ["name"] = "wool:grey"}, {["x"] = 1, ["y"] = 2, ["param1"] = 86, ["z"] = 15, ["name"] = "wool:grey"}, {["x"] = 1, ["y"] = 3, ["param1"] = 86, ["z"] = 0, ["name"] = "wool:grey"}, {["x"] = 1, ["y"] = 3, ["param1"] = 86, ["z"] = 1, ["name"] = "wool:grey"}, {["x"] = 1, ["y"] = 3, ["param1"] = 86, ["z"] = 14, ["name"] = "wool:grey"}, {["x"] = 1, ["y"] = 3, ["param1"] = 86, ["z"] = 15, ["name"] = "wool:grey"}, {["x"] = 1, ["y"] = 4, ["param1"] = 86, ["z"] = 0, ["name"] = "wool:grey"}, {["x"] = 1, ["y"] = 4, ["param1"] = 86, ["z"] = 1, ["name"] = "wool:grey"}, {["x"] = 1, ["y"] = 4, ["param1"] = 86, ["z"] = 14, ["name"] = "wool:grey"}, {["x"] = 1, ["y"] = 4, ["param1"] = 86, ["z"] = 15, ["name"] = "wool:grey"}, {["x"] = 1, ["y"] = 5, ["param1"] = 86, ["z"] = 0, ["name"] = "wool:grey"}, {["x"] = 1, ["y"] = 5, ["param1"] = 86, ["z"] = 1, ["name"] = "wool:grey"}, {["x"] = 1, ["y"] = 5, ["z"] = 2, ["name"] = "wool:grey"}, {["x"] = 1, ["y"] = 5, ["z"] = 3, ["name"] = "wool:grey"}, {["x"] = 1, ["y"] = 5, ["z"] = 4, ["name"] = "wool:grey"}, {["x"] = 1, ["y"] = 5, ["z"] = 5, ["name"] = "wool:grey"}, {["x"] = 1, ["y"] = 5, ["z"] = 6, ["name"] = "wool:grey"}, {["x"] = 1, ["y"] = 5, ["z"] = 7, ["name"] = "wool:grey"}, {["x"] = 1, ["y"] = 5, ["z"] = 8, ["name"] = "wool:grey"}, {["x"] = 1, ["y"] = 5, ["z"] = 9, ["name"] = "wool:grey"}, {["x"] = 1, ["y"] = 5, ["z"] = 10, ["name"] = "wool:grey"}, {["x"] = 1, ["y"] = 5, ["z"] = 11, ["name"] = "wool:grey"}, {["x"] = 1, ["y"] = 5, ["z"] = 12, ["name"] = "wool:grey"}, {["x"] = 1, ["y"] = 5, ["z"] = 13, ["name"] = "wool:grey"}, {["x"] = 1, ["y"] = 5, ["param1"] = 86, ["z"] = 14, ["name"] = "wool:grey"}, {["x"] = 1, ["y"] = 5, ["param1"] = 86, ["z"] = 15, ["name"] = "wool:grey"}, {["x"] = 1, ["y"] = 6, ["z"] = 0, ["name"] = "wool:grey"}, {["x"] = 1, ["y"] = 6, ["z"] = 1, ["name"] = "wool:grey"}, {["x"] = 1, ["y"] = 6, ["z"] = 2, ["name"] = "wool:grey"}, {["x"] = 1, ["y"] = 6, ["z"] = 3, ["name"] = "wool:grey"}, {["x"] = 1, ["y"] = 6, ["z"] = 4, ["name"] = "wool:grey"}, {["x"] = 1, ["y"] = 6, ["z"] = 5, ["name"] = "wool:grey"}, {["x"] = 1, ["y"] = 6, ["z"] = 6, ["name"] = "wool:grey"}, {["x"] = 1, ["y"] = 6, ["z"] = 7, ["name"] = "wool:grey"}, {["x"] = 1, ["y"] = 6, ["z"] = 8, ["name"] = "wool:grey"}, {["x"] = 1, ["y"] = 6, ["z"] = 9, ["name"] = "wool:grey"}, {["x"] = 1, ["y"] = 6, ["z"] = 10, ["name"] = "wool:grey"}, {["x"] = 1, ["y"] = 6, ["z"] = 11, ["name"] = "wool:grey"}, {["x"] = 1, ["y"] = 6, ["z"] = 12, ["name"] = "wool:grey"}, {["x"] = 1, ["y"] = 6, ["z"] = 13, ["name"] = "wool:grey"}, {["x"] = 1, ["y"] = 6, ["param1"] = 86, ["z"] = 14, ["name"] = "wool:grey"}, {["x"] = 1, ["y"] = 6, ["param1"] = 86, ["z"] = 15, ["name"] = "wool:grey"}, {["x"] = 1, ["y"] = 7, ["z"] = 0, ["name"] = "wool:grey"}, {["x"] = 1, ["y"] = 7, ["z"] = 1, ["name"] = "wool:grey"}, {["x"] = 1, ["y"] = 7, ["z"] = 7, ["name"] = "wool:yellow"}, {["x"] = 1, ["y"] = 7, ["z"] = 8, ["name"] = "wool:yellow"}, {["x"] = 1, ["y"] = 7, ["z"] = 14, ["name"] = "wool:grey"}, {["x"] = 1, ["y"] = 7, ["z"] = 15, ["name"] = "wool:grey"}, {["x"] = 1, ["y"] = 8, ["z"] = 0, ["name"] = "wool:grey"}, {["x"] = 1, ["y"] = 8, ["z"] = 1, ["name"] = "wool:grey"}, {["x"] = 1, ["y"] = 8, ["z"] = 7, ["name"] = "wool:yellow"}, {["x"] = 1, ["y"] = 8, ["z"] = 8, ["name"] = "wool:yellow"}, {["x"] = 1, ["y"] = 8, ["z"] = 14, ["name"] = "wool:grey"}, {["x"] = 1, ["y"] = 8, ["z"] = 15, ["name"] = "wool:grey"}, {["x"] = 1, ["y"] = 9, ["z"] = 0, ["name"] = "wool:grey"}, {["x"] = 1, ["y"] = 9, ["z"] = 1, ["name"] = "wool:grey"}, {["x"] = 1, ["y"] = 9, ["z"] = 7, ["name"] = "wool:yellow"}, {["x"] = 1, ["y"] = 9, ["z"] = 14, ["name"] = "wool:grey"}, {["x"] = 1, ["y"] = 9, ["z"] = 15, ["name"] = "wool:grey"}, {["x"] = 1, ["y"] = 10, ["z"] = 0, ["name"] = "wool:grey"}, {["x"] = 1, ["y"] = 10, ["z"] = 1, ["name"] = "wool:grey"}, {["x"] = 1, ["y"] = 10, ["z"] = 7, ["name"] = "wool:yellow"}, {["x"] = 1, ["y"] = 10, ["z"] = 14, ["name"] = "wool:grey"}, {["x"] = 1, ["y"] = 10, ["z"] = 15, ["name"] = "wool:grey"}, {["x"] = 1, ["y"] = 11, ["z"] = 0, ["name"] = "wool:grey"}, {["x"] = 1, ["y"] = 11, ["z"] = 1, ["name"] = "wool:grey"}, {["x"] = 1, ["y"] = 11, ["z"] = 2, ["name"] = "wool:grey"}, {["x"] = 1, ["y"] = 11, ["z"] = 3, ["name"] = "wool:grey"}, {["x"] = 1, ["y"] = 11, ["z"] = 4, ["name"] = "wool:grey"}, {["x"] = 1, ["y"] = 11, ["z"] = 5, ["name"] = "wool:grey"}, {["x"] = 1, ["y"] = 11, ["z"] = 6, ["name"] = "wool:grey"}, {["x"] = 1, ["y"] = 11, ["z"] = 7, ["name"] = "wool:grey"}, {["x"] = 1, ["y"] = 11, ["z"] = 8, ["name"] = "wool:grey"}, {["x"] = 1, ["y"] = 11, ["z"] = 9, ["name"] = "wool:grey"}, {["x"] = 1, ["y"] = 11, ["z"] = 10, ["name"] = "wool:grey"}, {["x"] = 1, ["y"] = 11, ["z"] = 11, ["name"] = "wool:grey"}, {["x"] = 1, ["y"] = 11, ["z"] = 12, ["name"] = "wool:grey"}, {["x"] = 1, ["y"] = 11, ["z"] = 13, ["name"] = "wool:grey"}, {["x"] = 1, ["y"] = 11, ["z"] = 14, ["name"] = "wool:grey"}, {["x"] = 1, ["y"] = 11, ["z"] = 15, ["name"] = "wool:grey"}, {["x"] = 1, ["y"] = 12, ["z"] = 0, ["name"] = "wool:grey"}, {["x"] = 1, ["y"] = 12, ["z"] = 1, ["name"] = "wool:grey"}, {["x"] = 1, ["y"] = 12, ["z"] = 2, ["name"] = "wool:grey"}, {["x"] = 1, ["y"] = 12, ["z"] = 3, ["name"] = "wool:grey"}, {["x"] = 1, ["y"] = 12, ["z"] = 4, ["name"] = "wool:grey"}, {["x"] = 1, ["y"] = 12, ["z"] = 5, ["name"] = "wool:grey"}, {["x"] = 1, ["y"] = 12, ["z"] = 6, ["name"] = "wool:grey"}, {["x"] = 1, ["y"] = 12, ["z"] = 7, ["name"] = "wool:grey"}, {["x"] = 1, ["y"] = 12, ["z"] = 8, ["name"] = "wool:grey"}, {["x"] = 1, ["y"] = 12, ["z"] = 9, ["name"] = "wool:grey"}, {["x"] = 1, ["y"] = 12, ["z"] = 10, ["name"] = "wool:grey"}, {["x"] = 1, ["y"] = 12, ["z"] = 11, ["name"] = "wool:grey"}, {["x"] = 1, ["y"] = 12, ["z"] = 12, ["name"] = "wool:grey"}, {["x"] = 1, ["y"] = 12, ["z"] = 13, ["name"] = "wool:grey"}, {["x"] = 1, ["y"] = 12, ["z"] = 14, ["name"] = "wool:grey"}, {["x"] = 1, ["y"] = 12, ["z"] = 15, ["name"] = "wool:grey"}, {["x"] = 1, ["y"] = 13, ["z"] = 0, ["name"] = "wool:grey"}, {["x"] = 1, ["y"] = 13, ["z"] = 1, ["name"] = "wool:grey"}, {["x"] = 1, ["y"] = 13, ["z"] = 14, ["name"] = "wool:grey"}, {["x"] = 1, ["y"] = 13, ["z"] = 15, ["name"] = "wool:grey"}, {["x"] = 1, ["y"] = 14, ["z"] = 0, ["name"] = "wool:grey"}, {["x"] = 1, ["y"] = 14, ["z"] = 1, ["name"] = "wool:grey"}, {["x"] = 1, ["y"] = 14, ["z"] = 14, ["name"] = "wool:grey"}, {["x"] = 1, ["y"] = 14, ["z"] = 15, ["name"] = "wool:grey"}, {["x"] = 1, ["y"] = 15, ["z"] = 0, ["name"] = "wool:grey"}, {["x"] = 1, ["y"] = 15, ["z"] = 1, ["name"] = "wool:grey"}, {["x"] = 1, ["y"] = 15, ["z"] = 14, ["name"] = "wool:grey"}, {["x"] = 1, ["y"] = 15, ["z"] = 15, ["name"] = "wool:grey"}, {["x"] = 2, ["y"] = 5, ["z"] = 1, ["name"] = "wool:grey"}, {["x"] = 2, ["y"] = 5, ["param1"] = 81, ["z"] = 2, ["name"] = "default:steelblock"}, {["x"] = 2, ["y"] = 5, ["param1"] = 81, ["z"] = 3, ["name"] = "default:steelblock"}, {["x"] = 2, ["y"] = 5, ["param1"] = 81, ["z"] = 4, ["name"] = "default:steelblock"}, {["x"] = 2, ["y"] = 5, ["param1"] = 81, ["z"] = 5, ["name"] = "default:steelblock"}, {["x"] = 2, ["y"] = 5, ["param1"] = 81, ["z"] = 6, ["name"] = "default:steelblock"}, {["x"] = 2, ["y"] = 5, ["param1"] = 81, ["z"] = 7, ["name"] = "default:steelblock"}, {["x"] = 2, ["y"] = 5, ["param1"] = 81, ["z"] = 8, ["name"] = "default:steelblock"}, {["x"] = 2, ["y"] = 5, ["param1"] = 81, ["z"] = 9, ["name"] = "default:steelblock"}, {["x"] = 2, ["y"] = 5, ["param1"] = 81, ["z"] = 10, ["name"] = "default:steelblock"}, {["x"] = 2, ["y"] = 5, ["param1"] = 81, ["z"] = 11, ["name"] = "default:steelblock"}, {["x"] = 2, ["y"] = 5, ["param1"] = 81, ["z"] = 12, ["name"] = "default:steelblock"}, {["x"] = 2, ["y"] = 5, ["param1"] = 81, ["z"] = 13, ["name"] = "default:steelblock"}, {["x"] = 2, ["y"] = 5, ["z"] = 14, ["name"] = "wool:grey"}, {["x"] = 2, ["y"] = 6, ["z"] = 1, ["name"] = "wool:grey"}, {["x"] = 2, ["y"] = 6, ["param1"] = 81, ["z"] = 2, ["name"] = "default:steelblock"}, {["x"] = 2, ["y"] = 6, ["param1"] = 81, ["z"] = 3, ["name"] = "default:steelblock"}, {["x"] = 2, ["y"] = 6, ["param1"] = 81, ["z"] = 4, ["name"] = "default:steelblock"}, {["x"] = 2, ["y"] = 6, ["param1"] = 81, ["z"] = 5, ["name"] = "default:steelblock"}, {["x"] = 2, ["y"] = 6, ["param1"] = 81, ["z"] = 6, ["name"] = "default:steelblock"}, {["x"] = 2, ["y"] = 6, ["param1"] = 81, ["z"] = 7, ["name"] = "default:steelblock"}, {["x"] = 2, ["y"] = 6, ["param1"] = 81, ["z"] = 8, ["name"] = "default:steelblock"}, {["x"] = 2, ["y"] = 6, ["param1"] = 81, ["z"] = 9, ["name"] = "default:steelblock"}, {["x"] = 2, ["y"] = 6, ["param1"] = 81, ["z"] = 10, ["name"] = "default:steelblock"}, {["x"] = 2, ["y"] = 6, ["param1"] = 81, ["z"] = 11, ["name"] = "default:steelblock"}, {["x"] = 2, ["y"] = 6, ["param1"] = 81, ["z"] = 12, ["name"] = "default:steelblock"}, {["x"] = 2, ["y"] = 6, ["param1"] = 81, ["z"] = 13, ["name"] = "default:steelblock"}, {["x"] = 2, ["y"] = 6, ["z"] = 14, ["name"] = "wool:grey"}, {["x"] = 2, ["y"] = 7, ["param1"] = 81, ["z"] = 2, ["name"] = "default:steelblock"}, {["x"] = 2, ["y"] = 7, ["param1"] = 81, ["z"] = 3, ["name"] = "default:steelblock"}, {["x"] = 2, ["y"] = 7, ["param1"] = 81, ["z"] = 4, ["name"] = "default:steelblock"}, {["x"] = 2, ["y"] = 7, ["param1"] = 81, ["z"] = 5, ["name"] = "default:steelblock"}, {["x"] = 2, ["y"] = 7, ["param1"] = 81, ["z"] = 6, ["name"] = "default:steelblock"}, {["x"] = 2, ["y"] = 7, ["param1"] = 81, ["z"] = 7, ["name"] = "default:steelblock"}, {["x"] = 2, ["y"] = 7, ["param1"] = 81, ["z"] = 8, ["name"] = "default:steelblock"}, {["x"] = 2, ["y"] = 7, ["param1"] = 81, ["z"] = 9, ["name"] = "default:steelblock"}, {["x"] = 2, ["y"] = 7, ["param1"] = 81, ["z"] = 10, ["name"] = "default:steelblock"}, {["x"] = 2, ["y"] = 7, ["param1"] = 81, ["z"] = 11, ["name"] = "default:steelblock"}, {["x"] = 2, ["y"] = 7, ["param1"] = 81, ["z"] = 12, ["name"] = "default:steelblock"}, {["x"] = 2, ["y"] = 7, ["param1"] = 81, ["z"] = 13, ["name"] = "default:steelblock"}, {["x"] = 2, ["y"] = 8, ["param1"] = 81, ["z"] = 2, ["name"] = "default:steelblock"}, {["x"] = 2, ["y"] = 8, ["param1"] = 81, ["z"] = 3, ["name"] = "default:steelblock"}, {["x"] = 2, ["y"] = 8, ["param1"] = 81, ["z"] = 4, ["name"] = "default:steelblock"}, {["x"] = 2, ["y"] = 8, ["param1"] = 81, ["z"] = 5, ["name"] = "default:steelblock"}, {["x"] = 2, ["y"] = 8, ["param1"] = 81, ["z"] = 6, ["name"] = "default:steelblock"}, {["x"] = 2, ["y"] = 8, ["param1"] = 81, ["z"] = 7, ["name"] = "default:steelblock"}, {["x"] = 2, ["y"] = 8, ["param1"] = 81, ["z"] = 8, ["name"] = "default:steelblock"}, {["x"] = 2, ["y"] = 8, ["param1"] = 81, ["z"] = 9, ["name"] = "default:steelblock"}, {["x"] = 2, ["y"] = 8, ["param1"] = 81, ["z"] = 10, ["name"] = "default:steelblock"}, {["x"] = 2, ["y"] = 8, ["param1"] = 81, ["z"] = 11, ["name"] = "default:steelblock"}, {["x"] = 2, ["y"] = 8, ["param1"] = 81, ["z"] = 12, ["name"] = "default:steelblock"}, {["x"] = 2, ["y"] = 8, ["param1"] = 81, ["z"] = 13, ["name"] = "default:steelblock"}, {["x"] = 2, ["y"] = 9, ["param1"] = 81, ["z"] = 2, ["name"] = "default:steelblock"}, {["x"] = 2, ["y"] = 9, ["param1"] = 81, ["z"] = 3, ["name"] = "default:steelblock"}, {["x"] = 2, ["y"] = 9, ["param1"] = 81, ["z"] = 4, ["name"] = "default:steelblock"}, {["x"] = 2, ["y"] = 9, ["param1"] = 81, ["z"] = 5, ["name"] = "default:steelblock"}, {["x"] = 2, ["y"] = 9, ["param1"] = 81, ["z"] = 6, ["name"] = "default:steelblock"}, {["x"] = 2, ["y"] = 9, ["param1"] = 81, ["z"] = 7, ["name"] = "default:steelblock"}, {["x"] = 2, ["y"] = 9, ["param1"] = 81, ["z"] = 8, ["name"] = "default:steelblock"}, {["x"] = 2, ["y"] = 9, ["param1"] = 81, ["z"] = 9, ["name"] = "default:steelblock"}, {["x"] = 2, ["y"] = 9, ["param1"] = 81, ["z"] = 10, ["name"] = "default:steelblock"}, {["x"] = 2, ["y"] = 9, ["param1"] = 81, ["z"] = 11, ["name"] = "default:steelblock"}, {["x"] = 2, ["y"] = 9, ["param1"] = 81, ["z"] = 12, ["name"] = "default:steelblock"}, {["x"] = 2, ["y"] = 9, ["param1"] = 81, ["z"] = 13, ["name"] = "default:steelblock"}, {["x"] = 2, ["y"] = 10, ["z"] = 2, ["name"] = "default:steelblock"}, {["x"] = 2, ["y"] = 10, ["z"] = 3, ["name"] = "default:steelblock"}, {["x"] = 2, ["y"] = 10, ["z"] = 4, ["name"] = "default:steelblock"}, {["x"] = 2, ["y"] = 10, ["z"] = 5, ["name"] = "default:steelblock"}, {["x"] = 2, ["y"] = 10, ["z"] = 6, ["name"] = "default:steelblock"}, {["x"] = 2, ["y"] = 10, ["z"] = 7, ["name"] = "default:steelblock"}, {["x"] = 2, ["y"] = 10, ["z"] = 8, ["name"] = "default:steelblock"}, {["x"] = 2, ["y"] = 10, ["z"] = 9, ["name"] = "default:steelblock"}, {["x"] = 2, ["y"] = 10, ["z"] = 10, ["name"] = "default:steelblock"}, {["x"] = 2, ["y"] = 10, ["z"] = 11, ["name"] = "default:steelblock"}, {["x"] = 2, ["y"] = 10, ["z"] = 12, ["name"] = "default:steelblock"}, {["x"] = 2, ["y"] = 10, ["z"] = 13, ["name"] = "default:steelblock"}, {["x"] = 2, ["y"] = 11, ["z"] = 1, ["name"] = "wool:grey"}, {["x"] = 2, ["y"] = 11, ["z"] = 7, ["name"] = "wool:yellow"}, {["x"] = 2, ["y"] = 11, ["z"] = 14, ["name"] = "wool:grey"}, {["x"] = 2, ["y"] = 12, ["z"] = 1, ["name"] = "wool:grey"}, {["x"] = 2, ["y"] = 12, ["z"] = 14, ["name"] = "wool:grey"}, {["x"] = 3, ["y"] = 4, ["param1"] = 81, ["z"] = 2, ["name"] = "default:steelblock"}, {["x"] = 3, ["y"] = 4, ["param1"] = 81, ["z"] = 3, ["name"] = "default:steelblock"}, {["x"] = 3, ["y"] = 4, ["param1"] = 81, ["z"] = 4, ["name"] = "default:steelblock"}, {["x"] = 3, ["y"] = 4, ["param1"] = 81, ["z"] = 5, ["name"] = "default:steelblock"}, {["x"] = 3, ["y"] = 4, ["param1"] = 81, ["z"] = 6, ["name"] = "default:steelblock"}, {["x"] = 3, ["y"] = 4, ["param1"] = 81, ["z"] = 7, ["name"] = "default:steelblock"}, {["x"] = 3, ["y"] = 4, ["param1"] = 81, ["z"] = 8, ["name"] = "default:steelblock"}, {["x"] = 3, ["y"] = 4, ["param1"] = 81, ["z"] = 9, ["name"] = "default:steelblock"}, {["x"] = 3, ["y"] = 4, ["param1"] = 81, ["z"] = 10, ["name"] = "default:steelblock"}, {["x"] = 3, ["y"] = 4, ["param1"] = 81, ["z"] = 11, ["name"] = "default:steelblock"}, {["x"] = 3, ["y"] = 4, ["param1"] = 81, ["z"] = 12, ["name"] = "default:steelblock"}, {["x"] = 3, ["y"] = 4, ["param1"] = 81, ["z"] = 13, ["name"] = "default:steelblock"}, {["x"] = 3, ["y"] = 5, ["z"] = 1, ["name"] = "wool:grey"}, {["x"] = 3, ["y"] = 5, ["param1"] = 81, ["z"] = 2, ["name"] = "default:steelblock"}, {["x"] = 3, ["y"] = 5, ["param1"] = 81, ["z"] = 3, ["name"] = "default:steelblock"}, {["x"] = 3, ["y"] = 5, ["param1"] = 81, ["z"] = 4, ["name"] = "default:steelblock"}, {["x"] = 3, ["y"] = 5, ["param1"] = 81, ["z"] = 5, ["name"] = "default:steelblock"}, {["x"] = 3, ["y"] = 5, ["param1"] = 81, ["z"] = 6, ["name"] = "default:steelblock"}, {["x"] = 3, ["y"] = 5, ["param1"] = 81, ["z"] = 7, ["name"] = "default:steelblock"}, {["x"] = 3, ["y"] = 5, ["param1"] = 81, ["z"] = 8, ["name"] = "default:steelblock"}, {["x"] = 3, ["y"] = 5, ["param1"] = 81, ["z"] = 9, ["name"] = "default:steelblock"}, {["x"] = 3, ["y"] = 5, ["param1"] = 81, ["z"] = 10, ["name"] = "default:steelblock"}, {["x"] = 3, ["y"] = 5, ["param1"] = 81, ["z"] = 11, ["name"] = "default:steelblock"}, {["x"] = 3, ["y"] = 5, ["param1"] = 81, ["z"] = 12, ["name"] = "default:steelblock"}, {["x"] = 3, ["y"] = 5, ["param1"] = 81, ["z"] = 13, ["name"] = "default:steelblock"}, {["x"] = 3, ["y"] = 5, ["z"] = 14, ["name"] = "wool:grey"}, {["x"] = 3, ["y"] = 6, ["z"] = 1, ["name"] = "wool:grey"}, {["x"] = 3, ["y"] = 6, ["param1"] = 81, ["z"] = 2, ["name"] = "default:steelblock"}, {["x"] = 3, ["y"] = 6, ["param1"] = 81, ["z"] = 3, ["name"] = "default:steelblock"}, {["x"] = 3, ["y"] = 6, ["param1"] = 81, ["z"] = 4, ["name"] = "default:steelblock"}, {["x"] = 3, ["y"] = 6, ["param1"] = 81, ["z"] = 5, ["name"] = "default:steelblock"}, {["x"] = 3, ["y"] = 6, ["param1"] = 81, ["z"] = 6, ["name"] = "default:steelblock"}, {["x"] = 3, ["y"] = 6, ["param1"] = 81, ["z"] = 7, ["name"] = "default:steelblock"}, {["x"] = 3, ["y"] = 6, ["param1"] = 81, ["z"] = 8, ["name"] = "default:steelblock"}, {["x"] = 3, ["y"] = 6, ["param1"] = 81, ["z"] = 9, ["name"] = "default:steelblock"}, {["x"] = 3, ["y"] = 6, ["param1"] = 81, ["z"] = 10, ["name"] = "default:steelblock"}, {["x"] = 3, ["y"] = 6, ["param1"] = 81, ["z"] = 11, ["name"] = "default:steelblock"}, {["x"] = 3, ["y"] = 6, ["param1"] = 81, ["z"] = 12, ["name"] = "default:steelblock"}, {["x"] = 3, ["y"] = 6, ["param1"] = 81, ["z"] = 13, ["name"] = "default:steelblock"}, {["x"] = 3, ["y"] = 6, ["z"] = 14, ["name"] = "wool:grey"}, {["x"] = 3, ["y"] = 7, ["param1"] = 81, ["z"] = 2, ["name"] = "default:steelblock"}, {["x"] = 3, ["y"] = 7, ["param1"] = 81, ["z"] = 3, ["name"] = "default:steelblock"}, {["x"] = 3, ["y"] = 7, ["param1"] = 81, ["z"] = 4, ["name"] = "default:steelblock"}, {["x"] = 3, ["y"] = 7, ["param1"] = 81, ["z"] = 5, ["name"] = "default:steelblock"}, {["x"] = 3, ["y"] = 7, ["param1"] = 81, ["z"] = 6, ["name"] = "default:steelblock"}, {["x"] = 3, ["y"] = 7, ["param1"] = 81, ["z"] = 7, ["name"] = "default:steelblock"}, {["x"] = 3, ["y"] = 7, ["param1"] = 81, ["z"] = 8, ["name"] = "default:steelblock"}, {["x"] = 3, ["y"] = 7, ["param1"] = 81, ["z"] = 9, ["name"] = "default:steelblock"}, {["x"] = 3, ["y"] = 7, ["param1"] = 81, ["z"] = 10, ["name"] = "default:steelblock"}, {["x"] = 3, ["y"] = 7, ["param1"] = 81, ["z"] = 11, ["name"] = "default:steelblock"}, {["x"] = 3, ["y"] = 7, ["param1"] = 81, ["z"] = 12, ["name"] = "default:steelblock"}, {["x"] = 3, ["y"] = 7, ["param1"] = 81, ["z"] = 13, ["name"] = "default:steelblock"}, {["x"] = 3, ["y"] = 8, ["param1"] = 81, ["z"] = 2, ["name"] = "default:steelblock"}, {["x"] = 3, ["y"] = 8, ["param1"] = 81, ["z"] = 3, ["name"] = "default:steelblock"}, {["x"] = 3, ["y"] = 8, ["param1"] = 81, ["z"] = 4, ["name"] = "default:steelblock"}, {["x"] = 3, ["y"] = 8, ["param1"] = 81, ["z"] = 5, ["name"] = "default:steelblock"}, {["x"] = 3, ["y"] = 8, ["param1"] = 81, ["z"] = 6, ["name"] = "default:steelblock"}, {["x"] = 3, ["y"] = 8, ["param1"] = 81, ["z"] = 7, ["name"] = "default:steelblock"}, {["x"] = 3, ["y"] = 8, ["param1"] = 81, ["z"] = 8, ["name"] = "default:steelblock"}, {["x"] = 3, ["y"] = 8, ["param1"] = 81, ["z"] = 9, ["name"] = "default:steelblock"}, {["x"] = 3, ["y"] = 8, ["param1"] = 81, ["z"] = 10, ["name"] = "default:steelblock"}, {["x"] = 3, ["y"] = 8, ["param1"] = 81, ["z"] = 11, ["name"] = "default:steelblock"}, {["x"] = 3, ["y"] = 8, ["param1"] = 81, ["z"] = 12, ["name"] = "default:steelblock"}, {["x"] = 3, ["y"] = 8, ["param1"] = 81, ["z"] = 13, ["name"] = "default:steelblock"}, {["x"] = 3, ["y"] = 9, ["param1"] = 81, ["z"] = 2, ["name"] = "default:steelblock"}, {["x"] = 3, ["y"] = 9, ["param1"] = 81, ["z"] = 3, ["name"] = "default:steelblock"}, {["x"] = 3, ["y"] = 9, ["param1"] = 81, ["z"] = 4, ["name"] = "default:steelblock"}, {["x"] = 3, ["y"] = 9, ["param1"] = 81, ["z"] = 5, ["name"] = "default:steelblock"}, {["x"] = 3, ["y"] = 9, ["param1"] = 81, ["z"] = 6, ["name"] = "default:steelblock"}, {["x"] = 3, ["y"] = 9, ["param1"] = 81, ["z"] = 7, ["name"] = "default:steelblock"}, {["x"] = 3, ["y"] = 9, ["param1"] = 81, ["z"] = 8, ["name"] = "default:steelblock"}, {["x"] = 3, ["y"] = 9, ["param1"] = 81, ["z"] = 9, ["name"] = "default:steelblock"}, {["x"] = 3, ["y"] = 9, ["param1"] = 81, ["z"] = 10, ["name"] = "default:steelblock"}, {["x"] = 3, ["y"] = 9, ["param1"] = 81, ["z"] = 11, ["name"] = "default:steelblock"}, {["x"] = 3, ["y"] = 9, ["param1"] = 81, ["z"] = 12, ["name"] = "default:steelblock"}, {["x"] = 3, ["y"] = 9, ["param1"] = 81, ["z"] = 13, ["name"] = "default:steelblock"}, {["x"] = 3, ["y"] = 10, ["param1"] = 81, ["z"] = 2, ["name"] = "default:steelblock"}, {["x"] = 3, ["y"] = 10, ["param1"] = 81, ["z"] = 3, ["name"] = "default:steelblock"}, {["x"] = 3, ["y"] = 10, ["param1"] = 81, ["z"] = 4, ["name"] = "default:steelblock"}, {["x"] = 3, ["y"] = 10, ["param1"] = 81, ["z"] = 5, ["name"] = "default:steelblock"}, {["x"] = 3, ["y"] = 10, ["param1"] = 81, ["z"] = 6, ["name"] = "default:steelblock"}, {["x"] = 3, ["y"] = 10, ["param1"] = 81, ["z"] = 7, ["name"] = "default:steelblock"}, {["x"] = 3, ["y"] = 10, ["param1"] = 81, ["z"] = 8, ["name"] = "default:steelblock"}, {["x"] = 3, ["y"] = 10, ["param1"] = 81, ["z"] = 9, ["name"] = "default:steelblock"}, {["x"] = 3, ["y"] = 10, ["param1"] = 81, ["z"] = 10, ["name"] = "default:steelblock"}, {["x"] = 3, ["y"] = 10, ["param1"] = 81, ["z"] = 11, ["name"] = "default:steelblock"}, {["x"] = 3, ["y"] = 10, ["param1"] = 81, ["z"] = 12, ["name"] = "default:steelblock"}, {["x"] = 3, ["y"] = 10, ["param1"] = 81, ["z"] = 13, ["name"] = "default:steelblock"}, {["x"] = 3, ["y"] = 11, ["z"] = 1, ["name"] = "wool:grey"}, {["x"] = 3, ["y"] = 11, ["z"] = 2, ["name"] = "default:steelblock"}, {["x"] = 3, ["y"] = 11, ["z"] = 3, ["name"] = "default:steelblock"}, {["x"] = 3, ["y"] = 11, ["z"] = 4, ["name"] = "default:steelblock"}, {["x"] = 3, ["y"] = 11, ["z"] = 5, ["name"] = "default:steelblock"}, {["x"] = 3, ["y"] = 11, ["z"] = 6, ["name"] = "default:steelblock"}, {["x"] = 3, ["y"] = 11, ["z"] = 7, ["name"] = "default:steelblock"}, {["x"] = 3, ["y"] = 11, ["z"] = 8, ["name"] = "default:steelblock"}, {["x"] = 3, ["y"] = 11, ["z"] = 9, ["name"] = "default:steelblock"}, {["x"] = 3, ["y"] = 11, ["z"] = 10, ["name"] = "default:steelblock"}, {["x"] = 3, ["y"] = 11, ["z"] = 11, ["name"] = "default:steelblock"}, {["x"] = 3, ["y"] = 11, ["z"] = 12, ["name"] = "default:steelblock"}, {["x"] = 3, ["y"] = 11, ["z"] = 13, ["name"] = "default:steelblock"}, {["x"] = 3, ["y"] = 11, ["z"] = 14, ["name"] = "wool:grey"}, {["x"] = 3, ["y"] = 12, ["z"] = 1, ["name"] = "wool:grey"}, {["x"] = 3, ["y"] = 12, ["z"] = 3, ["name"] = "default:steelblock"}, {["x"] = 3, ["y"] = 12, ["z"] = 4, ["name"] = "default:steelblock"}, {["x"] = 3, ["y"] = 12, ["z"] = 5, ["name"] = "default:steelblock"}, {["x"] = 3, ["y"] = 12, ["z"] = 6, ["name"] = "default:steelblock"}, {["x"] = 3, ["y"] = 12, ["z"] = 7, ["name"] = "wool:yellow"}, {["x"] = 3, ["y"] = 12, ["z"] = 14, ["name"] = "wool:grey"}, {["x"] = 3, ["y"] = 13, ["z"] = 3, ["name"] = "default:steelblock"}, {["x"] = 3, ["y"] = 13, ["z"] = 4, ["name"] = "default:steelblock"}, {["x"] = 3, ["y"] = 13, ["z"] = 5, ["name"] = "default:steelblock"}, {["x"] = 3, ["y"] = 13, ["z"] = 6, ["name"] = "default:steelblock"}, {["x"] = 3, ["y"] = 14, ["z"] = 3, ["name"] = "default:steelblock"}, {["x"] = 3, ["y"] = 14, ["z"] = 4, ["name"] = "default:steelblock"}, {["x"] = 3, ["y"] = 14, ["z"] = 5, ["name"] = "default:steelblock"}, {["x"] = 3, ["y"] = 14, ["z"] = 6, ["name"] = "default:steelblock"}, {["x"] = 3, ["y"] = 15, ["z"] = 3, ["name"] = "default:steelblock"}, {["x"] = 3, ["y"] = 15, ["z"] = 4, ["name"] = "default:steelblock"}, {["x"] = 3, ["y"] = 15, ["z"] = 5, ["name"] = "default:steelblock"}, {["x"] = 3, ["y"] = 15, ["z"] = 6, ["name"] = "default:steelblock"}, {["x"] = 4, ["y"] = 3, ["param1"] = 81, ["z"] = 2, ["name"] = "default:steelblock"}, {["x"] = 4, ["y"] = 3, ["param1"] = 81, ["z"] = 3, ["name"] = "default:steelblock"}, {["x"] = 4, ["y"] = 3, ["param1"] = 81, ["z"] = 4, ["name"] = "default:steelblock"}, {["x"] = 4, ["y"] = 3, ["param1"] = 81, ["z"] = 5, ["name"] = "default:steelblock"}, {["x"] = 4, ["y"] = 3, ["param1"] = 81, ["z"] = 6, ["name"] = "default:steelblock"}, {["x"] = 4, ["y"] = 3, ["param1"] = 81, ["z"] = 7, ["name"] = "default:steelblock"}, {["x"] = 4, ["y"] = 3, ["param1"] = 81, ["z"] = 8, ["name"] = "default:steelblock"}, {["x"] = 4, ["y"] = 3, ["param1"] = 81, ["z"] = 9, ["name"] = "default:steelblock"}, {["x"] = 4, ["y"] = 3, ["param1"] = 81, ["z"] = 10, ["name"] = "default:steelblock"}, {["x"] = 4, ["y"] = 3, ["param1"] = 81, ["z"] = 11, ["name"] = "default:steelblock"}, {["x"] = 4, ["y"] = 3, ["param1"] = 81, ["z"] = 12, ["name"] = "default:steelblock"}, {["x"] = 4, ["y"] = 3, ["param1"] = 81, ["z"] = 13, ["name"] = "default:steelblock"}, {["x"] = 4, ["y"] = 4, ["param1"] = 81, ["z"] = 2, ["name"] = "default:steelblock"}, {["x"] = 4, ["y"] = 4, ["param1"] = 81, ["z"] = 3, ["name"] = "default:steelblock"}, {["x"] = 4, ["y"] = 4, ["param1"] = 81, ["z"] = 4, ["name"] = "default:steelblock"}, {["x"] = 4, ["y"] = 4, ["param1"] = 81, ["z"] = 5, ["name"] = "default:steelblock"}, {["x"] = 4, ["y"] = 4, ["param1"] = 81, ["z"] = 6, ["name"] = "default:steelblock"}, {["x"] = 4, ["y"] = 4, ["param1"] = 81, ["z"] = 7, ["name"] = "default:steelblock"}, {["x"] = 4, ["y"] = 4, ["param1"] = 81, ["z"] = 8, ["name"] = "default:steelblock"}, {["x"] = 4, ["y"] = 4, ["param1"] = 81, ["z"] = 9, ["name"] = "default:steelblock"}, {["x"] = 4, ["y"] = 4, ["param1"] = 81, ["z"] = 10, ["name"] = "default:steelblock"}, {["x"] = 4, ["y"] = 4, ["param1"] = 81, ["z"] = 11, ["name"] = "default:steelblock"}, {["x"] = 4, ["y"] = 4, ["param1"] = 81, ["z"] = 12, ["name"] = "default:steelblock"}, {["x"] = 4, ["y"] = 4, ["param1"] = 81, ["z"] = 13, ["name"] = "default:steelblock"}, {["x"] = 4, ["y"] = 5, ["z"] = 1, ["name"] = "wool:grey"}, {["x"] = 4, ["y"] = 5, ["param1"] = 81, ["z"] = 2, ["name"] = "default:steelblock"}, {["x"] = 4, ["y"] = 5, ["param1"] = 81, ["z"] = 3, ["name"] = "default:steelblock"}, {["x"] = 4, ["y"] = 5, ["param1"] = 81, ["z"] = 4, ["name"] = "default:steelblock"}, {["x"] = 4, ["y"] = 5, ["param1"] = 81, ["z"] = 5, ["name"] = "default:steelblock"}, {["x"] = 4, ["y"] = 5, ["param1"] = 81, ["z"] = 6, ["name"] = "default:steelblock"}, {["x"] = 4, ["y"] = 5, ["param1"] = 81, ["z"] = 7, ["name"] = "default:steelblock"}, {["x"] = 4, ["y"] = 5, ["param1"] = 81, ["z"] = 8, ["name"] = "default:steelblock"}, {["x"] = 4, ["y"] = 5, ["param1"] = 81, ["z"] = 9, ["name"] = "default:steelblock"}, {["x"] = 4, ["y"] = 5, ["param1"] = 81, ["z"] = 10, ["name"] = "default:steelblock"}, {["x"] = 4, ["y"] = 5, ["param1"] = 81, ["z"] = 11, ["name"] = "default:steelblock"}, {["x"] = 4, ["y"] = 5, ["param1"] = 81, ["z"] = 12, ["name"] = "default:steelblock"}, {["x"] = 4, ["y"] = 5, ["param1"] = 81, ["z"] = 13, ["name"] = "default:steelblock"}, {["x"] = 4, ["y"] = 5, ["z"] = 14, ["name"] = "wool:grey"}, {["x"] = 4, ["y"] = 6, ["z"] = 1, ["name"] = "wool:grey"}, {["x"] = 4, ["y"] = 6, ["param1"] = 81, ["z"] = 2, ["name"] = "default:steelblock"}, {["x"] = 4, ["y"] = 6, ["param1"] = 81, ["z"] = 3, ["name"] = "default:steelblock"}, {["x"] = 4, ["y"] = 6, ["param1"] = 81, ["z"] = 4, ["name"] = "default:steelblock"}, {["x"] = 4, ["y"] = 6, ["param1"] = 81, ["z"] = 5, ["name"] = "default:steelblock"}, {["x"] = 4, ["y"] = 6, ["param1"] = 81, ["z"] = 6, ["name"] = "default:steelblock"}, {["x"] = 4, ["y"] = 6, ["param1"] = 81, ["z"] = 7, ["name"] = "default:steelblock"}, {["x"] = 4, ["y"] = 6, ["param1"] = 81, ["z"] = 8, ["name"] = "default:steelblock"}, {["x"] = 4, ["y"] = 6, ["param1"] = 81, ["z"] = 9, ["name"] = "default:steelblock"}, {["x"] = 4, ["y"] = 6, ["param1"] = 81, ["z"] = 10, ["name"] = "default:steelblock"}, {["x"] = 4, ["y"] = 6, ["param1"] = 81, ["z"] = 11, ["name"] = "default:steelblock"}, {["x"] = 4, ["y"] = 6, ["param1"] = 81, ["z"] = 12, ["name"] = "default:steelblock"}, {["x"] = 4, ["y"] = 6, ["param1"] = 81, ["z"] = 13, ["name"] = "default:steelblock"}, {["x"] = 4, ["y"] = 6, ["z"] = 14, ["name"] = "wool:grey"}, {["x"] = 4, ["y"] = 7, ["param1"] = 81, ["z"] = 2, ["name"] = "default:steelblock"}, {["x"] = 4, ["y"] = 7, ["param1"] = 81, ["z"] = 3, ["name"] = "default:steelblock"}, {["x"] = 4, ["y"] = 7, ["param1"] = 81, ["z"] = 4, ["name"] = "default:steelblock"}, {["x"] = 4, ["y"] = 7, ["param1"] = 81, ["z"] = 5, ["name"] = "default:steelblock"}, {["x"] = 4, ["y"] = 7, ["param1"] = 81, ["z"] = 6, ["name"] = "default:steelblock"}, {["x"] = 4, ["y"] = 7, ["param1"] = 81, ["z"] = 7, ["name"] = "default:steelblock"}, {["x"] = 4, ["y"] = 7, ["param1"] = 81, ["z"] = 8, ["name"] = "default:steelblock"}, {["x"] = 4, ["y"] = 7, ["param1"] = 81, ["z"] = 9, ["name"] = "default:steelblock"}, {["x"] = 4, ["y"] = 7, ["param1"] = 81, ["z"] = 10, ["name"] = "default:steelblock"}, {["x"] = 4, ["y"] = 7, ["param1"] = 81, ["z"] = 11, ["name"] = "default:steelblock"}, {["x"] = 4, ["y"] = 7, ["param1"] = 81, ["z"] = 12, ["name"] = "default:steelblock"}, {["x"] = 4, ["y"] = 7, ["param1"] = 81, ["z"] = 13, ["name"] = "default:steelblock"}, {["x"] = 4, ["y"] = 8, ["param1"] = 81, ["z"] = 2, ["name"] = "default:steelblock"}, {["x"] = 4, ["y"] = 8, ["param1"] = 81, ["z"] = 3, ["name"] = "default:steelblock"}, {["x"] = 4, ["y"] = 8, ["param1"] = 81, ["z"] = 4, ["name"] = "default:steelblock"}, {["x"] = 4, ["y"] = 8, ["param1"] = 81, ["z"] = 5, ["name"] = "default:steelblock"}, {["x"] = 4, ["y"] = 8, ["param1"] = 81, ["z"] = 6, ["name"] = "default:steelblock"}, {["x"] = 4, ["y"] = 8, ["param1"] = 81, ["z"] = 7, ["name"] = "default:steelblock"}, {["x"] = 4, ["y"] = 8, ["param1"] = 81, ["z"] = 8, ["name"] = "default:steelblock"}, {["x"] = 4, ["y"] = 8, ["param1"] = 81, ["z"] = 9, ["name"] = "default:steelblock"}, {["x"] = 4, ["y"] = 8, ["param1"] = 81, ["z"] = 10, ["name"] = "default:steelblock"}, {["x"] = 4, ["y"] = 8, ["param1"] = 81, ["z"] = 11, ["name"] = "default:steelblock"}, {["x"] = 4, ["y"] = 8, ["param1"] = 81, ["z"] = 12, ["name"] = "default:steelblock"}, {["x"] = 4, ["y"] = 8, ["param1"] = 81, ["z"] = 13, ["name"] = "default:steelblock"}, {["x"] = 4, ["y"] = 9, ["param1"] = 81, ["z"] = 2, ["name"] = "default:steelblock"}, {["x"] = 4, ["y"] = 9, ["param1"] = 81, ["z"] = 3, ["name"] = "default:steelblock"}, {["x"] = 4, ["y"] = 9, ["param1"] = 81, ["z"] = 4, ["name"] = "default:steelblock"}, {["x"] = 4, ["y"] = 9, ["param1"] = 81, ["z"] = 5, ["name"] = "default:steelblock"}, {["x"] = 4, ["y"] = 9, ["param1"] = 81, ["z"] = 6, ["name"] = "default:steelblock"}, {["x"] = 4, ["y"] = 9, ["param1"] = 81, ["z"] = 7, ["name"] = "default:steelblock"}, {["x"] = 4, ["y"] = 9, ["param1"] = 81, ["z"] = 8, ["name"] = "default:steelblock"}, {["x"] = 4, ["y"] = 9, ["param1"] = 81, ["z"] = 9, ["name"] = "default:steelblock"}, {["x"] = 4, ["y"] = 9, ["param1"] = 81, ["z"] = 10, ["name"] = "default:steelblock"}, {["x"] = 4, ["y"] = 9, ["param1"] = 81, ["z"] = 11, ["name"] = "default:steelblock"}, {["x"] = 4, ["y"] = 9, ["param1"] = 81, ["z"] = 12, ["name"] = "default:steelblock"}, {["x"] = 4, ["y"] = 9, ["param1"] = 81, ["z"] = 13, ["name"] = "default:steelblock"}, {["x"] = 4, ["y"] = 10, ["param1"] = 81, ["z"] = 2, ["name"] = "default:steelblock"}, {["x"] = 4, ["y"] = 10, ["param1"] = 81, ["z"] = 3, ["name"] = "default:steelblock"}, {["x"] = 4, ["y"] = 10, ["param1"] = 81, ["z"] = 4, ["name"] = "default:steelblock"}, {["x"] = 4, ["y"] = 10, ["param1"] = 81, ["z"] = 5, ["name"] = "default:steelblock"}, {["x"] = 4, ["y"] = 10, ["param1"] = 81, ["z"] = 6, ["name"] = "default:steelblock"}, {["x"] = 4, ["y"] = 10, ["param1"] = 81, ["z"] = 7, ["name"] = "default:steelblock"}, {["x"] = 4, ["y"] = 10, ["param1"] = 81, ["z"] = 8, ["name"] = "default:steelblock"}, {["x"] = 4, ["y"] = 10, ["param1"] = 81, ["z"] = 9, ["name"] = "default:steelblock"}, {["x"] = 4, ["y"] = 10, ["param1"] = 81, ["z"] = 10, ["name"] = "default:steelblock"}, {["x"] = 4, ["y"] = 10, ["param1"] = 81, ["z"] = 11, ["name"] = "default:steelblock"}, {["x"] = 4, ["y"] = 10, ["param1"] = 81, ["z"] = 12, ["name"] = "default:steelblock"}, {["x"] = 4, ["y"] = 10, ["param1"] = 81, ["z"] = 13, ["name"] = "default:steelblock"}, {["x"] = 4, ["y"] = 11, ["z"] = 1, ["name"] = "wool:grey"}, {["x"] = 4, ["y"] = 11, ["param1"] = 81, ["z"] = 2, ["name"] = "default:steelblock"}, {["x"] = 4, ["y"] = 11, ["param1"] = 81, ["z"] = 3, ["name"] = "default:steelblock"}, {["x"] = 4, ["y"] = 11, ["param1"] = 81, ["z"] = 4, ["name"] = "default:steelblock"}, {["x"] = 4, ["y"] = 11, ["param1"] = 81, ["z"] = 5, ["name"] = "default:steelblock"}, {["x"] = 4, ["y"] = 11, ["param1"] = 81, ["z"] = 6, ["name"] = "default:steelblock"}, {["x"] = 4, ["y"] = 11, ["param1"] = 81, ["z"] = 7, ["name"] = "default:steelblock"}, {["x"] = 4, ["y"] = 11, ["param1"] = 81, ["z"] = 8, ["name"] = "default:steelblock"}, {["x"] = 4, ["y"] = 11, ["param1"] = 81, ["z"] = 9, ["name"] = "default:steelblock"}, {["x"] = 4, ["y"] = 11, ["param1"] = 81, ["z"] = 10, ["name"] = "default:steelblock"}, {["x"] = 4, ["y"] = 11, ["param1"] = 81, ["z"] = 11, ["name"] = "default:steelblock"}, {["x"] = 4, ["y"] = 11, ["param1"] = 81, ["z"] = 12, ["name"] = "default:steelblock"}, {["x"] = 4, ["y"] = 11, ["param1"] = 81, ["z"] = 13, ["name"] = "default:steelblock"}, {["x"] = 4, ["y"] = 11, ["z"] = 14, ["name"] = "wool:grey"}, {["x"] = 4, ["y"] = 12, ["z"] = 1, ["name"] = "wool:grey"}, {["x"] = 4, ["y"] = 12, ["z"] = 2, ["name"] = "default:steelblock"}, {["x"] = 4, ["y"] = 12, ["z"] = 3, ["name"] = "default:steelblock"}, {["x"] = 4, ["y"] = 12, ["z"] = 4, ["name"] = "default:steelblock"}, {["x"] = 4, ["y"] = 12, ["z"] = 5, ["name"] = "default:steelblock"}, {["x"] = 4, ["y"] = 12, ["z"] = 6, ["name"] = "default:steelblock"}, {["x"] = 4, ["y"] = 12, ["z"] = 7, ["name"] = "default:steelblock"}, {["x"] = 4, ["y"] = 12, ["z"] = 8, ["name"] = "default:steelblock"}, {["x"] = 4, ["y"] = 12, ["z"] = 9, ["name"] = "default:steelblock"}, {["x"] = 4, ["y"] = 12, ["z"] = 10, ["name"] = "default:steelblock"}, {["x"] = 4, ["y"] = 12, ["z"] = 11, ["name"] = "default:steelblock"}, {["x"] = 4, ["y"] = 12, ["z"] = 12, ["name"] = "default:steelblock"}, {["x"] = 4, ["y"] = 12, ["z"] = 13, ["name"] = "default:steelblock"}, {["x"] = 4, ["y"] = 12, ["z"] = 14, ["name"] = "wool:grey"}, {["x"] = 4, ["y"] = 13, ["z"] = 3, ["name"] = "default:steelblock"}, {["x"] = 4, ["y"] = 13, ["z"] = 4, ["name"] = "default:steelblock"}, {["x"] = 4, ["y"] = 13, ["z"] = 5, ["name"] = "default:steelblock"}, {["x"] = 4, ["y"] = 13, ["z"] = 6, ["name"] = "default:steelblock"}, {["x"] = 4, ["y"] = 14, ["z"] = 3, ["name"] = "default:steelblock"}, {["x"] = 4, ["y"] = 14, ["z"] = 4, ["name"] = "default:steelblock"}, {["x"] = 4, ["y"] = 14, ["z"] = 5, ["name"] = "default:steelblock"}, {["x"] = 4, ["y"] = 14, ["z"] = 6, ["name"] = "default:steelblock"}, {["x"] = 4, ["y"] = 15, ["z"] = 3, ["name"] = "default:steelblock"}, {["x"] = 4, ["y"] = 15, ["z"] = 4, ["name"] = "default:steelblock"}, {["x"] = 4, ["y"] = 15, ["z"] = 5, ["name"] = "default:steelblock"}, {["x"] = 4, ["y"] = 15, ["z"] = 6, ["name"] = "default:steelblock"}, {["x"] = 5, ["y"] = 2, ["z"] = 2, ["name"] = "default:steelblock"}, {["x"] = 5, ["y"] = 2, ["z"] = 3, ["name"] = "default:steelblock"}, {["x"] = 5, ["y"] = 2, ["z"] = 4, ["name"] = "default:steelblock"}, {["x"] = 5, ["y"] = 2, ["z"] = 5, ["name"] = "default:steelblock"}, {["x"] = 5, ["y"] = 2, ["z"] = 6, ["name"] = "default:steelblock"}, {["x"] = 5, ["y"] = 2, ["z"] = 7, ["name"] = "default:steelblock"}, {["x"] = 5, ["y"] = 2, ["z"] = 8, ["name"] = "default:steelblock"}, {["x"] = 5, ["y"] = 2, ["z"] = 9, ["name"] = "default:steelblock"}, {["x"] = 5, ["y"] = 2, ["z"] = 10, ["name"] = "default:steelblock"}, {["x"] = 5, ["y"] = 2, ["z"] = 11, ["name"] = "default:steelblock"}, {["x"] = 5, ["y"] = 2, ["z"] = 12, ["name"] = "default:steelblock"}, {["x"] = 5, ["y"] = 2, ["z"] = 13, ["name"] = "default:steelblock"}, {["x"] = 5, ["y"] = 3, ["param1"] = 81, ["z"] = 2, ["name"] = "default:steelblock"}, {["x"] = 5, ["y"] = 3, ["param1"] = 81, ["z"] = 3, ["name"] = "default:steelblock"}, {["x"] = 5, ["y"] = 3, ["param1"] = 81, ["z"] = 4, ["name"] = "default:steelblock"}, {["x"] = 5, ["y"] = 3, ["param1"] = 81, ["z"] = 5, ["name"] = "default:steelblock"}, {["x"] = 5, ["y"] = 3, ["param1"] = 81, ["z"] = 6, ["name"] = "default:steelblock"}, {["x"] = 5, ["y"] = 3, ["param1"] = 81, ["z"] = 7, ["name"] = "default:steelblock"}, {["x"] = 5, ["y"] = 3, ["param1"] = 81, ["z"] = 8, ["name"] = "default:steelblock"}, {["x"] = 5, ["y"] = 3, ["param1"] = 81, ["z"] = 9, ["name"] = "default:steelblock"}, {["x"] = 5, ["y"] = 3, ["param1"] = 81, ["z"] = 10, ["name"] = "default:steelblock"}, {["x"] = 5, ["y"] = 3, ["param1"] = 81, ["z"] = 11, ["name"] = "default:steelblock"}, {["x"] = 5, ["y"] = 3, ["param1"] = 81, ["z"] = 12, ["name"] = "default:steelblock"}, {["x"] = 5, ["y"] = 3, ["param1"] = 81, ["z"] = 13, ["name"] = "default:steelblock"}, {["x"] = 5, ["y"] = 4, ["param1"] = 81, ["z"] = 2, ["name"] = "default:steelblock"}, {["x"] = 5, ["y"] = 4, ["param1"] = 81, ["z"] = 3, ["name"] = "default:steelblock"}, {["x"] = 5, ["y"] = 4, ["param1"] = 81, ["z"] = 4, ["name"] = "default:steelblock"}, {["x"] = 5, ["y"] = 4, ["param1"] = 81, ["z"] = 5, ["name"] = "default:steelblock"}, {["x"] = 5, ["y"] = 4, ["param1"] = 81, ["z"] = 6, ["name"] = "default:steelblock"}, {["x"] = 5, ["y"] = 4, ["param1"] = 81, ["z"] = 7, ["name"] = "default:steelblock"}, {["x"] = 5, ["y"] = 4, ["param1"] = 81, ["z"] = 8, ["name"] = "default:steelblock"}, {["x"] = 5, ["y"] = 4, ["param1"] = 81, ["z"] = 9, ["name"] = "default:steelblock"}, {["x"] = 5, ["y"] = 4, ["param1"] = 81, ["z"] = 10, ["name"] = "default:steelblock"}, {["x"] = 5, ["y"] = 4, ["param1"] = 81, ["z"] = 11, ["name"] = "default:steelblock"}, {["x"] = 5, ["y"] = 4, ["param1"] = 81, ["z"] = 12, ["name"] = "default:steelblock"}, {["x"] = 5, ["y"] = 4, ["param1"] = 81, ["z"] = 13, ["name"] = "default:steelblock"}, {["x"] = 5, ["y"] = 5, ["z"] = 1, ["name"] = "wool:grey"}, {["x"] = 5, ["y"] = 5, ["param1"] = 81, ["z"] = 2, ["name"] = "default:steelblock"}, {["x"] = 5, ["y"] = 5, ["param1"] = 81, ["z"] = 3, ["name"] = "default:steelblock"}, {["x"] = 5, ["y"] = 5, ["param1"] = 81, ["z"] = 4, ["name"] = "default:steelblock"}, {["x"] = 5, ["y"] = 5, ["param1"] = 81, ["z"] = 5, ["name"] = "default:steelblock"}, {["x"] = 5, ["y"] = 5, ["param1"] = 81, ["z"] = 6, ["name"] = "default:steelblock"}, {["x"] = 5, ["y"] = 5, ["param1"] = 81, ["z"] = 7, ["name"] = "default:steelblock"}, {["x"] = 5, ["y"] = 5, ["param1"] = 81, ["z"] = 8, ["name"] = "default:steelblock"}, {["x"] = 5, ["y"] = 5, ["param1"] = 81, ["z"] = 9, ["name"] = "default:steelblock"}, {["x"] = 5, ["y"] = 5, ["param1"] = 81, ["z"] = 10, ["name"] = "default:steelblock"}, {["x"] = 5, ["y"] = 5, ["param1"] = 81, ["z"] = 11, ["name"] = "default:steelblock"}, {["x"] = 5, ["y"] = 5, ["param1"] = 81, ["z"] = 12, ["name"] = "default:steelblock"}, {["x"] = 5, ["y"] = 5, ["param1"] = 81, ["z"] = 13, ["name"] = "default:steelblock"}, {["x"] = 5, ["y"] = 5, ["z"] = 14, ["name"] = "wool:grey"}, {["x"] = 5, ["y"] = 6, ["z"] = 1, ["name"] = "wool:grey"}, {["x"] = 5, ["y"] = 6, ["param1"] = 81, ["z"] = 2, ["name"] = "default:steelblock"}, {["x"] = 5, ["y"] = 6, ["param1"] = 81, ["z"] = 3, ["name"] = "default:steelblock"}, {["x"] = 5, ["y"] = 6, ["param1"] = 81, ["z"] = 4, ["name"] = "default:steelblock"}, {["x"] = 5, ["y"] = 6, ["param1"] = 81, ["z"] = 5, ["name"] = "default:steelblock"}, {["x"] = 5, ["y"] = 6, ["param1"] = 81, ["z"] = 6, ["name"] = "default:steelblock"}, {["x"] = 5, ["y"] = 6, ["param1"] = 81, ["z"] = 7, ["name"] = "default:steelblock"}, {["x"] = 5, ["y"] = 6, ["param1"] = 81, ["z"] = 8, ["name"] = "default:steelblock"}, {["x"] = 5, ["y"] = 6, ["param1"] = 81, ["z"] = 9, ["name"] = "default:steelblock"}, {["x"] = 5, ["y"] = 6, ["param1"] = 81, ["z"] = 10, ["name"] = "default:steelblock"}, {["x"] = 5, ["y"] = 6, ["param1"] = 81, ["z"] = 11, ["name"] = "default:steelblock"}, {["x"] = 5, ["y"] = 6, ["param1"] = 81, ["z"] = 12, ["name"] = "default:steelblock"}, {["x"] = 5, ["y"] = 6, ["param1"] = 81, ["z"] = 13, ["name"] = "default:steelblock"}, {["x"] = 5, ["y"] = 6, ["z"] = 14, ["name"] = "wool:grey"}, {["x"] = 5, ["y"] = 7, ["param1"] = 81, ["z"] = 2, ["name"] = "default:steelblock"}, {["x"] = 5, ["y"] = 7, ["param1"] = 81, ["z"] = 3, ["name"] = "default:steelblock"}, {["x"] = 5, ["y"] = 7, ["param1"] = 81, ["z"] = 4, ["name"] = "default:steelblock"}, {["x"] = 5, ["y"] = 7, ["param1"] = 81, ["z"] = 5, ["name"] = "default:steelblock"}, {["x"] = 5, ["y"] = 7, ["param1"] = 81, ["z"] = 6, ["name"] = "default:steelblock"}, {["x"] = 5, ["y"] = 7, ["param1"] = 81, ["z"] = 7, ["name"] = "default:steelblock"}, {["x"] = 5, ["y"] = 7, ["param1"] = 81, ["z"] = 8, ["name"] = "default:steelblock"}, {["x"] = 5, ["y"] = 7, ["param1"] = 81, ["z"] = 9, ["name"] = "default:steelblock"}, {["x"] = 5, ["y"] = 7, ["param1"] = 81, ["z"] = 10, ["name"] = "default:steelblock"}, {["x"] = 5, ["y"] = 7, ["param1"] = 81, ["z"] = 11, ["name"] = "default:steelblock"}, {["x"] = 5, ["y"] = 7, ["param1"] = 81, ["z"] = 12, ["name"] = "default:steelblock"}, {["x"] = 5, ["y"] = 7, ["param1"] = 81, ["z"] = 13, ["name"] = "default:steelblock"}, {["x"] = 5, ["y"] = 8, ["param1"] = 81, ["z"] = 2, ["name"] = "default:steelblock"}, {["x"] = 5, ["y"] = 8, ["param1"] = 81, ["z"] = 3, ["name"] = "default:steelblock"}, {["x"] = 5, ["y"] = 8, ["param1"] = 81, ["z"] = 4, ["name"] = "default:steelblock"}, {["x"] = 5, ["y"] = 8, ["param1"] = 81, ["z"] = 5, ["name"] = "default:steelblock"}, {["x"] = 5, ["y"] = 8, ["param1"] = 81, ["z"] = 6, ["name"] = "default:steelblock"}, {["x"] = 5, ["y"] = 8, ["param1"] = 81, ["z"] = 7, ["name"] = "default:steelblock"}, {["x"] = 5, ["y"] = 8, ["param1"] = 81, ["z"] = 8, ["name"] = "default:steelblock"}, {["x"] = 5, ["y"] = 8, ["param1"] = 81, ["z"] = 9, ["name"] = "default:steelblock"}, {["x"] = 5, ["y"] = 8, ["param1"] = 81, ["z"] = 10, ["name"] = "default:steelblock"}, {["x"] = 5, ["y"] = 8, ["param1"] = 81, ["z"] = 11, ["name"] = "default:steelblock"}, {["x"] = 5, ["y"] = 8, ["param1"] = 81, ["z"] = 12, ["name"] = "default:steelblock"}, {["x"] = 5, ["y"] = 8, ["param1"] = 81, ["z"] = 13, ["name"] = "default:steelblock"}, {["x"] = 5, ["y"] = 9, ["param1"] = 81, ["z"] = 2, ["name"] = "default:steelblock"}, {["x"] = 5, ["y"] = 9, ["param1"] = 81, ["z"] = 3, ["name"] = "default:steelblock"}, {["x"] = 5, ["y"] = 9, ["param1"] = 81, ["z"] = 4, ["name"] = "default:steelblock"}, {["x"] = 5, ["y"] = 9, ["param1"] = 81, ["z"] = 5, ["name"] = "default:steelblock"}, {["x"] = 5, ["y"] = 9, ["param1"] = 81, ["z"] = 6, ["name"] = "default:steelblock"}, {["x"] = 5, ["y"] = 9, ["param1"] = 81, ["z"] = 7, ["name"] = "default:steelblock"}, {["x"] = 5, ["y"] = 9, ["param1"] = 81, ["z"] = 8, ["name"] = "default:steelblock"}, {["x"] = 5, ["y"] = 9, ["param1"] = 81, ["z"] = 9, ["name"] = "default:steelblock"}, {["x"] = 5, ["y"] = 9, ["param1"] = 81, ["z"] = 10, ["name"] = "default:steelblock"}, {["x"] = 5, ["y"] = 9, ["param1"] = 81, ["z"] = 11, ["name"] = "default:steelblock"}, {["x"] = 5, ["y"] = 9, ["param1"] = 81, ["z"] = 12, ["name"] = "default:steelblock"}, {["x"] = 5, ["y"] = 9, ["param1"] = 81, ["z"] = 13, ["name"] = "default:steelblock"}, {["x"] = 5, ["y"] = 10, ["param1"] = 81, ["z"] = 2, ["name"] = "default:steelblock"}, {["x"] = 5, ["y"] = 10, ["param1"] = 81, ["z"] = 3, ["name"] = "default:steelblock"}, {["x"] = 5, ["y"] = 10, ["param1"] = 81, ["z"] = 4, ["name"] = "default:steelblock"}, {["x"] = 5, ["y"] = 10, ["param1"] = 81, ["z"] = 5, ["name"] = "default:steelblock"}, {["x"] = 5, ["y"] = 10, ["param1"] = 81, ["z"] = 6, ["name"] = "default:steelblock"}, {["x"] = 5, ["y"] = 10, ["param1"] = 81, ["z"] = 7, ["name"] = "default:steelblock"}, {["x"] = 5, ["y"] = 10, ["param1"] = 81, ["z"] = 8, ["name"] = "default:steelblock"}, {["x"] = 5, ["y"] = 10, ["param1"] = 81, ["z"] = 9, ["name"] = "default:steelblock"}, {["x"] = 5, ["y"] = 10, ["param1"] = 81, ["z"] = 10, ["name"] = "default:steelblock"}, {["x"] = 5, ["y"] = 10, ["param1"] = 81, ["z"] = 11, ["name"] = "default:steelblock"}, {["x"] = 5, ["y"] = 10, ["param1"] = 81, ["z"] = 12, ["name"] = "default:steelblock"}, {["x"] = 5, ["y"] = 10, ["param1"] = 81, ["z"] = 13, ["name"] = "default:steelblock"}, {["x"] = 5, ["y"] = 11, ["z"] = 1, ["name"] = "wool:grey"}, {["x"] = 5, ["y"] = 11, ["param1"] = 81, ["z"] = 2, ["name"] = "default:steelblock"}, {["x"] = 5, ["y"] = 11, ["param1"] = 81, ["z"] = 3, ["name"] = "default:steelblock"}, {["x"] = 5, ["y"] = 11, ["param1"] = 81, ["z"] = 4, ["name"] = "default:steelblock"}, {["x"] = 5, ["y"] = 11, ["param1"] = 81, ["z"] = 5, ["name"] = "default:steelblock"}, {["x"] = 5, ["y"] = 11, ["param1"] = 81, ["z"] = 6, ["name"] = "default:steelblock"}, {["x"] = 5, ["y"] = 11, ["param1"] = 81, ["z"] = 7, ["name"] = "default:steelblock"}, {["x"] = 5, ["y"] = 11, ["param1"] = 81, ["z"] = 8, ["name"] = "default:steelblock"}, {["x"] = 5, ["y"] = 11, ["param1"] = 81, ["z"] = 9, ["name"] = "default:steelblock"}, {["x"] = 5, ["y"] = 11, ["param1"] = 81, ["z"] = 10, ["name"] = "default:steelblock"}, {["x"] = 5, ["y"] = 11, ["param1"] = 81, ["z"] = 11, ["name"] = "default:steelblock"}, {["x"] = 5, ["y"] = 11, ["param1"] = 81, ["z"] = 12, ["name"] = "default:steelblock"}, {["x"] = 5, ["y"] = 11, ["param1"] = 81, ["z"] = 13, ["name"] = "default:steelblock"}, {["x"] = 5, ["y"] = 11, ["z"] = 14, ["name"] = "wool:grey"}, {["x"] = 5, ["y"] = 12, ["z"] = 1, ["name"] = "wool:grey"}, {["x"] = 5, ["y"] = 12, ["param1"] = 81, ["z"] = 2, ["name"] = "default:steelblock"}, {["x"] = 5, ["y"] = 12, ["param1"] = 81, ["z"] = 3, ["name"] = "default:steelblock"}, {["x"] = 5, ["y"] = 12, ["param1"] = 81, ["z"] = 4, ["name"] = "default:steelblock"}, {["x"] = 5, ["y"] = 12, ["param1"] = 81, ["z"] = 5, ["name"] = "default:steelblock"}, {["x"] = 5, ["y"] = 12, ["param1"] = 81, ["z"] = 6, ["name"] = "default:steelblock"}, {["x"] = 5, ["y"] = 12, ["param1"] = 81, ["z"] = 7, ["name"] = "default:steelblock"}, {["x"] = 5, ["y"] = 12, ["param1"] = 81, ["z"] = 8, ["name"] = "default:steelblock"}, {["x"] = 5, ["y"] = 12, ["param1"] = 81, ["z"] = 9, ["name"] = "default:steelblock"}, {["x"] = 5, ["y"] = 12, ["param1"] = 81, ["z"] = 10, ["name"] = "default:steelblock"}, {["x"] = 5, ["y"] = 12, ["param1"] = 81, ["z"] = 11, ["name"] = "default:steelblock"}, {["x"] = 5, ["y"] = 12, ["param1"] = 81, ["z"] = 12, ["name"] = "default:steelblock"}, {["x"] = 5, ["y"] = 12, ["param1"] = 81, ["z"] = 13, ["name"] = "default:steelblock"}, {["x"] = 5, ["y"] = 12, ["z"] = 14, ["name"] = "wool:grey"}, {["x"] = 5, ["y"] = 13, ["z"] = 2, ["name"] = "default:steelblock"}, {["x"] = 5, ["y"] = 13, ["z"] = 3, ["name"] = "default:steelblock"}, {["x"] = 5, ["y"] = 13, ["z"] = 4, ["name"] = "default:steelblock"}, {["x"] = 5, ["y"] = 13, ["z"] = 5, ["name"] = "default:steelblock"}, {["x"] = 5, ["y"] = 13, ["z"] = 6, ["name"] = "default:steelblock"}, {["x"] = 5, ["y"] = 13, ["z"] = 7, ["name"] = "default:steelblock"}, {["x"] = 5, ["y"] = 13, ["z"] = 8, ["name"] = "default:steelblock"}, {["x"] = 5, ["y"] = 13, ["z"] = 9, ["name"] = "default:steelblock"}, {["x"] = 5, ["y"] = 13, ["z"] = 10, ["name"] = "default:steelblock"}, {["x"] = 5, ["y"] = 13, ["z"] = 11, ["name"] = "default:steelblock"}, {["x"] = 5, ["y"] = 13, ["z"] = 12, ["name"] = "default:steelblock"}, {["x"] = 5, ["y"] = 13, ["z"] = 13, ["name"] = "default:steelblock"}, {["x"] = 5, ["y"] = 14, ["z"] = 3, ["name"] = "default:steelblock"}, {["x"] = 5, ["y"] = 14, ["z"] = 4, ["name"] = "default:steelblock"}, {["x"] = 5, ["y"] = 14, ["z"] = 5, ["name"] = "default:steelblock"}, {["x"] = 5, ["y"] = 14, ["z"] = 6, ["name"] = "default:steelblock"}, {["x"] = 5, ["y"] = 15, ["z"] = 3, ["name"] = "default:steelblock"}, {["x"] = 5, ["y"] = 15, ["z"] = 4, ["name"] = "default:steelblock"}, {["x"] = 5, ["y"] = 15, ["z"] = 5, ["name"] = "default:steelblock"}, {["x"] = 5, ["y"] = 15, ["z"] = 6, ["name"] = "default:steelblock"}, {["x"] = 6, ["y"] = 2, ["z"] = 2, ["name"] = "default:steelblock"}, {["x"] = 6, ["y"] = 2, ["z"] = 3, ["name"] = "default:steelblock"}, {["x"] = 6, ["y"] = 2, ["z"] = 4, ["name"] = "default:steelblock"}, {["x"] = 6, ["y"] = 2, ["z"] = 5, ["name"] = "default:steelblock"}, {["x"] = 6, ["y"] = 2, ["z"] = 6, ["name"] = "default:steelblock"}, {["x"] = 6, ["y"] = 2, ["z"] = 7, ["name"] = "default:steelblock"}, {["x"] = 6, ["y"] = 2, ["z"] = 8, ["name"] = "default:steelblock"}, {["x"] = 6, ["y"] = 2, ["z"] = 9, ["name"] = "default:steelblock"}, {["x"] = 6, ["y"] = 2, ["z"] = 10, ["name"] = "default:steelblock"}, {["x"] = 6, ["y"] = 2, ["z"] = 11, ["name"] = "default:steelblock"}, {["x"] = 6, ["y"] = 2, ["z"] = 12, ["name"] = "default:steelblock"}, {["x"] = 6, ["y"] = 2, ["z"] = 13, ["name"] = "default:steelblock"}, {["x"] = 6, ["y"] = 3, ["param1"] = 81, ["z"] = 2, ["name"] = "default:steelblock"}, {["x"] = 6, ["y"] = 3, ["param1"] = 81, ["z"] = 3, ["name"] = "default:steelblock"}, {["x"] = 6, ["y"] = 3, ["param1"] = 81, ["z"] = 4, ["name"] = "default:steelblock"}, {["x"] = 6, ["y"] = 3, ["param1"] = 81, ["z"] = 5, ["name"] = "default:steelblock"}, {["x"] = 6, ["y"] = 3, ["param1"] = 81, ["z"] = 6, ["name"] = "default:steelblock"}, {["x"] = 6, ["y"] = 3, ["param1"] = 81, ["z"] = 7, ["name"] = "default:steelblock"}, {["x"] = 6, ["y"] = 3, ["param1"] = 81, ["z"] = 8, ["name"] = "default:steelblock"}, {["x"] = 6, ["y"] = 3, ["param1"] = 81, ["z"] = 9, ["name"] = "default:steelblock"}, {["x"] = 6, ["y"] = 3, ["param1"] = 81, ["z"] = 10, ["name"] = "default:steelblock"}, {["x"] = 6, ["y"] = 3, ["param1"] = 81, ["z"] = 11, ["name"] = "default:steelblock"}, {["x"] = 6, ["y"] = 3, ["param1"] = 81, ["z"] = 12, ["name"] = "default:steelblock"}, {["x"] = 6, ["y"] = 3, ["param1"] = 81, ["z"] = 13, ["name"] = "default:steelblock"}, {["x"] = 6, ["y"] = 4, ["param1"] = 81, ["z"] = 2, ["name"] = "default:steelblock"}, {["x"] = 6, ["y"] = 4, ["param1"] = 81, ["z"] = 3, ["name"] = "default:steelblock"}, {["x"] = 6, ["y"] = 4, ["param1"] = 81, ["z"] = 4, ["name"] = "default:steelblock"}, {["x"] = 6, ["y"] = 4, ["param1"] = 81, ["z"] = 5, ["name"] = "default:steelblock"}, {["x"] = 6, ["y"] = 4, ["param1"] = 81, ["z"] = 6, ["name"] = "default:steelblock"}, {["x"] = 6, ["y"] = 4, ["param1"] = 81, ["z"] = 7, ["name"] = "default:steelblock"}, {["x"] = 6, ["y"] = 4, ["param1"] = 81, ["z"] = 8, ["name"] = "default:steelblock"}, {["x"] = 6, ["y"] = 4, ["param1"] = 81, ["z"] = 9, ["name"] = "default:steelblock"}, {["x"] = 6, ["y"] = 4, ["param1"] = 81, ["z"] = 10, ["name"] = "default:steelblock"}, {["x"] = 6, ["y"] = 4, ["param1"] = 81, ["z"] = 11, ["name"] = "default:steelblock"}, {["x"] = 6, ["y"] = 4, ["param1"] = 81, ["z"] = 12, ["name"] = "default:steelblock"}, {["x"] = 6, ["y"] = 4, ["param1"] = 81, ["z"] = 13, ["name"] = "default:steelblock"}, {["x"] = 6, ["y"] = 5, ["z"] = 1, ["name"] = "wool:grey"}, {["x"] = 6, ["y"] = 5, ["param1"] = 81, ["z"] = 2, ["name"] = "default:steelblock"}, {["x"] = 6, ["y"] = 5, ["param1"] = 81, ["z"] = 3, ["name"] = "default:steelblock"}, {["x"] = 6, ["y"] = 5, ["param1"] = 81, ["z"] = 4, ["name"] = "default:steelblock"}, {["x"] = 6, ["y"] = 5, ["param1"] = 81, ["z"] = 5, ["name"] = "default:steelblock"}, {["x"] = 6, ["y"] = 5, ["param1"] = 81, ["z"] = 6, ["name"] = "default:steelblock"}, {["x"] = 6, ["y"] = 5, ["param1"] = 81, ["z"] = 7, ["name"] = "default:steelblock"}, {["x"] = 6, ["y"] = 5, ["param1"] = 81, ["z"] = 8, ["name"] = "default:steelblock"}, {["x"] = 6, ["y"] = 5, ["param1"] = 81, ["z"] = 9, ["name"] = "default:steelblock"}, {["x"] = 6, ["y"] = 5, ["param1"] = 81, ["z"] = 10, ["name"] = "default:steelblock"}, {["x"] = 6, ["y"] = 5, ["param1"] = 81, ["z"] = 11, ["name"] = "default:steelblock"}, {["x"] = 6, ["y"] = 5, ["param1"] = 81, ["z"] = 12, ["name"] = "default:steelblock"}, {["x"] = 6, ["y"] = 5, ["param1"] = 81, ["z"] = 13, ["name"] = "default:steelblock"}, {["x"] = 6, ["y"] = 5, ["z"] = 14, ["name"] = "wool:grey"}, {["x"] = 6, ["y"] = 6, ["z"] = 1, ["name"] = "wool:grey"}, {["x"] = 6, ["y"] = 6, ["param1"] = 81, ["z"] = 2, ["name"] = "default:steelblock"}, {["x"] = 6, ["y"] = 6, ["param1"] = 81, ["z"] = 3, ["name"] = "default:steelblock"}, {["x"] = 6, ["y"] = 6, ["param1"] = 81, ["z"] = 4, ["name"] = "default:steelblock"}, {["x"] = 6, ["y"] = 6, ["param1"] = 81, ["z"] = 5, ["name"] = "default:steelblock"}, {["x"] = 6, ["y"] = 6, ["param1"] = 81, ["z"] = 6, ["name"] = "default:steelblock"}, {["x"] = 6, ["y"] = 6, ["param1"] = 81, ["z"] = 7, ["name"] = "default:steelblock"}, {["x"] = 6, ["y"] = 6, ["param1"] = 81, ["z"] = 8, ["name"] = "default:steelblock"}, {["x"] = 6, ["y"] = 6, ["param1"] = 81, ["z"] = 9, ["name"] = "default:steelblock"}, {["x"] = 6, ["y"] = 6, ["param1"] = 81, ["z"] = 10, ["name"] = "default:steelblock"}, {["x"] = 6, ["y"] = 6, ["param1"] = 81, ["z"] = 11, ["name"] = "default:steelblock"}, {["x"] = 6, ["y"] = 6, ["param1"] = 81, ["z"] = 12, ["name"] = "default:steelblock"}, {["x"] = 6, ["y"] = 6, ["param1"] = 81, ["z"] = 13, ["name"] = "default:steelblock"}, {["x"] = 6, ["y"] = 6, ["z"] = 14, ["name"] = "wool:grey"}, {["x"] = 6, ["y"] = 7, ["param1"] = 81, ["z"] = 2, ["name"] = "default:steelblock"}, {["x"] = 6, ["y"] = 7, ["param1"] = 81, ["z"] = 3, ["name"] = "default:steelblock"}, {["x"] = 6, ["y"] = 7, ["param1"] = 81, ["z"] = 4, ["name"] = "default:steelblock"}, {["x"] = 6, ["y"] = 7, ["param1"] = 81, ["z"] = 5, ["name"] = "default:steelblock"}, {["x"] = 6, ["y"] = 7, ["param1"] = 81, ["z"] = 6, ["name"] = "default:steelblock"}, {["x"] = 6, ["y"] = 7, ["param1"] = 81, ["z"] = 7, ["name"] = "default:steelblock"}, {["x"] = 6, ["y"] = 7, ["param1"] = 81, ["z"] = 8, ["name"] = "default:steelblock"}, {["x"] = 6, ["y"] = 7, ["param1"] = 81, ["z"] = 9, ["name"] = "default:steelblock"}, {["x"] = 6, ["y"] = 7, ["param1"] = 81, ["z"] = 10, ["name"] = "default:steelblock"}, {["x"] = 6, ["y"] = 7, ["param1"] = 81, ["z"] = 11, ["name"] = "default:steelblock"}, {["x"] = 6, ["y"] = 7, ["param1"] = 81, ["z"] = 12, ["name"] = "default:steelblock"}, {["x"] = 6, ["y"] = 7, ["param1"] = 81, ["z"] = 13, ["name"] = "default:steelblock"}, {["x"] = 6, ["y"] = 8, ["param1"] = 81, ["z"] = 2, ["name"] = "default:steelblock"}, {["x"] = 6, ["y"] = 8, ["param1"] = 81, ["z"] = 3, ["name"] = "default:steelblock"}, {["x"] = 6, ["y"] = 8, ["param1"] = 81, ["z"] = 4, ["name"] = "default:steelblock"}, {["x"] = 6, ["y"] = 8, ["param1"] = 81, ["z"] = 5, ["name"] = "default:steelblock"}, {["x"] = 6, ["y"] = 8, ["param1"] = 81, ["z"] = 6, ["name"] = "default:steelblock"}, {["x"] = 6, ["y"] = 8, ["param1"] = 81, ["z"] = 7, ["name"] = "default:steelblock"}, {["x"] = 6, ["y"] = 8, ["param1"] = 81, ["z"] = 8, ["name"] = "default:steelblock"}, {["x"] = 6, ["y"] = 8, ["param1"] = 81, ["z"] = 9, ["name"] = "default:steelblock"}, {["x"] = 6, ["y"] = 8, ["param1"] = 81, ["z"] = 10, ["name"] = "default:steelblock"}, {["x"] = 6, ["y"] = 8, ["param1"] = 81, ["z"] = 11, ["name"] = "default:steelblock"}, {["x"] = 6, ["y"] = 8, ["param1"] = 81, ["z"] = 12, ["name"] = "default:steelblock"}, {["x"] = 6, ["y"] = 8, ["param1"] = 81, ["z"] = 13, ["name"] = "default:steelblock"}, {["x"] = 6, ["y"] = 9, ["param1"] = 81, ["z"] = 2, ["name"] = "default:steelblock"}, {["x"] = 6, ["y"] = 9, ["param1"] = 81, ["z"] = 3, ["name"] = "default:steelblock"}, {["x"] = 6, ["y"] = 9, ["param1"] = 81, ["z"] = 4, ["name"] = "default:steelblock"}, {["x"] = 6, ["y"] = 9, ["param1"] = 81, ["z"] = 5, ["name"] = "default:steelblock"}, {["x"] = 6, ["y"] = 9, ["param1"] = 81, ["z"] = 6, ["name"] = "default:steelblock"}, {["x"] = 6, ["y"] = 9, ["param1"] = 81, ["z"] = 7, ["name"] = "default:steelblock"}, {["x"] = 6, ["y"] = 9, ["param1"] = 81, ["z"] = 8, ["name"] = "default:steelblock"}, {["x"] = 6, ["y"] = 9, ["param1"] = 81, ["z"] = 9, ["name"] = "default:steelblock"}, {["x"] = 6, ["y"] = 9, ["param1"] = 81, ["z"] = 10, ["name"] = "default:steelblock"}, {["x"] = 6, ["y"] = 9, ["param1"] = 81, ["z"] = 11, ["name"] = "default:steelblock"}, {["x"] = 6, ["y"] = 9, ["param1"] = 81, ["z"] = 12, ["name"] = "default:steelblock"}, {["x"] = 6, ["y"] = 9, ["param1"] = 81, ["z"] = 13, ["name"] = "default:steelblock"}, {["x"] = 6, ["y"] = 10, ["param1"] = 81, ["z"] = 2, ["name"] = "default:steelblock"}, {["x"] = 6, ["y"] = 10, ["param1"] = 81, ["z"] = 3, ["name"] = "default:steelblock"}, {["x"] = 6, ["y"] = 10, ["param1"] = 81, ["z"] = 4, ["name"] = "default:steelblock"}, {["x"] = 6, ["y"] = 10, ["param1"] = 81, ["z"] = 5, ["name"] = "default:steelblock"}, {["x"] = 6, ["y"] = 10, ["param1"] = 81, ["z"] = 6, ["name"] = "default:steelblock"}, {["x"] = 6, ["y"] = 10, ["param1"] = 81, ["z"] = 7, ["name"] = "default:steelblock"}, {["x"] = 6, ["y"] = 10, ["param1"] = 81, ["z"] = 8, ["name"] = "default:steelblock"}, {["x"] = 6, ["y"] = 10, ["param1"] = 81, ["z"] = 9, ["name"] = "default:steelblock"}, {["x"] = 6, ["y"] = 10, ["param1"] = 81, ["z"] = 10, ["name"] = "default:steelblock"}, {["x"] = 6, ["y"] = 10, ["param1"] = 81, ["z"] = 11, ["name"] = "default:steelblock"}, {["x"] = 6, ["y"] = 10, ["param1"] = 81, ["z"] = 12, ["name"] = "default:steelblock"}, {["x"] = 6, ["y"] = 10, ["param1"] = 81, ["z"] = 13, ["name"] = "default:steelblock"}, {["x"] = 6, ["y"] = 11, ["z"] = 1, ["name"] = "wool:grey"}, {["x"] = 6, ["y"] = 11, ["param1"] = 81, ["z"] = 2, ["name"] = "default:steelblock"}, {["x"] = 6, ["y"] = 11, ["param1"] = 81, ["z"] = 3, ["name"] = "default:steelblock"}, {["x"] = 6, ["y"] = 11, ["param1"] = 81, ["z"] = 4, ["name"] = "default:steelblock"}, {["x"] = 6, ["y"] = 11, ["param1"] = 81, ["z"] = 5, ["name"] = "default:steelblock"}, {["x"] = 6, ["y"] = 11, ["param1"] = 81, ["z"] = 6, ["name"] = "default:steelblock"}, {["x"] = 6, ["y"] = 11, ["param1"] = 81, ["z"] = 7, ["name"] = "default:steelblock"}, {["x"] = 6, ["y"] = 11, ["param1"] = 81, ["z"] = 8, ["name"] = "default:steelblock"}, {["x"] = 6, ["y"] = 11, ["param1"] = 81, ["z"] = 9, ["name"] = "default:steelblock"}, {["x"] = 6, ["y"] = 11, ["param1"] = 81, ["z"] = 10, ["name"] = "default:steelblock"}, {["x"] = 6, ["y"] = 11, ["param1"] = 81, ["z"] = 11, ["name"] = "default:steelblock"}, {["x"] = 6, ["y"] = 11, ["param1"] = 81, ["z"] = 12, ["name"] = "default:steelblock"}, {["x"] = 6, ["y"] = 11, ["param1"] = 81, ["z"] = 13, ["name"] = "default:steelblock"}, {["x"] = 6, ["y"] = 11, ["z"] = 14, ["name"] = "wool:grey"}, {["x"] = 6, ["y"] = 12, ["z"] = 1, ["name"] = "wool:grey"}, {["x"] = 6, ["y"] = 12, ["param1"] = 81, ["z"] = 2, ["name"] = "default:steelblock"}, {["x"] = 6, ["y"] = 12, ["param1"] = 81, ["z"] = 3, ["name"] = "default:steelblock"}, {["x"] = 6, ["y"] = 12, ["param1"] = 81, ["z"] = 4, ["name"] = "default:steelblock"}, {["x"] = 6, ["y"] = 12, ["param1"] = 81, ["z"] = 5, ["name"] = "default:steelblock"}, {["x"] = 6, ["y"] = 12, ["param1"] = 81, ["z"] = 6, ["name"] = "default:steelblock"}, {["x"] = 6, ["y"] = 12, ["param1"] = 81, ["z"] = 7, ["name"] = "default:steelblock"}, {["x"] = 6, ["y"] = 12, ["param1"] = 81, ["z"] = 8, ["name"] = "default:steelblock"}, {["x"] = 6, ["y"] = 12, ["param1"] = 81, ["z"] = 9, ["name"] = "default:steelblock"}, {["x"] = 6, ["y"] = 12, ["param1"] = 81, ["z"] = 10, ["name"] = "default:steelblock"}, {["x"] = 6, ["y"] = 12, ["param1"] = 81, ["z"] = 11, ["name"] = "default:steelblock"}, {["x"] = 6, ["y"] = 12, ["param1"] = 81, ["z"] = 12, ["name"] = "default:steelblock"}, {["x"] = 6, ["y"] = 12, ["param1"] = 81, ["z"] = 13, ["name"] = "default:steelblock"}, {["x"] = 6, ["y"] = 12, ["z"] = 14, ["name"] = "wool:grey"}, {["x"] = 6, ["y"] = 13, ["z"] = 2, ["name"] = "default:steelblock"}, {["x"] = 6, ["y"] = 13, ["z"] = 3, ["name"] = "default:steelblock"}, {["x"] = 6, ["y"] = 13, ["z"] = 4, ["name"] = "default:steelblock"}, {["x"] = 6, ["y"] = 13, ["z"] = 5, ["name"] = "default:steelblock"}, {["x"] = 6, ["y"] = 13, ["z"] = 6, ["name"] = "default:steelblock"}, {["x"] = 6, ["y"] = 13, ["z"] = 7, ["name"] = "default:steelblock"}, {["x"] = 6, ["y"] = 13, ["z"] = 8, ["name"] = "default:steelblock"}, {["x"] = 6, ["y"] = 13, ["z"] = 9, ["name"] = "default:steelblock"}, {["x"] = 6, ["y"] = 13, ["z"] = 10, ["name"] = "default:steelblock"}, {["x"] = 6, ["y"] = 13, ["z"] = 11, ["name"] = "default:steelblock"}, {["x"] = 6, ["y"] = 13, ["z"] = 12, ["name"] = "default:steelblock"}, {["x"] = 6, ["y"] = 13, ["z"] = 13, ["name"] = "default:steelblock"}, {["x"] = 6, ["y"] = 14, ["z"] = 3, ["name"] = "default:steelblock"}, {["x"] = 6, ["y"] = 14, ["z"] = 4, ["name"] = "default:steelblock"}, {["x"] = 6, ["y"] = 14, ["z"] = 5, ["name"] = "default:steelblock"}, {["x"] = 6, ["y"] = 14, ["z"] = 6, ["name"] = "default:steelblock"}, {["x"] = 6, ["y"] = 15, ["z"] = 3, ["name"] = "default:steelblock"}, {["x"] = 6, ["y"] = 15, ["z"] = 4, ["name"] = "default:steelblock"}, {["x"] = 6, ["y"] = 15, ["z"] = 5, ["name"] = "default:steelblock"}, {["x"] = 6, ["y"] = 15, ["z"] = 6, ["name"] = "default:steelblock"}, {["x"] = 7, ["y"] = 2, ["z"] = 2, ["name"] = "default:steelblock"}, {["x"] = 7, ["y"] = 2, ["z"] = 3, ["name"] = "default:steelblock"}, {["x"] = 7, ["y"] = 2, ["z"] = 4, ["name"] = "default:steelblock"}, {["x"] = 7, ["y"] = 2, ["z"] = 5, ["name"] = "default:steelblock"}, {["x"] = 7, ["y"] = 2, ["z"] = 6, ["name"] = "default:steelblock"}, {["x"] = 7, ["y"] = 2, ["z"] = 7, ["name"] = "default:steelblock"}, {["x"] = 7, ["y"] = 2, ["z"] = 8, ["name"] = "default:steelblock"}, {["x"] = 7, ["y"] = 2, ["z"] = 9, ["name"] = "default:steelblock"}, {["x"] = 7, ["y"] = 2, ["z"] = 10, ["name"] = "default:steelblock"}, {["x"] = 7, ["y"] = 2, ["z"] = 11, ["name"] = "default:steelblock"}, {["x"] = 7, ["y"] = 2, ["z"] = 12, ["name"] = "default:steelblock"}, {["x"] = 7, ["y"] = 2, ["z"] = 13, ["name"] = "default:steelblock"}, {["x"] = 7, ["y"] = 3, ["param1"] = 81, ["z"] = 2, ["name"] = "default:steelblock"}, {["x"] = 7, ["y"] = 3, ["param1"] = 81, ["z"] = 3, ["name"] = "default:steelblock"}, {["x"] = 7, ["y"] = 3, ["param1"] = 81, ["z"] = 4, ["name"] = "default:steelblock"}, {["x"] = 7, ["y"] = 3, ["param1"] = 81, ["z"] = 5, ["name"] = "default:steelblock"}, {["x"] = 7, ["y"] = 3, ["param1"] = 81, ["z"] = 6, ["name"] = "default:steelblock"}, {["x"] = 7, ["y"] = 3, ["param1"] = 81, ["z"] = 7, ["name"] = "default:steelblock"}, {["x"] = 7, ["y"] = 3, ["param1"] = 81, ["z"] = 8, ["name"] = "default:steelblock"}, {["x"] = 7, ["y"] = 3, ["param1"] = 81, ["z"] = 9, ["name"] = "default:steelblock"}, {["x"] = 7, ["y"] = 3, ["param1"] = 81, ["z"] = 10, ["name"] = "default:steelblock"}, {["x"] = 7, ["y"] = 3, ["param1"] = 81, ["z"] = 11, ["name"] = "default:steelblock"}, {["x"] = 7, ["y"] = 3, ["param1"] = 81, ["z"] = 12, ["name"] = "default:steelblock"}, {["x"] = 7, ["y"] = 3, ["param1"] = 81, ["z"] = 13, ["name"] = "default:steelblock"}, {["x"] = 7, ["y"] = 4, ["param1"] = 81, ["z"] = 2, ["name"] = "default:steelblock"}, {["x"] = 7, ["y"] = 4, ["param1"] = 81, ["z"] = 3, ["name"] = "default:steelblock"}, {["x"] = 7, ["y"] = 4, ["param1"] = 81, ["z"] = 4, ["name"] = "default:steelblock"}, {["x"] = 7, ["y"] = 4, ["param1"] = 81, ["z"] = 5, ["name"] = "default:steelblock"}, {["x"] = 7, ["y"] = 4, ["param1"] = 81, ["z"] = 6, ["name"] = "default:steelblock"}, {["x"] = 7, ["y"] = 4, ["param1"] = 81, ["z"] = 7, ["name"] = "default:steelblock"}, {["x"] = 7, ["y"] = 4, ["param1"] = 81, ["z"] = 8, ["name"] = "default:steelblock"}, {["x"] = 7, ["y"] = 4, ["param1"] = 81, ["z"] = 9, ["name"] = "default:steelblock"}, {["x"] = 7, ["y"] = 4, ["param1"] = 81, ["z"] = 10, ["name"] = "default:steelblock"}, {["x"] = 7, ["y"] = 4, ["param1"] = 81, ["z"] = 11, ["name"] = "default:steelblock"}, {["x"] = 7, ["y"] = 4, ["param1"] = 81, ["z"] = 12, ["name"] = "default:steelblock"}, {["x"] = 7, ["y"] = 4, ["param1"] = 81, ["z"] = 13, ["name"] = "default:steelblock"}, {["x"] = 7, ["y"] = 5, ["z"] = 1, ["name"] = "wool:grey"}, {["x"] = 7, ["y"] = 5, ["param1"] = 81, ["z"] = 2, ["name"] = "default:steelblock"}, {["x"] = 7, ["y"] = 5, ["param1"] = 81, ["z"] = 3, ["name"] = "default:steelblock"}, {["x"] = 7, ["y"] = 5, ["param1"] = 81, ["z"] = 4, ["name"] = "default:steelblock"}, {["x"] = 7, ["y"] = 5, ["param1"] = 81, ["z"] = 5, ["name"] = "default:steelblock"}, {["x"] = 7, ["y"] = 5, ["param1"] = 81, ["z"] = 6, ["name"] = "default:steelblock"}, {["x"] = 7, ["y"] = 5, ["param1"] = 81, ["z"] = 7, ["name"] = "default:steelblock"}, {["x"] = 7, ["y"] = 5, ["param1"] = 81, ["z"] = 8, ["name"] = "default:steelblock"}, {["x"] = 7, ["y"] = 5, ["param1"] = 81, ["z"] = 9, ["name"] = "default:steelblock"}, {["x"] = 7, ["y"] = 5, ["param1"] = 81, ["z"] = 10, ["name"] = "default:steelblock"}, {["x"] = 7, ["y"] = 5, ["param1"] = 81, ["z"] = 11, ["name"] = "default:steelblock"}, {["x"] = 7, ["y"] = 5, ["param1"] = 81, ["z"] = 12, ["name"] = "default:steelblock"}, {["x"] = 7, ["y"] = 5, ["param1"] = 81, ["z"] = 13, ["name"] = "default:steelblock"}, {["x"] = 7, ["y"] = 5, ["z"] = 14, ["name"] = "wool:grey"}, {["x"] = 7, ["y"] = 6, ["z"] = 1, ["name"] = "wool:grey"}, {["x"] = 7, ["y"] = 6, ["param1"] = 81, ["z"] = 2, ["name"] = "default:steelblock"}, {["x"] = 7, ["y"] = 6, ["param1"] = 81, ["z"] = 3, ["name"] = "default:steelblock"}, {["x"] = 7, ["y"] = 6, ["param1"] = 81, ["z"] = 4, ["name"] = "default:steelblock"}, {["x"] = 7, ["y"] = 6, ["param1"] = 81, ["z"] = 5, ["name"] = "default:steelblock"}, {["x"] = 7, ["y"] = 6, ["param1"] = 81, ["z"] = 6, ["name"] = "default:steelblock"}, {["x"] = 7, ["y"] = 6, ["param1"] = 81, ["z"] = 7, ["name"] = "default:steelblock"}, {["x"] = 7, ["y"] = 6, ["param1"] = 81, ["z"] = 8, ["name"] = "default:steelblock"}, {["x"] = 7, ["y"] = 6, ["param1"] = 81, ["z"] = 9, ["name"] = "default:steelblock"}, {["x"] = 7, ["y"] = 6, ["param1"] = 81, ["z"] = 10, ["name"] = "default:steelblock"}, {["x"] = 7, ["y"] = 6, ["param1"] = 81, ["z"] = 11, ["name"] = "default:steelblock"}, {["x"] = 7, ["y"] = 6, ["param1"] = 81, ["z"] = 12, ["name"] = "default:steelblock"}, {["x"] = 7, ["y"] = 6, ["param1"] = 81, ["z"] = 13, ["name"] = "default:steelblock"}, {["x"] = 7, ["y"] = 6, ["z"] = 14, ["name"] = "wool:grey"}, {["x"] = 7, ["y"] = 7, ["param1"] = 94, ["z"] = 0, ["name"] = "wool:yellow"}, {["x"] = 7, ["y"] = 7, ["z"] = 1, ["name"] = "wool:yellow"}, {["x"] = 7, ["y"] = 7, ["param1"] = 81, ["z"] = 2, ["name"] = "default:steelblock"}, {["x"] = 7, ["y"] = 7, ["param1"] = 81, ["z"] = 3, ["name"] = "default:steelblock"}, {["x"] = 7, ["y"] = 7, ["param1"] = 81, ["z"] = 4, ["name"] = "default:steelblock"}, {["x"] = 7, ["y"] = 7, ["param1"] = 81, ["z"] = 5, ["name"] = "default:steelblock"}, {["x"] = 7, ["y"] = 7, ["param1"] = 81, ["z"] = 6, ["name"] = "default:steelblock"}, {["x"] = 7, ["y"] = 7, ["param1"] = 81, ["z"] = 7, ["name"] = "default:steelblock"}, {["x"] = 7, ["y"] = 7, ["param1"] = 81, ["z"] = 8, ["name"] = "default:steelblock"}, {["x"] = 7, ["y"] = 7, ["param1"] = 81, ["z"] = 9, ["name"] = "default:steelblock"}, {["x"] = 7, ["y"] = 7, ["param1"] = 81, ["z"] = 10, ["name"] = "default:steelblock"}, {["x"] = 7, ["y"] = 7, ["param1"] = 81, ["z"] = 11, ["name"] = "default:steelblock"}, {["x"] = 7, ["y"] = 7, ["param1"] = 81, ["z"] = 12, ["name"] = "default:steelblock"}, {["x"] = 7, ["y"] = 7, ["param1"] = 81, ["z"] = 13, ["name"] = "default:steelblock"}, {["x"] = 7, ["y"] = 7, ["z"] = 14, ["name"] = "wool:red"}, {["x"] = 7, ["y"] = 7, ["param1"] = 97, ["z"] = 15, ["name"] = "wool:red"}, {["x"] = 7, ["y"] = 8, ["param1"] = 94, ["z"] = 0, ["name"] = "wool:yellow"}, {["x"] = 7, ["y"] = 8, ["z"] = 1, ["name"] = "wool:yellow"}, {["x"] = 7, ["y"] = 8, ["param1"] = 81, ["z"] = 2, ["name"] = "default:steelblock"}, {["x"] = 7, ["y"] = 8, ["param1"] = 81, ["z"] = 3, ["name"] = "default:steelblock"}, {["x"] = 7, ["y"] = 8, ["param1"] = 81, ["z"] = 4, ["name"] = "default:steelblock"}, {["x"] = 7, ["y"] = 8, ["param1"] = 81, ["z"] = 5, ["name"] = "default:steelblock"}, {["x"] = 7, ["y"] = 8, ["param1"] = 81, ["z"] = 6, ["name"] = "default:steelblock"}, {["x"] = 7, ["y"] = 8, ["param1"] = 81, ["z"] = 7, ["name"] = "default:steelblock"}, {["x"] = 7, ["y"] = 8, ["param1"] = 81, ["z"] = 8, ["name"] = "default:steelblock"}, {["x"] = 7, ["y"] = 8, ["param1"] = 81, ["z"] = 9, ["name"] = "default:steelblock"}, {["x"] = 7, ["y"] = 8, ["param1"] = 81, ["z"] = 10, ["name"] = "default:steelblock"}, {["x"] = 7, ["y"] = 8, ["param1"] = 81, ["z"] = 11, ["name"] = "default:steelblock"}, {["x"] = 7, ["y"] = 8, ["param1"] = 81, ["z"] = 12, ["name"] = "default:steelblock"}, {["x"] = 7, ["y"] = 8, ["param1"] = 81, ["z"] = 13, ["name"] = "default:steelblock"}, {["x"] = 7, ["y"] = 8, ["z"] = 14, ["name"] = "wool:red"}, {["x"] = 7, ["y"] = 8, ["z"] = 15, ["name"] = "wool:red"}, {["x"] = 7, ["y"] = 9, ["param1"] = 81, ["z"] = 2, ["name"] = "default:steelblock"}, {["x"] = 7, ["y"] = 9, ["param1"] = 81, ["z"] = 3, ["name"] = "default:steelblock"}, {["x"] = 7, ["y"] = 9, ["param1"] = 81, ["z"] = 4, ["name"] = "default:steelblock"}, {["x"] = 7, ["y"] = 9, ["param1"] = 81, ["z"] = 5, ["name"] = "default:steelblock"}, {["x"] = 7, ["y"] = 9, ["param1"] = 81, ["z"] = 6, ["name"] = "default:steelblock"}, {["x"] = 7, ["y"] = 9, ["param1"] = 81, ["z"] = 7, ["name"] = "default:steelblock"}, {["x"] = 7, ["y"] = 9, ["param1"] = 81, ["z"] = 8, ["name"] = "default:steelblock"}, {["x"] = 7, ["y"] = 9, ["param1"] = 81, ["z"] = 9, ["name"] = "default:steelblock"}, {["x"] = 7, ["y"] = 9, ["param1"] = 81, ["z"] = 10, ["name"] = "default:steelblock"}, {["x"] = 7, ["y"] = 9, ["param1"] = 81, ["z"] = 11, ["name"] = "default:steelblock"}, {["x"] = 7, ["y"] = 9, ["param1"] = 81, ["z"] = 12, ["name"] = "default:steelblock"}, {["x"] = 7, ["y"] = 9, ["param1"] = 81, ["z"] = 13, ["name"] = "default:steelblock"}, {["x"] = 7, ["y"] = 10, ["param1"] = 81, ["z"] = 2, ["name"] = "default:steelblock"}, {["x"] = 7, ["y"] = 10, ["param1"] = 81, ["z"] = 3, ["name"] = "default:steelblock"}, {["x"] = 7, ["y"] = 10, ["param1"] = 81, ["z"] = 4, ["name"] = "default:steelblock"}, {["x"] = 7, ["y"] = 10, ["param1"] = 81, ["z"] = 5, ["name"] = "default:steelblock"}, {["x"] = 7, ["y"] = 10, ["param1"] = 81, ["z"] = 6, ["name"] = "default:steelblock"}, {["x"] = 7, ["y"] = 10, ["param1"] = 81, ["z"] = 7, ["name"] = "default:steelblock"}, {["x"] = 7, ["y"] = 10, ["param1"] = 81, ["z"] = 8, ["name"] = "default:steelblock"}, {["x"] = 7, ["y"] = 10, ["param1"] = 81, ["z"] = 9, ["name"] = "default:steelblock"}, {["x"] = 7, ["y"] = 10, ["param1"] = 81, ["z"] = 10, ["name"] = "default:steelblock"}, {["x"] = 7, ["y"] = 10, ["param1"] = 81, ["z"] = 11, ["name"] = "default:steelblock"}, {["x"] = 7, ["y"] = 10, ["param1"] = 81, ["z"] = 12, ["name"] = "default:steelblock"}, {["x"] = 7, ["y"] = 10, ["param1"] = 81, ["z"] = 13, ["name"] = "default:steelblock"}, {["x"] = 7, ["y"] = 11, ["z"] = 1, ["name"] = "wool:grey"}, {["x"] = 7, ["y"] = 11, ["param1"] = 81, ["z"] = 2, ["name"] = "default:steelblock"}, {["x"] = 7, ["y"] = 11, ["param1"] = 81, ["z"] = 3, ["name"] = "default:steelblock"}, {["x"] = 7, ["y"] = 11, ["param1"] = 81, ["z"] = 4, ["name"] = "default:steelblock"}, {["x"] = 7, ["y"] = 11, ["param1"] = 81, ["z"] = 5, ["name"] = "default:steelblock"}, {["x"] = 7, ["y"] = 11, ["param1"] = 81, ["z"] = 6, ["name"] = "default:steelblock"}, {["x"] = 7, ["y"] = 11, ["param1"] = 81, ["z"] = 7, ["name"] = "default:steelblock"}, {["x"] = 7, ["y"] = 11, ["param1"] = 81, ["z"] = 8, ["name"] = "default:steelblock"}, {["x"] = 7, ["y"] = 11, ["param1"] = 81, ["z"] = 9, ["name"] = "default:steelblock"}, {["x"] = 7, ["y"] = 11, ["param1"] = 81, ["z"] = 10, ["name"] = "default:steelblock"}, {["x"] = 7, ["y"] = 11, ["param1"] = 81, ["z"] = 11, ["name"] = "default:steelblock"}, {["x"] = 7, ["y"] = 11, ["param1"] = 81, ["z"] = 12, ["name"] = "default:steelblock"}, {["x"] = 7, ["y"] = 11, ["param1"] = 81, ["z"] = 13, ["name"] = "default:steelblock"}, {["x"] = 7, ["y"] = 11, ["z"] = 14, ["name"] = "wool:grey"}, {["x"] = 7, ["y"] = 12, ["z"] = 1, ["name"] = "wool:grey"}, {["x"] = 7, ["y"] = 12, ["param1"] = 81, ["z"] = 2, ["name"] = "default:steelblock"}, {["x"] = 7, ["y"] = 12, ["param1"] = 81, ["z"] = 3, ["name"] = "default:steelblock"}, {["x"] = 7, ["y"] = 12, ["param1"] = 81, ["z"] = 4, ["name"] = "default:steelblock"}, {["x"] = 7, ["y"] = 12, ["param1"] = 81, ["z"] = 5, ["name"] = "default:steelblock"}, {["x"] = 7, ["y"] = 12, ["param1"] = 81, ["z"] = 6, ["name"] = "default:steelblock"}, {["x"] = 7, ["y"] = 12, ["param1"] = 81, ["z"] = 7, ["name"] = "default:steelblock"}, {["x"] = 7, ["y"] = 12, ["param1"] = 81, ["z"] = 8, ["name"] = "default:steelblock"}, {["x"] = 7, ["y"] = 12, ["param1"] = 81, ["z"] = 9, ["name"] = "default:steelblock"}, {["x"] = 7, ["y"] = 12, ["param1"] = 81, ["z"] = 10, ["name"] = "default:steelblock"}, {["x"] = 7, ["y"] = 12, ["param1"] = 81, ["z"] = 11, ["name"] = "default:steelblock"}, {["x"] = 7, ["y"] = 12, ["param1"] = 81, ["z"] = 12, ["name"] = "default:steelblock"}, {["x"] = 7, ["y"] = 12, ["param1"] = 81, ["z"] = 13, ["name"] = "default:steelblock"}, {["x"] = 7, ["y"] = 12, ["z"] = 14, ["name"] = "wool:grey"}, {["x"] = 7, ["y"] = 13, ["z"] = 2, ["name"] = "default:steelblock"}, {["x"] = 7, ["y"] = 13, ["z"] = 3, ["name"] = "default:steelblock"}, {["x"] = 7, ["y"] = 13, ["z"] = 4, ["name"] = "default:steelblock"}, {["x"] = 7, ["y"] = 13, ["z"] = 5, ["name"] = "default:steelblock"}, {["x"] = 7, ["y"] = 13, ["z"] = 6, ["name"] = "default:steelblock"}, {["x"] = 7, ["y"] = 13, ["z"] = 7, ["name"] = "default:steelblock"}, {["x"] = 7, ["y"] = 13, ["z"] = 8, ["name"] = "default:steelblock"}, {["x"] = 7, ["y"] = 13, ["z"] = 9, ["name"] = "default:steelblock"}, {["x"] = 7, ["y"] = 13, ["z"] = 10, ["name"] = "default:steelblock"}, {["x"] = 7, ["y"] = 13, ["z"] = 11, ["name"] = "default:steelblock"}, {["x"] = 7, ["y"] = 13, ["z"] = 12, ["name"] = "default:steelblock"}, {["x"] = 7, ["y"] = 13, ["z"] = 13, ["name"] = "default:steelblock"}, {["x"] = 7, ["y"] = 14, ["z"] = 3, ["name"] = "default:steelblock"}, {["x"] = 7, ["y"] = 14, ["z"] = 4, ["name"] = "default:steelblock"}, {["x"] = 7, ["y"] = 14, ["z"] = 5, ["name"] = "default:steelblock"}, {["x"] = 7, ["y"] = 14, ["z"] = 6, ["name"] = "default:steelblock"}, {["x"] = 7, ["y"] = 15, ["z"] = 3, ["name"] = "default:steelblock"}, {["x"] = 7, ["y"] = 15, ["z"] = 4, ["name"] = "default:steelblock"}, {["x"] = 7, ["y"] = 15, ["z"] = 5, ["name"] = "default:steelblock"}, {["x"] = 7, ["y"] = 15, ["z"] = 6, ["name"] = "default:steelblock"}, {["x"] = 8, ["y"] = 2, ["z"] = 2, ["name"] = "default:steelblock"}, {["x"] = 8, ["y"] = 2, ["z"] = 3, ["name"] = "default:steelblock"}, {["x"] = 8, ["y"] = 2, ["z"] = 4, ["name"] = "default:steelblock"}, {["x"] = 8, ["y"] = 2, ["z"] = 5, ["name"] = "default:steelblock"}, {["x"] = 8, ["y"] = 2, ["z"] = 6, ["name"] = "default:steelblock"}, {["x"] = 8, ["y"] = 2, ["z"] = 7, ["name"] = "default:steelblock"}, {["x"] = 8, ["y"] = 2, ["z"] = 8, ["name"] = "default:steelblock"}, {["x"] = 8, ["y"] = 2, ["z"] = 9, ["name"] = "default:steelblock"}, {["x"] = 8, ["y"] = 2, ["z"] = 10, ["name"] = "default:steelblock"}, {["x"] = 8, ["y"] = 2, ["z"] = 11, ["name"] = "default:steelblock"}, {["x"] = 8, ["y"] = 2, ["z"] = 12, ["name"] = "default:steelblock"}, {["x"] = 8, ["y"] = 2, ["z"] = 13, ["name"] = "default:steelblock"}, {["x"] = 8, ["y"] = 3, ["param1"] = 81, ["z"] = 2, ["name"] = "default:steelblock"}, {["x"] = 8, ["y"] = 3, ["param1"] = 81, ["z"] = 3, ["name"] = "default:steelblock"}, {["x"] = 8, ["y"] = 3, ["param1"] = 81, ["z"] = 4, ["name"] = "default:steelblock"}, {["x"] = 8, ["y"] = 3, ["param1"] = 81, ["z"] = 5, ["name"] = "default:steelblock"}, {["x"] = 8, ["y"] = 3, ["param1"] = 81, ["z"] = 6, ["name"] = "default:steelblock"}, {["x"] = 8, ["y"] = 3, ["param1"] = 81, ["z"] = 7, ["name"] = "default:steelblock"}, {["x"] = 8, ["y"] = 3, ["param1"] = 81, ["z"] = 8, ["name"] = "default:steelblock"}, {["x"] = 8, ["y"] = 3, ["param1"] = 81, ["z"] = 9, ["name"] = "default:steelblock"}, {["x"] = 8, ["y"] = 3, ["param1"] = 81, ["z"] = 10, ["name"] = "default:steelblock"}, {["x"] = 8, ["y"] = 3, ["param1"] = 81, ["z"] = 11, ["name"] = "default:steelblock"}, {["x"] = 8, ["y"] = 3, ["param1"] = 81, ["z"] = 12, ["name"] = "default:steelblock"}, {["x"] = 8, ["y"] = 3, ["param1"] = 81, ["z"] = 13, ["name"] = "default:steelblock"}, {["x"] = 8, ["y"] = 4, ["param1"] = 81, ["z"] = 2, ["name"] = "default:steelblock"}, {["x"] = 8, ["y"] = 4, ["param1"] = 81, ["z"] = 3, ["name"] = "default:steelblock"}, {["x"] = 8, ["y"] = 4, ["param1"] = 81, ["z"] = 4, ["name"] = "default:steelblock"}, {["x"] = 8, ["y"] = 4, ["param1"] = 81, ["z"] = 5, ["name"] = "default:steelblock"}, {["x"] = 8, ["y"] = 4, ["param1"] = 81, ["z"] = 6, ["name"] = "default:steelblock"}, {["x"] = 8, ["y"] = 4, ["param1"] = 81, ["z"] = 7, ["name"] = "default:steelblock"}, {["x"] = 8, ["y"] = 4, ["param1"] = 81, ["z"] = 8, ["name"] = "default:steelblock"}, {["x"] = 8, ["y"] = 4, ["param1"] = 81, ["z"] = 9, ["name"] = "default:steelblock"}, {["x"] = 8, ["y"] = 4, ["param1"] = 81, ["z"] = 10, ["name"] = "default:steelblock"}, {["x"] = 8, ["y"] = 4, ["param1"] = 81, ["z"] = 11, ["name"] = "default:steelblock"}, {["x"] = 8, ["y"] = 4, ["param1"] = 81, ["z"] = 12, ["name"] = "default:steelblock"}, {["x"] = 8, ["y"] = 4, ["param1"] = 81, ["z"] = 13, ["name"] = "default:steelblock"}, {["x"] = 8, ["y"] = 5, ["z"] = 1, ["name"] = "wool:grey"}, {["x"] = 8, ["y"] = 5, ["param1"] = 81, ["z"] = 2, ["name"] = "default:steelblock"}, {["x"] = 8, ["y"] = 5, ["param1"] = 81, ["z"] = 3, ["name"] = "default:steelblock"}, {["x"] = 8, ["y"] = 5, ["param1"] = 81, ["z"] = 4, ["name"] = "default:steelblock"}, {["x"] = 8, ["y"] = 5, ["param1"] = 81, ["z"] = 5, ["name"] = "default:steelblock"}, {["x"] = 8, ["y"] = 5, ["param1"] = 81, ["z"] = 6, ["name"] = "default:steelblock"}, {["x"] = 8, ["y"] = 5, ["param1"] = 81, ["z"] = 7, ["name"] = "default:steelblock"}, {["x"] = 8, ["y"] = 5, ["param1"] = 81, ["z"] = 8, ["name"] = "default:steelblock"}, {["x"] = 8, ["y"] = 5, ["param1"] = 81, ["z"] = 9, ["name"] = "default:steelblock"}, {["x"] = 8, ["y"] = 5, ["param1"] = 81, ["z"] = 10, ["name"] = "default:steelblock"}, {["x"] = 8, ["y"] = 5, ["param1"] = 81, ["z"] = 11, ["name"] = "default:steelblock"}, {["x"] = 8, ["y"] = 5, ["param1"] = 81, ["z"] = 12, ["name"] = "default:steelblock"}, {["x"] = 8, ["y"] = 5, ["param1"] = 81, ["z"] = 13, ["name"] = "default:steelblock"}, {["x"] = 8, ["y"] = 5, ["z"] = 14, ["name"] = "wool:grey"}, {["x"] = 8, ["y"] = 6, ["z"] = 1, ["name"] = "wool:grey"}, {["x"] = 8, ["y"] = 6, ["param1"] = 81, ["z"] = 2, ["name"] = "default:steelblock"}, {["x"] = 8, ["y"] = 6, ["param1"] = 81, ["z"] = 3, ["name"] = "default:steelblock"}, {["x"] = 8, ["y"] = 6, ["param1"] = 81, ["z"] = 4, ["name"] = "default:steelblock"}, {["x"] = 8, ["y"] = 6, ["param1"] = 81, ["z"] = 5, ["name"] = "default:steelblock"}, {["x"] = 8, ["y"] = 6, ["param1"] = 81, ["z"] = 6, ["name"] = "default:steelblock"}, {["x"] = 8, ["y"] = 6, ["param1"] = 81, ["z"] = 7, ["name"] = "default:steelblock"}, {["x"] = 8, ["y"] = 6, ["param1"] = 81, ["z"] = 8, ["name"] = "default:steelblock"}, {["x"] = 8, ["y"] = 6, ["param1"] = 81, ["z"] = 9, ["name"] = "default:steelblock"}, {["x"] = 8, ["y"] = 6, ["param1"] = 81, ["z"] = 10, ["name"] = "default:steelblock"}, {["x"] = 8, ["y"] = 6, ["param1"] = 81, ["z"] = 11, ["name"] = "default:steelblock"}, {["x"] = 8, ["y"] = 6, ["param1"] = 81, ["z"] = 12, ["name"] = "default:steelblock"}, {["x"] = 8, ["y"] = 6, ["param1"] = 81, ["z"] = 13, ["name"] = "default:steelblock"}, {["x"] = 8, ["y"] = 6, ["z"] = 14, ["name"] = "wool:grey"}, {["x"] = 8, ["y"] = 7, ["param1"] = 94, ["z"] = 0, ["name"] = "wool:yellow"}, {["x"] = 8, ["y"] = 7, ["z"] = 1, ["name"] = "wool:yellow"}, {["x"] = 8, ["y"] = 7, ["param1"] = 81, ["z"] = 2, ["name"] = "default:steelblock"}, {["x"] = 8, ["y"] = 7, ["param1"] = 81, ["z"] = 3, ["name"] = "default:steelblock"}, {["x"] = 8, ["y"] = 7, ["param1"] = 81, ["z"] = 4, ["name"] = "default:steelblock"}, {["x"] = 8, ["y"] = 7, ["param1"] = 81, ["z"] = 5, ["name"] = "default:steelblock"}, {["x"] = 8, ["y"] = 7, ["param1"] = 81, ["z"] = 6, ["name"] = "default:steelblock"}, {["x"] = 8, ["y"] = 7, ["param1"] = 81, ["z"] = 7, ["name"] = "default:steelblock"}, {["x"] = 8, ["y"] = 7, ["param1"] = 81, ["z"] = 8, ["name"] = "default:steelblock"}, {["x"] = 8, ["y"] = 7, ["param1"] = 81, ["z"] = 9, ["name"] = "default:steelblock"}, {["x"] = 8, ["y"] = 7, ["param1"] = 81, ["z"] = 10, ["name"] = "default:steelblock"}, {["x"] = 8, ["y"] = 7, ["param1"] = 81, ["z"] = 11, ["name"] = "default:steelblock"}, {["x"] = 8, ["y"] = 7, ["param1"] = 81, ["z"] = 12, ["name"] = "default:steelblock"}, {["x"] = 8, ["y"] = 7, ["param1"] = 81, ["z"] = 13, ["name"] = "default:steelblock"}, {["x"] = 8, ["y"] = 7, ["z"] = 14, ["name"] = "wool:red"}, {["x"] = 8, ["y"] = 7, ["param1"] = 97, ["z"] = 15, ["name"] = "wool:red"}, {["x"] = 8, ["y"] = 8, ["param1"] = 94, ["z"] = 0, ["name"] = "wool:yellow"}, {["x"] = 8, ["y"] = 8, ["z"] = 1, ["name"] = "wool:yellow"}, {["x"] = 8, ["y"] = 8, ["param1"] = 81, ["z"] = 2, ["name"] = "default:steelblock"}, {["x"] = 8, ["y"] = 8, ["param1"] = 81, ["z"] = 3, ["name"] = "default:steelblock"}, {["x"] = 8, ["y"] = 8, ["param1"] = 81, ["z"] = 4, ["name"] = "default:steelblock"}, {["x"] = 8, ["y"] = 8, ["param1"] = 81, ["z"] = 5, ["name"] = "default:steelblock"}, {["x"] = 8, ["y"] = 8, ["param1"] = 81, ["z"] = 6, ["name"] = "default:steelblock"}, {["x"] = 8, ["y"] = 8, ["param1"] = 81, ["z"] = 7, ["name"] = "default:steelblock"}, {["x"] = 8, ["y"] = 8, ["param1"] = 81, ["z"] = 8, ["name"] = "default:steelblock"}, {["x"] = 8, ["y"] = 8, ["param1"] = 81, ["z"] = 9, ["name"] = "default:steelblock"}, {["x"] = 8, ["y"] = 8, ["param1"] = 81, ["z"] = 10, ["name"] = "default:steelblock"}, {["x"] = 8, ["y"] = 8, ["param1"] = 81, ["z"] = 11, ["name"] = "default:steelblock"}, {["x"] = 8, ["y"] = 8, ["param1"] = 81, ["z"] = 12, ["name"] = "default:steelblock"}, {["x"] = 8, ["y"] = 8, ["param1"] = 81, ["z"] = 13, ["name"] = "default:steelblock"}, {["x"] = 8, ["y"] = 8, ["z"] = 14, ["name"] = "wool:red"}, {["x"] = 8, ["y"] = 8, ["z"] = 15, ["name"] = "wool:red"}, {["x"] = 8, ["y"] = 9, ["z"] = 1, ["name"] = "wool:yellow"}, {["x"] = 8, ["y"] = 9, ["param1"] = 81, ["z"] = 2, ["name"] = "default:steelblock"}, {["x"] = 8, ["y"] = 9, ["param1"] = 81, ["z"] = 3, ["name"] = "default:steelblock"}, {["x"] = 8, ["y"] = 9, ["param1"] = 81, ["z"] = 4, ["name"] = "default:steelblock"}, {["x"] = 8, ["y"] = 9, ["param1"] = 81, ["z"] = 5, ["name"] = "default:steelblock"}, {["x"] = 8, ["y"] = 9, ["param1"] = 81, ["z"] = 6, ["name"] = "default:steelblock"}, {["x"] = 8, ["y"] = 9, ["param1"] = 81, ["z"] = 7, ["name"] = "default:steelblock"}, {["x"] = 8, ["y"] = 9, ["param1"] = 81, ["z"] = 8, ["name"] = "default:steelblock"}, {["x"] = 8, ["y"] = 9, ["param1"] = 81, ["z"] = 9, ["name"] = "default:steelblock"}, {["x"] = 8, ["y"] = 9, ["param1"] = 81, ["z"] = 10, ["name"] = "default:steelblock"}, {["x"] = 8, ["y"] = 9, ["param1"] = 81, ["z"] = 11, ["name"] = "default:steelblock"}, {["x"] = 8, ["y"] = 9, ["param1"] = 81, ["z"] = 12, ["name"] = "default:steelblock"}, {["x"] = 8, ["y"] = 9, ["param1"] = 81, ["z"] = 13, ["name"] = "default:steelblock"}, {["x"] = 8, ["y"] = 10, ["param1"] = 81, ["z"] = 2, ["name"] = "default:steelblock"}, {["x"] = 8, ["y"] = 10, ["param1"] = 81, ["z"] = 3, ["name"] = "default:steelblock"}, {["x"] = 8, ["y"] = 10, ["param1"] = 81, ["z"] = 4, ["name"] = "default:steelblock"}, {["x"] = 8, ["y"] = 10, ["param1"] = 81, ["z"] = 5, ["name"] = "default:steelblock"}, {["x"] = 8, ["y"] = 10, ["param1"] = 81, ["z"] = 6, ["name"] = "default:steelblock"}, {["x"] = 8, ["y"] = 10, ["param1"] = 81, ["z"] = 7, ["name"] = "default:steelblock"}, {["x"] = 8, ["y"] = 10, ["param1"] = 81, ["z"] = 8, ["name"] = "default:steelblock"}, {["x"] = 8, ["y"] = 10, ["param1"] = 81, ["z"] = 9, ["name"] = "default:steelblock"}, {["x"] = 8, ["y"] = 10, ["param1"] = 81, ["z"] = 10, ["name"] = "default:steelblock"}, {["x"] = 8, ["y"] = 10, ["param1"] = 81, ["z"] = 11, ["name"] = "default:steelblock"}, {["x"] = 8, ["y"] = 10, ["param1"] = 81, ["z"] = 12, ["name"] = "default:steelblock"}, {["x"] = 8, ["y"] = 10, ["param1"] = 81, ["z"] = 13, ["name"] = "default:steelblock"}, {["x"] = 8, ["y"] = 11, ["z"] = 1, ["name"] = "wool:grey"}, {["x"] = 8, ["y"] = 11, ["param1"] = 81, ["z"] = 2, ["name"] = "default:steelblock"}, {["x"] = 8, ["y"] = 11, ["param1"] = 81, ["z"] = 3, ["name"] = "default:steelblock"}, {["x"] = 8, ["y"] = 11, ["param1"] = 81, ["z"] = 4, ["name"] = "default:steelblock"}, {["x"] = 8, ["y"] = 11, ["param1"] = 81, ["z"] = 5, ["name"] = "default:steelblock"}, {["x"] = 8, ["y"] = 11, ["param1"] = 81, ["z"] = 6, ["name"] = "default:steelblock"}, {["x"] = 8, ["y"] = 11, ["param1"] = 81, ["z"] = 7, ["name"] = "default:steelblock"}, {["x"] = 8, ["y"] = 11, ["param1"] = 81, ["z"] = 8, ["name"] = "default:steelblock"}, {["x"] = 8, ["y"] = 11, ["param1"] = 81, ["z"] = 9, ["name"] = "default:steelblock"}, {["x"] = 8, ["y"] = 11, ["param1"] = 81, ["z"] = 10, ["name"] = "default:steelblock"}, {["x"] = 8, ["y"] = 11, ["param1"] = 81, ["z"] = 11, ["name"] = "default:steelblock"}, {["x"] = 8, ["y"] = 11, ["param1"] = 81, ["z"] = 12, ["name"] = "default:steelblock"}, {["x"] = 8, ["y"] = 11, ["param1"] = 81, ["z"] = 13, ["name"] = "default:steelblock"}, {["x"] = 8, ["y"] = 11, ["z"] = 14, ["name"] = "wool:grey"}, {["x"] = 8, ["y"] = 12, ["z"] = 1, ["name"] = "wool:grey"}, {["x"] = 8, ["y"] = 12, ["param1"] = 81, ["z"] = 2, ["name"] = "default:steelblock"}, {["x"] = 8, ["y"] = 12, ["param1"] = 81, ["z"] = 3, ["name"] = "default:steelblock"}, {["x"] = 8, ["y"] = 12, ["param1"] = 81, ["z"] = 4, ["name"] = "default:steelblock"}, {["x"] = 8, ["y"] = 12, ["param1"] = 81, ["z"] = 5, ["name"] = "default:steelblock"}, {["x"] = 8, ["y"] = 12, ["param1"] = 81, ["z"] = 6, ["name"] = "default:steelblock"}, {["x"] = 8, ["y"] = 12, ["param1"] = 81, ["z"] = 7, ["name"] = "default:steelblock"}, {["x"] = 8, ["y"] = 12, ["param1"] = 81, ["z"] = 8, ["name"] = "default:steelblock"}, {["x"] = 8, ["y"] = 12, ["param1"] = 81, ["z"] = 9, ["name"] = "default:steelblock"}, {["x"] = 8, ["y"] = 12, ["param1"] = 81, ["z"] = 10, ["name"] = "default:steelblock"}, {["x"] = 8, ["y"] = 12, ["param1"] = 81, ["z"] = 11, ["name"] = "default:steelblock"}, {["x"] = 8, ["y"] = 12, ["param1"] = 81, ["z"] = 12, ["name"] = "default:steelblock"}, {["x"] = 8, ["y"] = 12, ["param1"] = 81, ["z"] = 13, ["name"] = "default:steelblock"}, {["x"] = 8, ["y"] = 12, ["z"] = 14, ["name"] = "wool:grey"}, {["x"] = 8, ["y"] = 13, ["z"] = 2, ["name"] = "default:steelblock"}, {["x"] = 8, ["y"] = 13, ["z"] = 3, ["name"] = "default:steelblock"}, {["x"] = 8, ["y"] = 13, ["z"] = 4, ["name"] = "default:steelblock"}, {["x"] = 8, ["y"] = 13, ["z"] = 5, ["name"] = "default:steelblock"}, {["x"] = 8, ["y"] = 13, ["z"] = 6, ["name"] = "default:steelblock"}, {["x"] = 8, ["y"] = 13, ["z"] = 7, ["name"] = "default:steelblock"}, {["x"] = 8, ["y"] = 13, ["z"] = 8, ["name"] = "default:steelblock"}, {["x"] = 8, ["y"] = 13, ["z"] = 9, ["name"] = "default:steelblock"}, {["x"] = 8, ["y"] = 13, ["z"] = 10, ["name"] = "default:steelblock"}, {["x"] = 8, ["y"] = 13, ["z"] = 11, ["name"] = "default:steelblock"}, {["x"] = 8, ["y"] = 13, ["z"] = 12, ["name"] = "default:steelblock"}, {["x"] = 8, ["y"] = 13, ["z"] = 13, ["name"] = "default:steelblock"}, {["x"] = 8, ["y"] = 14, ["z"] = 3, ["name"] = "default:steelblock"}, {["x"] = 8, ["y"] = 14, ["z"] = 4, ["name"] = "default:steelblock"}, {["x"] = 8, ["y"] = 14, ["z"] = 5, ["name"] = "default:steelblock"}, {["x"] = 8, ["y"] = 14, ["z"] = 6, ["name"] = "default:steelblock"}, {["x"] = 8, ["y"] = 15, ["z"] = 3, ["name"] = "default:steelblock"}, {["x"] = 8, ["y"] = 15, ["z"] = 4, ["name"] = "default:steelblock"}, {["x"] = 8, ["y"] = 15, ["z"] = 5, ["name"] = "default:steelblock"}, {["x"] = 8, ["y"] = 15, ["z"] = 6, ["name"] = "default:steelblock"}, {["x"] = 9, ["y"] = 2, ["z"] = 2, ["name"] = "default:steelblock"}, {["x"] = 9, ["y"] = 2, ["z"] = 3, ["name"] = "default:steelblock"}, {["x"] = 9, ["y"] = 2, ["z"] = 4, ["name"] = "default:steelblock"}, {["x"] = 9, ["y"] = 2, ["z"] = 5, ["name"] = "default:steelblock"}, {["x"] = 9, ["y"] = 2, ["z"] = 6, ["name"] = "default:steelblock"}, {["x"] = 9, ["y"] = 2, ["z"] = 7, ["name"] = "default:steelblock"}, {["x"] = 9, ["y"] = 2, ["z"] = 8, ["name"] = "default:steelblock"}, {["x"] = 9, ["y"] = 2, ["z"] = 9, ["name"] = "default:steelblock"}, {["x"] = 9, ["y"] = 2, ["z"] = 10, ["name"] = "default:steelblock"}, {["x"] = 9, ["y"] = 2, ["z"] = 11, ["name"] = "default:steelblock"}, {["x"] = 9, ["y"] = 2, ["z"] = 12, ["name"] = "default:steelblock"}, {["x"] = 9, ["y"] = 2, ["z"] = 13, ["name"] = "default:steelblock"}, {["x"] = 9, ["y"] = 3, ["param1"] = 81, ["z"] = 2, ["name"] = "default:steelblock"}, {["x"] = 9, ["y"] = 3, ["param1"] = 81, ["z"] = 3, ["name"] = "default:steelblock"}, {["x"] = 9, ["y"] = 3, ["param1"] = 81, ["z"] = 4, ["name"] = "default:steelblock"}, {["x"] = 9, ["y"] = 3, ["param1"] = 81, ["z"] = 5, ["name"] = "default:steelblock"}, {["x"] = 9, ["y"] = 3, ["param1"] = 81, ["z"] = 6, ["name"] = "default:steelblock"}, {["x"] = 9, ["y"] = 3, ["param1"] = 81, ["z"] = 7, ["name"] = "default:steelblock"}, {["x"] = 9, ["y"] = 3, ["param1"] = 81, ["z"] = 8, ["name"] = "default:steelblock"}, {["x"] = 9, ["y"] = 3, ["param1"] = 81, ["z"] = 9, ["name"] = "default:steelblock"}, {["x"] = 9, ["y"] = 3, ["param1"] = 81, ["z"] = 10, ["name"] = "default:steelblock"}, {["x"] = 9, ["y"] = 3, ["param1"] = 81, ["z"] = 11, ["name"] = "default:steelblock"}, {["x"] = 9, ["y"] = 3, ["param1"] = 81, ["z"] = 12, ["name"] = "default:steelblock"}, {["x"] = 9, ["y"] = 3, ["param1"] = 81, ["z"] = 13, ["name"] = "default:steelblock"}, {["x"] = 9, ["y"] = 4, ["param1"] = 81, ["z"] = 2, ["name"] = "default:steelblock"}, {["x"] = 9, ["y"] = 4, ["param1"] = 81, ["z"] = 3, ["name"] = "default:steelblock"}, {["x"] = 9, ["y"] = 4, ["param1"] = 81, ["z"] = 4, ["name"] = "default:steelblock"}, {["x"] = 9, ["y"] = 4, ["param1"] = 81, ["z"] = 5, ["name"] = "default:steelblock"}, {["x"] = 9, ["y"] = 4, ["param1"] = 81, ["z"] = 6, ["name"] = "default:steelblock"}, {["x"] = 9, ["y"] = 4, ["param1"] = 81, ["z"] = 7, ["name"] = "default:steelblock"}, {["x"] = 9, ["y"] = 4, ["param1"] = 81, ["z"] = 8, ["name"] = "default:steelblock"}, {["x"] = 9, ["y"] = 4, ["param1"] = 81, ["z"] = 9, ["name"] = "default:steelblock"}, {["x"] = 9, ["y"] = 4, ["param1"] = 81, ["z"] = 10, ["name"] = "default:steelblock"}, {["x"] = 9, ["y"] = 4, ["param1"] = 81, ["z"] = 11, ["name"] = "default:steelblock"}, {["x"] = 9, ["y"] = 4, ["param1"] = 81, ["z"] = 12, ["name"] = "default:steelblock"}, {["x"] = 9, ["y"] = 4, ["param1"] = 81, ["z"] = 13, ["name"] = "default:steelblock"}, {["x"] = 9, ["y"] = 5, ["z"] = 1, ["name"] = "wool:grey"}, {["x"] = 9, ["y"] = 5, ["param1"] = 81, ["z"] = 2, ["name"] = "default:steelblock"}, {["x"] = 9, ["y"] = 5, ["param1"] = 81, ["z"] = 3, ["name"] = "default:steelblock"}, {["x"] = 9, ["y"] = 5, ["param1"] = 81, ["z"] = 4, ["name"] = "default:steelblock"}, {["x"] = 9, ["y"] = 5, ["param1"] = 81, ["z"] = 5, ["name"] = "default:steelblock"}, {["x"] = 9, ["y"] = 5, ["param1"] = 81, ["z"] = 6, ["name"] = "default:steelblock"}, {["x"] = 9, ["y"] = 5, ["param1"] = 81, ["z"] = 7, ["name"] = "default:steelblock"}, {["x"] = 9, ["y"] = 5, ["param1"] = 81, ["z"] = 8, ["name"] = "default:steelblock"}, {["x"] = 9, ["y"] = 5, ["param1"] = 81, ["z"] = 9, ["name"] = "default:steelblock"}, {["x"] = 9, ["y"] = 5, ["param1"] = 81, ["z"] = 10, ["name"] = "default:steelblock"}, {["x"] = 9, ["y"] = 5, ["param1"] = 81, ["z"] = 11, ["name"] = "default:steelblock"}, {["x"] = 9, ["y"] = 5, ["param1"] = 81, ["z"] = 12, ["name"] = "default:steelblock"}, {["x"] = 9, ["y"] = 5, ["param1"] = 81, ["z"] = 13, ["name"] = "default:steelblock"}, {["x"] = 9, ["y"] = 5, ["z"] = 14, ["name"] = "wool:grey"}, {["x"] = 9, ["y"] = 6, ["z"] = 1, ["name"] = "wool:grey"}, {["x"] = 9, ["y"] = 6, ["param1"] = 81, ["z"] = 2, ["name"] = "default:steelblock"}, {["x"] = 9, ["y"] = 6, ["param1"] = 81, ["z"] = 3, ["name"] = "default:steelblock"}, {["x"] = 9, ["y"] = 6, ["param1"] = 81, ["z"] = 4, ["name"] = "default:steelblock"}, {["x"] = 9, ["y"] = 6, ["param1"] = 81, ["z"] = 5, ["name"] = "default:steelblock"}, {["x"] = 9, ["y"] = 6, ["param1"] = 81, ["z"] = 6, ["name"] = "default:steelblock"}, {["x"] = 9, ["y"] = 6, ["param1"] = 81, ["z"] = 7, ["name"] = "default:steelblock"}, {["x"] = 9, ["y"] = 6, ["param1"] = 81, ["z"] = 8, ["name"] = "default:steelblock"}, {["x"] = 9, ["y"] = 6, ["param1"] = 81, ["z"] = 9, ["name"] = "default:steelblock"}, {["x"] = 9, ["y"] = 6, ["param1"] = 81, ["z"] = 10, ["name"] = "default:steelblock"}, {["x"] = 9, ["y"] = 6, ["param1"] = 81, ["z"] = 11, ["name"] = "default:steelblock"}, {["x"] = 9, ["y"] = 6, ["param1"] = 81, ["z"] = 12, ["name"] = "default:steelblock"}, {["x"] = 9, ["y"] = 6, ["param1"] = 81, ["z"] = 13, ["name"] = "default:steelblock"}, {["x"] = 9, ["y"] = 6, ["z"] = 14, ["name"] = "wool:grey"}, {["x"] = 9, ["y"] = 7, ["param1"] = 81, ["z"] = 2, ["name"] = "default:steelblock"}, {["x"] = 9, ["y"] = 7, ["param1"] = 81, ["z"] = 3, ["name"] = "default:steelblock"}, {["x"] = 9, ["y"] = 7, ["param1"] = 81, ["z"] = 4, ["name"] = "default:steelblock"}, {["x"] = 9, ["y"] = 7, ["param1"] = 81, ["z"] = 5, ["name"] = "default:steelblock"}, {["x"] = 9, ["y"] = 7, ["param1"] = 81, ["z"] = 6, ["name"] = "default:steelblock"}, {["x"] = 9, ["y"] = 7, ["param1"] = 81, ["z"] = 7, ["name"] = "default:steelblock"}, {["x"] = 9, ["y"] = 7, ["param1"] = 81, ["z"] = 8, ["name"] = "default:steelblock"}, {["x"] = 9, ["y"] = 7, ["param1"] = 81, ["z"] = 9, ["name"] = "default:steelblock"}, {["x"] = 9, ["y"] = 7, ["param1"] = 81, ["z"] = 10, ["name"] = "default:steelblock"}, {["x"] = 9, ["y"] = 7, ["param1"] = 81, ["z"] = 11, ["name"] = "default:steelblock"}, {["x"] = 9, ["y"] = 7, ["param1"] = 81, ["z"] = 12, ["name"] = "default:steelblock"}, {["x"] = 9, ["y"] = 7, ["param1"] = 81, ["z"] = 13, ["name"] = "default:steelblock"}, {["x"] = 9, ["y"] = 8, ["param1"] = 81, ["z"] = 2, ["name"] = "default:steelblock"}, {["x"] = 9, ["y"] = 8, ["param1"] = 81, ["z"] = 3, ["name"] = "default:steelblock"}, {["x"] = 9, ["y"] = 8, ["param1"] = 81, ["z"] = 4, ["name"] = "default:steelblock"}, {["x"] = 9, ["y"] = 8, ["param1"] = 81, ["z"] = 5, ["name"] = "default:steelblock"}, {["x"] = 9, ["y"] = 8, ["param1"] = 81, ["z"] = 6, ["name"] = "default:steelblock"}, {["x"] = 9, ["y"] = 8, ["param1"] = 81, ["z"] = 7, ["name"] = "default:steelblock"}, {["x"] = 9, ["y"] = 8, ["param1"] = 81, ["z"] = 8, ["name"] = "default:steelblock"}, {["x"] = 9, ["y"] = 8, ["param1"] = 81, ["z"] = 9, ["name"] = "default:steelblock"}, {["x"] = 9, ["y"] = 8, ["param1"] = 81, ["z"] = 10, ["name"] = "default:steelblock"}, {["x"] = 9, ["y"] = 8, ["param1"] = 81, ["z"] = 11, ["name"] = "default:steelblock"}, {["x"] = 9, ["y"] = 8, ["param1"] = 81, ["z"] = 12, ["name"] = "default:steelblock"}, {["x"] = 9, ["y"] = 8, ["param1"] = 81, ["z"] = 13, ["name"] = "default:steelblock"}, {["x"] = 9, ["y"] = 9, ["param1"] = 81, ["z"] = 2, ["name"] = "default:steelblock"}, {["x"] = 9, ["y"] = 9, ["param1"] = 81, ["z"] = 3, ["name"] = "default:steelblock"},