5:return {{["x"] = 0, ["y"] = 0, ["param1"] = 86, ["z"] = 0, ["name"] = "wool:grey"}, {["x"] = 0, ["y"] = 0, ["param1"] = 86, ["z"] = 1, ["name"] = "wool:grey"}, {["x"] = 0, ["y"] = 0, ["param1"] = 86, ["z"] = 14, ["name"] = "wool:grey"}, {["x"] = 0, ["y"] = 0, ["param1"] = 86, ["z"] = 15, ["name"] = "wool:grey"}, {["x"] = 0, ["y"] = 1, ["param1"] = 86, ["z"] = 0, ["name"] = "wool:grey"}, {["x"] = 0, ["y"] = 1, ["param1"] = 86, ["z"] = 1, ["name"] = "wool:grey"}, {["x"] = 0, ["y"] = 1, ["param1"] = 86, ["z"] = 2, ["name"] = "wool:grey"}, {["x"] = 0, ["y"] = 1, ["param1"] = 86, ["z"] = 3, ["name"] = "wool:grey"}, {["x"] = 0, ["y"] = 1, ["param1"] = 86, ["z"] = 4, ["name"] = "wool:grey"}, {["x"] = 0, ["y"] = 1, ["param1"] = 86, ["z"] = 5, ["name"] = "wool:grey"}, {["x"] = 0, ["y"] = 1, ["param1"] = 86, ["z"] = 6, ["name"] = "wool:grey"}, {["x"] = 0, ["y"] = 1, ["param1"] = 86, ["z"] = 7, ["name"] = "wool:grey"}, {["x"] = 0, ["y"] = 1, ["param1"] = 86, ["z"] = 8, ["name"] = "wool:grey"}, {["x"] = 0, ["y"] = 1, ["param1"] = 86, ["z"] = 9, ["name"] = "wool:grey"}, {["x"] = 0, ["y"] = 1, ["param1"] = 86, ["z"] = 10, ["name"] = "wool:grey"}, {["x"] = 0, ["y"] = 1, ["param1"] = 86, ["z"] = 11, ["name"] = "wool:grey"}, {["x"] = 0, ["y"] = 1, ["param1"] = 86, ["z"] = 12, ["name"] = "wool:grey"}, {["x"] = 0, ["y"] = 1, ["param1"] = 86, ["z"] = 13, ["name"] = "wool:grey"}, {["x"] = 0, ["y"] = 1, ["param1"] = 86, ["z"] = 14, ["name"] = "wool:grey"}, {["x"] = 0, ["y"] = 1, ["param1"] = 86, ["z"] = 15, ["name"] = "wool:grey"}, {["x"] = 0, ["y"] = 2, ["param1"] = 86, ["z"] = 0, ["name"] = "wool:grey"}, {["x"] = 0, ["y"] = 2, ["param1"] = 86, ["z"] = 1, ["name"] = "wool:grey"}, {["x"] = 0, ["y"] = 2, ["param1"] = 86, ["z"] = 2, ["name"] = "wool:grey"}, {["x"] = 0, ["y"] = 2, ["param1"] = 86, ["z"] = 3, ["name"] = "wool:grey"}, {["x"] = 0, ["y"] = 2, ["param1"] = 86, ["z"] = 4, ["name"] = "wool:grey"}, {["x"] = 0, ["y"] = 2, ["param1"] = 86, ["z"] = 5, ["name"] = "wool:grey"}, {["x"] = 0, ["y"] = 2, ["param1"] = 86, ["z"] = 6, ["name"] = "wool:grey"}, {["x"] = 0, ["y"] = 2, ["param1"] = 86, ["z"] = 7, ["name"] = "wool:grey"}, {["x"] = 0, ["y"] = 2, ["param1"] = 86, ["z"] = 8, ["name"] = "wool:grey"}, {["x"] = 0, ["y"] = 2, ["param1"] = 86, ["z"] = 9, ["name"] = "wool:grey"}, {["x"] = 0, ["y"] = 2, ["param1"] = 86, ["z"] = 10, ["name"] = "wool:grey"}, {["x"] = 0, ["y"] = 2, ["param1"] = 86, ["z"] = 11, ["name"] = "wool:grey"}, {["x"] = 0, ["y"] = 2, ["param1"] = 86, ["z"] = 12, ["name"] = "wool:grey"}, {["x"] = 0, ["y"] = 2, ["param1"] = 86, ["z"] = 13, ["name"] = "wool:grey"}, {["x"] = 0, ["y"] = 2, ["param1"] = 86, ["z"] = 14, ["name"] = "wool:grey"}, {["x"] = 0, ["y"] = 2, ["param1"] = 86, ["z"] = 15, ["name"] = "wool:grey"}, {["x"] = 0, ["y"] = 3, ["param1"] = 86, ["z"] = 0, ["name"] = "wool:grey"}, {["x"] = 0, ["y"] = 3, ["param1"] = 86, ["z"] = 1, ["name"] = "wool:grey"}, {["x"] = 0, ["y"] = 3, ["param1"] = 86, ["z"] = 14, ["name"] = "wool:grey"}, {["x"] = 0, ["y"] = 3, ["param1"] = 86, ["z"] = 15, ["name"] = "wool:grey"}, {["x"] = 0, ["y"] = 4, ["param1"] = 86, ["z"] = 0, ["name"] = "wool:grey"}, {["x"] = 0, ["y"] = 4, ["param1"] = 86, ["z"] = 1, ["name"] = "wool:grey"}, {["x"] = 0, ["y"] = 4, ["param1"] = 86, ["z"] = 14, ["name"] = "wool:grey"}, {["x"] = 0, ["y"] = 4, ["param1"] = 86, ["z"] = 15, ["name"] = "wool:grey"}, {["x"] = 0, ["y"] = 5, ["param1"] = 86, ["z"] = 0, ["name"] = "wool:grey"}, {["x"] = 0, ["y"] = 5, ["param1"] = 86, ["z"] = 1, ["name"] = "wool:grey"}, {["x"] = 0, ["y"] = 5, ["param1"] = 86, ["z"] = 14, ["name"] = "wool:grey"}, {["x"] = 0, ["y"] = 5, ["param1"] = 86, ["z"] = 15, ["name"] = "wool:grey"}, {["x"] = 0, ["y"] = 6, ["param1"] = 86, ["z"] = 0, ["name"] = "wool:grey"}, {["x"] = 0, ["y"] = 6, ["param1"] = 86, ["z"] = 1, ["name"] = "wool:grey"}, {["x"] = 0, ["y"] = 6, ["param1"] = 86, ["z"] = 14, ["name"] = "wool:grey"}, {["x"] = 0, ["y"] = 6, ["param1"] = 86, ["z"] = 15, ["name"] = "wool:grey"}, {["x"] = 0, ["y"] = 7, ["param1"] = 86, ["z"] = 0, ["name"] = "wool:grey"}, {["x"] = 0, ["y"] = 7, ["param1"] = 86, ["z"] = 1, ["name"] = "wool:grey"}, {["x"] = 0, ["y"] = 7, ["param1"] = 86, ["z"] = 14, ["name"] = "wool:grey"}, {["x"] = 0, ["y"] = 7, ["param1"] = 86, ["z"] = 15, ["name"] = "wool:grey"}, {["x"] = 0, ["y"] = 8, ["param1"] = 86, ["z"] = 0, ["name"] = "wool:grey"}, {["x"] = 0, ["y"] = 8, ["param1"] = 86, ["z"] = 1, ["name"] = "wool:grey"}, {["x"] = 0, ["y"] = 8, ["param1"] = 86, ["z"] = 14, ["name"] = "wool:grey"}, {["x"] = 0, ["y"] = 8, ["param1"] = 86, ["z"] = 15, ["name"] = "wool:grey"}, {["x"] = 0, ["y"] = 9, ["param1"] = 86, ["z"] = 0, ["name"] = "wool:grey"}, {["x"] = 0, ["y"] = 9, ["param1"] = 86, ["z"] = 1, ["name"] = "wool:grey"}, {["x"] = 0, ["y"] = 9, ["param1"] = 86, ["z"] = 2, ["name"] = "wool:grey"}, {["x"] = 0, ["y"] = 9, ["param1"] = 86, ["z"] = 3, ["name"] = "wool:grey"}, {["x"] = 0, ["y"] = 9, ["param1"] = 86, ["z"] = 4, ["name"] = "wool:grey"}, {["x"] = 0, ["y"] = 9, ["param1"] = 86, ["z"] = 5, ["name"] = "wool:grey"}, {["x"] = 0, ["y"] = 9, ["param1"] = 86, ["z"] = 6, ["name"] = "wool:grey"}, {["x"] = 0, ["y"] = 9, ["param1"] = 86, ["z"] = 7, ["name"] = "wool:grey"}, {["x"] = 0, ["y"] = 9, ["param1"] = 86, ["z"] = 8, ["name"] = "wool:grey"}, {["x"] = 0, ["y"] = 9, ["param1"] = 86, ["z"] = 9, ["name"] = "wool:grey"}, {["x"] = 0, ["y"] = 9, ["param1"] = 86, ["z"] = 10, ["name"] = "wool:grey"}, {["x"] = 0, ["y"] = 9, ["param1"] = 86, ["z"] = 11, ["name"] = "wool:grey"}, {["x"] = 0, ["y"] = 9, ["param1"] = 86, ["z"] = 12, ["name"] = "wool:grey"}, {["x"] = 0, ["y"] = 9, ["param1"] = 86, ["z"] = 13, ["name"] = "wool:grey"}, {["x"] = 0, ["y"] = 9, ["param1"] = 86, ["z"] = 14, ["name"] = "wool:grey"}, {["x"] = 0, ["y"] = 9, ["param1"] = 86, ["z"] = 15, ["name"] = "wool:grey"}, {["x"] = 0, ["y"] = 10, ["param1"] = 86, ["z"] = 0, ["name"] = "wool:grey"}, {["x"] = 0, ["y"] = 10, ["param1"] = 86, ["z"] = 1, ["name"] = "wool:grey"}, {["x"] = 0, ["y"] = 10, ["param1"] = 86, ["z"] = 2, ["name"] = "wool:grey"}, {["x"] = 0, ["y"] = 10, ["param1"] = 86, ["z"] = 3, ["name"] = "wool:grey"}, {["x"] = 0, ["y"] = 10, ["param1"] = 86, ["z"] = 4, ["name"] = "wool:grey"}, {["x"] = 0, ["y"] = 10, ["param1"] = 86, ["z"] = 5, ["name"] = "wool:grey"}, {["x"] = 0, ["y"] = 10, ["param1"] = 86, ["z"] = 6, ["name"] = "wool:grey"}, {["x"] = 0, ["y"] = 10, ["param1"] = 86, ["z"] = 7, ["name"] = "wool:grey"}, {["x"] = 0, ["y"] = 10, ["param1"] = 86, ["z"] = 8, ["name"] = "wool:grey"}, {["x"] = 0, ["y"] = 10, ["param1"] = 86, ["z"] = 9, ["name"] = "wool:grey"}, {["x"] = 0, ["y"] = 10, ["param1"] = 86, ["z"] = 10, ["name"] = "wool:grey"}, {["x"] = 0, ["y"] = 10, ["param1"] = 86, ["z"] = 11, ["name"] = "wool:grey"}, {["x"] = 0, ["y"] = 10, ["param1"] = 86, ["z"] = 12, ["name"] = "wool:grey"}, {["x"] = 0, ["y"] = 10, ["param1"] = 86, ["z"] = 13, ["name"] = "wool:grey"}, {["x"] = 0, ["y"] = 10, ["param1"] = 86, ["z"] = 14, ["name"] = "wool:grey"}, {["x"] = 0, ["y"] = 10, ["param1"] = 86, ["z"] = 15, ["name"] = "wool:grey"}, {["x"] = 0, ["y"] = 11, ["param1"] = 86, ["z"] = 0, ["name"] = "wool:grey"}, {["x"] = 0, ["y"] = 11, ["param1"] = 86, ["z"] = 1, ["name"] = "wool:grey"}, {["x"] = 0, ["y"] = 11, ["param1"] = 86, ["z"] = 14, ["name"] = "wool:grey"}, {["x"] = 0, ["y"] = 11, ["param1"] = 86, ["z"] = 15, ["name"] = "wool:grey"}, {["x"] = 0, ["y"] = 12, ["param1"] = 86, ["z"] = 0, ["name"] = "wool:grey"}, {["x"] = 0, ["y"] = 12, ["param1"] = 86, ["z"] = 1, ["name"] = "wool:grey"}, {["x"] = 0, ["y"] = 12, ["param1"] = 86, ["z"] = 14, ["name"] = "wool:grey"}, {["x"] = 0, ["y"] = 12, ["param1"] = 86, ["z"] = 15, ["name"] = "wool:grey"}, {["x"] = 0, ["y"] = 13, ["param1"] = 86, ["z"] = 0, ["name"] = "wool:grey"}, {["x"] = 0, ["y"] = 13, ["param1"] = 86, ["z"] = 1, ["name"] = "wool:grey"}, {["x"] = 0, ["y"] = 13, ["param1"] = 86, ["z"] = 14, ["name"] = "wool:grey"}, {["x"] = 0, ["y"] = 13, ["param1"] = 86, ["z"] = 15, ["name"] = "wool:grey"}, {["x"] = 0, ["y"] = 14, ["param1"] = 86, ["z"] = 0, ["name"] = "wool:grey"}, {["x"] = 0, ["y"] = 14, ["param1"] = 86, ["z"] = 1, ["name"] = "wool:grey"}, {["x"] = 0, ["y"] = 14, ["param1"] = 86, ["z"] = 14, ["name"] = "wool:grey"}, {["x"] = 0, ["y"] = 14, ["param1"] = 86, ["z"] = 15, ["name"] = "wool:grey"}, {["x"] = 0, ["y"] = 15, ["param1"] = 86, ["z"] = 0, ["name"] = "wool:grey"}, {["x"] = 0, ["y"] = 15, ["param1"] = 86, ["z"] = 1, ["name"] = "wool:grey"}, {["x"] = 0, ["y"] = 15, ["param1"] = 86, ["z"] = 14, ["name"] = "wool:grey"}, {["x"] = 0, ["y"] = 15, ["param1"] = 86, ["z"] = 15, ["name"] = "wool:grey"}, {["x"] = 1, ["y"] = 0, ["param1"] = 86, ["z"] = 0, ["name"] = "wool:grey"}, {["x"] = 1, ["y"] = 0, ["param1"] = 86, ["z"] = 1, ["name"] = "wool:grey"}, {["x"] = 1, ["y"] = 0, ["param1"] = 86, ["z"] = 14, ["name"] = "wool:grey"}, {["x"] = 1, ["y"] = 0, ["param1"] = 86, ["z"] = 15, ["name"] = "wool:grey"}, {["x"] = 1, ["y"] = 1, ["param1"] = 86, ["z"] = 0, ["name"] = "wool:grey"}, {["x"] = 1, ["y"] = 1, ["param1"] = 86, ["z"] = 1, ["name"] = "wool:grey"}, {["x"] = 1, ["y"] = 1, ["param1"] = 86, ["z"] = 2, ["name"] = "wool:grey"}, {["x"] = 1, ["y"] = 1, ["param1"] = 86, ["z"] = 3, ["name"] = "wool:grey"}, {["x"] = 1, ["y"] = 1, ["param1"] = 86, ["z"] = 4, ["name"] = "wool:grey"}, {["x"] = 1, ["y"] = 1, ["param1"] = 86, ["z"] = 5, ["name"] = "wool:grey"}, {["x"] = 1, ["y"] = 1, ["param1"] = 86, ["z"] = 6, ["name"] = "wool:grey"}, {["x"] = 1, ["y"] = 1, ["param1"] = 86, ["z"] = 7, ["name"] = "wool:grey"}, {["x"] = 1, ["y"] = 1, ["param1"] = 86, ["z"] = 8, ["name"] = "wool:grey"}, {["x"] = 1, ["y"] = 1, ["param1"] = 86, ["z"] = 9, ["name"] = "wool:grey"}, {["x"] = 1, ["y"] = 1, ["param1"] = 86, ["z"] = 10, ["name"] = "wool:grey"}, {["x"] = 1, ["y"] = 1, ["param1"] = 86, ["z"] = 11, ["name"] = "wool:grey"}, {["x"] = 1, ["y"] = 1, ["param1"] = 86, ["z"] = 12, ["name"] = "wool:grey"}, {["x"] = 1, ["y"] = 1, ["param1"] = 86, ["z"] = 13, ["name"] = "wool:grey"}, {["x"] = 1, ["y"] = 1, ["param1"] = 86, ["z"] = 14, ["name"] = "wool:grey"}, {["x"] = 1, ["y"] = 1, ["param1"] = 86, ["z"] = 15, ["name"] = "wool:grey"}, {["x"] = 1, ["y"] = 2, ["param1"] = 86, ["z"] = 0, ["name"] = "wool:grey"}, {["x"] = 1, ["y"] = 2, ["param1"] = 86, ["z"] = 1, ["name"] = "wool:grey"}, {["x"] = 1, ["y"] = 2, ["param1"] = 86, ["z"] = 2, ["name"] = "wool:grey"}, {["x"] = 1, ["y"] = 2, ["param1"] = 86, ["z"] = 3, ["name"] = "wool:grey"}, {["x"] = 1, ["y"] = 2, ["param1"] = 86, ["z"] = 4, ["name"] = "wool:grey"}, {["x"] = 1, ["y"] = 2, ["param1"] = 86, ["z"] = 5, ["name"] = "wool:grey"}, {["x"] = 1, ["y"] = 2, ["param1"] = 86, ["z"] = 6, ["name"] = "wool:grey"}, {["x"] = 1, ["y"] = 2, ["param1"] = 86, ["z"] = 7, ["name"] = "wool:grey"}, {["x"] = 1, ["y"] = 2, ["param1"] = 86, ["z"] = 8, ["name"] = "wool:grey"}, {["x"] = 1, ["y"] = 2, ["param1"] = 86, ["z"] = 9, ["name"] = "wool:grey"}, {["x"] = 1, ["y"] = 2, ["param1"] = 86, ["z"] = 10, ["name"] = "wool:grey"}, {["x"] = 1, ["y"] = 2, ["param1"] = 86, ["z"] = 11, ["name"] = "wool:grey"}, {["x"] = 1, ["y"] = 2, ["param1"] = 86, ["z"] = 12, ["name"] = "wool:grey"}, {["x"] = 1, ["y"] = 2, ["param1"] = 86, ["z"] = 13, ["name"] = "wool:grey"}, {["x"] = 1, ["y"] = 2, ["param1"] = 86, ["z"] = 14, ["name"] = "wool:grey"}, {["x"] = 1, ["y"] = 2, ["param1"] = 86, ["z"] = 15, ["name"] = "wool:grey"}, {["x"] = 1, ["y"] = 3, ["param1"] = 86, ["z"] = 0, ["name"] = "wool:grey"}, {["x"] = 1, ["y"] = 3, ["param1"] = 86, ["z"] = 1, ["name"] = "wool:grey"}, {["x"] = 1, ["y"] = 3, ["param1"] = 86, ["z"] = 14, ["name"] = "wool:grey"}, {["x"] = 1, ["y"] = 3, ["param1"] = 86, ["z"] = 15, ["name"] = "wool:grey"}, {["x"] = 1, ["y"] = 4, ["param1"] = 86, ["z"] = 0, ["name"] = "wool:grey"}, {["x"] = 1, ["y"] = 4, ["param1"] = 86, ["z"] = 1, ["name"] = "wool:grey"}, {["x"] = 1, ["y"] = 4, ["param1"] = 86, ["z"] = 14, ["name"] = "wool:grey"}, {["x"] = 1, ["y"] = 4, ["param1"] = 86, ["z"] = 15, ["name"] = "wool:grey"}, {["x"] = 1, ["y"] = 5, ["param1"] = 86, ["z"] = 0, ["name"] = "wool:grey"}, {["x"] = 1, ["y"] = 5, ["param1"] = 86, ["z"] = 1, ["name"] = "wool:grey"}, {["x"] = 1, ["y"] = 5, ["param1"] = 86, ["z"] = 14, ["name"] = "wool:grey"}, {["x"] = 1, ["y"] = 5, ["param1"] = 86, ["z"] = 15, ["name"] = "wool:grey"}, {["x"] = 1, ["y"] = 6, ["param1"] = 86, ["z"] = 0, ["name"] = "wool:grey"}, {["x"] = 1, ["y"] = 6, ["param1"] = 86, ["z"] = 1, ["name"] = "wool:grey"}, {["x"] = 1, ["y"] = 6, ["param1"] = 86, ["z"] = 14, ["name"] = "wool:grey"}, {["x"] = 1, ["y"] = 6, ["param1"] = 86, ["z"] = 15, ["name"] = "wool:grey"}, {["x"] = 1, ["y"] = 7, ["param1"] = 86, ["z"] = 0, ["name"] = "wool:grey"}, {["x"] = 1, ["y"] = 7, ["param1"] = 86, ["z"] = 1, ["name"] = "wool:grey"}, {["x"] = 1, ["y"] = 7, ["param1"] = 86, ["z"] = 14, ["name"] = "wool:grey"}, {["x"] = 1, ["y"] = 7, ["param1"] = 86, ["z"] = 15, ["name"] = "wool:grey"}, {["x"] = 1, ["y"] = 8, ["param1"] = 86, ["z"] = 0, ["name"] = "wool:grey"}, {["x"] = 1, ["y"] = 8, ["param1"] = 86, ["z"] = 1, ["name"] = "wool:grey"}, {["x"] = 1, ["y"] = 8, ["param1"] = 86, ["z"] = 14, ["name"] = "wool:grey"}, {["x"] = 1, ["y"] = 8, ["param1"] = 86, ["z"] = 15, ["name"] = "wool:grey"}, {["x"] = 1, ["y"] = 9, ["param1"] = 86, ["z"] = 0, ["name"] = "wool:grey"}, {["x"] = 1, ["y"] = 9, ["param1"] = 86, ["z"] = 1, ["name"] = "wool:grey"}, {["x"] = 1, ["y"] = 9, ["param1"] = 86, ["z"] = 2, ["name"] = "wool:grey"}, {["x"] = 1, ["y"] = 9, ["param1"] = 86, ["z"] = 3, ["name"] = "wool:grey"}, {["x"] = 1, ["y"] = 9, ["param1"] = 86, ["z"] = 4, ["name"] = "wool:grey"}, {["x"] = 1, ["y"] = 9, ["param1"] = 86, ["z"] = 5, ["name"] = "wool:grey"}, {["x"] = 1, ["y"] = 9, ["param1"] = 86, ["z"] = 6, ["name"] = "wool:grey"}, {["x"] = 1, ["y"] = 9, ["param1"] = 86, ["z"] = 7, ["name"] = "wool:grey"}, {["x"] = 1, ["y"] = 9, ["param1"] = 86, ["z"] = 8, ["name"] = "wool:grey"}, {["x"] = 1, ["y"] = 9, ["param1"] = 86, ["z"] = 9, ["name"] = "wool:grey"}, {["x"] = 1, ["y"] = 9, ["param1"] = 86, ["z"] = 10, ["name"] = "wool:grey"}, {["x"] = 1, ["y"] = 9, ["param1"] = 86, ["z"] = 11, ["name"] = "wool:grey"}, {["x"] = 1, ["y"] = 9, ["param1"] = 86, ["z"] = 12, ["name"] = "wool:grey"}, {["x"] = 1, ["y"] = 9, ["param1"] = 86, ["z"] = 13, ["name"] = "wool:grey"}, {["x"] = 1, ["y"] = 9, ["param1"] = 86, ["z"] = 14, ["name"] = "wool:grey"}, {["x"] = 1, ["y"] = 9, ["param1"] = 86, ["z"] = 15, ["name"] = "wool:grey"}, {["x"] = 1, ["y"] = 10, ["param1"] = 86, ["z"] = 0, ["name"] = "wool:grey"}, {["x"] = 1, ["y"] = 10, ["param1"] = 86, ["z"] = 1, ["name"] = "wool:grey"}, {["x"] = 1, ["y"] = 10, ["param1"] = 86, ["z"] = 2, ["name"] = "wool:grey"}, {["x"] = 1, ["y"] = 10, ["param1"] = 86, ["z"] = 3, ["name"] = "wool:grey"}, {["x"] = 1, ["y"] = 10, ["param1"] = 86, ["z"] = 4, ["name"] = "wool:grey"}, {["x"] = 1, ["y"] = 10, ["param1"] = 86, ["z"] = 5, ["name"] = "wool:grey"}, {["x"] = 1, ["y"] = 10, ["param1"] = 86, ["z"] = 6, ["name"] = "wool:grey"}, {["x"] = 1, ["y"] = 10, ["param1"] = 86, ["z"] = 7, ["name"] = "wool:grey"}, {["x"] = 1, ["y"] = 10, ["param1"] = 86, ["z"] = 8, ["name"] = "wool:grey"}, {["x"] = 1, ["y"] = 10, ["param1"] = 86, ["z"] = 9, ["name"] = "wool:grey"}, {["x"] = 1, ["y"] = 10, ["param1"] = 86, ["z"] = 10, ["name"] = "wool:grey"}, {["x"] = 1, ["y"] = 10, ["param1"] = 86, ["z"] = 11, ["name"] = "wool:grey"}, {["x"] = 1, ["y"] = 10, ["param1"] = 86, ["z"] = 12, ["name"] = "wool:grey"}, {["x"] = 1, ["y"] = 10, ["param1"] = 86, ["z"] = 13, ["name"] = "wool:grey"}, {["x"] = 1, ["y"] = 10, ["param1"] = 86, ["z"] = 14, ["name"] = "wool:grey"}, {["x"] = 1, ["y"] = 10, ["param1"] = 86, ["z"] = 15, ["name"] = "wool:grey"}, {["x"] = 1, ["y"] = 11, ["param1"] = 86, ["z"] = 0, ["name"] = "wool:grey"}, {["x"] = 1, ["y"] = 11, ["param1"] = 86, ["z"] = 1, ["name"] = "wool:grey"}, {["x"] = 1, ["y"] = 11, ["param1"] = 86, ["z"] = 14, ["name"] = "wool:grey"}, {["x"] = 1, ["y"] = 11, ["param1"] = 86, ["z"] = 15, ["name"] = "wool:grey"}, {["x"] = 1, ["y"] = 12, ["param1"] = 86, ["z"] = 0, ["name"] = "wool:grey"}, {["x"] = 1, ["y"] = 12, ["param1"] = 86, ["z"] = 1, ["name"] = "wool:grey"}, {["x"] = 1, ["y"] = 12, ["param1"] = 86, ["z"] = 14, ["name"] = "wool:grey"}, {["x"] = 1, ["y"] = 12, ["param1"] = 86, ["z"] = 15, ["name"] = "wool:grey"}, {["x"] = 1, ["y"] = 13, ["param1"] = 86, ["z"] = 0, ["name"] = "wool:grey"}, {["x"] = 1, ["y"] = 13, ["param1"] = 86, ["z"] = 1, ["name"] = "wool:grey"}, {["x"] = 1, ["y"] = 13, ["param1"] = 93, ["z"] = 5, ["name"] = "wool:green"}, {["x"] = 1, ["y"] = 13, ["param1"] = 93, ["z"] = 6, ["name"] = "wool:green"}, {["x"] = 1, ["y"] = 13, ["param1"] = 93, ["z"] = 7, ["name"] = "wool:green"}, {["x"] = 1, ["y"] = 13, ["param1"] = 93, ["z"] = 8, ["name"] = "wool:green"}, {["x"] = 1, ["y"] = 13, ["param1"] = 93, ["z"] = 9, ["name"] = "wool:green"}, {["x"] = 1, ["y"] = 13, ["param1"] = 93, ["z"] = 10, ["name"] = "wool:green"}, {["x"] = 1, ["y"] = 13, ["param1"] = 93, ["z"] = 11, ["name"] = "wool:green"}, {["x"] = 1, ["y"] = 13, ["param1"] = 86, ["z"] = 14, ["name"] = "wool:grey"}, {["x"] = 1, ["y"] = 13, ["param1"] = 86, ["z"] = 15, ["name"] = "wool:grey"}, {["x"] = 1, ["y"] = 14, ["param1"] = 86, ["z"] = 0, ["name"] = "wool:grey"}, {["x"] = 1, ["y"] = 14, ["param1"] = 86, ["z"] = 1, ["name"] = "wool:grey"}, {["x"] = 1, ["y"] = 14, ["param1"] = 86, ["z"] = 14, ["name"] = "wool:grey"}, {["x"] = 1, ["y"] = 14, ["param1"] = 86, ["z"] = 15, ["name"] = "wool:grey"}, {["x"] = 1, ["y"] = 15, ["param1"] = 86, ["z"] = 0, ["name"] = "wool:grey"}, {["x"] = 1, ["y"] = 15, ["param1"] = 86, ["z"] = 1, ["name"] = "wool:grey"}, {["x"] = 1, ["y"] = 15, ["param1"] = 86, ["z"] = 14, ["name"] = "wool:grey"}, {["x"] = 1, ["y"] = 15, ["param1"] = 86, ["z"] = 15, ["name"] = "wool:grey"}, {["x"] = 2, ["y"] = 1, ["param1"] = 86, ["z"] = 0, ["name"] = "wool:grey"}, {["x"] = 2, ["y"] = 1, ["param1"] = 86, ["z"] = 1, ["name"] = "wool:grey"}, {["x"] = 2, ["y"] = 1, ["param1"] = 86, ["z"] = 14, ["name"] = "wool:grey"}, {["x"] = 2, ["y"] = 1, ["param1"] = 86, ["z"] = 15, ["name"] = "wool:grey"}, {["x"] = 2, ["y"] = 2, ["param1"] = 86, ["z"] = 0, ["name"] = "wool:grey"}, {["x"] = 2, ["y"] = 2, ["param1"] = 86, ["z"] = 1, ["name"] = "wool:grey"}, {["x"] = 2, ["y"] = 2, ["param1"] = 86, ["z"] = 14, ["name"] = "wool:grey"}, {["x"] = 2, ["y"] = 2, ["param1"] = 86, ["z"] = 15, ["name"] = "wool:grey"}, {["x"] = 2, ["y"] = 5, ["z"] = 3, ["name"] = "default:steelblock"}, {["x"] = 2, ["y"] = 5, ["param1"] = 81, ["z"] = 4, ["name"] = "default:steelblock"}, {["x"] = 2, ["y"] = 5, ["z"] = 6, ["name"] = "default:steelblock"}, {["x"] = 2, ["y"] = 5, ["param1"] = 81, ["z"] = 7, ["name"] = "default:steelblock"}, {["x"] = 2, ["y"] = 5, ["z"] = 9, ["name"] = "default:steelblock"}, {["x"] = 2, ["y"] = 5, ["param1"] = 81, ["z"] = 10, ["name"] = "default:steelblock"}, {["x"] = 2, ["y"] = 5, ["z"] = 12, ["name"] = "default:steelblock"}, {["x"] = 2, ["y"] = 5, ["z"] = 13, ["name"] = "default:steelblock"}, {["x"] = 2, ["y"] = 6, ["z"] = 3, ["name"] = "default:steelblock"}, {["x"] = 2, ["y"] = 6, ["param1"] = 81, ["z"] = 4, ["name"] = "default:steelblock"}, {["x"] = 2, ["y"] = 6, ["z"] = 6, ["name"] = "default:steelblock"}, {["x"] = 2, ["y"] = 6, ["param1"] = 81, ["z"] = 7, ["name"] = "default:steelblock"}, {["x"] = 2, ["y"] = 6, ["z"] = 9, ["name"] = "default:steelblock"}, {["x"] = 2, ["y"] = 6, ["param1"] = 81, ["z"] = 10, ["name"] = "default:steelblock"}, {["x"] = 2, ["y"] = 6, ["z"] = 12, ["name"] = "default:steelblock"}, {["x"] = 2, ["y"] = 6, ["z"] = 13, ["name"] = "default:steelblock"}, {["x"] = 2, ["y"] = 7, ["z"] = 3, ["name"] = "default:steelblock"}, {["x"] = 2, ["y"] = 7, ["param1"] = 81, ["z"] = 4, ["name"] = "default:steelblock"}, {["x"] = 2, ["y"] = 7, ["z"] = 6, ["name"] = "default:steelblock"}, {["x"] = 2, ["y"] = 7, ["param1"] = 81, ["z"] = 7, ["name"] = "default:steelblock"}, {["x"] = 2, ["y"] = 7, ["z"] = 9, ["name"] = "default:steelblock"}, {["x"] = 2, ["y"] = 7, ["param1"] = 81, ["z"] = 10, ["name"] = "default:steelblock"}, {["x"] = 2, ["y"] = 7, ["z"] = 12, ["name"] = "default:steelblock"}, {["x"] = 2, ["y"] = 7, ["z"] = 13, ["name"] = "default:steelblock"}, {["x"] = 2, ["y"] = 8, ["z"] = 0, ["name"] = "wool:grey"}, {["x"] = 2, ["y"] = 8, ["z"] = 1, ["name"] = "wool:grey"}, {["x"] = 2, ["y"] = 8, ["z"] = 3, ["name"] = "default:steelblock"}, {["x"] = 2, ["y"] = 8, ["param1"] = 81, ["z"] = 4, ["name"] = "default:steelblock"}, {["x"] = 2, ["y"] = 8, ["z"] = 6, ["name"] = "default:steelblock"}, {["x"] = 2, ["y"] = 8, ["param1"] = 81, ["z"] = 7, ["name"] = "default:steelblock"}, {["x"] = 2, ["y"] = 8, ["z"] = 9, ["name"] = "default:steelblock"}, {["x"] = 2, ["y"] = 8, ["param1"] = 81, ["z"] = 10, ["name"] = "default:steelblock"}, {["x"] = 2, ["y"] = 8, ["z"] = 12, ["name"] = "default:steelblock"}, {["x"] = 2, ["y"] = 8, ["z"] = 13, ["name"] = "default:steelblock"}, {["x"] = 2, ["y"] = 9, ["param1"] = 86, ["z"] = 0, ["name"] = "wool:grey"}, {["x"] = 2, ["y"] = 9, ["param1"] = 86, ["z"] = 1, ["name"] = "wool:grey"}, {["x"] = 2, ["y"] = 9, ["z"] = 3, ["name"] = "default:steelblock"}, {["x"] = 2, ["y"] = 9, ["param1"] = 81, ["z"] = 4, ["name"] = "default:steelblock"}, {["x"] = 2, ["y"] = 9, ["z"] = 6, ["name"] = "default:steelblock"}, {["x"] = 2, ["y"] = 9, ["param1"] = 81, ["z"] = 7, ["name"] = "default:steelblock"}, {["x"] = 2, ["y"] = 9, ["z"] = 9, ["name"] = "default:steelblock"}, {["x"] = 2, ["y"] = 9, ["param1"] = 81, ["z"] = 10, ["name"] = "default:steelblock"}, {["x"] = 2, ["y"] = 9, ["z"] = 12, ["name"] = "default:steelblock"}, {["x"] = 2, ["y"] = 9, ["z"] = 13, ["name"] = "default:steelblock"}, {["x"] = 2, ["y"] = 9, ["param1"] = 86, ["z"] = 14, ["name"] = "wool:grey"}, {["x"] = 2, ["y"] = 9, ["param1"] = 86, ["z"] = 15, ["name"] = "wool:grey"}, {["x"] = 2, ["y"] = 10, ["z"] = 3, ["name"] = "default:steelblock"}, {["x"] = 2, ["y"] = 10, ["param1"] = 81, ["z"] = 4, ["name"] = "default:steelblock"}, {["x"] = 2, ["y"] = 10, ["z"] = 6, ["name"] = "default:steelblock"}, {["x"] = 2, ["y"] = 10, ["param1"] = 81, ["z"] = 7, ["name"] = "default:steelblock"}, {["x"] = 2, ["y"] = 10, ["z"] = 9, ["name"] = "default:steelblock"}, {["x"] = 2, ["y"] = 10, ["param1"] = 81, ["z"] = 10, ["name"] = "default:steelblock"}, {["x"] = 2, ["y"] = 10, ["z"] = 12, ["name"] = "default:steelblock"}, {["x"] = 2, ["y"] = 10, ["z"] = 13, ["name"] = "default:steelblock"}, {["x"] = 2, ["y"] = 10, ["param1"] = 86, ["z"] = 14, ["name"] = "wool:grey"}, {["x"] = 2, ["y"] = 10, ["param1"] = 86, ["z"] = 15, ["name"] = "wool:grey"}, {["x"] = 2, ["y"] = 11, ["z"] = 3, ["name"] = "default:steelblock"}, {["x"] = 2, ["y"] = 11, ["param1"] = 81, ["z"] = 4, ["name"] = "default:steelblock"}, {["x"] = 2, ["y"] = 11, ["z"] = 6, ["name"] = "default:steelblock"}, {["x"] = 2, ["y"] = 11, ["param1"] = 81, ["z"] = 7, ["name"] = "default:steelblock"}, {["x"] = 2, ["y"] = 11, ["z"] = 9, ["name"] = "default:steelblock"}, {["x"] = 2, ["y"] = 11, ["param1"] = 81, ["z"] = 10, ["name"] = "default:steelblock"}, {["x"] = 2, ["y"] = 11, ["z"] = 12, ["name"] = "default:steelblock"}, {["x"] = 2, ["y"] = 11, ["z"] = 13, ["name"] = "default:steelblock"}, {["x"] = 2, ["y"] = 12, ["z"] = 3, ["name"] = "default:steelblock"}, {["x"] = 2, ["y"] = 12, ["param1"] = 81, ["z"] = 4, ["name"] = "default:steelblock"}, {["x"] = 2, ["y"] = 12, ["z"] = 6, ["name"] = "default:steelblock"}, {["x"] = 2, ["y"] = 12, ["param1"] = 81, ["z"] = 7, ["name"] = "default:steelblock"}, {["x"] = 2, ["y"] = 12, ["z"] = 9, ["name"] = "default:steelblock"}, {["x"] = 2, ["y"] = 12, ["param1"] = 81, ["z"] = 10, ["name"] = "default:steelblock"}, {["x"] = 2, ["y"] = 12, ["z"] = 12, ["name"] = "default:steelblock"}, {["x"] = 2, ["y"] = 12, ["z"] = 13, ["name"] = "default:steelblock"}, {["x"] = 2, ["y"] = 13, ["z"] = 3, ["name"] = "default:steelblock"}, {["x"] = 2, ["y"] = 13, ["param1"] = 81, ["z"] = 4, ["name"] = "default:steelblock"}, {["x"] = 2, ["y"] = 13, ["z"] = 6, ["name"] = "default:steelblock"}, {["x"] = 2, ["y"] = 13, ["param1"] = 81, ["z"] = 7, ["name"] = "default:steelblock"}, {["x"] = 2, ["y"] = 13, ["z"] = 9, ["name"] = "default:steelblock"}, {["x"] = 2, ["y"] = 13, ["param1"] = 81, ["z"] = 10, ["name"] = "default:steelblock"}, {["x"] = 2, ["y"] = 13, ["z"] = 12, ["name"] = "default:steelblock"}, {["x"] = 2, ["y"] = 13, ["z"] = 13, ["name"] = "default:steelblock"}, {["x"] = 3, ["y"] = 1, ["param1"] = 86, ["z"] = 0, ["name"] = "wool:grey"}, {["x"] = 3, ["y"] = 1, ["param1"] = 86, ["z"] = 1, ["name"] = "wool:grey"}, {["x"] = 3, ["y"] = 1, ["param1"] = 86, ["z"] = 14, ["name"] = "wool:grey"}, {["x"] = 3, ["y"] = 1, ["param1"] = 86, ["z"] = 15, ["name"] = "wool:grey"}, {["x"] = 3, ["y"] = 2, ["param1"] = 86, ["z"] = 0, ["name"] = "wool:grey"}, {["x"] = 3, ["y"] = 2, ["param1"] = 86, ["z"] = 1, ["name"] = "wool:grey"}, {["x"] = 3, ["y"] = 2, ["param1"] = 86, ["z"] = 14, ["name"] = "wool:grey"}, {["x"] = 3, ["y"] = 2, ["param1"] = 86, ["z"] = 15, ["name"] = "wool:grey"}, {["x"] = 3, ["y"] = 3, ["z"] = 3, ["name"] = "default:steelblock"}, {["x"] = 3, ["y"] = 3, ["param1"] = 81, ["z"] = 4, ["name"] = "default:steelblock"}, {["x"] = 3, ["y"] = 3, ["z"] = 6, ["name"] = "default:steelblock"}, {["x"] = 3, ["y"] = 3, ["param1"] = 81, ["z"] = 7, ["name"] = "default:steelblock"}, {["x"] = 3, ["y"] = 3, ["z"] = 9, ["name"] = "default:steelblock"}, {["x"] = 3, ["y"] = 3, ["param1"] = 81, ["z"] = 10, ["name"] = "default:steelblock"}, {["x"] = 3, ["y"] = 3, ["z"] = 12, ["name"] = "default:steelblock"}, {["x"] = 3, ["y"] = 3, ["z"] = 13, ["name"] = "default:steelblock"}, {["x"] = 3, ["y"] = 4, ["z"] = 3, ["name"] = "default:steelblock"}, {["x"] = 3, ["y"] = 4, ["param1"] = 81, ["z"] = 4, ["name"] = "default:steelblock"}, {["x"] = 3, ["y"] = 4, ["z"] = 6, ["name"] = "default:steelblock"}, {["x"] = 3, ["y"] = 4, ["param1"] = 81, ["z"] = 7, ["name"] = "default:steelblock"}, {["x"] = 3, ["y"] = 4, ["z"] = 9, ["name"] = "default:steelblock"}, {["x"] = 3, ["y"] = 4, ["param1"] = 81, ["z"] = 10, ["name"] = "default:steelblock"}, {["x"] = 3, ["y"] = 4, ["z"] = 12, ["name"] = "default:steelblock"}, {["x"] = 3, ["y"] = 4, ["z"] = 13, ["name"] = "default:steelblock"}, {["x"] = 3, ["y"] = 5, ["z"] = 2, ["name"] = "default:steelblock"}, {["x"] = 3, ["y"] = 5, ["param1"] = 81, ["z"] = 3, ["name"] = "default:steelblock"}, {["x"] = 3, ["y"] = 5, ["param1"] = 81, ["z"] = 4, ["name"] = "default:steelblock"}, {["x"] = 3, ["y"] = 5, ["param1"] = 81, ["z"] = 5, ["name"] = "default:steelblock"}, {["x"] = 3, ["y"] = 5, ["param1"] = 81, ["z"] = 6, ["name"] = "default:steelblock"}, {["x"] = 3, ["y"] = 5, ["param1"] = 81, ["z"] = 7, ["name"] = "default:steelblock"}, {["x"] = 3, ["y"] = 5, ["param1"] = 81, ["z"] = 8, ["name"] = "default:steelblock"}, {["x"] = 3, ["y"] = 5, ["param1"] = 81, ["z"] = 9, ["name"] = "default:steelblock"}, {["x"] = 3, ["y"] = 5, ["param1"] = 81, ["z"] = 10, ["name"] = "default:steelblock"}, {["x"] = 3, ["y"] = 5, ["param1"] = 81, ["z"] = 11, ["name"] = "default:steelblock"}, {["x"] = 3, ["y"] = 5, ["param1"] = 81, ["z"] = 12, ["name"] = "default:steelblock"}, {["x"] = 3, ["y"] = 5, ["z"] = 13, ["name"] = "default:steelblock"}, {["x"] = 3, ["y"] = 5, ["z"] = 14, ["name"] = "default:steelblock"}, {["x"] = 3, ["y"] = 6, ["z"] = 2, ["name"] = "default:steelblock"}, {["x"] = 3, ["y"] = 6, ["param1"] = 81, ["z"] = 3, ["name"] = "default:steelblock"}, {["x"] = 3, ["y"] = 6, ["param1"] = 81, ["z"] = 4, ["name"] = "default:steelblock"}, {["x"] = 3, ["y"] = 6, ["param1"] = 81, ["z"] = 5, ["name"] = "default:steelblock"}, {["x"] = 3, ["y"] = 6, ["param1"] = 81, ["z"] = 6, ["name"] = "default:steelblock"}, {["x"] = 3, ["y"] = 6, ["param1"] = 81, ["z"] = 7, ["name"] = "default:steelblock"}, {["x"] = 3, ["y"] = 6, ["param1"] = 81, ["z"] = 8, ["name"] = "default:steelblock"}, {["x"] = 3, ["y"] = 6, ["param1"] = 81, ["z"] = 9, ["name"] = "default:steelblock"}, {["x"] = 3, ["y"] = 6, ["param1"] = 81, ["z"] = 10, ["name"] = "default:steelblock"}, {["x"] = 3, ["y"] = 6, ["param1"] = 81, ["z"] = 11, ["name"] = "default:steelblock"}, {["x"] = 3, ["y"] = 6, ["param1"] = 81, ["z"] = 12, ["name"] = "default:steelblock"}, {["x"] = 3, ["y"] = 6, ["z"] = 13, ["name"] = "default:steelblock"}, {["x"] = 3, ["y"] = 6, ["z"] = 14, ["name"] = "default:steelblock"}, {["x"] = 3, ["y"] = 7, ["z"] = 2, ["name"] = "default:steelblock"}, {["x"] = 3, ["y"] = 7, ["param1"] = 81, ["z"] = 3, ["name"] = "default:steelblock"}, {["x"] = 3, ["y"] = 7, ["param1"] = 81, ["z"] = 4, ["name"] = "default:steelblock"}, {["x"] = 3, ["y"] = 7, ["param1"] = 81, ["z"] = 5, ["name"] = "default:steelblock"}, {["x"] = 3, ["y"] = 7, ["param1"] = 81, ["z"] = 6, ["name"] = "default:steelblock"}, {["x"] = 3, ["y"] = 7, ["param1"] = 81, ["z"] = 7, ["name"] = "default:steelblock"}, {["x"] = 3, ["y"] = 7, ["param1"] = 81, ["z"] = 8, ["name"] = "default:steelblock"}, {["x"] = 3, ["y"] = 7, ["param1"] = 81, ["z"] = 9, ["name"] = "default:steelblock"}, {["x"] = 3, ["y"] = 7, ["param1"] = 81, ["z"] = 10, ["name"] = "default:steelblock"}, {["x"] = 3, ["y"] = 7, ["param1"] = 81, ["z"] = 11, ["name"] = "default:steelblock"}, {["x"] = 3, ["y"] = 7, ["param1"] = 81, ["z"] = 12, ["name"] = "default:steelblock"}, {["x"] = 3, ["y"] = 7, ["z"] = 13, ["name"] = "default:steelblock"}, {["x"] = 3, ["y"] = 7, ["z"] = 14, ["name"] = "default:steelblock"}, {["x"] = 3, ["y"] = 8, ["z"] = 0, ["name"] = "wool:grey"}, {["x"] = 3, ["y"] = 8, ["z"] = 1, ["name"] = "wool:grey"}, {["x"] = 3, ["y"] = 8, ["z"] = 2, ["name"] = "default:steelblock"}, {["x"] = 3, ["y"] = 8, ["param1"] = 81, ["z"] = 3, ["name"] = "default:steelblock"}, {["x"] = 3, ["y"] = 8, ["param1"] = 81, ["z"] = 4, ["name"] = "default:steelblock"}, {["x"] = 3, ["y"] = 8, ["param1"] = 81, ["z"] = 5, ["name"] = "default:steelblock"}, {["x"] = 3, ["y"] = 8, ["param1"] = 81, ["z"] = 6, ["name"] = "default:steelblock"}, {["x"] = 3, ["y"] = 8, ["param1"] = 81, ["z"] = 7, ["name"] = "default:steelblock"}, {["x"] = 3, ["y"] = 8, ["param1"] = 81, ["z"] = 8, ["name"] = "default:steelblock"}, {["x"] = 3, ["y"] = 8, ["param1"] = 81, ["z"] = 9, ["name"] = "default:steelblock"}, {["x"] = 3, ["y"] = 8, ["param1"] = 81, ["z"] = 10, ["name"] = "default:steelblock"}, {["x"] = 3, ["y"] = 8, ["param1"] = 81, ["z"] = 11, ["name"] = "default:steelblock"}, {["x"] = 3, ["y"] = 8, ["param1"] = 81, ["z"] = 12, ["name"] = "default:steelblock"}, {["x"] = 3, ["y"] = 8, ["z"] = 13, ["name"] = "default:steelblock"}, {["x"] = 3, ["y"] = 8, ["z"] = 14, ["name"] = "default:steelblock"}, {["x"] = 3, ["y"] = 9, ["param1"] = 86, ["z"] = 0, ["name"] = "wool:grey"}, {["x"] = 3, ["y"] = 9, ["z"] = 1, ["name"] = "wool:grey"}, {["x"] = 3, ["y"] = 9, ["z"] = 2, ["name"] = "default:steelblock"}, {["x"] = 3, ["y"] = 9, ["param1"] = 81, ["z"] = 3, ["name"] = "default:steelblock"}, {["x"] = 3, ["y"] = 9, ["param1"] = 81, ["z"] = 4, ["name"] = "default:steelblock"}, {["x"] = 3, ["y"] = 9, ["param1"] = 81, ["z"] = 5, ["name"] = "default:steelblock"}, {["x"] = 3, ["y"] = 9, ["param1"] = 81, ["z"] = 6, ["name"] = "default:steelblock"}, {["x"] = 3, ["y"] = 9, ["param1"] = 81, ["z"] = 7, ["name"] = "default:steelblock"}, {["x"] = 3, ["y"] = 9, ["param1"] = 81, ["z"] = 8, ["name"] = "default:steelblock"}, {["x"] = 3, ["y"] = 9, ["param1"] = 81, ["z"] = 9, ["name"] = "default:steelblock"}, {["x"] = 3, ["y"] = 9, ["param1"] = 81, ["z"] = 10, ["name"] = "default:steelblock"}, {["x"] = 3, ["y"] = 9, ["param1"] = 81, ["z"] = 11, ["name"] = "default:steelblock"}, {["x"] = 3, ["y"] = 9, ["param1"] = 81, ["z"] = 12, ["name"] = "default:steelblock"}, {["x"] = 3, ["y"] = 9, ["z"] = 13, ["name"] = "default:steelblock"}, {["x"] = 3, ["y"] = 9, ["z"] = 14, ["name"] = "default:steelblock"}, {["x"] = 3, ["y"] = 9, ["param1"] = 86, ["z"] = 15, ["name"] = "wool:grey"}, {["x"] = 3, ["y"] = 10, ["z"] = 2, ["name"] = "default:steelblock"}, {["x"] = 3, ["y"] = 10, ["param1"] = 81, ["z"] = 3, ["name"] = "default:steelblock"}, {["x"] = 3, ["y"] = 10, ["param1"] = 81, ["z"] = 4, ["name"] = "default:steelblock"}, {["x"] = 3, ["y"] = 10, ["param1"] = 81, ["z"] = 5, ["name"] = "default:steelblock"}, {["x"] = 3, ["y"] = 10, ["param1"] = 81, ["z"] = 6, ["name"] = "default:steelblock"}, {["x"] = 3, ["y"] = 10, ["param1"] = 81, ["z"] = 7, ["name"] = "default:steelblock"}, {["x"] = 3, ["y"] = 10, ["param1"] = 81, ["z"] = 8, ["name"] = "default:steelblock"}, {["x"] = 3, ["y"] = 10, ["param1"] = 81, ["z"] = 9, ["name"] = "default:steelblock"}, {["x"] = 3, ["y"] = 10, ["param1"] = 81, ["z"] = 10, ["name"] = "default:steelblock"}, {["x"] = 3, ["y"] = 10, ["param1"] = 81, ["z"] = 11, ["name"] = "default:steelblock"}, {["x"] = 3, ["y"] = 10, ["param1"] = 81, ["z"] = 12, ["name"] = "default:steelblock"}, {["x"] = 3, ["y"] = 10, ["z"] = 13, ["name"] = "default:steelblock"}, {["x"] = 3, ["y"] = 10, ["z"] = 14, ["name"] = "default:steelblock"}, {["x"] = 3, ["y"] = 10, ["param1"] = 86, ["z"] = 15, ["name"] = "wool:grey"}, {["x"] = 3, ["y"] = 11, ["z"] = 2, ["name"] = "default:steelblock"}, {["x"] = 3, ["y"] = 11, ["param1"] = 81, ["z"] = 3, ["name"] = "default:steelblock"}, {["x"] = 3, ["y"] = 11, ["param1"] = 81, ["z"] = 4, ["name"] = "default:steelblock"}, {["x"] = 3, ["y"] = 11, ["param1"] = 81, ["z"] = 5, ["name"] = "default:steelblock"}, {["x"] = 3, ["y"] = 11, ["param1"] = 81, ["z"] = 6, ["name"] = "default:steelblock"}, {["x"] = 3, ["y"] = 11, ["param1"] = 81, ["z"] = 7, ["name"] = "default:steelblock"}, {["x"] = 3, ["y"] = 11, ["param1"] = 81, ["z"] = 8, ["name"] = "default:steelblock"}, {["x"] = 3, ["y"] = 11, ["param1"] = 81, ["z"] = 9, ["name"] = "default:steelblock"}, {["x"] = 3, ["y"] = 11, ["param1"] = 81, ["z"] = 10, ["name"] = "default:steelblock"}, {["x"] = 3, ["y"] = 11, ["param1"] = 81, ["z"] = 11, ["name"] = "default:steelblock"}, {["x"] = 3, ["y"] = 11, ["param1"] = 81, ["z"] = 12, ["name"] = "default:steelblock"}, {["x"] = 3, ["y"] = 11, ["z"] = 13, ["name"] = "default:steelblock"}, {["x"] = 3, ["y"] = 11, ["z"] = 14, ["name"] = "default:steelblock"}, {["x"] = 3, ["y"] = 12, ["z"] = 2, ["name"] = "default:steelblock"}, {["x"] = 3, ["y"] = 12, ["param1"] = 81, ["z"] = 3, ["name"] = "default:steelblock"}, {["x"] = 3, ["y"] = 12, ["param1"] = 81, ["z"] = 4, ["name"] = "default:steelblock"}, {["x"] = 3, ["y"] = 12, ["param1"] = 81, ["z"] = 5, ["name"] = "default:steelblock"}, {["x"] = 3, ["y"] = 12, ["param1"] = 81, ["z"] = 6, ["name"] = "default:steelblock"}, {["x"] = 3, ["y"] = 12, ["param1"] = 81, ["z"] = 7, ["name"] = "default:steelblock"}, {["x"] = 3, ["y"] = 12, ["param1"] = 81, ["z"] = 8, ["name"] = "default:steelblock"}, {["x"] = 3, ["y"] = 12, ["param1"] = 81, ["z"] = 9, ["name"] = "default:steelblock"}, {["x"] = 3, ["y"] = 12, ["param1"] = 81, ["z"] = 10, ["name"] = "default:steelblock"}, {["x"] = 3, ["y"] = 12, ["param1"] = 81, ["z"] = 11, ["name"] = "default:steelblock"}, {["x"] = 3, ["y"] = 12, ["param1"] = 81, ["z"] = 12, ["name"] = "default:steelblock"}, {["x"] = 3, ["y"] = 12, ["z"] = 13, ["name"] = "default:steelblock"}, {["x"] = 3, ["y"] = 12, ["z"] = 14, ["name"] = "default:steelblock"}, {["x"] = 3, ["y"] = 13, ["z"] = 2, ["name"] = "default:steelblock"}, {["x"] = 3, ["y"] = 13, ["param1"] = 81, ["z"] = 3, ["name"] = "default:steelblock"}, {["x"] = 3, ["y"] = 13, ["param1"] = 81, ["z"] = 4, ["name"] = "default:steelblock"}, {["x"] = 3, ["y"] = 13, ["param1"] = 81, ["z"] = 5, ["name"] = "default:steelblock"}, {["x"] = 3, ["y"] = 13, ["param1"] = 81, ["z"] = 6, ["name"] = "default:steelblock"}, {["x"] = 3, ["y"] = 13, ["param1"] = 81, ["z"] = 7, ["name"] = "default:steelblock"}, {["x"] = 3, ["y"] = 13, ["param1"] = 81, ["z"] = 8, ["name"] = "default:steelblock"}, {["x"] = 3, ["y"] = 13, ["param1"] = 81, ["z"] = 9, ["name"] = "default:steelblock"}, {["x"] = 3, ["y"] = 13, ["param1"] = 81, ["z"] = 10, ["name"] = "default:steelblock"}, {["x"] = 3, ["y"] = 13, ["param1"] = 81, ["z"] = 11, ["name"] = "default:steelblock"}, {["x"] = 3, ["y"] = 13, ["param1"] = 81, ["z"] = 12, ["name"] = "default:steelblock"}, {["x"] = 3, ["y"] = 13, ["z"] = 13, ["name"] = "default:steelblock"}, {["x"] = 3, ["y"] = 13, ["z"] = 14, ["name"] = "default:steelblock"}, {["x"] = 3, ["y"] = 14, ["z"] = 3, ["name"] = "default:steelblock"}, {["x"] = 3, ["y"] = 14, ["z"] = 4, ["name"] = "default:steelblock"}, {["x"] = 3, ["y"] = 14, ["z"] = 6, ["name"] = "default:steelblock"}, {["x"] = 3, ["y"] = 14, ["param1"] = 81, ["z"] = 7, ["name"] = "default:steelblock"}, {["x"] = 3, ["y"] = 14, ["z"] = 9, ["name"] = "default:steelblock"}, {["x"] = 3, ["y"] = 14, ["param1"] = 81, ["z"] = 10, ["name"] = "default:steelblock"}, {["x"] = 3, ["y"] = 14, ["z"] = 12, ["name"] = "default:steelblock"}, {["x"] = 3, ["y"] = 14, ["z"] = 13, ["name"] = "default:steelblock"}, {["x"] = 3, ["y"] = 14, ["z"] = 14, ["name"] = "wool:green"}, {["x"] = 4, ["y"] = 1, ["param1"] = 86, ["z"] = 0, ["name"] = "wool:grey"}, {["x"] = 4, ["y"] = 1, ["param1"] = 86, ["z"] = 1, ["name"] = "wool:grey"}, {["x"] = 4, ["y"] = 1, ["z"] = 14, ["name"] = "wool:grey"}, {["x"] = 4, ["y"] = 1, ["z"] = 15, ["name"] = "wool:grey"}, {["x"] = 4, ["y"] = 2, ["param1"] = 86, ["z"] = 0, ["name"] = "wool:grey"}, {["x"] = 4, ["y"] = 2, ["z"] = 1, ["name"] = "default:steelblock"}, {["x"] = 4, ["y"] = 2, ["param1"] = 81, ["z"] = 2, ["name"] = "default:steelblock"}, {["x"] = 4, ["y"] = 2, ["param1"] = 81, ["z"] = 3, ["name"] = "default:steelblock"}, {["x"] = 4, ["y"] = 2, ["param1"] = 81, ["z"] = 4, ["name"] = "default:steelblock"}, {["x"] = 4, ["y"] = 2, ["param1"] = 81, ["z"] = 5, ["name"] = "default:steelblock"}, {["x"] = 4, ["y"] = 2, ["param1"] = 81, ["z"] = 6, ["name"] = "default:steelblock"}, {["x"] = 4, ["y"] = 2, ["param1"] = 81, ["z"] = 7, ["name"] = "default:steelblock"}, {["x"] = 4, ["y"] = 2, ["param1"] = 81, ["z"] = 8, ["name"] = "default:steelblock"}, {["x"] = 4, ["y"] = 2, ["param1"] = 81, ["z"] = 9, ["name"] = "default:steelblock"}, {["x"] = 4, ["y"] = 2, ["param1"] = 81, ["z"] = 10, ["name"] = "default:steelblock"}, {["x"] = 4, ["y"] = 2, ["param1"] = 81, ["z"] = 11, ["name"] = "default:steelblock"}, {["x"] = 4, ["y"] = 2, ["param1"] = 81, ["z"] = 12, ["name"] = "default:steelblock"}, {["x"] = 4, ["y"] = 2, ["param1"] = 81, ["z"] = 13, ["name"] = "default:steelblock"}, {["x"] = 4, ["y"] = 2, ["z"] = 14, ["name"] = "default:steelblock"}, {["x"] = 4, ["y"] = 2, ["z"] = 15, ["name"] = "default:steelblock"}, {["x"] = 4, ["y"] = 3, ["z"] = 1, ["name"] = "default:steelblock"}, {["x"] = 4, ["y"] = 3, ["param1"] = 81, ["z"] = 2, ["name"] = "default:steelblock"}, {["x"] = 4, ["y"] = 3, ["param1"] = 81, ["z"] = 3, ["name"] = "default:steelblock"}, {["x"] = 4, ["y"] = 3, ["param1"] = 81, ["z"] = 4, ["name"] = "default:steelblock"}, {["x"] = 4, ["y"] = 3, ["param1"] = 81, ["z"] = 5, ["name"] = "default:steelblock"}, {["x"] = 4, ["y"] = 3, ["param1"] = 81, ["z"] = 6, ["name"] = "default:steelblock"}, {["x"] = 4, ["y"] = 3, ["param1"] = 81, ["z"] = 7, ["name"] = "default:steelblock"}, {["x"] = 4, ["y"] = 3, ["param1"] = 81, ["z"] = 8, ["name"] = "default:steelblock"}, {["x"] = 4, ["y"] = 3, ["param1"] = 81, ["z"] = 9, ["name"] = "default:steelblock"}, {["x"] = 4, ["y"] = 3, ["param1"] = 81, ["z"] = 10, ["name"] = "default:steelblock"}, {["x"] = 4, ["y"] = 3, ["param1"] = 81, ["z"] = 11, ["name"] = "default:steelblock"}, {["x"] = 4, ["y"] = 3, ["param1"] = 81, ["z"] = 12, ["name"] = "default:steelblock"}, {["x"] = 4, ["y"] = 3, ["param1"] = 81, ["z"] = 13, ["name"] = "default:steelblock"}, {["x"] = 4, ["y"] = 3, ["z"] = 14, ["name"] = "default:steelblock"}, {["x"] = 4, ["y"] = 3, ["z"] = 15, ["name"] = "default:steelblock"}, {["x"] = 4, ["y"] = 4, ["z"] = 1, ["name"] = "default:steelblock"}, {["x"] = 4, ["y"] = 4, ["param1"] = 81, ["z"] = 2, ["name"] = "default:steelblock"}, {["x"] = 4, ["y"] = 4, ["param1"] = 81, ["z"] = 3, ["name"] = "default:steelblock"}, {["x"] = 4, ["y"] = 4, ["param1"] = 81, ["z"] = 4, ["name"] = "default:steelblock"}, {["x"] = 4, ["y"] = 4, ["param1"] = 81, ["z"] = 5, ["name"] = "default:steelblock"}, {["x"] = 4, ["y"] = 4, ["param1"] = 81, ["z"] = 6, ["name"] = "default:steelblock"}, {["x"] = 4, ["y"] = 4, ["param1"] = 81, ["z"] = 7, ["name"] = "default:steelblock"}, {["x"] = 4, ["y"] = 4, ["param1"] = 81, ["z"] = 8, ["name"] = "default:steelblock"}, {["x"] = 4, ["y"] = 4, ["param1"] = 81, ["z"] = 9, ["name"] = "default:steelblock"}, {["x"] = 4, ["y"] = 4, ["param1"] = 81, ["z"] = 10, ["name"] = "default:steelblock"}, {["x"] = 4, ["y"] = 4, ["param1"] = 81, ["z"] = 11, ["name"] = "default:steelblock"}, {["x"] = 4, ["y"] = 4, ["param1"] = 81, ["z"] = 12, ["name"] = "default:steelblock"}, {["x"] = 4, ["y"] = 4, ["param1"] = 81, ["z"] = 13, ["name"] = "default:steelblock"}, {["x"] = 4, ["y"] = 4, ["z"] = 14, ["name"] = "default:steelblock"}, {["x"] = 4, ["y"] = 4, ["z"] = 15, ["name"] = "default:steelblock"}, {["x"] = 4, ["y"] = 5, ["z"] = 1, ["name"] = "default:steelblock"}, {["x"] = 4, ["y"] = 5, ["param1"] = 81, ["z"] = 2, ["name"] = "default:steelblock"}, {["x"] = 4, ["y"] = 5, ["param1"] = 81, ["z"] = 3, ["name"] = "default:steelblock"}, {["x"] = 4, ["y"] = 5, ["param1"] = 81, ["z"] = 4, ["name"] = "default:steelblock"}, {["x"] = 4, ["y"] = 5, ["param1"] = 81, ["z"] = 5, ["name"] = "default:steelblock"}, {["x"] = 4, ["y"] = 5, ["param1"] = 81, ["z"] = 6, ["name"] = "default:steelblock"}, {["x"] = 4, ["y"] = 5, ["param1"] = 81, ["z"] = 7, ["name"] = "default:steelblock"}, {["x"] = 4, ["y"] = 5, ["param1"] = 81, ["z"] = 8, ["name"] = "default:steelblock"}, {["x"] = 4, ["y"] = 5, ["param1"] = 81, ["z"] = 9, ["name"] = "default:steelblock"}, {["x"] = 4, ["y"] = 5, ["param1"] = 81, ["z"] = 10, ["name"] = "default:steelblock"}, {["x"] = 4, ["y"] = 5, ["param1"] = 81, ["z"] = 11, ["name"] = "default:steelblock"}, {["x"] = 4, ["y"] = 5, ["param1"] = 81, ["z"] = 12, ["name"] = "default:steelblock"}, {["x"] = 4, ["y"] = 5, ["param1"] = 81, ["z"] = 13, ["name"] = "default:steelblock"}, {["x"] = 4, ["y"] = 5, ["z"] = 14, ["name"] = "default:steelblock"}, {["x"] = 4, ["y"] = 5, ["z"] = 15, ["name"] = "default:steelblock"}, {["x"] = 4, ["y"] = 6, ["z"] = 2, ["name"] = "default:steelblock"}, {["x"] = 4, ["y"] = 6, ["param1"] = 81, ["z"] = 3, ["name"] = "default:steelblock"}, {["x"] = 4, ["y"] = 6, ["param1"] = 81, ["z"] = 4, ["name"] = "default:steelblock"}, {["x"] = 4, ["y"] = 6, ["param1"] = 81, ["z"] = 5, ["name"] = "default:steelblock"}, {["x"] = 4, ["y"] = 6, ["param1"] = 81, ["z"] = 6, ["name"] = "default:steelblock"}, {["x"] = 4, ["y"] = 6, ["param1"] = 81, ["z"] = 7, ["name"] = "default:steelblock"}, {["x"] = 4, ["y"] = 6, ["param1"] = 81, ["z"] = 8, ["name"] = "default:steelblock"}, {["x"] = 4, ["y"] = 6, ["param1"] = 81, ["z"] = 9, ["name"] = "default:steelblock"}, {["x"] = 4, ["y"] = 6, ["param1"] = 81, ["z"] = 10, ["name"] = "default:steelblock"}, {["x"] = 4, ["y"] = 6, ["param1"] = 81, ["z"] = 11, ["name"] = "default:steelblock"}, {["x"] = 4, ["y"] = 6, ["param1"] = 81, ["z"] = 12, ["name"] = "default:steelblock"}, {["x"] = 4, ["y"] = 6, ["z"] = 13, ["name"] = "default:steelblock"}, {["x"] = 4, ["y"] = 6, ["z"] = 14, ["name"] = "default:steelblock"}, {["x"] = 4, ["y"] = 7, ["z"] = 2, ["name"] = "default:steelblock"}, {["x"] = 4, ["y"] = 7, ["param1"] = 81, ["z"] = 3, ["name"] = "default:steelblock"}, {["x"] = 4, ["y"] = 7, ["param1"] = 81, ["z"] = 4, ["name"] = "default:steelblock"}, {["x"] = 4, ["y"] = 7, ["param1"] = 81, ["z"] = 5, ["name"] = "default:steelblock"}, {["x"] = 4, ["y"] = 7, ["param1"] = 81, ["z"] = 6, ["name"] = "default:steelblock"}, {["x"] = 4, ["y"] = 7, ["param1"] = 81, ["z"] = 7, ["name"] = "default:steelblock"}, {["x"] = 4, ["y"] = 7, ["param1"] = 81, ["z"] = 8, ["name"] = "default:steelblock"}, {["x"] = 4, ["y"] = 7, ["param1"] = 81, ["z"] = 9, ["name"] = "default:steelblock"}, {["x"] = 4, ["y"] = 7, ["param1"] = 81, ["z"] = 10, ["name"] = "default:steelblock"}, {["x"] = 4, ["y"] = 7, ["param1"] = 81, ["z"] = 11, ["name"] = "default:steelblock"}, {["x"] = 4, ["y"] = 7, ["param1"] = 81, ["z"] = 12, ["name"] = "default:steelblock"}, {["x"] = 4, ["y"] = 7, ["z"] = 13, ["name"] = "default:steelblock"}, {["x"] = 4, ["y"] = 7, ["z"] = 14, ["name"] = "default:steelblock"}, {["x"] = 4, ["y"] = 8, ["z"] = 0, ["name"] = "wool:grey"}, {["x"] = 4, ["y"] = 8, ["z"] = 1, ["name"] = "wool:grey"}, {["x"] = 4, ["y"] = 8, ["z"] = 2, ["name"] = "default:steelblock"}, {["x"] = 4, ["y"] = 8, ["param1"] = 81, ["z"] = 3, ["name"] = "default:steelblock"}, {["x"] = 4, ["y"] = 8, ["param1"] = 81, ["z"] = 4, ["name"] = "default:steelblock"}, {["x"] = 4, ["y"] = 8, ["param1"] = 81, ["z"] = 5, ["name"] = "default:steelblock"}, {["x"] = 4, ["y"] = 8, ["param1"] = 81, ["z"] = 6, ["name"] = "default:steelblock"}, {["x"] = 4, ["y"] = 8, ["param1"] = 81, ["z"] = 7, ["name"] = "default:steelblock"}, {["x"] = 4, ["y"] = 8, ["param1"] = 81, ["z"] = 8, ["name"] = "default:steelblock"}, {["x"] = 4, ["y"] = 8, ["param1"] = 81, ["z"] = 9, ["name"] = "default:steelblock"}, {["x"] = 4, ["y"] = 8, ["param1"] = 81, ["z"] = 10, ["name"] = "default:steelblock"}, {["x"] = 4, ["y"] = 8, ["param1"] = 81, ["z"] = 11, ["name"] = "default:steelblock"}, {["x"] = 4, ["y"] = 8, ["param1"] = 81, ["z"] = 12, ["name"] = "default:steelblock"}, {["x"] = 4, ["y"] = 8, ["z"] = 13, ["name"] = "default:steelblock"}, {["x"] = 4, ["y"] = 8, ["z"] = 14, ["name"] = "default:steelblock"}, {["x"] = 4, ["y"] = 9, ["param1"] = 86, ["z"] = 0, ["name"] = "wool:grey"}, {["x"] = 4, ["y"] = 9, ["z"] = 1, ["name"] = "wool:grey"}, {["x"] = 4, ["y"] = 9, ["z"] = 2, ["name"] = "default:steelblock"}, {["x"] = 4, ["y"] = 9, ["param1"] = 81, ["z"] = 3, ["name"] = "default:steelblock"}, {["x"] = 4, ["y"] = 9, ["param1"] = 81, ["z"] = 4, ["name"] = "default:steelblock"}, {["x"] = 4, ["y"] = 9, ["param1"] = 81, ["z"] = 5, ["name"] = "default:steelblock"}, {["x"] = 4, ["y"] = 9, ["param1"] = 81, ["z"] = 6, ["name"] = "default:steelblock"}, {["x"] = 4, ["y"] = 9, ["param1"] = 81, ["z"] = 7, ["name"] = "default:steelblock"}, {["x"] = 4, ["y"] = 9, ["param1"] = 81, ["z"] = 8, ["name"] = "default:steelblock"}, {["x"] = 4, ["y"] = 9, ["param1"] = 81, ["z"] = 9, ["name"] = "default:steelblock"}, {["x"] = 4, ["y"] = 9, ["param1"] = 81, ["z"] = 10, ["name"] = "default:steelblock"}, {["x"] = 4, ["y"] = 9, ["param1"] = 81, ["z"] = 11, ["name"] = "default:steelblock"}, {["x"] = 4, ["y"] = 9, ["param1"] = 81, ["z"] = 12, ["name"] = "default:steelblock"}, {["x"] = 4, ["y"] = 9, ["z"] = 13, ["name"] = "default:steelblock"}, {["x"] = 4, ["y"] = 9, ["z"] = 14, ["name"] = "default:steelblock"}, {["x"] = 4, ["y"] = 9, ["param1"] = 86, ["z"] = 15, ["name"] = "wool:grey"}, {["x"] = 4, ["y"] = 10, ["z"] = 2, ["name"] = "default:steelblock"}, {["x"] = 4, ["y"] = 10, ["param1"] = 81, ["z"] = 3, ["name"] = "default:steelblock"}, {["x"] = 4, ["y"] = 10, ["param1"] = 81, ["z"] = 4, ["name"] = "default:steelblock"}, {["x"] = 4, ["y"] = 10, ["param1"] = 81, ["z"] = 5, ["name"] = "default:steelblock"}, {["x"] = 4, ["y"] = 10, ["param1"] = 81, ["z"] = 6, ["name"] = "default:steelblock"}, {["x"] = 4, ["y"] = 10, ["param1"] = 81, ["z"] = 7, ["name"] = "default:steelblock"}, {["x"] = 4, ["y"] = 10, ["param1"] = 81, ["z"] = 8, ["name"] = "default:steelblock"}, {["x"] = 4, ["y"] = 10, ["param1"] = 81, ["z"] = 9, ["name"] = "default:steelblock"}, {["x"] = 4, ["y"] = 10, ["param1"] = 81, ["z"] = 10, ["name"] = "default:steelblock"}, {["x"] = 4, ["y"] = 10, ["param1"] = 81, ["z"] = 11, ["name"] = "default:steelblock"}, {["x"] = 4, ["y"] = 10, ["param1"] = 81, ["z"] = 12, ["name"] = "default:steelblock"}, {["x"] = 4, ["y"] = 10, ["z"] = 13, ["name"] = "default:steelblock"}, {["x"] = 4, ["y"] = 10, ["z"] = 14, ["name"] = "default:steelblock"}, {["x"] = 4, ["y"] = 10, ["param1"] = 86, ["z"] = 15, ["name"] = "wool:grey"}, {["x"] = 4, ["y"] = 11, ["z"] = 2, ["name"] = "default:steelblock"}, {["x"] = 4, ["y"] = 11, ["param1"] = 81, ["z"] = 3, ["name"] = "default:steelblock"}, {["x"] = 4, ["y"] = 11, ["param1"] = 81, ["z"] = 4, ["name"] = "default:steelblock"}, {["x"] = 4, ["y"] = 11, ["param1"] = 81, ["z"] = 5, ["name"] = "default:steelblock"}, {["x"] = 4, ["y"] = 11, ["param1"] = 81, ["z"] = 6, ["name"] = "default:steelblock"}, {["x"] = 4, ["y"] = 11, ["param1"] = 81, ["z"] = 7, ["name"] = "default:steelblock"}, {["x"] = 4, ["y"] = 11, ["param1"] = 81, ["z"] = 8, ["name"] = "default:steelblock"}, {["x"] = 4, ["y"] = 11, ["param1"] = 81, ["z"] = 9, ["name"] = "default:steelblock"}, {["x"] = 4, ["y"] = 11, ["param1"] = 81, ["z"] = 10, ["name"] = "default:steelblock"}, {["x"] = 4, ["y"] = 11, ["param1"] = 81, ["z"] = 11, ["name"] = "default:steelblock"}, {["x"] = 4, ["y"] = 11, ["param1"] = 81, ["z"] = 12, ["name"] = "default:steelblock"}, {["x"] = 4, ["y"] = 11, ["z"] = 13, ["name"] = "default:steelblock"}, {["x"] = 4, ["y"] = 11, ["z"] = 14, ["name"] = "default:steelblock"}, {["x"] = 4, ["y"] = 12, ["z"] = 2, ["name"] = "default:steelblock"}, {["x"] = 4, ["y"] = 12, ["param1"] = 81, ["z"] = 3, ["name"] = "default:steelblock"}, {["x"] = 4, ["y"] = 12, ["param1"] = 81, ["z"] = 4, ["name"] = "default:steelblock"}, {["x"] = 4, ["y"] = 12, ["param1"] = 81, ["z"] = 5, ["name"] = "default:steelblock"}, {["x"] = 4, ["y"] = 12, ["param1"] = 81, ["z"] = 6, ["name"] = "default:steelblock"}, {["x"] = 4, ["y"] = 12, ["param1"] = 81, ["z"] = 7, ["name"] = "default:steelblock"}, {["x"] = 4, ["y"] = 12, ["param1"] = 81, ["z"] = 8, ["name"] = "default:steelblock"}, {["x"] = 4, ["y"] = 12, ["param1"] = 81, ["z"] = 9, ["name"] = "default:steelblock"}, {["x"] = 4, ["y"] = 12, ["param1"] = 81, ["z"] = 10, ["name"] = "default:steelblock"}, {["x"] = 4, ["y"] = 12, ["param1"] = 81, ["z"] = 11, ["name"] = "default:steelblock"}, {["x"] = 4, ["y"] = 12, ["param1"] = 81, ["z"] = 12, ["name"] = "default:steelblock"}, {["x"] = 4, ["y"] = 12, ["z"] = 13, ["name"] = "default:steelblock"}, {["x"] = 4, ["y"] = 12, ["z"] = 14, ["name"] = "default:steelblock"}, {["x"] = 4, ["y"] = 13, ["z"] = 2, ["name"] = "default:steelblock"}, {["x"] = 4, ["y"] = 13, ["param1"] = 81, ["z"] = 3, ["name"] = "default:steelblock"}, {["x"] = 4, ["y"] = 13, ["param1"] = 81, ["z"] = 4, ["name"] = "default:steelblock"}, {["x"] = 4, ["y"] = 13, ["param1"] = 81, ["z"] = 5, ["name"] = "default:steelblock"}, {["x"] = 4, ["y"] = 13, ["param1"] = 81, ["z"] = 6, ["name"] = "default:steelblock"}, {["x"] = 4, ["y"] = 13, ["param1"] = 81, ["z"] = 7, ["name"] = "default:steelblock"}, {["x"] = 4, ["y"] = 13, ["param1"] = 81, ["z"] = 8, ["name"] = "default:steelblock"}, {["x"] = 4, ["y"] = 13, ["param1"] = 81, ["z"] = 9, ["name"] = "default:steelblock"}, {["x"] = 4, ["y"] = 13, ["param1"] = 81, ["z"] = 10, ["name"] = "default:steelblock"}, {["x"] = 4, ["y"] = 13, ["param1"] = 81, ["z"] = 11, ["name"] = "default:steelblock"}, {["x"] = 4, ["y"] = 13, ["param1"] = 81, ["z"] = 12, ["name"] = "default:steelblock"}, {["x"] = 4, ["y"] = 13, ["z"] = 13, ["name"] = "default:steelblock"}, {["x"] = 4, ["y"] = 13, ["z"] = 14, ["name"] = "default:steelblock"}, {["x"] = 4, ["y"] = 14, ["z"] = 3, ["name"] = "default:steelblock"}, {["x"] = 4, ["y"] = 14, ["z"] = 4, ["name"] = "default:steelblock"}, {["x"] = 4, ["y"] = 14, ["z"] = 6, ["name"] = "default:steelblock"}, {["x"] = 4, ["y"] = 14, ["param1"] = 81, ["z"] = 7, ["name"] = "default:steelblock"}, {["x"] = 4, ["y"] = 14, ["z"] = 9, ["name"] = "default:steelblock"}, {["x"] = 4, ["y"] = 14, ["param1"] = 81, ["z"] = 10, ["name"] = "default:steelblock"}, {["x"] = 4, ["y"] = 14, ["z"] = 12, ["name"] = "default:steelblock"}, {["x"] = 4, ["y"] = 14, ["z"] = 13, ["name"] = "default:steelblock"}, {["x"] = 4, ["y"] = 14, ["z"] = 14, ["name"] = "wool:green"}, {["x"] = 5, ["y"] = 1, ["param1"] = 86, ["z"] = 0, ["name"] = "wool:grey"}, {["x"] = 5, ["y"] = 1, ["z"] = 1, ["name"] = "default:steelblock"}, {["x"] = 5, ["y"] = 1, ["param1"] = 81, ["z"] = 2, ["name"] = "default:steelblock"}, {["x"] = 5, ["y"] = 1, ["param1"] = 81, ["z"] = 3, ["name"] = "default:steelblock"}, {["x"] = 5, ["y"] = 1, ["param1"] = 81, ["z"] = 4, ["name"] = "default:steelblock"}, {["x"] = 5, ["y"] = 1, ["param1"] = 81, ["z"] = 5, ["name"] = "default:steelblock"}, {["x"] = 5, ["y"] = 1, ["param1"] = 81, ["z"] = 6, ["name"] = "default:steelblock"}, {["x"] = 5, ["y"] = 1, ["param1"] = 81, ["z"] = 7, ["name"] = "default:steelblock"}, {["x"] = 5, ["y"] = 1, ["param1"] = 81, ["z"] = 8, ["name"] = "default:steelblock"}, {["x"] = 5, ["y"] = 1, ["param1"] = 81, ["z"] = 9, ["name"] = "default:steelblock"}, {["x"] = 5, ["y"] = 1, ["param1"] = 81, ["z"] = 10, ["name"] = "default:steelblock"}, {["x"] = 5, ["y"] = 1, ["param1"] = 81, ["z"] = 11, ["name"] = "default:steelblock"}, {["x"] = 5, ["y"] = 1, ["param1"] = 81, ["z"] = 12, ["name"] = "default:steelblock"}, {["x"] = 5, ["y"] = 1, ["param1"] = 81, ["z"] = 13, ["name"] = "default:steelblock"}, {["x"] = 5, ["y"] = 1, ["z"] = 14, ["name"] = "default:steelblock"}, {["x"] = 5, ["y"] = 1, ["z"] = 15, ["name"] = "default:steelblock"}, {["x"] = 5, ["y"] = 2, ["param1"] = 86, ["z"] = 0, ["name"] = "wool:grey"}, {["x"] = 5, ["y"] = 2, ["z"] = 1, ["name"] = "default:steelblock"}, {["x"] = 5, ["y"] = 2, ["param1"] = 81, ["z"] = 2, ["name"] = "default:steelblock"}, {["x"] = 5, ["y"] = 2, ["param1"] = 81, ["z"] = 3, ["name"] = "default:steelblock"}, {["x"] = 5, ["y"] = 2, ["param1"] = 81, ["z"] = 4, ["name"] = "default:steelblock"}, {["x"] = 5, ["y"] = 2, ["param1"] = 81, ["z"] = 5, ["name"] = "default:steelblock"}, {["x"] = 5, ["y"] = 2, ["param1"] = 81, ["z"] = 6, ["name"] = "default:steelblock"}, {["x"] = 5, ["y"] = 2, ["param1"] = 81, ["z"] = 7, ["name"] = "default:steelblock"}, {["x"] = 5, ["y"] = 2, ["param1"] = 81, ["z"] = 8, ["name"] = "default:steelblock"}, {["x"] = 5, ["y"] = 2, ["param1"] = 81, ["z"] = 9, ["name"] = "default:steelblock"}, {["x"] = 5, ["y"] = 2, ["param1"] = 81, ["z"] = 10, ["name"] = "default:steelblock"}, {["x"] = 5, ["y"] = 2, ["param1"] = 81, ["z"] = 11, ["name"] = "default:steelblock"}, {["x"] = 5, ["y"] = 2, ["param1"] = 81, ["z"] = 12, ["name"] = "default:steelblock"}, {["x"] = 5, ["y"] = 2, ["param1"] = 81, ["z"] = 13, ["name"] = "default:steelblock"}, {["x"] = 5, ["y"] = 2, ["z"] = 14, ["name"] = "default:steelblock"}, {["x"] = 5, ["y"] = 2, ["z"] = 15, ["name"] = "default:steelblock"}, {["x"] = 5, ["y"] = 3, ["z"] = 1, ["name"] = "default:steelblock"}, {["x"] = 5, ["y"] = 3, ["param1"] = 81, ["z"] = 2, ["name"] = "default:steelblock"}, {["x"] = 5, ["y"] = 3, ["param1"] = 81, ["z"] = 3, ["name"] = "default:steelblock"}, {["x"] = 5, ["y"] = 3, ["param1"] = 81, ["z"] = 4, ["name"] = "default:steelblock"}, {["x"] = 5, ["y"] = 3, ["param1"] = 81, ["z"] = 5, ["name"] = "default:steelblock"}, {["x"] = 5, ["y"] = 3, ["param1"] = 81, ["z"] = 6, ["name"] = "default:steelblock"}, {["x"] = 5, ["y"] = 3, ["param1"] = 81, ["z"] = 7, ["name"] = "default:steelblock"}, {["x"] = 5, ["y"] = 3, ["param1"] = 81, ["z"] = 8, ["name"] = "default:steelblock"}, {["x"] = 5, ["y"] = 3, ["param1"] = 81, ["z"] = 9, ["name"] = "default:steelblock"}, {["x"] = 5, ["y"] = 3, ["param1"] = 81, ["z"] = 10, ["name"] = "default:steelblock"}, {["x"] = 5, ["y"] = 3, ["param1"] = 81, ["z"] = 11, ["name"] = "default:steelblock"}, {["x"] = 5, ["y"] = 3, ["param1"] = 81, ["z"] = 12, ["name"] = "default:steelblock"}, {["x"] = 5, ["y"] = 3, ["param1"] = 81, ["z"] = 13, ["name"] = "default:steelblock"}, {["x"] = 5, ["y"] = 3, ["z"] = 14, ["name"] = "default:steelblock"}, {["x"] = 5, ["y"] = 3, ["z"] = 15, ["name"] = "default:steelblock"}, {["x"] = 5, ["y"] = 4, ["z"] = 1, ["name"] = "default:steelblock"}, {["x"] = 5, ["y"] = 4, ["param1"] = 81, ["z"] = 2, ["name"] = "default:steelblock"}, {["x"] = 5, ["y"] = 4, ["param1"] = 81, ["z"] = 3, ["name"] = "default:steelblock"}, {["x"] = 5, ["y"] = 4, ["param1"] = 81, ["z"] = 4, ["name"] = "default:steelblock"}, {["x"] = 5, ["y"] = 4, ["param1"] = 81, ["z"] = 5, ["name"] = "default:steelblock"}, {["x"] = 5, ["y"] = 4, ["param1"] = 81, ["z"] = 6, ["name"] = "default:steelblock"}, {["x"] = 5, ["y"] = 4, ["param1"] = 81, ["z"] = 7, ["name"] = "default:steelblock"}, {["x"] = 5, ["y"] = 4, ["param1"] = 81, ["z"] = 8, ["name"] = "default:steelblock"}, {["x"] = 5, ["y"] = 4, ["param1"] = 81, ["z"] = 9, ["name"] = "default:steelblock"}, {["x"] = 5, ["y"] = 4, ["param1"] = 81, ["z"] = 10, ["name"] = "default:steelblock"}, {["x"] = 5, ["y"] = 4, ["param1"] = 81, ["z"] = 11, ["name"] = "default:steelblock"}, {["x"] = 5, ["y"] = 4, ["param1"] = 81, ["z"] = 12, ["name"] = "default:steelblock"}, {["x"] = 5, ["y"] = 4, ["param1"] = 81, ["z"] = 13, ["name"] = "default:steelblock"}, {["x"] = 5, ["y"] = 4, ["z"] = 14, ["name"] = "default:steelblock"}, {["x"] = 5, ["y"] = 4, ["z"] = 15, ["name"] = "default:steelblock"}, {["x"] = 5, ["y"] = 5, ["z"] = 1, ["name"] = "default:steelblock"}, {["x"] = 5, ["y"] = 5, ["param1"] = 81, ["z"] = 2, ["name"] = "default:steelblock"}, {["x"] = 5, ["y"] = 5, ["param1"] = 81, ["z"] = 3, ["name"] = "default:steelblock"}, {["x"] = 5, ["y"] = 5, ["param1"] = 81, ["z"] = 4, ["name"] = "default:steelblock"}, {["x"] = 5, ["y"] = 5, ["param1"] = 81, ["z"] = 5, ["name"] = "default:steelblock"}, {["x"] = 5, ["y"] = 5, ["param1"] = 81, ["z"] = 6, ["name"] = "default:steelblock"}, {["x"] = 5, ["y"] = 5, ["param1"] = 81, ["z"] = 7, ["name"] = "default:steelblock"}, {["x"] = 5, ["y"] = 5, ["param1"] = 81, ["z"] = 8, ["name"] = "default:steelblock"}, {["x"] = 5, ["y"] = 5, ["param1"] = 81, ["z"] = 9, ["name"] = "default:steelblock"}, {["x"] = 5, ["y"] = 5, ["param1"] = 81, ["z"] = 10, ["name"] = "default:steelblock"}, {["x"] = 5, ["y"] = 5, ["param1"] = 81, ["z"] = 11, ["name"] = "default:steelblock"}, {["x"] = 5, ["y"] = 5, ["param1"] = 81, ["z"] = 12, ["name"] = "default:steelblock"}, {["x"] = 5, ["y"] = 5, ["param1"] = 81, ["z"] = 13, ["name"] = "default:steelblock"}, {["x"] = 5, ["y"] = 5, ["z"] = 14, ["name"] = "default:steelblock"}, {["x"] = 5, ["y"] = 5, ["z"] = 15, ["name"] = "default:steelblock"}, {["x"] = 5, ["y"] = 6, ["z"] = 1, ["name"] = "default:steelblock"}, {["x"] = 5, ["y"] = 6, ["param1"] = 81, ["z"] = 2, ["name"] = "default:steelblock"}, {["x"] = 5, ["y"] = 6, ["param1"] = 81, ["z"] = 3, ["name"] = "default:steelblock"}, {["x"] = 5, ["y"] = 6, ["param1"] = 81, ["z"] = 4, ["name"] = "default:steelblock"}, {["x"] = 5, ["y"] = 6, ["z"] = 5, ["name"] = "default:steelblock"}, {["x"] = 5, ["y"] = 6, ["param1"] = 81, ["z"] = 6, ["name"] = "default:steelblock"}, {["x"] = 5, ["y"] = 6, ["param1"] = 81, ["z"] = 7, ["name"] = "default:steelblock"}, {["x"] = 5, ["y"] = 6, ["param1"] = 81, ["z"] = 8, ["name"] = "default:steelblock"}, {["x"] = 5, ["y"] = 6, ["param1"] = 81, ["z"] = 9, ["name"] = "default:steelblock"}, {["x"] = 5, ["y"] = 6, ["param1"] = 81, ["z"] = 10, ["name"] = "default:steelblock"}, {["x"] = 5, ["y"] = 6, ["param1"] = 81, ["z"] = 11, ["name"] = "default:steelblock"}, {["x"] = 5, ["y"] = 6, ["param1"] = 81, ["z"] = 12, ["name"] = "default:steelblock"}, {["x"] = 5, ["y"] = 6, ["param1"] = 81, ["z"] = 13, ["name"] = "default:steelblock"}, {["x"] = 5, ["y"] = 6, ["z"] = 14, ["name"] = "default:steelblock"}, {["x"] = 5, ["y"] = 6, ["z"] = 15, ["name"] = "default:steelblock"}, {["x"] = 5, ["y"] = 7, ["z"] = 3, ["name"] = "default:steelblock"}, {["x"] = 5, ["y"] = 7, ["param1"] = 81, ["z"] = 4, ["name"] = "default:steelblock"}, {["x"] = 5, ["y"] = 7, ["z"] = 6, ["name"] = "default:steelblock"}, {["x"] = 5, ["y"] = 7, ["param1"] = 81, ["z"] = 7, ["name"] = "default:steelblock"}, {["x"] = 5, ["y"] = 7, ["z"] = 9, ["name"] = "default:steelblock"}, {["x"] = 5, ["y"] = 7, ["z"] = 10, ["name"] = "default:steelblock"}, {["x"] = 5, ["y"] = 7, ["z"] = 12, ["name"] = "default:steelblock"}, {["x"] = 5, ["y"] = 7, ["z"] = 13, ["name"] = "default:steelblock"}, {["x"] = 5, ["y"] = 8, ["z"] = 0, ["name"] = "wool:grey"}, {["x"] = 5, ["y"] = 8, ["z"] = 1, ["name"] = "wool:grey"}, {["x"] = 5, ["y"] = 8, ["z"] = 3, ["name"] = "default:steelblock"}, {["x"] = 5, ["y"] = 8, ["param1"] = 81, ["z"] = 4, ["name"] = "default:steelblock"}, {["x"] = 5, ["y"] = 8, ["z"] = 6, ["name"] = "default:steelblock"}, {["x"] = 5, ["y"] = 8, ["param1"] = 81, ["z"] = 7, ["name"] = "default:steelblock"}, {["x"] = 5, ["y"] = 8, ["z"] = 9, ["name"] = "default:steelblock"}, {["x"] = 5, ["y"] = 8, ["z"] = 10, ["name"] = "default:steelblock"}, {["x"] = 5, ["y"] = 8, ["z"] = 12, ["name"] = "default:steelblock"}, {["x"] = 5, ["y"] = 8, ["z"] = 13, ["name"] = "default:steelblock"}, {["x"] = 5, ["y"] = 9, ["param1"] = 86, ["z"] = 0, ["name"] = "wool:grey"}, {["x"] = 5, ["y"] = 9, ["param1"] = 86, ["z"] = 1, ["name"] = "wool:grey"}, {["x"] = 5, ["y"] = 9, ["z"] = 3, ["name"] = "default:steelblock"}, {["x"] = 5, ["y"] = 9, ["param1"] = 81, ["z"] = 4, ["name"] = "default:steelblock"}, {["x"] = 5, ["y"] = 9, ["z"] = 6, ["name"] = "default:steelblock"}, {["x"] = 5, ["y"] = 9, ["param1"] = 81, ["z"] = 7, ["name"] = "default:steelblock"}, {["x"] = 5, ["y"] = 9, ["z"] = 9, ["name"] = "default:steelblock"}, {["x"] = 5, ["y"] = 9, ["param1"] = 81, ["z"] = 10, ["name"] = "default:steelblock"}, {["x"] = 5, ["y"] = 9, ["z"] = 12, ["name"] = "default:steelblock"}, {["x"] = 5, ["y"] = 9, ["z"] = 13, ["name"] = "default:steelblock"}, {["x"] = 5, ["y"] = 9, ["param1"] = 86, ["z"] = 14, ["name"] = "wool:grey"}, {["x"] = 5, ["y"] = 9, ["param1"] = 86, ["z"] = 15, ["name"] = "wool:grey"}, {["x"] = 5, ["y"] = 10, ["z"] = 3, ["name"] = "default:steelblock"}, {["x"] = 5, ["y"] = 10, ["param1"] = 81, ["z"] = 4, ["name"] = "default:steelblock"}, {["x"] = 5, ["y"] = 10, ["z"] = 6, ["name"] = "default:steelblock"}, {["x"] = 5, ["y"] = 10, ["param1"] = 81, ["z"] = 7, ["name"] = "default:steelblock"}, {["x"] = 5, ["y"] = 10, ["z"] = 9, ["name"] = "default:steelblock"}, {["x"] = 5, ["y"] = 10, ["param1"] = 81, ["z"] = 10, ["name"] = "default:steelblock"}, {["x"] = 5, ["y"] = 10, ["z"] = 12, ["name"] = "default:steelblock"}, {["x"] = 5, ["y"] = 10, ["z"] = 13, ["name"] = "default:steelblock"}, {["x"] = 5, ["y"] = 10, ["param1"] = 86, ["z"] = 14, ["name"] = "wool:grey"}, {["x"] = 5, ["y"] = 10, ["param1"] = 86, ["z"] = 15, ["name"] = "wool:grey"}, {["x"] = 5, ["y"] = 11, ["z"] = 3, ["name"] = "default:steelblock"}, {["x"] = 5, ["y"] = 11, ["param1"] = 81, ["z"] = 4, ["name"] = "default:steelblock"}, {["x"] = 5, ["y"] = 11, ["z"] = 6, ["name"] = "default:steelblock"}, {["x"] = 5, ["y"] = 11, ["param1"] = 81, ["z"] = 7, ["name"] = "default:steelblock"}, {["x"] = 5, ["y"] = 11, ["z"] = 9, ["name"] = "default:steelblock"}, {["x"] = 5, ["y"] = 11, ["param1"] = 81, ["z"] = 10, ["name"] = "default:steelblock"}, {["x"] = 5, ["y"] = 11, ["z"] = 12, ["name"] = "default:steelblock"}, {["x"] = 5, ["y"] = 11, ["z"] = 13, ["name"] = "default:steelblock"}, {["x"] = 5, ["y"] = 12, ["z"] = 3, ["name"] = "default:steelblock"}, {["x"] = 5, ["y"] = 12, ["param1"] = 81, ["z"] = 4, ["name"] = "default:steelblock"}, {["x"] = 5, ["y"] = 12, ["z"] = 6, ["name"] = "default:steelblock"}, {["x"] = 5, ["y"] = 12, ["param1"] = 81, ["z"] = 7, ["name"] = "default:steelblock"}, {["x"] = 5, ["y"] = 12, ["z"] = 9, ["name"] = "default:steelblock"}, {["x"] = 5, ["y"] = 12, ["param1"] = 81, ["z"] = 10, ["name"] = "default:steelblock"}, {["x"] = 5, ["y"] = 12, ["z"] = 12, ["name"] = "default:steelblock"}, {["x"] = 5, ["y"] = 12, ["z"] = 13, ["name"] = "default:steelblock"}, {["x"] = 5, ["y"] = 13, ["z"] = 3, ["name"] = "default:steelblock"}, {["x"] = 5, ["y"] = 13, ["param1"] = 81, ["z"] = 4, ["name"] = "default:steelblock"}, {["x"] = 5, ["y"] = 13, ["z"] = 6, ["name"] = "default:steelblock"}, {["x"] = 5, ["y"] = 13, ["param1"] = 81, ["z"] = 7, ["name"] = "default:steelblock"}, {["x"] = 5, ["y"] = 13, ["z"] = 9, ["name"] = "default:steelblock"}, {["x"] = 5, ["y"] = 13, ["param1"] = 81, ["z"] = 10, ["name"] = "default:steelblock"}, {["x"] = 5, ["y"] = 13, ["z"] = 12, ["name"] = "default:steelblock"}, {["x"] = 5, ["y"] = 13, ["z"] = 13, ["name"] = "default:steelblock"}, {["x"] = 5, ["y"] = 13, ["z"] = 14, ["name"] = "wool:green"}, {["x"] = 6, ["y"] = 0, ["param1"] = 81, ["z"] = 2, ["name"] = "default:steelblock"}, {["x"] = 6, ["y"] = 0, ["param1"] = 81, ["z"] = 3, ["name"] = "default:steelblock"}, {["x"] = 6, ["y"] = 0, ["param1"] = 81, ["z"] = 4, ["name"] = "default:steelblock"}, {["x"] = 6, ["y"] = 0, ["param1"] = 81, ["z"] = 5, ["name"] = "default:steelblock"}, {["x"] = 6, ["y"] = 0, ["param1"] = 81, ["z"] = 6, ["name"] = "default:steelblock"}, {["x"] = 6, ["y"] = 0, ["param1"] = 81, ["z"] = 7, ["name"] = "default:steelblock"}, {["x"] = 6, ["y"] = 0, ["param1"] = 81, ["z"] = 8, ["name"] = "default:steelblock"}, {["x"] = 6, ["y"] = 0, ["param1"] = 81, ["z"] = 9, ["name"] = "default:steelblock"}, {["x"] = 6, ["y"] = 0, ["param1"] = 81, ["z"] = 10, ["name"] = "default:steelblock"}, {["x"] = 6, ["y"] = 0, ["param1"] = 81, ["z"] = 11, ["name"] = "default:steelblock"}, {["x"] = 6, ["y"] = 0, ["param1"] = 81, ["z"] = 12, ["name"] = "default:steelblock"}, {["x"] = 6, ["y"] = 0, ["param1"] = 81, ["z"] = 13, ["name"] = "default:steelblock"}, {["x"] = 6, ["y"] = 0, ["z"] = 14, ["name"] = "default:steelblock"}, {["x"] = 6, ["y"] = 0, ["z"] = 15, ["name"] = "default:steelblock"}, {["x"] = 6, ["y"] = 1, ["param1"] = 86, ["z"] = 0, ["name"] = "wool:grey"}, {["x"] = 6, ["y"] = 1, ["param1"] = 86, ["z"] = 1, ["name"] = "wool:grey"}, {["x"] = 6, ["y"] = 1, ["param1"] = 81, ["z"] = 2, ["name"] = "default:steelblock"}, {["x"] = 6, ["y"] = 1, ["param1"] = 81, ["z"] = 3, ["name"] = "default:steelblock"}, {["x"] = 6, ["y"] = 1, ["param1"] = 81, ["z"] = 4, ["name"] = "default:steelblock"}, {["x"] = 6, ["y"] = 1, ["param1"] = 81, ["z"] = 5, ["name"] = "default:steelblock"}, {["x"] = 6, ["y"] = 1, ["param1"] = 81, ["z"] = 6, ["name"] = "default:steelblock"}, {["x"] = 6, ["y"] = 1, ["param1"] = 81, ["z"] = 7, ["name"] = "default:steelblock"}, {["x"] = 6, ["y"] = 1, ["param1"] = 81, ["z"] = 8, ["name"] = "default:steelblock"}, {["x"] = 6, ["y"] = 1, ["param1"] = 81, ["z"] = 9, ["name"] = "default:steelblock"}, {["x"] = 6, ["y"] = 1, ["param1"] = 81, ["z"] = 10, ["name"] = "default:steelblock"}, {["x"] = 6, ["y"] = 1, ["param1"] = 81, ["z"] = 11, ["name"] = "default:steelblock"}, {["x"] = 6, ["y"] = 1, ["param1"] = 81, ["z"] = 12, ["name"] = "default:steelblock"}, {["x"] = 6, ["y"] = 1, ["param1"] = 81, ["z"] = 13, ["name"] = "default:steelblock"}, {["x"] = 6, ["y"] = 1, ["z"] = 14, ["name"] = "default:steelblock"}, {["x"] = 6, ["y"] = 1, ["z"] = 15, ["name"] = "default:steelblock"}, {["x"] = 6, ["y"] = 2, ["param1"] = 86, ["z"] = 0, ["name"] = "wool:grey"}, {["x"] = 6, ["y"] = 2, ["param1"] = 86, ["z"] = 1, ["name"] = "wool:grey"}, {["x"] = 6, ["y"] = 2, ["param1"] = 81, ["z"] = 2, ["name"] = "default:steelblock"}, {["x"] = 6, ["y"] = 2, ["param1"] = 81, ["z"] = 3, ["name"] = "default:steelblock"}, {["x"] = 6, ["y"] = 2, ["param1"] = 81, ["z"] = 4, ["name"] = "default:steelblock"}, {["x"] = 6, ["y"] = 2, ["param1"] = 81, ["z"] = 5, ["name"] = "default:steelblock"}, {["x"] = 6, ["y"] = 2, ["param1"] = 81, ["z"] = 6, ["name"] = "default:steelblock"}, {["x"] = 6, ["y"] = 2, ["param1"] = 81, ["z"] = 7, ["name"] = "default:steelblock"}, {["x"] = 6, ["y"] = 2, ["param1"] = 81, ["z"] = 8, ["name"] = "default:steelblock"}, {["x"] = 6, ["y"] = 2, ["param1"] = 81, ["z"] = 9, ["name"] = "default:steelblock"}, {["x"] = 6, ["y"] = 2, ["param1"] = 81, ["z"] = 10, ["name"] = "default:steelblock"}, {["x"] = 6, ["y"] = 2, ["param1"] = 81, ["z"] = 11, ["name"] = "default:steelblock"}, {["x"] = 6, ["y"] = 2, ["param1"] = 81, ["z"] = 12, ["name"] = "default:steelblock"}, {["x"] = 6, ["y"] = 2, ["param1"] = 81, ["z"] = 13, ["name"] = "default:steelblock"}, {["x"] = 6, ["y"] = 2, ["z"] = 14, ["name"] = "default:steelblock"}, {["x"] = 6, ["y"] = 2, ["z"] = 15, ["name"] = "default:steelblock"}, {["x"] = 6, ["y"] = 3, ["z"] = 1, ["name"] = "default:steelblock"}, {["x"] = 6, ["y"] = 3, ["param1"] = 81, ["z"] = 2, ["name"] = "default:steelblock"}, {["x"] = 6, ["y"] = 3, ["param1"] = 81, ["z"] = 3, ["name"] = "default:steelblock"}, {["x"] = 6, ["y"] = 3, ["param1"] = 81, ["z"] = 4, ["name"] = "default:steelblock"}, {["x"] = 6, ["y"] = 3, ["param1"] = 81, ["z"] = 5, ["name"] = "default:steelblock"}, {["x"] = 6, ["y"] = 3, ["param1"] = 81, ["z"] = 6, ["name"] = "default:steelblock"}, {["x"] = 6, ["y"] = 3, ["param1"] = 81, ["z"] = 7, ["name"] = "default:steelblock"}, {["x"] = 6, ["y"] = 3, ["param1"] = 81, ["z"] = 8, ["name"] = "default:steelblock"}, {["x"] = 6, ["y"] = 3, ["param1"] = 81, ["z"] = 9, ["name"] = "default:steelblock"}, {["x"] = 6, ["y"] = 3, ["param1"] = 81, ["z"] = 10, ["name"] = "default:steelblock"}, {["x"] = 6, ["y"] = 3, ["param1"] = 81, ["z"] = 11, ["name"] = "default:steelblock"}, {["x"] = 6, ["y"] = 3, ["param1"] = 81, ["z"] = 12, ["name"] = "default:steelblock"}, {["x"] = 6, ["y"] = 3, ["param1"] = 81, ["z"] = 13, ["name"] = "default:steelblock"}, {["x"] = 6, ["y"] = 3, ["z"] = 14, ["name"] = "default:steelblock"}, {["x"] = 6, ["y"] = 3, ["z"] = 15, ["name"] = "default:steelblock"}, {["x"] = 6, ["y"] = 4, ["param1"] = 94, ["z"] = 0, ["name"] = "wool:yellow"}, {["x"] = 6, ["y"] = 4, ["param1"] = 94, ["z"] = 1, ["name"] = "wool:yellow"}, {["x"] = 6, ["y"] = 4, ["param1"] = 94, ["z"] = 2, ["name"] = "wool:yellow"}, {["x"] = 6, ["y"] = 4, ["param1"] = 81, ["z"] = 3, ["name"] = "default:steelblock"}, {["x"] = 6, ["y"] = 4, ["param1"] = 81, ["z"] = 4, ["name"] = "default:steelblock"}, {["x"] = 6, ["y"] = 4, ["param1"] = 81, ["z"] = 5, ["name"] = "default:steelblock"}, {["x"] = 6, ["y"] = 4, ["param1"] = 81, ["z"] = 6, ["name"] = "default:steelblock"}, {["x"] = 6, ["y"] = 4, ["param1"] = 81, ["z"] = 7, ["name"] = "default:steelblock"}, {["x"] = 6, ["y"] = 4, ["param1"] = 81, ["z"] = 8, ["name"] = "default:steelblock"}, {["x"] = 6, ["y"] = 4, ["param1"] = 81, ["z"] = 9, ["name"] = "default:steelblock"}, {["x"] = 6, ["y"] = 4, ["param1"] = 81, ["z"] = 10, ["name"] = "default:steelblock"}, {["x"] = 6, ["y"] = 4, ["param1"] = 81, ["z"] = 11, ["name"] = "default:steelblock"}, {["x"] = 6, ["y"] = 4, ["param1"] = 81, ["z"] = 12, ["name"] = "default:steelblock"}, {["x"] = 6, ["y"] = 4, ["param1"] = 94, ["z"] = 13, ["name"] = "wool:yellow"}, {["x"] = 6, ["y"] = 4, ["z"] = 14, ["name"] = "wool:yellow"}, {["x"] = 6, ["y"] = 4, ["z"] = 15, ["name"] = "wool:yellow"}, {["x"] = 6, ["y"] = 5, ["param1"] = 94, ["z"] = 0, ["name"] = "wool:yellow"}, {["x"] = 6, ["y"] = 5, ["param1"] = 94, ["z"] = 1, ["name"] = "wool:yellow"}, {["x"] = 6, ["y"] = 5, ["param1"] = 94, ["z"] = 2, ["name"] = "wool:yellow"}, {["x"] = 6, ["y"] = 5, ["param1"] = 81, ["z"] = 3, ["name"] = "default:steelblock"}, {["x"] = 6, ["y"] = 5, ["param1"] = 81, ["z"] = 4, ["name"] = "default:steelblock"}, {["x"] = 6, ["y"] = 5, ["param1"] = 81, ["z"] = 5, ["name"] = "default:steelblock"}, {["x"] = 6, ["y"] = 5, ["param1"] = 81, ["z"] = 6, ["name"] = "default:steelblock"}, {["x"] = 6, ["y"] = 5, ["param1"] = 81, ["z"] = 7, ["name"] = "default:steelblock"}, {["x"] = 6, ["y"] = 5, ["param1"] = 81, ["z"] = 8, ["name"] = "default:steelblock"}, {["x"] = 6, ["y"] = 5, ["param1"] = 81, ["z"] = 9, ["name"] = "default:steelblock"}, {["x"] = 6, ["y"] = 5, ["param1"] = 81, ["z"] = 10, ["name"] = "default:steelblock"}, {["x"] = 6, ["y"] = 5, ["param1"] = 81, ["z"] = 11, ["name"] = "default:steelblock"}, {["x"] = 6, ["y"] = 5, ["param1"] = 81, ["z"] = 12, ["name"] = "default:steelblock"}, {["x"] = 6, ["y"] = 5, ["param1"] = 94, ["z"] = 13, ["name"] = "wool:yellow"}, {["x"] = 6, ["y"] = 5, ["z"] = 14, ["name"] = "wool:yellow"}, {["x"] = 6, ["y"] = 5, ["z"] = 15, ["name"] = "wool:yellow"}, {["x"] = 6, ["y"] = 6, ["z"] = 1, ["name"] = "default:steelblock"}, {["x"] = 6, ["y"] = 6, ["param1"] = 81, ["z"] = 2, ["name"] = "default:steelblock"}, {["x"] = 6, ["y"] = 6, ["param1"] = 81, ["z"] = 3, ["name"] = "default:steelblock"}, {["x"] = 6, ["y"] = 6, ["param1"] = 81, ["z"] = 4, ["name"] = "default:steelblock"}, {["x"] = 6, ["y"] = 6, ["param1"] = 81, ["z"] = 5, ["name"] = "default:steelblock"}, {["x"] = 6, ["y"] = 6, ["param1"] = 81, ["z"] = 6, ["name"] = "default:steelblock"}, {["x"] = 6, ["y"] = 6, ["param1"] = 81, ["z"] = 7, ["name"] = "default:steelblock"}, {["x"] = 6, ["y"] = 6, ["param1"] = 81, ["z"] = 8, ["name"] = "default:steelblock"}, {["x"] = 6, ["y"] = 6, ["param1"] = 81, ["z"] = 9, ["name"] = "default:steelblock"}, {["x"] = 6, ["y"] = 6, ["param1"] = 81, ["z"] = 10, ["name"] = "default:steelblock"}, {["x"] = 6, ["y"] = 6, ["param1"] = 81, ["z"] = 11, ["name"] = "default:steelblock"}, {["x"] = 6, ["y"] = 6, ["param1"] = 81, ["z"] = 12, ["name"] = "default:steelblock"}, {["x"] = 6, ["y"] = 6, ["param1"] = 81, ["z"] = 13, ["name"] = "default:steelblock"}, {["x"] = 6, ["y"] = 6, ["z"] = 14, ["name"] = "default:steelblock"}, {["x"] = 6, ["y"] = 6, ["z"] = 15, ["name"] = "default:steelblock"}, {["x"] = 6, ["y"] = 7, ["z"] = 1, ["name"] = "default:steelblock"}, {["x"] = 6, ["y"] = 7, ["param1"] = 81, ["z"] = 2, ["name"] = "default:steelblock"}, {["x"] = 6, ["y"] = 7, ["param1"] = 81, ["z"] = 3, ["name"] = "default:steelblock"}, {["x"] = 6, ["y"] = 7, ["param1"] = 81, ["z"] = 4, ["name"] = "default:steelblock"}, {["x"] = 6, ["y"] = 7, ["param1"] = 81, ["z"] = 5, ["name"] = "default:steelblock"}, {["x"] = 6, ["y"] = 7, ["param1"] = 81, ["z"] = 6, ["name"] = "default:steelblock"}, {["x"] = 6, ["y"] = 7, ["param1"] = 81, ["z"] = 7, ["name"] = "default:steelblock"}, {["x"] = 6, ["y"] = 7, ["param1"] = 81, ["z"] = 8, ["name"] = "default:steelblock"}, {["x"] = 6, ["y"] = 7, ["param1"] = 81, ["z"] = 9, ["name"] = "default:steelblock"}, {["x"] = 6, ["y"] = 7, ["param1"] = 81, ["z"] = 10, ["name"] = "default:steelblock"}, {["x"] = 6, ["y"] = 7, ["param1"] = 81, ["z"] = 11, ["name"] = "default:steelblock"}, {["x"] = 6, ["y"] = 7, ["param1"] = 81, ["z"] = 12, ["name"] = "default:steelblock"}, {["x"] = 6, ["y"] = 7, ["param1"] = 81, ["z"] = 13, ["name"] = "default:steelblock"}, {["x"] = 6, ["y"] = 7, ["z"] = 14, ["name"] = "default:steelblock"}, {["x"] = 6, ["y"] = 7, ["z"] = 15, ["name"] = "default:steelblock"}, {["x"] = 6, ["y"] = 8, ["z"] = 0, ["name"] = "wool:grey"}, {["x"] = 6, ["y"] = 8, ["z"] = 1, ["name"] = "wool:grey"}, {["x"] = 6, ["y"] = 8, ["param1"] = 93, ["z"] = 5, ["name"] = "wool:green"}, {["x"] = 6, ["y"] = 8, ["z"] = 6, ["name"] = "default:steelblock"}, {["x"] = 6, ["y"] = 8, ["z"] = 7, ["name"] = "default:steelblock"}, {["x"] = 6, ["y"] = 8, ["param1"] = 93, ["z"] = 8, ["name"] = "wool:green"}, {["x"] = 6, ["y"] = 8, ["param1"] = 81, ["z"] = 9, ["name"] = "default:steelblock"}, {["x"] = 6, ["y"] = 8, ["param1"] = 81, ["z"] = 10, ["name"] = "default:steelblock"}, {["x"] = 6, ["y"] = 8, ["param1"] = 93, ["z"] = 11, ["name"] = "wool:green"}, {["x"] = 6, ["y"] = 8, ["param1"] = 81, ["z"] = 12, ["name"] = "default:steelblock"}, {["x"] = 6, ["y"] = 8, ["param1"] = 81, ["z"] = 13, ["name"] = "default:steelblock"}, {["x"] = 6, ["y"] = 8, ["z"] = 14, ["name"] = "default:steelblock"}, {["x"] = 6, ["y"] = 8, ["z"] = 15, ["name"] = "default:steelblock"}, {["x"] = 6, ["y"] = 9, ["param1"] = 86, ["z"] = 0, ["name"] = "wool:grey"}, {["x"] = 6, ["y"] = 9, ["param1"] = 86, ["z"] = 1, ["name"] = "wool:grey"}, {["x"] = 6, ["y"] = 9, ["param1"] = 93, ["z"] = 5, ["name"] = "wool:green"}, {["x"] = 6, ["y"] = 9, ["param1"] = 93, ["z"] = 6, ["name"] = "wool:green"}, {["x"] = 6, ["y"] = 9, ["param1"] = 93, ["z"] = 7, ["name"] = "wool:green"}, {["x"] = 6, ["y"] = 9, ["param1"] = 93, ["z"] = 8, ["name"] = "wool:green"}, {["x"] = 6, ["y"] = 9, ["param1"] = 93, ["z"] = 9, ["name"] = "wool:green"}, {["x"] = 6, ["y"] = 9, ["param1"] = 93, ["z"] = 10, ["name"] = "wool:green"}, {["x"] = 6, ["y"] = 9, ["param1"] = 93, ["z"] = 11, ["name"] = "wool:green"}, {["x"] = 6, ["y"] = 9, ["param1"] = 81, ["z"] = 12, ["name"] = "default:steelblock"}, {["x"] = 6, ["y"] = 9, ["param1"] = 81, ["z"] = 13, ["name"] = "default:steelblock"}, {["x"] = 6, ["y"] = 9, ["param1"] = 86, ["z"] = 14, ["name"] = "wool:grey"}, {["x"] = 6, ["y"] = 9, ["param1"] = 86, ["z"] = 15, ["name"] = "wool:grey"}, {["x"] = 6, ["y"] = 10, ["z"] = 2, ["name"] = "default:steelblock"}, {["x"] = 6, ["y"] = 10, ["z"] = 3, ["name"] = "default:steelblock"}, {["x"] = 6, ["y"] = 10, ["z"] = 4, ["name"] = "default:steelblock"}, {["x"] = 6, ["y"] = 10, ["z"] = 5, ["name"] = "default:steelblock"}, {["x"] = 6, ["y"] = 10, ["z"] = 6, ["name"] = "default:steelblock"}, {["x"] = 6, ["y"] = 10, ["z"] = 7, ["name"] = "default:steelblock"}, {["x"] = 6, ["y"] = 10, ["z"] = 8, ["name"] = "default:steelblock"}, {["x"] = 6, ["y"] = 10, ["param1"] = 81, ["z"] = 9, ["name"] = "default:steelblock"}, {["x"] = 6, ["y"] = 10, ["param1"] = 81, ["z"] = 10, ["name"] = "default:steelblock"}, {["x"] = 6, ["y"] = 10, ["param1"] = 81, ["z"] = 11, ["name"] = "default:steelblock"}, {["x"] = 6, ["y"] = 10, ["param1"] = 81, ["z"] = 12, ["name"] = "default:steelblock"}, {["x"] = 6, ["y"] = 10, ["param1"] = 81, ["z"] = 13, ["name"] = "default:steelblock"}, {["x"] = 6, ["y"] = 10, ["param1"] = 86, ["z"] = 14, ["name"] = "wool:grey"}, {["x"] = 6, ["y"] = 10, ["param1"] = 86, ["z"] = 15, ["name"] = "wool:grey"}, {["x"] = 6, ["y"] = 11, ["z"] = 2, ["name"] = "default:steelblock"}, {["x"] = 6, ["y"] = 11, ["z"] = 3, ["name"] = "default:steelblock"}, {["x"] = 6, ["y"] = 11, ["z"] = 4, ["name"] = "default:steelblock"}, {["x"] = 6, ["y"] = 11, ["z"] = 5, ["name"] = "default:steelblock"}, {["x"] = 6, ["y"] = 11, ["z"] = 6, ["name"] = "default:steelblock"}, {["x"] = 6, ["y"] = 11, ["z"] = 7, ["name"] = "default:steelblock"}, {["x"] = 6, ["y"] = 11, ["z"] = 8, ["name"] = "default:steelblock"}, {["x"] = 6, ["y"] = 11, ["param1"] = 81, ["z"] = 9, ["name"] = "default:steelblock"}, {["x"] = 6, ["y"] = 11, ["param1"] = 81, ["z"] = 10, ["name"] = "default:steelblock"}, {["x"] = 6, ["y"] = 11, ["param1"] = 81, ["z"] = 11, ["name"] = "default:steelblock"}, {["x"] = 6, ["y"] = 11, ["param1"] = 81, ["z"] = 12, ["name"] = "default:steelblock"}, {["x"] = 6, ["y"] = 11, ["param1"] = 81, ["z"] = 13, ["name"] = "default:steelblock"}, {["x"] = 6, ["y"] = 11, ["param1"] = 81, ["z"] = 14, ["name"] = "default:steelblock"}, {["x"] = 6, ["y"] = 11, ["param1"] = 81, ["z"] = 15, ["name"] = "default:steelblock"}, {["x"] = 6, ["y"] = 12, ["z"] = 2, ["name"] = "default:steelblock"}, {["x"] = 6, ["y"] = 12, ["z"] = 3, ["name"] = "default:steelblock"}, {["x"] = 6, ["y"] = 12, ["z"] = 4, ["name"] = "default:steelblock"}, {["x"] = 6, ["y"] = 12, ["z"] = 5, ["name"] = "default:steelblock"}, {["x"] = 6, ["y"] = 12, ["z"] = 6, ["name"] = "default:steelblock"}, {["x"] = 6, ["y"] = 12, ["z"] = 7, ["name"] = "default:steelblock"}, {["x"] = 6, ["y"] = 12, ["z"] = 8, ["name"] = "default:steelblock"}, {["x"] = 6, ["y"] = 12, ["param1"] = 81, ["z"] = 9, ["name"] = "default:steelblock"}, {["x"] = 6, ["y"] = 12, ["param1"] = 81, ["z"] = 10, ["name"] = "default:steelblock"}, {["x"] = 6, ["y"] = 12, ["param1"] = 81, ["z"] = 11, ["name"] = "default:steelblock"}, {["x"] = 6, ["y"] = 12, ["param1"] = 81, ["z"] = 12, ["name"] = "default:steelblock"}, {["x"] = 6, ["y"] = 12, ["param1"] = 81, ["z"] = 13, ["name"] = "default:steelblock"}, {["x"] = 6, ["y"] = 13, ["param1"] = 93, ["z"] = 5, ["name"] = "wool:green"}, {["x"] = 6, ["y"] = 13, ["param1"] = 93, ["z"] = 6, ["name"] = "wool:green"}, {["x"] = 6, ["y"] = 13, ["param1"] = 93, ["z"] = 7, ["name"] = "wool:green"}, {["x"] = 6, ["y"] = 13, ["param1"] = 93, ["z"] = 8, ["name"] = "wool:green"}, {["x"] = 6, ["y"] = 13, ["param1"] = 93, ["z"] = 9, ["name"] = "wool:green"}, {["x"] = 6, ["y"] = 13, ["param1"] = 93, ["z"] = 10, ["name"] = "wool:green"}, {["x"] = 6, ["y"] = 13, ["param1"] = 93, ["z"] = 11, ["name"] = "wool:green"}, {["x"] = 6, ["y"] = 13, ["param1"] = 93, ["z"] = 12, ["name"] = "wool:green"}, {["x"] = 6, ["y"] = 13, ["z"] = 13, ["name"] = "wool:green"}, {["x"] = 6, ["y"] = 14, ["param1"] = 93, ["z"] = 11, ["name"] = "wool:green"}, {["x"] = 6, ["y"] = 14, ["param1"] = 93, ["z"] = 12, ["name"] = "wool:green"}, {["x"] = 6, ["y"] = 15, ["param1"] = 93, ["z"] = 11, ["name"] = "wool:green"}, {["x"] = 6, ["y"] = 15, ["param1"] = 93, ["z"] = 12, ["name"] = "wool:green"}, {["x"] = 7, ["y"] = 0, ["param1"] = 81, ["z"] = 2, ["name"] = "default:steelblock"}, {["x"] = 7, ["y"] = 0, ["param1"] = 81, ["z"] = 3, ["name"] = "default:steelblock"}, {["x"] = 7, ["y"] = 0, ["param1"] = 81, ["z"] = 4, ["name"] = "default:steelblock"}, {["x"] = 7, ["y"] = 0, ["param1"] = 81, ["z"] = 5, ["name"] = "default:steelblock"}, {["x"] = 7, ["y"] = 0, ["param1"] = 81, ["z"] = 6, ["name"] = "default:steelblock"}, {["x"] = 7, ["y"] = 0, ["param1"] = 81, ["z"] = 7, ["name"] = "default:steelblock"}, {["x"] = 7, ["y"] = 0, ["param1"] = 81, ["z"] = 8, ["name"] = "default:steelblock"}, {["x"] = 7, ["y"] = 0, ["param1"] = 81, ["z"] = 9, ["name"] = "default:steelblock"}, {["x"] = 7, ["y"] = 0, ["param1"] = 81, ["z"] = 10, ["name"] = "default:steelblock"}, {["x"] = 7, ["y"] = 0, ["param1"] = 81, ["z"] = 11, ["name"] = "default:steelblock"}, {["x"] = 7, ["y"] = 0, ["param1"] = 81, ["z"] = 12, ["name"] = "default:steelblock"}, {["x"] = 7, ["y"] = 0, ["param1"] = 81, ["z"] = 13, ["name"] = "default:steelblock"}, {["x"] = 7, ["y"] = 0, ["z"] = 14, ["name"] = "default:steelblock"}, {["x"] = 7, ["y"] = 0, ["z"] = 15, ["name"] = "default:steelblock"}, {["x"] = 7, ["y"] = 1, ["param1"] = 86, ["z"] = 0, ["name"] = "wool:grey"}, {["x"] = 7, ["y"] = 1, ["param1"] = 86, ["z"] = 1, ["name"] = "wool:grey"}, {["x"] = 7, ["y"] = 1, ["param1"] = 81, ["z"] = 2, ["name"] = "default:steelblock"}, {["x"] = 7, ["y"] = 1, ["param1"] = 81, ["z"] = 3, ["name"] = "default:steelblock"}, {["x"] = 7, ["y"] = 1, ["param1"] = 81, ["z"] = 4, ["name"] = "default:steelblock"}, {["x"] = 7, ["y"] = 1, ["param1"] = 81, ["z"] = 5, ["name"] = "default:steelblock"}, {["x"] = 7, ["y"] = 1, ["param1"] = 81, ["z"] = 6, ["name"] = "default:steelblock"}, {["x"] = 7, ["y"] = 1, ["param1"] = 81, ["z"] = 7, ["name"] = "default:steelblock"}, {["x"] = 7, ["y"] = 1, ["param1"] = 81, ["z"] = 8, ["name"] = "default:steelblock"}, {["x"] = 7, ["y"] = 1, ["param1"] = 81, ["z"] = 9, ["name"] = "default:steelblock"}, {["x"] = 7, ["y"] = 1, ["param1"] = 81, ["z"] = 10, ["name"] = "default:steelblock"}, {["x"] = 7, ["y"] = 1, ["param1"] = 81, ["z"] = 11, ["name"] = "default:steelblock"}, {["x"] = 7, ["y"] = 1, ["param1"] = 81, ["z"] = 12, ["name"] = "default:steelblock"}, {["x"] = 7, ["y"] = 1, ["param1"] = 81, ["z"] = 13, ["name"] = "default:steelblock"}, {["x"] = 7, ["y"] = 1, ["z"] = 14, ["name"] = "default:steelblock"}, {["x"] = 7, ["y"] = 1, ["z"] = 15, ["name"] = "default:steelblock"}, {["x"] = 7, ["y"] = 2, ["param1"] = 86, ["z"] = 0, ["name"] = "wool:grey"}, {["x"] = 7, ["y"] = 2, ["param1"] = 86, ["z"] = 1, ["name"] = "wool:grey"}, {["x"] = 7, ["y"] = 2, ["param1"] = 81, ["z"] = 2, ["name"] = "default:steelblock"}, {["x"] = 7, ["y"] = 2, ["param1"] = 81, ["z"] = 3, ["name"] = "default:steelblock"}, {["x"] = 7, ["y"] = 2, ["param1"] = 81, ["z"] = 4, ["name"] = "default:steelblock"}, {["x"] = 7, ["y"] = 2, ["param1"] = 81, ["z"] = 5, ["name"] = "default:steelblock"}, {["x"] = 7, ["y"] = 2, ["param1"] = 81, ["z"] = 6, ["name"] = "default:steelblock"}, {["x"] = 7, ["y"] = 2, ["param1"] = 81, ["z"] = 7, ["name"] = "default:steelblock"}, {["x"] = 7, ["y"] = 2, ["param1"] = 81, ["z"] = 8, ["name"] = "default:steelblock"}, {["x"] = 7, ["y"] = 2, ["param1"] = 81, ["z"] = 9, ["name"] = "default:steelblock"}, {["x"] = 7, ["y"] = 2, ["param1"] = 81, ["z"] = 10, ["name"] = "default:steelblock"}, {["x"] = 7, ["y"] = 2, ["param1"] = 81, ["z"] = 11, ["name"] = "default:steelblock"}, {["x"] = 7, ["y"] = 2, ["param1"] = 81, ["z"] = 12, ["name"] = "default:steelblock"}, {["x"] = 7, ["y"] = 2, ["param1"] = 81, ["z"] = 13, ["name"] = "default:steelblock"}, {["x"] = 7, ["y"] = 2, ["z"] = 14, ["name"] = "default:steelblock"}, {["x"] = 7, ["y"] = 2, ["z"] = 15, ["name"] = "default:steelblock"}, {["x"] = 7, ["y"] = 3, ["param1"] = 94, ["z"] = 0, ["name"] = "wool:yellow"}, {["x"] = 7, ["y"] = 3, ["param1"] = 94, ["z"] = 1, ["name"] = "wool:yellow"}, {["x"] = 7, ["y"] = 3, ["param1"] = 94, ["z"] = 2, ["name"] = "wool:yellow"}, {["x"] = 7, ["y"] = 3, ["param1"] = 81, ["z"] = 3, ["name"] = "default:steelblock"}, {["x"] = 7, ["y"] = 3, ["param1"] = 81, ["z"] = 4, ["name"] = "default:steelblock"}, {["x"] = 7, ["y"] = 3, ["param1"] = 81, ["z"] = 5, ["name"] = "default:steelblock"}, {["x"] = 7, ["y"] = 3, ["param1"] = 81, ["z"] = 6, ["name"] = "default:steelblock"}, {["x"] = 7, ["y"] = 3, ["param1"] = 81, ["z"] = 7, ["name"] = "default:steelblock"}, {["x"] = 7, ["y"] = 3, ["param1"] = 81, ["z"] = 8, ["name"] = "default:steelblock"}, {["x"] = 7, ["y"] = 3, ["param1"] = 81, ["z"] = 9, ["name"] = "default:steelblock"}, {["x"] = 7, ["y"] = 3, ["param1"] = 81, ["z"] = 10, ["name"] = "default:steelblock"}, {["x"] = 7, ["y"] = 3, ["param1"] = 81, ["z"] = 11, ["name"] = "default:steelblock"}, {["x"] = 7, ["y"] = 3, ["param1"] = 81, ["z"] = 12, ["name"] = "default:steelblock"}, {["x"] = 7, ["y"] = 3, ["param1"] = 94, ["z"] = 13, ["name"] = "wool:yellow"}, {["x"] = 7, ["y"] = 3, ["z"] = 14, ["name"] = "wool:yellow"}, {["x"] = 7, ["y"] = 3, ["z"] = 15, ["name"] = "wool:yellow"}, {["x"] = 7, ["y"] = 4, ["param1"] = 94, ["z"] = 0, ["name"] = "wool:yellow"}, {["x"] = 7, ["y"] = 4, ["param1"] = 94, ["z"] = 1, ["name"] = "wool:yellow"}, {["x"] = 7, ["y"] = 4, ["param1"] = 94, ["z"] = 2, ["name"] = "wool:yellow"}, {["x"] = 7, ["y"] = 4, ["param1"] = 81, ["z"] = 3, ["name"] = "default:steelblock"}, {["x"] = 7, ["y"] = 4, ["param1"] = 81, ["z"] = 4, ["name"] = "default:steelblock"}, {["x"] = 7, ["y"] = 4, ["param1"] = 81, ["z"] = 5, ["name"] = "default:steelblock"}, {["x"] = 7, ["y"] = 4, ["param1"] = 81, ["z"] = 6, ["name"] = "default:steelblock"}, {["x"] = 7, ["y"] = 4, ["param1"] = 81, ["z"] = 7, ["name"] = "default:steelblock"}, {["x"] = 7, ["y"] = 4, ["param1"] = 81, ["z"] = 8, ["name"] = "default:steelblock"}, {["x"] = 7, ["y"] = 4, ["param1"] = 81, ["z"] = 9, ["name"] = "default:steelblock"}, {["x"] = 7, ["y"] = 4, ["param1"] = 81, ["z"] = 10, ["name"] = "default:steelblock"}, {["x"] = 7, ["y"] = 4, ["param1"] = 81, ["z"] = 11, ["name"] = "default:steelblock"}, {["x"] = 7, ["y"] = 4, ["param1"] = 81, ["z"] = 12, ["name"] = "default:steelblock"}, {["x"] = 7, ["y"] = 4, ["param1"] = 94, ["z"] = 13, ["name"] = "wool:yellow"}, {["x"] = 7, ["y"] = 4, ["z"] = 14, ["name"] = "wool:yellow"}, {["x"] = 7, ["y"] = 4, ["z"] = 15, ["name"] = "wool:yellow"}, {["x"] = 7, ["y"] = 5, ["param1"] = 94, ["z"] = 0, ["name"] = "wool:yellow"}, {["x"] = 7, ["y"] = 5, ["param1"] = 94, ["z"] = 1, ["name"] = "wool:yellow"}, {["x"] = 7, ["y"] = 5, ["param1"] = 94, ["z"] = 2, ["name"] = "wool:yellow"}, {["x"] = 7, ["y"] = 5, ["param1"] = 81, ["z"] = 3, ["name"] = "default:steelblock"}, {["x"] = 7, ["y"] = 5, ["param1"] = 81, ["z"] = 4, ["name"] = "default:steelblock"}, {["x"] = 7, ["y"] = 5, ["param1"] = 81, ["z"] = 5, ["name"] = "default:steelblock"}, {["x"] = 7, ["y"] = 5, ["param1"] = 81, ["z"] = 6, ["name"] = "default:steelblock"}, {["x"] = 7, ["y"] = 5, ["param1"] = 81, ["z"] = 7, ["name"] = "default:steelblock"}, {["x"] = 7, ["y"] = 5, ["param1"] = 81, ["z"] = 8, ["name"] = "default:steelblock"}, {["x"] = 7, ["y"] = 5, ["param1"] = 81, ["z"] = 9, ["name"] = "default:steelblock"}, {["x"] = 7, ["y"] = 5, ["param1"] = 81, ["z"] = 10, ["name"] = "default:steelblock"}, {["x"] = 7, ["y"] = 5, ["param1"] = 81, ["z"] = 11, ["name"] = "default:steelblock"}, {["x"] = 7, ["y"] = 5, ["param1"] = 81, ["z"] = 12, ["name"] = "default:steelblock"}, {["x"] = 7, ["y"] = 5, ["param1"] = 94, ["z"] = 13, ["name"] = "wool:yellow"}, {["x"] = 7, ["y"] = 5, ["z"] = 14, ["name"] = "wool:yellow"}, {["x"] = 7, ["y"] = 5, ["z"] = 15, ["name"] = "wool:yellow"}, {["x"] = 7, ["y"] = 6, ["param1"] = 94, ["z"] = 0, ["name"] = "wool:yellow"}, {["x"] = 7, ["y"] = 6, ["param1"] = 94, ["z"] = 1, ["name"] = "wool:yellow"}, {["x"] = 7, ["y"] = 6, ["param1"] = 94, ["z"] = 2, ["name"] = "wool:yellow"}, {["x"] = 7, ["y"] = 6, ["param1"] = 81, ["z"] = 3, ["name"] = "default:steelblock"}, {["x"] = 7, ["y"] = 6, ["param1"] = 81, ["z"] = 4, ["name"] = "default:steelblock"}, {["x"] = 7, ["y"] = 6, ["param1"] = 81, ["z"] = 5, ["name"] = "default:steelblock"}, {["x"] = 7, ["y"] = 6, ["param1"] = 81, ["z"] = 6, ["name"] = "default:steelblock"}, {["x"] = 7, ["y"] = 6, ["param1"] = 81, ["z"] = 7, ["name"] = "default:steelblock"}, {["x"] = 7, ["y"] = 6, ["param1"] = 81, ["z"] = 8, ["name"] = "default:steelblock"}, {["x"] = 7, ["y"] = 6, ["param1"] = 81, ["z"] = 9, ["name"] = "default:steelblock"}, {["x"] = 7, ["y"] = 6, ["param1"] = 81, ["z"] = 10, ["name"] = "default:steelblock"}, {["x"] = 7, ["y"] = 6, ["param1"] = 81, ["z"] = 11, ["name"] = "default:steelblock"}, {["x"] = 7, ["y"] = 6, ["param1"] = 81, ["z"] = 12, ["name"] = "default:steelblock"}, {["x"] = 7, ["y"] = 6, ["param1"] = 94, ["z"] = 13, ["name"] = "wool:yellow"}, {["x"] = 7, ["y"] = 6, ["z"] = 14, ["name"] = "wool:yellow"}, {["x"] = 7, ["y"] = 6, ["z"] = 15, ["name"] = "wool:yellow"}, {["x"] = 7, ["y"] = 7, ["z"] = 1, ["name"] = "default:steelblock"}, {["x"] = 7, ["y"] = 7, ["param1"] = 81, ["z"] = 2, ["name"] = "default:steelblock"}, {["x"] = 7, ["y"] = 7, ["param1"] = 81, ["z"] = 3, ["name"] = "default:steelblock"}, {["x"] = 7, ["y"] = 7, ["param1"] = 81, ["z"] = 4, ["name"] = "default:steelblock"}, {["x"] = 7, ["y"] = 7, ["param1"] = 81, ["z"] = 5, ["name"] = "default:steelblock"}, {["x"] = 7, ["y"] = 7, ["param1"] = 81, ["z"] = 6, ["name"] = "default:steelblock"}, {["x"] = 7, ["y"] = 7, ["param1"] = 81, ["z"] = 7, ["name"] = "default:steelblock"}, {["x"] = 7, ["y"] = 7, ["param1"] = 81, ["z"] = 8, ["name"] = "default:steelblock"}, {["x"] = 7, ["y"] = 7, ["param1"] = 81, ["z"] = 9, ["name"] = "default:steelblock"}, {["x"] = 7, ["y"] = 7, ["param1"] = 81, ["z"] = 10, ["name"] = "default:steelblock"}, {["x"] = 7, ["y"] = 7, ["param1"] = 81, ["z"] = 11, ["name"] = "default:steelblock"}, {["x"] = 7, ["y"] = 7, ["param1"] = 81, ["z"] = 12, ["name"] = "default:steelblock"}, {["x"] = 7, ["y"] = 7, ["param1"] = 81, ["z"] = 13, ["name"] = "default:steelblock"}, {["x"] = 7, ["y"] = 7, ["z"] = 14, ["name"] = "default:steelblock"}, {["x"] = 7, ["y"] = 7, ["z"] = 15, ["name"] = "default:steelblock"}, {["x"] = 7, ["y"] = 8, ["z"] = 0, ["name"] = "wool:grey"}, {["x"] = 7, ["y"] = 8, ["z"] = 1, ["name"] = "wool:grey"}, {["x"] = 7, ["y"] = 8, ["z"] = 4, ["name"] = "default:steelblock"}, {["x"] = 7, ["y"] = 8, ["z"] = 5, ["name"] = "default:steelblock"}, {["x"] = 7, ["y"] = 8, ["z"] = 6, ["name"] = "default:steelblock"}, {["x"] = 7, ["y"] = 8, ["z"] = 7, ["name"] = "default:steelblock"}, {["x"] = 7, ["y"] = 8, ["z"] = 8, ["name"] = "default:steelblock"}, {["x"] = 7, ["y"] = 8, ["param1"] = 81, ["z"] = 9, ["name"] = "default:steelblock"}, {["x"] = 7, ["y"] = 8, ["param1"] = 81, ["z"] = 10, ["name"] = "default:steelblock"}, {["x"] = 7, ["y"] = 8, ["param1"] = 81, ["z"] = 11, ["name"] = "default:steelblock"}, {["x"] = 7, ["y"] = 8, ["param1"] = 81, ["z"] = 12, ["name"] = "default:steelblock"}, {["x"] = 7, ["y"] = 8, ["param1"] = 81, ["z"] = 13, ["name"] = "default:steelblock"}, {["x"] = 7, ["y"] = 8, ["z"] = 14, ["name"] = "default:steelblock"}, {["x"] = 7, ["y"] = 8, ["z"] = 15, ["name"] = "default:steelblock"}, {["x"] = 7, ["y"] = 9, ["param1"] = 86, ["z"] = 0, ["name"] = "wool:grey"}, {["x"] = 7, ["y"] = 9, ["param1"] = 86, ["z"] = 1, ["name"] = "wool:grey"}, {["x"] = 7, ["y"] = 9, ["z"] = 2, ["name"] = "default:steelblock"}, {["x"] = 7, ["y"] = 9, ["z"] = 3, ["name"] = "default:steelblock"}, {["x"] = 7, ["y"] = 9, ["z"] = 4, ["name"] = "default:steelblock"}, {["x"] = 7, ["y"] = 9, ["z"] = 5, ["name"] = "default:steelblock"}, {["x"] = 7, ["y"] = 9, ["z"] = 6, ["name"] = "default:steelblock"}, {["x"] = 7, ["y"] = 9, ["z"] = 7, ["name"] = "default:steelblock"}, {["x"] = 7, ["y"] = 9, ["z"] = 8, ["name"] = "default:steelblock"}, {["x"] = 7, ["y"] = 9, ["param1"] = 81, ["z"] = 9, ["name"] = "default:steelblock"}, {["x"] = 7, ["y"] = 9, ["param1"] = 81, ["z"] = 10, ["name"] = "default:steelblock"}, {["x"] = 7, ["y"] = 9, ["param1"] = 81, ["z"] = 11, ["name"] = "default:steelblock"}, {["x"] = 7, ["y"] = 9, ["param1"] = 81, ["z"] = 12, ["name"] = "default:steelblock"}, {["x"] = 7, ["y"] = 9, ["param1"] = 81, ["z"] = 13, ["name"] = "default:steelblock"}, {["x"] = 7, ["y"] = 9, ["param1"] = 86, ["z"] = 14, ["name"] = "wool:grey"}, {["x"] = 7, ["y"] = 9, ["param1"] = 86, ["z"] = 15, ["name"] = "wool:grey"}, {["x"] = 7, ["y"] = 10, ["param1"] = 81, ["z"] = 9, ["name"] = "default:steelblock"}, {["x"] = 7, ["y"] = 10, ["param1"] = 81, ["z"] = 10, ["name"] = "default:steelblock"}, {["x"] = 7, ["y"] = 10, ["param1"] = 81, ["z"] = 11, ["name"] = "default:steelblock"}, {["x"] = 7, ["y"] = 10, ["param1"] = 81, ["z"] = 12, ["name"] = "default:steelblock"}, {["x"] = 7, ["y"] = 10, ["param1"] = 81, ["z"] = 13, ["name"] = "default:steelblock"}, {["x"] = 7, ["y"] = 10, ["param1"] = 81, ["z"] = 14, ["name"] = "default:steelblock"}, {["x"] = 7, ["y"] = 10, ["param1"] = 81, ["z"] = 15, ["name"] = "default:steelblock"}, {["x"] = 7, ["y"] = 11, ["param1"] = 81, ["z"] = 9, ["name"] = "default:steelblock"}, {["x"] = 7, ["y"] = 11, ["param1"] = 81, ["z"] = 10, ["name"] = "default:steelblock"}, {["x"] = 7, ["y"] = 11, ["param1"] = 81, ["z"] = 11, ["name"] = "default:steelblock"}, {["x"] = 7, ["y"] = 11, ["param1"] = 81, ["z"] = 12, ["name"] = "default:steelblock"}, {["x"] = 7, ["y"] = 11, ["param1"] = 81, ["z"] = 13, ["name"] = "default:steelblock"}, {["x"] = 7, ["y"] = 12, ["param1"] = 81, ["z"] = 9, ["name"] = "default:steelblock"}, {["x"] = 7, ["y"] = 12, ["param1"] = 81, ["z"] = 10, ["name"] = "default:steelblock"}, {["x"] = 7, ["y"] = 12, ["param1"] = 93, ["z"] = 11, ["name"] = "wool:green"}, {["x"] = 7, ["y"] = 12, ["param1"] = 93, ["z"] = 12, ["name"] = "wool:green"}, {["x"] = 7, ["y"] = 12, ["param1"] = 81, ["z"] = 13, ["name"] = "default:steelblock"}, {["x"] = 7, ["y"] = 12, ["param1"] = 81, ["z"] = 14, ["name"] = "default:steelblock"}, {["x"] = 7, ["y"] = 12, ["param1"] = 81, ["z"] = 15, ["name"] = "default:steelblock"}, {["x"] = 7, ["y"] = 13, ["z"] = 2, ["name"] = "default:steelblock"}, {["x"] = 7, ["y"] = 13, ["z"] = 3, ["name"] = "default:steelblock"}, {["x"] = 7, ["y"] = 13, ["z"] = 4, ["name"] = "default:steelblock"}, {["x"] = 7, ["y"] = 13, ["z"] = 5, ["name"] = "default:steelblock"}, {["x"] = 7, ["y"] = 13, ["z"] = 6, ["name"] = "default:steelblock"}, {["x"] = 7, ["y"] = 13, ["z"] = 7, ["name"] = "default:steelblock"}, {["x"] = 7, ["y"] = 13, ["z"] = 8, ["name"] = "default:steelblock"}, {["x"] = 7, ["y"] = 13, ["z"] = 9, ["name"] = "default:steelblock"}, {["x"] = 7, ["y"] = 13, ["param1"] = 93, ["z"] = 10, ["name"] = "wool:green"}, {["x"] = 7, ["y"] = 13, ["param1"] = 93, ["z"] = 13, ["name"] = "wool:green"}, {["x"] = 7, ["y"] = 14, ["param1"] = 93, ["z"] = 10, ["name"] = "wool:green"}, {["x"] = 7, ["y"] = 14, ["param1"] = 93, ["z"] = 13, ["name"] = "wool:green"}, {["x"] = 7, ["y"] = 15, ["param1"] = 93, ["z"] = 10, ["name"] = "wool:green"}, {["x"] = 7, ["y"] = 15, ["param1"] = 93, ["z"] = 13, ["name"] = "wool:green"}, {["x"] = 8, ["y"] = 0, ["param1"] = 81, ["z"] = 2, ["name"] = "default:steelblock"}, {["x"] = 8, ["y"] = 0, ["param1"] = 81, ["z"] = 3, ["name"] = "default:steelblock"}, {["x"] = 8, ["y"] = 0, ["param1"] = 81, ["z"] = 4, ["name"] = "default:steelblock"}, {["x"] = 8, ["y"] = 0, ["param1"] = 81, ["z"] = 5, ["name"] = "default:steelblock"}, {["x"] = 8, ["y"] = 0, ["param1"] = 81, ["z"] = 6, ["name"] = "default:steelblock"}, {["x"] = 8, ["y"] = 0, ["param1"] = 81, ["z"] = 7, ["name"] = "default:steelblock"}, {["x"] = 8, ["y"] = 0, ["param1"] = 81, ["z"] = 8, ["name"] = "default:steelblock"}, {["x"] = 8, ["y"] = 0, ["param1"] = 81, ["z"] = 9, ["name"] = "default:steelblock"}, {["x"] = 8, ["y"] = 0, ["param1"] = 81, ["z"] = 10, ["name"] = "default:steelblock"}, {["x"] = 8, ["y"] = 0, ["param1"] = 81, ["z"] = 11, ["name"] = "default:steelblock"}, {["x"] = 8, ["y"] = 0, ["param1"] = 81, ["z"] = 12, ["name"] = "default:steelblock"}, {["x"] = 8, ["y"] = 0, ["param1"] = 81, ["z"] = 13, ["name"] = "default:steelblock"}, {["x"] = 8, ["y"] = 0, ["z"] = 14, ["name"] = "default:steelblock"}, {["x"] = 8, ["y"] = 0, ["z"] = 15, ["name"] = "default:steelblock"}, {["x"] = 8, ["y"] = 1, ["param1"] = 86, ["z"] = 0, ["name"] = "wool:grey"}, {["x"] = 8, ["y"] = 1, ["param1"] = 86, ["z"] = 1, ["name"] = "wool:grey"}, {["x"] = 8, ["y"] = 1, ["param1"] = 81, ["z"] = 2, ["name"] = "default:steelblock"}, {["x"] = 8, ["y"] = 1, ["param1"] = 81, ["z"] = 3, ["name"] = "default:steelblock"}, {["x"] = 8, ["y"] = 1, ["param1"] = 81, ["z"] = 4, ["name"] = "default:steelblock"}, {["x"] = 8, ["y"] = 1, ["param1"] = 81, ["z"] = 5, ["name"] = "default:steelblock"}, {["x"] = 8, ["y"] = 1, ["param1"] = 81, ["z"] = 6, ["name"] = "default:steelblock"}, {["x"] = 8, ["y"] = 1, ["param1"] = 81, ["z"] = 7, ["name"] = "default:steelblock"}, {["x"] = 8, ["y"] = 1, ["param1"] = 81, ["z"] = 8, ["name"] = "default:steelblock"}, {["x"] = 8, ["y"] = 1, ["param1"] = 81, ["z"] = 9, ["name"] = "default:steelblock"}, {["x"] = 8, ["y"] = 1, ["param1"] = 81, ["z"] = 10, ["name"] = "default:steelblock"}, {["x"] = 8, ["y"] = 1, ["param1"] = 81, ["z"] = 11, ["name"] = "default:steelblock"}, {["x"] = 8, ["y"] = 1, ["param1"] = 81, ["z"] = 12, ["name"] = "default:steelblock"}, {["x"] = 8, ["y"] = 1, ["param1"] = 81, ["z"] = 13, ["name"] = "default:steelblock"}, {["x"] = 8, ["y"] = 1, ["z"] = 14, ["name"] = "default:steelblock"}, {["x"] = 8, ["y"] = 1, ["z"] = 15, ["name"] = "default:steelblock"}, {["x"] = 8, ["y"] = 2, ["param1"] = 86, ["z"] = 0, ["name"] = "wool:grey"}, {["x"] = 8, ["y"] = 2, ["param1"] = 86, ["z"] = 1, ["name"] = "wool:grey"}, {["x"] = 8, ["y"] = 2, ["param1"] = 81, ["z"] = 2, ["name"] = "default:steelblock"}, {["x"] = 8, ["y"] = 2, ["param1"] = 81, ["z"] = 3, ["name"] = "default:steelblock"}, {["x"] = 8, ["y"] = 2, ["param1"] = 81, ["z"] = 4, ["name"] = "default:steelblock"}, {["x"] = 8, ["y"] = 2, ["param1"] = 81, ["z"] = 5, ["name"] = "default:steelblock"}, {["x"] = 8, ["y"] = 2, ["param1"] = 81, ["z"] = 6, ["name"] = "default:steelblock"}, {["x"] = 8, ["y"] = 2, ["param1"] = 81, ["z"] = 7, ["name"] = "default:steelblock"}, {["x"] = 8, ["y"] = 2, ["param1"] = 81, ["z"] = 8, ["name"] = "default:steelblock"}, {["x"] = 8, ["y"] = 2, ["param1"] = 81, ["z"] = 9, ["name"] = "default:steelblock"}, {["x"] = 8, ["y"] = 2, ["param1"] = 81, ["z"] = 10, ["name"] = "default:steelblock"}, {["x"] = 8, ["y"] = 2, ["param1"] = 81, ["z"] = 11, ["name"] = "default:steelblock"}, {["x"] = 8, ["y"] = 2, ["param1"] = 81, ["z"] = 12, ["name"] = "default:steelblock"}, {["x"] = 8, ["y"] = 2, ["param1"] = 81, ["z"] = 13, ["name"] = "default:steelblock"}, {["x"] = 8, ["y"] = 2, ["z"] = 14, ["name"] = "default:steelblock"}, {["x"] = 8, ["y"] = 2, ["z"] = 15, ["name"] = "default:steelblock"}, {["x"] = 8, ["y"] = 3, ["param1"] = 94, ["z"] = 0, ["name"] = "wool:yellow"}, {["x"] = 8, ["y"] = 3, ["param1"] = 94, ["z"] = 1, ["name"] = "wool:yellow"}, {["x"] = 8, ["y"] = 3, ["param1"] = 94, ["z"] = 2, ["name"] = "wool:yellow"}, {["x"] = 8, ["y"] = 3, ["param1"] = 81, ["z"] = 3, ["name"] = "default:steelblock"}, {["x"] = 8, ["y"] = 3, ["param1"] = 81, ["z"] = 4, ["name"] = "default:steelblock"}, {["x"] = 8, ["y"] = 3, ["param1"] = 81, ["z"] = 5, ["name"] = "default:steelblock"}, {["x"] = 8, ["y"] = 3, ["param1"] = 81, ["z"] = 6, ["name"] = "default:steelblock"}, {["x"] = 8, ["y"] = 3, ["param1"] = 81, ["z"] = 7, ["name"] = "default:steelblock"}, {["x"] = 8, ["y"] = 3, ["param1"] = 81, ["z"] = 8, ["name"] = "default:steelblock"}, {["x"] = 8, ["y"] = 3, ["param1"] = 81, ["z"] = 9, ["name"] = "default:steelblock"}, {["x"] = 8, ["y"] = 3, ["param1"] = 81, ["z"] = 10, ["name"] = "default:steelblock"}, {["x"] = 8, ["y"] = 3, ["param1"] = 81, ["z"] = 11, ["name"] = "default:steelblock"},