5:return {{["x"] = 0, ["y"] = 0, ["param1"] = 86, ["z"] = 0, ["name"] = "wool:grey"}, {["x"] = 0, ["y"] = 0, ["param1"] = 86, ["z"] = 1, ["name"] = "wool:grey"}, {["x"] = 0, ["y"] = 0, ["param1"] = 86, ["z"] = 14, ["name"] = "wool:grey"}, {["x"] = 0, ["y"] = 0, ["param1"] = 86, ["z"] = 15, ["name"] = "wool:grey"}, {["x"] = 0, ["y"] = 1, ["param1"] = 86, ["z"] = 0, ["name"] = "wool:grey"}, {["x"] = 0, ["y"] = 1, ["param1"] = 86, ["z"] = 1, ["name"] = "wool:grey"}, {["x"] = 0, ["y"] = 1, ["param1"] = 86, ["z"] = 14, ["name"] = "wool:grey"}, {["x"] = 0, ["y"] = 1, ["param1"] = 86, ["z"] = 15, ["name"] = "wool:grey"}, {["x"] = 0, ["y"] = 2, ["param1"] = 86, ["z"] = 0, ["name"] = "wool:grey"}, {["x"] = 0, ["y"] = 2, ["param1"] = 86, ["z"] = 1, ["name"] = "wool:grey"}, {["x"] = 0, ["y"] = 2, ["param1"] = 86, ["z"] = 14, ["name"] = "wool:grey"}, {["x"] = 0, ["y"] = 2, ["param1"] = 86, ["z"] = 15, ["name"] = "wool:grey"}, {["x"] = 0, ["y"] = 3, ["param1"] = 86, ["z"] = 0, ["name"] = "wool:grey"}, {["x"] = 0, ["y"] = 3, ["param1"] = 86, ["z"] = 1, ["name"] = "wool:grey"}, {["x"] = 0, ["y"] = 3, ["param1"] = 86, ["z"] = 14, ["name"] = "wool:grey"}, {["x"] = 0, ["y"] = 3, ["param1"] = 86, ["z"] = 15, ["name"] = "wool:grey"}, {["x"] = 0, ["y"] = 4, ["param1"] = 86, ["z"] = 0, ["name"] = "wool:grey"}, {["x"] = 0, ["y"] = 4, ["param1"] = 86, ["z"] = 1, ["name"] = "wool:grey"}, {["x"] = 0, ["y"] = 4, ["param1"] = 86, ["z"] = 14, ["name"] = "wool:grey"}, {["x"] = 0, ["y"] = 4, ["param1"] = 86, ["z"] = 15, ["name"] = "wool:grey"}, {["x"] = 0, ["y"] = 5, ["param1"] = 86, ["z"] = 0, ["name"] = "wool:grey"}, {["x"] = 0, ["y"] = 5, ["param1"] = 86, ["z"] = 1, ["name"] = "wool:grey"}, {["x"] = 0, ["y"] = 5, ["param1"] = 86, ["z"] = 14, ["name"] = "wool:grey"}, {["x"] = 0, ["y"] = 5, ["param1"] = 86, ["z"] = 15, ["name"] = "wool:grey"}, {["x"] = 0, ["y"] = 6, ["param1"] = 86, ["z"] = 0, ["name"] = "wool:grey"}, {["x"] = 0, ["y"] = 6, ["param1"] = 86, ["z"] = 1, ["name"] = "wool:grey"}, {["x"] = 0, ["y"] = 6, ["param1"] = 86, ["z"] = 14, ["name"] = "wool:grey"}, {["x"] = 0, ["y"] = 6, ["param1"] = 86, ["z"] = 15, ["name"] = "wool:grey"}, {["x"] = 0, ["y"] = 7, ["param1"] = 86, ["z"] = 0, ["name"] = "wool:grey"}, {["x"] = 0, ["y"] = 7, ["param1"] = 86, ["z"] = 1, ["name"] = "wool:grey"}, {["x"] = 0, ["y"] = 7, ["param1"] = 86, ["z"] = 14, ["name"] = "wool:grey"}, {["x"] = 0, ["y"] = 7, ["param1"] = 86, ["z"] = 15, ["name"] = "wool:grey"}, {["x"] = 0, ["y"] = 8, ["param1"] = 86, ["z"] = 0, ["name"] = "wool:grey"}, {["x"] = 0, ["y"] = 8, ["param1"] = 86, ["z"] = 1, ["name"] = "wool:grey"}, {["x"] = 0, ["y"] = 8, ["param1"] = 86, ["z"] = 14, ["name"] = "wool:grey"}, {["x"] = 0, ["y"] = 8, ["param1"] = 86, ["z"] = 15, ["name"] = "wool:grey"}, {["x"] = 0, ["y"] = 9, ["param1"] = 86, ["z"] = 0, ["name"] = "wool:grey"}, {["x"] = 0, ["y"] = 9, ["param1"] = 86, ["z"] = 1, ["name"] = "wool:grey"}, {["x"] = 0, ["y"] = 9, ["param1"] = 86, ["z"] = 14, ["name"] = "wool:grey"}, {["x"] = 0, ["y"] = 9, ["param1"] = 86, ["z"] = 15, ["name"] = "wool:grey"}, {["x"] = 0, ["y"] = 10, ["param1"] = 86, ["z"] = 0, ["name"] = "wool:grey"}, {["x"] = 0, ["y"] = 10, ["param1"] = 86, ["z"] = 1, ["name"] = "wool:grey"}, {["x"] = 0, ["y"] = 10, ["param1"] = 86, ["z"] = 14, ["name"] = "wool:grey"}, {["x"] = 0, ["y"] = 10, ["param1"] = 86, ["z"] = 15, ["name"] = "wool:grey"}, {["x"] = 0, ["y"] = 11, ["param1"] = 86, ["z"] = 0, ["name"] = "wool:grey"}, {["x"] = 0, ["y"] = 11, ["param1"] = 86, ["z"] = 1, ["name"] = "wool:grey"}, {["x"] = 0, ["y"] = 11, ["param1"] = 86, ["z"] = 14, ["name"] = "wool:grey"}, {["x"] = 0, ["y"] = 11, ["param1"] = 86, ["z"] = 15, ["name"] = "wool:grey"}, {["x"] = 0, ["y"] = 12, ["param1"] = 86, ["z"] = 0, ["name"] = "wool:grey"}, {["x"] = 0, ["y"] = 12, ["param1"] = 86, ["z"] = 1, ["name"] = "wool:grey"}, {["x"] = 0, ["y"] = 12, ["param1"] = 86, ["z"] = 14, ["name"] = "wool:grey"}, {["x"] = 0, ["y"] = 12, ["param1"] = 86, ["z"] = 15, ["name"] = "wool:grey"}, {["x"] = 0, ["y"] = 13, ["param1"] = 86, ["z"] = 0, ["name"] = "wool:grey"}, {["x"] = 0, ["y"] = 13, ["param1"] = 86, ["z"] = 1, ["name"] = "wool:grey"}, {["x"] = 0, ["y"] = 13, ["param1"] = 86, ["z"] = 14, ["name"] = "wool:grey"}, {["x"] = 0, ["y"] = 13, ["param1"] = 86, ["z"] = 15, ["name"] = "wool:grey"}, {["x"] = 0, ["y"] = 14, ["param1"] = 86, ["z"] = 0, ["name"] = "wool:grey"}, {["x"] = 0, ["y"] = 14, ["param1"] = 86, ["z"] = 1, ["name"] = "wool:grey"}, {["x"] = 0, ["y"] = 14, ["param1"] = 86, ["z"] = 14, ["name"] = "wool:grey"}, {["x"] = 0, ["y"] = 14, ["param1"] = 86, ["z"] = 15, ["name"] = "wool:grey"}, {["x"] = 0, ["y"] = 15, ["param1"] = 86, ["z"] = 0, ["name"] = "wool:grey"}, {["x"] = 0, ["y"] = 15, ["param1"] = 86, ["z"] = 1, ["name"] = "wool:grey"}, {["x"] = 0, ["y"] = 15, ["param1"] = 86, ["z"] = 14, ["name"] = "wool:grey"}, {["x"] = 0, ["y"] = 15, ["param1"] = 86, ["z"] = 15, ["name"] = "wool:grey"}, {["x"] = 1, ["y"] = 0, ["param1"] = 86, ["z"] = 0, ["name"] = "wool:grey"}, {["x"] = 1, ["y"] = 0, ["param1"] = 86, ["z"] = 1, ["name"] = "wool:grey"}, {["x"] = 1, ["y"] = 0, ["param1"] = 86, ["z"] = 14, ["name"] = "wool:grey"}, {["x"] = 1, ["y"] = 0, ["param1"] = 86, ["z"] = 15, ["name"] = "wool:grey"}, {["x"] = 1, ["y"] = 1, ["param1"] = 86, ["z"] = 0, ["name"] = "wool:grey"}, {["x"] = 1, ["y"] = 1, ["param1"] = 86, ["z"] = 1, ["name"] = "wool:grey"}, {["x"] = 1, ["y"] = 1, ["param1"] = 86, ["z"] = 14, ["name"] = "wool:grey"}, {["x"] = 1, ["y"] = 1, ["param1"] = 86, ["z"] = 15, ["name"] = "wool:grey"}, {["x"] = 1, ["y"] = 2, ["param1"] = 86, ["z"] = 0, ["name"] = "wool:grey"}, {["x"] = 1, ["y"] = 2, ["param1"] = 86, ["z"] = 1, ["name"] = "wool:grey"}, {["x"] = 1, ["y"] = 2, ["param1"] = 86, ["z"] = 14, ["name"] = "wool:grey"}, {["x"] = 1, ["y"] = 2, ["param1"] = 86, ["z"] = 15, ["name"] = "wool:grey"}, {["x"] = 1, ["y"] = 3, ["param1"] = 86, ["z"] = 0, ["name"] = "wool:grey"}, {["x"] = 1, ["y"] = 3, ["param1"] = 86, ["z"] = 1, ["name"] = "wool:grey"}, {["x"] = 1, ["y"] = 3, ["param1"] = 86, ["z"] = 14, ["name"] = "wool:grey"}, {["x"] = 1, ["y"] = 3, ["param1"] = 86, ["z"] = 15, ["name"] = "wool:grey"}, {["x"] = 1, ["y"] = 4, ["param1"] = 86, ["z"] = 0, ["name"] = "wool:grey"}, {["x"] = 1, ["y"] = 4, ["param1"] = 86, ["z"] = 1, ["name"] = "wool:grey"}, {["x"] = 1, ["y"] = 4, ["param1"] = 86, ["z"] = 14, ["name"] = "wool:grey"}, {["x"] = 1, ["y"] = 4, ["param1"] = 86, ["z"] = 15, ["name"] = "wool:grey"}, {["x"] = 1, ["y"] = 5, ["param1"] = 86, ["z"] = 0, ["name"] = "wool:grey"}, {["x"] = 1, ["y"] = 5, ["param1"] = 86, ["z"] = 1, ["name"] = "wool:grey"}, {["x"] = 1, ["y"] = 5, ["param1"] = 86, ["z"] = 14, ["name"] = "wool:grey"}, {["x"] = 1, ["y"] = 5, ["param1"] = 86, ["z"] = 15, ["name"] = "wool:grey"}, {["x"] = 1, ["y"] = 6, ["param1"] = 86, ["z"] = 0, ["name"] = "wool:grey"}, {["x"] = 1, ["y"] = 6, ["param1"] = 86, ["z"] = 1, ["name"] = "wool:grey"}, {["x"] = 1, ["y"] = 6, ["z"] = 2, ["name"] = "wool:grey"}, {["x"] = 1, ["y"] = 6, ["z"] = 3, ["name"] = "wool:grey"}, {["x"] = 1, ["y"] = 6, ["z"] = 4, ["name"] = "wool:grey"}, {["x"] = 1, ["y"] = 6, ["z"] = 5, ["name"] = "wool:grey"}, {["x"] = 1, ["y"] = 6, ["z"] = 6, ["name"] = "wool:grey"}, {["x"] = 1, ["y"] = 6, ["z"] = 7, ["name"] = "wool:grey"}, {["x"] = 1, ["y"] = 6, ["z"] = 8, ["name"] = "wool:grey"}, {["x"] = 1, ["y"] = 6, ["z"] = 9, ["name"] = "wool:grey"}, {["x"] = 1, ["y"] = 6, ["z"] = 10, ["name"] = "wool:grey"}, {["x"] = 1, ["y"] = 6, ["z"] = 11, ["name"] = "wool:grey"}, {["x"] = 1, ["y"] = 6, ["z"] = 12, ["name"] = "wool:grey"}, {["x"] = 1, ["y"] = 6, ["z"] = 13, ["name"] = "wool:grey"}, {["x"] = 1, ["y"] = 6, ["param1"] = 86, ["z"] = 14, ["name"] = "wool:grey"}, {["x"] = 1, ["y"] = 6, ["param1"] = 86, ["z"] = 15, ["name"] = "wool:grey"}, {["x"] = 1, ["y"] = 7, ["param1"] = 86, ["z"] = 0, ["name"] = "wool:grey"}, {["x"] = 1, ["y"] = 7, ["param1"] = 86, ["z"] = 1, ["name"] = "wool:grey"}, {["x"] = 1, ["y"] = 7, ["z"] = 6, ["name"] = "wool:grey"}, {["x"] = 1, ["y"] = 7, ["z"] = 9, ["name"] = "wool:grey"}, {["x"] = 1, ["y"] = 7, ["param1"] = 86, ["z"] = 14, ["name"] = "wool:grey"}, {["x"] = 1, ["y"] = 7, ["param1"] = 86, ["z"] = 15, ["name"] = "wool:grey"}, {["x"] = 1, ["y"] = 8, ["param1"] = 86, ["z"] = 0, ["name"] = "wool:grey"}, {["x"] = 1, ["y"] = 8, ["param1"] = 86, ["z"] = 1, ["name"] = "wool:grey"}, {["x"] = 1, ["y"] = 8, ["z"] = 6, ["name"] = "wool:grey"}, {["x"] = 1, ["y"] = 8, ["z"] = 9, ["name"] = "wool:grey"}, {["x"] = 1, ["y"] = 8, ["param1"] = 86, ["z"] = 14, ["name"] = "wool:grey"}, {["x"] = 1, ["y"] = 8, ["param1"] = 86, ["z"] = 15, ["name"] = "wool:grey"}, {["x"] = 1, ["y"] = 9, ["param1"] = 86, ["z"] = 0, ["name"] = "wool:grey"}, {["x"] = 1, ["y"] = 9, ["param1"] = 86, ["z"] = 1, ["name"] = "wool:grey"}, {["x"] = 1, ["y"] = 9, ["z"] = 2, ["name"] = "wool:grey"}, {["x"] = 1, ["y"] = 9, ["z"] = 3, ["name"] = "wool:grey"}, {["x"] = 1, ["y"] = 9, ["z"] = 4, ["name"] = "wool:grey"}, {["x"] = 1, ["y"] = 9, ["z"] = 5, ["name"] = "wool:grey"}, {["x"] = 1, ["y"] = 9, ["z"] = 6, ["name"] = "wool:grey"}, {["x"] = 1, ["y"] = 9, ["z"] = 7, ["name"] = "wool:grey"}, {["x"] = 1, ["y"] = 9, ["z"] = 8, ["name"] = "wool:grey"}, {["x"] = 1, ["y"] = 9, ["z"] = 9, ["name"] = "wool:grey"}, {["x"] = 1, ["y"] = 9, ["z"] = 10, ["name"] = "wool:grey"}, {["x"] = 1, ["y"] = 9, ["z"] = 11, ["name"] = "wool:grey"}, {["x"] = 1, ["y"] = 9, ["z"] = 12, ["name"] = "wool:grey"}, {["x"] = 1, ["y"] = 9, ["z"] = 13, ["name"] = "wool:grey"}, {["x"] = 1, ["y"] = 9, ["param1"] = 86, ["z"] = 14, ["name"] = "wool:grey"}, {["x"] = 1, ["y"] = 9, ["param1"] = 86, ["z"] = 15, ["name"] = "wool:grey"}, {["x"] = 1, ["y"] = 10, ["param1"] = 86, ["z"] = 0, ["name"] = "wool:grey"}, {["x"] = 1, ["y"] = 10, ["param1"] = 86, ["z"] = 1, ["name"] = "wool:grey"}, {["x"] = 1, ["y"] = 10, ["param1"] = 86, ["z"] = 14, ["name"] = "wool:grey"}, {["x"] = 1, ["y"] = 10, ["param1"] = 86, ["z"] = 15, ["name"] = "wool:grey"}, {["x"] = 1, ["y"] = 11, ["param1"] = 86, ["z"] = 0, ["name"] = "wool:grey"}, {["x"] = 1, ["y"] = 11, ["param1"] = 86, ["z"] = 1, ["name"] = "wool:grey"}, {["x"] = 1, ["y"] = 11, ["param1"] = 86, ["z"] = 14, ["name"] = "wool:grey"}, {["x"] = 1, ["y"] = 11, ["param1"] = 86, ["z"] = 15, ["name"] = "wool:grey"}, {["x"] = 1, ["y"] = 12, ["param1"] = 86, ["z"] = 0, ["name"] = "wool:grey"}, {["x"] = 1, ["y"] = 12, ["param1"] = 86, ["z"] = 1, ["name"] = "wool:grey"}, {["x"] = 1, ["y"] = 12, ["param1"] = 86, ["z"] = 14, ["name"] = "wool:grey"}, {["x"] = 1, ["y"] = 12, ["param1"] = 86, ["z"] = 15, ["name"] = "wool:grey"}, {["x"] = 1, ["y"] = 13, ["param1"] = 86, ["z"] = 0, ["name"] = "wool:grey"}, {["x"] = 1, ["y"] = 13, ["param1"] = 86, ["z"] = 1, ["name"] = "wool:grey"}, {["x"] = 1, ["y"] = 13, ["param1"] = 86, ["z"] = 14, ["name"] = "wool:grey"}, {["x"] = 1, ["y"] = 13, ["param1"] = 86, ["z"] = 15, ["name"] = "wool:grey"}, {["x"] = 1, ["y"] = 14, ["param1"] = 86, ["z"] = 0, ["name"] = "wool:grey"}, {["x"] = 1, ["y"] = 14, ["param1"] = 86, ["z"] = 1, ["name"] = "wool:grey"}, {["x"] = 1, ["y"] = 14, ["param1"] = 86, ["z"] = 14, ["name"] = "wool:grey"}, {["x"] = 1, ["y"] = 14, ["param1"] = 86, ["z"] = 15, ["name"] = "wool:grey"}, {["x"] = 1, ["y"] = 15, ["param1"] = 86, ["z"] = 0, ["name"] = "wool:grey"}, {["x"] = 1, ["y"] = 15, ["param1"] = 86, ["z"] = 1, ["name"] = "wool:grey"}, {["x"] = 1, ["y"] = 15, ["param1"] = 86, ["z"] = 14, ["name"] = "wool:grey"}, {["x"] = 1, ["y"] = 15, ["param1"] = 86, ["z"] = 15, ["name"] = "wool:grey"}, {["x"] = 2, ["y"] = 6, ["z"] = 1, ["name"] = "wool:grey"}, {["x"] = 2, ["y"] = 6, ["z"] = 14, ["name"] = "wool:grey"}, {["x"] = 2, ["y"] = 9, ["z"] = 1, ["name"] = "wool:grey"}, {["x"] = 2, ["y"] = 9, ["z"] = 14, ["name"] = "wool:grey"}, {["x"] = 3, ["y"] = 6, ["z"] = 1, ["name"] = "wool:grey"}, {["x"] = 3, ["y"] = 6, ["z"] = 14, ["name"] = "wool:grey"}, {["x"] = 3, ["y"] = 9, ["z"] = 1, ["name"] = "wool:grey"}, {["x"] = 3, ["y"] = 9, ["z"] = 14, ["name"] = "wool:grey"}, {["x"] = 4, ["y"] = 6, ["z"] = 1, ["name"] = "wool:grey"}, {["x"] = 4, ["y"] = 6, ["param1"] = 81, ["z"] = 2, ["name"] = "default:steelblock"}, {["x"] = 4, ["y"] = 6, ["param1"] = 81, ["z"] = 3, ["name"] = "default:steelblock"}, {["x"] = 4, ["y"] = 6, ["param1"] = 81, ["z"] = 4, ["name"] = "default:steelblock"}, {["x"] = 4, ["y"] = 6, ["param1"] = 81, ["z"] = 5, ["name"] = "default:steelblock"}, {["x"] = 4, ["y"] = 6, ["param1"] = 81, ["z"] = 6, ["name"] = "default:steelblock"}, {["x"] = 4, ["y"] = 6, ["param1"] = 81, ["z"] = 7, ["name"] = "default:steelblock"}, {["x"] = 4, ["y"] = 6, ["param1"] = 81, ["z"] = 8, ["name"] = "default:steelblock"}, {["x"] = 4, ["y"] = 6, ["param1"] = 81, ["z"] = 9, ["name"] = "default:steelblock"}, {["x"] = 4, ["y"] = 6, ["z"] = 10, ["name"] = "default:steelblock"}, {["x"] = 4, ["y"] = 6, ["z"] = 11, ["name"] = "default:steelblock"}, {["x"] = 4, ["y"] = 6, ["z"] = 12, ["name"] = "default:steelblock"}, {["x"] = 4, ["y"] = 6, ["z"] = 13, ["name"] = "default:steelblock"}, {["x"] = 4, ["y"] = 6, ["z"] = 14, ["name"] = "wool:grey"}, {["x"] = 4, ["y"] = 7, ["param1"] = 81, ["z"] = 2, ["name"] = "default:steelblock"}, {["x"] = 4, ["y"] = 7, ["param1"] = 81, ["z"] = 3, ["name"] = "default:steelblock"}, {["x"] = 4, ["y"] = 7, ["param1"] = 81, ["z"] = 4, ["name"] = "default:steelblock"}, {["x"] = 4, ["y"] = 7, ["param1"] = 81, ["z"] = 5, ["name"] = "default:steelblock"}, {["x"] = 4, ["y"] = 7, ["param1"] = 81, ["z"] = 6, ["name"] = "default:steelblock"}, {["x"] = 4, ["y"] = 7, ["param1"] = 81, ["z"] = 7, ["name"] = "default:steelblock"}, {["x"] = 4, ["y"] = 7, ["param1"] = 81, ["z"] = 8, ["name"] = "default:steelblock"}, {["x"] = 4, ["y"] = 7, ["param1"] = 81, ["z"] = 9, ["name"] = "default:steelblock"}, {["x"] = 4, ["y"] = 7, ["z"] = 10, ["name"] = "default:steelblock"}, {["x"] = 4, ["y"] = 7, ["z"] = 11, ["name"] = "default:steelblock"}, {["x"] = 4, ["y"] = 7, ["z"] = 12, ["name"] = "default:steelblock"}, {["x"] = 4, ["y"] = 7, ["z"] = 13, ["name"] = "default:steelblock"}, {["x"] = 4, ["y"] = 8, ["param1"] = 81, ["z"] = 2, ["name"] = "default:steelblock"}, {["x"] = 4, ["y"] = 8, ["param1"] = 81, ["z"] = 3, ["name"] = "default:steelblock"}, {["x"] = 4, ["y"] = 8, ["param1"] = 81, ["z"] = 4, ["name"] = "default:steelblock"}, {["x"] = 4, ["y"] = 8, ["param1"] = 81, ["z"] = 5, ["name"] = "default:steelblock"}, {["x"] = 4, ["y"] = 8, ["param1"] = 81, ["z"] = 6, ["name"] = "default:steelblock"}, {["x"] = 4, ["y"] = 8, ["param1"] = 81, ["z"] = 7, ["name"] = "default:steelblock"}, {["x"] = 4, ["y"] = 8, ["param1"] = 81, ["z"] = 8, ["name"] = "default:steelblock"}, {["x"] = 4, ["y"] = 8, ["param1"] = 81, ["z"] = 9, ["name"] = "default:steelblock"}, {["x"] = 4, ["y"] = 8, ["z"] = 10, ["name"] = "default:steelblock"}, {["x"] = 4, ["y"] = 8, ["z"] = 11, ["name"] = "default:steelblock"}, {["x"] = 4, ["y"] = 8, ["z"] = 12, ["name"] = "default:steelblock"}, {["x"] = 4, ["y"] = 8, ["z"] = 13, ["name"] = "default:steelblock"}, {["x"] = 4, ["y"] = 9, ["z"] = 1, ["name"] = "wool:grey"}, {["x"] = 4, ["y"] = 9, ["param1"] = 81, ["z"] = 2, ["name"] = "default:steelblock"}, {["x"] = 4, ["y"] = 9, ["param1"] = 81, ["z"] = 3, ["name"] = "default:steelblock"}, {["x"] = 4, ["y"] = 9, ["param1"] = 81, ["z"] = 4, ["name"] = "default:steelblock"}, {["x"] = 4, ["y"] = 9, ["param1"] = 81, ["z"] = 5, ["name"] = "default:steelblock"}, {["x"] = 4, ["y"] = 9, ["param1"] = 81, ["z"] = 6, ["name"] = "default:steelblock"}, {["x"] = 4, ["y"] = 9, ["param1"] = 81, ["z"] = 7, ["name"] = "default:steelblock"}, {["x"] = 4, ["y"] = 9, ["param1"] = 81, ["z"] = 8, ["name"] = "default:steelblock"}, {["x"] = 4, ["y"] = 9, ["param1"] = 81, ["z"] = 9, ["name"] = "default:steelblock"}, {["x"] = 4, ["y"] = 9, ["z"] = 10, ["name"] = "default:steelblock"}, {["x"] = 4, ["y"] = 9, ["z"] = 11, ["name"] = "default:steelblock"}, {["x"] = 4, ["y"] = 9, ["z"] = 12, ["name"] = "default:steelblock"}, {["x"] = 4, ["y"] = 9, ["z"] = 13, ["name"] = "default:steelblock"}, {["x"] = 4, ["y"] = 9, ["z"] = 14, ["name"] = "wool:grey"}, {["x"] = 5, ["y"] = 5, ["param1"] = 81, ["z"] = 2, ["name"] = "default:steelblock"}, {["x"] = 5, ["y"] = 5, ["param1"] = 81, ["z"] = 3, ["name"] = "default:steelblock"}, {["x"] = 5, ["y"] = 5, ["param1"] = 81, ["z"] = 4, ["name"] = "default:steelblock"}, {["x"] = 5, ["y"] = 5, ["param1"] = 81, ["z"] = 5, ["name"] = "default:steelblock"}, {["x"] = 5, ["y"] = 5, ["param1"] = 81, ["z"] = 6, ["name"] = "default:steelblock"}, {["x"] = 5, ["y"] = 5, ["param1"] = 81, ["z"] = 7, ["name"] = "default:steelblock"}, {["x"] = 5, ["y"] = 5, ["param1"] = 81, ["z"] = 8, ["name"] = "default:steelblock"}, {["x"] = 5, ["y"] = 5, ["param1"] = 81, ["z"] = 9, ["name"] = "default:steelblock"}, {["x"] = 5, ["y"] = 5, ["z"] = 10, ["name"] = "default:steelblock"}, {["x"] = 5, ["y"] = 5, ["z"] = 11, ["name"] = "default:steelblock"}, {["x"] = 5, ["y"] = 5, ["z"] = 12, ["name"] = "default:steelblock"}, {["x"] = 5, ["y"] = 5, ["z"] = 13, ["name"] = "default:steelblock"}, {["x"] = 5, ["y"] = 6, ["z"] = 1, ["name"] = "wool:grey"}, {["x"] = 5, ["y"] = 6, ["param1"] = 81, ["z"] = 2, ["name"] = "default:steelblock"}, {["x"] = 5, ["y"] = 6, ["param1"] = 81, ["z"] = 3, ["name"] = "default:steelblock"}, {["x"] = 5, ["y"] = 6, ["param1"] = 81, ["z"] = 4, ["name"] = "default:steelblock"}, {["x"] = 5, ["y"] = 6, ["param1"] = 81, ["z"] = 5, ["name"] = "default:steelblock"}, {["x"] = 5, ["y"] = 6, ["param1"] = 81, ["z"] = 6, ["name"] = "default:steelblock"}, {["x"] = 5, ["y"] = 6, ["param1"] = 81, ["z"] = 7, ["name"] = "default:steelblock"}, {["x"] = 5, ["y"] = 6, ["param1"] = 81, ["z"] = 8, ["name"] = "default:steelblock"}, {["x"] = 5, ["y"] = 6, ["param1"] = 81, ["z"] = 9, ["name"] = "default:steelblock"}, {["x"] = 5, ["y"] = 6, ["z"] = 10, ["name"] = "default:steelblock"}, {["x"] = 5, ["y"] = 6, ["z"] = 11, ["name"] = "default:steelblock"}, {["x"] = 5, ["y"] = 6, ["z"] = 12, ["name"] = "default:steelblock"}, {["x"] = 5, ["y"] = 6, ["z"] = 13, ["name"] = "default:steelblock"}, {["x"] = 5, ["y"] = 6, ["z"] = 14, ["name"] = "wool:grey"}, {["x"] = 5, ["y"] = 7, ["param1"] = 81, ["z"] = 2, ["name"] = "default:steelblock"}, {["x"] = 5, ["y"] = 7, ["param1"] = 81, ["z"] = 3, ["name"] = "default:steelblock"}, {["x"] = 5, ["y"] = 7, ["param1"] = 81, ["z"] = 4, ["name"] = "default:steelblock"}, {["x"] = 5, ["y"] = 7, ["param1"] = 81, ["z"] = 5, ["name"] = "default:steelblock"}, {["x"] = 5, ["y"] = 7, ["param1"] = 81, ["z"] = 6, ["name"] = "default:steelblock"}, {["x"] = 5, ["y"] = 7, ["param1"] = 81, ["z"] = 7, ["name"] = "default:steelblock"}, {["x"] = 5, ["y"] = 7, ["param1"] = 81, ["z"] = 8, ["name"] = "default:steelblock"}, {["x"] = 5, ["y"] = 7, ["param1"] = 81, ["z"] = 9, ["name"] = "default:steelblock"}, {["x"] = 5, ["y"] = 7, ["z"] = 10, ["name"] = "default:steelblock"}, {["x"] = 5, ["y"] = 7, ["z"] = 11, ["name"] = "default:steelblock"}, {["x"] = 5, ["y"] = 7, ["z"] = 12, ["name"] = "default:steelblock"}, {["x"] = 5, ["y"] = 7, ["z"] = 13, ["name"] = "default:steelblock"}, {["x"] = 5, ["y"] = 8, ["param1"] = 81, ["z"] = 2, ["name"] = "default:steelblock"}, {["x"] = 5, ["y"] = 8, ["param1"] = 81, ["z"] = 3, ["name"] = "default:steelblock"}, {["x"] = 5, ["y"] = 8, ["param1"] = 81, ["z"] = 4, ["name"] = "default:steelblock"}, {["x"] = 5, ["y"] = 8, ["param1"] = 81, ["z"] = 5, ["name"] = "default:steelblock"}, {["x"] = 5, ["y"] = 8, ["param1"] = 81, ["z"] = 6, ["name"] = "default:steelblock"}, {["x"] = 5, ["y"] = 8, ["param1"] = 81, ["z"] = 7, ["name"] = "default:steelblock"}, {["x"] = 5, ["y"] = 8, ["param1"] = 81, ["z"] = 8, ["name"] = "default:steelblock"}, {["x"] = 5, ["y"] = 8, ["param1"] = 81, ["z"] = 9, ["name"] = "default:steelblock"}, {["x"] = 5, ["y"] = 8, ["z"] = 10, ["name"] = "default:steelblock"}, {["x"] = 5, ["y"] = 8, ["z"] = 11, ["name"] = "default:steelblock"}, {["x"] = 5, ["y"] = 8, ["z"] = 12, ["name"] = "default:steelblock"}, {["x"] = 5, ["y"] = 8, ["z"] = 13, ["name"] = "default:steelblock"}, {["x"] = 5, ["y"] = 9, ["z"] = 1, ["name"] = "wool:grey"}, {["x"] = 5, ["y"] = 9, ["param1"] = 81, ["z"] = 2, ["name"] = "default:steelblock"}, {["x"] = 5, ["y"] = 9, ["param1"] = 81, ["z"] = 3, ["name"] = "default:steelblock"}, {["x"] = 5, ["y"] = 9, ["param1"] = 81, ["z"] = 4, ["name"] = "default:steelblock"}, {["x"] = 5, ["y"] = 9, ["param1"] = 81, ["z"] = 5, ["name"] = "default:steelblock"}, {["x"] = 5, ["y"] = 9, ["param1"] = 81, ["z"] = 6, ["name"] = "default:steelblock"}, {["x"] = 5, ["y"] = 9, ["param1"] = 81, ["z"] = 7, ["name"] = "default:steelblock"}, {["x"] = 5, ["y"] = 9, ["param1"] = 81, ["z"] = 8, ["name"] = "default:steelblock"}, {["x"] = 5, ["y"] = 9, ["param1"] = 81, ["z"] = 9, ["name"] = "default:steelblock"}, {["x"] = 5, ["y"] = 9, ["z"] = 10, ["name"] = "default:steelblock"}, {["x"] = 5, ["y"] = 9, ["z"] = 11, ["name"] = "default:steelblock"}, {["x"] = 5, ["y"] = 9, ["z"] = 12, ["name"] = "default:steelblock"}, {["x"] = 5, ["y"] = 9, ["z"] = 13, ["name"] = "default:steelblock"}, {["x"] = 5, ["y"] = 9, ["z"] = 14, ["name"] = "wool:grey"}, {["x"] = 5, ["y"] = 10, ["param1"] = 81, ["z"] = 2, ["name"] = "default:steelblock"}, {["x"] = 5, ["y"] = 10, ["param1"] = 81, ["z"] = 3, ["name"] = "default:steelblock"}, {["x"] = 5, ["y"] = 10, ["param1"] = 81, ["z"] = 4, ["name"] = "default:steelblock"}, {["x"] = 5, ["y"] = 10, ["param1"] = 81, ["z"] = 5, ["name"] = "default:steelblock"}, {["x"] = 5, ["y"] = 10, ["param1"] = 81, ["z"] = 6, ["name"] = "default:steelblock"}, {["x"] = 5, ["y"] = 10, ["param1"] = 81, ["z"] = 7, ["name"] = "default:steelblock"}, {["x"] = 5, ["y"] = 10, ["param1"] = 81, ["z"] = 8, ["name"] = "default:steelblock"}, {["x"] = 5, ["y"] = 10, ["param1"] = 81, ["z"] = 9, ["name"] = "default:steelblock"}, {["x"] = 5, ["y"] = 10, ["z"] = 10, ["name"] = "default:steelblock"}, {["x"] = 5, ["y"] = 10, ["z"] = 11, ["name"] = "default:steelblock"}, {["x"] = 5, ["y"] = 10, ["z"] = 12, ["name"] = "default:steelblock"}, {["x"] = 5, ["y"] = 10, ["z"] = 13, ["name"] = "default:steelblock"}, {["x"] = 6, ["y"] = 4, ["param1"] = 81, ["z"] = 2, ["name"] = "default:steelblock"}, {["x"] = 6, ["y"] = 4, ["param1"] = 81, ["z"] = 3, ["name"] = "default:steelblock"}, {["x"] = 6, ["y"] = 4, ["param1"] = 81, ["z"] = 4, ["name"] = "default:steelblock"}, {["x"] = 6, ["y"] = 4, ["param1"] = 81, ["z"] = 5, ["name"] = "default:steelblock"}, {["x"] = 6, ["y"] = 4, ["param1"] = 81, ["z"] = 6, ["name"] = "default:steelblock"}, {["x"] = 6, ["y"] = 4, ["param1"] = 81, ["z"] = 7, ["name"] = "default:steelblock"}, {["x"] = 6, ["y"] = 4, ["z"] = 8, ["name"] = "default:steelblock"}, {["x"] = 6, ["y"] = 4, ["z"] = 9, ["name"] = "default:steelblock"}, {["x"] = 6, ["y"] = 4, ["z"] = 10, ["name"] = "default:steelblock"}, {["x"] = 6, ["y"] = 4, ["z"] = 11, ["name"] = "default:steelblock"}, {["x"] = 6, ["y"] = 4, ["z"] = 12, ["name"] = "default:steelblock"}, {["x"] = 6, ["y"] = 4, ["z"] = 13, ["name"] = "default:steelblock"}, {["x"] = 6, ["y"] = 5, ["param1"] = 81, ["z"] = 2, ["name"] = "default:steelblock"}, {["x"] = 6, ["y"] = 5, ["param1"] = 81, ["z"] = 3, ["name"] = "default:steelblock"}, {["x"] = 6, ["y"] = 5, ["param1"] = 81, ["z"] = 4, ["name"] = "default:steelblock"}, {["x"] = 6, ["y"] = 5, ["param1"] = 81, ["z"] = 5, ["name"] = "default:steelblock"}, {["x"] = 6, ["y"] = 5, ["param1"] = 81, ["z"] = 6, ["name"] = "default:steelblock"}, {["x"] = 6, ["y"] = 5, ["param1"] = 81, ["z"] = 7, ["name"] = "default:steelblock"}, {["x"] = 6, ["y"] = 5, ["z"] = 8, ["name"] = "default:steelblock"}, {["x"] = 6, ["y"] = 5, ["z"] = 9, ["name"] = "default:steelblock"}, {["x"] = 6, ["y"] = 5, ["z"] = 10, ["name"] = "default:steelblock"}, {["x"] = 6, ["y"] = 5, ["z"] = 11, ["name"] = "default:steelblock"}, {["x"] = 6, ["y"] = 5, ["z"] = 12, ["name"] = "default:steelblock"}, {["x"] = 6, ["y"] = 5, ["z"] = 13, ["name"] = "default:steelblock"}, {["x"] = 6, ["y"] = 6, ["z"] = 1, ["name"] = "wool:grey"}, {["x"] = 6, ["y"] = 6, ["param1"] = 81, ["z"] = 2, ["name"] = "default:steelblock"}, {["x"] = 6, ["y"] = 6, ["param1"] = 81, ["z"] = 3, ["name"] = "default:steelblock"}, {["x"] = 6, ["y"] = 6, ["param1"] = 81, ["z"] = 4, ["name"] = "default:steelblock"}, {["x"] = 6, ["y"] = 6, ["param1"] = 81, ["z"] = 5, ["name"] = "default:steelblock"}, {["x"] = 6, ["y"] = 6, ["param1"] = 81, ["z"] = 6, ["name"] = "default:steelblock"}, {["x"] = 6, ["y"] = 6, ["param1"] = 81, ["z"] = 7, ["name"] = "default:steelblock"}, {["x"] = 6, ["y"] = 6, ["param1"] = 81, ["z"] = 8, ["name"] = "default:steelblock"}, {["x"] = 6, ["y"] = 6, ["param1"] = 81, ["z"] = 9, ["name"] = "default:steelblock"}, {["x"] = 6, ["y"] = 6, ["z"] = 10, ["name"] = "default:steelblock"}, {["x"] = 6, ["y"] = 6, ["z"] = 11, ["name"] = "default:steelblock"}, {["x"] = 6, ["y"] = 6, ["z"] = 12, ["name"] = "default:steelblock"}, {["x"] = 6, ["y"] = 6, ["z"] = 13, ["name"] = "default:steelblock"}, {["x"] = 6, ["y"] = 6, ["z"] = 14, ["name"] = "wool:grey"}, {["x"] = 6, ["y"] = 7, ["z"] = 1, ["name"] = "wool:grey"}, {["x"] = 6, ["y"] = 7, ["param1"] = 81, ["z"] = 2, ["name"] = "default:steelblock"}, {["x"] = 6, ["y"] = 7, ["param1"] = 81, ["z"] = 3, ["name"] = "default:steelblock"}, {["x"] = 6, ["y"] = 7, ["param1"] = 81, ["z"] = 4, ["name"] = "default:steelblock"}, {["x"] = 6, ["y"] = 7, ["param1"] = 81, ["z"] = 5, ["name"] = "default:steelblock"}, {["x"] = 6, ["y"] = 7, ["param1"] = 81, ["z"] = 6, ["name"] = "default:steelblock"}, {["x"] = 6, ["y"] = 7, ["param1"] = 81, ["z"] = 7, ["name"] = "default:steelblock"}, {["x"] = 6, ["y"] = 7, ["param1"] = 81, ["z"] = 8, ["name"] = "default:steelblock"}, {["x"] = 6, ["y"] = 7, ["param1"] = 81, ["z"] = 9, ["name"] = "default:steelblock"}, {["x"] = 6, ["y"] = 7, ["z"] = 10, ["name"] = "default:steelblock"}, {["x"] = 6, ["y"] = 7, ["z"] = 11, ["name"] = "default:steelblock"}, {["x"] = 6, ["y"] = 7, ["z"] = 12, ["name"] = "default:steelblock"}, {["x"] = 6, ["y"] = 7, ["z"] = 13, ["name"] = "default:steelblock"}, {["x"] = 6, ["y"] = 7, ["z"] = 14, ["name"] = "wool:grey"}, {["x"] = 6, ["y"] = 8, ["z"] = 1, ["name"] = "wool:grey"}, {["x"] = 6, ["y"] = 8, ["param1"] = 81, ["z"] = 2, ["name"] = "default:steelblock"}, {["x"] = 6, ["y"] = 8, ["param1"] = 81, ["z"] = 3, ["name"] = "default:steelblock"}, {["x"] = 6, ["y"] = 8, ["param1"] = 81, ["z"] = 4, ["name"] = "default:steelblock"}, {["x"] = 6, ["y"] = 8, ["param1"] = 81, ["z"] = 5, ["name"] = "default:steelblock"}, {["x"] = 6, ["y"] = 8, ["param1"] = 81, ["z"] = 6, ["name"] = "default:steelblock"}, {["x"] = 6, ["y"] = 8, ["param1"] = 81, ["z"] = 7, ["name"] = "default:steelblock"}, {["x"] = 6, ["y"] = 8, ["param1"] = 81, ["z"] = 8, ["name"] = "default:steelblock"}, {["x"] = 6, ["y"] = 8, ["param1"] = 81, ["z"] = 9, ["name"] = "default:steelblock"}, {["x"] = 6, ["y"] = 8, ["z"] = 10, ["name"] = "default:steelblock"}, {["x"] = 6, ["y"] = 8, ["z"] = 11, ["name"] = "default:steelblock"}, {["x"] = 6, ["y"] = 8, ["z"] = 12, ["name"] = "default:steelblock"}, {["x"] = 6, ["y"] = 8, ["z"] = 13, ["name"] = "default:steelblock"}, {["x"] = 6, ["y"] = 8, ["z"] = 14, ["name"] = "wool:grey"}, {["x"] = 6, ["y"] = 9, ["z"] = 1, ["name"] = "wool:grey"}, {["x"] = 6, ["y"] = 9, ["param1"] = 81, ["z"] = 2, ["name"] = "default:steelblock"}, {["x"] = 6, ["y"] = 9, ["param1"] = 81, ["z"] = 3, ["name"] = "default:steelblock"}, {["x"] = 6, ["y"] = 9, ["param1"] = 81, ["z"] = 4, ["name"] = "default:steelblock"}, {["x"] = 6, ["y"] = 9, ["param1"] = 81, ["z"] = 5, ["name"] = "default:steelblock"}, {["x"] = 6, ["y"] = 9, ["param1"] = 81, ["z"] = 6, ["name"] = "default:steelblock"}, {["x"] = 6, ["y"] = 9, ["param1"] = 81, ["z"] = 7, ["name"] = "default:steelblock"}, {["x"] = 6, ["y"] = 9, ["param1"] = 81, ["z"] = 8, ["name"] = "default:steelblock"}, {["x"] = 6, ["y"] = 9, ["param1"] = 81, ["z"] = 9, ["name"] = "default:steelblock"}, {["x"] = 6, ["y"] = 9, ["z"] = 10, ["name"] = "default:steelblock"}, {["x"] = 6, ["y"] = 9, ["z"] = 11, ["name"] = "default:steelblock"}, {["x"] = 6, ["y"] = 9, ["z"] = 12, ["name"] = "default:steelblock"}, {["x"] = 6, ["y"] = 9, ["z"] = 13, ["name"] = "default:steelblock"}, {["x"] = 6, ["y"] = 9, ["z"] = 14, ["name"] = "wool:grey"}, {["x"] = 6, ["y"] = 10, ["param1"] = 81, ["z"] = 2, ["name"] = "default:steelblock"}, {["x"] = 6, ["y"] = 10, ["param1"] = 81, ["z"] = 3, ["name"] = "default:steelblock"}, {["x"] = 6, ["y"] = 10, ["param1"] = 81, ["z"] = 4, ["name"] = "default:steelblock"}, {["x"] = 6, ["y"] = 10, ["param1"] = 81, ["z"] = 5, ["name"] = "default:steelblock"}, {["x"] = 6, ["y"] = 10, ["param1"] = 81, ["z"] = 6, ["name"] = "default:steelblock"}, {["x"] = 6, ["y"] = 10, ["param1"] = 81, ["z"] = 7, ["name"] = "default:steelblock"}, {["x"] = 6, ["y"] = 10, ["param1"] = 81, ["z"] = 8, ["name"] = "default:steelblock"}, {["x"] = 6, ["y"] = 10, ["param1"] = 81, ["z"] = 9, ["name"] = "default:steelblock"}, {["x"] = 6, ["y"] = 10, ["z"] = 10, ["name"] = "default:steelblock"}, {["x"] = 6, ["y"] = 10, ["z"] = 11, ["name"] = "default:steelblock"}, {["x"] = 6, ["y"] = 10, ["z"] = 12, ["name"] = "default:steelblock"}, {["x"] = 6, ["y"] = 10, ["z"] = 13, ["name"] = "default:steelblock"}, {["x"] = 6, ["y"] = 11, ["param1"] = 81, ["z"] = 2, ["name"] = "default:steelblock"}, {["x"] = 6, ["y"] = 11, ["param1"] = 81, ["z"] = 3, ["name"] = "default:steelblock"}, {["x"] = 6, ["y"] = 11, ["param1"] = 81, ["z"] = 4, ["name"] = "default:steelblock"}, {["x"] = 6, ["y"] = 11, ["param1"] = 81, ["z"] = 5, ["name"] = "default:steelblock"}, {["x"] = 6, ["y"] = 11, ["param1"] = 81, ["z"] = 6, ["name"] = "default:steelblock"}, {["x"] = 6, ["y"] = 11, ["param1"] = 81, ["z"] = 7, ["name"] = "default:steelblock"}, {["x"] = 6, ["y"] = 11, ["param1"] = 81, ["z"] = 8, ["name"] = "default:steelblock"}, {["x"] = 6, ["y"] = 11, ["param1"] = 81, ["z"] = 9, ["name"] = "default:steelblock"}, {["x"] = 6, ["y"] = 11, ["z"] = 10, ["name"] = "default:steelblock"}, {["x"] = 6, ["y"] = 11, ["z"] = 11, ["name"] = "default:steelblock"}, {["x"] = 6, ["y"] = 11, ["z"] = 12, ["name"] = "default:steelblock"}, {["x"] = 6, ["y"] = 11, ["z"] = 13, ["name"] = "default:steelblock"}, {["x"] = 7, ["y"] = 4, ["param1"] = 81, ["z"] = 2, ["name"] = "default:steelblock"}, {["x"] = 7, ["y"] = 4, ["param1"] = 81, ["z"] = 3, ["name"] = "default:steelblock"}, {["x"] = 7, ["y"] = 4, ["param1"] = 81, ["z"] = 4, ["name"] = "default:steelblock"}, {["x"] = 7, ["y"] = 4, ["param1"] = 81, ["z"] = 5, ["name"] = "default:steelblock"}, {["x"] = 7, ["y"] = 4, ["param1"] = 81, ["z"] = 6, ["name"] = "default:steelblock"}, {["x"] = 7, ["y"] = 4, ["param1"] = 81, ["z"] = 7, ["name"] = "default:steelblock"}, {["x"] = 7, ["y"] = 4, ["z"] = 8, ["name"] = "default:steelblock"}, {["x"] = 7, ["y"] = 4, ["z"] = 9, ["name"] = "default:steelblock"}, {["x"] = 7, ["y"] = 4, ["z"] = 10, ["name"] = "default:steelblock"}, {["x"] = 7, ["y"] = 4, ["z"] = 11, ["name"] = "default:steelblock"}, {["x"] = 7, ["y"] = 4, ["z"] = 12, ["name"] = "default:steelblock"}, {["x"] = 7, ["y"] = 4, ["z"] = 13, ["name"] = "default:steelblock"}, {["x"] = 7, ["y"] = 5, ["param1"] = 81, ["z"] = 2, ["name"] = "default:steelblock"}, {["x"] = 7, ["y"] = 5, ["param1"] = 81, ["z"] = 3, ["name"] = "default:steelblock"}, {["x"] = 7, ["y"] = 5, ["param1"] = 81, ["z"] = 4, ["name"] = "default:steelblock"}, {["x"] = 7, ["y"] = 5, ["param1"] = 81, ["z"] = 5, ["name"] = "default:steelblock"}, {["x"] = 7, ["y"] = 5, ["param1"] = 81, ["z"] = 6, ["name"] = "default:steelblock"}, {["x"] = 7, ["y"] = 5, ["param1"] = 81, ["z"] = 7, ["name"] = "default:steelblock"}, {["x"] = 7, ["y"] = 5, ["z"] = 8, ["name"] = "default:steelblock"}, {["x"] = 7, ["y"] = 5, ["z"] = 9, ["name"] = "default:steelblock"}, {["x"] = 7, ["y"] = 5, ["z"] = 10, ["name"] = "default:steelblock"}, {["x"] = 7, ["y"] = 5, ["z"] = 11, ["name"] = "default:steelblock"}, {["x"] = 7, ["y"] = 5, ["z"] = 12, ["name"] = "default:steelblock"}, {["x"] = 7, ["y"] = 5, ["z"] = 13, ["name"] = "default:steelblock"}, {["x"] = 7, ["y"] = 6, ["z"] = 1, ["name"] = "wool:grey"}, {["x"] = 7, ["y"] = 6, ["param1"] = 81, ["z"] = 2, ["name"] = "default:steelblock"}, {["x"] = 7, ["y"] = 6, ["param1"] = 81, ["z"] = 3, ["name"] = "default:steelblock"}, {["x"] = 7, ["y"] = 6, ["param1"] = 81, ["z"] = 4, ["name"] = "default:steelblock"}, {["x"] = 7, ["y"] = 6, ["param1"] = 81, ["z"] = 5, ["name"] = "default:steelblock"}, {["x"] = 7, ["y"] = 6, ["param1"] = 81, ["z"] = 6, ["name"] = "default:steelblock"}, {["x"] = 7, ["y"] = 6, ["param1"] = 81, ["z"] = 7, ["name"] = "default:steelblock"}, {["x"] = 7, ["y"] = 6, ["z"] = 8, ["name"] = "default:steelblock"}, {["x"] = 7, ["y"] = 6, ["z"] = 9, ["name"] = "default:steelblock"}, {["x"] = 7, ["y"] = 6, ["z"] = 10, ["name"] = "default:steelblock"}, {["x"] = 7, ["y"] = 6, ["z"] = 11, ["name"] = "default:steelblock"}, {["x"] = 7, ["y"] = 6, ["z"] = 12, ["name"] = "default:steelblock"}, {["x"] = 7, ["y"] = 6, ["z"] = 13, ["name"] = "default:steelblock"}, {["x"] = 7, ["y"] = 6, ["z"] = 14, ["name"] = "wool:grey"}, {["x"] = 7, ["y"] = 7, ["z"] = 0, ["name"] = "wool:red"}, {["x"] = 7, ["y"] = 7, ["z"] = 1, ["name"] = "wool:red"}, {["x"] = 7, ["y"] = 7, ["param1"] = 81, ["z"] = 2, ["name"] = "default:steelblock"}, {["x"] = 7, ["y"] = 7, ["param1"] = 81, ["z"] = 3, ["name"] = "default:steelblock"}, {["x"] = 7, ["y"] = 7, ["param1"] = 81, ["z"] = 4, ["name"] = "default:steelblock"}, {["x"] = 7, ["y"] = 7, ["param1"] = 81, ["z"] = 5, ["name"] = "default:steelblock"}, {["x"] = 7, ["y"] = 7, ["param1"] = 81, ["z"] = 6, ["name"] = "default:steelblock"}, {["x"] = 7, ["y"] = 7, ["param1"] = 81, ["z"] = 7, ["name"] = "default:steelblock"}, {["x"] = 7, ["y"] = 7, ["param1"] = 81, ["z"] = 8, ["name"] = "default:steelblock"}, {["x"] = 7, ["y"] = 7, ["param1"] = 81, ["z"] = 9, ["name"] = "default:steelblock"}, {["x"] = 7, ["y"] = 7, ["z"] = 10, ["name"] = "default:steelblock"}, {["x"] = 7, ["y"] = 7, ["z"] = 11, ["name"] = "default:steelblock"}, {["x"] = 7, ["y"] = 7, ["z"] = 12, ["name"] = "default:steelblock"}, {["x"] = 7, ["y"] = 7, ["z"] = 13, ["name"] = "default:steelblock"}, {["x"] = 7, ["y"] = 7, ["z"] = 14, ["name"] = "wool:red"}, {["x"] = 7, ["y"] = 7, ["z"] = 15, ["name"] = "wool:red"}, {["x"] = 7, ["y"] = 8, ["z"] = 0, ["name"] = "wool:red"}, {["x"] = 7, ["y"] = 8, ["z"] = 1, ["name"] = "wool:red"}, {["x"] = 7, ["y"] = 8, ["param1"] = 81, ["z"] = 2, ["name"] = "default:steelblock"}, {["x"] = 7, ["y"] = 8, ["param1"] = 81, ["z"] = 3, ["name"] = "default:steelblock"}, {["x"] = 7, ["y"] = 8, ["param1"] = 81, ["z"] = 4, ["name"] = "default:steelblock"}, {["x"] = 7, ["y"] = 8, ["param1"] = 81, ["z"] = 5, ["name"] = "default:steelblock"}, {["x"] = 7, ["y"] = 8, ["param1"] = 81, ["z"] = 6, ["name"] = "default:steelblock"}, {["x"] = 7, ["y"] = 8, ["param1"] = 81, ["z"] = 7, ["name"] = "default:steelblock"}, {["x"] = 7, ["y"] = 8, ["param1"] = 81, ["z"] = 8, ["name"] = "default:steelblock"}, {["x"] = 7, ["y"] = 8, ["param1"] = 81, ["z"] = 9, ["name"] = "default:steelblock"}, {["x"] = 7, ["y"] = 8, ["z"] = 10, ["name"] = "default:steelblock"}, {["x"] = 7, ["y"] = 8, ["z"] = 11, ["name"] = "default:steelblock"}, {["x"] = 7, ["y"] = 8, ["z"] = 12, ["name"] = "default:steelblock"}, {["x"] = 7, ["y"] = 8, ["z"] = 13, ["name"] = "default:steelblock"}, {["x"] = 7, ["y"] = 8, ["z"] = 14, ["name"] = "wool:red"}, {["x"] = 7, ["y"] = 8, ["z"] = 15, ["name"] = "wool:red"}, {["x"] = 7, ["y"] = 9, ["z"] = 1, ["name"] = "wool:grey"}, {["x"] = 7, ["y"] = 9, ["param1"] = 81, ["z"] = 2, ["name"] = "default:steelblock"}, {["x"] = 7, ["y"] = 9, ["param1"] = 81, ["z"] = 3, ["name"] = "default:steelblock"}, {["x"] = 7, ["y"] = 9, ["param1"] = 81, ["z"] = 4, ["name"] = "default:steelblock"}, {["x"] = 7, ["y"] = 9, ["param1"] = 81, ["z"] = 5, ["name"] = "default:steelblock"}, {["x"] = 7, ["y"] = 9, ["param1"] = 81, ["z"] = 6, ["name"] = "default:steelblock"}, {["x"] = 7, ["y"] = 9, ["param1"] = 81, ["z"] = 7, ["name"] = "default:steelblock"}, {["x"] = 7, ["y"] = 9, ["param1"] = 81, ["z"] = 8, ["name"] = "default:steelblock"}, {["x"] = 7, ["y"] = 9, ["param1"] = 81, ["z"] = 9, ["name"] = "default:steelblock"}, {["x"] = 7, ["y"] = 9, ["z"] = 10, ["name"] = "default:steelblock"}, {["x"] = 7, ["y"] = 9, ["z"] = 11, ["name"] = "default:steelblock"}, {["x"] = 7, ["y"] = 9, ["z"] = 12, ["name"] = "default:steelblock"}, {["x"] = 7, ["y"] = 9, ["z"] = 13, ["name"] = "default:steelblock"}, {["x"] = 7, ["y"] = 9, ["z"] = 14, ["name"] = "wool:grey"}, {["x"] = 7, ["y"] = 10, ["param1"] = 81, ["z"] = 2, ["name"] = "default:steelblock"}, {["x"] = 7, ["y"] = 10, ["param1"] = 81, ["z"] = 3, ["name"] = "default:steelblock"}, {["x"] = 7, ["y"] = 10, ["param1"] = 81, ["z"] = 4, ["name"] = "default:steelblock"}, {["x"] = 7, ["y"] = 10, ["param1"] = 81, ["z"] = 5, ["name"] = "default:steelblock"}, {["x"] = 7, ["y"] = 10, ["param1"] = 81, ["z"] = 6, ["name"] = "default:steelblock"}, {["x"] = 7, ["y"] = 10, ["param1"] = 81, ["z"] = 7, ["name"] = "default:steelblock"}, {["x"] = 7, ["y"] = 10, ["param1"] = 81, ["z"] = 8, ["name"] = "default:steelblock"}, {["x"] = 7, ["y"] = 10, ["param1"] = 81, ["z"] = 9, ["name"] = "default:steelblock"}, {["x"] = 7, ["y"] = 10, ["z"] = 10, ["name"] = "default:steelblock"}, {["x"] = 7, ["y"] = 10, ["z"] = 11, ["name"] = "default:steelblock"}, {["x"] = 7, ["y"] = 10, ["z"] = 12, ["name"] = "default:steelblock"}, {["x"] = 7, ["y"] = 10, ["z"] = 13, ["name"] = "default:steelblock"}, {["x"] = 7, ["y"] = 11, ["param1"] = 81, ["z"] = 2, ["name"] = "default:steelblock"}, {["x"] = 7, ["y"] = 11, ["param1"] = 81, ["z"] = 3, ["name"] = "default:steelblock"}, {["x"] = 7, ["y"] = 11, ["param1"] = 81, ["z"] = 4, ["name"] = "default:steelblock"}, {["x"] = 7, ["y"] = 11, ["param1"] = 81, ["z"] = 5, ["name"] = "default:steelblock"}, {["x"] = 7, ["y"] = 11, ["param1"] = 81, ["z"] = 6, ["name"] = "default:steelblock"}, {["x"] = 7, ["y"] = 11, ["param1"] = 81, ["z"] = 7, ["name"] = "default:steelblock"}, {["x"] = 7, ["y"] = 11, ["param1"] = 81, ["z"] = 8, ["name"] = "default:steelblock"}, {["x"] = 7, ["y"] = 11, ["param1"] = 81, ["z"] = 9, ["name"] = "default:steelblock"}, {["x"] = 7, ["y"] = 11, ["z"] = 10, ["name"] = "default:steelblock"}, {["x"] = 7, ["y"] = 11, ["z"] = 11, ["name"] = "default:steelblock"}, {["x"] = 7, ["y"] = 11, ["z"] = 12, ["name"] = "default:steelblock"}, {["x"] = 7, ["y"] = 11, ["z"] = 13, ["name"] = "default:steelblock"}, {["x"] = 8, ["y"] = 4, ["param1"] = 81, ["z"] = 2, ["name"] = "default:steelblock"}, {["x"] = 8, ["y"] = 4, ["param1"] = 81, ["z"] = 3, ["name"] = "default:steelblock"}, {["x"] = 8, ["y"] = 4, ["param1"] = 81, ["z"] = 4, ["name"] = "default:steelblock"}, {["x"] = 8, ["y"] = 4, ["param1"] = 81, ["z"] = 5, ["name"] = "default:steelblock"}, {["x"] = 8, ["y"] = 4, ["param1"] = 81, ["z"] = 6, ["name"] = "default:steelblock"}, {["x"] = 8, ["y"] = 4, ["param1"] = 81, ["z"] = 7, ["name"] = "default:steelblock"}, {["x"] = 8, ["y"] = 4, ["z"] = 8, ["name"] = "default:steelblock"}, {["x"] = 8, ["y"] = 4, ["z"] = 9, ["name"] = "default:steelblock"}, {["x"] = 8, ["y"] = 4, ["z"] = 10, ["name"] = "default:steelblock"}, {["x"] = 8, ["y"] = 4, ["z"] = 11, ["name"] = "default:steelblock"}, {["x"] = 8, ["y"] = 4, ["z"] = 12, ["name"] = "default:steelblock"}, {["x"] = 8, ["y"] = 4, ["z"] = 13, ["name"] = "default:steelblock"}, {["x"] = 8, ["y"] = 5, ["param1"] = 81, ["z"] = 2, ["name"] = "default:steelblock"}, {["x"] = 8, ["y"] = 5, ["param1"] = 81, ["z"] = 3, ["name"] = "default:steelblock"}, {["x"] = 8, ["y"] = 5, ["param1"] = 81, ["z"] = 4, ["name"] = "default:steelblock"}, {["x"] = 8, ["y"] = 5, ["param1"] = 81, ["z"] = 5, ["name"] = "default:steelblock"}, {["x"] = 8, ["y"] = 5, ["param1"] = 81, ["z"] = 6, ["name"] = "default:steelblock"}, {["x"] = 8, ["y"] = 5, ["param1"] = 81, ["z"] = 7, ["name"] = "default:steelblock"}, {["x"] = 8, ["y"] = 5, ["z"] = 8, ["name"] = "default:steelblock"}, {["x"] = 8, ["y"] = 5, ["z"] = 9, ["name"] = "default:steelblock"}, {["x"] = 8, ["y"] = 5, ["z"] = 10, ["name"] = "default:steelblock"}, {["x"] = 8, ["y"] = 5, ["z"] = 11, ["name"] = "default:steelblock"}, {["x"] = 8, ["y"] = 5, ["z"] = 12, ["name"] = "default:steelblock"}, {["x"] = 8, ["y"] = 5, ["z"] = 13, ["name"] = "default:steelblock"}, {["x"] = 8, ["y"] = 6, ["z"] = 1, ["name"] = "wool:grey"}, {["x"] = 8, ["y"] = 6, ["param1"] = 81, ["z"] = 2, ["name"] = "default:steelblock"}, {["x"] = 8, ["y"] = 6, ["param1"] = 81, ["z"] = 3, ["name"] = "default:steelblock"}, {["x"] = 8, ["y"] = 6, ["param1"] = 81, ["z"] = 4, ["name"] = "default:steelblock"}, {["x"] = 8, ["y"] = 6, ["param1"] = 81, ["z"] = 5, ["name"] = "default:steelblock"}, {["x"] = 8, ["y"] = 6, ["param1"] = 81, ["z"] = 6, ["name"] = "default:steelblock"}, {["x"] = 8, ["y"] = 6, ["param1"] = 81, ["z"] = 7, ["name"] = "default:steelblock"}, {["x"] = 8, ["y"] = 6, ["z"] = 8, ["name"] = "default:steelblock"}, {["x"] = 8, ["y"] = 6, ["z"] = 9, ["name"] = "default:steelblock"}, {["x"] = 8, ["y"] = 6, ["z"] = 10, ["name"] = "default:steelblock"}, {["x"] = 8, ["y"] = 6, ["z"] = 11, ["name"] = "default:steelblock"}, {["x"] = 8, ["y"] = 6, ["z"] = 12, ["name"] = "default:steelblock"}, {["x"] = 8, ["y"] = 6, ["z"] = 13, ["name"] = "default:steelblock"}, {["x"] = 8, ["y"] = 6, ["z"] = 14, ["name"] = "wool:grey"}, {["x"] = 8, ["y"] = 7, ["z"] = 0, ["name"] = "wool:red"}, {["x"] = 8, ["y"] = 7, ["z"] = 1, ["name"] = "wool:red"}, {["x"] = 8, ["y"] = 7, ["param1"] = 81, ["z"] = 2, ["name"] = "default:steelblock"}, {["x"] = 8, ["y"] = 7, ["param1"] = 81, ["z"] = 3, ["name"] = "default:steelblock"}, {["x"] = 8, ["y"] = 7, ["param1"] = 81, ["z"] = 4, ["name"] = "default:steelblock"}, {["x"] = 8, ["y"] = 7, ["param1"] = 81, ["z"] = 5, ["name"] = "default:steelblock"}, {["x"] = 8, ["y"] = 7, ["param1"] = 81, ["z"] = 6, ["name"] = "default:steelblock"}, {["x"] = 8, ["y"] = 7, ["param1"] = 81, ["z"] = 7, ["name"] = "default:steelblock"}, {["x"] = 8, ["y"] = 7, ["param1"] = 81, ["z"] = 8, ["name"] = "default:steelblock"}, {["x"] = 8, ["y"] = 7, ["param1"] = 81, ["z"] = 9, ["name"] = "default:steelblock"}, {["x"] = 8, ["y"] = 7, ["z"] = 10, ["name"] = "default:steelblock"}, {["x"] = 8, ["y"] = 7, ["z"] = 11, ["name"] = "default:steelblock"}, {["x"] = 8, ["y"] = 7, ["z"] = 12, ["name"] = "default:steelblock"}, {["x"] = 8, ["y"] = 7, ["z"] = 13, ["name"] = "default:steelblock"}, {["x"] = 8, ["y"] = 7, ["z"] = 14, ["name"] = "wool:red"}, {["x"] = 8, ["y"] = 7, ["z"] = 15, ["name"] = "wool:red"}, {["x"] = 8, ["y"] = 8, ["z"] = 0, ["name"] = "wool:red"}, {["x"] = 8, ["y"] = 8, ["z"] = 1, ["name"] = "wool:red"}, {["x"] = 8, ["y"] = 8, ["param1"] = 81, ["z"] = 2, ["name"] = "default:steelblock"}, {["x"] = 8, ["y"] = 8, ["param1"] = 81, ["z"] = 3, ["name"] = "default:steelblock"}, {["x"] = 8, ["y"] = 8, ["param1"] = 81, ["z"] = 4, ["name"] = "default:steelblock"}, {["x"] = 8, ["y"] = 8, ["param1"] = 81, ["z"] = 5, ["name"] = "default:steelblock"}, {["x"] = 8, ["y"] = 8, ["param1"] = 81, ["z"] = 6, ["name"] = "default:steelblock"}, {["x"] = 8, ["y"] = 8, ["param1"] = 81, ["z"] = 7, ["name"] = "default:steelblock"}, {["x"] = 8, ["y"] = 8, ["param1"] = 81, ["z"] = 8, ["name"] = "default:steelblock"}, {["x"] = 8, ["y"] = 8, ["param1"] = 81, ["z"] = 9, ["name"] = "default:steelblock"}, {["x"] = 8, ["y"] = 8, ["z"] = 10, ["name"] = "default:steelblock"}, {["x"] = 8, ["y"] = 8, ["z"] = 11, ["name"] = "default:steelblock"}, {["x"] = 8, ["y"] = 8, ["z"] = 12, ["name"] = "default:steelblock"}, {["x"] = 8, ["y"] = 8, ["z"] = 13, ["name"] = "default:steelblock"}, {["x"] = 8, ["y"] = 8, ["z"] = 14, ["name"] = "wool:red"}, {["x"] = 8, ["y"] = 8, ["z"] = 15, ["name"] = "wool:red"}, {["x"] = 8, ["y"] = 9, ["z"] = 1, ["name"] = "wool:grey"}, {["x"] = 8, ["y"] = 9, ["param1"] = 81, ["z"] = 2, ["name"] = "default:steelblock"}, {["x"] = 8, ["y"] = 9, ["param1"] = 81, ["z"] = 3, ["name"] = "default:steelblock"}, {["x"] = 8, ["y"] = 9, ["param1"] = 81, ["z"] = 4, ["name"] = "default:steelblock"}, {["x"] = 8, ["y"] = 9, ["param1"] = 81, ["z"] = 5, ["name"] = "default:steelblock"}, {["x"] = 8, ["y"] = 9, ["param1"] = 81, ["z"] = 6, ["name"] = "default:steelblock"}, {["x"] = 8, ["y"] = 9, ["param1"] = 81, ["z"] = 7, ["name"] = "default:steelblock"}, {["x"] = 8, ["y"] = 9, ["param1"] = 81, ["z"] = 8, ["name"] = "default:steelblock"}, {["x"] = 8, ["y"] = 9, ["param1"] = 81, ["z"] = 9, ["name"] = "default:steelblock"}, {["x"] = 8, ["y"] = 9, ["z"] = 10, ["name"] = "default:steelblock"}, {["x"] = 8, ["y"] = 9, ["z"] = 11, ["name"] = "default:steelblock"}, {["x"] = 8, ["y"] = 9, ["z"] = 12, ["name"] = "default:steelblock"}, {["x"] = 8, ["y"] = 9, ["z"] = 13, ["name"] = "default:steelblock"}, {["x"] = 8, ["y"] = 9, ["z"] = 14, ["name"] = "wool:grey"}, {["x"] = 8, ["y"] = 10, ["param1"] = 81, ["z"] = 2, ["name"] = "default:steelblock"}, {["x"] = 8, ["y"] = 10, ["param1"] = 81, ["z"] = 3, ["name"] = "default:steelblock"}, {["x"] = 8, ["y"] = 10, ["param1"] = 81, ["z"] = 4, ["name"] = "default:steelblock"}, {["x"] = 8, ["y"] = 10, ["param1"] = 81, ["z"] = 5, ["name"] = "default:steelblock"}, {["x"] = 8, ["y"] = 10, ["param1"] = 81, ["z"] = 6, ["name"] = "default:steelblock"}, {["x"] = 8, ["y"] = 10, ["param1"] = 81, ["z"] = 7, ["name"] = "default:steelblock"}, {["x"] = 8, ["y"] = 10, ["param1"] = 81, ["z"] = 8, ["name"] = "default:steelblock"}, {["x"] = 8, ["y"] = 10, ["param1"] = 81, ["z"] = 9, ["name"] = "default:steelblock"}, {["x"] = 8, ["y"] = 10, ["z"] = 10, ["name"] = "default:steelblock"}, {["x"] = 8, ["y"] = 10, ["z"] = 11, ["name"] = "default:steelblock"}, {["x"] = 8, ["y"] = 10, ["z"] = 12, ["name"] = "default:steelblock"}, {["x"] = 8, ["y"] = 10, ["z"] = 13, ["name"] = "default:steelblock"}, {["x"] = 8, ["y"] = 11, ["param1"] = 81, ["z"] = 2, ["name"] = "default:steelblock"}, {["x"] = 8, ["y"] = 11, ["param1"] = 81, ["z"] = 3, ["name"] = "default:steelblock"}, {["x"] = 8, ["y"] = 11, ["param1"] = 81, ["z"] = 4, ["name"] = "default:steelblock"}, {["x"] = 8, ["y"] = 11, ["param1"] = 81, ["z"] = 5, ["name"] = "default:steelblock"}, {["x"] = 8, ["y"] = 11, ["param1"] = 81, ["z"] = 6, ["name"] = "default:steelblock"}, {["x"] = 8, ["y"] = 11, ["param1"] = 81, ["z"] = 7, ["name"] = "default:steelblock"}, {["x"] = 8, ["y"] = 11, ["param1"] = 81, ["z"] = 8, ["name"] = "default:steelblock"}, {["x"] = 8, ["y"] = 11, ["param1"] = 81, ["z"] = 9, ["name"] = "default:steelblock"}, {["x"] = 8, ["y"] = 11, ["z"] = 10, ["name"] = "default:steelblock"}, {["x"] = 8, ["y"] = 11, ["z"] = 11, ["name"] = "default:steelblock"}, {["x"] = 8, ["y"] = 11, ["z"] = 12, ["name"] = "default:steelblock"}, {["x"] = 8, ["y"] = 11, ["z"] = 13, ["name"] = "default:steelblock"}, {["x"] = 9, ["y"] = 4, ["param1"] = 81, ["z"] = 2, ["name"] = "default:steelblock"}, {["x"] = 9, ["y"] = 4, ["param1"] = 81, ["z"] = 3, ["name"] = "default:steelblock"}, {["x"] = 9, ["y"] = 4, ["param1"] = 81, ["z"] = 4, ["name"] = "default:steelblock"}, {["x"] = 9, ["y"] = 4, ["param1"] = 81, ["z"] = 5, ["name"] = "default:steelblock"}, {["x"] = 9, ["y"] = 4, ["param1"] = 81, ["z"] = 6, ["name"] = "default:steelblock"}, {["x"] = 9, ["y"] = 4, ["param1"] = 81, ["z"] = 7, ["name"] = "default:steelblock"}, {["x"] = 9, ["y"] = 4, ["z"] = 8, ["name"] = "default:steelblock"}, {["x"] = 9, ["y"] = 4, ["z"] = 9, ["name"] = "default:steelblock"}, {["x"] = 9, ["y"] = 4, ["z"] = 10, ["name"] = "default:steelblock"}, {["x"] = 9, ["y"] = 4, ["z"] = 11, ["name"] = "default:steelblock"}, {["x"] = 9, ["y"] = 4, ["z"] = 12, ["name"] = "default:steelblock"}, {["x"] = 9, ["y"] = 4, ["z"] = 13, ["name"] = "default:steelblock"}, {["x"] = 9, ["y"] = 5, ["param1"] = 81, ["z"] = 2, ["name"] = "default:steelblock"}, {["x"] = 9, ["y"] = 5, ["param1"] = 81, ["z"] = 3, ["name"] = "default:steelblock"}, {["x"] = 9, ["y"] = 5, ["param1"] = 81, ["z"] = 4, ["name"] = "default:steelblock"}, {["x"] = 9, ["y"] = 5, ["param1"] = 81, ["z"] = 5, ["name"] = "default:steelblock"}, {["x"] = 9, ["y"] = 5, ["param1"] = 81, ["z"] = 6, ["name"] = "default:steelblock"}, {["x"] = 9, ["y"] = 5, ["param1"] = 81, ["z"] = 7, ["name"] = "default:steelblock"}, {["x"] = 9, ["y"] = 5, ["z"] = 8, ["name"] = "default:steelblock"}, {["x"] = 9, ["y"] = 5, ["z"] = 9, ["name"] = "default:steelblock"}, {["x"] = 9, ["y"] = 5, ["z"] = 10, ["name"] = "default:steelblock"}, {["x"] = 9, ["y"] = 5, ["z"] = 11, ["name"] = "default:steelblock"}, {["x"] = 9, ["y"] = 5, ["z"] = 12, ["name"] = "default:steelblock"}, {["x"] = 9, ["y"] = 5, ["z"] = 13, ["name"] = "default:steelblock"}, {["x"] = 9, ["y"] = 6, ["z"] = 1, ["name"] = "wool:grey"}, {["x"] = 9, ["y"] = 6, ["param1"] = 81, ["z"] = 2, ["name"] = "default:steelblock"}, {["x"] = 9, ["y"] = 6, ["param1"] = 81, ["z"] = 3, ["name"] = "default:steelblock"}, {["x"] = 9, ["y"] = 6, ["param1"] = 81, ["z"] = 4, ["name"] = "default:steelblock"}, {["x"] = 9, ["y"] = 6, ["param1"] = 81, ["z"] = 5, ["name"] = "default:steelblock"}, {["x"] = 9, ["y"] = 6, ["param1"] = 81, ["z"] = 6, ["name"] = "default:steelblock"}, {["x"] = 9, ["y"] = 6, ["param1"] = 81, ["z"] = 7, ["name"] = "default:steelblock"}, {["x"] = 9, ["y"] = 6, ["param1"] = 81, ["z"] = 8, ["name"] = "default:steelblock"}, {["x"] = 9, ["y"] = 6, ["param1"] = 81, ["z"] = 9, ["name"] = "default:steelblock"}, {["x"] = 9, ["y"] = 6, ["z"] = 10, ["name"] = "default:steelblock"}, {["x"] = 9, ["y"] = 6, ["z"] = 11, ["name"] = "default:steelblock"}, {["x"] = 9, ["y"] = 6, ["z"] = 12, ["name"] = "default:steelblock"}, {["x"] = 9, ["y"] = 6, ["z"] = 13, ["name"] = "default:steelblock"}, {["x"] = 9, ["y"] = 6, ["z"] = 14, ["name"] = "wool:grey"}, {["x"] = 9, ["y"] = 7, ["z"] = 1, ["name"] = "wool:grey"}, {["x"] = 9, ["y"] = 7, ["param1"] = 81, ["z"] = 2, ["name"] = "default:steelblock"}, {["x"] = 9, ["y"] = 7, ["param1"] = 81, ["z"] = 3, ["name"] = "default:steelblock"}, {["x"] = 9, ["y"] = 7, ["param1"] = 81, ["z"] = 4, ["name"] = "default:steelblock"}, {["x"] = 9, ["y"] = 7, ["param1"] = 81, ["z"] = 5, ["name"] = "default:steelblock"}, {["x"] = 9, ["y"] = 7, ["param1"] = 81, ["z"] = 6, ["name"] = "default:steelblock"}, {["x"] = 9, ["y"] = 7, ["param1"] = 81, ["z"] = 7, ["name"] = "default:steelblock"}, {["x"] = 9, ["y"] = 7, ["param1"] = 81, ["z"] = 8, ["name"] = "default:steelblock"}, {["x"] = 9, ["y"] = 7, ["param1"] = 81, ["z"] = 9, ["name"] = "default:steelblock"}, {["x"] = 9, ["y"] = 7, ["z"] = 10, ["name"] = "default:steelblock"}, {["x"] = 9, ["y"] = 7, ["z"] = 11, ["name"] = "default:steelblock"}, {["x"] = 9, ["y"] = 7, ["z"] = 12, ["name"] = "default:steelblock"}, {["x"] = 9, ["y"] = 7, ["z"] = 13, ["name"] = "default:steelblock"}, {["x"] = 9, ["y"] = 7, ["z"] = 14, ["name"] = "wool:grey"}, {["x"] = 9, ["y"] = 8, ["z"] = 1, ["name"] = "wool:grey"}, {["x"] = 9, ["y"] = 8, ["param1"] = 81, ["z"] = 2, ["name"] = "default:steelblock"}, {["x"] = 9, ["y"] = 8, ["param1"] = 81, ["z"] = 3, ["name"] = "default:steelblock"}, {["x"] = 9, ["y"] = 8, ["param1"] = 81, ["z"] = 4, ["name"] = "default:steelblock"}, {["x"] = 9, ["y"] = 8, ["param1"] = 81, ["z"] = 5, ["name"] = "default:steelblock"}, {["x"] = 9, ["y"] = 8, ["param1"] = 81, ["z"] = 6, ["name"] = "default:steelblock"}, {["x"] = 9, ["y"] = 8, ["param1"] = 81, ["z"] = 7, ["name"] = "default:steelblock"}, {["x"] = 9, ["y"] = 8, ["param1"] = 81, ["z"] = 8, ["name"] = "default:steelblock"}, {["x"] = 9, ["y"] = 8, ["param1"] = 81, ["z"] = 9, ["name"] = "default:steelblock"}, {["x"] = 9, ["y"] = 8, ["z"] = 10, ["name"] = "default:steelblock"}, {["x"] = 9, ["y"] = 8, ["z"] = 11, ["name"] = "default:steelblock"}, {["x"] = 9, ["y"] = 8, ["z"] = 12, ["name"] = "default:steelblock"}, {["x"] = 9, ["y"] = 8, ["z"] = 13, ["name"] = "default:steelblock"}, {["x"] = 9, ["y"] = 8, ["z"] = 14, ["name"] = "wool:grey"}, {["x"] = 9, ["y"] = 9, ["z"] = 1, ["name"] = "wool:grey"}, {["x"] = 9, ["y"] = 9, ["param1"] = 81, ["z"] = 2, ["name"] = "default:steelblock"}, {["x"] = 9, ["y"] = 9, ["param1"] = 81, ["z"] = 3, ["name"] = "default:steelblock"}, {["x"] = 9, ["y"] = 9, ["param1"] = 81, ["z"] = 4, ["name"] = "default:steelblock"}, {["x"] = 9, ["y"] = 9, ["param1"] = 81, ["z"] = 5, ["name"] = "default:steelblock"}, {["x"] = 9, ["y"] = 9, ["param1"] = 81, ["z"] = 6, ["name"] = "default:steelblock"}, {["x"] = 9, ["y"] = 9, ["param1"] = 81, ["z"] = 7, ["name"] = "default:steelblock"}, {["x"] = 9, ["y"] = 9, ["param1"] = 81, ["z"] = 8, ["name"] = "default:steelblock"}, {["x"] = 9, ["y"] = 9, ["param1"] = 81, ["z"] = 9, ["name"] = "default:steelblock"}, {["x"] = 9, ["y"] = 9, ["z"] = 10, ["name"] = "default:steelblock"}, {["x"] = 9, ["y"] = 9, ["z"] = 11, ["name"] = "default:steelblock"}, {["x"] = 9, ["y"] = 9, ["z"] = 12, ["name"] = "default:steelblock"}, {["x"] = 9, ["y"] = 9, ["z"] = 13, ["name"] = "default:steelblock"}, {["x"] = 9, ["y"] = 9, ["z"] = 14, ["name"] = "wool:grey"}, {["x"] = 9, ["y"] = 10, ["param1"] = 81, ["z"] = 2, ["name"] = "default:steelblock"}, {["x"] = 9, ["y"] = 10, ["param1"] = 81, ["z"] = 3, ["name"] = "default:steelblock"}, {["x"] = 9, ["y"] = 10, ["param1"] = 81, ["z"] = 4, ["name"] = "default:steelblock"}, {["x"] = 9, ["y"] = 10, ["param1"] = 81, ["z"] = 5, ["name"] = "default:steelblock"}, {["x"] = 9, ["y"] = 10, ["param1"] = 81, ["z"] = 6, ["name"] = "default:steelblock"}, {["x"] = 9, ["y"] = 10, ["param1"] = 81, ["z"] = 7, ["name"] = "default:steelblock"}, {["x"] = 9, ["y"] = 10, ["param1"] = 81, ["z"] = 8, ["name"] = "default:steelblock"}, {["x"] = 9, ["y"] = 10, ["param1"] = 81, ["z"] = 9, ["name"] = "default:steelblock"}, {["x"] = 9, ["y"] = 10, ["z"] = 10, ["name"] = "default:steelblock"}, {["x"] = 9, ["y"] = 10, ["z"] = 11, ["name"] = "default:steelblock"}, {["x"] = 9, ["y"] = 10, ["z"] = 12, ["name"] = "default:steelblock"}, {["x"] = 9, ["y"] = 10, ["z"] = 13, ["name"] = "default:steelblock"}, {["x"] = 9, ["y"] = 11, ["param1"] = 81, ["z"] = 2, ["name"] = "default:steelblock"}, {["x"] = 9, ["y"] = 11, ["param1"] = 81, ["z"] = 3, ["name"] = "default:steelblock"}, {["x"] = 9, ["y"] = 11, ["param1"] = 81, ["z"] = 4, ["name"] = "default:steelblock"}, {["x"] = 9, ["y"] = 11, ["param1"] = 81, ["z"] = 5, ["name"] = "default:steelblock"}, {["x"] = 9, ["y"] = 11, ["param1"] = 81, ["z"] = 6, ["name"] = "default:steelblock"}, {["x"] = 9, ["y"] = 11, ["param1"] = 81, ["z"] = 7, ["name"] = "default:steelblock"}, {["x"] = 9, ["y"] = 11, ["param1"] = 81, ["z"] = 8, ["name"] = "default:steelblock"}, {["x"] = 9, ["y"] = 11, ["z"] = 9, ["name"] = "default:steelblock"}, {["x"] = 9, ["y"] = 11, ["z"] = 10, ["name"] = "default:steelblock"}, {["x"] = 9, ["y"] = 11, ["z"] = 11, ["name"] = "default:steelblock"}, {["x"] = 9, ["y"] = 11, ["z"] = 12, ["name"] = "default:steelblock"}, {["x"] = 9, ["y"] = 11, ["z"] = 13, ["name"] = "default:steelblock"}, {["x"] = 10, ["y"] = 5, ["param1"] = 81, ["z"] = 2, ["name"] = "default:steelblock"}, {["x"] = 10, ["y"] = 5, ["param1"] = 81, ["z"] = 3, ["name"] = "default:steelblock"}, {["x"] = 10, ["y"] = 5, ["param1"] = 81, ["z"] = 4, ["name"] = "default:steelblock"}, {["x"] = 10, ["y"] = 5, ["param1"] = 81, ["z"] = 5, ["name"] = "default:steelblock"}, {["x"] = 10, ["y"] = 5, ["param1"] = 81, ["z"] = 6, ["name"] = "default:steelblock"}, {["x"] = 10, ["y"] = 5, ["param1"] = 81, ["z"] = 7, ["name"] = "default:steelblock"}, {["x"] = 10, ["y"] = 5, ["param1"] = 81, ["z"] = 8, ["name"] = "default:steelblock"}, {["x"] = 10, ["y"] = 5, ["param1"] = 81, ["z"] = 9, ["name"] = "default:steelblock"}, {["x"] = 10, ["y"] = 5, ["z"] = 10, ["name"] = "default:steelblock"}, {["x"] = 10, ["y"] = 5, ["z"] = 11, ["name"] = "default:steelblock"}, {["x"] = 10, ["y"] = 5, ["z"] = 12, ["name"] = "default:steelblock"}, {["x"] = 10, ["y"] = 5, ["z"] = 13, ["name"] = "default:steelblock"}, {["x"] = 10, ["y"] = 6, ["z"] = 1, ["name"] = "wool:grey"}, {["x"] = 10, ["y"] = 6, ["param1"] = 81, ["z"] = 2, ["name"] = "default:steelblock"}, {["x"] = 10, ["y"] = 6, ["param1"] = 81, ["z"] = 3, ["name"] = "default:steelblock"}, {["x"] = 10, ["y"] = 6, ["param1"] = 81, ["z"] = 4, ["name"] = "default:steelblock"}, {["x"] = 10, ["y"] = 6, ["param1"] = 81, ["z"] = 5, ["name"] = "default:steelblock"}, {["x"] = 10, ["y"] = 6, ["param1"] = 81, ["z"] = 6, ["name"] = "default:steelblock"}, {["x"] = 10, ["y"] = 6, ["param1"] = 81, ["z"] = 7, ["name"] = "default:steelblock"}, {["x"] = 10, ["y"] = 6, ["param1"] = 81, ["z"] = 8, ["name"] = "default:steelblock"}, {["x"] = 10, ["y"] = 6, ["param1"] = 81, ["z"] = 9, ["name"] = "default:steelblock"}, {["x"] = 10, ["y"] = 6, ["z"] = 10, ["name"] = "default:steelblock"}, {["x"] = 10, ["y"] = 6, ["z"] = 11, ["name"] = "default:steelblock"}, {["x"] = 10, ["y"] = 6, ["z"] = 12, ["name"] = "default:steelblock"}, {["x"] = 10, ["y"] = 6, ["z"] = 13, ["name"] = "default:steelblock"}, {["x"] = 10, ["y"] = 6, ["z"] = 14, ["name"] = "wool:grey"}, {["x"] = 10, ["y"] = 7, ["param1"] = 81, ["z"] = 2, ["name"] = "default:steelblock"}, {["x"] = 10, ["y"] = 7, ["param1"] = 81, ["z"] = 3, ["name"] = "default:steelblock"}, {["x"] = 10, ["y"] = 7, ["param1"] = 81, ["z"] = 4, ["name"] = "default:steelblock"}, {["x"] = 10, ["y"] = 7, ["param1"] = 81, ["z"] = 5, ["name"] = "default:steelblock"}, {["x"] = 10, ["y"] = 7, ["param1"] = 81, ["z"] = 6, ["name"] = "default:steelblock"}, {["x"] = 10, ["y"] = 7, ["param1"] = 81, ["z"] = 7, ["name"] = "default:steelblock"}, {["x"] = 10, ["y"] = 7, ["param1"] = 81, ["z"] = 8, ["name"] = "default:steelblock"}, {["x"] = 10, ["y"] = 7, ["param1"] = 81, ["z"] = 9, ["name"] = "default:steelblock"}, {["x"] = 10, ["y"] = 7, ["z"] = 10, ["name"] = "default:steelblock"}, {["x"] = 10, ["y"] = 7, ["z"] = 11, ["name"] = "default:steelblock"}, {["x"] = 10, ["y"] = 7, ["z"] = 12, ["name"] = "default:steelblock"}, {["x"] = 10, ["y"] = 7, ["z"] = 13, ["name"] = "default:steelblock"}, {["x"] = 10, ["y"] = 8, ["param1"] = 81, ["z"] = 2, ["name"] = "default:steelblock"}, {["x"] = 10, ["y"] = 8, ["param1"] = 81, ["z"] = 3, ["name"] = "default:steelblock"}, {["x"] = 10, ["y"] = 8, ["param1"] = 81, ["z"] = 4, ["name"] = "default:steelblock"}, {["x"] = 10, ["y"] = 8, ["param1"] = 81, ["z"] = 5, ["name"] = "default:steelblock"}, {["x"] = 10, ["y"] = 8, ["param1"] = 81, ["z"] = 6, ["name"] = "default:steelblock"}, {["x"] = 10, ["y"] = 8, ["param1"] = 81, ["z"] = 7, ["name"] = "default:steelblock"}, {["x"] = 10, ["y"] = 8, ["param1"] = 81, ["z"] = 8, ["name"] = "default:steelblock"}, {["x"] = 10, ["y"] = 8, ["param1"] = 81, ["z"] = 9, ["name"] = "default:steelblock"}, {["x"] = 10, ["y"] = 8, ["z"] = 10, ["name"] = "default:steelblock"}, {["x"] = 10, ["y"] = 8, ["z"] = 11, ["name"] = "default:steelblock"}, {["x"] = 10, ["y"] = 8, ["z"] = 12, ["name"] = "default:steelblock"}, {["x"] = 10, ["y"] = 8, ["z"] = 13, ["name"] = "default:steelblock"}, {["x"] = 10, ["y"] = 9, ["z"] = 1, ["name"] = "wool:grey"}, {["x"] = 10, ["y"] = 9, ["param1"] = 81, ["z"] = 2, ["name"] = "default:steelblock"}, {["x"] = 10, ["y"] = 9, ["param1"] = 81, ["z"] = 3, ["name"] = "default:steelblock"}, {["x"] = 10, ["y"] = 9, ["param1"] = 81, ["z"] = 4, ["name"] = "default:steelblock"}, {["x"] = 10, ["y"] = 9, ["param1"] = 81, ["z"] = 5, ["name"] = "default:steelblock"}, {["x"] = 10, ["y"] = 9, ["param1"] = 81, ["z"] = 6, ["name"] = "default:steelblock"}, {["x"] = 10, ["y"] = 9, ["param1"] = 81, ["z"] = 7, ["name"] = "default:steelblock"}, {["x"] = 10, ["y"] = 9, ["param1"] = 81, ["z"] = 8, ["name"] = "default:steelblock"}, {["x"] = 10, ["y"] = 9, ["param1"] = 81, ["z"] = 9, ["name"] = "default:steelblock"}, {["x"] = 10, ["y"] = 9, ["z"] = 10, ["name"] = "default:steelblock"}, {["x"] = 10, ["y"] = 9, ["z"] = 11, ["name"] = "default:steelblock"}, {["x"] = 10, ["y"] = 9, ["z"] = 12, ["name"] = "default:steelblock"}, {["x"] = 10, ["y"] = 9, ["z"] = 13, ["name"] = "default:steelblock"}, {["x"] = 10, ["y"] = 9, ["z"] = 14, ["name"] = "wool:grey"}, {["x"] = 10, ["y"] = 10, ["z"] = 2, ["name"] = "default:steelblock"}, {["x"] = 10, ["y"] = 10, ["param1"] = 81, ["z"] = 3, ["name"] = "default:steelblock"}, {["x"] = 10, ["y"] = 10, ["param1"] = 81, ["z"] = 4, ["name"] = "default:steelblock"}, {["x"] = 10, ["y"] = 10, ["param1"] = 81, ["z"] = 5, ["name"] = "default:steelblock"}, {["x"] = 10, ["y"] = 10, ["param1"] = 81, ["z"] = 6, ["name"] = "default:steelblock"}, {["x"] = 10, ["y"] = 10, ["param1"] = 81, ["z"] = 7, ["name"] = "default:steelblock"}, {["x"] = 10, ["y"] = 10, ["param1"] = 81, ["z"] = 8, ["name"] = "default:steelblock"}, {["x"] = 10, ["y"] = 10, ["param1"] = 81, ["z"] = 9, ["name"] = "default:steelblock"}, {["x"] = 10, ["y"] = 10, ["z"] = 10, ["name"] = "default:steelblock"}, {["x"] = 10, ["y"] = 10, ["z"] = 11, ["name"] = "default:steelblock"}, {["x"] = 10, ["y"] = 10, ["z"] = 12, ["name"] = "default:steelblock"}, {["x"] = 10, ["y"] = 10, ["z"] = 13, ["name"] = "default:steelblock"}, {["x"] = 11, ["y"] = 6, ["z"] = 1, ["name"] = "wool:grey"}, {["x"] = 11, ["y"] = 6, ["param1"] = 81, ["z"] = 2, ["name"] = "default:steelblock"}, {["x"] = 11, ["y"] = 6, ["param1"] = 81, ["z"] = 3, ["name"] = "default:steelblock"}, {["x"] = 11, ["y"] = 6, ["param1"] = 81, ["z"] = 4, ["name"] = "default:steelblock"}, {["x"] = 11, ["y"] = 6, ["param1"] = 81, ["z"] = 5, ["name"] = "default:steelblock"}, {["x"] = 11, ["y"] = 6, ["param1"] = 81, ["z"] = 6, ["name"] = "default:steelblock"}, {["x"] = 11, ["y"] = 6, ["param1"] = 81, ["z"] = 7, ["name"] = "default:steelblock"}, {["x"] = 11, ["y"] = 6, ["param1"] = 81, ["z"] = 8, ["name"] = "default:steelblock"}, {["x"] = 11, ["y"] = 6, ["param1"] = 81, ["z"] = 9, ["name"] = "default:steelblock"}, {["x"] = 11, ["y"] = 6, ["z"] = 10, ["name"] = "default:steelblock"}, {["x"] = 11, ["y"] = 6, ["z"] = 11, ["name"] = "default:steelblock"}, {["x"] = 11, ["y"] = 6, ["z"] = 12, ["name"] = "default:steelblock"}, {["x"] = 11, ["y"] = 6, ["z"] = 13, ["name"] = "default:steelblock"}, {["x"] = 11, ["y"] = 6, ["z"] = 14, ["name"] = "wool:grey"}, {["x"] = 11, ["y"] = 7, ["param1"] = 81, ["z"] = 2, ["name"] = "default:steelblock"}, {["x"] = 11, ["y"] = 7, ["param1"] = 81, ["z"] = 3, ["name"] = "default:steelblock"}, {["x"] = 11, ["y"] = 7, ["param1"] = 81, ["z"] = 4, ["name"] = "default:steelblock"}, {["x"] = 11, ["y"] = 7, ["param1"] = 81, ["z"] = 5, ["name"] = "default:steelblock"}, {["x"] = 11, ["y"] = 7, ["param1"] = 81, ["z"] = 6, ["name"] = "default:steelblock"}, {["x"] = 11, ["y"] = 7, ["param1"] = 81, ["z"] = 7, ["name"] = "default:steelblock"}, {["x"] = 11, ["y"] = 7, ["param1"] = 81, ["z"] = 8, ["name"] = "default:steelblock"}, {["x"] = 11, ["y"] = 7, ["param1"] = 81, ["z"] = 9, ["name"] = "default:steelblock"}, {["x"] = 11, ["y"] = 7, ["z"] = 10, ["name"] = "default:steelblock"}, {["x"] = 11, ["y"] = 7, ["z"] = 11, ["name"] = "default:steelblock"}, {["x"] = 11, ["y"] = 7, ["z"] = 12, ["name"] = "default:steelblock"}, {["x"] = 11, ["y"] = 7, ["z"] = 13, ["name"] = "default:steelblock"}, {["x"] = 11, ["y"] = 8, ["param1"] = 81, ["z"] = 2, ["name"] = "default:steelblock"}, {["x"] = 11, ["y"] = 8, ["param1"] = 81, ["z"] = 3, ["name"] = "default:steelblock"}, {["x"] = 11, ["y"] = 8, ["param1"] = 81, ["z"] = 4, ["name"] = "default:steelblock"}, {["x"] = 11, ["y"] = 8, ["param1"] = 81, ["z"] = 5, ["name"] = "default:steelblock"}, {["x"] = 11, ["y"] = 8, ["param1"] = 81, ["z"] = 6, ["name"] = "default:steelblock"}, {["x"] = 11, ["y"] = 8, ["param1"] = 81, ["z"] = 7, ["name"] = "default:steelblock"}, {["x"] = 11, ["y"] = 8, ["param1"] = 81, ["z"] = 8, ["name"] = "default:steelblock"}, {["x"] = 11, ["y"] = 8, ["param1"] = 81, ["z"] = 9, ["name"] = "default:steelblock"}, {["x"] = 11, ["y"] = 8, ["z"] = 10, ["name"] = "default:steelblock"}, {["x"] = 11, ["y"] = 8, ["z"] = 11, ["name"] = "default:steelblock"}, {["x"] = 11, ["y"] = 8, ["z"] = 12, ["name"] = "default:steelblock"}, {["x"] = 11, ["y"] = 8, ["z"] = 13, ["name"] = "default:steelblock"}, {["x"] = 11, ["y"] = 9, ["z"] = 1, ["name"] = "wool:grey"}, {["x"] = 11, ["y"] = 9, ["z"] = 2, ["name"] = "default:steelblock"}, {["x"] = 11, ["y"] = 9, ["param1"] = 81, ["z"] = 3, ["name"] = "default:steelblock"}, {["x"] = 11, ["y"] = 9, ["param1"] = 81, ["z"] = 4, ["name"] = "default:steelblock"}, {["x"] = 11, ["y"] = 9, ["param1"] = 81, ["z"] = 5, ["name"] = "default:steelblock"}, {["x"] = 11, ["y"] = 9, ["param1"] = 81, ["z"] = 6, ["name"] = "default:steelblock"}, {["x"] = 11, ["y"] = 9, ["param1"] = 81, ["z"] = 7, ["name"] = "default:steelblock"}, {["x"] = 11, ["y"] = 9, ["param1"] = 81, ["z"] = 8, ["name"] = "default:steelblock"}, {["x"] = 11, ["y"] = 9, ["param1"] = 81, ["z"] = 9, ["name"] = "default:steelblock"}, {["x"] = 11, ["y"] = 9, ["z"] = 10, ["name"] = "default:steelblock"}, {["x"] = 11, ["y"] = 9, ["z"] = 11, ["name"] = "default:steelblock"}, {["x"] = 11, ["y"] = 9, ["z"] = 12, ["name"] = "default:steelblock"}, {["x"] = 11, ["y"] = 9, ["z"] = 13, ["name"] = "default:steelblock"}, {["x"] = 11, ["y"] = 9, ["z"] = 14, ["name"] = "wool:grey"}, {["x"] = 12, ["y"] = 6, ["z"] = 1, ["name"] = "wool:grey"}, {["x"] = 12, ["y"] = 6, ["z"] = 14, ["name"] = "wool:grey"}, {["x"] = 12, ["y"] = 9, ["z"] = 1, ["name"] = "wool:grey"}, {["x"] = 12, ["y"] = 9, ["z"] = 14, ["name"] = "wool:grey"}, {["x"] = 13, ["y"] = 6, ["z"] = 1, ["name"] = "wool:grey"}, {["x"] = 13, ["y"] = 6, ["z"] = 14, ["name"] = "wool:grey"}, {["x"] = 13, ["y"] = 9, ["z"] = 1, ["name"] = "wool:grey"}, {["x"] = 13, ["y"] = 9, ["z"] = 14, ["name"] = "wool:grey"}, {["x"] = 14, ["y"] = 0, ["param1"] = 86, ["z"] = 0, ["name"] = "wool:grey"}, {["x"] = 14, ["y"] = 0, ["param1"] = 86, ["z"] = 1, ["name"] = "wool:grey"}, {["x"] = 14, ["y"] = 0, ["param1"] = 86, ["z"] = 14, ["name"] = "wool:grey"}, {["x"] = 14, ["y"] = 0, ["param1"] = 86, ["z"] = 15, ["name"] = "wool:grey"}, {["x"] = 14, ["y"] = 1, ["param1"] = 86, ["z"] = 0, ["name"] = "wool:grey"}, {["x"] = 14, ["y"] = 1, ["param1"] = 86, ["z"] = 1, ["name"] = "wool:grey"}, {["x"] = 14, ["y"] = 1, ["param1"] = 86, ["z"] = 14, ["name"] = "wool:grey"}, {["x"] = 14, ["y"] = 1, ["param1"] = 86, ["z"] = 15, ["name"] = "wool:grey"}, {["x"] = 14, ["y"] = 2, ["param1"] = 86, ["z"] = 0, ["name"] = "wool:grey"}, {["x"] = 14, ["y"] = 2, ["param1"] = 86, ["z"] = 1, ["name"] = "wool:grey"}, {["x"] = 14, ["y"] = 2, ["param1"] = 86, ["z"] = 14, ["name"] = "wool:grey"}, {["x"] = 14, ["y"] = 2, ["param1"] = 86, ["z"] = 15, ["name"] = "wool:grey"}, {["x"] = 14, ["y"] = 3, ["param1"] = 86, ["z"] = 0, ["name"] = "wool:grey"}, {["x"] = 14, ["y"] = 3, ["param1"] = 86, ["z"] = 1, ["name"] = "wool:grey"}, {["x"] = 14, ["y"] = 3, ["param1"] = 86, ["z"] = 14, ["name"] = "wool:grey"}, {["x"] = 14, ["y"] = 3, ["param1"] = 86, ["z"] = 15, ["name"] = "wool:grey"}, {["x"] = 14, ["y"] = 4, ["param1"] = 86, ["z"] = 0, ["name"] = "wool:grey"}, {["x"] = 14, ["y"] = 4, ["param1"] = 86, ["z"] = 1, ["name"] = "wool:grey"}, {["x"] = 14, ["y"] = 4, ["param1"] = 86, ["z"] = 14, ["name"] = "wool:grey"}, {["x"] = 14, ["y"] = 4, ["param1"] = 86, ["z"] = 15, ["name"] = "wool:grey"}, {["x"] = 14, ["y"] = 5, ["param1"] = 86, ["z"] = 0, ["name"] = "wool:grey"}, {["x"] = 14, ["y"] = 5, ["param1"] = 86, ["z"] = 1, ["name"] = "wool:grey"}, {["x"] = 14, ["y"] = 5, ["param1"] = 86, ["z"] = 14, ["name"] = "wool:grey"}, {["x"] = 14, ["y"] = 5, ["param1"] = 86, ["z"] = 15, ["name"] = "wool:grey"}, {["x"] = 14, ["y"] = 6, ["param1"] = 86, ["z"] = 0, ["name"] = "wool:grey"}, {["x"] = 14, ["y"] = 6, ["param1"] = 86, ["z"] = 1, ["name"] = "wool:grey"}, {["x"] = 14, ["y"] = 6, ["z"] = 2, ["name"] = "wool:grey"}, {["x"] = 14, ["y"] = 6, ["z"] = 3, ["name"] = "wool:grey"}, {["x"] = 14, ["y"] = 6, ["z"] = 4, ["name"] = "wool:grey"}, {["x"] = 14, ["y"] = 6, ["z"] = 5, ["name"] = "wool:grey"}, {["x"] = 14, ["y"] = 6, ["z"] = 6, ["name"] = "wool:grey"}, {["x"] = 14, ["y"] = 6, ["z"] = 7, ["name"] = "wool:grey"}, {["x"] = 14, ["y"] = 6, ["z"] = 8, ["name"] = "wool:grey"}, {["x"] = 14, ["y"] = 6, ["z"] = 9, ["name"] = "wool:grey"}, {["x"] = 14, ["y"] = 6, ["z"] = 10, ["name"] = "wool:grey"}, {["x"] = 14, ["y"] = 6, ["z"] = 11, ["name"] = "wool:grey"}, {["x"] = 14, ["y"] = 6, ["z"] = 12, ["name"] = "wool:grey"}, {["x"] = 14, ["y"] = 6, ["z"] = 13, ["name"] = "wool:grey"}, {["x"] = 14, ["y"] = 6, ["param1"] = 86, ["z"] = 14, ["name"] = "wool:grey"}, {["x"] = 14, ["y"] = 6, ["param1"] = 86, ["z"] = 15, ["name"] = "wool:grey"}, {["x"] = 14, ["y"] = 7, ["param1"] = 86, ["z"] = 0, ["name"] = "wool:grey"}, {["x"] = 14, ["y"] = 7, ["param1"] = 86, ["z"] = 1, ["name"] = "wool:grey"}, {["x"] = 14, ["y"] = 7, ["z"] = 6, ["name"] = "wool:grey"}, {["x"] = 14, ["y"] = 7, ["z"] = 9, ["name"] = "wool:grey"}, {["x"] = 14, ["y"] = 7, ["param1"] = 86, ["z"] = 14, ["name"] = "wool:grey"}, {["x"] = 14, ["y"] = 7, ["param1"] = 86, ["z"] = 15, ["name"] = "wool:grey"}, {["x"] = 14, ["y"] = 8, ["param1"] = 86, ["z"] = 0, ["name"] = "wool:grey"}, {["x"] = 14, ["y"] = 8, ["param1"] = 86, ["z"] = 1, ["name"] = "wool:grey"}, {["x"] = 14, ["y"] = 8, ["z"] = 6, ["name"] = "wool:grey"}, {["x"] = 14, ["y"] = 8, ["z"] = 9, ["name"] = "wool:grey"}, {["x"] = 14, ["y"] = 8, ["param1"] = 86, ["z"] = 14, ["name"] = "wool:grey"}, {["x"] = 14, ["y"] = 8, ["param1"] = 86, ["z"] = 15, ["name"] = "wool:grey"}, {["x"] = 14, ["y"] = 9, ["param1"] = 86, ["z"] = 0, ["name"] = "wool:grey"}, {["x"] = 14, ["y"] = 9, ["param1"] = 86, ["z"] = 1, ["name"] = "wool:grey"}, {["x"] = 14, ["y"] = 9, ["z"] = 2, ["name"] = "wool:grey"}, {["x"] = 14, ["y"] = 9, ["z"] = 3, ["name"] = "wool:grey"}, {["x"] = 14, ["y"] = 9, ["z"] = 4, ["name"] = "wool:grey"}, {["x"] = 14, ["y"] = 9, ["z"] = 5, ["name"] = "wool:grey"}, {["x"] = 14, ["y"] = 9, ["z"] = 6, ["name"] = "wool:grey"}, {["x"] = 14, ["y"] = 9, ["z"] = 7, ["name"] = "wool:grey"}, {["x"] = 14, ["y"] = 9, ["z"] = 8, ["name"] = "wool:grey"}, {["x"] = 14, ["y"] = 9, ["z"] = 9, ["name"] = "wool:grey"}, {["x"] = 14, ["y"] = 9, ["z"] = 10, ["name"] = "wool:grey"}, {["x"] = 14, ["y"] = 9, ["z"] = 11, ["name"] = "wool:grey"}, {["x"] = 14, ["y"] = 9, ["z"] = 12, ["name"] = "wool:grey"}, {["x"] = 14, ["y"] = 9, ["z"] = 13, ["name"] = "wool:grey"}, {["x"] = 14, ["y"] = 9, ["param1"] = 86, ["z"] = 14, ["name"] = "wool:grey"}, {["x"] = 14, ["y"] = 9, ["param1"] = 86, ["z"] = 15, ["name"] = "wool:grey"}, {["x"] = 14, ["y"] = 10, ["param1"] = 86, ["z"] = 0, ["name"] = "wool:grey"}, {["x"] = 14, ["y"] = 10, ["param1"] = 86, ["z"] = 1, ["name"] = "wool:grey"}, {["x"] = 14, ["y"] = 10, ["param1"] = 86, ["z"] = 14, ["name"] = "wool:grey"}, {["x"] = 14, ["y"] = 10, ["param1"] = 86, ["z"] = 15, ["name"] = "wool:grey"}, {["x"] = 14, ["y"] = 11, ["param1"] = 86, ["z"] = 0, ["name"] = "wool:grey"}, {["x"] = 14, ["y"] = 11, ["param1"] = 86, ["z"] = 1, ["name"] = "wool:grey"}, {["x"] = 14, ["y"] = 11, ["param1"] = 86, ["z"] = 14, ["name"] = "wool:grey"}, {["x"] = 14, ["y"] = 11, ["param1"] = 86, ["z"] = 15, ["name"] = "wool:grey"}, {["x"] = 14, ["y"] = 12, ["param1"] = 86, ["z"] = 0, ["name"] = "wool:grey"}, {["x"] = 14, ["y"] = 12, ["param1"] = 86, ["z"] = 1, ["name"] = "wool:grey"}, {["x"] = 14, ["y"] = 12, ["param1"] = 86, ["z"] = 14, ["name"] = "wool:grey"}, {["x"] = 14, ["y"] = 12, ["param1"] = 86, ["z"] = 15, ["name"] = "wool:grey"}, {["x"] = 14, ["y"] = 13, ["param1"] = 86, ["z"] = 0, ["name"] = "wool:grey"}, {["x"] = 14, ["y"] = 13, ["param1"] = 86, ["z"] = 1, ["name"] = "wool:grey"}, {["x"] = 14, ["y"] = 13, ["param1"] = 86, ["z"] = 14, ["name"] = "wool:grey"}, {["x"] = 14, ["y"] = 13, ["param1"] = 86, ["z"] = 15, ["name"] = "wool:grey"}, {["x"] = 14, ["y"] = 14, ["param1"] = 86, ["z"] = 0, ["name"] = "wool:grey"}, {["x"] = 14, ["y"] = 14, ["param1"] = 86, ["z"] = 1, ["name"] = "wool:grey"}, {["x"] = 14, ["y"] = 14, ["param1"] = 86, ["z"] = 14, ["name"] = "wool:grey"}, {["x"] = 14, ["y"] = 14, ["param1"] = 86, ["z"] = 15, ["name"] = "wool:grey"}, {["x"] = 14, ["y"] = 15, ["param1"] = 86, ["z"] = 0, ["name"] = "wool:grey"}, {["x"] = 14, ["y"] = 15, ["param1"] = 86, ["z"] = 1, ["name"] = "wool:grey"}, {["x"] = 14, ["y"] = 15, ["param1"] = 86, ["z"] = 14, ["name"] = "wool:grey"}, {["x"] = 14, ["y"] = 15, ["param1"] = 86, ["z"] = 15, ["name"] = "wool:grey"}, {["x"] = 15, ["y"] = 0, ["param1"] = 86, ["z"] = 0, ["name"] = "wool:grey"}, {["x"] = 15, ["y"] = 0, ["param1"] = 86, ["z"] = 1, ["name"] = "wool:grey"}, {["x"] = 15, ["y"] = 0, ["param1"] = 86, ["z"] = 14, ["name"] = "wool:grey"}, {["x"] = 15, ["y"] = 0, ["param1"] = 86, ["z"] = 15, ["name"] = "wool:grey"}, {["x"] = 15, ["y"] = 1, ["param1"] = 86, ["z"] = 0, ["name"] = "wool:grey"}, {["x"] = 15, ["y"] = 1, ["param1"] = 86, ["z"] = 1, ["name"] = "wool:grey"}, {["x"] = 15, ["y"] = 1, ["param1"] = 86, ["z"] = 14, ["name"] = "wool:grey"}, {["x"] = 15, ["y"] = 1, ["param1"] = 86, ["z"] = 15, ["name"] = "wool:grey"}, {["x"] = 15, ["y"] = 2, ["param1"] = 86, ["z"] = 0, ["name"] = "wool:grey"}, {["x"] = 15, ["y"] = 2, ["param1"] = 86, ["z"] = 1, ["name"] = "wool:grey"}, {["x"] = 15, ["y"] = 2, ["param1"] = 86, ["z"] = 14, ["name"] = "wool:grey"}, {["x"] = 15, ["y"] = 2, ["param1"] = 86, ["z"] = 15, ["name"] = "wool:grey"}, {["x"] = 15, ["y"] = 3, ["param1"] = 86, ["z"] = 0, ["name"] = "wool:grey"}, {["x"] = 15, ["y"] = 3, ["param1"] = 86, ["z"] = 1, ["name"] = "wool:grey"}, {["x"] = 15, ["y"] = 3, ["param1"] = 86, ["z"] = 14, ["name"] = "wool:grey"}, {["x"] = 15, ["y"] = 3, ["param1"] = 86, ["z"] = 15, ["name"] = "wool:grey"}, {["x"] = 15, ["y"] = 4, ["param1"] = 86, ["z"] = 0, ["name"] = "wool:grey"}, {["x"] = 15, ["y"] = 4, ["param1"] = 86, ["z"] = 1, ["name"] = "wool:grey"}, {["x"] = 15, ["y"] = 4, ["param1"] = 86, ["z"] = 14, ["name"] = "wool:grey"}, {["x"] = 15, ["y"] = 4, ["param1"] = 86, ["z"] = 15, ["name"] = "wool:grey"}, {["x"] = 15, ["y"] = 5, ["param1"] = 86, ["z"] = 0, ["name"] = "wool:grey"}, {["x"] = 15, ["y"] = 5, ["param1"] = 86, ["z"] = 1, ["name"] = "wool:grey"}, {["x"] = 15, ["y"] = 5, ["param1"] = 86, ["z"] = 14, ["name"] = "wool:grey"}, {["x"] = 15, ["y"] = 5, ["param1"] = 86, ["z"] = 15, ["name"] = "wool:grey"}, {["x"] = 15, ["y"] = 6, ["param1"] = 86, ["z"] = 0, ["name"] = "wool:grey"}, {["x"] = 15, ["y"] = 6, ["param1"] = 86, ["z"] = 1, ["name"] = "wool:grey"}, {["x"] = 15, ["y"] = 6, ["param1"] = 86, ["z"] = 14, ["name"] = "wool:grey"}, {["x"] = 15, ["y"] = 6, ["param1"] = 86, ["z"] = 15, ["name"] = "wool:grey"}, {["x"] = 15, ["y"] = 7, ["param1"] = 86, ["z"] = 0, ["name"] = "wool:grey"}, {["x"] = 15, ["y"] = 7, ["param1"] = 86, ["z"] = 1, ["name"] = "wool:grey"}, {["x"] = 15, ["y"] = 7, ["param1"] = 86, ["z"] = 14, ["name"] = "wool:grey"}, {["x"] = 15, ["y"] = 7, ["param1"] = 86, ["z"] = 15, ["name"] = "wool:grey"}, {["x"] = 15, ["y"] = 8, ["param1"] = 86, ["z"] = 0, ["name"] = "wool:grey"}, {["x"] = 15, ["y"] = 8, ["param1"] = 86, ["z"] = 1, ["name"] = "wool:grey"}, {["x"] = 15, ["y"] = 8, ["param1"] = 86, ["z"] = 14, ["name"] = "wool:grey"}, {["x"] = 15, ["y"] = 8, ["param1"] = 86, ["z"] = 15, ["name"] = "wool:grey"}, {["x"] = 15, ["y"] = 9, ["param1"] = 86, ["z"] = 0, ["name"] = "wool:grey"}, {["x"] = 15, ["y"] = 9, ["param1"] = 86, ["z"] = 1, ["name"] = "wool:grey"}, {["x"] = 15, ["y"] = 9, ["param1"] = 86, ["z"] = 14, ["name"] = "wool:grey"}, {["x"] = 15, ["y"] = 9, ["param1"] = 86, ["z"] = 15, ["name"] = "wool:grey"}, {["x"] = 15, ["y"] = 10, ["param1"] = 86, ["z"] = 0, ["name"] = "wool:grey"}, {["x"] = 15, ["y"] = 10, ["param1"] = 86, ["z"] = 1, ["name"] = "wool:grey"}, {["x"] = 15, ["y"] = 10, ["param1"] = 86, ["z"] = 14, ["name"] = "wool:grey"}, {["x"] = 15, ["y"] = 10, ["param1"] = 86, ["z"] = 15, ["name"] = "wool:grey"}, {["x"] = 15, ["y"] = 11, ["param1"] = 86, ["z"] = 0, ["name"] = "wool:grey"}, {["x"] = 15, ["y"] = 11, ["param1"] = 86, ["z"] = 1, ["name"] = "wool:grey"}, {["x"] = 15, ["y"] = 11, ["param1"] = 86, ["z"] = 14, ["name"] = "wool:grey"}, {["x"] = 15, ["y"] = 11, ["param1"] = 86, ["z"] = 15, ["name"] = "wool:grey"}, {["x"] = 15, ["y"] = 12, ["param1"] = 86, ["z"] = 0, ["name"] = "wool:grey"}, {["x"] = 15, ["y"] = 12, ["param1"] = 86, ["z"] = 1, ["name"] = "wool:grey"}, {["x"] = 15, ["y"] = 12, ["param1"] = 86, ["z"] = 14, ["name"] = "wool:grey"}, {["x"] = 15, ["y"] = 12, ["param1"] = 86, ["z"] = 15, ["name"] = "wool:grey"}, {["x"] = 15, ["y"] = 13, ["param1"] = 86, ["z"] = 0, ["name"] = "wool:grey"}, {["x"] = 15, ["y"] = 13, ["param1"] = 86, ["z"] = 1, ["name"] = "wool:grey"}, {["x"] = 15, ["y"] = 13, ["param1"] = 86, ["z"] = 14, ["name"] = "wool:grey"}, {["x"] = 15, ["y"] = 13, ["param1"] = 86, ["z"] = 15, ["name"] = "wool:grey"}, {["x"] = 15, ["y"] = 14, ["param1"] = 86, ["z"] = 0, ["name"] = "wool:grey"}, {["x"] = 15, ["y"] = 14, ["param1"] = 86, ["z"] = 1, ["name"] = "wool:grey"}, {["x"] = 15, ["y"] = 14, ["param1"] = 86, ["z"] = 14, ["name"] = "wool:grey"}, {["x"] = 15, ["y"] = 14, ["param1"] = 86, ["z"] = 15, ["name"] = "wool:grey"}, {["x"] = 15, ["y"] = 15, ["param1"] = 86, ["z"] = 0, ["name"] = "wool:grey"}, {["x"] = 15, ["y"] = 15, ["param1"] = 86, ["z"] = 1, ["name"] = "wool:grey"}, {["x"] = 15, ["y"] = 15, ["param1"] = 86, ["z"] = 14, ["name"] = "wool:grey"}, {["x"] = 15, ["y"] = 15, ["param1"] = 86, ["z"] = 15, ["name"] = "wool:grey"}}