5:return {{["x"] = 0, ["y"] = 0, ["z"] = 0, ["name"] = "default:wood"}, {["x"] = 0, ["y"] = 0, ["z"] = 1, ["name"] = "default:wood"}, {["x"] = 0, ["y"] = 0, ["z"] = 14, ["name"] = "default:wood"}, {["x"] = 0, ["y"] = 0, ["z"] = 15, ["name"] = "default:wood"}, {["x"] = 0, ["y"] = 8, ["z"] = 7, ["name"] = "wool:grey"}, {["x"] = 0, ["y"] = 8, ["z"] = 8, ["name"] = "wool:grey"}, {["x"] = 1, ["y"] = 0, ["z"] = 0, ["name"] = "default:wood"}, {["x"] = 1, ["y"] = 0, ["z"] = 1, ["name"] = "default:wood"}, {["x"] = 1, ["y"] = 0, ["z"] = 2, ["name"] = "default:wood"}, {["x"] = 1, ["y"] = 0, ["z"] = 13, ["name"] = "default:wood"}, {["x"] = 1, ["y"] = 0, ["z"] = 14, ["name"] = "default:wood"}, {["x"] = 1, ["y"] = 0, ["z"] = 15, ["name"] = "default:wood"}, {["x"] = 1, ["y"] = 9, ["z"] = 7, ["name"] = "wool:white"}, {["x"] = 1, ["y"] = 9, ["z"] = 8, ["name"] = "wool:white"}, {["x"] = 2, ["y"] = 0, ["z"] = 1, ["name"] = "default:wood"}, {["x"] = 2, ["y"] = 0, ["z"] = 2, ["name"] = "default:wood"}, {["x"] = 2, ["y"] = 0, ["z"] = 3, ["name"] = "default:wood"}, {["x"] = 2, ["y"] = 0, ["z"] = 12, ["name"] = "default:wood"}, {["x"] = 2, ["y"] = 0, ["z"] = 13, ["name"] = "default:wood"}, {["x"] = 2, ["y"] = 0, ["z"] = 14, ["name"] = "default:wood"}, {["x"] = 2, ["y"] = 9, ["z"] = 7, ["name"] = "wool:white"}, {["x"] = 2, ["y"] = 9, ["z"] = 8, ["name"] = "wool:white"}, {["x"] = 2, ["y"] = 10, ["z"] = 7, ["name"] = "wool:white"}, {["x"] = 2, ["y"] = 10, ["z"] = 8, ["name"] = "wool:white"}, {["x"] = 3, ["y"] = 0, ["z"] = 2, ["name"] = "default:wood"}, {["x"] = 3, ["y"] = 0, ["z"] = 3, ["name"] = "default:wood"}, {["x"] = 3, ["y"] = 0, ["z"] = 4, ["name"] = "default:wood"}, {["x"] = 3, ["y"] = 0, ["z"] = 11, ["name"] = "default:wood"}, {["x"] = 3, ["y"] = 0, ["z"] = 12, ["name"] = "default:wood"}, {["x"] = 3, ["y"] = 0, ["z"] = 13, ["name"] = "default:wood"}, {["x"] = 3, ["y"] = 8, ["z"] = 7, ["name"] = "wool:white"}, {["x"] = 3, ["y"] = 8, ["z"] = 8, ["name"] = "wool:white"}, {["x"] = 3, ["y"] = 11, ["z"] = 7, ["name"] = "wool:white"}, {["x"] = 3, ["y"] = 11, ["z"] = 8, ["name"] = "wool:white"}, {["x"] = 4, ["y"] = 0, ["z"] = 3, ["name"] = "default:wood"}, {["x"] = 4, ["y"] = 0, ["z"] = 4, ["name"] = "default:wood"}, {["x"] = 4, ["y"] = 0, ["z"] = 5, ["name"] = "default:wood"}, {["x"] = 4, ["y"] = 0, ["z"] = 6, ["name"] = "default:wood"}, {["x"] = 4, ["y"] = 0, ["z"] = 7, ["name"] = "default:wood"}, {["x"] = 4, ["y"] = 0, ["z"] = 8, ["name"] = "default:wood"}, {["x"] = 4, ["y"] = 0, ["z"] = 9, ["name"] = "default:wood"}, {["x"] = 4, ["y"] = 0, ["z"] = 10, ["name"] = "default:wood"}, {["x"] = 4, ["y"] = 0, ["z"] = 11, ["name"] = "default:wood"}, {["x"] = 4, ["y"] = 0, ["z"] = 12, ["name"] = "default:wood"}, {["x"] = 4, ["y"] = 7, ["z"] = 7, ["name"] = "wool:white"}, {["x"] = 4, ["y"] = 7, ["z"] = 8, ["name"] = "wool:white"}, {["x"] = 4, ["y"] = 12, ["z"] = 7, ["name"] = "wool:white"}, {["x"] = 4, ["y"] = 12, ["z"] = 8, ["name"] = "wool:white"}, {["x"] = 5, ["y"] = 0, ["z"] = 4, ["name"] = "default:wood"}, {["x"] = 5, ["y"] = 0, ["z"] = 5, ["name"] = "default:wood"}, {["x"] = 5, ["y"] = 0, ["z"] = 6, ["name"] = "default:wood"}, {["x"] = 5, ["y"] = 0, ["z"] = 7, ["name"] = "default:wood"}, {["x"] = 5, ["y"] = 0, ["z"] = 8, ["name"] = "default:wood"}, {["x"] = 5, ["y"] = 0, ["z"] = 9, ["name"] = "default:wood"}, {["x"] = 5, ["y"] = 0, ["z"] = 10, ["name"] = "default:wood"}, {["x"] = 5, ["y"] = 0, ["z"] = 11, ["name"] = "default:wood"}, {["x"] = 5, ["y"] = 3, ["z"] = 4, ["name"] = "default:aspen_wood"}, {["x"] = 5, ["y"] = 4, ["z"] = 4, ["name"] = "default:aspen_wood"}, {["x"] = 5, ["y"] = 6, ["z"] = 7, ["name"] = "wool:white"}, {["x"] = 5, ["y"] = 6, ["z"] = 8, ["name"] = "wool:white"}, {["x"] = 5, ["y"] = 13, ["z"] = 7, ["name"] = "wool:white"}, {["x"] = 5, ["y"] = 13, ["z"] = 8, ["name"] = "wool:white"}, {["x"] = 6, ["y"] = 0, ["z"] = 4, ["name"] = "default:wood"}, {["x"] = 6, ["y"] = 0, ["z"] = 5, ["name"] = "default:wood"}, {["x"] = 6, ["y"] = 0, ["z"] = 6, ["name"] = "default:wood"}, {["x"] = 6, ["y"] = 0, ["z"] = 7, ["name"] = "default:wood"}, {["x"] = 6, ["y"] = 0, ["z"] = 8, ["name"] = "default:wood"}, {["x"] = 6, ["y"] = 0, ["z"] = 9, ["name"] = "default:wood"}, {["x"] = 6, ["y"] = 0, ["z"] = 10, ["name"] = "default:wood"}, {["x"] = 6, ["y"] = 0, ["z"] = 11, ["name"] = "default:wood"}, {["x"] = 6, ["y"] = 1, ["z"] = 7, ["name"] = "default:wood"}, {["x"] = 6, ["y"] = 1, ["z"] = 8, ["name"] = "default:wood"}, {["x"] = 6, ["y"] = 2, ["z"] = 4, ["name"] = "default:aspen_wood"}, {["x"] = 6, ["y"] = 2, ["z"] = 7, ["name"] = "default:wood"}, {["x"] = 6, ["y"] = 2, ["z"] = 8, ["name"] = "default:wood"}, {["x"] = 6, ["y"] = 3, ["z"] = 4, ["name"] = "default:aspen_wood"}, {["x"] = 6, ["y"] = 4, ["z"] = 4, ["name"] = "default:aspen_wood"}, {["x"] = 6, ["y"] = 5, ["z"] = 4, ["name"] = "default:aspen_wood"}, {["x"] = 6, ["y"] = 6, ["z"] = 6, ["name"] = "wool:grey"}, {["x"] = 6, ["y"] = 6, ["z"] = 7, ["name"] = "wool:grey"}, {["x"] = 6, ["y"] = 6, ["z"] = 8, ["name"] = "wool:grey"}, {["x"] = 6, ["y"] = 6, ["z"] = 9, ["name"] = "wool:grey"}, {["x"] = 6, ["y"] = 9, ["z"] = 7, ["name"] = "wool:grey"}, {["x"] = 6, ["y"] = 9, ["z"] = 8, ["name"] = "wool:grey"}, {["x"] = 6, ["y"] = 13, ["z"] = 6, ["name"] = "wool:grey"}, {["x"] = 6, ["y"] = 13, ["z"] = 7, ["name"] = "wool:grey"}, {["x"] = 6, ["y"] = 13, ["z"] = 8, ["name"] = "wool:grey"}, {["x"] = 6, ["y"] = 13, ["z"] = 9, ["name"] = "wool:grey"}, {["x"] = 6, ["y"] = 15, ["z"] = 6, ["name"] = "wool:white"}, {["x"] = 6, ["y"] = 15, ["z"] = 7, ["name"] = "wool:white"}, {["x"] = 6, ["y"] = 15, ["z"] = 8, ["name"] = "wool:white"}, {["x"] = 6, ["y"] = 15, ["z"] = 9, ["name"] = "wool:white"}, {["x"] = 7, ["y"] = 0, ["z"] = 4, ["name"] = "default:wood"}, {["x"] = 7, ["y"] = 0, ["z"] = 5, ["name"] = "default:wood"}, {["x"] = 7, ["y"] = 0, ["z"] = 6, ["name"] = "default:wood"}, {["x"] = 7, ["y"] = 0, ["z"] = 7, ["name"] = "wool:red"}, {["x"] = 7, ["y"] = 0, ["z"] = 8, ["name"] = "wool:red"}, {["x"] = 7, ["y"] = 0, ["z"] = 9, ["name"] = "default:wood"}, {["x"] = 7, ["y"] = 0, ["z"] = 10, ["name"] = "default:wood"}, {["x"] = 7, ["y"] = 0, ["z"] = 11, ["name"] = "default:wood"}, {["x"] = 7, ["y"] = 1, ["z"] = 4, ["name"] = "default:aspen_wood"}, {["x"] = 7, ["y"] = 1, ["z"] = 6, ["name"] = "default:wood"}, {["x"] = 7, ["y"] = 1, ["z"] = 7, ["name"] = "wool:red"}, {["x"] = 7, ["y"] = 1, ["z"] = 8, ["name"] = "wool:red"}, {["x"] = 7, ["y"] = 1, ["z"] = 9, ["name"] = "default:wood"}, {["x"] = 7, ["y"] = 2, ["z"] = 4, ["name"] = "default:aspen_wood"}, {["x"] = 7, ["y"] = 2, ["z"] = 6, ["name"] = "default:wood"}, {["x"] = 7, ["y"] = 2, ["z"] = 7, ["name"] = "wool:red"}, {["x"] = 7, ["y"] = 2, ["z"] = 8, ["name"] = "wool:red"}, {["x"] = 7, ["y"] = 2, ["z"] = 9, ["name"] = "default:wood"}, {["x"] = 7, ["y"] = 3, ["z"] = 4, ["name"] = "default:aspen_wood"}, {["x"] = 7, ["y"] = 3, ["z"] = 5, ["name"] = "default:wood"}, {["x"] = 7, ["y"] = 3, ["z"] = 6, ["name"] = "default:wood"}, {["x"] = 7, ["y"] = 3, ["z"] = 7, ["name"] = "wool:red"}, {["x"] = 7, ["y"] = 3, ["z"] = 8, ["name"] = "wool:red"}, {["x"] = 7, ["y"] = 4, ["z"] = 4, ["name"] = "default:aspen_wood"}, {["x"] = 7, ["y"] = 4, ["z"] = 5, ["name"] = "default:wood"}, {["x"] = 7, ["y"] = 4, ["z"] = 6, ["name"] = "default:wood"}, {["x"] = 7, ["y"] = 4, ["z"] = 7, ["name"] = "wool:red"}, {["x"] = 7, ["y"] = 4, ["z"] = 8, ["name"] = "wool:red"}, {["x"] = 7, ["y"] = 5, ["z"] = 4, ["name"] = "default:aspen_wood"}, {["x"] = 7, ["y"] = 5, ["z"] = 7, ["name"] = "wool:red"}, {["x"] = 7, ["y"] = 5, ["z"] = 8, ["name"] = "wool:red"}, {["x"] = 7, ["y"] = 6, ["z"] = 4, ["name"] = "default:aspen_wood"}, {["x"] = 7, ["y"] = 6, ["z"] = 6, ["name"] = "wool:grey"}, {["x"] = 7, ["y"] = 6, ["z"] = 7, ["name"] = "wool:red"}, {["x"] = 7, ["y"] = 6, ["z"] = 8, ["name"] = "wool:red"}, {["x"] = 7, ["y"] = 6, ["z"] = 9, ["name"] = "wool:grey"}, {["x"] = 7, ["y"] = 7, ["z"] = 7, ["name"] = "wool:red"}, {["x"] = 7, ["y"] = 7, ["z"] = 8, ["name"] = "wool:red"}, {["x"] = 7, ["y"] = 8, ["z"] = 7, ["name"] = "wool:red"}, {["x"] = 7, ["y"] = 8, ["z"] = 8, ["name"] = "wool:red"}, {["x"] = 7, ["y"] = 9, ["z"] = 6, ["name"] = "wool:grey"}, {["x"] = 7, ["y"] = 9, ["z"] = 7, ["name"] = "wool:red"}, {["x"] = 7, ["y"] = 9, ["z"] = 8, ["name"] = "wool:red"}, {["x"] = 7, ["y"] = 9, ["z"] = 9, ["name"] = "wool:grey"}, {["x"] = 7, ["y"] = 10, ["z"] = 7, ["name"] = "wool:red"}, {["x"] = 7, ["y"] = 10, ["z"] = 8, ["name"] = "wool:red"}, {["x"] = 7, ["y"] = 11, ["z"] = 7, ["name"] = "wool:red"}, {["x"] = 7, ["y"] = 11, ["z"] = 8, ["name"] = "wool:red"}, {["x"] = 7, ["y"] = 12, ["z"] = 7, ["name"] = "wool:red"}, {["x"] = 7, ["y"] = 12, ["z"] = 8, ["name"] = "wool:red"}, {["x"] = 7, ["y"] = 13, ["z"] = 6, ["name"] = "wool:grey"}, {["x"] = 7, ["y"] = 13, ["z"] = 7, ["name"] = "wool:red"}, {["x"] = 7, ["y"] = 13, ["z"] = 8, ["name"] = "wool:red"}, {["x"] = 7, ["y"] = 13, ["z"] = 9, ["name"] = "wool:grey"}, {["x"] = 7, ["y"] = 14, ["z"] = 7, ["name"] = "wool:red"}, {["x"] = 7, ["y"] = 14, ["z"] = 8, ["name"] = "wool:red"}, {["x"] = 7, ["y"] = 15, ["z"] = 6, ["name"] = "wool:white"}, {["x"] = 7, ["y"] = 15, ["z"] = 7, ["name"] = "wool:white"}, {["x"] = 7, ["y"] = 15, ["z"] = 8, ["name"] = "wool:white"}, {["x"] = 7, ["y"] = 15, ["z"] = 9, ["name"] = "wool:white"}, {["x"] = 7, ["y"] = 16, ["z"] = 7, ["name"] = "wool:white"}, {["x"] = 7, ["y"] = 16, ["z"] = 8, ["name"] = "wool:white"}, {["x"] = 8, ["y"] = 0, ["z"] = 4, ["name"] = "default:wood"}, {["x"] = 8, ["y"] = 0, ["z"] = 5, ["name"] = "default:wood"}, {["x"] = 8, ["y"] = 0, ["z"] = 6, ["name"] = "default:wood"}, {["x"] = 8, ["y"] = 0, ["z"] = 7, ["name"] = "wool:red"}, {["x"] = 8, ["y"] = 0, ["z"] = 8, ["name"] = "wool:red"}, {["x"] = 8, ["y"] = 0, ["z"] = 9, ["name"] = "default:wood"}, {["x"] = 8, ["y"] = 0, ["z"] = 10, ["name"] = "default:wood"}, {["x"] = 8, ["y"] = 0, ["z"] = 11, ["name"] = "default:wood"}, {["x"] = 8, ["y"] = 1, ["z"] = 4, ["name"] = "default:aspen_wood"}, {["x"] = 8, ["y"] = 1, ["z"] = 6, ["name"] = "default:wood"}, {["x"] = 8, ["y"] = 1, ["z"] = 7, ["name"] = "wool:red"}, {["x"] = 8, ["y"] = 1, ["z"] = 8, ["name"] = "wool:red"}, {["x"] = 8, ["y"] = 1, ["z"] = 9, ["name"] = "default:wood"}, {["x"] = 8, ["y"] = 2, ["z"] = 4, ["name"] = "default:aspen_wood"}, {["x"] = 8, ["y"] = 2, ["z"] = 6, ["name"] = "default:wood"}, {["x"] = 8, ["y"] = 2, ["z"] = 7, ["name"] = "wool:red"}, {["x"] = 8, ["y"] = 2, ["z"] = 8, ["name"] = "wool:red"}, {["x"] = 8, ["y"] = 2, ["z"] = 9, ["name"] = "default:wood"}, {["x"] = 8, ["y"] = 3, ["z"] = 4, ["name"] = "default:aspen_wood"}, {["x"] = 8, ["y"] = 3, ["z"] = 5, ["name"] = "default:wood"}, {["x"] = 8, ["y"] = 3, ["z"] = 6, ["name"] = "default:wood"}, {["x"] = 8, ["y"] = 3, ["z"] = 7, ["name"] = "wool:red"}, {["x"] = 8, ["y"] = 3, ["z"] = 8, ["name"] = "wool:red"}, {["x"] = 8, ["y"] = 4, ["z"] = 4, ["name"] = "default:aspen_wood"}, {["x"] = 8, ["y"] = 4, ["z"] = 5, ["name"] = "default:wood"}, {["x"] = 8, ["y"] = 4, ["z"] = 6, ["name"] = "default:wood"}, {["x"] = 8, ["y"] = 4, ["z"] = 7, ["name"] = "wool:red"}, {["x"] = 8, ["y"] = 4, ["z"] = 8, ["name"] = "wool:red"}, {["x"] = 8, ["y"] = 5, ["z"] = 4, ["name"] = "default:aspen_wood"}, {["x"] = 8, ["y"] = 5, ["z"] = 7, ["name"] = "wool:red"}, {["x"] = 8, ["y"] = 5, ["z"] = 8, ["name"] = "wool:red"}, {["x"] = 8, ["y"] = 6, ["z"] = 4, ["name"] = "default:aspen_wood"}, {["x"] = 8, ["y"] = 6, ["z"] = 6, ["name"] = "wool:grey"}, {["x"] = 8, ["y"] = 6, ["z"] = 7, ["name"] = "wool:red"}, {["x"] = 8, ["y"] = 6, ["z"] = 8, ["name"] = "wool:red"}, {["x"] = 8, ["y"] = 6, ["z"] = 9, ["name"] = "wool:grey"}, {["x"] = 8, ["y"] = 7, ["z"] = 7, ["name"] = "wool:red"}, {["x"] = 8, ["y"] = 7, ["z"] = 8, ["name"] = "wool:red"}, {["x"] = 8, ["y"] = 8, ["z"] = 7, ["name"] = "wool:red"}, {["x"] = 8, ["y"] = 8, ["z"] = 8, ["name"] = "wool:red"}, {["x"] = 8, ["y"] = 9, ["z"] = 6, ["name"] = "wool:grey"}, {["x"] = 8, ["y"] = 9, ["z"] = 7, ["name"] = "wool:red"}, {["x"] = 8, ["y"] = 9, ["z"] = 8, ["name"] = "wool:red"}, {["x"] = 8, ["y"] = 9, ["z"] = 9, ["name"] = "wool:grey"}, {["x"] = 8, ["y"] = 10, ["z"] = 7, ["name"] = "wool:red"}, {["x"] = 8, ["y"] = 10, ["z"] = 8, ["name"] = "wool:red"}, {["x"] = 8, ["y"] = 11, ["z"] = 7, ["name"] = "wool:red"}, {["x"] = 8, ["y"] = 11, ["z"] = 8, ["name"] = "wool:red"}, {["x"] = 8, ["y"] = 12, ["z"] = 7, ["name"] = "wool:red"}, {["x"] = 8, ["y"] = 12, ["z"] = 8, ["name"] = "wool:red"}, {["x"] = 8, ["y"] = 13, ["z"] = 6, ["name"] = "wool:grey"}, {["x"] = 8, ["y"] = 13, ["z"] = 7, ["name"] = "wool:red"}, {["x"] = 8, ["y"] = 13, ["z"] = 8, ["name"] = "wool:red"}, {["x"] = 8, ["y"] = 13, ["z"] = 9, ["name"] = "wool:grey"}, {["x"] = 8, ["y"] = 14, ["z"] = 7, ["name"] = "wool:red"}, {["x"] = 8, ["y"] = 14, ["z"] = 8, ["name"] = "wool:red"}, {["x"] = 8, ["y"] = 15, ["z"] = 6, ["name"] = "wool:white"}, {["x"] = 8, ["y"] = 15, ["z"] = 7, ["name"] = "wool:white"}, {["x"] = 8, ["y"] = 15, ["z"] = 8, ["name"] = "wool:white"}, {["x"] = 8, ["y"] = 15, ["z"] = 9, ["name"] = "wool:white"}, {["x"] = 8, ["y"] = 16, ["z"] = 7, ["name"] = "wool:white"}, {["x"] = 8, ["y"] = 16, ["z"] = 8, ["name"] = "wool:white"}, {["x"] = 9, ["y"] = 0, ["z"] = 4, ["name"] = "default:wood"}, {["x"] = 9, ["y"] = 0, ["z"] = 5, ["name"] = "default:wood"}, {["x"] = 9, ["y"] = 0, ["z"] = 6, ["name"] = "default:wood"}, {["x"] = 9, ["y"] = 0, ["z"] = 7, ["name"] = "default:wood"}, {["x"] = 9, ["y"] = 0, ["z"] = 8, ["name"] = "default:wood"}, {["x"] = 9, ["y"] = 0, ["z"] = 9, ["name"] = "default:wood"}, {["x"] = 9, ["y"] = 0, ["z"] = 10, ["name"] = "default:wood"}, {["x"] = 9, ["y"] = 0, ["z"] = 11, ["name"] = "default:wood"}, {["x"] = 9, ["y"] = 1, ["z"] = 7, ["name"] = "default:wood"}, {["x"] = 9, ["y"] = 1, ["z"] = 8, ["name"] = "default:wood"}, {["x"] = 9, ["y"] = 2, ["z"] = 4, ["name"] = "default:aspen_wood"}, {["x"] = 9, ["y"] = 2, ["z"] = 7, ["name"] = "default:wood"}, {["x"] = 9, ["y"] = 2, ["z"] = 8, ["name"] = "default:wood"}, {["x"] = 9, ["y"] = 3, ["z"] = 4, ["name"] = "default:aspen_wood"}, {["x"] = 9, ["y"] = 4, ["z"] = 4, ["name"] = "default:aspen_wood"}, {["x"] = 9, ["y"] = 5, ["z"] = 4, ["name"] = "default:aspen_wood"}, {["x"] = 9, ["y"] = 6, ["z"] = 6, ["name"] = "wool:grey"}, {["x"] = 9, ["y"] = 6, ["z"] = 7, ["name"] = "wool:grey"}, {["x"] = 9, ["y"] = 6, ["z"] = 8, ["name"] = "wool:grey"}, {["x"] = 9, ["y"] = 6, ["z"] = 9, ["name"] = "wool:grey"}, {["x"] = 9, ["y"] = 9, ["z"] = 7, ["name"] = "wool:grey"}, {["x"] = 9, ["y"] = 9, ["z"] = 8, ["name"] = "wool:grey"}, {["x"] = 9, ["y"] = 13, ["z"] = 6, ["name"] = "wool:grey"}, {["x"] = 9, ["y"] = 13, ["z"] = 7, ["name"] = "wool:grey"}, {["x"] = 9, ["y"] = 13, ["z"] = 8, ["name"] = "wool:grey"}, {["x"] = 9, ["y"] = 13, ["z"] = 9, ["name"] = "wool:grey"}, {["x"] = 9, ["y"] = 15, ["z"] = 6, ["name"] = "wool:white"}, {["x"] = 9, ["y"] = 15, ["z"] = 7, ["name"] = "wool:white"}, {["x"] = 9, ["y"] = 15, ["z"] = 8, ["name"] = "wool:white"}, {["x"] = 9, ["y"] = 15, ["z"] = 9, ["name"] = "wool:white"}, {["x"] = 10, ["y"] = 0, ["z"] = 4, ["name"] = "default:wood"}, {["x"] = 10, ["y"] = 0, ["z"] = 5, ["name"] = "default:wood"}, {["x"] = 10, ["y"] = 0, ["z"] = 6, ["name"] = "default:wood"}, {["x"] = 10, ["y"] = 0, ["z"] = 7, ["name"] = "default:wood"}, {["x"] = 10, ["y"] = 0, ["z"] = 8, ["name"] = "default:wood"}, {["x"] = 10, ["y"] = 0, ["z"] = 9, ["name"] = "default:wood"}, {["x"] = 10, ["y"] = 0, ["z"] = 10, ["name"] = "default:wood"}, {["x"] = 10, ["y"] = 0, ["z"] = 11, ["name"] = "default:wood"}, {["x"] = 10, ["y"] = 3, ["z"] = 4, ["name"] = "default:aspen_wood"}, {["x"] = 10, ["y"] = 4, ["z"] = 4, ["name"] = "default:aspen_wood"}, {["x"] = 10, ["y"] = 6, ["z"] = 7, ["name"] = "wool:white"}, {["x"] = 10, ["y"] = 6, ["z"] = 8, ["name"] = "wool:white"}, {["x"] = 10, ["y"] = 13, ["z"] = 7, ["name"] = "wool:white"}, {["x"] = 10, ["y"] = 13, ["z"] = 8, ["name"] = "wool:white"}, {["x"] = 11, ["y"] = 0, ["z"] = 3, ["name"] = "default:wood"}, {["x"] = 11, ["y"] = 0, ["z"] = 4, ["name"] = "default:wood"}, {["x"] = 11, ["y"] = 0, ["z"] = 5, ["name"] = "default:wood"}, {["x"] = 11, ["y"] = 0, ["z"] = 6, ["name"] = "default:wood"}, {["x"] = 11, ["y"] = 0, ["z"] = 7, ["name"] = "default:wood"}, {["x"] = 11, ["y"] = 0, ["z"] = 8, ["name"] = "default:wood"}, {["x"] = 11, ["y"] = 0, ["z"] = 9, ["name"] = "default:wood"}, {["x"] = 11, ["y"] = 0, ["z"] = 10, ["name"] = "default:wood"}, {["x"] = 11, ["y"] = 0, ["z"] = 11, ["name"] = "default:wood"}, {["x"] = 11, ["y"] = 0, ["z"] = 12, ["name"] = "default:wood"}, {["x"] = 11, ["y"] = 7, ["z"] = 7, ["name"] = "wool:white"}, {["x"] = 11, ["y"] = 7, ["z"] = 8, ["name"] = "wool:white"}, {["x"] = 11, ["y"] = 12, ["z"] = 7, ["name"] = "wool:white"}, {["x"] = 11, ["y"] = 12, ["z"] = 8, ["name"] = "wool:white"}, {["x"] = 12, ["y"] = 0, ["z"] = 2, ["name"] = "default:wood"}, {["x"] = 12, ["y"] = 0, ["z"] = 3, ["name"] = "default:wood"}, {["x"] = 12, ["y"] = 0, ["z"] = 4, ["name"] = "default:wood"}, {["x"] = 12, ["y"] = 0, ["z"] = 11, ["name"] = "default:wood"}, {["x"] = 12, ["y"] = 0, ["z"] = 12, ["name"] = "default:wood"}, {["x"] = 12, ["y"] = 0, ["z"] = 13, ["name"] = "default:wood"}, {["x"] = 12, ["y"] = 8, ["z"] = 7, ["name"] = "wool:white"}, {["x"] = 12, ["y"] = 8, ["z"] = 8, ["name"] = "wool:white"}, {["x"] = 12, ["y"] = 11, ["z"] = 7, ["name"] = "wool:white"}, {["x"] = 12, ["y"] = 11, ["z"] = 8, ["name"] = "wool:white"}, {["x"] = 13, ["y"] = 0, ["z"] = 1, ["name"] = "default:wood"}, {["x"] = 13, ["y"] = 0, ["z"] = 2, ["name"] = "default:wood"}, {["x"] = 13, ["y"] = 0, ["z"] = 3, ["name"] = "default:wood"}, {["x"] = 13, ["y"] = 0, ["z"] = 12, ["name"] = "default:wood"}, {["x"] = 13, ["y"] = 0, ["z"] = 13, ["name"] = "default:wood"}, {["x"] = 13, ["y"] = 0, ["z"] = 14, ["name"] = "default:wood"}, {["x"] = 13, ["y"] = 9, ["z"] = 7, ["name"] = "wool:white"}, {["x"] = 13, ["y"] = 9, ["z"] = 8, ["name"] = "wool:white"}, {["x"] = 13, ["y"] = 10, ["z"] = 7, ["name"] = "wool:white"}, {["x"] = 13, ["y"] = 10, ["z"] = 8, ["name"] = "wool:white"}, {["x"] = 14, ["y"] = 0, ["z"] = 0, ["name"] = "default:wood"}, {["x"] = 14, ["y"] = 0, ["z"] = 1, ["name"] = "default:wood"}, {["x"] = 14, ["y"] = 0, ["z"] = 2, ["name"] = "default:wood"}, {["x"] = 14, ["y"] = 0, ["z"] = 13, ["name"] = "default:wood"}, {["x"] = 14, ["y"] = 0, ["z"] = 14, ["name"] = "default:wood"}, {["x"] = 14, ["y"] = 0, ["z"] = 15, ["name"] = "default:wood"}, {["x"] = 14, ["y"] = 9, ["z"] = 7, ["name"] = "wool:white"}, {["x"] = 14, ["y"] = 9, ["z"] = 8, ["name"] = "wool:white"}, {["x"] = 15, ["y"] = 0, ["z"] = 0, ["name"] = "default:wood"}, {["x"] = 15, ["y"] = 0, ["z"] = 1, ["name"] = "default:wood"}, {["x"] = 15, ["y"] = 0, ["z"] = 14, ["name"] = "default:wood"}, {["x"] = 15, ["y"] = 0, ["z"] = 15, ["name"] = "default:wood"}, {["x"] = 15, ["y"] = 8, ["z"] = 7, ["name"] = "wool:grey"}, {["x"] = 15, ["y"] = 8, ["z"] = 8, ["name"] = "wool:grey"}}